# Ancient Warfare Structure Template File
# Auto-generated structure template file. created on: 3/12/2015 at: 6:18:24
# Lines beginning with # denote comments

header:
version=2.1
name=CityWallsGateTowerLeft
size=16,75,16
offset=9,4,15
:endheader

#### VALIDATION ####
validation:
type=ground
survival=false
worldGenEnabled=true
unique=false
preserveBlocks=false
selectionWeight=0
clusterValue=0
minDuplicateDistance=0
dimensionWhiteList=false
dimensionList=
biomeWhiteList=false
biomeList=
leveling=0
fill=0
border=0
validTargetBlocks=
blockSwap=false
data:
:enddata
:endvalidation

#### LAYERS ####
layer: 0
1,1,1,1,1,1,1,1,1,1,1,1,1,1,1,1
1,1,1,1,1,1,1,1,1,1,1,1,1,1,1,1
1,1,1,1,1,1,1,1,1,1,1,1,1,1,1,1
1,1,1,1,1,1,1,1,1,1,1,1,1,1,1,1
1,1,1,1,1,1,1,1,1,1,1,1,1,1,1,1
1,1,1,1,1,1,1,1,1,1,1,1,1,1,1,1
1,1,1,1,1,1,1,1,1,1,1,1,1,1,1,1
1,1,1,1,1,1,1,1,1,1,1,1,1,1,1,1
1,1,1,1,1,1,1,1,1,1,1,1,1,1,1,1
1,1,1,1,1,1,1,1,1,1,1,1,1,1,1,1
1,1,1,1,1,1,1,1,1,1,1,1,1,1,1,1
1,1,1,1,1,1,1,1,1,1,1,1,1,1,1,1
1,1,1,1,1,1,1,1,1,1,1,1,1,1,1,1
1,1,1,1,1,1,1,1,1,1,1,1,1,1,1,1
1,1,1,1,1,1,1,1,1,1,1,1,1,1,1,1
1,1,1,1,1,1,1,1,1,1,1,1,1,1,1,1
:endlayer
layer: 1
1,1,1,1,1,1,1,1,1,1,1,1,1,1,1,1
1,1,1,1,1,1,1,1,1,1,1,1,1,1,1,1
1,1,1,1,1,1,1,1,1,1,1,1,1,1,1,1
1,1,1,1,1,1,1,1,1,1,1,1,1,1,1,1
1,1,1,1,1,1,1,1,1,1,1,1,1,1,1,1
1,1,1,1,1,1,1,1,1,1,1,1,1,1,1,1
1,1,1,1,1,1,1,1,1,1,1,1,1,1,1,1
1,1,1,1,1,1,1,1,1,1,1,1,1,1,1,1
1,1,1,1,1,1,1,1,1,1,1,1,1,1,1,1
1,1,1,1,1,1,1,1,1,1,1,1,1,1,1,1
1,1,1,1,1,1,1,1,1,1,1,1,1,1,1,1
1,1,1,1,1,1,1,1,1,1,1,1,1,1,1,1
1,1,1,1,1,1,1,1,1,1,1,1,1,1,1,1
1,1,1,1,1,1,1,1,1,1,1,1,1,1,1,1
1,1,1,1,1,1,1,1,1,1,1,1,1,1,1,1
1,1,1,1,1,1,1,1,1,1,1,1,1,1,1,1
:endlayer
layer: 2
1,1,1,1,1,1,1,1,1,1,1,1,1,1,1,1
1,1,1,1,1,1,1,1,1,1,1,1,1,1,1,1
1,1,1,1,1,1,1,1,1,1,1,1,1,1,1,1
1,1,1,1,1,1,1,1,1,1,1,1,1,1,1,1
1,1,1,1,1,1,2,2,2,2,5,5,1,1,1,1
1,1,1,1,1,1,2,2,2,2,2,2,1,1,1,1
1,1,1,1,1,1,2,3,2,2,3,2,2,1,1,1
2,2,2,2,2,2,2,2,3,4,2,2,3,1,2,2
2,4,4,2,4,2,2,2,2,2,2,2,2,2,4,2
2,2,2,2,2,2,2,2,4,2,2,2,2,2,2,2
2,3,3,2,2,2,2,2,2,2,2,2,2,2,3,2
2,2,2,2,2,2,3,3,2,2,2,3,4,2,2,2
2,2,2,2,4,3,2,2,4,2,2,2,2,1,2,2
1,1,1,1,2,2,4,2,2,2,2,3,4,1,1,1
1,1,1,1,2,2,3,2,2,2,2,2,5,1,1,1
1,1,1,1,1,1,2,2,2,2,1,1,1,1,1,1
:endlayer
layer: 3
7,7,7,7,7,7,7,7,7,7,7,7,7,7,7,7
7,7,7,7,7,7,7,7,7,7,7,7,7,7,7,7
7,7,7,7,7,7,7,7,7,7,7,7,7,7,7,7
7,7,7,7,7,1,1,1,1,1,1,7,7,7,7,7
7,7,7,1,1,1,3,3,2,3,1,1,1,7,7,7
7,7,1,1,2,2,2,2,2,2,2,4,1,1,7,7
1,1,1,2,2,2,4,4,2,2,2,2,2,1,1,1
2,2,2,2,2,2,2,2,2,2,2,2,2,7,2,2
2,2,2,2,2,4,2,2,2,2,2,2,2,2,2,2
2,2,2,3,2,2,2,3,2,2,2,2,2,2,2,2
2,2,2,2,2,4,2,2,2,2,2,2,2,2,2,2
3,2,2,2,4,2,2,2,2,2,2,3,2,2,2,3
4,2,2,2,2,3,2,2,2,2,2,2,2,7,2,4
1,1,1,1,2,2,3,2,2,2,2,2,2,5,1,1
1,1,1,1,2,2,2,2,3,4,2,2,1,1,1,1
6,6,6,6,6,6,2,2,2,2,6,6,6,6,6,6
:endlayer
layer: 4
0,0,0,0,0,0,0,0,0,0,0,0,0,0,0,0
0,0,0,0,0,0,0,0,0,0,0,0,0,0,0,0
0,0,0,0,0,0,0,0,0,0,0,0,0,0,0,0
0,0,0,0,0,0,0,0,0,0,0,0,0,0,0,0
0,0,0,0,0,0,2,2,17,2,0,0,0,0,0,0
0,0,0,0,2,2,0,0,0,0,2,2,0,0,0,0
0,0,0,2,0,0,0,0,0,0,0,21,2,0,0,0
2,2,2,2,0,0,0,14,16,19,0,0,2,2,2,2
2,2,2,0,0,0,0,14,16,19,0,0,2,2,2,2
0,0,9,0,0,0,0,14,16,19,0,0,22,0,0,0
2,2,2,11,11,0,0,14,16,19,0,0,2,2,2,2
2,2,2,10,0,0,0,0,15,0,0,11,2,2,2,2
2,2,2,2,11,0,0,0,0,0,0,20,2,2,2,2
0,0,2,2,11,12,11,0,11,0,11,11,2,2,0,0
0,0,0,0,2,2,11,13,11,18,2,2,0,0,0,0
8,8,8,0,8,0,2,2,2,2,0,0,0,0,8,8
:endlayer
layer: 5
0,0,0,0,0,0,0,0,0,0,0,0,0,0,0,0
0,0,0,0,0,0,0,0,0,0,0,0,0,0,0,0
0,0,0,0,0,0,0,0,0,0,0,0,0,0,0,0
0,0,0,0,0,0,0,0,0,0,0,0,0,0,0,0
0,0,0,0,0,0,2,4,25,2,0,0,0,0,0,0
0,0,0,0,2,2,0,0,0,0,2,2,0,0,0,0
0,0,0,2,0,0,0,0,0,0,0,0,2,0,0,0
2,2,2,2,0,0,0,0,24,0,0,0,2,2,2,2
2,4,4,0,0,0,0,0,24,0,0,0,2,27,4,2
0,0,23,0,0,0,0,0,24,0,0,0,26,0,0,0
2,2,2,0,0,0,0,0,24,0,0,0,2,2,2,2
2,2,2,0,0,0,0,0,0,0,0,0,2,2,2,2
3,2,2,2,0,0,0,0,0,0,0,0,2,2,2,3
0,0,2,2,0,0,0,0,0,0,0,0,4,2,0,0
0,0,0,0,2,2,0,0,0,0,2,2,0,0,0,0
0,0,0,0,0,0,4,2,2,2,0,0,0,0,0,0
:endlayer
layer: 6
0,0,0,0,0,0,0,0,0,0,0,0,0,0,0,0
0,0,0,0,0,0,0,0,0,0,0,0,0,0,0,0
0,0,0,0,0,0,0,0,0,0,0,0,0,0,0,0
0,0,0,0,0,0,0,0,30,0,0,0,0,0,0,0
0,0,0,0,0,0,2,2,2,2,0,0,0,0,0,0
0,0,0,0,2,2,0,0,0,0,2,2,0,0,0,0
0,0,0,2,0,0,0,0,0,0,0,0,3,0,0,0
2,2,2,2,0,0,0,0,0,0,0,0,2,2,2,2
2,2,2,0,0,0,0,0,0,0,0,0,2,2,2,2
2,3,3,29,0,0,0,0,0,0,0,31,2,2,3,2
2,2,2,0,0,0,0,0,0,0,0,0,2,2,2,2
2,2,2,28,0,0,0,0,0,0,0,0,2,2,2,2
2,2,2,2,0,0,0,0,0,0,0,0,2,2,2,2
0,0,2,2,0,0,0,0,0,0,0,0,2,2,0,0
0,0,0,0,2,2,0,0,0,0,2,4,0,0,0,0
0,0,0,0,0,0,2,2,2,2,0,0,0,0,0,0
:endlayer
layer: 7
0,0,0,0,0,0,0,0,0,0,0,0,0,0,0,0
0,0,0,0,0,0,0,0,0,0,0,0,0,0,0,0
0,0,0,0,0,0,0,0,0,0,0,0,0,0,0,0
0,0,0,0,0,0,0,0,0,0,0,0,0,0,0,0
0,0,0,0,0,0,2,2,2,2,0,0,0,0,0,0
0,0,0,0,2,2,0,0,0,27,2,2,0,0,0,0
0,0,0,2,28,0,0,0,0,0,0,0,4,0,0,0
2,2,2,2,0,0,0,0,0,0,0,0,2,2,2,2
2,2,2,0,0,0,0,0,0,0,0,32,2,2,2,2
2,2,2,0,0,0,0,0,0,0,0,0,2,2,2,2
2,2,2,0,0,0,0,0,0,0,0,0,2,2,2,2
2,2,2,0,0,0,0,0,0,0,0,0,2,2,2,2
2,2,2,4,0,0,0,0,0,0,0,0,2,2,2,2
0,0,2,2,0,0,0,0,0,0,0,30,2,2,0,0
0,0,0,0,3,3,30,0,0,0,2,2,0,0,0,0
0,0,0,0,0,0,2,2,2,2,0,0,0,0,0,0
:endlayer
layer: 8
0,0,0,0,0,0,0,0,0,0,0,0,0,0,0,0
0,0,0,0,0,0,0,0,0,0,0,0,0,0,0,0
0,0,0,0,0,0,0,0,0,0,0,0,0,0,0,0
0,0,0,0,0,0,0,0,0,0,0,0,0,0,0,0
0,0,0,0,0,0,2,2,2,2,0,0,0,0,0,0
0,0,0,0,2,2,2,2,2,2,2,2,0,0,0,0
0,0,0,2,2,2,3,2,2,4,2,2,2,0,0,0
2,2,2,2,2,2,2,2,2,3,2,2,2,2,2,2
2,2,2,2,2,2,2,4,2,2,2,2,2,2,2,2
2,2,2,2,2,2,2,2,4,2,2,2,2,2,2,2
2,2,2,3,2,2,4,2,2,2,2,2,2,2,2,2
2,2,2,3,3,2,2,2,2,2,2,2,2,2,2,2
4,2,2,2,2,2,2,2,2,4,2,2,2,2,2,4
0,0,2,4,2,2,2,2,2,2,2,2,2,2,0,0
0,0,27,32,2,2,2,2,2,2,2,2,28,27,0,0
0,0,0,0,0,32,2,4,2,4,28,0,0,0,0,0
:endlayer
layer: 9
0,0,0,0,0,0,0,0,0,0,0,0,0,0,0,0
0,0,0,0,0,0,0,0,0,0,0,0,0,0,0,0
0,0,0,0,0,0,0,0,0,0,0,0,0,0,0,0
0,0,0,0,0,0,0,0,0,0,0,0,0,0,0,0
0,0,0,0,0,0,2,2,2,2,0,0,0,0,0,0
0,0,0,0,2,2,0,33,0,0,2,2,0,0,0,0
0,0,0,2,0,0,0,0,0,0,0,0,2,0,0,0
2,2,2,2,0,0,0,0,0,0,0,0,2,2,2,2
2,2,2,0,0,0,0,0,0,0,0,0,2,2,2,2
2,2,2,0,0,0,0,0,0,0,0,0,2,2,2,2
2,2,2,0,0,0,0,0,0,0,0,0,2,2,2,2
2,2,2,0,0,0,0,0,0,0,0,0,2,2,2,2
2,2,2,2,0,0,0,0,0,0,0,0,2,2,2,2
0,0,2,2,0,0,0,0,0,0,0,0,2,2,0,0
0,0,0,0,2,2,0,0,0,0,3,2,0,0,0,0
0,0,0,0,0,0,4,2,4,2,0,0,0,0,0,0
:endlayer
layer: 10
0,0,0,0,0,0,0,0,0,0,0,0,0,0,0,0
0,0,0,0,0,0,0,0,0,0,0,0,0,0,0,0
0,0,0,0,0,0,0,0,0,0,0,0,0,0,0,0
0,0,0,0,0,0,0,0,0,0,0,0,0,0,0,0
0,0,0,0,0,0,2,2,2,2,0,0,0,0,0,0
0,0,0,0,2,2,0,33,0,0,2,2,0,0,0,0
0,0,0,2,0,0,0,0,0,0,0,0,3,0,0,0
2,2,2,2,0,0,0,0,0,0,0,0,2,2,2,2
2,2,2,0,0,0,0,0,0,0,0,0,2,2,2,2
2,2,2,0,0,0,0,0,0,0,0,0,2,2,2,2
2,4,4,0,0,0,0,0,0,0,0,0,2,2,4,2
2,2,2,0,0,0,0,0,0,0,0,0,2,2,2,2
2,2,2,2,0,0,0,0,0,0,0,0,2,2,2,2
0,0,34,2,0,0,0,0,0,0,0,0,2,34,0,0
0,0,0,0,2,2,0,0,0,0,2,2,0,0,0,0
0,0,0,0,0,0,2,4,2,2,0,0,0,0,0,0
:endlayer
layer: 11
0,0,0,0,0,0,0,0,0,0,0,0,0,0,0,0
0,0,0,0,0,0,0,0,0,0,0,0,0,0,0,0
0,0,0,0,0,0,0,0,0,0,0,0,0,0,0,0
0,0,0,0,0,0,0,0,0,0,0,0,0,0,0,0
0,0,0,0,0,0,2,2,2,2,0,0,0,0,0,0
0,0,0,0,2,2,0,0,0,0,3,2,0,0,0,0
0,0,0,2,0,0,0,0,0,0,0,0,2,0,0,0
2,2,2,2,0,0,0,0,0,0,0,0,2,2,2,2
2,2,2,0,0,0,0,0,0,0,0,0,2,2,2,2
2,4,4,0,0,0,0,0,0,0,0,0,2,2,4,2
2,2,2,0,0,0,0,0,0,0,0,0,2,2,2,2
2,2,2,28,0,0,0,0,0,0,0,0,2,2,2,2
2,2,2,2,0,0,0,0,0,0,0,0,2,2,2,2
35,35,35,2,0,0,0,0,0,0,0,0,2,35,35,35
0,0,0,0,2,2,0,0,0,0,2,2,0,0,0,0
0,0,0,0,0,0,2,2,2,4,0,0,0,0,0,0
:endlayer
layer: 12
0,0,0,0,0,0,0,0,0,0,0,0,0,0,0,0
0,0,0,0,0,0,0,0,0,0,0,0,0,0,0,0
0,0,0,0,0,0,0,0,0,0,0,0,0,0,0,0
0,0,0,0,0,0,0,0,0,0,0,0,0,0,0,0
0,0,0,0,0,0,4,4,2,2,0,0,0,0,0,0
0,0,0,0,2,2,2,2,2,2,2,2,0,0,0,0
0,0,0,2,2,2,2,2,2,2,2,2,2,0,0,0
2,2,2,2,2,2,2,2,2,2,2,2,2,2,2,2
0,2,2,2,2,2,2,2,2,3,2,2,2,2,2,0
0,2,2,2,2,2,2,2,2,4,2,2,2,2,2,0
0,0,36,2,2,2,4,2,2,2,2,2,2,2,37,0
0,2,2,2,2,2,2,2,2,3,2,3,2,2,2,0
0,0,2,4,2,2,2,2,2,2,2,2,2,2,0,0
2,2,2,2,2,2,2,2,2,2,2,2,2,2,2,2
0,0,0,0,2,2,2,2,2,2,2,2,0,0,0,0
0,0,0,0,0,0,2,4,4,2,0,0,0,0,0,0
:endlayer
layer: 13
0,0,0,0,0,0,0,0,0,0,0,0,0,0,0,0
0,0,0,0,0,0,0,0,0,0,0,0,0,0,0,0
0,0,0,0,0,0,0,0,0,0,0,0,0,0,0,0
0,0,0,0,0,0,0,0,0,0,0,0,0,0,0,0
0,0,0,0,0,0,2,2,2,2,0,0,0,0,0,0
0,0,0,0,2,2,0,0,0,0,2,2,0,0,0,0
0,0,0,2,0,0,0,0,0,0,0,0,2,0,0,0
0,37,2,2,2,2,0,0,0,0,0,0,2,2,37,0
0,2,2,2,2,2,0,0,0,0,0,0,2,2,2,0
0,2,2,0,34,34,0,0,0,0,0,0,2,2,2,0
0,0,0,0,0,0,0,0,0,0,0,0,0,0,0,0
0,2,2,0,0,0,0,0,0,0,0,0,2,2,2,0
0,0,2,2,0,0,0,0,0,0,0,0,2,2,0,0
0,37,37,2,0,0,0,0,0,0,0,0,2,37,0,37
0,0,0,0,2,2,0,0,0,0,3,2,0,0,0,0
0,0,0,0,0,0,2,2,2,3,0,0,0,0,0,0
:endlayer
layer: 14
0,0,0,0,0,0,0,0,0,0,0,0,0,0,0,0
0,0,0,0,0,0,0,0,0,0,0,0,0,0,0,0
0,0,0,0,0,0,0,0,0,0,0,0,0,0,0,0
0,0,0,0,0,0,0,0,0,0,0,0,0,0,0,0
0,0,0,0,0,0,2,2,0,2,0,0,0,0,0,0
0,0,0,0,2,2,0,0,0,0,4,2,0,0,0,0
0,0,0,2,0,0,0,0,0,0,0,0,4,0,0,0
0,0,2,2,2,2,0,0,0,0,0,0,2,2,0,0
0,2,2,0,34,34,0,0,0,0,0,0,2,2,2,0
0,2,2,0,0,0,0,0,0,0,0,0,2,2,2,0
0,0,0,0,0,0,0,0,0,0,0,0,0,0,0,0
0,2,2,0,0,0,0,0,0,0,0,0,2,2,2,0
0,0,2,2,0,0,0,0,0,0,0,0,2,2,0,0
0,0,0,2,0,0,0,0,0,0,0,0,4,0,0,0
0,0,0,0,2,2,0,0,0,0,2,2,0,0,0,0
0,0,0,0,0,0,2,2,0,2,0,0,0,0,0,0
:endlayer
layer: 15
0,0,0,0,0,0,0,0,0,0,0,0,0,0,0,0
0,0,0,0,0,0,0,0,0,0,0,0,0,0,0,0
0,0,0,0,0,0,0,0,0,0,0,0,0,0,0,0
0,0,0,0,0,0,0,0,0,0,0,0,0,0,0,0
0,0,0,0,0,0,2,4,0,2,0,0,0,0,0,0
0,0,0,0,2,2,28,0,0,0,2,2,0,0,0,0
0,0,0,2,2,2,0,0,0,0,0,0,2,0,0,0
0,0,2,2,34,34,0,0,0,0,0,0,2,2,0,0
0,4,4,0,0,0,0,0,0,0,0,0,2,2,4,0
0,2,2,0,0,0,0,0,0,0,0,0,2,2,2,0
32,2,2,0,0,0,0,0,0,0,0,32,2,2,2,28
0,2,2,28,0,0,0,0,0,0,0,0,2,2,2,0
0,0,2,2,0,0,0,0,0,0,0,0,2,2,0,0
0,0,0,2,0,0,0,0,0,0,30,0,2,0,0,0
0,0,0,0,2,2,0,0,0,0,2,2,0,0,0,0
0,0,0,0,0,0,2,2,0,2,0,0,0,0,0,0
:endlayer
layer: 16
0,0,0,0,0,0,0,0,0,0,0,0,0,0,0,0
0,0,0,0,0,0,0,0,0,0,0,0,0,0,0,0
0,0,0,0,0,0,0,0,0,0,0,0,0,0,0,0
0,0,0,0,0,0,0,0,0,0,0,0,0,0,0,0
0,0,0,0,0,0,2,2,2,2,0,0,0,0,0,0
0,0,0,0,2,2,2,2,2,2,2,2,0,0,0,0
39,39,39,2,34,34,2,2,2,2,4,2,2,39,39,39
0,0,2,2,0,0,2,2,2,2,2,2,2,2,39,0
0,2,2,2,0,0,2,2,2,2,2,3,2,2,2,0
0,2,2,2,0,0,2,2,2,4,2,4,2,2,2,0
0,2,2,4,2,2,2,2,2,2,2,2,2,2,2,0
0,2,2,2,2,2,2,2,2,2,2,2,2,2,2,0
0,0,2,2,2,2,2,2,3,2,2,2,2,2,30,0
38,38,38,3,2,3,3,2,2,2,2,4,3,11,38,38
0,0,0,0,2,2,2,4,2,2,2,2,0,0,0,0
0,0,0,0,0,0,2,2,2,2,0,0,0,0,0,0
:endlayer
layer: 17
0,0,0,0,0,0,0,0,0,0,0,0,0,0,0,0
0,0,0,0,0,0,0,0,0,0,0,0,0,0,0,0
0,0,0,0,0,0,0,0,0,0,0,0,0,0,0,0
0,0,0,0,0,0,0,0,0,0,0,0,0,0,0,0
0,0,0,0,0,0,2,2,2,2,0,0,0,0,0,0
0,0,0,0,2,2,2,0,0,0,2,2,0,0,0,0
0,0,0,2,0,0,0,0,0,0,0,0,2,0,0,0
15,15,2,2,0,0,0,0,0,0,0,0,2,2,0,15
40,2,2,0,0,0,2,0,0,0,0,0,2,2,2,40
40,2,2,0,0,0,2,0,0,0,0,0,2,2,2,40
40,2,2,0,0,0,34,0,0,0,0,0,2,2,2,40
40,2,2,0,0,0,0,0,0,0,0,0,2,2,2,40
38,38,2,2,0,0,0,0,0,0,0,0,2,2,38,38
0,0,0,2,0,0,0,0,0,0,0,0,2,0,0,0
0,0,0,0,2,2,0,0,0,0,2,2,0,0,0,0
0,0,0,0,0,0,2,2,4,2,0,0,0,0,0,0
:endlayer
layer: 18
0,0,0,0,0,0,0,0,0,0,0,0,0,0,0,0
0,0,0,0,0,0,0,0,0,0,0,0,0,0,0,0
0,0,0,0,0,0,0,0,0,0,0,0,0,0,0,0
0,0,0,0,0,0,0,0,0,0,0,0,0,0,0,0
0,0,0,0,0,0,2,2,2,2,0,0,0,0,0,0
0,0,0,0,2,2,2,0,0,0,2,2,0,0,0,0
0,0,0,2,0,0,0,0,0,0,0,0,2,0,0,0
0,0,2,2,0,0,0,0,0,0,0,0,2,2,0,0
15,2,2,0,0,0,2,0,0,0,0,0,2,2,2,15
40,2,2,0,0,0,34,0,0,0,0,0,2,2,2,40
40,2,2,0,0,0,0,0,0,0,0,0,2,2,2,40
38,2,2,0,0,0,0,0,0,0,0,0,2,2,2,38
0,0,2,2,0,0,0,0,0,0,0,0,2,2,0,0
0,0,0,2,0,0,0,0,0,0,0,0,2,0,0,0
0,0,0,0,2,2,0,0,0,0,2,2,0,0,0,0
0,0,0,0,0,0,3,2,0,2,0,0,0,0,0,0
:endlayer
layer: 19
0,0,0,0,0,0,0,0,0,0,0,0,0,0,0,0
0,0,0,0,0,0,0,0,0,0,0,0,0,0,0,0
0,0,0,0,0,0,0,0,0,0,0,0,0,0,0,0
0,0,0,0,0,0,0,0,0,0,0,0,0,0,0,0
0,0,0,0,0,0,2,3,2,2,0,0,0,0,0,0
0,0,0,0,2,2,2,0,0,32,2,2,0,0,0,0
0,0,0,2,0,0,0,0,0,0,27,0,4,0,0,0
0,0,2,2,28,0,0,0,0,0,0,0,2,2,0,0
0,2,2,0,0,0,34,0,0,0,0,0,2,2,2,0
32,2,2,0,0,0,0,0,0,0,0,0,2,2,2,0
0,2,2,0,0,0,0,0,0,0,0,0,2,2,2,0
0,2,2,28,0,0,0,0,0,0,0,0,2,2,2,0
0,0,2,2,0,0,0,0,0,0,0,0,2,2,0,0
0,0,0,2,0,0,0,0,0,0,30,0,2,0,0,0
0,0,0,0,2,2,0,0,0,0,2,2,0,0,0,0
0,0,0,0,0,0,2,2,0,2,0,0,0,0,0,0
:endlayer
layer: 20
0,0,0,0,0,0,0,0,0,0,0,0,0,0,0,0
0,0,0,0,0,0,0,0,0,0,0,0,0,0,0,0
0,0,0,0,0,0,0,0,0,0,0,0,0,0,0,0
0,0,0,0,0,0,0,0,0,0,0,0,0,0,0,0
0,0,0,0,0,0,2,2,2,3,0,0,0,0,0,0
0,0,0,0,2,2,2,2,2,2,2,2,0,0,0,0
0,0,0,2,2,3,2,2,2,2,4,2,3,0,0,0
0,0,2,2,2,2,34,2,2,2,2,2,2,2,0,0
0,2,2,2,2,2,0,2,2,2,2,2,2,2,2,0
0,4,4,2,2,2,0,2,2,2,2,2,2,2,4,0
0,2,2,2,2,2,0,2,2,2,2,2,2,2,2,0
0,2,2,2,2,2,2,2,2,2,2,2,2,2,2,0
0,0,2,2,2,2,4,2,2,2,4,2,2,2,0,0
0,0,0,2,2,2,2,2,2,4,2,2,2,0,0,0
0,0,0,0,3,2,2,2,2,2,2,2,0,0,0,0
0,0,0,0,0,0,2,2,2,2,0,0,0,0,0,0
:endlayer
layer: 21
0,0,0,0,0,0,0,0,0,0,0,0,0,0,0,0
0,0,0,0,0,0,0,0,0,0,0,0,0,0,0,0
0,0,0,0,0,0,0,0,0,0,0,0,0,0,0,0
0,0,0,0,0,0,0,0,0,0,0,0,0,0,0,0
0,0,0,0,0,0,2,2,2,2,0,0,0,0,0,0
0,0,0,0,2,2,0,0,0,0,2,2,0,0,0,0
0,0,0,2,0,0,0,0,0,0,0,0,2,0,0,0
0,0,2,2,0,0,0,0,0,0,0,0,2,2,0,0
0,2,2,0,0,0,0,2,0,0,0,0,2,2,2,0
0,2,2,0,0,0,0,2,0,0,0,0,2,2,2,0
0,2,2,0,0,0,0,34,0,0,0,0,2,2,2,0
0,2,2,0,0,0,0,0,0,0,0,0,2,2,2,0
0,0,2,2,0,0,0,0,0,0,0,0,2,2,0,0
0,0,0,2,0,0,0,0,0,0,0,0,2,0,0,0
0,0,0,0,3,2,0,0,0,0,2,2,0,0,0,0
0,0,0,0,0,0,2,2,2,4,0,0,0,0,0,0
:endlayer
layer: 22
0,0,0,0,0,0,0,0,0,0,0,0,0,0,0,0
0,0,0,0,0,0,0,0,0,0,0,0,0,0,0,0
0,0,0,0,0,0,0,0,0,0,0,0,0,0,0,0
0,0,0,0,0,0,0,0,0,0,0,0,0,0,0,0
0,0,0,0,0,0,2,2,0,2,0,0,0,0,0,0
0,0,0,0,2,2,0,0,0,0,2,2,0,0,0,0
0,0,0,2,0,0,0,0,0,0,0,0,2,0,0,0
0,0,2,2,0,0,0,0,0,0,0,0,2,2,0,0
0,2,2,0,0,0,0,2,0,0,0,0,2,2,2,0
0,2,2,0,0,0,0,34,0,0,0,0,2,2,2,0
0,0,0,0,0,0,0,0,0,0,0,0,2,2,0,0
0,2,2,0,0,0,0,0,0,0,0,0,2,2,2,0
0,0,2,2,0,0,0,0,0,0,0,0,2,2,0,0
0,0,0,2,0,0,0,0,0,0,0,0,2,0,0,0
0,0,0,0,2,2,0,0,0,0,2,2,0,0,0,0
0,0,0,0,0,0,2,2,0,2,0,0,0,0,0,0
:endlayer
layer: 23
0,0,0,0,0,0,0,0,0,0,0,0,0,0,0,0
0,0,0,0,0,0,0,0,0,0,0,0,0,0,0,0
0,0,0,0,0,0,0,0,0,0,0,0,0,0,0,0
0,0,0,0,0,0,0,0,0,0,0,0,0,0,0,0
0,0,0,0,0,0,2,2,0,2,0,0,0,0,0,0
0,0,0,0,2,2,0,27,0,0,2,2,0,0,0,0
0,0,0,2,0,0,0,0,0,0,27,0,2,0,0,0
0,0,2,2,0,0,0,0,0,0,0,0,2,2,0,0
0,2,2,0,0,0,0,34,0,0,0,0,2,2,2,0
0,2,2,0,0,0,0,0,0,0,0,0,2,2,2,0
0,0,0,0,0,0,0,0,0,0,0,0,2,2,0,0
0,4,4,28,0,0,0,0,0,0,0,0,2,2,4,0
0,0,2,3,0,0,0,0,0,0,0,0,2,2,0,0
0,0,0,2,0,30,0,0,0,0,30,0,2,0,0,0
0,0,0,0,2,3,0,0,0,0,2,3,0,0,0,0
0,0,0,0,0,0,2,2,0,3,0,0,0,0,0,0
:endlayer
layer: 24
0,0,0,0,0,0,0,0,0,0,0,0,0,0,0,0
0,0,0,0,0,0,0,0,0,0,0,0,0,0,0,0
0,0,0,0,0,0,0,0,0,0,0,0,0,0,0,0
0,0,0,0,0,0,0,0,0,0,0,0,0,0,0,0
0,0,0,0,0,0,2,2,2,2,0,0,0,0,0,0
0,0,0,0,3,2,2,2,2,2,2,2,0,0,0,0
0,0,0,2,3,2,2,2,2,2,2,2,2,0,0,0
0,0,2,2,2,2,2,34,2,2,2,2,2,2,0,0
0,2,2,2,2,2,3,0,2,2,2,4,2,2,2,0
0,2,2,2,2,2,4,0,2,2,2,2,2,2,2,0
0,2,2,2,2,2,4,0,2,2,2,2,2,2,2,0
0,3,3,2,2,2,2,2,2,2,2,2,2,2,3,0
0,0,2,2,2,2,2,2,2,2,2,2,2,2,0,0
0,0,0,2,4,3,2,2,2,2,2,2,2,0,0,0
0,0,0,0,2,2,2,2,2,3,2,2,0,0,0,0
0,0,0,0,0,0,2,2,2,2,0,0,0,0,0,0
:endlayer
layer: 25
0,0,0,0,0,0,0,0,0,0,0,0,0,0,0,0
0,0,0,0,0,0,0,0,0,0,0,0,0,0,0,0
0,0,0,0,0,0,0,0,0,0,0,0,0,0,0,0
0,0,0,0,0,0,0,0,0,0,0,0,0,0,0,0
0,0,0,0,0,0,2,2,2,2,0,0,0,0,0,0
0,0,0,0,2,2,0,0,0,0,2,2,0,0,0,0
0,0,0,2,0,0,0,0,0,0,0,0,2,0,0,0
0,0,2,2,0,0,0,0,0,0,0,0,2,2,0,0
0,2,0,0,0,0,0,0,0,0,0,0,0,0,2,0
0,2,0,0,0,0,0,0,0,0,0,0,0,0,2,0
0,3,0,0,0,0,0,0,0,0,0,0,0,0,3,0
0,2,2,0,0,0,0,0,0,0,0,0,0,0,2,0
0,0,2,0,0,0,0,0,0,0,0,0,0,2,0,0
0,0,0,2,0,0,0,0,0,0,0,0,2,0,0,0
0,0,0,0,2,2,0,0,0,0,2,2,0,0,0,0
0,0,0,0,0,0,2,2,2,2,0,0,0,0,0,0
:endlayer
layer: 26
0,0,0,0,0,0,0,0,0,0,0,0,0,0,0,0
0,0,0,0,0,0,0,0,0,0,0,0,0,0,0,0
0,0,0,0,0,0,0,0,0,0,0,0,0,0,0,0
0,0,0,0,0,0,0,0,0,0,0,0,0,0,0,0
0,0,0,0,0,0,0,2,0,2,0,0,0,0,0,0
0,0,0,0,0,2,0,0,0,0,0,2,0,0,0,0
0,0,0,2,0,0,0,0,0,0,0,0,0,0,0,0
0,0,0,0,0,0,0,0,0,0,0,0,0,2,0,0
0,2,0,0,0,0,0,0,0,0,0,0,0,0,0,0
0,0,0,0,0,0,0,0,0,0,0,0,0,0,2,0
0,2,0,0,0,0,0,0,0,0,0,0,0,0,0,0
0,0,0,0,0,0,0,0,0,0,0,0,0,0,2,0
0,0,2,0,0,0,0,0,0,0,0,0,0,0,0,0
0,0,0,0,0,0,0,0,0,0,0,0,2,0,0,0
0,0,0,0,2,0,0,0,0,0,2,0,0,0,0,0
0,0,0,0,0,0,2,0,2,0,0,0,0,0,0,0
:endlayer
layer: 27
0,0,0,0,0,0,0,0,0,0,0,0,0,0,0,0
0,0,0,0,0,0,0,0,0,0,0,0,0,0,0,0
0,0,0,0,0,0,0,0,0,0,0,0,0,0,0,0
0,0,0,0,0,0,0,0,0,0,0,0,0,0,0,0
0,0,0,0,0,0,0,0,0,0,0,0,0,0,0,0
0,0,0,0,0,41,0,0,0,0,0,41,0,0,0,0
0,0,0,0,0,0,0,0,0,0,0,0,0,0,0,0
0,0,0,0,0,0,0,0,0,0,0,0,0,0,0,0
0,0,0,0,0,0,0,0,0,0,0,0,0,0,0,0
0,0,0,0,0,0,0,0,0,0,0,0,0,0,0,0
0,41,0,0,0,0,0,0,0,0,0,0,0,0,0,0
0,0,0,0,0,0,0,0,0,0,0,0,0,0,41,0
0,0,0,0,0,0,0,0,0,0,0,0,0,0,0,0
0,0,0,0,0,0,0,0,0,0,0,0,0,0,0,0
0,0,0,0,41,0,0,0,0,0,41,0,0,0,0,0
0,0,0,0,0,0,0,0,0,0,0,0,0,0,0,0
:endlayer
layer: 28
0,0,0,0,0,0,0,0,0,0,0,0,0,0,0,0
0,0,0,0,0,0,0,0,0,0,0,0,0,0,0,0
0,0,0,0,0,0,0,0,0,0,0,0,0,0,0,0
0,0,0,0,0,0,0,0,0,0,0,0,0,0,0,0
0,0,0,0,0,0,0,0,0,0,0,0,0,0,0,0
0,0,0,0,0,0,0,0,0,0,0,0,0,0,0,0
0,0,0,0,0,0,0,0,0,0,0,0,0,0,0,0
0,0,0,0,0,0,0,0,0,0,0,0,0,0,0,0
0,0,0,0,0,0,0,0,0,0,0,0,0,0,0,0
0,0,0,0,0,0,0,0,0,0,0,0,0,0,0,0
0,0,0,0,0,0,0,0,0,0,0,0,0,0,0,0
0,0,0,0,0,0,0,0,0,0,0,0,0,0,0,0
0,0,0,0,0,0,0,0,0,0,0,0,0,0,0,0
0,0,0,0,0,0,0,0,0,0,0,0,0,0,0,0
0,0,0,0,0,0,0,0,0,0,0,0,0,0,0,0
0,0,0,0,0,0,0,0,0,0,0,0,0,0,0,0
:endlayer
layer: 29
0,0,0,0,0,0,0,0,0,0,0,0,0,0,0,0
0,0,0,0,0,0,0,0,0,0,0,0,0,0,0,0
0,0,0,0,0,0,0,0,0,0,0,0,0,0,0,0
0,0,0,0,0,0,0,0,0,0,0,0,0,0,0,0
0,0,0,0,0,0,0,0,0,0,0,0,0,0,0,0
0,0,0,0,0,0,0,0,0,0,0,0,0,0,0,0
0,0,0,0,0,0,0,0,0,0,0,0,0,0,0,0
0,0,0,0,0,0,0,0,0,0,0,0,0,0,0,0
0,0,0,0,0,0,0,0,0,0,0,0,0,0,0,0
0,0,0,0,0,0,0,0,0,0,0,0,0,0,0,0
0,0,0,0,0,0,0,0,0,0,0,0,0,0,0,0
0,0,0,0,0,0,0,0,0,0,0,0,0,0,0,0
0,0,0,0,0,0,0,0,0,0,0,0,0,0,0,0
0,0,0,0,0,0,0,0,0,0,0,0,0,0,0,0
0,0,0,0,0,0,0,0,0,0,0,0,0,0,0,0
0,0,0,0,0,0,0,0,0,0,0,0,0,0,0,0
:endlayer
layer: 30
0,0,0,0,0,0,0,0,0,0,0,0,0,0,0,0
0,0,0,0,0,0,0,0,0,0,0,0,0,0,0,0
0,0,0,0,0,0,0,0,0,0,0,0,0,0,0,0
0,0,0,0,0,0,0,0,0,0,0,0,0,0,0,0
0,0,0,0,0,0,0,0,0,0,0,0,0,0,0,0
0,0,0,0,0,0,0,0,0,0,0,0,0,0,0,0
0,0,0,0,0,0,0,0,0,0,0,0,0,0,0,0
0,0,0,0,0,0,0,0,0,0,0,0,0,0,0,0
0,0,0,0,0,0,0,0,0,0,0,0,0,0,0,0
0,0,0,0,0,0,0,0,0,0,0,0,0,0,0,0
0,0,0,0,0,0,0,0,0,0,0,0,0,0,0,0
0,0,0,0,0,0,0,0,0,0,0,0,0,0,0,0
0,0,0,0,0,0,0,0,0,0,0,0,0,0,0,0
0,0,0,0,0,0,0,0,0,0,0,0,0,0,0,0
0,0,0,0,0,0,0,0,0,0,0,0,0,0,0,0
0,0,0,0,0,0,0,0,0,0,0,0,0,0,0,0
:endlayer
layer: 31
0,0,0,0,0,0,0,0,0,0,0,0,0,0,0,0
0,0,0,0,0,0,0,0,0,0,0,0,0,0,0,0
0,0,0,0,0,0,0,0,0,0,0,0,0,0,0,0
0,0,0,0,0,0,0,0,0,0,0,0,0,0,0,0
0,0,0,0,0,0,0,0,0,0,0,0,0,0,0,0
0,0,0,0,0,0,0,0,0,0,0,0,0,0,0,0
0,0,0,0,0,0,0,0,0,0,0,0,0,0,0,0
0,0,0,0,0,0,0,0,0,0,0,0,0,0,0,0
0,0,0,0,0,0,0,0,0,0,0,0,0,0,0,0
0,0,0,0,0,0,0,0,0,0,0,0,0,0,0,0
0,0,0,0,0,0,0,0,0,0,0,0,0,0,0,0
0,0,0,0,0,0,0,0,0,0,0,0,0,0,0,0
0,0,0,0,0,0,0,0,0,0,0,0,0,0,0,0
0,0,0,0,0,0,0,0,0,0,0,0,0,0,0,0
0,0,0,0,0,0,0,0,0,0,0,0,0,0,0,0
0,0,0,0,0,0,0,0,0,0,0,0,0,0,0,0
:endlayer
layer: 32
0,0,0,0,0,0,0,0,0,0,0,0,0,0,0,0
0,0,0,0,0,0,0,0,0,0,0,0,0,0,0,0
0,0,0,0,0,0,0,0,0,0,0,0,0,0,0,0
0,0,0,0,0,0,0,0,0,0,0,0,0,0,0,0
0,0,0,0,0,0,0,0,0,0,0,0,0,0,0,0
0,0,0,0,0,0,0,0,0,0,0,0,0,0,0,0
0,0,0,0,0,0,0,0,0,0,0,0,0,0,0,0
0,0,0,0,0,0,0,0,0,0,0,0,0,0,0,0
0,0,0,0,0,0,0,0,0,0,0,0,0,0,0,0
0,0,0,0,0,0,0,0,0,0,0,0,0,0,0,0
0,0,0,0,0,0,0,0,0,0,0,0,0,0,0,0
0,0,0,0,0,0,0,0,0,0,0,0,0,0,0,0
0,0,0,0,0,0,0,0,0,0,0,0,0,0,0,0
0,0,0,0,0,0,0,0,0,0,0,0,0,0,0,0
0,0,0,0,0,0,0,0,0,0,0,0,0,0,0,0
0,0,0,0,0,0,0,0,0,0,0,0,0,0,0,0
:endlayer
layer: 33
0,0,0,0,0,0,0,0,0,0,0,0,0,0,0,0
0,0,0,0,0,0,0,0,0,0,0,0,0,0,0,0
0,0,0,0,0,0,0,0,0,0,0,0,0,0,0,0
0,0,0,0,0,0,0,0,0,0,0,0,0,0,0,0
0,0,0,0,0,0,0,0,0,0,0,0,0,0,0,0
0,0,0,0,0,0,0,0,0,0,0,0,0,0,0,0
0,0,0,0,0,0,0,0,0,0,0,0,0,0,0,0
0,0,0,0,0,0,0,0,0,0,0,0,0,0,0,0
0,0,0,0,0,0,0,0,0,0,0,0,0,0,0,0
0,0,0,0,0,0,0,0,0,0,0,0,0,0,0,0
0,0,0,0,0,0,0,0,0,0,0,0,0,0,0,0
0,0,0,0,0,0,0,0,0,0,0,0,0,0,0,0
0,0,0,0,0,0,0,0,0,0,0,0,0,0,0,0
0,0,0,0,0,0,0,0,0,0,0,0,0,0,0,0
0,0,0,0,0,0,0,0,0,0,0,0,0,0,0,0
0,0,0,0,0,0,0,0,0,0,0,0,0,0,0,0
:endlayer
layer: 34
0,0,0,0,0,0,0,0,0,0,0,0,0,0,0,0
0,0,0,0,0,0,0,0,0,0,0,0,0,0,0,0
0,0,0,0,0,0,0,0,0,0,0,0,0,0,0,0
0,0,0,0,0,0,0,0,0,0,0,0,0,0,0,0
0,0,0,0,0,0,0,0,0,0,0,0,0,0,0,0
0,0,0,0,0,0,0,0,0,0,0,0,0,0,0,0
0,0,0,0,0,0,0,0,0,0,0,0,0,0,0,0
0,0,0,0,0,0,0,0,0,0,0,0,0,0,0,0
0,0,0,0,0,0,0,0,0,0,0,0,0,0,0,0
0,0,0,0,0,0,0,0,0,0,0,0,0,0,0,0
0,0,0,0,0,0,0,0,0,0,0,0,0,0,0,0
0,0,0,0,0,0,0,0,0,0,0,0,0,0,0,0
0,0,0,0,0,0,0,0,0,0,0,0,0,0,0,0
0,0,0,0,0,0,0,0,0,0,0,0,0,0,0,0
0,0,0,0,0,0,0,0,0,0,0,0,0,0,0,0
0,0,0,0,0,0,0,0,0,0,0,0,0,0,0,0
:endlayer
layer: 35
0,0,0,0,0,0,0,0,0,0,0,0,0,0,0,0
0,0,0,0,0,0,0,0,0,0,0,0,0,0,0,0
0,0,0,0,0,0,0,0,0,0,0,0,0,0,0,0
0,0,0,0,0,0,0,0,0,0,0,0,0,0,0,0
0,0,0,0,0,0,0,0,0,0,0,0,0,0,0,0
0,0,0,0,0,0,0,0,0,0,0,0,0,0,0,0
0,0,0,0,0,0,0,0,0,0,0,0,0,0,0,0
0,0,0,0,0,0,0,0,0,0,0,0,0,0,0,0
0,0,0,0,0,0,0,0,0,0,0,0,0,0,0,0
0,0,0,0,0,0,0,0,0,0,0,0,0,0,0,0
0,0,0,0,0,0,0,0,0,0,0,0,0,0,0,0
0,0,0,0,0,0,0,0,0,0,0,0,0,0,0,0
0,0,0,0,0,0,0,0,0,0,0,0,0,0,0,0
0,0,0,0,0,0,0,0,0,0,0,0,0,0,0,0
0,0,0,0,0,0,0,0,0,0,0,0,0,0,0,0
0,0,0,0,0,0,0,0,0,0,0,0,0,0,0,0
:endlayer
layer: 36
0,0,0,0,0,0,0,0,0,0,0,0,0,0,0,0
0,0,0,0,0,0,0,0,0,0,0,0,0,0,0,0
0,0,0,0,0,0,0,0,0,0,0,0,0,0,0,0
0,0,0,0,0,0,0,0,0,0,0,0,0,0,0,0
0,0,0,0,0,0,0,0,0,0,0,0,0,0,0,0
0,0,0,0,0,0,0,0,0,0,0,0,0,0,0,0
0,0,0,0,0,0,0,0,0,0,0,0,0,0,0,0
0,0,0,0,0,0,0,0,0,0,0,0,0,0,0,0
0,0,0,0,0,0,0,0,0,0,0,0,0,0,0,0
0,0,0,0,0,0,0,0,0,0,0,0,0,0,0,0
0,0,0,0,0,0,0,0,0,0,0,0,0,0,0,0
0,0,0,0,0,0,0,0,0,0,0,0,0,0,0,0
0,0,0,0,0,0,0,0,0,0,0,0,0,0,0,0
0,0,0,0,0,0,0,0,0,0,0,0,0,0,0,0
0,0,0,0,0,0,0,0,0,0,0,0,0,0,0,0
0,0,0,0,0,0,0,0,0,0,0,0,0,0,0,0
:endlayer
layer: 37
0,0,0,0,0,0,0,0,0,0,0,0,0,0,0,0
0,0,0,0,0,0,0,0,0,0,0,0,0,0,0,0
0,0,0,0,0,0,0,0,0,0,0,0,0,0,0,0
0,0,0,0,0,0,0,0,0,0,0,0,0,0,0,0
0,0,0,0,0,0,0,0,0,0,0,0,0,0,0,0
0,0,0,0,0,0,0,0,0,0,0,0,0,0,0,0
0,0,0,0,0,0,0,0,0,0,0,0,0,0,0,0
0,0,0,0,0,0,0,0,0,0,0,0,0,0,0,0
0,0,0,0,0,0,0,0,0,0,0,0,0,0,0,0
0,0,0,0,0,0,0,0,0,0,0,0,0,0,0,0
0,0,0,0,0,0,0,0,0,0,0,0,0,0,0,0
0,0,0,0,0,0,0,0,0,0,0,0,0,0,0,0
0,0,0,0,0,0,0,0,0,0,0,0,0,0,0,0
0,0,0,0,0,0,0,0,0,0,0,0,0,0,0,0
0,0,0,0,0,0,0,0,0,0,0,0,0,0,0,0
0,0,0,0,0,0,0,0,0,0,0,0,0,0,0,0
:endlayer
layer: 38
0,0,0,0,0,0,0,0,0,0,0,0,0,0,0,0
0,0,0,0,0,0,0,0,0,0,0,0,0,0,0,0
0,0,0,0,0,0,0,0,0,0,0,0,0,0,0,0
0,0,0,0,0,0,0,0,0,0,0,0,0,0,0,0
0,0,0,0,0,0,0,0,0,0,0,0,0,0,0,0
0,0,0,0,0,0,0,0,0,0,0,0,0,0,0,0
0,0,0,0,0,0,0,0,0,0,0,0,0,0,0,0
0,0,0,0,0,0,0,0,0,0,0,0,0,0,0,0
0,0,0,0,0,0,0,0,0,0,0,0,0,0,0,0
0,0,0,0,0,0,0,0,0,0,0,0,0,0,0,0
0,0,0,0,0,0,0,0,0,0,0,0,0,0,0,0
0,0,0,0,0,0,0,0,0,0,0,0,0,0,0,0
0,0,0,0,0,0,0,0,0,0,0,0,0,0,0,0
0,0,0,0,0,0,0,0,0,0,0,0,0,0,0,0
0,0,0,0,0,0,0,0,0,0,0,0,0,0,0,0
0,0,0,0,0,0,0,0,0,0,0,0,0,0,0,0
:endlayer
layer: 39
0,0,0,0,0,0,0,0,0,0,0,0,0,0,0,0
0,0,0,0,0,0,0,0,0,0,0,0,0,0,0,0
0,0,0,0,0,0,0,0,0,0,0,0,0,0,0,0
0,0,0,0,0,0,0,0,0,0,0,0,0,0,0,0
0,0,0,0,0,0,0,0,0,0,0,0,0,0,0,0
0,0,0,0,0,0,0,0,0,0,0,0,0,0,0,0
0,0,0,0,0,0,0,0,0,0,0,0,0,0,0,0
0,0,0,0,0,0,0,0,0,0,0,0,0,0,0,0
0,0,0,0,0,0,0,0,0,0,0,0,0,0,0,0
0,0,0,0,0,0,0,0,0,0,0,0,0,0,0,0
0,0,0,0,0,0,0,0,0,0,0,0,0,0,0,0
0,0,0,0,0,0,0,0,0,0,0,0,0,0,0,0
0,0,0,0,0,0,0,0,0,0,0,0,0,0,0,0
0,0,0,0,0,0,0,0,0,0,0,0,0,0,0,0
0,0,0,0,0,0,0,0,0,0,0,0,0,0,0,0
0,0,0,0,0,0,0,0,0,0,0,0,0,0,0,0
:endlayer
layer: 40
0,0,0,0,0,0,0,0,0,0,0,0,0,0,0,0
0,0,0,0,0,0,0,0,0,0,0,0,0,0,0,0
0,0,0,0,0,0,0,0,0,0,0,0,0,0,0,0
0,0,0,0,0,0,0,0,0,0,0,0,0,0,0,0
0,0,0,0,0,0,0,0,0,0,0,0,0,0,0,0
0,0,0,0,0,0,0,0,0,0,0,0,0,0,0,0
0,0,0,0,0,0,0,0,0,0,0,0,0,0,0,0
0,0,0,0,0,0,0,0,0,0,0,0,0,0,0,0
0,0,0,0,0,0,0,0,0,0,0,0,0,0,0,0
0,0,0,0,0,0,0,0,0,0,0,0,0,0,0,0
0,0,0,0,0,0,0,0,0,0,0,0,0,0,0,0
0,0,0,0,0,0,0,0,0,0,0,0,0,0,0,0
0,0,0,0,0,0,0,0,0,0,0,0,0,0,0,0
0,0,0,0,0,0,0,0,0,0,0,0,0,0,0,0
0,0,0,0,0,0,0,0,0,0,0,0,0,0,0,0
0,0,0,0,0,0,0,0,0,0,0,0,0,0,0,0
:endlayer
layer: 41
0,0,0,0,0,0,0,0,0,0,0,0,0,0,0,0
0,0,0,0,0,0,0,0,0,0,0,0,0,0,0,0
0,0,0,0,0,0,0,0,0,0,0,0,0,0,0,0
0,0,0,0,0,0,0,0,0,0,0,0,0,0,0,0
0,0,0,0,0,0,0,0,0,0,0,0,0,0,0,0
0,0,0,0,0,0,0,0,0,0,0,0,0,0,0,0
0,0,0,0,0,0,0,0,0,0,0,0,0,0,0,0
0,0,0,0,0,0,0,0,0,0,0,0,0,0,0,0
0,0,0,0,0,0,0,0,0,0,0,0,0,0,0,0
0,0,0,0,0,0,0,0,0,0,0,0,0,0,0,0
0,0,0,0,0,0,0,0,0,0,0,0,0,0,0,0
0,0,0,0,0,0,0,0,0,0,0,0,0,0,0,0
0,0,0,0,0,0,0,0,0,0,0,0,0,0,0,0
0,0,0,0,0,0,0,0,0,0,0,0,0,0,0,0
0,0,0,0,0,0,0,0,0,0,0,0,0,0,0,0
0,0,0,0,0,0,0,0,0,0,0,0,0,0,0,0
:endlayer
layer: 42
0,0,0,0,0,0,0,0,0,0,0,0,0,0,0,0
0,0,0,0,0,0,0,0,0,0,0,0,0,0,0,0
0,0,0,0,0,0,0,0,0,0,0,0,0,0,0,0
0,0,0,0,0,0,0,0,0,0,0,0,0,0,0,0
0,0,0,0,0,0,0,0,0,0,0,0,0,0,0,0
0,0,0,0,0,0,0,0,0,0,0,0,0,0,0,0
0,0,0,0,0,0,0,0,0,0,0,0,0,0,0,0
0,0,0,0,0,0,0,0,0,0,0,0,0,0,0,0
0,0,0,0,0,0,0,0,0,0,0,0,0,0,0,0
0,0,0,0,0,0,0,0,0,0,0,0,0,0,0,0
0,0,0,0,0,0,0,0,0,0,0,0,0,0,0,0
0,0,0,0,0,0,0,0,0,0,0,0,0,0,0,0
0,0,0,0,0,0,0,0,0,0,0,0,0,0,0,0
0,0,0,0,0,0,0,0,0,0,0,0,0,0,0,0
0,0,0,0,0,0,0,0,0,0,0,0,0,0,0,0
0,0,0,0,0,0,0,0,0,0,0,0,0,0,0,0
:endlayer
layer: 43
0,0,0,0,0,0,0,0,0,0,0,0,0,0,0,0
0,0,0,0,0,0,0,0,0,0,0,0,0,0,0,0
0,0,0,0,0,0,0,0,0,0,0,0,0,0,0,0
0,0,0,0,0,0,0,0,0,0,0,0,0,0,0,0
0,0,0,0,0,0,0,0,0,0,0,0,0,0,0,0
0,0,0,0,0,0,0,0,0,0,0,0,0,0,0,0
0,0,0,0,0,0,0,0,0,0,0,0,0,0,0,0
0,0,0,0,0,0,0,0,0,0,0,0,0,0,0,0
0,0,0,0,0,0,0,0,0,0,0,0,0,0,0,0
0,0,0,0,0,0,0,0,0,0,0,0,0,0,0,0
0,0,0,0,0,0,0,0,0,0,0,0,0,0,0,0
0,0,0,0,0,0,0,0,0,0,0,0,0,0,0,0
0,0,0,0,0,0,0,0,0,0,0,0,0,0,0,0
0,0,0,0,0,0,0,0,0,0,0,0,0,0,0,0
0,0,0,0,0,0,0,0,0,0,0,0,0,0,0,0
0,0,0,0,0,0,0,0,0,0,0,0,0,0,0,0
:endlayer
layer: 44
0,0,0,0,0,0,0,0,0,0,0,0,0,0,0,0
0,0,0,0,0,0,0,0,0,0,0,0,0,0,0,0
0,0,0,0,0,0,0,0,0,0,0,0,0,0,0,0
0,0,0,0,0,0,0,0,0,0,0,0,0,0,0,0
0,0,0,0,0,0,0,0,0,0,0,0,0,0,0,0
0,0,0,0,0,0,0,0,0,0,0,0,0,0,0,0
0,0,0,0,0,0,0,0,0,0,0,0,0,0,0,0
0,0,0,0,0,0,0,0,0,0,0,0,0,0,0,0
0,0,0,0,0,0,0,0,0,0,0,0,0,0,0,0
0,0,0,0,0,0,0,0,0,0,0,0,0,0,0,0
0,0,0,0,0,0,0,0,0,0,0,0,0,0,0,0
0,0,0,0,0,0,0,0,0,0,0,0,0,0,0,0
0,0,0,0,0,0,0,0,0,0,0,0,0,0,0,0
0,0,0,0,0,0,0,0,0,0,0,0,0,0,0,0
0,0,0,0,0,0,0,0,0,0,0,0,0,0,0,0
0,0,0,0,0,0,0,0,0,0,0,0,0,0,0,0
:endlayer
layer: 45
0,0,0,0,0,0,0,0,0,0,0,0,0,0,0,0
0,0,0,0,0,0,0,0,0,0,0,0,0,0,0,0
0,0,0,0,0,0,0,0,0,0,0,0,0,0,0,0
0,0,0,0,0,0,0,0,0,0,0,0,0,0,0,0
0,0,0,0,0,0,0,0,0,0,0,0,0,0,0,0
0,0,0,0,0,0,0,0,0,0,0,0,0,0,0,0
0,0,0,0,0,0,0,0,0,0,0,0,0,0,0,0
0,0,0,0,0,0,0,0,0,0,0,0,0,0,0,0
0,0,0,0,0,0,0,0,0,0,0,0,0,0,0,0
0,0,0,0,0,0,0,0,0,0,0,0,0,0,0,0
0,0,0,0,0,0,0,0,0,0,0,0,0,0,0,0
0,0,0,0,0,0,0,0,0,0,0,0,0,0,0,0
0,0,0,0,0,0,0,0,0,0,0,0,0,0,0,0
0,0,0,0,0,0,0,0,0,0,0,0,0,0,0,0
0,0,0,0,0,0,0,0,0,0,0,0,0,0,0,0
0,0,0,0,0,0,0,0,0,0,0,0,0,0,0,0
:endlayer
layer: 46
0,0,0,0,0,0,0,0,0,0,0,0,0,0,0,0
0,0,0,0,0,0,0,0,0,0,0,0,0,0,0,0
0,0,0,0,0,0,0,0,0,0,0,0,0,0,0,0
0,0,0,0,0,0,0,0,0,0,0,0,0,0,0,0
0,0,0,0,0,0,0,0,0,0,0,0,0,0,0,0
0,0,0,0,0,0,0,0,0,0,0,0,0,0,0,0
0,0,0,0,0,0,0,0,0,0,0,0,0,0,0,0
0,0,0,0,0,0,0,0,0,0,0,0,0,0,0,0
0,0,0,0,0,0,0,0,0,0,0,0,0,0,0,0
0,0,0,0,0,0,0,0,0,0,0,0,0,0,0,0
0,0,0,0,0,0,0,0,0,0,0,0,0,0,0,0
0,0,0,0,0,0,0,0,0,0,0,0,0,0,0,0
0,0,0,0,0,0,0,0,0,0,0,0,0,0,0,0
0,0,0,0,0,0,0,0,0,0,0,0,0,0,0,0
0,0,0,0,0,0,0,0,0,0,0,0,0,0,0,0
0,0,0,0,0,0,0,0,0,0,0,0,0,0,0,0
:endlayer
layer: 47
0,0,0,0,0,0,0,0,0,0,0,0,0,0,0,0
0,0,0,0,0,0,0,0,0,0,0,0,0,0,0,0
0,0,0,0,0,0,0,0,0,0,0,0,0,0,0,0
0,0,0,0,0,0,0,0,0,0,0,0,0,0,0,0
0,0,0,0,0,0,0,0,0,0,0,0,0,0,0,0
0,0,0,0,0,0,0,0,0,0,0,0,0,0,0,0
0,0,0,0,0,0,0,0,0,0,0,0,0,0,0,0
0,0,0,0,0,0,0,0,0,0,0,0,0,0,0,0
0,0,0,0,0,0,0,0,0,0,0,0,0,0,0,0
0,0,0,0,0,0,0,0,0,0,0,0,0,0,0,0
0,0,0,0,0,0,0,0,0,0,0,0,0,0,0,0
0,0,0,0,0,0,0,0,0,0,0,0,0,0,0,0
0,0,0,0,0,0,0,0,0,0,0,0,0,0,0,0
0,0,0,0,0,0,0,0,0,0,0,0,0,0,0,0
0,0,0,0,0,0,0,0,0,0,0,0,0,0,0,0
0,0,0,0,0,0,0,0,0,0,0,0,0,0,0,0
:endlayer
layer: 48
0,0,0,0,0,0,0,0,0,0,0,0,0,0,0,0
0,0,0,0,0,0,0,0,0,0,0,0,0,0,0,0
0,0,0,0,0,0,0,0,0,0,0,0,0,0,0,0
0,0,0,0,0,0,0,0,0,0,0,0,0,0,0,0
0,0,0,0,0,0,0,0,0,0,0,0,0,0,0,0
0,0,0,0,0,0,0,0,0,0,0,0,0,0,0,0
0,0,0,0,0,0,0,0,0,0,0,0,0,0,0,0
0,0,0,0,0,0,0,0,0,0,0,0,0,0,0,0
0,0,0,0,0,0,0,0,0,0,0,0,0,0,0,0
0,0,0,0,0,0,0,0,0,0,0,0,0,0,0,0
0,0,0,0,0,0,0,0,0,0,0,0,0,0,0,0
0,0,0,0,0,0,0,0,0,0,0,0,0,0,0,0
0,0,0,0,0,0,0,0,0,0,0,0,0,0,0,0
0,0,0,0,0,0,0,0,0,0,0,0,0,0,0,0
0,0,0,0,0,0,0,0,0,0,0,0,0,0,0,0
0,0,0,0,0,0,0,0,0,0,0,0,0,0,0,0
:endlayer
layer: 49
0,0,0,0,0,0,0,0,0,0,0,0,0,0,0,0
0,0,0,0,0,0,0,0,0,0,0,0,0,0,0,0
0,0,0,0,0,0,0,0,0,0,0,0,0,0,0,0
0,0,0,0,0,0,0,0,0,0,0,0,0,0,0,0
0,0,0,0,0,0,0,0,0,0,0,0,0,0,0,0
0,0,0,0,0,0,0,0,0,0,0,0,0,0,0,0
0,0,0,0,0,0,0,0,0,0,0,0,0,0,0,0
0,0,0,0,0,0,0,0,0,0,0,0,0,0,0,0
0,0,0,0,0,0,0,0,0,0,0,0,0,0,0,0
0,0,0,0,0,0,0,0,0,0,0,0,0,0,0,0
0,0,0,0,0,0,0,0,0,0,0,0,0,0,0,0
0,0,0,0,0,0,0,0,0,0,0,0,0,0,0,0
0,0,0,0,0,0,0,0,0,0,0,0,0,0,0,0
0,0,0,0,0,0,0,0,0,0,0,0,0,0,0,0
0,0,0,0,0,0,0,0,0,0,0,0,0,0,0,0
0,0,0,0,0,0,0,0,0,0,0,0,0,0,0,0
:endlayer
layer: 50
0,0,0,0,0,0,0,0,0,0,0,0,0,0,0,0
0,0,0,0,0,0,0,0,0,0,0,0,0,0,0,0
0,0,0,0,0,0,0,0,0,0,0,0,0,0,0,0
0,0,0,0,0,0,0,0,0,0,0,0,0,0,0,0
0,0,0,0,0,0,0,0,0,0,0,0,0,0,0,0
0,0,0,0,0,0,0,0,0,0,0,0,0,0,0,0
0,0,0,0,0,0,0,0,0,0,0,0,0,0,0,0
0,0,0,0,0,0,0,0,0,0,0,0,0,0,0,0
0,0,0,0,0,0,0,0,0,0,0,0,0,0,0,0
0,0,0,0,0,0,0,0,0,0,0,0,0,0,0,0
0,0,0,0,0,0,0,0,0,0,0,0,0,0,0,0
0,0,0,0,0,0,0,0,0,0,0,0,0,0,0,0
0,0,0,0,0,0,0,0,0,0,0,0,0,0,0,0
0,0,0,0,0,0,0,0,0,0,0,0,0,0,0,0
0,0,0,0,0,0,0,0,0,0,0,0,0,0,0,0
0,0,0,0,0,0,0,0,0,0,0,0,0,0,0,0
:endlayer
layer: 51
0,0,0,0,0,0,0,0,0,0,0,0,0,0,0,0
0,0,0,0,0,0,0,0,0,0,0,0,0,0,0,0
0,0,0,0,0,0,0,0,0,0,0,0,0,0,0,0
0,0,0,0,0,0,0,0,0,0,0,0,0,0,0,0
0,0,0,0,0,0,0,0,0,0,0,0,0,0,0,0
0,0,0,0,0,0,0,0,0,0,0,0,0,0,0,0
0,0,0,0,0,0,0,0,0,0,0,0,0,0,0,0
0,0,0,0,0,0,0,0,0,0,0,0,0,0,0,0
0,0,0,0,0,0,0,0,0,0,0,0,0,0,0,0
0,0,0,0,0,0,0,0,0,0,0,0,0,0,0,0
0,0,0,0,0,0,0,0,0,0,0,0,0,0,0,0
0,0,0,0,0,0,0,0,0,0,0,0,0,0,0,0
0,0,0,0,0,0,0,0,0,0,0,0,0,0,0,0
0,0,0,0,0,0,0,0,0,0,0,0,0,0,0,0
0,0,0,0,0,0,0,0,0,0,0,0,0,0,0,0
0,0,0,0,0,0,0,0,0,0,0,0,0,0,0,0
:endlayer
layer: 52
0,0,0,0,0,0,0,0,0,0,0,0,0,0,0,0
0,0,0,0,0,0,0,0,0,0,0,0,0,0,0,0
0,0,0,0,0,0,0,0,0,0,0,0,0,0,0,0
0,0,0,0,0,0,0,0,0,0,0,0,0,0,0,0
0,0,0,0,0,0,0,0,0,0,0,0,0,0,0,0
0,0,0,0,0,0,0,0,0,0,0,0,0,0,0,0
0,0,0,0,0,0,0,0,0,0,0,0,0,0,0,0
0,0,0,0,0,0,0,0,0,0,0,0,0,0,0,0
0,0,0,0,0,0,0,0,0,0,0,0,0,0,0,0
0,0,0,0,0,0,0,0,0,0,0,0,0,0,0,0
0,0,0,0,0,0,0,0,0,0,0,0,0,0,0,0
0,0,0,0,0,0,0,0,0,0,0,0,0,0,0,0
0,0,0,0,0,0,0,0,0,0,0,0,0,0,0,0
0,0,0,0,0,0,0,0,0,0,0,0,0,0,0,0
0,0,0,0,0,0,0,0,0,0,0,0,0,0,0,0
0,0,0,0,0,0,0,0,0,0,0,0,0,0,0,0
:endlayer
layer: 53
0,0,0,0,0,0,0,0,0,0,0,0,0,0,0,0
0,0,0,0,0,0,0,0,0,0,0,0,0,0,0,0
0,0,0,0,0,0,0,0,0,0,0,0,0,0,0,0
0,0,0,0,0,0,0,0,0,0,0,0,0,0,0,0
0,0,0,0,0,0,0,0,0,0,0,0,0,0,0,0
0,0,0,0,0,0,0,0,0,0,0,0,0,0,0,0
0,0,0,0,0,0,0,0,0,0,0,0,0,0,0,0
0,0,0,0,0,0,0,0,0,0,0,0,0,0,0,0
0,0,0,0,0,0,0,0,0,0,0,0,0,0,0,0
0,0,0,0,0,0,0,0,0,0,0,0,0,0,0,0
0,0,0,0,0,0,0,0,0,0,0,0,0,0,0,0
0,0,0,0,0,0,0,0,0,0,0,0,0,0,0,0
0,0,0,0,0,0,0,0,0,0,0,0,0,0,0,0
0,0,0,0,0,0,0,0,0,0,0,0,0,0,0,0
0,0,0,0,0,0,0,0,0,0,0,0,0,0,0,0
0,0,0,0,0,0,0,0,0,0,0,0,0,0,0,0
:endlayer
layer: 54
0,0,0,0,0,0,0,0,0,0,0,0,0,0,0,0
0,0,0,0,0,0,0,0,0,0,0,0,0,0,0,0
0,0,0,0,0,0,0,0,0,0,0,0,0,0,0,0
0,0,0,0,0,0,0,0,0,0,0,0,0,0,0,0
0,0,0,0,0,0,0,0,0,0,0,0,0,0,0,0
0,0,0,0,0,0,0,0,0,0,0,0,0,0,0,0
0,0,0,0,0,0,0,0,0,0,0,0,0,0,0,0
0,0,0,0,0,0,0,0,0,0,0,0,0,0,0,0
0,0,0,0,0,0,0,0,0,0,0,0,0,0,0,0
0,0,0,0,0,0,0,0,0,0,0,0,0,0,0,0
0,0,0,0,0,0,0,0,0,0,0,0,0,0,0,0
0,0,0,0,0,0,0,0,0,0,0,0,0,0,0,0
0,0,0,0,0,0,0,0,0,0,0,0,0,0,0,0
0,0,0,0,0,0,0,0,0,0,0,0,0,0,0,0
0,0,0,0,0,0,0,0,0,0,0,0,0,0,0,0
0,0,0,0,0,0,0,0,0,0,0,0,0,0,0,0
:endlayer
layer: 55
0,0,0,0,0,0,0,0,0,0,0,0,0,0,0,0
0,0,0,0,0,0,0,0,0,0,0,0,0,0,0,0
0,0,0,0,0,0,0,0,0,0,0,0,0,0,0,0
0,0,0,0,0,0,0,0,0,0,0,0,0,0,0,0
0,0,0,0,0,0,0,0,0,0,0,0,0,0,0,0
0,0,0,0,0,0,0,0,0,0,0,0,0,0,0,0
0,0,0,0,0,0,0,0,0,0,0,0,0,0,0,0
0,0,0,0,0,0,0,0,0,0,0,0,0,0,0,0
0,0,0,0,0,0,0,0,0,0,0,0,0,0,0,0
0,0,0,0,0,0,0,0,0,0,0,0,0,0,0,0
0,0,0,0,0,0,0,0,0,0,0,0,0,0,0,0
0,0,0,0,0,0,0,0,0,0,0,0,0,0,0,0
0,0,0,0,0,0,0,0,0,0,0,0,0,0,0,0
0,0,0,0,0,0,0,0,0,0,0,0,0,0,0,0
0,0,0,0,0,0,0,0,0,0,0,0,0,0,0,0
0,0,0,0,0,0,0,0,0,0,0,0,0,0,0,0
:endlayer
layer: 56
0,0,0,0,0,0,0,0,0,0,0,0,0,0,0,0
0,0,0,0,0,0,0,0,0,0,0,0,0,0,0,0
0,0,0,0,0,0,0,0,0,0,0,0,0,0,0,0
0,0,0,0,0,0,0,0,0,0,0,0,0,0,0,0
0,0,0,0,0,0,0,0,0,0,0,0,0,0,0,0
0,0,0,0,0,0,0,0,0,0,0,0,0,0,0,0
0,0,0,0,0,0,0,0,0,0,0,0,0,0,0,0
0,0,0,0,0,0,0,0,0,0,0,0,0,0,0,0
0,0,0,0,0,0,0,0,0,0,0,0,0,0,0,0
0,0,0,0,0,0,0,0,0,0,0,0,0,0,0,0
0,0,0,0,0,0,0,0,0,0,0,0,0,0,0,0
0,0,0,0,0,0,0,0,0,0,0,0,0,0,0,0
0,0,0,0,0,0,0,0,0,0,0,0,0,0,0,0
0,0,0,0,0,0,0,0,0,0,0,0,0,0,0,0
0,0,0,0,0,0,0,0,0,0,0,0,0,0,0,0
0,0,0,0,0,0,0,0,0,0,0,0,0,0,0,0
:endlayer
layer: 57
0,0,0,0,0,0,0,0,0,0,0,0,0,0,0,0
0,0,0,0,0,0,0,0,0,0,0,0,0,0,0,0
0,0,0,0,0,0,0,0,0,0,0,0,0,0,0,0
0,0,0,0,0,0,0,0,0,0,0,0,0,0,0,0
0,0,0,0,0,0,0,0,0,0,0,0,0,0,0,0
0,0,0,0,0,0,0,0,0,0,0,0,0,0,0,0
0,0,0,0,0,0,0,0,0,0,0,0,0,0,0,0
0,0,0,0,0,0,0,0,0,0,0,0,0,0,0,0
0,0,0,0,0,0,0,0,0,0,0,0,0,0,0,0
0,0,0,0,0,0,0,0,0,0,0,0,0,0,0,0
0,0,0,0,0,0,0,0,0,0,0,0,0,0,0,0
0,0,0,0,0,0,0,0,0,0,0,0,0,0,0,0
0,0,0,0,0,0,0,0,0,0,0,0,0,0,0,0
0,0,0,0,0,0,0,0,0,0,0,0,0,0,0,0
0,0,0,0,0,0,0,0,0,0,0,0,0,0,0,0
0,0,0,0,0,0,0,0,0,0,0,0,0,0,0,0
:endlayer
layer: 58
0,0,0,0,0,0,0,0,0,0,0,0,0,0,0,0
0,0,0,0,0,0,0,0,0,0,0,0,0,0,0,0
0,0,0,0,0,0,0,0,0,0,0,0,0,0,0,0
0,0,0,0,0,0,0,0,0,0,0,0,0,0,0,0
0,0,0,0,0,0,0,0,0,0,0,0,0,0,0,0
0,0,0,0,0,0,0,0,0,0,0,0,0,0,0,0
0,0,0,0,0,0,0,0,0,0,0,0,0,0,0,0
0,0,0,0,0,0,0,0,0,0,0,0,0,0,0,0
0,0,0,0,0,0,0,0,0,0,0,0,0,0,0,0
0,0,0,0,0,0,0,0,0,0,0,0,0,0,0,0
0,0,0,0,0,0,0,0,0,0,0,0,0,0,0,0
0,0,0,0,0,0,0,0,0,0,0,0,0,0,0,0
0,0,0,0,0,0,0,0,0,0,0,0,0,0,0,0
0,0,0,0,0,0,0,0,0,0,0,0,0,0,0,0
0,0,0,0,0,0,0,0,0,0,0,0,0,0,0,0
0,0,0,0,0,0,0,0,0,0,0,0,0,0,0,0
:endlayer
layer: 59
0,0,0,0,0,0,0,0,0,0,0,0,0,0,0,0
0,0,0,0,0,0,0,0,0,0,0,0,0,0,0,0
0,0,0,0,0,0,0,0,0,0,0,0,0,0,0,0
0,0,0,0,0,0,0,0,0,0,0,0,0,0,0,0
0,0,0,0,0,0,0,0,0,0,0,0,0,0,0,0
0,0,0,0,0,0,0,0,0,0,0,0,0,0,0,0
0,0,0,0,0,0,0,0,0,0,0,0,0,0,0,0
0,0,0,0,0,0,0,0,0,0,0,0,0,0,0,0
0,0,0,0,0,0,0,0,0,0,0,0,0,0,0,0
0,0,0,0,0,0,0,0,0,0,0,0,0,0,0,0
0,0,0,0,0,0,0,0,0,0,0,0,0,0,0,0
0,0,0,0,0,0,0,0,0,0,0,0,0,0,0,0
0,0,0,0,0,0,0,0,0,0,0,0,0,0,0,0
0,0,0,0,0,0,0,0,0,0,0,0,0,0,0,0
0,0,0,0,0,0,0,0,0,0,0,0,0,0,0,0
0,0,0,0,0,0,0,0,0,0,0,0,0,0,0,0
:endlayer
layer: 60
0,0,0,0,0,0,0,0,0,0,0,0,0,0,0,0
0,0,0,0,0,0,0,0,0,0,0,0,0,0,0,0
0,0,0,0,0,0,0,0,0,0,0,0,0,0,0,0
0,0,0,0,0,0,0,0,0,0,0,0,0,0,0,0
0,0,0,0,0,0,0,0,0,0,0,0,0,0,0,0
0,0,0,0,0,0,0,0,0,0,0,0,0,0,0,0
0,0,0,0,0,0,0,0,0,0,0,0,0,0,0,0
0,0,0,0,0,0,0,0,0,0,0,0,0,0,0,0
0,0,0,0,0,0,0,0,0,0,0,0,0,0,0,0
0,0,0,0,0,0,0,0,0,0,0,0,0,0,0,0
0,0,0,0,0,0,0,0,0,0,0,0,0,0,0,0
0,0,0,0,0,0,0,0,0,0,0,0,0,0,0,0
0,0,0,0,0,0,0,0,0,0,0,0,0,0,0,0
0,0,0,0,0,0,0,0,0,0,0,0,0,0,0,0
0,0,0,0,0,0,0,0,0,0,0,0,0,0,0,0
0,0,0,0,0,0,0,0,0,0,0,0,0,0,0,0
:endlayer
layer: 61
0,0,0,0,0,0,0,0,0,0,0,0,0,0,0,0
0,0,0,0,0,0,0,0,0,0,0,0,0,0,0,0
0,0,0,0,0,0,0,0,0,0,0,0,0,0,0,0
0,0,0,0,0,0,0,0,0,0,0,0,0,0,0,0
0,0,0,0,0,0,0,0,0,0,0,0,0,0,0,0
0,0,0,0,0,0,0,0,0,0,0,0,0,0,0,0
0,0,0,0,0,0,0,0,0,0,0,0,0,0,0,0
0,0,0,0,0,0,0,0,0,0,0,0,0,0,0,0
0,0,0,0,0,0,0,0,0,0,0,0,0,0,0,0
0,0,0,0,0,0,0,0,0,0,0,0,0,0,0,0
0,0,0,0,0,0,0,0,0,0,0,0,0,0,0,0
0,0,0,0,0,0,0,0,0,0,0,0,0,0,0,0
0,0,0,0,0,0,0,0,0,0,0,0,0,0,0,0
0,0,0,0,0,0,0,0,0,0,0,0,0,0,0,0
0,0,0,0,0,0,0,0,0,0,0,0,0,0,0,0
0,0,0,0,0,0,0,0,0,0,0,0,0,0,0,0
:endlayer
layer: 62
0,0,0,0,0,0,0,0,0,0,0,0,0,0,0,0
0,0,0,0,0,0,0,0,0,0,0,0,0,0,0,0
0,0,0,0,0,0,0,0,0,0,0,0,0,0,0,0
0,0,0,0,0,0,0,0,0,0,0,0,0,0,0,0
0,0,0,0,0,0,0,0,0,0,0,0,0,0,0,0
0,0,0,0,0,0,0,0,0,0,0,0,0,0,0,0
0,0,0,0,0,0,0,0,0,0,0,0,0,0,0,0
0,0,0,0,0,0,0,0,0,0,0,0,0,0,0,0
0,0,0,0,0,0,0,0,0,0,0,0,0,0,0,0
0,0,0,0,0,0,0,0,0,0,0,0,0,0,0,0
0,0,0,0,0,0,0,0,0,0,0,0,0,0,0,0
0,0,0,0,0,0,0,0,0,0,0,0,0,0,0,0
0,0,0,0,0,0,0,0,0,0,0,0,0,0,0,0
0,0,0,0,0,0,0,0,0,0,0,0,0,0,0,0
0,0,0,0,0,0,0,0,0,0,0,0,0,0,0,0
0,0,0,0,0,0,0,0,0,0,0,0,0,0,0,0
:endlayer
layer: 63
0,0,0,0,0,0,0,0,0,0,0,0,0,0,0,0
0,0,0,0,0,0,0,0,0,0,0,0,0,0,0,0
0,0,0,0,0,0,0,0,0,0,0,0,0,0,0,0
0,0,0,0,0,0,0,0,0,0,0,0,0,0,0,0
0,0,0,0,0,0,0,0,0,0,0,0,0,0,0,0
0,0,0,0,0,0,0,0,0,0,0,0,0,0,0,0
0,0,0,0,0,0,0,0,0,0,0,0,0,0,0,0
0,0,0,0,0,0,0,0,0,0,0,0,0,0,0,0
0,0,0,0,0,0,0,0,0,0,0,0,0,0,0,0
0,0,0,0,0,0,0,0,0,0,0,0,0,0,0,0
0,0,0,0,0,0,0,0,0,0,0,0,0,0,0,0
0,0,0,0,0,0,0,0,0,0,0,0,0,0,0,0
0,0,0,0,0,0,0,0,0,0,0,0,0,0,0,0
0,0,0,0,0,0,0,0,0,0,0,0,0,0,0,0
0,0,0,0,0,0,0,0,0,0,0,0,0,0,0,0
0,0,0,0,0,0,0,0,0,0,0,0,0,0,0,0
:endlayer
layer: 64
0,0,0,0,0,0,0,0,0,0,0,0,0,0,0,0
0,0,0,0,0,0,0,0,0,0,0,0,0,0,0,0
0,0,0,0,0,0,0,0,0,0,0,0,0,0,0,0
0,0,0,0,0,0,0,0,0,0,0,0,0,0,0,0
0,0,0,0,0,0,0,0,0,0,0,0,0,0,0,0
0,0,0,0,0,0,0,0,0,0,0,0,0,0,0,0
0,0,0,0,0,0,0,0,0,0,0,0,0,0,0,0
0,0,0,0,0,0,0,0,0,0,0,0,0,0,0,0
0,0,0,0,0,0,0,0,0,0,0,0,0,0,0,0
0,0,0,0,0,0,0,0,0,0,0,0,0,0,0,0
0,0,0,0,0,0,0,0,0,0,0,0,0,0,0,0
0,0,0,0,0,0,0,0,0,0,0,0,0,0,0,0
0,0,0,0,0,0,0,0,0,0,0,0,0,0,0,0
0,0,0,0,0,0,0,0,0,0,0,0,0,0,0,0
0,0,0,0,0,0,0,0,0,0,0,0,0,0,0,0
0,0,0,0,0,0,0,0,0,0,0,0,0,0,0,0
:endlayer
layer: 65
0,0,0,0,0,0,0,0,0,0,0,0,0,0,0,0
0,0,0,0,0,0,0,0,0,0,0,0,0,0,0,0
0,0,0,0,0,0,0,0,0,0,0,0,0,0,0,0
0,0,0,0,0,0,0,0,0,0,0,0,0,0,0,0
0,0,0,0,0,0,0,0,0,0,0,0,0,0,0,0
0,0,0,0,0,0,0,0,0,0,0,0,0,0,0,0
0,0,0,0,0,0,0,0,0,0,0,0,0,0,0,0
0,0,0,0,0,0,0,0,0,0,0,0,0,0,0,0
0,0,0,0,0,0,0,0,0,0,0,0,0,0,0,0
0,0,0,0,0,0,0,0,0,0,0,0,0,0,0,0
0,0,0,0,0,0,0,0,0,0,0,0,0,0,0,0
0,0,0,0,0,0,0,0,0,0,0,0,0,0,0,0
0,0,0,0,0,0,0,0,0,0,0,0,0,0,0,0
0,0,0,0,0,0,0,0,0,0,0,0,0,0,0,0
0,0,0,0,0,0,0,0,0,0,0,0,0,0,0,0
0,0,0,0,0,0,0,0,0,0,0,0,0,0,0,0
:endlayer
layer: 66
0,0,0,0,0,0,0,0,0,0,0,0,0,0,0,0
0,0,0,0,0,0,0,0,0,0,0,0,0,0,0,0
0,0,0,0,0,0,0,0,0,0,0,0,0,0,0,0
0,0,0,0,0,0,0,0,0,0,0,0,0,0,0,0
0,0,0,0,0,0,0,0,0,0,0,0,0,0,0,0
0,0,0,0,0,0,0,0,0,0,0,0,0,0,0,0
0,0,0,0,0,0,0,0,0,0,0,0,0,0,0,0
0,0,0,0,0,0,0,0,0,0,0,0,0,0,0,0
0,0,0,0,0,0,0,0,0,0,0,0,0,0,0,0
0,0,0,0,0,0,0,0,0,0,0,0,0,0,0,0
0,0,0,0,0,0,0,0,0,0,0,0,0,0,0,0
0,0,0,0,0,0,0,0,0,0,0,0,0,0,0,0
0,0,0,0,0,0,0,0,0,0,0,0,0,0,0,0
0,0,0,0,0,0,0,0,0,0,0,0,0,0,0,0
0,0,0,0,0,0,0,0,0,0,0,0,0,0,0,0
0,0,0,0,0,0,0,0,0,0,0,0,0,0,0,0
:endlayer
layer: 67
0,0,0,0,0,0,0,0,0,0,0,0,0,0,0,0
0,0,0,0,0,0,0,0,0,0,0,0,0,0,0,0
0,0,0,0,0,0,0,0,0,0,0,0,0,0,0,0
0,0,0,0,0,0,0,0,0,0,0,0,0,0,0,0
0,0,0,0,0,0,0,0,0,0,0,0,0,0,0,0
0,0,0,0,0,0,0,0,0,0,0,0,0,0,0,0
0,0,0,0,0,0,0,0,0,0,0,0,0,0,0,0
0,0,0,0,0,0,0,0,0,0,0,0,0,0,0,0
0,0,0,0,0,0,0,0,0,0,0,0,0,0,0,0
0,0,0,0,0,0,0,0,0,0,0,0,0,0,0,0
0,0,0,0,0,0,0,0,0,0,0,0,0,0,0,0
0,0,0,0,0,0,0,0,0,0,0,0,0,0,0,0
0,0,0,0,0,0,0,0,0,0,0,0,0,0,0,0
0,0,0,0,0,0,0,0,0,0,0,0,0,0,0,0
0,0,0,0,0,0,0,0,0,0,0,0,0,0,0,0
0,0,0,0,0,0,0,0,0,0,0,0,0,0,0,0
:endlayer
layer: 68
0,0,0,0,0,0,0,0,0,0,0,0,0,0,0,0
0,0,0,0,0,0,0,0,0,0,0,0,0,0,0,0
0,0,0,0,0,0,0,0,0,0,0,0,0,0,0,0
0,0,0,0,0,0,0,0,0,0,0,0,0,0,0,0
0,0,0,0,0,0,0,0,0,0,0,0,0,0,0,0
0,0,0,0,0,0,0,0,0,0,0,0,0,0,0,0
0,0,0,0,0,0,0,0,0,0,0,0,0,0,0,0
0,0,0,0,0,0,0,0,0,0,0,0,0,0,0,0
0,0,0,0,0,0,0,0,0,0,0,0,0,0,0,0
0,0,0,0,0,0,0,0,0,0,0,0,0,0,0,0
0,0,0,0,0,0,0,0,0,0,0,0,0,0,0,0
0,0,0,0,0,0,0,0,0,0,0,0,0,0,0,0
0,0,0,0,0,0,0,0,0,0,0,0,0,0,0,0
0,0,0,0,0,0,0,0,0,0,0,0,0,0,0,0
0,0,0,0,0,0,0,0,0,0,0,0,0,0,0,0
0,0,0,0,0,0,0,0,0,0,0,0,0,0,0,0
:endlayer
layer: 69
0,0,0,0,0,0,0,0,0,0,0,0,0,0,0,0
0,0,0,0,0,0,0,0,0,0,0,0,0,0,0,0
0,0,0,0,0,0,0,0,0,0,0,0,0,0,0,0
0,0,0,0,0,0,0,0,0,0,0,0,0,0,0,0
0,0,0,0,0,0,0,0,0,0,0,0,0,0,0,0
0,0,0,0,0,0,0,0,0,0,0,0,0,0,0,0
0,0,0,0,0,0,0,0,0,0,0,0,0,0,0,0
0,0,0,0,0,0,0,0,0,0,0,0,0,0,0,0
0,0,0,0,0,0,0,0,0,0,0,0,0,0,0,0
0,0,0,0,0,0,0,0,0,0,0,0,0,0,0,0
0,0,0,0,0,0,0,0,0,0,0,0,0,0,0,0
0,0,0,0,0,0,0,0,0,0,0,0,0,0,0,0
0,0,0,0,0,0,0,0,0,0,0,0,0,0,0,0
0,0,0,0,0,0,0,0,0,0,0,0,0,0,0,0
0,0,0,0,0,0,0,0,0,0,0,0,0,0,0,0
0,0,0,0,0,0,0,0,0,0,0,0,0,0,0,0
:endlayer
layer: 70
0,0,0,0,0,0,0,0,0,0,0,0,0,0,0,0
0,0,0,0,0,0,0,0,0,0,0,0,0,0,0,0
0,0,0,0,0,0,0,0,0,0,0,0,0,0,0,0
0,0,0,0,0,0,0,0,0,0,0,0,0,0,0,0
0,0,0,0,0,0,0,0,0,0,0,0,0,0,0,0
0,0,0,0,0,0,0,0,0,0,0,0,0,0,0,0
0,0,0,0,0,0,0,0,0,0,0,0,0,0,0,0
0,0,0,0,0,0,0,0,0,0,0,0,0,0,0,0
0,0,0,0,0,0,0,0,0,0,0,0,0,0,0,0
0,0,0,0,0,0,0,0,0,0,0,0,0,0,0,0
0,0,0,0,0,0,0,0,0,0,0,0,0,0,0,0
0,0,0,0,0,0,0,0,0,0,0,0,0,0,0,0
0,0,0,0,0,0,0,0,0,0,0,0,0,0,0,0
0,0,0,0,0,0,0,0,0,0,0,0,0,0,0,0
0,0,0,0,0,0,0,0,0,0,0,0,0,0,0,0
0,0,0,0,0,0,0,0,0,0,0,0,0,0,0,0
:endlayer
layer: 71
0,0,0,0,0,0,0,0,0,0,0,0,0,0,0,0
0,0,0,0,0,0,0,0,0,0,0,0,0,0,0,0
0,0,0,0,0,0,0,0,0,0,0,0,0,0,0,0
0,0,0,0,0,0,0,0,0,0,0,0,0,0,0,0
0,0,0,0,0,0,0,0,0,0,0,0,0,0,0,0
0,0,0,0,0,0,0,0,0,0,0,0,0,0,0,0
0,0,0,0,0,0,0,0,0,0,0,0,0,0,0,0
0,0,0,0,0,0,0,0,0,0,0,0,0,0,0,0
0,0,0,0,0,0,0,0,0,0,0,0,0,0,0,0
0,0,0,0,0,0,0,0,0,0,0,0,0,0,0,0
0,0,0,0,0,0,0,0,0,0,0,0,0,0,0,0
0,0,0,0,0,0,0,0,0,0,0,0,0,0,0,0
0,0,0,0,0,0,0,0,0,0,0,0,0,0,0,0
0,0,0,0,0,0,0,0,0,0,0,0,0,0,0,0
0,0,0,0,0,0,0,0,0,0,0,0,0,0,0,0
0,0,0,0,0,0,0,0,0,0,0,0,0,0,0,0
:endlayer
layer: 72
0,0,0,0,0,0,0,0,0,0,0,0,0,0,0,0
0,0,0,0,0,0,0,0,0,0,0,0,0,0,0,0
0,0,0,0,0,0,0,0,0,0,0,0,0,0,0,0
0,0,0,0,0,0,0,0,0,0,0,0,0,0,0,0
0,0,0,0,0,0,0,0,0,0,0,0,0,0,0,0
0,0,0,0,0,0,0,0,0,0,0,0,0,0,0,0
0,0,0,0,0,0,0,0,0,0,0,0,0,0,0,0
0,0,0,0,0,0,0,0,0,0,0,0,0,0,0,0
0,0,0,0,0,0,0,0,0,0,0,0,0,0,0,0
0,0,0,0,0,0,0,0,0,0,0,0,0,0,0,0
0,0,0,0,0,0,0,0,0,0,0,0,0,0,0,0
0,0,0,0,0,0,0,0,0,0,0,0,0,0,0,0
0,0,0,0,0,0,0,0,0,0,0,0,0,0,0,0
0,0,0,0,0,0,0,0,0,0,0,0,0,0,0,0
0,0,0,0,0,0,0,0,0,0,0,0,0,0,0,0
0,0,0,0,0,0,0,0,0,0,0,0,0,0,0,0
:endlayer
layer: 73
0,0,0,0,0,0,0,0,0,0,0,0,0,0,0,0
0,0,0,0,0,0,0,0,0,0,0,0,0,0,0,0
0,0,0,0,0,0,0,0,0,0,0,0,0,0,0,0
0,0,0,0,0,0,0,0,0,0,0,0,0,0,0,0
0,0,0,0,0,0,0,0,0,0,0,0,0,0,0,0
0,0,0,0,0,0,0,0,0,0,0,0,0,0,0,0
0,0,0,0,0,0,0,0,0,0,0,0,0,0,0,0
0,0,0,0,0,0,0,0,0,0,0,0,0,0,0,0
0,0,0,0,0,0,0,0,0,0,0,0,0,0,0,0
0,0,0,0,0,0,0,0,0,0,0,0,0,0,0,0
0,0,0,0,0,0,0,0,0,0,0,0,0,0,0,0
0,0,0,0,0,0,0,0,0,0,0,0,0,0,0,0
0,0,0,0,0,0,0,0,0,0,0,0,0,0,0,0
0,0,0,0,0,0,0,0,0,0,0,0,0,0,0,0
0,0,0,0,0,0,0,0,0,0,0,0,0,0,0,0
0,0,0,0,0,0,0,0,0,0,0,0,0,0,0,0
:endlayer
layer: 74
0,0,0,0,0,0,0,0,0,0,0,0,0,0,0,0
0,0,0,0,0,0,0,0,0,0,0,0,0,0,0,0
0,0,0,0,0,0,0,0,0,0,0,0,0,0,0,0
0,0,0,0,0,0,0,0,0,0,0,0,0,0,0,0
0,0,0,0,0,0,0,0,0,0,0,0,0,0,0,0
0,0,0,0,0,0,0,0,0,0,0,0,0,0,0,0
0,0,0,0,0,0,0,0,0,0,0,0,0,0,0,0
0,0,0,0,0,0,0,0,0,0,0,0,0,0,0,0
0,0,0,0,0,0,0,0,0,0,0,0,0,0,0,0
0,0,0,0,0,0,0,0,0,0,0,0,0,0,0,0
0,0,0,0,0,0,0,0,0,0,0,0,0,0,0,0
0,0,0,0,0,0,0,0,0,0,0,0,0,0,0,0
0,0,0,0,0,0,0,0,0,0,0,0,0,0,0,0
0,0,0,0,0,0,0,0,0,0,0,0,0,0,0,0
0,0,0,0,0,0,0,0,0,0,0,0,0,0,0,0
0,0,0,0,0,0,0,0,0,0,0,0,0,0,0,0
:endlayer

#### RULES ####
rule:
plugin=vanillaBlocks
number=1
data:
JSON:{{"val":{"blockName":{"val":"minecraft:cobblestone","id":"ss"},"meta":{"val":"0","id":"pi"},"buildPass":{"val":"0","id":"pi"}},"id":"ct"}}
:enddata
:endrule

rule:
plugin=vanillaBlocks
number=2
data:
JSON:{{"val":{"blockName":{"val":"minecraft:stonebrick","id":"ss"},"meta":{"val":"0","id":"pi"},"buildPass":{"val":"0","id":"pi"}},"id":"ct"}}
:enddata
:endrule

rule:
plugin=vanillaBlocks
number=3
data:
JSON:{{"val":{"blockName":{"val":"minecraft:stonebrick","id":"ss"},"meta":{"val":"1","id":"pi"},"buildPass":{"val":"0","id":"pi"}},"id":"ct"}}
:enddata
:endrule

rule:
plugin=vanillaBlocks
number=4
data:
JSON:{{"val":{"blockName":{"val":"minecraft:stonebrick","id":"ss"},"meta":{"val":"2","id":"pi"},"buildPass":{"val":"0","id":"pi"}},"id":"ct"}}
:enddata
:endrule

rule:
plugin=vanillaBlocks
number=5
data:
JSON:{{"val":{"blockName":{"val":"minecraft:dirt","id":"ss"},"meta":{"val":"0","id":"pi"},"buildPass":{"val":"0","id":"pi"}},"id":"ct"}}
:enddata
:endrule

rule:
plugin=vanillaBlocks
number=6
data:
JSON:{{"val":{"blockName":{"val":"minecraft:grass","id":"ss"},"meta":{"val":"0","id":"pi"},"buildPass":{"val":"0","id":"pi"}},"id":"ct"}}
:enddata
:endrule

rule:
plugin=vanillaBlocks
number=7
data:
JSON:{{"val":{"blockName":{"val":"minecraft:gravel","id":"ss"},"meta":{"val":"0","id":"pi"},"buildPass":{"val":"0","id":"pi"}},"id":"ct"}}
:enddata
:endrule

rule:
plugin=vanillaBlocks
number=8
data:
JSON:{{"val":{"blockName":{"val":"minecraft:tallgrass","id":"ss"},"meta":{"val":"1","id":"pi"},"buildPass":{"val":"2","id":"pi"}},"id":"ct"}}
:enddata
:endrule

rule:
plugin=vanillaDoors
number=9
data:
JSON:{{"val":{"sideFlag":{"val":"8","id":"pb"},"blockName":{"val":"minecraft:iron_door","id":"ss"},"meta":{"val":"2","id":"pi"},"buildPass":{"val":"2","id":"pi"}},"id":"ct"}}
:enddata
:endrule

rule:
plugin=vanillaInventory
number=10
data:
JSON:{{"val":{"lootLevel":{"val":"0","id":"pi"},"inventoryData":{"val":{"length":{"val":"27","id":"pi"},"inventoryContents":{"val":[],"id":"ls"}},"id":"ct"},"teData":{"val":{"id":{"val":"Chest","id":"ss"},"z":{"val":"566","id":"pi"},"y":{"val":"87","id":"pi"},"x":{"val":"1503","id":"pi"}},"id":"ct"},"blockName":{"val":"minecraft:chest","id":"ss"},"meta":{"val":"5","id":"pi"},"buildPass":{"val":"0","id":"pi"}},"id":"ct"}}
:enddata
:endrule

rule:
plugin=vanillaBlocks
number=11
data:
JSON:{{"val":{"blockName":{"val":"minecraft:wooden_slab","id":"ss"},"meta":{"val":"0","id":"pi"},"buildPass":{"val":"0","id":"pi"}},"id":"ct"}}
:enddata
:endrule

rule:
plugin=vanillaInventory
number=12
data:
JSON:{{"val":{"lootLevel":{"val":"0","id":"pi"},"inventoryData":{"val":{"length":{"val":"27","id":"pi"},"inventoryContents":{"val":[],"id":"ls"}},"id":"ct"},"teData":{"val":{"id":{"val":"Chest","id":"ss"},"z":{"val":"568","id":"pi"},"y":{"val":"87","id":"pi"},"x":{"val":"1501","id":"pi"}},"id":"ct"},"blockName":{"val":"minecraft:chest","id":"ss"},"meta":{"val":"2","id":"pi"},"buildPass":{"val":"0","id":"pi"}},"id":"ct"}}
:enddata
:endrule

rule:
plugin=vanillaInventory
number=13
data:
JSON:{{"val":{"lootLevel":{"val":"0","id":"pi"},"inventoryData":{"val":{"length":{"val":"27","id":"pi"},"inventoryContents":{"val":[],"id":"ls"}},"id":"ct"},"teData":{"val":{"id":{"val":"Chest","id":"ss"},"z":{"val":"570","id":"pi"},"y":{"val":"87","id":"pi"},"x":{"val":"1500","id":"pi"}},"id":"ct"},"blockName":{"val":"minecraft:chest","id":"ss"},"meta":{"val":"2","id":"pi"},"buildPass":{"val":"0","id":"pi"}},"id":"ct"}}
:enddata
:endrule

rule:
plugin=vanillaBlocks
number=14
data:
JSON:{{"val":{"blockName":{"val":"minecraft:oak_stairs","id":"ss"},"meta":{"val":"1","id":"pi"},"buildPass":{"val":"0","id":"pi"}},"id":"ct"}}
:enddata
:endrule

rule:
plugin=vanillaBlocks
number=15
data:
JSON:{{"val":{"blockName":{"val":"minecraft:oak_stairs","id":"ss"},"meta":{"val":"2","id":"pi"},"buildPass":{"val":"0","id":"pi"}},"id":"ct"}}
:enddata
:endrule

rule:
plugin=vanillaBlocks
number=16
data:
JSON:{{"val":{"blockName":{"val":"minecraft:fence","id":"ss"},"meta":{"val":"0","id":"pi"},"buildPass":{"val":"0","id":"pi"}},"id":"ct"}}
:enddata
:endrule

rule:
plugin=vanillaDoors
number=17
data:
JSON:{{"val":{"sideFlag":{"val":"8","id":"pb"},"blockName":{"val":"minecraft:wooden_door","id":"ss"},"meta":{"val":"1","id":"pi"},"buildPass":{"val":"2","id":"pi"}},"id":"ct"}}
:enddata
:endrule

rule:
plugin=vanillaInventory
number=18
data:
JSON:{{"val":{"lootLevel":{"val":"0","id":"pi"},"inventoryData":{"val":{"length":{"val":"27","id":"pi"},"inventoryContents":{"val":[],"id":"ls"}},"id":"ct"},"teData":{"val":{"id":{"val":"Chest","id":"ss"},"z":{"val":"572","id":"pi"},"y":{"val":"87","id":"pi"},"x":{"val":"1500","id":"pi"}},"id":"ct"},"blockName":{"val":"minecraft:chest","id":"ss"},"meta":{"val":"2","id":"pi"},"buildPass":{"val":"0","id":"pi"}},"id":"ct"}}
:enddata
:endrule

rule:
plugin=vanillaBlocks
number=19
data:
JSON:{{"val":{"blockName":{"val":"minecraft:oak_stairs","id":"ss"},"meta":{"val":"0","id":"pi"},"buildPass":{"val":"0","id":"pi"}},"id":"ct"}}
:enddata
:endrule

rule:
plugin=vanillaInventory
number=20
data:
JSON:{{"val":{"lootLevel":{"val":"0","id":"pi"},"inventoryData":{"val":{"length":{"val":"27","id":"pi"},"inventoryContents":{"val":[],"id":"ls"}},"id":"ct"},"teData":{"val":{"id":{"val":"Chest","id":"ss"},"z":{"val":"574","id":"pi"},"y":{"val":"87","id":"pi"},"x":{"val":"1502","id":"pi"}},"id":"ct"},"blockName":{"val":"minecraft:chest","id":"ss"},"meta":{"val":"2","id":"pi"},"buildPass":{"val":"0","id":"pi"}},"id":"ct"}}
:enddata
:endrule

rule:
plugin=awTownHall
number=21
data:
JSON:{{"val":{"teData":{"val":{"id":{"val":"Furnace","id":"ss"},"Items":{"val":[],"id":"ls"},"BurnTime":{"val":"0","id":"ps"},"z":{"val":"574","id":"pi"},"y":{"val":"87","id":"pi"},"CookTime":{"val":"0","id":"ps"},"x":{"val":"1508","id":"pi"}},"id":"ct"},"blockName":{"val":"minecraft:furnace","id":"ss"},"meta":{"val":"4","id":"pi"},"buildPass":{"val":"0","id":"pi"}},"id":"ct"}}
:enddata
:endrule

rule:
plugin=vanillaDoors
number=22
data:
JSON:{{"val":{"sideFlag":{"val":"8","id":"pb"},"blockName":{"val":"minecraft:iron_door","id":"ss"},"meta":{"val":"0","id":"pi"},"buildPass":{"val":"2","id":"pi"}},"id":"ct"}}
:enddata
:endrule

rule:
plugin=vanillaDoors
number=23
data:
JSON:{{"val":{"sideFlag":{"val":"0","id":"pb"},"blockName":{"val":"minecraft:iron_door","id":"ss"},"meta":{"val":"8","id":"pi"},"buildPass":{"val":"2","id":"pi"}},"id":"ct"}}
:enddata
:endrule

rule:
plugin=vanillaBlocks
number=24
data:
JSON:{{"val":{"blockName":{"val":"minecraft:carpet","id":"ss"},"meta":{"val":"12","id":"pi"},"buildPass":{"val":"2","id":"pi"}},"id":"ct"}}
:enddata
:endrule

rule:
plugin=vanillaDoors
number=25
data:
JSON:{{"val":{"sideFlag":{"val":"0","id":"pb"},"blockName":{"val":"minecraft:wooden_door","id":"ss"},"meta":{"val":"8","id":"pi"},"buildPass":{"val":"2","id":"pi"}},"id":"ct"}}
:enddata
:endrule

rule:
plugin=vanillaDoors
number=26
data:
JSON:{{"val":{"sideFlag":{"val":"0","id":"pb"},"blockName":{"val":"minecraft:iron_door","id":"ss"},"meta":{"val":"8","id":"pi"},"buildPass":{"val":"2","id":"pi"}},"id":"ct"}}
:enddata
:endrule

rule:
plugin=vanillaBlocks
number=27
data:
JSON:{{"val":{"blockName":{"val":"minecraft:torch","id":"ss"},"meta":{"val":"3","id":"pi"},"buildPass":{"val":"2","id":"pi"}},"id":"ct"}}
:enddata
:endrule

rule:
plugin=vanillaBlocks
number=28
data:
JSON:{{"val":{"blockName":{"val":"minecraft:torch","id":"ss"},"meta":{"val":"1","id":"pi"},"buildPass":{"val":"2","id":"pi"}},"id":"ct"}}
:enddata
:endrule

rule:
plugin=vanillaBlocks
number=29
data:
JSON:{{"val":{"blockName":{"val":"minecraft:lever","id":"ss"},"meta":{"val":"1","id":"pi"},"buildPass":{"val":"2","id":"pi"}},"id":"ct"}}
:enddata
:endrule

rule:
plugin=vanillaBlocks
number=30
data:
JSON:{{"val":{"blockName":{"val":"minecraft:torch","id":"ss"},"meta":{"val":"4","id":"pi"},"buildPass":{"val":"2","id":"pi"}},"id":"ct"}}
:enddata
:endrule

rule:
plugin=vanillaBlocks
number=31
data:
JSON:{{"val":{"blockName":{"val":"minecraft:lever","id":"ss"},"meta":{"val":"2","id":"pi"},"buildPass":{"val":"2","id":"pi"}},"id":"ct"}}
:enddata
:endrule

rule:
plugin=vanillaBlocks
number=32
data:
JSON:{{"val":{"blockName":{"val":"minecraft:torch","id":"ss"},"meta":{"val":"2","id":"pi"},"buildPass":{"val":"2","id":"pi"}},"id":"ct"}}
:enddata
:endrule

rule:
plugin=vanillaBlocks
number=33
data:
JSON:{{"val":{"blockName":{"val":"minecraft:ladder","id":"ss"},"meta":{"val":"3","id":"pi"},"buildPass":{"val":"2","id":"pi"}},"id":"ct"}}
:enddata
:endrule

rule:
plugin=vanillaBlocks
number=34
data:
JSON:{{"val":{"blockName":{"val":"minecraft:stone_brick_stairs","id":"ss"},"meta":{"val":"3","id":"pi"},"buildPass":{"val":"0","id":"pi"}},"id":"ct"}}
:enddata
:endrule

rule:
plugin=vanillaBlocks
number=35
data:
JSON:{{"val":{"blockName":{"val":"minecraft:stone_brick_stairs","id":"ss"},"meta":{"val":"7","id":"pi"},"buildPass":{"val":"0","id":"pi"}},"id":"ct"}}
:enddata
:endrule

rule:
plugin=vanillaBlocks
number=36
data:
JSON:{{"val":{"blockName":{"val":"minecraft:stone_brick_stairs","id":"ss"},"meta":{"val":"0","id":"pi"},"buildPass":{"val":"0","id":"pi"}},"id":"ct"}}
:enddata
:endrule

rule:
plugin=vanillaBlocks
number=37
data:
JSON:{{"val":{"blockName":{"val":"minecraft:stone_slab","id":"ss"},"meta":{"val":"5","id":"pi"},"buildPass":{"val":"0","id":"pi"}},"id":"ct"}}
:enddata
:endrule

rule:
plugin=vanillaBlocks
number=38
data:
JSON:{{"val":{"blockName":{"val":"minecraft:oak_stairs","id":"ss"},"meta":{"val":"3","id":"pi"},"buildPass":{"val":"0","id":"pi"}},"id":"ct"}}
:enddata
:endrule

rule:
plugin=vanillaBlocks
number=39
data:
JSON:{{"val":{"blockName":{"val":"minecraft:wooden_slab","id":"ss"},"meta":{"val":"8","id":"pi"},"buildPass":{"val":"0","id":"pi"}},"id":"ct"}}
:enddata
:endrule

rule:
plugin=vanillaBlocks
number=40
data:
JSON:{{"val":{"blockName":{"val":"minecraft:planks","id":"ss"},"meta":{"val":"0","id":"pi"},"buildPass":{"val":"0","id":"pi"}},"id":"ct"}}
:enddata
:endrule

rule:
plugin=vanillaBlocks
number=41
data:
JSON:{{"val":{"blockName":{"val":"minecraft:torch","id":"ss"},"meta":{"val":"5","id":"pi"},"buildPass":{"val":"2","id":"pi"}},"id":"ct"}}
:enddata
:endrule

#### ENTITIES ####
