# Ancient Warfare Structure Template File
# Auto-generated structure template file. created on: 10/27/2016 at: 22:17:0
# Lines beginning with # denote comments

header:
version=2.1
name=LiarBryChurch
size=18,44,63
offset=9,2,54
:endheader

#### VALIDATION ####
validation:
type=ground
survival=true
worldGenEnabled=true
unique=false
preserveBlocks=false
selectionWeight=10
clusterValue=100
minDuplicateDistance=100
dimensionWhiteList=true
dimensionList=
biomeWhiteList=true
biomeList=tundra,roofed forest,extreme hills+,taiga,cold taiga,arctic,highland,ice plains,ice mountains,frost forest,ominous woods
leveling=10
fill=10
border=0
validTargetBlocks=minecraft:stained_hardened_clay,minecraft:dirt,minecraft:coal_ore,minecraft:lapis_ore,minecraft:diamond_ore,minecraft:gravel,minecraft:stone,minecraft:gold_ore,minecraft:sand,minecraft:clay,minecraft:redstone_ore,minecraft:grass,minecraft:iron_ore
blockSwap=false
data:
:enddata
:endvalidation

#### LAYERS ####
layer: 0
4,4,1,1,1,1,1,1,1,1,1,1,1,1,1,1,1,1
4,2,0,0,0,0,0,0,0,0,0,4,4,3,0,0,4,2
4,3,0,0,0,0,0,0,0,0,0,0,0,0,0,0,4,3
4,3,0,0,0,0,0,0,0,0,0,0,0,0,0,0,2,3
4,3,0,0,0,0,0,0,0,0,0,0,5,4,4,0,4,4
4,2,0,0,0,0,0,0,0,0,0,5,5,4,4,4,4,4
4,2,0,0,0,0,0,0,0,0,5,5,5,5,4,4,4,4
4,3,0,0,0,0,0,0,5,5,5,5,5,5,4,4,4,4
4,3,0,0,5,5,5,5,5,5,5,5,5,5,4,4,4,4
4,3,0,0,5,5,5,5,5,5,5,5,5,5,4,4,4,4
4,2,5,5,5,5,5,5,5,5,5,5,5,5,4,4,4,4
4,2,0,5,5,5,5,5,5,5,5,5,5,5,4,4,4,4
4,3,0,5,5,5,5,5,5,5,5,5,5,5,4,4,4,4
4,3,0,4,5,5,5,5,5,5,5,5,5,4,4,4,4,4
4,3,4,4,4,4,5,5,5,4,4,4,4,4,4,4,4,4
4,2,4,4,4,4,4,4,4,4,4,4,4,4,4,4,4,4
4,2,4,4,4,4,4,4,4,4,4,4,4,4,4,4,4,4
4,3,4,4,4,4,4,4,4,4,4,4,4,4,4,4,4,4
4,3,4,4,4,4,4,4,4,4,4,4,4,4,4,4,4,4
4,4,4,4,4,4,4,4,4,4,4,4,4,4,4,4,4,4
4,4,4,4,4,4,4,4,4,4,4,4,4,4,4,4,4,4
4,4,4,4,4,4,4,4,4,4,4,4,4,4,4,4,4,4
4,4,4,4,4,4,4,4,4,4,4,4,4,4,4,4,4,4
4,4,4,4,4,4,4,4,4,4,4,4,4,4,4,4,4,4
4,4,4,4,4,4,4,4,4,4,4,4,4,4,4,4,4,4
4,4,4,4,4,4,4,4,4,4,4,4,4,4,4,4,4,4
4,4,4,4,4,4,4,4,4,4,4,4,4,4,4,4,4,4
4,4,4,4,4,4,4,4,4,4,4,4,4,4,4,4,4,4
4,4,4,4,4,4,4,4,4,4,4,4,4,4,4,4,4,4
4,4,4,4,4,4,4,4,4,4,4,4,4,4,4,4,4,4
4,4,4,4,4,4,4,4,4,4,4,4,4,4,4,4,4,4
4,4,4,4,4,4,4,4,4,4,4,4,4,4,4,4,4,4
4,4,4,4,4,4,4,4,4,4,4,4,4,4,4,4,4,4
4,4,4,4,4,4,4,4,4,4,4,4,4,4,4,4,4,4
4,4,4,4,4,4,4,4,4,4,4,4,4,4,4,4,4,4
4,4,4,4,4,4,4,4,4,4,4,4,4,4,4,4,4,4
4,4,4,4,4,4,4,4,4,4,4,4,4,4,4,4,4,4
4,4,4,4,4,4,4,4,4,4,4,4,4,4,4,4,4,4
4,4,4,4,4,4,4,4,4,4,4,4,4,4,4,4,4,4
4,4,4,4,4,4,4,4,4,3,4,4,4,4,4,4,4,4
4,4,4,4,4,4,4,4,4,4,4,4,4,4,4,4,4,4
4,4,4,4,4,4,4,4,4,4,4,4,4,4,4,4,4,4
4,4,4,4,4,4,4,4,4,4,4,4,4,4,4,4,4,4
4,4,4,4,4,4,4,4,4,4,4,4,4,4,4,4,4,4
4,4,4,4,4,4,4,4,4,4,4,4,4,4,4,4,4,4
4,4,4,4,4,4,4,4,4,4,4,4,4,4,4,4,4,4
4,4,4,4,4,4,3,4,4,4,4,4,4,4,4,4,4,4
4,4,4,4,4,4,4,4,4,4,4,4,4,4,4,4,4,4
4,4,4,4,4,4,4,4,4,4,4,4,4,4,4,4,4,4
4,4,4,4,4,4,4,4,4,3,4,4,4,4,4,4,4,4
4,4,4,4,4,4,4,4,4,0,4,4,4,4,4,4,4,4
4,4,4,4,4,4,4,4,4,4,4,4,4,4,4,4,4,4
4,4,4,4,4,4,4,4,4,4,4,4,4,4,4,4,4,4
4,4,4,4,4,4,4,4,2,2,2,4,4,4,4,4,4,4
4,4,4,4,4,4,4,4,2,2,2,4,4,4,4,4,4,4
4,4,4,4,4,4,4,4,4,4,4,4,4,4,4,4,4,4
4,4,4,4,4,4,4,4,4,4,4,4,4,4,4,4,4,4
4,4,4,4,4,4,4,4,4,4,4,4,4,4,4,4,4,4
4,4,4,4,4,4,4,4,4,4,4,4,4,4,4,4,4,4
4,4,4,4,4,4,4,4,4,4,4,4,4,4,4,4,4,1
4,4,4,4,4,4,4,4,4,4,4,4,4,4,4,4,4,1
4,4,4,4,4,4,4,4,4,4,4,4,4,4,4,4,1,1
4,4,4,4,4,4,4,4,4,4,4,4,4,4,4,1,1,1
:endlayer
layer: 1
1,1,0,0,0,0,6,6,0,6,6,0,6,6,6,6,6,6
1,2,3,3,3,3,3,11,3,3,3,3,3,3,3,3,3,2
1,3,4,0,0,0,2,0,0,2,0,0,2,0,2,2,3,3
1,3,4,3,3,3,3,3,3,3,3,3,3,3,3,3,3,3
1,3,4,3,3,3,3,3,3,3,3,3,3,3,3,3,4,3
1,2,2,2,2,2,2,2,2,2,2,2,2,2,2,2,2,2
1,2,2,2,3,3,3,3,3,3,3,3,3,3,3,2,2,2
1,3,4,2,3,2,2,2,2,2,2,2,2,2,3,2,4,3
1,3,4,2,3,2,4,2,2,2,2,2,4,2,3,2,3,3
1,3,4,2,3,2,2,2,3,3,3,2,2,2,3,2,3,3
1,4,2,2,3,2,2,3,2,3,2,3,2,2,3,2,2,2
1,4,2,2,3,2,2,3,2,3,2,3,2,2,3,2,2,2
1,3,4,2,3,2,2,2,3,3,3,2,2,2,3,2,4,3
1,3,4,2,3,2,4,2,2,2,2,2,4,2,3,2,4,3
1,3,4,2,3,2,2,2,3,3,3,2,2,2,3,2,4,3
1,2,2,2,3,2,2,3,2,3,2,3,2,2,3,2,2,2
1,2,2,2,3,2,2,3,2,3,2,3,2,2,3,2,2,2
1,3,4,2,3,2,2,2,3,3,3,2,2,2,3,2,4,3
1,3,4,2,3,2,4,2,2,2,2,2,4,2,3,2,4,3
1,3,4,2,3,2,2,2,3,3,3,2,2,2,3,2,3,3
1,4,2,2,3,2,2,3,2,3,2,3,2,2,3,2,2,2
1,4,2,2,3,2,2,3,2,3,2,3,2,2,3,2,2,2
1,3,4,2,3,2,2,2,3,3,3,2,2,2,3,2,4,3
1,3,4,2,3,2,4,2,2,2,2,2,4,2,3,2,4,3
1,3,4,2,3,2,2,2,3,3,3,2,2,2,3,2,4,3
1,4,2,2,3,2,2,3,2,3,2,3,2,2,3,2,2,4
1,4,2,2,3,2,2,3,2,3,2,3,2,2,3,2,2,4
1,3,4,2,3,2,2,2,3,3,3,2,2,2,3,2,4,3
1,3,4,2,3,2,4,2,2,2,2,2,4,2,3,2,4,3
1,3,4,2,3,2,2,2,3,3,3,2,2,2,3,2,4,3
4,4,2,2,3,2,2,3,2,3,2,3,2,2,3,2,2,4
4,4,2,2,3,2,2,3,2,3,2,3,2,2,3,2,2,4
4,3,4,2,3,2,2,2,3,3,3,2,2,2,3,2,4,3
4,3,4,2,3,2,4,2,2,2,2,2,4,2,3,2,4,3
1,3,4,2,3,2,2,3,3,10,3,3,2,2,3,2,4,3
1,4,2,2,3,2,2,3,3,4,3,3,2,2,3,2,2,4
1,4,2,2,3,2,2,3,3,4,3,3,2,2,3,2,2,4
1,3,4,2,3,2,2,3,3,3,3,3,2,2,3,2,4,3
1,3,4,2,3,2,4,2,2,2,2,2,4,2,3,2,4,3
1,3,4,2,3,2,2,2,2,2,2,2,2,2,3,2,4,3
1,4,2,2,3,3,3,3,3,3,3,3,3,3,3,2,2,4
1,4,2,2,2,2,2,2,2,2,2,2,2,2,2,2,2,4
1,3,4,3,3,3,3,3,3,3,3,3,3,3,3,3,4,3
1,3,4,3,3,3,3,3,3,3,3,3,3,3,3,3,4,3
1,3,3,3,3,3,2,7,7,7,7,7,2,3,3,3,4,3
1,4,4,4,4,4,4,3,3,3,3,3,3,3,3,4,4,4
1,3,1,4,4,3,12,3,3,3,3,3,3,3,3,4,1,3
1,3,1,4,4,4,3,3,3,3,4,4,4,4,4,4,1,3
1,3,1,4,4,4,4,4,3,3,3,4,4,4,4,4,1,3
1,3,1,4,4,4,4,4,3,3,3,4,4,4,4,4,1,3
1,3,1,4,4,4,4,1,3,3,3,1,4,4,4,4,1,3
1,3,1,4,1,1,1,1,3,3,3,1,4,1,1,4,1,3
1,3,1,4,1,1,1,4,8,8,8,4,4,4,4,4,1,3
1,3,1,4,4,4,4,8,9,9,9,8,4,4,4,4,1,3
1,3,4,1,1,1,1,8,9,8,9,8,1,1,1,1,4,3
1,3,3,3,3,3,3,3,3,3,3,3,3,3,3,3,3,3
1,1,1,1,1,1,1,1,3,2,3,1,1,1,1,1,1,1
1,1,1,1,1,1,1,1,3,2,3,1,1,1,1,1,1,1
1,1,1,1,1,1,1,1,3,2,3,1,1,1,1,1,1,1
1,1,1,1,1,1,1,1,3,2,3,1,1,1,1,1,1,6
1,1,1,1,1,1,1,1,3,2,3,1,1,1,1,1,1,6
1,1,1,1,1,1,1,1,1,1,1,1,1,1,1,1,6,6
1,1,1,1,1,1,1,1,1,1,1,1,1,1,1,0,6,0
:endlayer
layer: 2
6,6,0,0,0,0,0,0,0,0,0,0,0,0,0,0,0,0
6,2,2,14,0,15,2,14,15,2,14,15,2,14,0,15,2,2
6,0,3,2,2,2,16,2,2,27,2,2,16,2,2,2,3,0
6,0,3,13,13,13,0,13,13,0,13,13,0,13,13,13,3,0
6,0,3,13,0,0,0,0,0,0,0,0,0,0,0,13,3,0
6,2,13,0,0,0,0,0,0,0,0,0,0,0,0,0,13,2
6,2,13,0,0,0,0,0,0,0,0,0,0,0,0,0,13,2
51,0,3,13,0,0,13,13,0,28,0,13,13,0,0,13,3,0
0,0,3,13,0,0,19,13,0,29,0,13,19,0,0,13,3,0
52,0,3,13,0,0,13,13,0,30,0,13,13,0,0,13,3,0
0,2,13,0,0,0,0,0,0,0,0,0,0,0,0,0,13,2
0,2,13,0,0,0,0,0,0,0,0,0,0,0,0,0,13,2
6,0,3,13,0,0,13,13,0,31,0,13,13,0,0,13,3,0
6,0,3,13,0,0,19,13,0,32,0,13,19,0,0,13,3,0
6,0,3,13,0,0,13,13,0,33,0,13,13,0,0,13,3,0
6,2,13,0,0,0,0,0,0,0,0,0,0,0,0,0,13,2
6,2,13,0,0,0,0,0,0,0,0,0,0,0,0,0,13,2
0,0,3,13,0,0,13,13,0,34,0,13,13,0,0,13,3,0
0,0,3,13,0,0,19,13,0,35,0,13,19,0,0,13,3,0
0,0,3,13,0,0,13,13,0,36,0,13,13,0,0,13,3,0
0,2,13,0,0,0,0,0,0,0,0,0,0,0,0,0,13,2
0,2,13,0,0,0,0,0,0,0,0,0,0,0,0,0,13,2
6,0,3,13,0,0,13,13,0,37,0,13,13,0,0,13,3,0
0,0,3,13,0,0,19,13,0,38,0,13,19,0,0,13,3,0
0,0,3,13,0,0,13,13,0,39,0,13,13,0,0,13,3,0
0,2,13,0,0,0,0,0,0,0,0,0,0,0,0,0,13,2
6,2,13,0,0,0,0,0,0,0,0,0,0,0,0,0,13,2
6,0,3,13,0,0,13,13,0,40,0,13,13,0,0,13,3,0
6,0,3,13,0,0,19,13,0,41,0,13,19,0,0,13,3,0
6,0,3,13,0,0,13,13,0,42,0,13,13,0,0,13,3,0
1,2,13,0,0,0,0,0,0,0,0,0,0,0,0,0,13,2
1,2,13,0,0,0,0,0,0,0,0,0,0,0,0,0,13,2
1,0,3,13,0,0,0,0,0,0,0,0,0,0,0,13,3,0
1,0,3,13,0,0,2,0,0,0,0,0,2,0,0,13,3,0
0,0,3,13,0,0,0,0,45,0,0,0,0,0,0,13,3,0
6,2,13,0,0,0,0,0,46,2,0,0,0,0,0,0,13,2
0,2,13,0,0,0,0,0,0,2,0,0,0,0,0,0,13,2
6,0,3,13,0,0,0,0,0,0,0,0,0,0,0,13,3,0
6,0,3,13,0,0,2,0,0,0,0,0,2,0,0,13,3,0
6,0,3,13,0,0,0,0,0,0,0,0,0,0,0,13,3,0
6,2,13,0,0,0,0,47,0,0,0,22,0,0,0,0,13,2
0,2,13,0,0,0,0,48,0,0,0,23,0,0,0,0,13,2
0,0,3,13,0,0,0,0,0,0,0,0,0,0,0,13,3,0
6,0,3,13,13,13,50,49,0,0,0,24,20,13,13,13,3,0
0,0,3,16,16,16,16,7,26,26,26,7,16,16,16,16,3,0
0,2,2,14,2,15,2,14,15,0,14,15,2,14,2,15,2,2
6,0,15,2,3,8,0,18,2,0,2,18,18,18,8,2,14,0
6,0,15,2,3,2,3,3,2,0,2,3,3,3,3,2,14,0
6,0,15,2,2,16,2,2,2,0,2,2,2,16,2,2,14,0
0,0,15,3,3,3,3,3,2,43,2,3,3,3,3,3,14,0
0,0,15,2,2,2,8,25,0,0,0,25,8,2,2,2,14,0
6,0,15,2,0,0,21,25,0,0,0,25,21,0,0,2,14,0
6,0,15,2,0,0,0,2,3,16,3,2,3,3,3,2,14,0
0,0,15,2,2,3,3,2,0,0,0,2,3,3,2,2,14,0
0,0,3,17,17,17,17,2,0,44,0,2,17,17,17,17,3,0
0,0,0,0,0,0,0,0,0,0,0,0,0,0,0,0,0,0
6,6,0,0,0,0,0,0,0,0,0,6,0,6,0,6,6,0
6,6,6,0,0,0,0,0,0,0,0,0,0,6,0,6,6,6
0,6,0,0,6,0,6,0,0,0,0,0,6,0,6,0,6,6
6,6,6,0,6,6,6,0,0,0,0,0,6,0,0,6,6,0
0,0,0,0,6,6,6,6,0,0,0,0,6,0,0,6,0,0
6,6,0,0,0,0,6,0,0,6,0,0,0,0,0,0,0,0
0,6,0,0,6,6,6,0,0,6,6,6,0,0,6,0,0,0
:endlayer
layer: 3
0,0,0,0,0,0,0,0,0,0,0,0,0,0,0,0,0,0
0,2,2,11,0,53,2,11,53,2,11,53,2,11,0,53,2,2
0,0,3,2,2,2,16,2,2,27,2,2,16,2,2,2,3,0
0,0,3,13,13,13,0,13,13,0,13,13,0,13,13,13,3,0
0,0,3,13,0,0,0,0,0,0,0,0,0,0,0,13,3,0
0,2,13,0,0,0,0,0,0,0,0,0,0,0,0,0,13,2
0,2,13,0,0,0,0,0,0,0,0,0,0,0,0,0,13,2
0,0,3,13,0,0,13,13,0,0,0,13,13,0,0,13,3,0
0,0,3,13,0,0,16,13,0,0,0,13,16,0,0,13,3,0
0,0,3,13,0,0,13,13,0,0,0,13,13,0,0,13,3,0
0,2,13,0,0,0,0,0,0,0,0,0,0,0,0,0,13,2
0,2,13,0,0,0,0,0,0,0,0,0,0,0,0,0,13,2
0,0,3,13,0,0,13,13,0,0,0,13,13,0,0,13,3,0
0,0,3,13,0,0,16,13,0,0,0,13,16,0,0,13,3,0
0,0,3,13,0,0,13,13,0,0,0,13,13,0,0,13,3,0
0,2,13,0,0,0,0,0,0,0,0,0,0,0,0,0,13,2
0,2,13,0,0,0,0,0,0,0,0,0,0,0,0,0,13,2
0,0,3,13,0,0,13,13,0,0,0,13,13,0,0,13,3,0
0,0,3,13,0,0,16,13,0,0,0,13,16,0,0,13,3,0
0,0,3,13,0,0,13,13,0,0,0,13,13,0,0,13,3,0
0,2,13,0,0,0,0,0,0,0,0,0,0,0,0,0,13,2
0,2,13,0,0,0,0,0,0,0,0,0,0,0,0,0,13,2
0,0,3,13,0,0,13,13,0,0,0,13,13,0,0,13,3,0
0,0,3,13,0,0,16,13,0,0,0,13,16,0,0,13,3,0
0,0,3,13,0,0,13,13,0,0,0,13,13,0,0,13,3,0
0,2,13,0,0,0,0,0,0,0,0,0,0,0,0,0,13,2
0,2,13,0,0,0,0,0,0,0,0,0,0,0,0,0,13,2
0,0,3,13,0,0,13,13,0,0,0,13,13,0,0,13,3,0
0,0,3,13,0,0,16,13,0,0,0,13,16,0,0,13,3,0
0,0,3,13,0,0,13,13,0,0,0,13,13,0,0,13,3,0
0,2,13,0,0,0,0,0,0,0,0,0,0,0,0,0,13,2
6,2,13,0,0,0,0,0,0,0,0,0,0,0,0,0,13,2
6,0,3,13,0,0,0,0,0,0,0,0,0,0,0,13,3,0
6,0,3,13,0,0,2,0,0,0,0,0,2,0,0,13,3,0
0,0,3,13,0,0,0,0,0,0,0,0,0,0,0,13,3,0
0,2,13,0,0,0,0,0,0,2,0,0,0,0,0,0,13,2
0,2,13,0,0,0,0,0,45,2,0,0,0,0,0,0,13,2
0,0,3,13,0,0,0,0,46,0,0,0,0,0,0,13,3,0
0,0,3,13,0,0,2,0,0,0,0,0,2,0,0,13,3,0
0,0,3,13,0,0,0,0,0,0,0,0,0,0,0,13,3,0
0,2,13,0,0,0,0,0,0,0,0,0,0,0,0,0,13,2
0,2,13,0,0,0,0,0,0,0,0,0,0,0,0,0,13,2
0,0,3,13,0,0,0,0,0,0,0,0,0,0,0,13,3,0
0,0,3,13,13,13,61,60,0,0,0,57,56,13,13,13,3,0
0,0,3,16,16,16,16,7,26,26,26,7,16,16,16,16,3,0
0,2,2,11,2,53,2,11,53,0,11,53,2,11,2,53,2,2
0,0,0,3,2,8,18,18,2,0,2,18,18,54,8,2,0,0
0,0,0,3,0,2,3,3,2,0,2,3,3,2,3,2,0,0
0,0,0,2,2,55,2,2,2,0,2,2,2,55,2,2,0,0
0,0,0,3,3,3,3,3,2,58,2,3,3,3,3,3,0,0
0,0,0,25,8,25,0,0,0,0,0,0,0,25,8,25,0,0
0,0,0,25,8,25,0,0,0,0,0,0,0,25,8,25,0,0
0,0,0,25,8,3,3,2,3,16,3,2,3,3,8,25,0,0
0,0,0,25,8,3,3,2,0,0,0,2,3,3,8,25,0,0
0,0,0,0,0,0,0,2,0,59,0,2,0,0,0,0,0,0
0,0,0,0,0,0,0,0,0,0,0,0,0,0,0,0,0,0
0,0,0,0,0,0,0,0,0,0,0,0,0,0,0,0,0,0
0,0,0,0,0,0,0,0,0,0,0,0,0,0,0,0,0,0
0,0,0,0,0,0,0,0,0,0,0,0,0,0,0,0,0,0
0,0,0,0,0,0,0,0,0,0,0,0,0,0,0,0,0,0
0,0,0,0,0,0,0,0,0,0,0,0,0,0,0,0,0,0
0,0,0,0,0,0,0,0,0,0,0,0,0,0,0,0,0,0
0,0,0,0,0,0,0,0,0,0,0,0,0,0,0,0,0,0
:endlayer
layer: 4
0,0,0,0,0,0,0,0,0,0,0,0,0,0,0,0,0,0
0,2,2,14,0,15,2,14,15,2,14,15,2,14,0,15,2,2
0,2,3,2,2,2,16,2,2,27,2,2,16,2,2,2,3,0
0,0,3,13,13,13,0,13,13,0,13,13,0,13,13,13,3,0
0,2,3,13,0,0,0,0,0,0,0,0,0,0,0,13,3,0
0,2,13,0,0,0,0,0,0,0,0,0,0,0,0,0,13,2
0,2,13,0,0,0,0,0,0,0,0,0,0,0,0,0,13,2
0,0,3,13,0,0,13,13,0,0,0,13,13,0,0,13,3,0
0,0,3,13,0,73,2,13,0,0,0,13,2,62,0,13,3,0
0,2,3,13,0,0,13,13,0,0,0,13,13,0,0,13,3,0
0,2,13,0,0,0,0,0,0,0,0,0,0,0,0,0,13,2
0,2,13,0,0,0,0,0,0,0,0,0,0,0,0,0,13,2
0,0,3,13,0,0,13,13,0,0,0,13,13,0,0,13,3,0
0,0,3,13,0,73,2,13,0,0,0,13,2,62,0,13,3,0
0,0,3,13,0,0,13,13,0,0,0,13,13,0,0,13,3,0
0,2,13,0,0,0,0,0,0,0,0,0,0,0,0,0,13,2
0,2,13,0,0,0,0,0,0,0,0,0,0,0,0,0,13,2
0,0,3,13,0,0,13,13,0,0,0,13,13,0,0,13,3,0
0,0,3,13,0,73,2,13,0,0,0,13,2,62,0,13,3,0
0,0,3,13,0,0,13,13,0,0,0,13,13,0,0,13,3,0
0,2,13,0,0,0,0,0,0,0,0,0,0,0,0,0,13,2
0,2,13,0,0,0,0,0,0,0,0,0,0,0,0,0,13,2
0,0,3,13,0,0,13,13,0,0,0,13,13,0,0,13,3,0
0,0,3,13,0,73,2,13,0,0,0,13,2,62,0,13,3,0
0,0,3,13,0,0,13,13,0,0,0,13,13,0,0,13,3,0
0,2,13,0,0,0,0,0,0,0,0,0,0,0,0,0,13,2
0,2,13,0,0,0,0,0,0,0,0,0,0,0,0,0,13,2
0,0,3,13,0,0,13,13,0,0,0,13,13,0,0,13,3,0
0,0,3,13,0,73,2,13,0,0,0,13,2,62,0,13,3,0
0,0,3,13,0,0,13,13,0,0,0,13,13,0,0,13,3,0
0,2,13,0,0,0,0,0,0,0,0,0,0,0,0,0,13,2
0,2,13,0,0,0,0,0,0,0,0,0,0,0,0,0,13,2
0,0,3,13,0,0,0,0,0,0,0,0,0,0,0,13,3,0
0,0,3,13,0,73,2,0,0,0,0,0,2,62,0,13,3,0
0,0,3,13,0,0,0,0,0,0,0,0,0,0,0,13,3,0
0,2,13,0,0,0,0,0,0,2,0,0,0,0,0,0,13,2
0,2,13,0,0,0,0,0,0,2,0,0,0,0,0,0,13,2
0,0,3,13,0,0,0,0,0,45,46,0,0,0,0,13,3,0
0,0,3,13,0,73,2,0,0,0,0,0,2,62,0,13,3,0
0,0,3,13,0,0,63,0,0,0,0,0,63,0,0,13,3,0
0,2,13,0,0,0,0,0,0,0,0,0,0,0,0,0,13,2
0,2,13,0,0,0,0,0,0,0,0,0,0,0,0,0,13,2
0,0,3,13,0,0,0,0,0,0,0,0,0,0,0,13,3,0
0,0,3,13,13,13,72,71,0,0,0,65,64,13,13,13,3,0
0,0,3,16,16,16,16,7,26,26,26,7,16,16,16,16,3,0
0,2,2,14,2,15,2,14,70,67,66,15,2,14,2,15,2,2
0,0,0,3,2,8,54,18,2,0,2,18,18,18,8,3,0,0
0,0,0,3,3,3,3,2,2,0,2,3,3,3,3,3,0,0
0,0,0,2,0,55,0,2,2,68,2,2,0,55,0,2,0,0
0,0,0,0,0,0,0,0,2,2,2,0,0,0,0,0,0,0
0,0,0,0,0,0,0,0,0,69,0,0,0,0,0,0,0,0
0,0,0,0,0,0,0,0,0,0,0,0,0,0,0,0,0,0
0,0,0,0,0,25,8,2,3,16,3,2,8,25,0,0,0,0
0,0,0,0,0,25,8,2,11,0,53,2,8,25,0,0,0,0
0,0,0,0,0,0,0,2,0,0,0,2,0,0,0,0,0,0
0,0,0,0,0,0,0,0,0,0,0,0,0,0,0,0,0,0
0,0,0,0,0,0,0,0,0,0,0,0,0,0,0,0,0,0
0,0,0,0,0,0,0,0,0,0,0,0,0,0,0,0,0,0
0,0,0,0,0,0,0,0,0,0,0,0,0,0,0,0,0,0
0,0,0,0,0,0,0,0,0,0,0,0,0,0,0,0,0,0
0,0,0,0,0,0,0,0,0,0,0,0,0,0,0,0,0,0
0,0,0,0,0,0,0,0,0,0,0,0,0,0,0,0,0,0
0,0,0,0,0,0,0,0,0,0,0,0,0,0,0,0,0,0
:endlayer
layer: 5
0,0,0,0,0,0,0,0,0,0,0,0,0,0,0,0,0,0
0,2,2,11,0,53,2,11,53,2,11,53,2,11,0,53,2,2
0,2,3,2,2,2,16,2,2,27,2,2,16,2,2,2,3,0
0,2,3,74,74,74,76,0,0,0,0,0,76,74,74,74,3,0
0,2,3,74,74,74,76,0,0,0,0,0,76,74,74,74,3,0
0,2,74,74,74,74,76,0,0,0,0,0,76,74,74,74,74,2
0,2,74,74,74,74,76,0,0,0,0,0,76,74,74,74,74,2
0,2,3,74,74,74,76,81,0,0,0,77,76,74,74,74,3,0
0,2,3,27,75,75,2,81,0,0,0,77,2,75,75,27,3,0
0,2,3,74,74,74,76,81,0,0,0,77,76,74,74,74,3,0
0,2,74,74,74,74,76,0,0,0,0,0,76,74,74,74,74,2
0,2,74,74,74,74,76,0,0,0,0,0,76,74,74,74,74,2
0,0,3,74,74,74,76,81,0,0,0,77,76,74,74,74,3,0
0,0,3,27,75,75,2,81,0,0,0,77,2,75,75,27,3,0
0,0,3,74,74,74,76,81,0,0,0,77,76,74,74,74,3,0
0,2,74,74,74,74,76,0,0,0,0,0,76,74,74,74,74,2
0,2,74,74,74,74,76,0,0,0,0,0,76,74,74,74,74,2
0,0,3,74,74,74,76,81,0,0,0,77,76,74,74,74,3,0
0,0,3,27,75,75,2,81,0,0,0,77,2,75,75,27,3,0
0,0,3,74,74,74,76,81,0,0,0,77,76,74,74,74,3,0
0,2,74,74,74,74,76,0,0,0,0,0,76,74,74,74,74,2
0,2,74,74,74,74,76,0,0,0,0,0,76,74,74,74,74,2
0,0,3,74,74,74,76,81,0,0,0,77,76,74,74,74,3,0
0,0,3,27,75,75,2,81,0,0,0,77,2,75,75,75,3,0
0,0,3,74,74,74,76,81,0,0,0,77,76,74,74,74,3,0
0,2,74,74,74,74,76,0,0,0,0,0,76,74,74,74,74,2
0,2,74,74,74,74,76,0,0,0,0,0,76,74,74,74,74,2
0,0,3,74,74,74,76,81,0,0,0,77,76,74,74,74,3,0
0,0,3,27,75,75,2,81,0,0,0,77,2,75,75,75,3,0
0,0,3,74,74,74,76,81,0,0,0,77,76,74,74,74,3,0
0,2,74,74,74,74,76,0,0,0,0,0,76,74,74,74,74,2
0,2,74,74,74,74,76,0,0,0,0,0,76,74,74,74,74,2
0,0,3,74,74,74,76,0,0,0,0,0,76,74,74,74,3,0
0,0,3,75,75,75,2,75,75,75,75,75,2,75,75,27,3,0
0,0,3,74,74,74,76,74,0,0,0,74,76,74,74,74,3,0
0,2,74,74,74,74,76,74,0,2,46,74,76,74,74,74,74,2
0,2,74,74,74,74,76,74,0,2,45,74,76,74,74,74,74,2
0,0,3,74,74,74,76,74,0,0,0,74,76,74,74,74,3,0
0,0,3,75,75,75,2,75,75,75,75,75,2,75,75,27,3,0
0,0,3,74,74,74,76,74,74,74,74,74,76,74,74,74,3,0
0,2,74,74,74,74,76,74,74,74,74,74,76,74,74,74,74,2
0,2,74,74,74,74,76,74,74,74,74,74,76,74,74,74,74,2
0,0,3,74,74,74,76,74,74,74,74,74,76,74,74,74,3,0
0,0,3,74,74,74,76,74,74,74,74,74,76,74,74,74,3,0
0,0,3,2,2,2,76,7,7,7,7,7,76,2,2,2,3,0
0,2,2,11,2,53,2,11,53,2,11,53,2,11,2,53,2,2
0,0,0,3,2,8,18,18,2,2,2,18,18,18,8,3,0,0
0,0,0,3,3,3,3,2,2,2,2,3,3,3,3,3,0,0
0,0,0,2,0,55,0,2,2,2,2,2,0,55,0,2,0,0
0,0,0,0,0,0,0,0,2,2,2,0,0,0,0,0,0,0
0,0,0,0,0,0,0,0,78,78,78,0,0,0,0,0,0,0
0,0,0,0,0,0,0,0,21,21,21,0,0,0,0,0,0,0
0,0,0,0,0,0,0,25,8,8,8,25,0,0,0,0,0,0
0,0,0,0,0,0,0,25,8,8,8,25,0,0,0,0,0,0
0,0,0,0,0,0,0,2,80,46,79,2,0,0,0,0,0,0
0,0,0,0,0,0,0,0,0,0,0,0,0,0,0,0,0,0
0,0,0,0,0,0,0,0,0,0,0,0,0,0,0,0,0,0
0,0,0,0,0,0,0,0,0,0,0,0,0,0,0,0,0,0
0,0,0,0,0,0,0,0,0,0,0,0,0,0,0,0,0,0
0,0,0,0,0,0,0,0,0,0,0,0,0,0,0,0,0,0
0,0,0,0,0,0,0,0,0,0,0,0,0,0,0,0,0,0
0,0,0,0,0,0,0,0,0,0,0,0,0,0,0,0,0,0
0,0,0,0,0,0,0,0,0,0,0,0,0,0,0,0,0,0
:endlayer
layer: 6
0,0,0,0,0,0,0,0,0,0,0,0,0,0,0,0,0,0
0,2,2,14,0,15,2,14,15,2,14,15,2,14,0,15,2,2
0,78,2,2,2,2,16,2,2,27,2,2,16,2,2,2,2,78
0,0,19,13,13,13,118,0,0,111,0,0,82,13,13,13,19,0
0,67,2,13,0,0,119,0,0,0,0,0,83,0,0,13,2,67
0,2,16,0,0,0,120,0,0,0,0,0,84,0,0,0,16,2
0,2,16,0,0,0,121,0,0,0,0,0,85,0,0,0,16,2
0,78,2,13,0,0,122,0,0,0,0,0,86,0,0,13,2,78
0,0,19,13,0,0,2,0,0,0,0,0,2,0,0,13,19,0
0,67,2,13,0,0,123,0,0,0,0,0,87,0,0,13,2,67
0,2,16,0,0,0,124,0,0,0,0,0,88,0,0,0,16,2
0,2,16,0,0,0,125,0,0,0,0,0,89,0,0,0,16,2
0,78,2,13,0,0,126,0,0,0,0,0,90,0,0,13,2,78
0,0,19,13,0,0,2,0,0,0,0,0,2,0,0,13,19,0
0,67,2,13,0,0,127,0,0,0,0,0,91,0,0,13,2,67
0,2,16,0,0,0,128,0,0,0,0,0,92,0,0,0,16,2
0,2,16,0,0,0,129,0,0,0,0,0,93,0,0,0,16,2
0,78,2,13,0,0,130,0,0,0,0,0,94,0,0,13,2,78
0,0,19,13,0,0,2,0,0,0,0,0,2,0,0,13,19,0
0,67,2,13,0,0,131,0,0,0,0,0,95,0,0,13,2,67
0,2,16,0,0,0,132,0,0,0,0,0,96,0,0,0,16,2
0,2,16,0,0,0,133,0,0,0,0,0,97,0,0,0,16,2
0,78,2,13,0,0,134,0,0,0,0,0,98,0,0,13,2,78
0,0,19,13,0,0,2,0,0,0,0,0,2,0,0,13,19,0
0,67,2,13,0,0,135,0,0,0,0,0,99,0,0,13,2,67
0,2,16,0,0,0,136,0,0,0,0,0,100,0,0,0,16,2
0,2,16,0,0,0,137,0,0,0,0,0,101,0,0,0,16,2
0,78,2,13,0,0,138,0,0,0,0,0,102,0,0,13,2,78
0,0,19,13,0,0,2,0,0,0,0,0,2,0,0,13,19,0
0,67,2,13,0,0,139,0,0,0,0,0,103,0,0,13,2,67
0,2,16,0,0,0,140,0,0,0,0,0,104,0,0,0,16,2
0,2,16,0,0,0,141,0,0,0,0,0,105,0,0,0,16,2
0,78,2,13,0,0,142,0,0,0,0,0,106,0,0,13,2,78
0,0,19,13,0,0,2,116,114,112,109,107,2,0,0,13,19,0
0,67,2,13,0,0,143,0,0,46,45,0,0,0,0,13,2,67
0,2,16,0,0,0,144,0,0,2,0,0,0,0,0,0,16,2
0,2,16,0,0,0,145,0,0,2,0,0,0,0,0,0,16,2
0,78,2,13,0,0,146,0,0,0,0,0,0,0,0,13,2,78
0,0,19,13,0,0,2,117,115,113,110,108,2,0,0,13,19,0
0,67,2,13,0,0,0,0,0,0,0,0,0,0,0,13,2,67
0,2,16,0,0,0,0,0,0,0,0,0,0,0,0,0,16,2
0,2,16,0,0,0,0,13,13,13,13,13,0,0,0,0,16,2
0,78,2,13,0,0,0,0,0,0,0,0,0,0,0,13,2,78
0,0,19,13,13,13,0,13,13,13,13,13,0,13,13,13,19,0
0,67,2,2,2,2,0,2,2,3,2,2,0,2,2,2,2,67
0,2,2,14,2,15,2,14,15,2,14,15,2,14,2,53,2,2
0,0,0,3,2,8,54,54,2,2,2,54,54,54,8,3,0,0
0,0,0,3,3,3,3,2,2,2,2,3,3,3,3,3,0,0
0,0,0,2,0,55,0,2,2,2,2,2,0,55,0,2,0,0
0,0,0,0,0,0,0,63,2,2,2,63,0,0,0,0,0,0
0,0,0,0,0,0,0,0,8,8,8,0,0,0,0,0,0,0
0,0,0,0,0,0,0,0,25,25,25,0,0,0,0,0,0,0
0,0,0,0,0,0,0,0,0,0,0,0,0,0,0,0,0,0
0,0,0,0,0,0,0,0,0,0,0,0,0,0,0,0,0,0
0,0,0,0,0,0,0,0,2,2,2,0,0,0,0,0,0,0
0,0,0,0,0,0,0,0,0,0,0,0,0,0,0,0,0,0
0,0,0,0,0,0,0,0,0,0,0,0,0,0,0,0,0,0
0,0,0,0,0,0,0,0,0,0,0,0,0,0,0,0,0,0
0,0,0,0,0,0,0,0,0,0,0,0,0,0,0,0,0,0
0,0,0,0,0,0,0,0,0,0,0,0,0,0,0,0,0,0
0,0,0,0,0,0,0,0,0,0,0,0,0,0,0,0,0,0
0,0,0,0,0,0,0,0,0,0,0,0,0,0,0,0,0,0
0,0,0,0,0,0,0,0,0,0,0,0,0,0,0,0,0,0
:endlayer
layer: 7
0,0,0,0,0,0,0,0,0,0,0,0,0,0,0,0,0,0
0,147,2,11,0,53,2,11,53,2,11,53,2,11,0,53,2,147
0,2,16,2,2,2,16,2,2,27,2,2,16,2,2,2,16,2
0,2,16,13,13,13,0,155,154,152,151,150,0,13,13,13,16,2
0,2,16,13,0,0,0,0,0,0,0,0,0,0,0,13,16,2
0,17,16,0,0,0,0,0,0,0,0,0,0,0,0,0,16,17
0,147,16,0,0,0,0,0,0,0,0,0,0,0,0,0,16,147
0,2,16,13,0,0,0,0,0,0,0,0,0,0,0,13,16,2
0,2,16,13,0,73,2,62,0,0,0,73,2,62,0,13,16,2
0,2,16,13,0,0,0,0,0,0,0,0,0,0,0,13,16,2
0,17,16,0,0,0,0,0,0,0,0,0,0,0,0,0,16,17
0,147,16,0,0,0,0,0,0,0,0,0,0,0,0,0,16,147
0,2,16,13,0,0,0,0,0,0,0,0,0,0,0,13,16,2
0,2,16,13,0,73,2,62,0,0,0,73,2,62,0,13,16,2
0,2,16,13,0,0,0,0,0,0,0,0,0,0,0,13,16,2
0,17,16,0,0,0,0,0,0,0,0,0,0,0,0,0,16,17
0,147,16,0,0,0,0,0,0,0,0,0,0,0,0,0,16,147
0,2,16,13,0,0,0,0,0,0,0,0,0,0,0,13,16,2
0,2,16,13,0,73,2,62,0,0,0,73,2,62,0,13,16,2
0,2,16,13,0,0,0,0,0,0,0,0,0,0,0,13,16,2
0,17,16,0,0,0,0,0,0,0,0,0,0,0,0,0,16,17
0,147,16,0,0,0,0,0,0,0,0,0,0,0,0,0,16,147
0,2,16,13,0,0,0,0,0,0,0,0,0,0,0,13,16,2
0,2,16,13,0,73,2,62,0,0,0,73,2,62,0,13,16,2
0,2,16,13,0,0,0,0,0,0,0,0,0,0,0,13,16,2
0,17,16,0,0,0,0,0,0,0,0,0,0,0,0,0,16,17
0,147,16,0,0,0,0,0,0,0,0,0,0,0,0,0,16,147
0,2,16,13,0,0,0,0,0,0,0,0,0,0,0,13,16,2
0,2,16,13,0,73,2,62,0,0,0,73,2,62,0,13,16,2
0,2,16,13,0,0,0,0,0,0,0,0,0,0,0,13,16,2
0,17,16,0,0,0,0,0,0,0,0,0,0,0,0,0,16,17
0,147,16,0,0,0,0,0,0,0,0,0,0,0,0,0,16,147
0,2,16,13,0,0,0,0,0,0,0,0,0,0,0,13,16,2
0,2,16,13,0,73,2,0,0,0,0,0,2,0,0,13,16,2
0,2,16,13,0,0,0,0,45,0,0,0,0,0,0,13,16,2
0,17,16,0,0,0,0,0,46,2,0,0,0,0,0,0,16,17
0,147,16,0,0,0,0,0,0,2,0,0,0,0,0,0,16,147
0,2,16,13,0,0,0,0,0,0,0,0,0,0,0,13,16,2
0,2,16,13,0,73,2,62,0,0,0,73,2,62,0,13,16,2
0,2,16,13,0,0,0,0,0,0,0,0,0,0,0,13,16,2
0,17,16,0,0,0,0,0,0,0,0,0,0,0,0,0,16,17
0,147,16,0,0,0,0,13,13,13,13,13,0,0,0,0,16,147
0,2,16,13,0,0,0,0,0,0,0,0,0,0,0,13,16,2
0,2,16,13,13,13,0,13,13,13,13,13,0,13,13,13,16,2
0,2,16,2,2,2,156,2,2,3,2,2,149,2,2,2,16,2
0,17,2,11,2,3,2,11,53,2,11,53,2,11,2,53,2,17
0,0,0,3,8,8,54,54,2,2,2,3,3,2,8,3,0,0
0,0,0,3,3,9,3,8,8,8,8,3,3,9,3,3,0,0
0,0,0,2,11,148,53,2,8,8,8,2,11,148,53,2,0,0
0,0,0,0,0,0,0,0,25,25,25,0,0,0,0,0,0,0
0,0,0,0,0,0,0,0,0,0,0,0,0,0,0,0,0,0
0,0,0,0,0,0,0,0,0,0,0,0,0,0,0,0,0,0
0,0,0,0,0,0,0,0,0,0,0,0,0,0,0,0,0,0
0,0,0,0,0,0,0,0,0,0,0,0,0,0,0,0,0,0
0,0,0,0,0,0,0,0,0,153,0,0,0,0,0,0,0,0
0,0,0,0,0,0,0,0,0,0,0,0,0,0,0,0,0,0
0,0,0,0,0,0,0,0,0,0,0,0,0,0,0,0,0,0
0,0,0,0,0,0,0,0,0,0,0,0,0,0,0,0,0,0
0,0,0,0,0,0,0,0,0,0,0,0,0,0,0,0,0,0
0,0,0,0,0,0,0,0,0,0,0,0,0,0,0,0,0,0
0,0,0,0,0,0,0,0,0,0,0,0,0,0,0,0,0,0
0,0,0,0,0,0,0,0,0,0,0,0,0,0,0,0,0,0
0,0,0,0,0,0,0,0,0,0,0,0,0,0,0,0,0,0
:endlayer
layer: 8
0,0,0,0,0,0,0,0,0,0,0,0,0,0,0,0,0,0
0,147,2,14,0,15,2,14,15,2,14,15,2,14,0,15,2,147
0,147,2,2,2,2,16,2,2,27,2,2,16,2,2,2,2,147
0,2,16,13,13,13,0,162,161,160,159,158,0,13,13,13,16,2
0,17,16,13,0,0,0,0,0,0,0,0,0,0,0,13,16,17
0,0,16,0,0,0,0,0,0,0,0,0,0,0,0,0,16,0
0,0,16,0,0,0,0,0,0,0,0,0,0,0,0,0,16,0
0,147,16,13,0,0,0,0,0,0,0,0,0,0,0,13,16,147
0,2,16,13,0,0,2,0,0,0,0,0,2,0,0,13,16,2
0,17,16,13,0,0,0,0,0,0,0,0,0,0,0,13,16,17
0,0,16,0,0,0,0,0,0,0,0,0,0,0,0,0,16,0
0,0,16,0,0,0,0,0,0,0,0,0,0,0,0,0,16,0
0,147,16,13,0,0,0,0,0,0,0,0,0,0,0,13,16,147
0,2,16,13,0,0,2,0,0,0,0,0,2,0,0,13,16,2
0,17,16,13,0,0,0,0,0,0,0,0,0,0,0,13,16,17
0,0,16,0,0,0,0,0,0,0,0,0,0,0,0,0,16,0
0,0,16,0,0,0,0,0,0,0,0,0,0,0,0,0,16,0
0,147,16,13,0,0,0,0,0,0,0,0,0,0,0,13,16,147
0,2,16,13,0,0,2,0,0,0,0,0,2,0,0,13,16,2
0,17,16,13,0,0,0,0,0,0,0,0,0,0,0,13,16,17
0,0,16,0,0,0,0,0,0,0,0,0,0,0,0,0,16,0
0,0,16,0,0,0,0,0,0,0,0,0,0,0,0,0,16,0
0,147,16,13,0,0,0,0,0,0,0,0,0,0,0,13,16,147
0,2,16,13,0,0,2,0,0,0,0,0,2,0,0,13,16,2
0,17,16,13,0,0,0,0,0,0,0,0,0,0,0,13,16,17
0,0,16,0,0,0,0,0,0,0,0,0,0,0,0,0,16,0
0,0,16,0,0,0,0,0,0,0,0,0,0,0,0,0,16,0
0,147,16,13,0,0,0,0,0,0,0,0,0,0,0,13,16,147
0,2,16,13,0,0,2,0,0,0,0,0,2,0,0,13,16,2
0,17,16,13,0,0,0,0,0,0,0,0,0,0,0,13,16,17
0,0,16,0,0,0,0,0,0,0,0,0,0,0,0,0,16,0
0,0,16,0,0,0,0,0,0,0,0,0,0,0,0,0,16,0
0,147,16,13,0,0,0,0,0,0,0,0,0,0,0,13,16,147
0,2,16,13,0,0,2,0,0,0,0,0,2,0,0,13,16,2
0,17,16,13,0,0,0,0,0,0,0,0,0,0,0,13,16,17
0,0,16,0,0,0,0,0,0,2,0,0,0,0,0,0,16,0
0,0,16,0,0,0,0,0,45,2,0,0,0,0,0,0,16,0
0,147,16,13,0,0,0,0,46,0,0,0,0,0,0,13,16,147
0,2,16,13,0,0,2,0,0,0,0,0,2,0,0,13,16,2
0,17,16,13,0,0,0,0,0,0,0,0,0,0,0,13,16,17
0,0,16,0,0,0,0,0,0,0,0,0,0,0,0,0,16,0
0,0,16,0,0,0,0,13,13,13,13,13,0,0,0,0,16,0
0,147,16,13,0,0,0,0,0,0,0,0,0,0,0,13,16,147
0,2,16,13,13,13,0,13,13,13,13,13,0,13,13,13,16,2
0,17,2,2,2,2,163,2,2,3,2,2,157,2,2,2,2,17
0,17,2,14,2,3,2,14,15,2,14,15,2,14,2,15,2,17
0,0,0,3,8,8,3,3,3,3,3,3,3,3,8,3,0,0
0,0,0,8,8,8,8,25,0,0,0,25,8,8,8,8,0,0
0,0,0,8,8,8,8,25,0,0,0,25,8,8,8,8,0,0
0,0,0,0,0,0,0,0,0,0,0,0,0,0,0,0,0,0
0,0,0,0,0,0,0,0,0,0,0,0,0,0,0,0,0,0
0,0,0,0,0,0,0,0,0,0,0,0,0,0,0,0,0,0
0,0,0,0,0,0,0,0,0,0,0,0,0,0,0,0,0,0
0,0,0,0,0,0,0,0,0,0,0,0,0,0,0,0,0,0
0,0,0,0,0,0,0,0,0,0,0,0,0,0,0,0,0,0
0,0,0,0,0,0,0,0,0,0,0,0,0,0,0,0,0,0
0,0,0,0,0,0,0,0,0,0,0,0,0,0,0,0,0,0
0,0,0,0,0,0,0,0,0,0,0,0,0,0,0,0,0,0
0,0,0,0,0,0,0,0,0,0,0,0,0,0,0,0,0,0
0,0,0,0,0,0,0,0,0,0,0,0,0,0,0,0,0,0
0,0,0,0,0,0,0,0,0,0,0,0,0,0,0,0,0,0
0,0,0,0,0,0,0,0,0,0,0,0,0,0,0,0,0,0
0,0,0,0,0,0,0,0,0,0,0,0,0,0,0,0,0,0
:endlayer
layer: 9
0,0,0,0,0,0,0,0,0,0,0,0,0,0,0,0,0,0
0,3,2,2,2,2,2,2,2,2,2,2,2,2,2,2,2,3
0,3,27,27,27,27,27,27,27,27,27,27,27,27,27,27,27,3
0,3,27,2,3,2,2,2,2,3,3,2,2,2,3,2,27,3
0,3,27,2,3,2,2,3,2,3,2,3,2,2,3,2,27,3
0,3,27,2,3,2,2,3,3,19,3,3,2,2,3,2,27,3
0,3,27,2,3,2,2,3,19,19,19,3,2,2,3,2,27,3
0,3,27,2,3,2,2,2,3,19,3,2,2,2,3,2,27,3
0,3,27,2,3,2,74,2,3,2,3,2,74,2,3,2,27,3
0,3,27,2,3,2,2,3,2,2,2,3,2,2,3,2,27,3
0,3,27,2,3,2,2,3,2,2,2,3,2,2,3,2,27,3
0,3,27,2,3,2,2,3,2,2,2,3,2,2,3,2,27,3
0,3,27,2,3,2,2,2,3,2,3,2,2,2,3,2,27,3
0,3,27,2,3,2,74,3,3,2,3,3,74,2,3,2,27,3
0,3,27,2,3,2,2,2,3,2,3,2,2,2,3,2,27,3
0,3,27,2,3,2,2,3,2,2,2,3,2,2,3,2,27,3
0,3,27,2,3,2,2,3,2,2,2,3,2,2,3,2,27,3
0,3,27,2,3,2,2,2,3,2,3,2,2,2,3,2,27,3
0,3,27,2,3,2,74,3,3,2,3,3,74,2,3,2,27,3
0,3,27,2,3,2,2,2,3,2,3,2,2,2,3,2,27,3
0,3,27,2,3,2,2,3,2,2,2,3,2,2,3,2,27,3
0,3,27,2,3,2,2,3,2,2,2,3,2,2,3,2,27,3
0,3,27,2,3,2,2,2,3,2,3,2,2,2,3,2,27,3
0,3,27,2,3,2,74,3,3,2,3,3,74,2,3,2,27,3
0,3,27,2,3,2,2,2,3,2,3,2,2,2,3,2,27,3
0,3,27,2,3,2,2,3,2,2,2,3,2,2,3,2,27,3
0,3,27,2,3,2,2,3,2,2,2,3,2,2,3,2,27,3
0,3,27,2,3,2,2,2,3,2,3,2,2,2,3,2,27,3
0,3,27,2,3,2,74,3,3,2,3,3,74,2,3,2,27,3
0,3,27,2,3,2,2,2,3,2,3,2,2,2,3,2,27,3
0,3,27,2,3,2,2,3,2,2,2,3,2,2,3,2,27,3
0,3,27,2,3,2,2,3,2,2,2,3,2,2,3,2,27,3
0,3,27,2,3,2,2,2,3,2,3,2,2,2,3,2,27,3
0,3,27,2,3,2,74,3,3,2,3,3,74,2,3,2,27,3
0,3,27,2,3,2,2,3,0,0,0,3,2,2,3,2,27,3
0,3,27,2,3,2,2,3,0,2,0,3,2,2,3,2,27,3
0,3,27,2,3,2,2,3,0,2,0,3,2,2,3,2,27,3
0,3,27,2,3,2,2,3,0,45,46,3,2,2,3,2,27,3
0,3,27,2,3,2,74,3,3,2,3,3,2,2,3,2,27,3
0,3,27,2,3,2,2,2,3,2,3,2,2,2,3,2,27,3
0,3,27,2,3,2,2,3,2,2,2,3,2,2,3,2,27,3
0,3,27,2,3,2,2,2,3,2,3,2,2,2,3,2,27,3
0,3,27,2,3,2,2,2,3,2,3,2,2,2,3,2,27,3
0,3,27,2,3,2,2,2,3,2,3,2,2,2,3,2,27,3
0,3,27,3,3,3,27,27,27,27,27,27,27,3,3,3,27,3
0,3,2,2,2,2,2,2,2,2,2,2,2,2,2,2,2,3
0,0,0,25,25,25,2,2,2,2,2,2,2,25,25,25,0,0
0,0,0,0,0,0,0,0,0,0,0,0,0,0,0,0,0,0
0,0,0,0,0,0,0,0,0,0,0,0,0,0,0,0,0,0
0,0,0,0,0,0,0,0,0,0,0,0,0,0,0,0,0,0
0,0,0,0,0,0,0,0,0,0,0,0,0,0,0,0,0,0
0,0,0,0,0,0,0,0,0,0,0,0,0,0,0,0,0,0
0,0,0,0,0,0,0,0,0,0,0,0,0,0,0,0,0,0
0,0,0,0,0,0,0,0,0,0,0,0,0,0,0,0,0,0
0,0,0,0,0,0,0,0,0,0,0,0,0,0,0,0,0,0
0,0,0,0,0,0,0,0,0,0,0,0,0,0,0,0,0,0
0,0,0,0,0,0,0,0,0,0,0,0,0,0,0,0,0,0
0,0,0,0,0,0,0,0,0,0,0,0,0,0,0,0,0,0
0,0,0,0,0,0,0,0,0,0,0,0,0,0,0,0,0,0
0,0,0,0,0,0,0,0,0,0,0,0,0,0,0,0,0,0
0,0,0,0,0,0,0,0,0,0,0,0,0,0,0,0,0,0
0,0,0,0,0,0,0,0,0,0,0,0,0,0,0,0,0,0
0,0,0,0,0,0,0,0,0,0,0,0,0,0,0,0,0,0
:endlayer
layer: 10
0,0,0,0,0,0,0,0,0,0,0,0,0,0,0,0,0,0
0,3,164,164,147,147,164,147,147,147,147,147,164,147,147,164,164,3
0,70,2,2,2,2,2,2,2,2,2,2,2,2,2,2,2,66
0,70,2,201,200,0,77,166,166,74,166,166,81,0,0,0,2,66
0,15,3,0,27,0,77,76,76,76,76,76,81,0,27,0,3,14
0,15,3,0,0,0,77,76,76,76,76,76,81,0,0,0,3,14
0,15,3,0,0,0,77,76,76,76,76,76,81,0,0,0,3,14
0,15,3,0,0,0,77,76,76,76,76,76,81,0,0,0,3,14
0,70,2,0,0,0,2,167,167,167,167,167,2,0,0,0,2,66
0,15,3,0,0,0,0,0,0,0,0,0,0,0,0,0,3,14
0,15,3,0,0,0,0,0,0,0,0,0,0,0,0,0,3,14
0,15,3,0,0,0,0,0,0,0,0,0,0,0,0,0,3,14
0,15,3,0,0,0,0,0,0,0,0,0,0,0,0,0,3,14
0,70,2,0,0,0,2,192,184,0,176,168,2,0,0,0,2,66
0,15,3,0,0,0,0,0,0,0,0,0,0,0,0,0,3,14
0,15,3,0,0,0,0,193,185,0,177,169,0,0,0,0,3,14
0,15,3,0,0,0,0,0,0,0,0,0,0,0,0,0,3,14
0,15,3,0,0,0,0,194,186,0,178,170,0,0,0,0,3,14
0,70,2,0,0,0,2,0,0,0,0,0,2,0,0,0,2,66
0,15,3,0,0,0,0,195,187,0,179,171,0,0,0,0,3,14
0,15,3,0,0,0,0,0,0,0,0,0,0,0,0,0,3,14
0,15,3,0,0,0,0,196,188,0,180,172,0,0,0,0,3,14
0,15,3,0,0,0,0,0,0,0,0,0,0,0,0,0,14,14
0,70,2,0,0,0,2,197,189,0,181,173,2,0,0,0,2,66
0,15,3,0,0,0,0,0,0,0,0,0,0,0,0,0,3,14
0,15,3,0,0,0,0,198,190,0,182,174,0,0,0,0,3,14
0,15,3,0,0,0,0,0,0,0,0,0,0,0,0,0,3,14
0,15,3,0,0,0,0,199,191,0,183,175,0,0,0,0,3,14
0,70,2,0,0,0,2,0,0,0,0,0,2,0,0,0,2,66
0,15,3,0,0,0,0,0,0,0,0,0,0,0,0,0,3,14
0,15,3,0,0,0,0,0,0,0,0,0,0,0,0,0,3,14
0,15,3,0,0,0,0,0,0,0,0,0,0,0,0,0,3,14
0,15,3,0,0,0,0,0,0,0,0,0,0,0,0,0,3,14
0,70,2,0,0,0,2,0,0,0,0,0,2,0,0,0,2,66
0,15,3,0,0,0,0,0,0,0,0,0,0,0,0,0,3,14
0,15,3,0,0,0,0,0,0,2,46,0,0,0,0,0,3,14
0,15,3,0,0,0,0,0,0,2,45,0,0,0,0,0,3,14
0,15,3,0,0,0,0,0,0,0,0,0,0,0,0,0,3,14
0,70,2,0,0,0,2,0,0,0,0,0,2,0,0,0,2,66
0,15,3,0,0,0,0,0,0,0,0,0,0,0,0,0,3,14
0,15,3,0,0,0,0,0,0,0,0,0,0,0,0,0,3,14
0,15,3,0,0,0,0,0,0,0,0,0,0,0,0,0,3,14
0,15,3,0,0,0,0,0,0,0,0,0,0,0,0,0,3,14
0,70,2,0,0,0,0,0,0,0,0,0,0,0,0,0,2,66
0,70,2,0,0,0,2,2,2,2,2,2,2,0,0,0,2,66
0,3,165,0,0,0,165,165,165,165,165,165,165,0,0,0,165,3
0,0,0,0,0,0,0,0,0,0,0,0,0,0,0,0,0,0
0,0,0,0,0,0,0,0,0,0,0,0,0,0,0,0,0,0
0,0,0,0,0,0,0,0,0,0,0,0,0,0,0,0,0,0
0,0,0,0,0,0,0,0,0,0,0,0,0,0,0,0,0,0
0,0,0,0,0,0,0,0,0,0,0,0,0,0,0,0,0,0
0,0,0,0,0,0,0,0,0,0,0,0,0,0,0,0,0,0
0,0,0,0,0,0,0,0,0,0,0,0,0,0,0,0,0,0
0,0,0,0,0,0,0,0,0,0,0,0,0,0,0,0,0,0
0,0,0,0,0,0,0,0,0,0,0,0,0,0,0,0,0,0
0,0,0,0,0,0,0,0,0,0,0,0,0,0,0,0,0,0
0,0,0,0,0,0,0,0,0,0,0,0,0,0,0,0,0,0
0,0,0,0,0,0,0,0,0,0,0,0,0,0,0,0,0,0
0,0,0,0,0,0,0,0,0,0,0,0,0,0,0,0,0,0
0,0,0,0,0,0,0,0,0,0,0,0,0,0,0,0,0,0
0,0,0,0,0,0,0,0,0,0,0,0,0,0,0,0,0,0
0,0,0,0,0,0,0,0,0,0,0,0,0,0,0,0,0,0
0,0,0,0,0,0,0,0,0,0,0,0,0,0,0,0,0,0
:endlayer
layer: 11
0,0,0,0,0,0,0,0,0,0,0,0,0,0,0,0,0,0
0,0,0,0,0,0,0,0,0,0,0,0,0,0,0,0,0,0
0,0,2,2,202,202,2,3,3,3,3,3,2,202,202,2,2,0
0,0,2,0,0,0,0,0,0,231,0,0,0,0,0,0,2,0
0,0,3,0,27,0,257,245,233,0,219,207,203,0,27,0,3,0
0,0,202,0,0,0,258,246,234,0,220,208,204,0,0,0,202,0
0,0,202,0,0,0,259,247,235,0,221,209,205,0,0,0,202,0
0,0,3,0,0,0,260,248,236,232,222,210,206,0,0,0,3,0
0,0,2,0,0,0,2,0,0,0,0,0,2,0,0,0,2,0
0,0,3,0,0,0,0,0,0,0,0,0,0,0,0,0,3,0
0,0,202,0,0,0,0,0,0,0,0,0,0,0,0,0,202,0
0,0,202,0,0,0,0,0,0,0,0,0,0,0,0,0,202,0
0,0,3,0,0,0,0,0,0,0,0,0,0,0,0,0,3,0
0,0,2,0,0,0,2,249,237,0,223,211,2,0,0,0,2,0
0,0,3,0,0,0,0,0,0,0,0,0,0,0,0,0,3,0
0,0,202,0,0,0,0,250,238,0,224,212,0,0,0,0,202,0
0,0,202,0,0,0,0,0,0,0,0,0,0,0,0,0,202,0
0,0,3,0,0,0,0,251,239,0,225,213,0,0,0,0,3,0
0,0,2,0,0,0,2,0,0,0,0,0,2,0,0,0,2,0
0,0,3,0,0,0,0,252,240,0,226,214,0,0,0,0,3,0
0,0,202,0,0,0,0,0,0,0,0,0,0,0,0,0,202,0
0,0,202,0,0,0,0,253,241,0,227,215,0,0,0,0,202,0
0,0,3,0,0,0,0,0,0,0,0,0,0,0,0,0,3,0
0,0,2,0,0,0,2,254,242,0,228,216,2,0,0,0,2,0
0,0,3,0,0,0,0,0,0,0,0,0,0,0,0,0,3,0
0,0,202,0,0,0,0,255,243,0,229,217,0,0,0,0,202,0
0,0,202,0,0,0,0,0,0,0,0,0,0,0,0,0,202,0
0,0,3,0,0,0,0,256,244,0,230,218,0,0,0,0,3,0
0,0,2,0,0,0,2,0,0,0,0,0,2,0,0,0,2,0
0,0,3,0,0,0,0,0,0,0,0,0,0,0,0,0,3,0
0,0,202,0,0,0,0,0,0,0,0,0,0,0,0,0,202,0
0,0,202,0,0,0,0,0,0,0,0,0,0,0,0,0,202,0
0,0,3,0,0,0,0,0,0,0,0,0,0,0,0,0,3,0
0,0,2,0,0,0,2,0,0,0,0,0,2,0,0,0,2,0
0,0,3,0,0,0,0,0,0,46,45,0,0,0,0,0,3,0
0,0,202,0,0,0,0,0,0,2,0,0,0,0,0,0,202,0
0,0,202,0,0,0,0,0,0,2,0,0,0,0,0,0,202,0
0,0,3,0,0,0,0,0,0,0,0,0,0,0,0,0,3,0
0,0,2,0,0,0,2,0,0,0,0,0,2,0,0,0,2,0
0,0,3,0,0,0,0,0,0,0,0,0,0,0,0,0,3,0
0,0,202,0,0,0,0,0,0,0,0,0,0,0,0,0,202,0
0,0,202,0,0,0,0,0,0,0,0,0,0,0,0,0,202,0
0,0,3,0,0,0,0,0,0,0,0,0,0,0,0,0,3,0
0,0,2,0,0,0,0,0,0,0,0,0,0,0,0,0,2,0
0,0,2,0,0,0,2,3,2,202,2,3,2,0,0,0,2,0
0,0,0,0,0,0,0,0,0,0,0,0,0,0,0,0,0,0
0,0,0,0,0,0,0,0,0,0,0,0,0,0,0,0,0,0
0,0,0,0,0,0,0,0,0,0,0,0,0,0,0,0,0,0
0,0,0,0,0,0,0,0,0,0,0,0,0,0,0,0,0,0
0,0,0,0,0,0,0,0,0,0,0,0,0,0,0,0,0,0
0,0,0,0,0,0,0,0,0,0,0,0,0,0,0,0,0,0
0,0,0,0,0,0,0,0,0,0,0,0,0,0,0,0,0,0
0,0,0,0,0,0,0,0,0,0,0,0,0,0,0,0,0,0
0,0,0,0,0,0,0,0,0,0,0,0,0,0,0,0,0,0
0,0,0,0,0,0,0,0,0,0,0,0,0,0,0,0,0,0
0,0,0,0,0,0,0,0,0,0,0,0,0,0,0,0,0,0
0,0,0,0,0,0,0,0,0,0,0,0,0,0,0,0,0,0
0,0,0,0,0,0,0,0,0,0,0,0,0,0,0,0,0,0
0,0,0,0,0,0,0,0,0,0,0,0,0,0,0,0,0,0
0,0,0,0,0,0,0,0,0,0,0,0,0,0,0,0,0,0
0,0,0,0,0,0,0,0,0,0,0,0,0,0,0,0,0,0
0,0,0,0,0,0,0,0,0,0,0,0,0,0,0,0,0,0
0,0,0,0,0,0,0,0,0,0,0,0,0,0,0,0,0,0
:endlayer
layer: 12
0,0,0,0,0,0,0,0,0,0,0,0,0,0,0,0,0,0
0,0,0,0,0,0,0,0,0,0,0,0,0,0,0,0,0,0
0,0,2,2,202,202,2,3,202,202,202,3,2,202,202,2,2,0
0,0,2,0,0,0,0,0,0,0,0,0,0,0,0,0,2,0
0,0,3,0,27,0,282,278,274,0,269,265,261,0,27,0,3,0
0,0,202,0,0,0,283,279,275,0,270,266,262,0,0,0,202,0
0,0,202,0,0,0,284,280,276,0,271,267,263,0,0,0,202,0
0,0,3,0,0,0,285,281,277,273,272,268,264,0,0,0,3,0
0,0,2,0,0,73,2,0,0,0,0,0,2,62,0,0,2,0
0,0,3,0,0,0,0,0,0,0,0,0,0,0,0,0,3,0
0,0,202,0,0,0,0,0,0,0,0,0,0,0,0,0,202,0
0,0,202,0,0,0,0,0,0,0,0,0,0,0,0,0,202,0
0,0,3,0,0,0,0,0,0,0,0,0,0,0,0,0,3,0
0,0,2,0,0,73,2,0,0,0,0,0,2,62,0,0,2,0
0,0,3,0,0,0,0,0,0,0,0,0,0,0,0,0,3,0
0,0,202,0,0,0,0,0,0,0,0,0,0,0,0,0,202,0
0,0,202,0,0,0,0,0,0,0,0,0,0,0,0,0,202,0
0,0,3,0,0,0,0,0,0,0,0,0,0,0,0,0,3,0
0,0,2,0,0,73,2,0,0,0,0,0,2,62,0,0,2,0
0,0,3,0,0,0,0,0,0,0,0,0,0,0,0,0,3,0
0,0,202,0,0,0,0,0,0,0,0,0,0,0,0,0,202,0
0,0,202,0,0,0,0,0,0,0,0,0,0,0,0,0,202,0
0,0,3,0,0,0,0,0,0,0,0,0,0,0,0,0,3,0
0,0,2,0,0,73,2,0,0,0,0,0,2,62,0,0,2,0
0,0,3,0,0,0,0,0,0,0,0,0,0,0,0,0,3,0
0,0,202,0,0,0,0,0,0,0,0,0,0,0,0,0,202,0
0,0,202,0,0,0,0,0,0,0,0,0,0,0,0,0,202,0
0,0,3,0,0,0,0,0,0,0,0,0,0,0,0,0,3,0
0,0,2,0,0,73,2,0,0,0,0,0,2,62,0,0,2,0
0,0,3,0,0,0,0,0,0,0,0,0,0,0,0,0,3,0
0,0,202,0,0,0,0,0,0,0,0,0,0,0,0,0,202,0
0,0,202,0,0,0,0,0,0,0,0,0,0,0,0,0,202,0
0,0,3,0,0,0,0,0,0,0,0,0,0,0,0,0,3,0
0,0,2,0,0,0,2,0,0,0,0,0,2,62,0,0,2,0
0,0,3,0,0,0,0,0,45,0,0,0,0,0,0,0,3,0
0,0,202,0,0,0,0,0,46,2,0,0,0,0,0,0,202,0
0,0,202,0,0,0,0,0,0,2,0,0,0,0,0,0,202,0
0,0,3,0,0,0,0,0,0,0,0,0,0,0,0,0,3,0
0,0,2,0,0,0,2,0,0,0,0,0,2,62,0,0,2,0
0,0,3,0,0,0,0,0,0,0,0,0,0,0,0,0,3,0
0,0,202,0,0,0,0,0,0,0,0,0,0,0,0,0,202,0
0,0,202,0,0,0,0,0,0,0,0,0,0,0,0,0,202,0
0,0,3,0,0,0,0,0,0,0,0,0,0,0,0,0,3,0
0,0,2,0,0,0,0,0,0,0,0,0,0,0,0,0,2,0
0,0,2,0,0,0,2,3,2,202,2,3,2,0,0,0,2,0
0,0,63,0,0,0,63,0,0,0,0,0,63,0,0,0,63,0
0,0,0,0,0,0,0,0,0,0,0,0,0,0,0,0,0,0
0,0,0,0,0,0,0,0,0,0,0,0,0,0,0,0,0,0
0,0,0,0,0,0,0,0,0,0,0,0,0,0,0,0,0,0
0,0,0,0,0,0,0,0,0,0,0,0,0,0,0,0,0,0
0,0,0,0,0,0,0,0,0,0,0,0,0,0,0,0,0,0
0,0,0,0,0,0,0,0,0,0,0,0,0,0,0,0,0,0
0,0,0,0,0,0,0,0,0,0,0,0,0,0,0,0,0,0
0,0,0,0,0,0,0,0,0,0,0,0,0,0,0,0,0,0
0,0,0,0,0,0,0,0,0,0,0,0,0,0,0,0,0,0
0,0,0,0,0,0,0,0,0,0,0,0,0,0,0,0,0,0
0,0,0,0,0,0,0,0,0,0,0,0,0,0,0,0,0,0
0,0,0,0,0,0,0,0,0,0,0,0,0,0,0,0,0,0
0,0,0,0,0,0,0,0,0,0,0,0,0,0,0,0,0,0
0,0,0,0,0,0,0,0,0,0,0,0,0,0,0,0,0,0
0,0,0,0,0,0,0,0,0,0,0,0,0,0,0,0,0,0
0,0,0,0,0,0,0,0,0,0,0,0,0,0,0,0,0,0
0,0,0,0,0,0,0,0,0,0,0,0,0,0,0,0,0,0
:endlayer
layer: 13
0,0,0,0,0,0,0,0,0,0,0,0,0,0,0,0,0,0
0,0,0,0,0,0,0,0,0,0,0,0,0,0,0,0,0,0
0,0,2,2,202,202,2,3,202,202,202,3,2,202,202,2,2,0
0,0,2,0,0,0,0,0,0,0,0,0,0,0,0,0,2,0
0,0,3,0,27,0,0,0,0,0,0,0,0,0,27,0,3,0
0,0,202,0,0,0,0,0,0,0,0,0,0,0,0,0,202,0
0,0,202,0,0,0,0,0,0,0,0,0,0,0,0,0,202,0
0,0,3,0,0,0,0,0,0,0,0,0,0,0,0,0,3,0
0,0,2,0,0,0,2,0,0,0,0,0,2,0,0,0,2,0
0,0,3,0,0,0,0,0,0,0,0,0,0,0,0,0,3,0
0,0,202,0,0,0,0,0,0,0,0,0,0,0,0,0,202,0
0,0,202,0,0,0,0,0,0,0,0,0,0,0,0,0,202,0
0,0,3,0,0,0,0,0,0,0,0,0,0,0,0,0,3,0
0,0,2,0,0,0,2,0,0,0,0,0,2,0,0,0,2,0
0,0,3,0,0,0,0,0,0,0,0,0,0,0,0,0,3,0
0,0,202,0,0,0,0,0,0,0,0,0,0,0,0,0,202,0
0,0,202,0,0,0,0,0,0,0,0,0,0,0,0,0,202,0
0,0,3,0,0,0,0,0,0,0,0,0,0,0,0,0,3,0
0,0,2,0,0,0,2,0,0,0,0,0,2,0,0,0,2,0
0,0,3,0,0,0,0,0,0,0,0,0,0,0,0,0,3,0
0,0,202,0,0,0,0,0,0,0,0,0,0,0,0,0,202,0
0,0,202,0,0,0,0,0,0,0,0,0,0,0,0,0,202,0
0,0,3,0,0,0,0,0,0,0,0,0,0,0,0,0,3,0
0,0,2,0,0,0,2,0,0,0,0,0,2,0,0,0,2,0
0,0,3,0,0,0,0,0,0,0,0,0,0,0,0,0,3,0
0,0,202,0,0,0,0,0,0,0,0,0,0,0,0,0,202,0
0,0,202,0,0,0,0,0,0,0,0,0,0,0,0,0,202,0
0,0,3,0,0,0,0,0,0,0,0,0,0,0,0,0,3,0
0,0,2,0,0,0,2,0,0,0,0,0,2,0,0,0,2,0
0,0,3,0,0,0,0,0,0,0,0,0,0,0,0,0,3,0
0,0,202,0,0,0,0,0,0,0,0,0,0,0,0,0,202,0
0,0,202,0,0,0,0,0,0,0,0,0,0,0,0,0,202,0
0,0,3,0,0,0,0,0,0,0,0,0,0,0,0,0,3,0
0,0,2,0,0,0,2,0,0,0,0,0,2,0,0,0,2,0
0,0,3,0,0,0,0,0,0,0,0,0,0,0,0,0,3,0
0,0,202,0,0,0,0,0,0,2,0,0,0,0,0,0,202,0
0,0,202,0,0,0,0,0,45,2,0,0,0,0,0,0,202,0
0,0,3,0,0,0,0,0,46,0,0,0,0,0,0,0,3,0
0,0,2,0,0,0,2,0,0,0,0,0,2,0,0,0,2,0
0,0,3,0,0,0,0,0,0,0,0,0,0,0,0,0,3,0
0,0,202,0,0,0,0,0,0,0,0,0,0,0,0,0,202,0
0,0,202,0,0,0,0,0,0,0,0,0,0,0,0,0,202,0
0,0,3,0,0,0,0,0,0,0,0,0,0,0,0,0,3,0
0,0,2,0,0,0,0,0,0,0,0,0,0,0,0,0,2,0
0,0,2,11,0,53,2,3,2,202,2,3,2,11,0,53,2,0
0,0,0,0,0,0,0,0,0,0,0,0,0,0,0,0,0,0
0,0,0,0,0,0,0,0,0,0,0,0,0,0,0,0,0,0
0,0,0,0,0,0,0,0,0,0,0,0,0,0,0,0,0,0
0,0,0,0,0,0,0,0,0,0,0,0,0,0,0,0,0,0
0,0,0,0,0,0,0,0,0,0,0,0,0,0,0,0,0,0
0,0,0,0,0,0,0,0,0,0,0,0,0,0,0,0,0,0
0,0,0,0,0,0,0,0,0,0,0,0,0,0,0,0,0,0
0,0,0,0,0,0,0,0,0,0,0,0,0,0,0,0,0,0
0,0,0,0,0,0,0,0,0,0,0,0,0,0,0,0,0,0
0,0,0,0,0,0,0,0,0,0,0,0,0,0,0,0,0,0
0,0,0,0,0,0,0,0,0,0,0,0,0,0,0,0,0,0
0,0,0,0,0,0,0,0,0,0,0,0,0,0,0,0,0,0
0,0,0,0,0,0,0,0,0,0,0,0,0,0,0,0,0,0
0,0,0,0,0,0,0,0,0,0,0,0,0,0,0,0,0,0
0,0,0,0,0,0,0,0,0,0,0,0,0,0,0,0,0,0
0,0,0,0,0,0,0,0,0,0,0,0,0,0,0,0,0,0
0,0,0,0,0,0,0,0,0,0,0,0,0,0,0,0,0,0
0,0,0,0,0,0,0,0,0,0,0,0,0,0,0,0,0,0
:endlayer
layer: 14
0,0,0,0,0,0,0,0,0,0,0,0,0,0,0,0,0,0
0,0,0,0,0,0,0,0,0,0,0,0,0,0,0,0,0,0
0,0,2,2,202,202,2,3,202,202,202,3,2,202,202,2,2,0
0,0,2,0,0,0,76,0,0,0,0,0,76,0,0,0,2,0
0,0,3,75,75,75,76,0,0,0,0,0,76,75,76,0,3,0
0,0,202,0,76,74,76,0,0,0,0,0,76,74,76,0,202,0
0,0,202,0,76,74,76,0,0,0,0,0,76,74,76,0,202,0
0,0,3,75,76,74,76,0,0,0,0,0,76,74,76,75,3,0
0,0,2,74,76,75,2,0,0,0,0,0,2,74,76,74,2,0
0,0,3,75,76,74,76,0,0,0,0,0,76,74,76,75,3,0
0,0,202,0,76,74,76,0,0,0,0,0,76,74,76,0,202,0
0,0,202,0,76,74,76,0,0,0,0,0,76,74,76,0,202,0
0,0,3,75,76,74,76,0,0,0,0,0,76,74,76,75,3,0
0,0,2,74,76,74,2,74,76,0,76,74,2,74,76,74,2,0
0,0,3,75,76,74,76,74,76,0,76,74,76,74,76,75,3,0
0,0,202,0,76,74,76,74,76,0,76,74,76,74,76,0,202,0
0,0,202,0,76,74,76,74,76,0,76,74,76,74,76,0,202,0
0,0,3,75,76,74,76,74,76,0,76,74,76,74,76,75,3,0
0,0,2,74,76,74,2,74,76,0,76,74,2,74,76,74,2,0
0,0,3,75,76,74,76,74,76,0,76,74,76,74,76,75,3,0
0,0,202,0,76,74,76,74,76,0,76,74,76,74,76,0,202,0
0,0,202,0,76,74,76,74,76,0,76,74,76,74,76,0,202,0
0,0,3,75,76,74,76,74,76,0,76,74,76,74,76,75,3,0
0,0,2,74,76,74,2,74,76,0,76,74,2,74,76,74,2,0
0,0,3,75,76,74,76,74,76,0,76,74,76,74,76,75,3,0
0,0,202,0,76,74,76,74,76,0,76,74,76,74,76,0,202,0
0,0,202,0,76,74,76,74,76,0,76,74,76,74,76,0,202,0
0,0,3,75,76,74,76,74,76,0,76,74,76,74,76,75,3,0
0,0,2,74,76,74,2,74,76,0,76,74,2,74,76,74,2,0
0,0,3,75,76,74,76,74,76,0,76,74,76,74,76,75,3,0
0,0,202,0,76,74,76,74,76,0,76,74,76,74,76,0,202,0
0,0,202,0,76,74,76,74,76,0,76,74,76,74,76,0,202,0
0,0,3,75,76,74,76,74,76,0,76,74,76,74,76,75,3,0
0,0,2,74,76,74,2,75,75,75,75,75,2,74,76,74,2,0
0,0,3,75,76,74,76,74,0,0,0,74,76,74,76,75,3,0
0,0,202,0,76,74,76,74,0,2,0,74,76,74,76,0,202,0
0,0,202,0,76,74,76,74,0,2,0,74,76,74,76,0,202,0
0,0,3,75,76,74,76,74,0,45,46,74,76,74,76,75,3,0
0,0,2,74,76,74,2,75,75,75,75,75,2,74,76,74,2,0
0,0,3,75,76,74,76,0,0,0,0,0,76,74,76,75,3,0
0,0,202,0,76,74,76,0,0,0,0,0,76,74,76,0,202,0
0,0,202,0,76,74,76,0,0,0,0,0,76,74,76,0,202,0
0,0,3,75,75,75,76,0,0,0,0,0,76,75,75,75,3,0
0,0,2,0,0,0,76,0,0,0,0,0,76,0,0,0,2,0
0,0,3,2,19,2,2,3,2,202,2,3,2,2,19,2,3,0
0,0,0,0,0,0,0,0,0,0,0,0,0,0,0,0,0,0
0,0,0,0,0,0,0,0,0,0,0,0,0,0,0,0,0,0
0,0,0,0,0,0,0,0,0,0,0,0,0,0,0,0,0,0
0,0,0,0,0,0,0,0,0,0,0,0,0,0,0,0,0,0
0,0,0,0,0,0,0,0,0,0,0,0,0,0,0,0,0,0
0,0,0,0,0,0,0,0,0,0,0,0,0,0,0,0,0,0
0,0,0,0,0,0,0,0,0,0,0,0,0,0,0,0,0,0
0,0,0,0,0,0,0,0,0,0,0,0,0,0,0,0,0,0
0,0,0,0,0,0,0,0,0,0,0,0,0,0,0,0,0,0
0,0,0,0,0,0,0,0,0,0,0,0,0,0,0,0,0,0
0,0,0,0,0,0,0,0,0,0,0,0,0,0,0,0,0,0
0,0,0,0,0,0,0,0,0,0,0,0,0,0,0,0,0,0
0,0,0,0,0,0,0,0,0,0,0,0,0,0,0,0,0,0
0,0,0,0,0,0,0,0,0,0,0,0,0,0,0,0,0,0
0,0,0,0,0,0,0,0,0,0,0,0,0,0,0,0,0,0
0,0,0,0,0,0,0,0,0,0,0,0,0,0,0,0,0,0
0,0,0,0,0,0,0,0,0,0,0,0,0,0,0,0,0,0
0,0,0,0,0,0,0,0,0,0,0,0,0,0,0,0,0,0
:endlayer
layer: 15
0,0,0,0,0,0,0,0,0,0,0,0,0,0,0,0,0,0
0,0,0,0,0,0,0,0,0,0,0,0,0,0,0,0,0,0
0,0,2,2,202,202,2,3,202,202,202,3,2,202,202,2,2,0
0,0,2,0,0,0,0,0,0,0,0,0,0,0,0,0,2,0
0,0,3,0,418,416,400,0,0,0,0,0,334,332,300,0,3,0
0,0,202,0,419,0,401,0,0,0,0,0,335,0,301,0,202,0
0,0,202,0,420,0,402,0,0,0,0,0,336,0,302,0,202,0
0,0,3,439,421,0,403,0,0,0,0,0,337,0,303,286,3,0
0,0,2,0,0,0,2,62,0,0,0,73,2,0,0,0,2,0
0,0,3,440,422,0,404,0,0,0,0,0,338,0,304,287,3,0
0,0,202,0,423,0,405,0,0,0,0,0,339,0,305,0,202,0
0,0,202,0,424,0,406,0,0,0,0,0,340,0,306,0,202,0
0,0,3,441,425,0,407,0,0,0,0,0,341,0,307,288,3,0
0,0,2,0,0,0,2,397,27,0,27,350,2,0,0,0,2,0
0,0,3,426,426,0,0,0,376,0,353,0,0,0,308,289,3,0
0,0,202,0,426,0,0,0,377,0,354,0,0,0,309,0,202,0
0,0,202,0,426,0,0,0,378,0,355,0,0,0,310,0,202,0
0,0,3,426,426,0,0,0,379,0,356,0,0,0,311,290,3,0
0,0,2,0,0,0,2,0,380,0,357,0,2,0,0,0,2,0
0,0,3,426,426,0,0,0,381,0,358,0,0,0,312,291,3,0
0,0,202,0,426,0,0,0,382,0,359,0,0,0,313,0,202,0
0,0,202,0,426,0,0,0,383,0,360,0,0,0,314,0,202,0
0,0,3,426,426,0,0,0,384,0,361,0,0,0,315,292,3,0
0,0,2,0,0,0,2,0,385,0,362,0,2,0,0,0,2,0
0,0,3,0,0,0,0,0,386,0,363,0,0,0,316,293,3,0
0,0,202,0,0,0,0,0,387,0,364,0,0,0,317,0,202,0
0,0,202,0,0,0,0,0,388,0,365,0,0,0,318,0,202,0
0,0,3,0,0,0,0,0,389,0,366,0,0,0,319,294,3,0
0,0,2,0,0,0,2,0,390,0,367,0,2,0,0,0,2,0
0,0,3,442,427,0,0,0,391,0,368,0,342,0,320,295,3,0
0,0,202,0,428,0,0,0,392,0,369,0,343,0,321,0,202,0
0,0,202,0,429,0,0,0,393,0,370,0,344,0,322,0,202,0
0,0,3,443,430,0,0,0,394,0,371,0,345,0,323,296,3,0
0,0,2,0,0,0,2,398,395,374,372,351,2,0,0,0,2,0
0,0,3,444,431,0,408,0,0,0,0,0,0,0,324,297,3,0
0,0,202,0,432,0,409,0,0,2,46,0,0,0,325,0,202,0
0,0,202,0,433,0,410,0,0,2,45,0,0,0,326,0,202,0
0,0,3,445,434,0,411,0,0,0,0,0,0,0,327,298,3,0
0,0,2,0,0,0,2,399,396,375,373,352,2,0,0,0,2,0
0,0,3,446,435,0,412,0,0,0,0,0,346,0,328,299,3,0
0,0,202,0,436,0,413,0,0,0,0,0,347,0,329,0,202,0
0,0,202,0,437,0,414,0,0,0,0,0,348,0,330,0,202,0
0,0,3,0,438,417,415,0,0,0,0,0,349,333,331,0,3,0
0,0,2,0,0,0,0,0,0,0,0,0,0,0,0,0,2,0
0,0,3,3,2,3,2,3,3,2,3,3,2,3,2,3,3,0
0,0,0,0,0,0,0,0,0,0,0,0,0,0,0,0,0,0
0,0,0,0,0,0,0,0,0,0,0,0,0,0,0,0,0,0
0,0,0,0,0,0,0,0,0,0,0,0,0,0,0,0,0,0
0,0,0,0,0,0,0,0,0,0,0,0,0,0,0,0,0,0
0,0,0,0,0,0,0,0,0,0,0,0,0,0,0,0,0,0
0,0,0,0,0,0,0,0,0,0,0,0,0,0,0,0,0,0
0,0,0,0,0,0,0,0,0,0,0,0,0,0,0,0,0,0
0,0,0,0,0,0,0,0,0,0,0,0,0,0,0,0,0,0
0,0,0,0,0,0,0,0,0,0,0,0,0,0,0,0,0,0
0,0,0,0,0,0,0,0,0,0,0,0,0,0,0,0,0,0
0,0,0,0,0,0,0,0,0,0,0,0,0,0,0,0,0,0
0,0,0,0,0,0,0,0,0,0,0,0,0,0,0,0,0,0
0,0,0,0,0,0,0,0,0,0,0,0,0,0,0,0,0,0
0,0,0,0,0,0,0,0,0,0,0,0,0,0,0,0,0,0
0,0,0,0,0,0,0,0,0,0,0,0,0,0,0,0,0,0
0,0,0,0,0,0,0,0,0,0,0,0,0,0,0,0,0,0
0,0,0,0,0,0,0,0,0,0,0,0,0,0,0,0,0,0
0,0,0,0,0,0,0,0,0,0,0,0,0,0,0,0,0,0
:endlayer
layer: 16
0,0,0,0,0,0,0,0,0,0,0,0,0,0,0,0,0,0
0,0,0,0,0,0,0,0,0,0,0,0,0,0,0,0,0,0
0,0,3,3,2,2,2,2,202,202,202,2,2,2,2,3,3,0
0,0,3,0,0,0,0,0,0,0,0,0,0,0,0,0,3,0
0,0,2,0,0,0,0,0,0,0,0,0,0,0,0,0,2,0
0,0,3,0,0,0,0,0,0,0,0,0,0,0,0,0,3,0
0,0,3,0,0,0,0,0,0,0,0,0,0,0,0,0,3,0
0,0,2,0,0,0,0,0,0,0,0,0,0,0,0,0,2,0
0,0,3,0,0,73,2,0,0,0,0,0,2,62,0,0,3,0
0,0,2,0,0,0,0,0,0,0,0,0,0,0,0,0,2,0
0,0,3,0,0,0,0,0,0,0,0,0,0,0,0,0,3,0
0,0,3,0,0,0,0,0,0,0,0,0,0,0,0,0,3,0
0,0,2,0,0,0,0,0,0,0,0,0,0,0,0,0,2,0
0,0,3,0,0,73,2,0,27,0,27,0,2,62,0,0,3,0
0,0,2,0,0,0,0,0,0,0,0,0,0,0,0,0,2,0
0,0,3,0,0,0,0,0,0,0,0,0,0,0,0,0,3,0
0,0,3,0,0,0,0,0,0,0,0,0,0,0,0,0,3,0
0,0,2,0,0,0,0,0,0,0,0,0,0,0,0,0,2,0
0,0,3,0,0,73,2,0,0,0,0,0,2,62,0,0,3,0
0,0,2,0,0,0,0,0,0,0,0,0,0,0,0,0,2,0
0,0,3,0,0,0,0,0,0,0,0,0,0,0,0,0,3,0
0,0,3,0,0,0,0,0,0,0,0,0,0,0,0,0,3,0
0,0,2,0,0,0,0,0,0,0,0,0,0,0,0,0,2,0
0,0,3,0,0,73,2,0,0,0,0,0,2,62,0,0,3,0
0,0,2,0,0,0,0,0,0,0,0,0,0,0,0,0,2,0
0,0,3,0,0,0,0,0,0,0,0,0,0,0,0,0,3,0
0,0,3,0,0,0,0,0,0,0,0,0,0,0,0,0,3,0
0,0,2,0,0,0,0,0,0,0,0,0,0,0,0,0,2,0
0,0,3,0,0,73,2,0,0,0,0,0,2,62,0,0,3,0
0,0,2,0,0,0,0,0,0,0,0,0,0,0,0,0,2,0
0,0,3,0,0,0,0,0,0,0,0,0,0,0,0,0,3,0
0,0,3,0,0,0,0,0,0,0,0,0,0,0,0,0,3,0
0,0,2,0,0,0,0,0,0,0,0,0,0,0,0,0,2,0
0,0,3,0,0,73,2,0,0,0,0,0,2,62,0,0,3,0
0,0,2,0,0,0,0,0,0,46,45,0,0,0,0,0,2,0
0,0,3,0,0,0,0,0,0,2,0,0,0,0,0,0,3,0
0,0,3,0,0,0,0,0,0,2,0,0,0,0,0,0,3,0
0,0,2,0,0,0,0,0,0,0,0,0,0,0,0,0,2,0
0,0,3,0,0,73,2,0,0,0,0,0,2,62,0,0,3,0
0,0,2,0,0,0,0,0,0,0,0,0,0,0,0,0,2,0
0,0,3,0,0,0,0,0,0,0,0,0,0,0,0,0,3,0
0,0,3,0,0,0,0,0,0,0,0,0,0,0,0,0,3,0
0,0,2,0,0,0,0,0,0,0,0,0,0,0,0,0,2,0
0,0,3,0,0,0,0,0,0,0,0,0,0,0,0,0,3,0
0,0,3,165,2,165,165,165,165,3,165,165,165,165,2,165,3,0
0,0,0,0,0,0,0,0,0,0,0,0,0,0,0,0,0,0
0,0,0,0,0,0,0,0,0,0,0,0,0,0,0,0,0,0
0,0,0,0,0,0,0,0,0,0,0,0,0,0,0,0,0,0
0,0,0,0,0,0,0,0,0,0,0,0,0,0,0,0,0,0
0,0,0,0,0,0,0,0,0,0,0,0,0,0,0,0,0,0
0,0,0,0,0,0,0,0,0,0,0,0,0,0,0,0,0,0
0,0,0,0,0,0,0,0,0,0,0,0,0,0,0,0,0,0
0,0,0,0,0,0,0,0,0,0,0,0,0,0,0,0,0,0
0,0,0,0,0,0,0,0,0,0,0,0,0,0,0,0,0,0
0,0,0,0,0,0,0,0,0,0,0,0,0,0,0,0,0,0
0,0,0,0,0,0,0,0,0,0,0,0,0,0,0,0,0,0
0,0,0,0,0,0,0,0,0,0,0,0,0,0,0,0,0,0
0,0,0,0,0,0,0,0,0,0,0,0,0,0,0,0,0,0
0,0,0,0,0,0,0,0,0,0,0,0,0,0,0,0,0,0
0,0,0,0,0,0,0,0,0,0,0,0,0,0,0,0,0,0
0,0,0,0,0,0,0,0,0,0,0,0,0,0,0,0,0,0
0,0,0,0,0,0,0,0,0,0,0,0,0,0,0,0,0,0
0,0,0,0,0,0,0,0,0,0,0,0,0,0,0,0,0,0
:endlayer
layer: 17
0,0,0,0,0,0,0,0,0,0,0,0,0,0,0,0,0,0
0,0,0,0,0,0,0,0,0,0,0,0,0,0,0,0,0,0
0,0,3,3,3,3,2,2,202,202,202,2,2,3,3,3,3,0
0,0,3,0,0,0,0,0,0,0,0,0,0,0,0,0,3,0
0,0,3,0,0,0,0,0,0,0,0,0,0,0,0,0,3,0
0,0,2,0,0,0,0,0,0,0,0,0,0,0,0,0,2,0
0,0,2,0,0,0,0,0,0,0,0,0,0,0,0,0,2,0
0,0,3,0,0,0,0,0,0,0,0,0,0,0,0,0,3,0
0,0,3,0,0,0,2,0,0,0,0,0,2,0,0,0,3,0
0,0,3,0,0,0,0,0,0,0,0,0,0,0,0,0,3,0
0,0,2,0,0,0,0,0,0,0,0,0,0,0,0,0,2,0
0,0,2,0,0,0,0,0,0,0,0,0,0,0,0,0,2,0
0,0,3,0,0,0,0,0,0,0,0,0,0,0,0,0,3,0
0,0,3,0,0,0,2,0,27,0,27,0,2,0,0,0,3,0
0,0,3,0,0,0,0,0,0,0,0,0,0,0,0,0,3,0
0,0,2,0,0,0,0,0,0,0,0,0,0,0,0,0,2,0
0,0,2,0,0,0,0,0,0,0,0,0,0,0,0,0,2,0
0,0,3,0,0,0,0,0,0,0,0,0,0,0,0,0,3,0
0,0,3,0,0,0,2,0,0,0,0,0,2,0,0,0,3,0
0,0,3,0,0,0,0,0,0,0,0,0,0,0,0,0,3,0
0,0,2,0,0,0,0,0,0,0,0,0,0,0,0,0,2,0
0,0,2,0,0,0,0,0,0,0,0,0,0,0,0,0,2,0
0,0,3,0,0,0,0,0,0,0,0,0,0,0,0,0,3,0
0,0,3,0,0,0,2,0,0,0,0,0,2,0,0,0,3,0
0,0,3,0,0,0,0,0,0,0,0,0,0,0,0,0,3,0
0,0,2,0,0,0,0,0,0,0,0,0,0,0,0,0,2,0
0,0,2,0,0,0,0,0,0,0,0,0,0,0,0,0,2,0
0,0,3,0,0,0,0,0,0,0,0,0,0,0,0,0,3,0
0,0,3,0,0,0,2,0,0,0,0,0,2,0,0,0,3,0
0,0,3,0,0,0,0,0,0,0,0,0,0,0,0,0,3,0
0,0,2,0,0,0,0,0,0,0,0,0,0,0,0,0,2,0
0,0,2,0,0,0,0,0,0,0,0,0,0,0,0,0,2,0
0,0,3,0,0,0,0,0,0,0,0,0,0,0,0,0,3,0
0,0,3,0,0,0,2,0,0,0,0,0,2,0,0,0,3,0
0,0,3,0,0,0,0,0,45,0,0,0,0,0,0,0,3,0
0,0,2,0,0,0,0,0,46,2,0,0,0,0,0,0,2,0
0,0,2,0,0,0,0,0,0,2,0,0,0,0,0,0,2,0
0,0,3,0,0,0,0,0,0,0,0,0,0,0,0,0,3,0
0,0,3,0,0,0,2,0,0,0,0,0,2,0,0,0,3,0
0,0,3,0,0,0,0,0,0,0,0,0,0,0,0,0,3,0
0,0,2,0,0,0,0,0,0,0,0,0,0,0,0,0,2,0
0,0,2,0,0,0,0,0,0,0,0,0,0,0,0,0,2,0
0,0,3,0,0,0,0,0,0,0,0,0,0,0,0,0,3,0
0,0,3,0,0,0,0,0,0,0,0,0,0,0,0,0,3,0
0,0,3,447,2,447,447,447,447,19,447,447,447,447,2,447,3,0
0,0,0,0,0,0,0,0,0,0,0,0,0,0,0,0,0,0
0,0,0,0,0,0,0,0,0,0,0,0,0,0,0,0,0,0
0,0,0,0,0,0,0,0,0,0,0,0,0,0,0,0,0,0
0,0,0,0,0,0,0,0,0,0,0,0,0,0,0,0,0,0
0,0,0,0,0,0,0,0,0,0,0,0,0,0,0,0,0,0
0,0,0,0,0,0,0,0,0,0,0,0,0,0,0,0,0,0
0,0,0,0,0,0,0,0,0,0,0,0,0,0,0,0,0,0
0,0,0,0,0,0,0,0,0,0,0,0,0,0,0,0,0,0
0,0,0,0,0,0,0,0,0,0,0,0,0,0,0,0,0,0
0,0,0,0,0,0,0,0,0,0,0,0,0,0,0,0,0,0
0,0,0,0,0,0,0,0,0,0,0,0,0,0,0,0,0,0
0,0,0,0,0,0,0,0,0,0,0,0,0,0,0,0,0,0
0,0,0,0,0,0,0,0,0,0,0,0,0,0,0,0,0,0
0,0,0,0,0,0,0,0,0,0,0,0,0,0,0,0,0,0
0,0,0,0,0,0,0,0,0,0,0,0,0,0,0,0,0,0
0,0,0,0,0,0,0,0,0,0,0,0,0,0,0,0,0,0
0,0,0,0,0,0,0,0,0,0,0,0,0,0,0,0,0,0
0,0,0,0,0,0,0,0,0,0,0,0,0,0,0,0,0,0
:endlayer
layer: 18
0,0,0,0,0,0,0,0,0,0,0,0,0,0,0,0,0,0
0,0,0,0,0,0,0,0,0,0,0,0,0,0,0,0,0,0
0,0,15,2,3,3,2,2,202,202,202,2,2,3,3,2,14,0
0,0,70,74,0,0,0,0,0,0,0,0,0,0,0,74,66,0
0,0,70,74,0,0,0,0,0,0,0,0,0,0,0,74,66,0
0,0,70,74,0,0,0,0,0,0,0,0,0,0,0,74,66,0
0,0,70,74,0,0,0,0,0,0,0,0,0,0,0,74,66,0
0,0,70,74,0,0,0,0,0,0,0,0,0,0,0,74,66,0
0,0,15,2,0,0,2,0,0,0,0,0,2,0,0,2,14,0
0,0,70,74,0,0,0,0,0,0,0,0,0,0,0,74,66,0
0,0,70,74,0,0,0,0,0,0,0,0,0,0,0,74,66,0
0,0,70,74,0,0,0,0,0,0,0,0,0,0,0,74,66,0
0,0,70,74,0,0,0,0,448,0,448,0,0,0,0,74,66,0
0,0,15,2,0,0,2,0,27,0,27,0,2,0,0,2,14,0
0,0,70,74,0,0,0,0,0,0,0,0,0,0,0,74,66,0
0,0,70,74,0,0,0,0,0,0,0,0,0,0,0,74,66,0
0,0,70,74,0,0,0,0,0,0,0,0,0,0,0,74,66,0
0,0,70,74,0,0,0,0,0,0,0,0,0,0,0,74,66,0
0,0,15,2,0,0,2,62,0,0,0,73,2,0,0,2,14,0
0,0,70,74,0,0,0,0,0,0,0,0,0,0,0,74,66,0
0,0,70,74,0,0,0,0,0,0,0,0,0,0,0,74,66,0
0,0,70,74,0,0,0,0,0,0,0,0,0,0,0,74,66,0
0,0,70,74,0,0,0,0,0,0,0,0,0,0,0,74,66,0
0,0,15,2,0,0,2,62,0,0,0,73,2,0,0,2,14,0
0,0,70,74,0,0,0,0,0,0,0,0,0,0,0,74,66,0
0,0,70,74,0,0,0,0,0,0,0,0,0,0,0,74,66,0
0,0,70,74,0,0,0,0,0,0,0,0,0,0,0,74,66,0
0,0,70,74,0,0,0,0,0,0,0,0,0,0,0,74,66,0
0,0,15,2,0,0,2,62,0,0,0,73,2,0,0,2,14,0
0,0,70,74,0,0,0,0,0,0,0,0,0,0,0,74,66,0
0,0,70,74,0,0,0,0,0,0,0,0,0,0,0,74,66,0
0,0,70,74,0,0,0,0,0,0,0,0,0,0,0,74,66,0
0,0,70,74,0,0,0,0,0,0,0,0,0,0,0,74,66,0
0,0,15,2,0,0,2,0,0,0,0,73,2,0,0,2,14,0
0,0,70,74,0,0,63,0,0,0,0,0,0,0,0,74,66,0
0,0,70,74,0,0,0,0,0,2,0,0,0,0,0,74,66,0
0,0,70,74,0,0,0,0,45,2,0,0,0,0,0,74,66,0
0,0,70,74,0,0,0,0,46,0,0,0,0,0,0,74,66,0
0,0,15,2,0,0,2,62,0,0,0,73,2,0,0,2,14,0
0,0,70,74,0,0,0,0,0,0,0,0,0,0,0,74,66,0
0,0,70,74,0,0,0,0,0,0,0,0,0,0,0,74,66,0
0,0,70,74,0,0,0,0,0,0,0,0,0,0,0,74,66,0
0,0,70,74,0,0,0,0,0,0,0,0,0,0,0,74,66,0
0,0,70,74,0,0,0,0,0,0,0,0,0,0,0,74,66,0
0,0,15,2,3,17,2,17,3,2,3,17,2,17,3,2,14,0
0,0,0,0,0,0,0,0,0,0,0,0,0,0,0,0,0,0
0,0,0,0,0,0,0,0,0,0,0,0,0,0,0,0,0,0
0,0,0,0,0,0,0,0,0,0,0,0,0,0,0,0,0,0
0,0,0,0,0,0,0,0,0,0,0,0,0,0,0,0,0,0
0,0,0,0,0,0,0,0,0,0,0,0,0,0,0,0,0,0
0,0,0,0,0,0,0,0,0,0,0,0,0,0,0,0,0,0
0,0,0,0,0,0,0,0,0,0,0,0,0,0,0,0,0,0
0,0,0,0,0,0,0,0,0,0,0,0,0,0,0,0,0,0
0,0,0,0,0,0,0,0,0,0,0,0,0,0,0,0,0,0
0,0,0,0,0,0,0,0,0,0,0,0,0,0,0,0,0,0
0,0,0,0,0,0,0,0,0,0,0,0,0,0,0,0,0,0
0,0,0,0,0,0,0,0,0,0,0,0,0,0,0,0,0,0
0,0,0,0,0,0,0,0,0,0,0,0,0,0,0,0,0,0
0,0,0,0,0,0,0,0,0,0,0,0,0,0,0,0,0,0
0,0,0,0,0,0,0,0,0,0,0,0,0,0,0,0,0,0
0,0,0,0,0,0,0,0,0,0,0,0,0,0,0,0,0,0
0,0,0,0,0,0,0,0,0,0,0,0,0,0,0,0,0,0
0,0,0,0,0,0,0,0,0,0,0,0,0,0,0,0,0,0
:endlayer
layer: 19
0,0,0,0,0,0,0,0,0,0,0,0,0,0,0,0,0,0
0,0,0,0,0,0,0,0,0,0,0,0,0,0,0,0,0,0
0,0,0,15,2,3,2,3,202,202,202,3,2,3,2,14,0,0
0,0,0,70,74,0,0,0,0,0,0,0,0,0,74,66,0,0
0,0,0,70,74,0,0,0,0,0,0,0,0,0,74,66,0,0
0,0,0,70,74,0,0,0,0,0,0,0,0,0,74,66,0,0
0,0,0,70,74,0,0,0,0,0,0,0,0,0,74,66,0,0
0,0,0,70,74,0,0,0,0,0,0,0,0,0,74,66,0,0
0,0,0,15,2,0,2,0,0,0,0,0,2,0,2,14,0,0
0,0,0,70,74,0,0,0,0,0,0,0,0,0,74,66,0,0
0,0,0,70,74,0,0,0,0,0,0,0,0,0,74,66,0,0
0,0,0,70,74,0,0,0,0,0,0,0,0,0,74,66,0,0
0,0,0,70,74,0,0,0,0,0,0,0,0,0,74,66,0,0
0,0,0,15,2,0,2,0,27,0,27,0,2,0,2,14,0,0
0,0,0,70,74,0,0,0,0,0,0,0,0,0,74,66,0,0
0,0,0,70,74,0,0,0,0,0,0,0,0,0,74,66,0,0
0,0,0,70,74,0,0,0,0,0,0,0,0,0,74,66,0,0
0,0,0,70,74,0,0,0,0,0,0,0,0,0,74,66,0,0
0,0,0,15,2,0,2,0,0,0,0,0,2,0,2,14,0,0
0,0,0,70,74,0,0,0,0,0,0,0,0,0,74,66,0,0
0,0,0,70,74,0,0,0,0,0,0,0,0,0,74,66,0,0
0,0,0,70,74,0,0,0,0,0,0,0,0,0,74,66,0,0
0,0,0,70,74,0,0,0,0,0,0,0,0,0,74,66,0,0
0,0,0,15,2,0,2,0,0,0,0,0,2,0,2,14,0,0
0,0,0,70,74,0,0,0,0,0,0,0,0,0,74,66,0,0
0,0,0,70,74,0,0,0,0,0,0,0,0,0,74,66,0,0
0,0,0,70,74,0,0,0,0,0,0,0,0,0,74,66,0,0
0,0,0,70,74,0,0,0,0,0,0,0,0,0,74,66,0,0
0,0,0,15,2,0,2,0,0,0,0,0,2,0,2,14,0,0
0,0,0,70,74,0,0,0,0,0,0,0,0,0,74,66,0,0
0,0,0,70,74,0,0,0,0,0,0,0,0,0,74,66,0,0
0,0,0,70,74,0,0,0,0,0,0,0,0,0,74,66,0,0
0,0,0,70,74,0,0,0,0,0,0,0,0,0,74,66,0,0
0,0,0,15,2,0,2,0,0,0,0,0,2,0,2,14,0,0
0,0,0,70,74,0,0,0,0,0,0,0,0,0,74,66,0,0
0,0,0,70,74,0,0,0,0,2,0,0,0,0,74,66,0,0
0,0,0,70,74,0,0,0,0,2,0,0,0,0,74,66,0,0
0,0,0,70,74,0,0,0,0,45,46,0,0,0,74,66,0,0
0,0,0,15,2,0,2,0,0,0,0,0,2,0,2,14,0,0
0,0,0,70,74,0,0,0,0,0,0,0,0,0,74,66,0,0
0,0,0,70,74,0,0,0,0,0,0,0,0,0,74,66,0,0
0,0,0,70,74,0,0,0,0,0,0,0,0,0,74,66,0,0
0,0,0,70,74,0,0,0,0,0,0,0,0,0,74,66,0,0
0,0,0,70,74,0,0,0,448,0,448,0,0,0,74,66,0,0
0,0,0,15,2,78,2,78,2,202,2,78,2,78,2,14,0,0
0,0,0,0,0,0,0,0,0,0,0,0,0,0,0,0,0,0
0,0,0,0,0,0,0,0,0,0,0,0,0,0,0,0,0,0
0,0,0,0,0,0,0,0,0,0,0,0,0,0,0,0,0,0
0,0,0,0,0,0,0,0,0,0,0,0,0,0,0,0,0,0
0,0,0,0,0,0,0,0,0,0,0,0,0,0,0,0,0,0
0,0,0,0,0,0,0,0,0,0,0,0,0,0,0,0,0,0
0,0,0,0,0,0,0,0,0,0,0,0,0,0,0,0,0,0
0,0,0,0,0,0,0,0,0,0,0,0,0,0,0,0,0,0
0,0,0,0,0,0,0,0,0,0,0,0,0,0,0,0,0,0
0,0,0,0,0,0,0,0,0,0,0,0,0,0,0,0,0,0
0,0,0,0,0,0,0,0,0,0,0,0,0,0,0,0,0,0
0,0,0,0,0,0,0,0,0,0,0,0,0,0,0,0,0,0
0,0,0,0,0,0,0,0,0,0,0,0,0,0,0,0,0,0
0,0,0,0,0,0,0,0,0,0,0,0,0,0,0,0,0,0
0,0,0,0,0,0,0,0,0,0,0,0,0,0,0,0,0,0
0,0,0,0,0,0,0,0,0,0,0,0,0,0,0,0,0,0
0,0,0,0,0,0,0,0,0,0,0,0,0,0,0,0,0,0
0,0,0,0,0,0,0,0,0,0,0,0,0,0,0,0,0,0
:endlayer
layer: 20
0,0,0,0,0,0,0,0,0,0,0,0,0,0,0,0,0,0
0,0,0,0,0,0,0,0,0,0,0,0,0,0,0,0,0,0
0,0,0,0,15,2,2,147,3,19,3,147,2,2,14,0,0,0
0,0,0,0,70,74,3,0,0,0,0,0,3,74,66,0,0,0
0,0,0,0,70,74,3,0,0,0,0,0,3,74,66,0,0,0
0,0,0,0,70,74,3,0,0,0,0,0,3,74,66,0,0,0
0,0,0,0,70,74,3,0,0,0,0,0,3,74,66,0,0,0
0,0,0,0,70,74,3,0,0,0,0,0,3,74,66,0,0,0
0,0,0,0,15,2,2,0,0,0,0,0,2,2,14,0,0,0
0,0,0,0,70,74,3,0,0,0,0,0,3,74,66,0,0,0
0,0,0,0,70,74,3,0,0,0,0,0,3,74,66,0,0,0
0,0,0,0,70,74,3,0,0,0,0,0,3,74,66,0,0,0
0,0,0,0,70,74,3,0,0,0,0,0,3,74,66,0,0,0
0,0,0,0,15,2,2,75,75,75,75,75,2,2,14,0,0,0
0,0,0,0,70,74,3,76,74,74,74,76,3,74,66,0,0,0
0,0,0,0,70,74,3,76,74,74,74,76,3,74,66,0,0,0
0,0,0,0,70,74,3,76,74,74,74,76,3,74,66,0,0,0
0,0,0,0,70,74,3,76,74,74,74,76,3,74,66,0,0,0
0,0,0,0,15,2,2,76,74,74,74,76,2,2,14,0,0,0
0,0,0,0,70,74,3,76,74,74,74,76,3,74,66,0,0,0
0,0,0,0,70,74,3,76,74,74,74,76,3,74,66,0,0,0
0,0,0,0,70,74,3,76,74,74,74,76,3,74,66,0,0,0
0,0,0,0,70,74,3,76,74,74,74,76,3,74,66,0,0,0
0,0,0,0,15,2,2,76,74,74,74,76,2,2,14,0,0,0
0,0,0,0,70,74,3,76,74,74,74,76,3,74,66,0,0,0
0,0,0,0,70,74,3,76,74,74,74,76,3,74,66,0,0,0
0,0,0,0,70,74,3,76,74,74,74,76,3,74,66,0,0,0
0,0,0,0,70,74,3,76,74,74,74,76,3,74,66,0,0,0
0,0,0,0,15,2,2,76,74,74,74,76,2,2,14,0,0,0
0,0,0,0,70,74,3,76,74,74,74,76,3,74,66,0,0,0
0,0,0,0,70,74,3,76,74,74,74,76,3,74,66,0,0,0
0,0,0,0,70,74,3,76,74,74,74,76,3,74,66,0,0,0
0,0,0,0,70,74,3,76,74,74,74,76,3,74,66,0,0,0
0,0,0,0,15,2,2,76,74,74,74,76,2,2,14,0,0,0
0,0,0,0,70,74,3,76,46,46,46,76,3,74,66,0,0,0
0,0,0,0,70,74,3,76,0,2,46,76,3,74,66,0,0,0
0,0,0,0,70,74,3,76,0,2,45,76,3,74,66,0,0,0
0,0,0,0,70,74,3,76,0,0,0,76,3,74,66,0,0,0
0,0,0,0,15,2,2,75,75,75,75,76,2,2,14,0,0,0
0,0,0,0,70,74,3,76,0,0,0,76,3,74,66,0,0,0
0,0,0,0,70,74,3,76,0,0,0,76,3,74,66,0,0,0
0,0,0,0,70,74,3,76,0,0,0,76,3,74,66,0,0,0
0,0,0,0,70,74,3,76,0,0,0,76,3,74,66,0,0,0
0,0,0,0,70,74,3,76,0,0,0,76,3,74,66,0,0,0
0,0,0,0,15,2,2,2,449,202,449,2,2,2,14,0,0,0
0,0,0,0,0,0,0,0,0,0,0,0,0,0,0,0,0,0
0,0,0,0,0,0,0,0,0,0,0,0,0,0,0,0,0,0
0,0,0,0,0,0,0,0,0,0,0,0,0,0,0,0,0,0
0,0,0,0,0,0,0,0,0,0,0,0,0,0,0,0,0,0
0,0,0,0,0,0,0,0,0,0,0,0,0,0,0,0,0,0
0,0,0,0,0,0,0,0,0,0,0,0,0,0,0,0,0,0
0,0,0,0,0,0,0,0,0,0,0,0,0,0,0,0,0,0
0,0,0,0,0,0,0,0,0,0,0,0,0,0,0,0,0,0
0,0,0,0,0,0,0,0,0,0,0,0,0,0,0,0,0,0
0,0,0,0,0,0,0,0,0,0,0,0,0,0,0,0,0,0
0,0,0,0,0,0,0,0,0,0,0,0,0,0,0,0,0,0
0,0,0,0,0,0,0,0,0,0,0,0,0,0,0,0,0,0
0,0,0,0,0,0,0,0,0,0,0,0,0,0,0,0,0,0
0,0,0,0,0,0,0,0,0,0,0,0,0,0,0,0,0,0
0,0,0,0,0,0,0,0,0,0,0,0,0,0,0,0,0,0
0,0,0,0,0,0,0,0,0,0,0,0,0,0,0,0,0,0
0,0,0,0,0,0,0,0,0,0,0,0,0,0,0,0,0,0
0,0,0,0,0,0,0,0,0,0,0,0,0,0,0,0,0,0
:endlayer
layer: 21
0,0,0,0,0,0,0,0,0,0,0,0,0,0,0,0,0,0
0,0,0,0,0,0,0,0,0,0,0,0,0,0,0,0,0,0
0,0,0,0,0,15,2,67,2,202,2,67,2,14,0,0,0,0
0,0,0,0,0,70,3,0,63,0,63,0,3,66,0,0,0,0
0,0,0,0,0,70,3,0,0,0,0,0,3,66,0,0,0,0
0,0,0,0,0,70,3,0,0,0,0,0,3,66,0,0,0,0
0,0,0,0,0,70,3,0,0,0,0,0,3,66,0,0,0,0
0,0,0,0,0,70,3,0,0,0,0,0,3,66,0,0,0,0
0,0,0,0,0,15,2,0,0,0,0,0,2,14,0,0,0,0
0,0,0,0,0,70,3,0,0,0,0,0,3,66,0,0,0,0
0,0,0,0,0,70,3,0,0,0,0,0,3,66,0,0,0,0
0,0,0,0,0,70,3,0,0,0,0,0,3,66,0,0,0,0
0,0,0,0,0,70,3,0,0,0,0,0,3,66,0,0,0,0
0,0,0,0,0,15,2,458,456,454,452,450,2,14,0,0,0,0
0,0,0,0,0,70,3,0,0,0,0,0,3,66,0,0,0,0
0,0,0,0,0,70,3,0,0,0,0,0,3,66,0,0,0,0
0,0,0,0,0,70,3,0,0,0,0,0,3,66,0,0,0,0
0,0,0,0,0,70,3,0,0,0,0,0,3,66,0,0,0,0
0,0,0,0,0,15,2,0,0,0,0,0,2,14,0,0,0,0
0,0,0,0,0,70,3,0,0,0,0,0,3,66,0,0,0,0
0,0,0,0,0,70,3,0,0,0,0,0,3,66,0,0,0,0
0,0,0,0,0,70,3,0,0,0,0,0,3,66,0,0,0,0
0,0,0,0,0,70,3,0,0,0,0,0,3,66,0,0,0,0
0,0,0,0,0,15,2,0,0,0,0,0,2,14,0,0,0,0
0,0,0,0,0,70,3,0,0,0,0,0,3,66,0,0,0,0
0,0,0,0,0,70,3,0,0,0,0,0,3,66,0,0,0,0
0,0,0,0,0,70,3,0,0,0,0,0,3,66,0,0,0,0
0,0,0,0,0,70,3,0,0,0,0,0,3,66,0,0,0,0
0,0,0,0,0,15,2,0,0,0,0,0,2,14,0,0,0,0
0,0,0,0,0,70,3,0,0,0,0,0,3,66,0,0,0,0
0,0,0,0,0,70,3,0,0,0,0,0,3,66,0,0,0,0
0,0,0,0,0,70,3,0,0,0,0,0,3,66,0,0,0,0
0,0,0,0,0,70,3,0,0,0,0,0,3,66,0,0,0,0
0,0,0,0,0,15,2,0,0,0,0,0,2,14,0,0,0,0
0,0,0,0,0,70,3,0,0,0,0,0,3,66,0,0,0,0
0,0,0,0,0,70,3,0,0,0,0,0,3,66,0,0,0,0
0,0,0,0,0,70,3,0,0,0,0,0,3,66,0,0,0,0
0,0,0,0,0,70,3,0,0,0,0,0,3,66,0,0,0,0
0,0,0,0,0,15,2,459,457,455,453,451,2,14,0,0,0,0
0,0,0,0,0,70,3,0,0,0,0,0,3,66,0,0,0,0
0,0,0,0,0,70,3,0,0,0,0,0,3,66,0,0,0,0
0,0,0,0,0,70,3,0,0,0,0,0,3,66,0,0,0,0
0,0,0,0,0,70,3,0,0,0,0,0,3,66,0,0,0,0
0,0,0,0,0,70,3,0,0,0,0,0,3,66,0,0,0,0
0,0,0,0,0,15,2,2,449,202,449,2,2,14,0,0,0,0
0,0,0,0,0,0,0,0,0,0,0,0,0,0,0,0,0,0
0,0,0,0,0,0,0,0,0,0,0,0,0,0,0,0,0,0
0,0,0,0,0,0,0,0,0,0,0,0,0,0,0,0,0,0
0,0,0,0,0,0,0,0,0,0,0,0,0,0,0,0,0,0
0,0,0,0,0,0,0,0,0,0,0,0,0,0,0,0,0,0
0,0,0,0,0,0,0,0,0,0,0,0,0,0,0,0,0,0
0,0,0,0,0,0,0,0,0,0,0,0,0,0,0,0,0,0
0,0,0,0,0,0,0,0,0,0,0,0,0,0,0,0,0,0
0,0,0,0,0,0,0,0,0,0,0,0,0,0,0,0,0,0
0,0,0,0,0,0,0,0,0,0,0,0,0,0,0,0,0,0
0,0,0,0,0,0,0,0,0,0,0,0,0,0,0,0,0,0
0,0,0,0,0,0,0,0,0,0,0,0,0,0,0,0,0,0
0,0,0,0,0,0,0,0,0,0,0,0,0,0,0,0,0,0
0,0,0,0,0,0,0,0,0,0,0,0,0,0,0,0,0,0
0,0,0,0,0,0,0,0,0,0,0,0,0,0,0,0,0,0
0,0,0,0,0,0,0,0,0,0,0,0,0,0,0,0,0,0
0,0,0,0,0,0,0,0,0,0,0,0,0,0,0,0,0,0
0,0,0,0,0,0,0,0,0,0,0,0,0,0,0,0,0,0
:endlayer
layer: 22
0,0,0,0,0,0,0,0,0,0,0,0,0,0,0,0,0,0
0,0,0,0,0,0,0,0,0,0,0,0,0,0,0,0,0,0
0,0,0,0,0,0,2,2,202,202,202,2,2,0,0,0,0,0
0,0,0,0,0,0,3,0,0,0,0,0,3,0,0,0,0,0
0,0,0,0,0,0,202,0,0,0,0,0,202,0,0,0,0,0
0,0,0,0,0,0,202,0,0,0,0,0,202,0,0,0,0,0
0,0,0,0,0,0,202,0,0,0,0,0,202,0,0,0,0,0
0,0,0,0,0,0,3,0,0,0,0,0,3,0,0,0,0,0
0,0,0,0,0,0,2,0,0,0,0,0,2,0,0,0,0,0
0,0,0,0,0,0,3,0,0,0,0,0,3,0,0,0,0,0
0,0,0,0,0,0,202,0,0,0,0,0,202,0,0,0,0,0
0,0,0,0,0,0,202,0,0,0,0,0,202,0,0,0,0,0
0,0,0,0,0,0,3,0,0,0,0,0,3,0,0,0,0,0
0,0,0,0,0,0,2,0,0,0,0,0,2,0,0,0,0,0
0,0,0,0,0,0,3,0,0,0,0,0,3,0,0,0,0,0
0,0,0,0,0,0,202,0,0,0,0,0,202,0,0,0,0,0
0,0,0,0,0,0,202,0,0,0,0,0,202,0,0,0,0,0
0,0,0,0,0,0,3,0,0,0,0,0,3,0,0,0,0,0
0,0,0,0,0,0,2,0,0,0,0,0,2,0,0,0,0,0
0,0,0,0,0,0,3,0,0,0,0,0,3,0,0,0,0,0
0,0,0,0,0,0,202,0,0,0,0,0,202,0,0,0,0,0
0,0,0,0,0,0,202,0,0,0,0,0,202,0,0,0,0,0
0,0,0,0,0,0,3,0,0,0,0,0,3,0,0,0,0,0
0,0,0,0,0,0,2,0,0,0,0,0,2,0,0,0,0,0
0,0,0,0,0,0,3,0,0,0,0,0,3,0,0,0,0,0
0,0,0,0,0,0,202,0,0,0,0,0,202,0,0,0,0,0
0,0,0,0,0,0,202,0,0,0,0,0,202,0,0,0,0,0
0,0,0,0,0,0,3,0,0,0,0,0,3,0,0,0,0,0
0,0,0,0,0,0,2,0,0,0,0,0,2,0,0,0,0,0
0,0,0,0,0,0,3,0,0,0,0,0,3,0,0,0,0,0
0,0,0,0,0,0,202,0,0,0,0,0,202,0,0,0,0,0
0,0,0,0,0,0,202,0,0,0,0,0,202,0,0,0,0,0
0,0,0,0,0,0,3,0,0,0,0,0,3,0,0,0,0,0
0,0,0,0,0,0,2,0,0,0,0,0,2,0,0,0,0,0
0,0,0,0,0,0,3,0,0,0,0,0,3,0,0,0,0,0
0,0,0,0,0,0,202,0,0,0,0,0,202,0,0,0,0,0
0,0,0,0,0,0,202,0,0,0,0,0,202,0,0,0,0,0
0,0,0,0,0,0,3,0,0,0,0,0,3,0,0,0,0,0
0,0,0,0,0,0,2,0,0,0,0,0,2,0,0,0,0,0
0,0,0,0,0,0,3,0,0,0,0,0,3,0,0,0,0,0
0,0,0,0,0,0,202,0,0,0,0,0,202,0,0,0,0,0
0,0,0,0,0,0,202,0,0,0,0,0,202,0,0,0,0,0
0,0,0,0,0,0,202,0,0,0,0,0,202,0,0,0,0,0
0,0,0,0,0,0,3,0,0,0,0,0,3,0,0,0,0,0
0,0,0,0,0,0,2,2,202,202,202,2,2,0,0,0,0,0
0,0,0,0,0,0,0,0,0,0,0,0,0,0,0,0,0,0
0,0,0,0,0,0,0,0,0,0,0,0,0,0,0,0,0,0
0,0,0,0,0,0,0,0,0,0,0,0,0,0,0,0,0,0
0,0,0,0,0,0,0,0,0,0,0,0,0,0,0,0,0,0
0,0,0,0,0,0,0,0,0,0,0,0,0,0,0,0,0,0
0,0,0,0,0,0,0,0,0,0,0,0,0,0,0,0,0,0
0,0,0,0,0,0,0,0,0,0,0,0,0,0,0,0,0,0
0,0,0,0,0,0,0,0,0,0,0,0,0,0,0,0,0,0
0,0,0,0,0,0,0,0,0,0,0,0,0,0,0,0,0,0
0,0,0,0,0,0,0,0,0,0,0,0,0,0,0,0,0,0
0,0,0,0,0,0,0,0,0,0,0,0,0,0,0,0,0,0
0,0,0,0,0,0,0,0,0,0,0,0,0,0,0,0,0,0
0,0,0,0,0,0,0,0,0,0,0,0,0,0,0,0,0,0
0,0,0,0,0,0,0,0,0,0,0,0,0,0,0,0,0,0
0,0,0,0,0,0,0,0,0,0,0,0,0,0,0,0,0,0
0,0,0,0,0,0,0,0,0,0,0,0,0,0,0,0,0,0
0,0,0,0,0,0,0,0,0,0,0,0,0,0,0,0,0,0
0,0,0,0,0,0,0,0,0,0,0,0,0,0,0,0,0,0
:endlayer
layer: 23
0,0,0,0,0,0,0,0,0,0,0,0,0,0,0,0,0,0
0,0,0,0,0,0,0,0,0,0,0,0,0,0,0,0,0,0
0,0,0,0,0,0,2,202,202,460,202,202,2,0,0,0,0,0
0,0,0,0,0,0,3,0,0,0,0,0,3,0,0,0,0,0
0,0,0,0,0,0,202,0,0,0,0,0,202,0,0,0,0,0
0,0,0,0,0,0,202,0,0,0,0,0,202,0,0,0,0,0
0,0,0,0,0,0,202,0,0,0,0,0,202,0,0,0,0,0
0,0,0,0,0,0,3,0,0,0,0,0,3,0,0,0,0,0
0,0,0,0,0,0,2,62,0,0,0,73,2,0,0,0,0,0
0,0,0,0,0,0,3,0,0,0,0,0,3,0,0,0,0,0
0,0,0,0,0,0,202,0,0,0,0,0,202,0,0,0,0,0
0,0,0,0,0,0,202,0,0,0,0,0,202,0,0,0,0,0
0,0,0,0,0,0,3,0,0,0,0,0,3,0,0,0,0,0
0,0,0,0,0,0,2,62,0,0,0,73,2,0,0,0,0,0
0,0,0,0,0,0,3,0,0,0,0,0,3,0,0,0,0,0
0,0,0,0,0,0,202,0,0,0,0,0,202,0,0,0,0,0
0,0,0,0,0,0,202,0,0,0,0,0,202,0,0,0,0,0
0,0,0,0,0,0,3,0,0,0,0,0,3,0,0,0,0,0
0,0,0,0,0,0,2,62,0,0,0,73,2,0,0,0,0,0
0,0,0,0,0,0,3,0,0,0,0,0,3,0,0,0,0,0
0,0,0,0,0,0,202,0,0,0,0,0,202,0,0,0,0,0
0,0,0,0,0,0,202,0,0,0,0,0,202,0,0,0,0,0
0,0,0,0,0,0,3,0,0,0,0,0,3,0,0,0,0,0
0,0,0,0,0,0,2,62,0,0,0,73,2,0,0,0,0,0
0,0,0,0,0,0,3,0,0,0,0,0,3,0,0,0,0,0
0,0,0,0,0,0,202,0,0,0,0,0,202,0,0,0,0,0
0,0,0,0,0,0,202,0,0,0,0,0,202,0,0,0,0,0
0,0,0,0,0,0,3,0,0,0,0,0,3,0,0,0,0,0
0,0,0,0,0,0,2,62,0,0,0,73,2,0,0,0,0,0
0,0,0,0,0,0,3,0,0,0,0,0,3,0,0,0,0,0
0,0,0,0,0,0,202,0,0,0,0,0,202,0,0,0,0,0
0,0,0,0,0,0,202,0,0,0,0,0,202,0,0,0,0,0
0,0,0,0,0,0,3,0,0,0,0,0,3,0,0,0,0,0
0,0,0,0,0,0,2,62,0,0,0,73,2,0,0,0,0,0
0,0,0,0,0,0,3,0,0,0,0,0,3,0,0,0,0,0
0,0,0,0,0,0,202,0,0,0,0,0,202,0,0,0,0,0
0,0,0,0,0,0,202,0,0,0,0,0,202,0,0,0,0,0
0,0,0,0,0,0,3,0,0,0,0,0,3,0,0,0,0,0
0,0,0,0,0,0,2,62,0,0,0,73,2,0,0,0,0,0
0,0,0,0,0,0,3,0,0,0,0,0,3,0,0,0,0,0
0,0,0,0,0,0,202,0,0,0,0,0,202,0,0,0,0,0
0,0,0,0,0,0,202,0,0,0,0,0,202,0,0,0,0,0
0,0,0,0,0,0,202,0,0,0,0,0,202,0,0,0,0,0
0,0,0,0,0,0,3,0,448,0,448,0,3,0,0,0,0,0
0,0,0,0,0,0,2,17,2,202,2,17,2,0,0,0,0,0
0,0,0,0,0,0,0,0,0,0,0,0,0,0,0,0,0,0
0,0,0,0,0,0,0,0,0,0,0,0,0,0,0,0,0,0
0,0,0,0,0,0,0,0,0,0,0,0,0,0,0,0,0,0
0,0,0,0,0,0,0,0,0,0,0,0,0,0,0,0,0,0
0,0,0,0,0,0,0,0,0,0,0,0,0,0,0,0,0,0
0,0,0,0,0,0,0,0,0,0,0,0,0,0,0,0,0,0
0,0,0,0,0,0,0,0,0,0,0,0,0,0,0,0,0,0
0,0,0,0,0,0,0,0,0,0,0,0,0,0,0,0,0,0
0,0,0,0,0,0,0,0,0,0,0,0,0,0,0,0,0,0
0,0,0,0,0,0,0,0,0,0,0,0,0,0,0,0,0,0
0,0,0,0,0,0,0,0,0,0,0,0,0,0,0,0,0,0
0,0,0,0,0,0,0,0,0,0,0,0,0,0,0,0,0,0
0,0,0,0,0,0,0,0,0,0,0,0,0,0,0,0,0,0
0,0,0,0,0,0,0,0,0,0,0,0,0,0,0,0,0,0
0,0,0,0,0,0,0,0,0,0,0,0,0,0,0,0,0,0
0,0,0,0,0,0,0,0,0,0,0,0,0,0,0,0,0,0
0,0,0,0,0,0,0,0,0,0,0,0,0,0,0,0,0,0
0,0,0,0,0,0,0,0,0,0,0,0,0,0,0,0,0,0
:endlayer
layer: 24
0,0,0,0,0,0,0,0,0,0,0,0,0,0,0,0,0,0
0,0,0,0,0,0,0,0,0,0,0,0,0,0,0,0,0,0
0,0,0,0,0,0,2,2,202,202,202,2,2,0,0,0,0,0
0,0,0,0,0,0,3,0,0,0,0,0,3,0,0,0,0,0
0,0,0,0,0,0,202,0,0,0,0,0,202,0,0,0,0,0
0,0,0,0,0,0,202,0,0,0,0,0,202,0,0,0,0,0
0,0,0,0,0,0,202,0,0,0,0,0,202,0,0,0,0,0
0,0,0,0,0,0,3,0,0,0,0,0,3,0,0,0,0,0
0,0,0,0,0,0,2,0,0,0,0,0,2,0,0,0,0,0
0,0,0,0,0,0,3,0,0,0,0,0,3,0,0,0,0,0
0,0,0,0,0,0,202,0,0,0,0,0,202,0,0,0,0,0
0,0,0,0,0,0,202,0,0,0,0,0,202,0,0,0,0,0
0,0,0,0,0,0,3,0,0,0,0,0,3,0,0,0,0,0
0,0,0,0,0,0,2,0,0,0,0,0,2,0,0,0,0,0
0,0,0,0,0,0,3,0,0,0,0,0,3,0,0,0,0,0
0,0,0,0,0,0,202,0,0,0,0,0,202,0,0,0,0,0
0,0,0,0,0,0,202,0,0,0,0,0,202,0,0,0,0,0
0,0,0,0,0,0,3,0,0,0,0,0,3,0,0,0,0,0
0,0,0,0,0,0,2,0,0,0,0,0,2,0,0,0,0,0
0,0,0,0,0,0,3,0,0,0,0,0,3,0,0,0,0,0
0,0,0,0,0,0,202,0,0,0,0,0,202,0,0,0,0,0
0,0,0,0,0,0,202,0,0,0,0,0,202,0,0,0,0,0
0,0,0,0,0,0,3,0,0,0,0,0,3,0,0,0,0,0
0,0,0,0,0,0,2,0,0,0,0,0,2,0,0,0,0,0
0,0,0,0,0,0,3,0,0,0,0,0,3,0,0,0,0,0
0,0,0,0,0,0,202,0,0,0,0,0,202,0,0,0,0,0
0,0,0,0,0,0,202,0,0,0,0,0,202,0,0,0,0,0
0,0,0,0,0,0,3,0,0,0,0,0,3,0,0,0,0,0
0,0,0,0,0,0,2,0,0,0,0,0,2,0,0,0,0,0
0,0,0,0,0,0,3,0,0,0,0,0,3,0,0,0,0,0
0,0,0,0,0,0,202,0,0,0,0,0,202,0,0,0,0,0
0,0,0,0,0,0,202,0,0,0,0,0,202,0,0,0,0,0
0,0,0,0,0,0,3,0,0,0,0,0,3,0,0,0,0,0
0,0,0,0,0,0,2,0,0,0,0,0,2,0,0,0,0,0
0,0,0,0,0,0,3,0,0,0,0,0,3,0,0,0,0,0
0,0,0,0,0,0,202,0,0,0,0,0,202,0,0,0,0,0
0,0,0,0,0,0,202,0,0,0,0,0,202,0,0,0,0,0
0,0,0,0,0,0,3,0,0,0,0,0,3,0,0,0,0,0
0,0,0,0,0,0,2,0,0,0,0,0,2,0,0,0,0,0
0,0,0,0,0,0,3,0,0,0,0,0,3,0,0,0,0,0
0,0,0,0,0,0,202,0,0,0,0,0,202,0,0,0,0,0
0,0,0,0,0,0,202,0,0,0,0,0,202,0,0,0,0,0
0,0,0,0,0,0,202,0,0,0,0,0,202,0,0,0,0,0
0,0,0,0,0,0,3,0,0,0,0,0,3,0,0,0,0,0
0,0,0,0,0,0,2,78,17,2,17,78,2,0,0,0,0,0
0,0,0,0,0,0,0,0,0,0,0,0,0,0,0,0,0,0
0,0,0,0,0,0,0,0,0,0,0,0,0,0,0,0,0,0
0,0,0,0,0,0,0,0,0,0,0,0,0,0,0,0,0,0
0,0,0,0,0,0,0,0,0,0,0,0,0,0,0,0,0,0
0,0,0,0,0,0,0,0,0,0,0,0,0,0,0,0,0,0
0,0,0,0,0,0,0,0,0,0,0,0,0,0,0,0,0,0
0,0,0,0,0,0,0,0,0,0,0,0,0,0,0,0,0,0
0,0,0,0,0,0,0,0,0,0,0,0,0,0,0,0,0,0
0,0,0,0,0,0,0,0,0,0,0,0,0,0,0,0,0,0
0,0,0,0,0,0,0,0,0,0,0,0,0,0,0,0,0,0
0,0,0,0,0,0,0,0,0,0,0,0,0,0,0,0,0,0
0,0,0,0,0,0,0,0,0,0,0,0,0,0,0,0,0,0
0,0,0,0,0,0,0,0,0,0,0,0,0,0,0,0,0,0
0,0,0,0,0,0,0,0,0,0,0,0,0,0,0,0,0,0
0,0,0,0,0,0,0,0,0,0,0,0,0,0,0,0,0,0
0,0,0,0,0,0,0,0,0,0,0,0,0,0,0,0,0,0
0,0,0,0,0,0,0,0,0,0,0,0,0,0,0,0,0,0
0,0,0,0,0,0,0,0,0,0,0,0,0,0,0,0,0,0
:endlayer
layer: 25
0,0,0,0,0,0,0,0,0,0,0,0,0,0,0,0,0,0
0,0,0,0,0,0,0,0,0,0,0,0,0,0,0,0,0,0
0,0,0,0,0,0,2,2,2,202,2,2,2,0,0,0,0,0
0,0,0,0,0,0,2,0,63,0,63,0,2,0,0,0,0,0
0,0,0,0,0,0,3,0,0,0,0,0,3,0,0,0,0,0
0,0,0,0,0,0,202,0,0,0,0,0,202,0,0,0,0,0
0,0,0,0,0,0,3,0,0,0,0,0,3,0,0,0,0,0
0,0,0,0,0,0,2,0,0,0,0,0,2,0,0,0,0,0
0,0,0,0,0,0,15,2,0,0,0,2,14,0,0,0,0,0
0,0,0,0,0,0,2,0,0,0,0,0,2,0,0,0,0,0
0,0,0,0,0,0,3,0,0,0,0,0,3,0,0,0,0,0
0,0,0,0,0,0,3,0,0,0,0,0,3,0,0,0,0,0
0,0,0,0,0,0,2,0,0,0,0,0,2,0,0,0,0,0
0,0,0,0,0,0,15,2,0,0,0,2,14,0,0,0,0,0
0,0,0,0,0,0,2,0,0,0,0,0,2,0,0,0,0,0
0,0,0,0,0,0,3,0,0,0,0,0,3,0,0,0,0,0
0,0,0,0,0,0,3,0,0,0,0,0,3,0,0,0,0,0
0,0,0,0,0,0,2,0,0,0,0,0,2,0,0,0,0,0
0,0,0,0,0,0,15,2,0,0,0,2,14,0,0,0,0,0
0,0,0,0,0,0,2,0,0,0,0,0,2,0,0,0,0,0
0,0,0,0,0,0,3,0,0,0,0,0,3,0,0,0,0,0
0,0,0,0,0,0,3,0,0,0,0,0,3,0,0,0,0,0
0,0,0,0,0,0,2,0,0,0,0,0,2,0,0,0,0,0
0,0,0,0,0,0,15,2,0,0,0,2,14,0,0,0,0,0
0,0,0,0,0,0,2,0,0,0,0,0,2,0,0,0,0,0
0,0,0,0,0,0,3,0,0,0,0,0,3,0,0,0,0,0
0,0,0,0,0,0,3,0,0,0,0,0,3,0,0,0,0,0
0,0,0,0,0,0,2,0,0,0,0,0,2,0,0,0,0,0
0,0,0,0,0,0,15,2,0,0,0,2,14,0,0,0,0,0
0,0,0,0,0,0,2,0,0,0,0,0,2,0,0,0,0,0
0,0,0,0,0,0,3,0,0,0,0,0,3,0,0,0,0,0
0,0,0,0,0,0,3,0,0,0,0,0,3,0,0,0,0,0
0,0,0,0,0,0,2,0,0,0,0,0,2,0,0,0,0,0
0,0,0,0,0,0,15,2,0,0,0,2,14,0,0,0,0,0
0,0,0,0,0,0,2,0,0,0,0,0,2,0,0,0,0,0
0,0,0,0,0,0,3,0,0,0,0,0,3,0,0,0,0,0
0,0,0,0,0,0,3,0,0,0,0,0,3,0,0,0,0,0
0,0,0,0,0,0,2,0,0,0,0,0,2,0,0,0,0,0
0,0,0,0,0,0,15,2,0,0,0,2,14,0,0,0,0,0
0,0,0,0,0,0,2,0,0,0,0,0,2,0,0,0,0,0
0,0,0,0,0,0,3,0,0,0,0,0,3,0,0,0,0,0
0,0,0,0,0,0,202,0,0,0,0,0,202,0,0,0,0,0
0,0,0,0,0,0,3,0,0,0,0,0,3,0,0,0,0,0
0,0,0,0,0,0,2,0,0,0,0,0,2,0,0,0,0,0
0,0,0,0,0,0,2,2,78,3,78,2,2,0,0,0,0,0
0,0,0,0,0,0,0,0,0,0,0,0,0,0,0,0,0,0
0,0,0,0,0,0,0,0,0,0,0,0,0,0,0,0,0,0
0,0,0,0,0,0,0,0,0,0,0,0,0,0,0,0,0,0
0,0,0,0,0,0,0,0,0,0,0,0,0,0,0,0,0,0
0,0,0,0,0,0,0,0,0,0,0,0,0,0,0,0,0,0
0,0,0,0,0,0,0,0,0,0,0,0,0,0,0,0,0,0
0,0,0,0,0,0,0,0,0,0,0,0,0,0,0,0,0,0
0,0,0,0,0,0,0,0,0,0,0,0,0,0,0,0,0,0
0,0,0,0,0,0,0,0,0,0,0,0,0,0,0,0,0,0
0,0,0,0,0,0,0,0,0,0,0,0,0,0,0,0,0,0
0,0,0,0,0,0,0,0,0,0,0,0,0,0,0,0,0,0
0,0,0,0,0,0,0,0,0,0,0,0,0,0,0,0,0,0
0,0,0,0,0,0,0,0,0,0,0,0,0,0,0,0,0,0
0,0,0,0,0,0,0,0,0,0,0,0,0,0,0,0,0,0
0,0,0,0,0,0,0,0,0,0,0,0,0,0,0,0,0,0
0,0,0,0,0,0,0,0,0,0,0,0,0,0,0,0,0,0
0,0,0,0,0,0,0,0,0,0,0,0,0,0,0,0,0,0
0,0,0,0,0,0,0,0,0,0,0,0,0,0,0,0,0,0
:endlayer
layer: 26
0,0,0,0,0,0,0,0,0,0,0,0,0,0,0,0,0,0
0,0,0,0,0,0,0,0,0,0,0,0,0,0,0,0,0,0
0,0,0,0,0,0,2,3,2,2,2,3,2,0,0,0,0,0
0,0,0,0,0,0,15,0,0,0,0,0,14,0,0,0,0,0
0,0,0,0,0,0,2,0,0,0,0,0,2,0,0,0,0,0
0,0,0,0,0,0,3,0,0,0,0,0,3,0,0,0,0,0
0,0,0,0,0,0,2,0,0,0,0,0,2,0,0,0,0,0
0,0,0,0,0,0,15,0,0,0,0,0,14,0,0,0,0,0
0,0,0,0,0,0,15,0,2,0,2,0,14,0,0,0,0,0
0,0,0,0,0,0,15,0,0,0,0,0,14,0,0,0,0,0
0,0,0,0,0,0,2,0,0,0,0,0,2,0,0,0,0,0
0,0,0,0,0,0,2,0,0,0,0,0,2,0,0,0,0,0
0,0,0,0,0,0,15,0,0,0,0,0,14,0,0,0,0,0
0,0,0,0,0,0,15,0,2,0,2,0,14,0,0,0,0,0
0,0,0,0,0,0,15,0,0,0,0,0,14,0,0,0,0,0
0,0,0,0,0,0,2,0,0,0,0,0,2,0,0,0,0,0
0,0,0,0,0,0,2,0,0,0,0,0,2,0,0,0,0,0
0,0,0,0,0,0,15,0,0,0,0,0,14,0,0,0,0,0
0,0,0,0,0,0,15,0,2,0,2,0,14,0,0,0,0,0
0,0,0,0,0,0,15,0,0,0,0,0,14,0,0,0,0,0
0,0,0,0,0,0,2,0,0,0,0,0,2,0,0,0,0,0
0,0,0,0,0,0,2,0,0,0,0,0,2,0,0,0,0,0
0,0,0,0,0,0,15,0,0,0,0,0,14,0,0,0,0,0
0,0,0,0,0,0,15,0,2,0,2,0,14,0,0,0,0,0
0,0,0,0,0,0,15,0,0,0,0,0,14,0,0,0,0,0
0,0,0,0,0,0,2,0,0,0,0,0,2,0,0,0,0,0
0,0,0,0,0,0,2,0,0,0,0,0,2,0,0,0,0,0
0,0,0,0,0,0,15,0,0,0,0,0,14,0,0,0,0,0
0,0,0,0,0,0,15,0,2,0,2,0,14,0,0,0,0,0
0,0,0,0,0,0,15,0,0,0,0,0,14,0,0,0,0,0
0,0,0,0,0,0,2,0,0,0,0,0,2,0,0,0,0,0
0,0,0,0,0,0,2,0,0,0,0,0,2,0,0,0,0,0
0,0,0,0,0,0,15,0,0,0,0,0,14,0,0,0,0,0
0,0,0,0,0,0,15,0,2,0,2,0,14,0,0,0,0,0
0,0,0,0,0,0,15,0,0,0,0,0,14,0,0,0,0,0
0,0,0,0,0,0,2,0,0,0,0,0,2,0,0,0,0,0
0,0,0,0,0,0,2,0,0,0,0,0,2,0,0,0,0,0
0,0,0,0,0,0,15,0,0,0,0,0,14,0,0,0,0,0
0,0,0,0,0,0,15,0,2,0,2,0,14,0,0,0,0,0
0,0,0,0,0,0,15,0,0,0,0,0,14,0,0,0,0,0
0,0,0,0,0,0,2,0,0,0,0,0,2,0,0,0,0,0
0,0,0,0,0,0,3,0,0,0,0,0,3,0,0,0,0,0
0,0,0,0,0,0,2,0,0,0,0,0,2,0,0,0,0,0
0,0,0,0,0,0,15,0,0,0,0,0,14,0,0,0,0,0
0,0,0,0,0,0,2,17,2,19,2,17,2,0,0,0,0,0
0,0,0,0,0,0,0,0,0,0,0,0,0,0,0,0,0,0
0,0,0,0,0,0,0,0,0,0,0,0,0,0,0,0,0,0
0,0,0,0,0,0,0,0,0,0,0,0,0,0,0,0,0,0
0,0,0,0,0,0,0,0,0,0,0,0,0,0,0,0,0,0
0,0,0,0,0,0,0,0,0,0,0,0,0,0,0,0,0,0
0,0,0,0,0,0,0,0,0,0,0,0,0,0,0,0,0,0
0,0,0,0,0,0,0,0,0,0,0,0,0,0,0,0,0,0
0,0,0,0,0,0,0,0,0,0,0,0,0,0,0,0,0,0
0,0,0,0,0,0,0,0,0,0,0,0,0,0,0,0,0,0
0,0,0,0,0,0,0,0,0,0,0,0,0,0,0,0,0,0
0,0,0,0,0,0,0,0,0,0,0,0,0,0,0,0,0,0
0,0,0,0,0,0,0,0,0,0,0,0,0,0,0,0,0,0
0,0,0,0,0,0,0,0,0,0,0,0,0,0,0,0,0,0
0,0,0,0,0,0,0,0,0,0,0,0,0,0,0,0,0,0
0,0,0,0,0,0,0,0,0,0,0,0,0,0,0,0,0,0
0,0,0,0,0,0,0,0,0,0,0,0,0,0,0,0,0,0
0,0,0,0,0,0,0,0,0,0,0,0,0,0,0,0,0,0
0,0,0,0,0,0,0,0,0,0,0,0,0,0,0,0,0,0
:endlayer
layer: 27
0,0,0,0,0,0,0,0,0,0,0,0,0,0,0,0,0,0
0,0,0,0,0,0,0,0,0,0,0,0,0,0,0,0,0,0
0,0,0,0,0,0,2,3,3,2,3,3,2,0,0,0,0,0
0,0,0,0,0,0,15,0,0,0,0,0,66,0,0,0,0,0
0,0,0,0,0,0,15,0,0,0,0,0,66,0,0,0,0,0
0,0,0,0,0,0,2,0,0,0,0,0,2,0,0,0,0,0
0,0,0,0,0,0,70,0,0,0,0,0,66,0,0,0,0,0
0,0,0,0,0,0,70,0,0,448,0,0,66,0,0,0,0,0
0,0,0,0,0,0,70,0,0,2,0,0,66,0,0,0,0,0
0,0,0,0,0,0,70,0,0,63,0,0,66,0,0,0,0,0
0,0,0,0,0,0,15,2,0,0,0,2,14,0,0,0,0,0
0,0,0,0,0,0,15,2,0,0,0,2,14,0,0,0,0,0
0,0,0,0,0,0,70,0,0,448,0,0,66,0,0,0,0,0
0,0,0,0,0,0,70,0,0,2,0,0,66,0,0,0,0,0
0,0,0,0,0,0,70,0,0,63,0,0,66,0,0,0,0,0
0,0,0,0,0,0,15,2,0,0,0,2,14,0,0,0,0,0
0,0,0,0,0,0,15,2,0,0,0,2,14,0,0,0,0,0
0,0,0,0,0,0,70,0,0,448,0,0,66,0,0,0,0,0
0,0,0,0,0,0,70,0,0,2,0,0,66,0,0,0,0,0
0,0,0,0,0,0,70,0,0,63,0,0,66,0,0,0,0,0
0,0,0,0,0,0,15,2,0,0,0,2,14,0,0,0,0,0
0,0,0,0,0,0,15,2,0,0,0,2,14,0,0,0,0,0
0,0,0,0,0,0,70,0,0,448,0,0,66,0,0,0,0,0
0,0,0,0,0,0,70,0,0,2,0,0,66,0,0,0,0,0
0,0,0,0,0,0,70,0,0,63,0,0,66,0,0,0,0,0
0,0,0,0,0,0,15,2,0,0,0,2,14,0,0,0,0,0
0,0,0,0,0,0,15,2,0,0,0,2,14,0,0,0,0,0
0,0,0,0,0,0,70,0,0,448,0,0,66,0,0,0,0,0
0,0,0,0,0,0,70,0,0,2,0,0,66,0,0,0,0,0
0,0,0,0,0,0,70,0,0,63,0,0,66,0,0,0,0,0
0,0,0,0,0,0,15,2,0,0,0,2,14,0,0,0,0,0
0,0,0,0,0,0,15,2,0,0,0,2,14,0,0,0,0,0
0,0,0,0,0,0,70,0,0,448,0,0,66,0,0,0,0,0
0,0,0,0,0,0,70,0,0,2,0,0,66,0,0,0,0,0
0,0,0,0,0,0,70,0,0,63,0,0,66,0,0,0,0,0
0,0,0,0,0,0,15,2,0,0,0,2,14,0,0,0,0,0
0,0,0,0,0,0,15,2,0,0,0,2,14,0,0,0,0,0
0,0,0,0,0,0,70,0,0,448,0,0,66,0,0,0,0,0
0,0,0,0,0,0,70,0,0,2,0,0,66,0,0,0,0,0
0,0,0,0,0,0,70,0,0,63,0,0,66,0,0,0,0,0
0,0,0,0,0,0,70,0,0,0,0,0,66,0,0,0,0,0
0,0,0,0,0,0,2,0,0,0,0,0,2,0,0,0,0,0
0,0,0,0,0,0,70,0,0,0,0,0,66,0,0,0,0,0
0,0,0,0,0,0,70,0,0,0,0,0,66,0,0,0,0,0
0,0,0,0,0,0,2,78,17,2,17,78,2,0,0,0,0,0
0,0,0,0,0,0,0,0,0,0,0,0,0,0,0,0,0,0
0,0,0,0,0,0,0,0,0,0,0,0,0,0,0,0,0,0
0,0,0,0,0,0,0,0,0,0,0,0,0,0,0,0,0,0
0,0,0,0,0,0,0,0,0,0,0,0,0,0,0,0,0,0
0,0,0,0,0,0,0,0,0,0,0,0,0,0,0,0,0,0
0,0,0,0,0,0,0,0,0,0,0,0,0,0,0,0,0,0
0,0,0,0,0,0,0,0,0,0,0,0,0,0,0,0,0,0
0,0,0,0,0,0,0,0,0,0,0,0,0,0,0,0,0,0
0,0,0,0,0,0,0,0,0,0,0,0,0,0,0,0,0,0
0,0,0,0,0,0,0,0,0,0,0,0,0,0,0,0,0,0
0,0,0,0,0,0,0,0,0,0,0,0,0,0,0,0,0,0
0,0,0,0,0,0,0,0,0,0,0,0,0,0,0,0,0,0
0,0,0,0,0,0,0,0,0,0,0,0,0,0,0,0,0,0
0,0,0,0,0,0,0,0,0,0,0,0,0,0,0,0,0,0
0,0,0,0,0,0,0,0,0,0,0,0,0,0,0,0,0,0
0,0,0,0,0,0,0,0,0,0,0,0,0,0,0,0,0,0
0,0,0,0,0,0,0,0,0,0,0,0,0,0,0,0,0,0
0,0,0,0,0,0,0,0,0,0,0,0,0,0,0,0,0,0
:endlayer
layer: 28
0,0,0,0,0,0,0,0,0,0,0,0,0,0,0,0,0,0
0,0,0,0,0,0,0,0,0,0,0,0,0,0,0,0,0,0
0,0,0,0,0,0,15,2,3,3,3,2,14,0,0,0,0,0
0,0,0,0,0,0,70,74,0,0,0,74,66,0,0,0,0,0
0,0,0,0,0,0,70,74,0,0,0,74,66,0,0,0,0,0
0,0,0,0,0,0,15,2,0,0,0,2,14,0,0,0,0,0
0,0,0,0,0,0,70,74,0,0,0,74,66,0,0,0,0,0
0,0,0,0,0,0,70,74,0,0,0,74,66,0,0,0,0,0
0,0,0,0,0,0,70,74,0,2,0,74,66,0,0,0,0,0
0,0,0,0,0,0,70,74,0,0,0,74,66,0,0,0,0,0
0,0,0,0,0,0,15,74,2,0,2,74,14,0,0,0,0,0
0,0,0,0,0,0,15,74,2,0,2,74,14,0,0,0,0,0
0,0,0,0,0,0,70,74,0,0,0,74,66,0,0,0,0,0
0,0,0,0,0,0,70,74,0,2,0,74,66,0,0,0,0,0
0,0,0,0,0,0,70,74,0,0,0,74,66,0,0,0,0,0
0,0,0,0,0,0,15,74,2,0,2,74,14,0,0,0,0,0
0,0,0,0,0,0,15,74,2,0,2,74,14,0,0,0,0,0
0,0,0,0,0,0,70,74,0,0,0,74,66,0,0,0,0,0
0,0,0,0,0,0,70,74,0,2,0,74,66,0,0,0,0,0
0,0,0,0,0,0,70,74,0,0,0,74,66,0,0,0,0,0
0,0,0,0,0,0,15,74,2,0,2,74,14,0,0,0,0,0
0,0,0,0,0,0,15,74,2,0,2,74,14,0,0,0,0,0
0,0,0,0,0,0,70,74,0,0,0,74,66,0,0,0,0,0
0,0,0,0,0,0,70,74,0,2,0,74,66,0,0,0,0,0
0,0,0,0,0,0,70,74,0,0,0,74,66,0,0,0,0,0
0,0,0,0,0,0,15,74,2,0,2,74,14,0,0,0,0,0
0,0,0,0,0,0,15,74,2,0,2,74,14,0,0,0,0,0
0,0,0,0,0,0,70,74,0,0,0,74,66,0,0,0,0,0
0,0,0,0,0,0,70,74,0,2,0,74,66,0,0,0,0,0
0,0,0,0,0,0,70,74,0,0,0,74,66,0,0,0,0,0
0,0,0,0,0,0,15,74,2,0,2,74,14,0,0,0,0,0
0,0,0,0,0,0,15,74,2,0,2,74,14,0,0,0,0,0
0,0,0,0,0,0,70,74,0,0,0,74,66,0,0,0,0,0
0,0,0,0,0,0,70,74,0,2,0,74,66,0,0,0,0,0
0,0,0,0,0,0,70,74,0,0,0,74,66,0,0,0,0,0
0,0,0,0,0,0,15,74,2,0,2,74,14,0,0,0,0,0
0,0,0,0,0,0,15,74,2,0,2,74,14,0,0,0,0,0
0,0,0,0,0,0,70,74,0,0,0,74,66,0,0,0,0,0
0,0,0,0,0,0,70,74,0,2,0,74,66,0,0,0,0,0
0,0,0,0,0,0,70,74,0,0,0,74,66,0,0,0,0,0
0,0,0,0,0,0,70,74,0,0,0,74,66,0,0,0,0,0
0,0,0,0,0,0,15,2,0,0,0,2,14,0,0,0,0,0
0,0,0,0,0,0,70,74,0,0,0,74,66,0,0,0,0,0
0,0,0,0,0,0,70,74,0,0,0,74,66,0,0,0,0,0
0,0,0,0,0,0,15,2,78,2,78,2,14,0,0,0,0,0
0,0,0,0,0,0,0,0,0,0,0,0,0,0,0,0,0,0
0,0,0,0,0,0,0,0,0,0,0,0,0,0,0,0,0,0
0,0,0,0,0,0,0,0,0,0,0,0,0,0,0,0,0,0
0,0,0,0,0,0,0,0,0,0,0,0,0,0,0,0,0,0
0,0,0,0,0,0,0,0,0,0,0,0,0,0,0,0,0,0
0,0,0,0,0,0,0,0,0,0,0,0,0,0,0,0,0,0
0,0,0,0,0,0,0,0,0,0,0,0,0,0,0,0,0,0
0,0,0,0,0,0,0,0,0,0,0,0,0,0,0,0,0,0
0,0,0,0,0,0,0,0,0,0,0,0,0,0,0,0,0,0
0,0,0,0,0,0,0,0,0,0,0,0,0,0,0,0,0,0
0,0,0,0,0,0,0,0,0,0,0,0,0,0,0,0,0,0
0,0,0,0,0,0,0,0,0,0,0,0,0,0,0,0,0,0
0,0,0,0,0,0,0,0,0,0,0,0,0,0,0,0,0,0
0,0,0,0,0,0,0,0,0,0,0,0,0,0,0,0,0,0
0,0,0,0,0,0,0,0,0,0,0,0,0,0,0,0,0,0
0,0,0,0,0,0,0,0,0,0,0,0,0,0,0,0,0,0
0,0,0,0,0,0,0,0,0,0,0,0,0,0,0,0,0,0
0,0,0,0,0,0,0,0,0,0,0,0,0,0,0,0,0,0
:endlayer
layer: 29
0,0,0,0,0,0,0,0,0,0,0,0,0,0,0,0,0,0
0,0,0,0,0,0,0,0,0,0,0,0,0,0,0,0,0,0
0,0,0,0,0,0,0,15,2,3,2,14,0,0,0,0,0,0
0,0,0,0,0,0,0,70,74,0,74,66,0,0,0,0,0,0
0,0,0,0,0,0,0,70,74,0,74,66,0,0,0,0,0,0
0,0,0,0,0,0,0,15,2,0,2,14,0,0,0,0,0,0
0,0,0,0,0,0,0,70,74,0,74,66,0,0,0,0,0,0
0,0,0,0,0,0,0,70,74,0,74,66,0,0,0,0,0,0
0,0,0,0,0,0,0,70,74,2,74,66,0,0,0,0,0,0
0,0,0,0,0,0,0,70,74,0,74,66,0,0,0,0,0,0
0,0,0,0,0,0,0,15,74,2,74,14,0,0,0,0,0,0
0,0,0,0,0,0,0,15,74,2,74,14,0,0,0,0,0,0
0,0,0,0,0,0,0,70,74,0,74,66,0,0,0,0,0,0
0,0,0,0,0,0,0,70,74,2,74,66,0,0,0,0,0,0
0,0,0,0,0,0,0,70,74,0,74,66,0,0,0,0,0,0
0,0,0,0,0,0,0,15,74,2,74,14,0,0,0,0,0,0
0,0,0,0,0,0,0,15,74,2,74,14,0,0,0,0,0,0
0,0,0,0,0,0,0,70,74,0,74,66,0,0,0,0,0,0
0,0,0,0,0,0,0,70,74,2,74,66,0,0,0,0,0,0
0,0,0,0,0,0,0,70,74,0,74,66,0,0,0,0,0,0
0,0,0,0,0,0,0,15,74,2,74,14,0,0,0,0,0,0
0,0,0,0,0,0,0,15,74,2,74,14,0,0,0,0,0,0
0,0,0,0,0,0,0,70,74,0,74,66,0,0,0,0,0,0
0,0,0,0,0,0,0,70,74,2,74,66,0,0,0,0,0,0
0,0,0,0,0,0,0,70,74,0,74,66,0,0,0,0,0,0
0,0,0,0,0,0,0,15,74,2,74,14,0,0,0,0,0,0
0,0,0,0,0,0,0,15,74,2,74,14,0,0,0,0,0,0
0,0,0,0,0,0,0,70,74,0,74,66,0,0,0,0,0,0
0,0,0,0,0,0,0,70,74,2,74,66,0,0,0,0,0,0
0,0,0,0,0,0,0,70,74,0,74,66,0,0,0,0,0,0
0,0,0,0,0,0,0,15,74,2,74,14,0,0,0,0,0,0
0,0,0,0,0,0,0,15,74,2,74,14,0,0,0,0,0,0
0,0,0,0,0,0,0,70,74,0,74,66,0,0,0,0,0,0
0,0,0,0,0,0,0,70,74,2,74,66,0,0,0,0,0,0
0,0,0,0,0,0,0,70,74,0,74,66,0,0,0,0,0,0
0,0,0,0,0,0,0,15,74,2,74,14,0,0,0,0,0,0
0,0,0,0,0,0,0,15,74,2,74,14,0,0,0,0,0,0
0,0,0,0,0,0,0,70,74,0,74,66,0,0,0,0,0,0
0,0,0,0,0,0,0,70,74,2,74,66,0,0,0,0,0,0
0,0,0,0,0,0,0,70,74,0,74,66,0,0,0,0,0,0
0,0,0,0,0,0,0,70,74,0,74,66,0,0,0,0,0,0
0,0,0,0,0,0,0,15,2,0,2,14,0,0,0,0,0,0
0,0,0,0,0,0,0,70,74,0,74,66,0,0,0,0,0,0
0,0,0,0,0,0,0,70,74,0,74,66,0,0,0,0,0,0
0,0,0,0,0,0,0,15,2,3,2,14,0,0,0,0,0,0
0,0,0,0,0,0,0,0,0,0,0,0,0,0,0,0,0,0
0,0,0,0,0,0,0,0,0,0,0,0,0,0,0,0,0,0
0,0,0,0,0,0,0,0,0,0,0,0,0,0,0,0,0,0
0,0,0,0,0,0,0,0,0,0,0,0,0,0,0,0,0,0
0,0,0,0,0,0,0,0,0,0,0,0,0,0,0,0,0,0
0,0,0,0,0,0,0,0,0,0,0,0,0,0,0,0,0,0
0,0,0,0,0,0,0,0,0,0,0,0,0,0,0,0,0,0
0,0,0,0,0,0,0,0,0,0,0,0,0,0,0,0,0,0
0,0,0,0,0,0,0,0,0,0,0,0,0,0,0,0,0,0
0,0,0,0,0,0,0,0,0,0,0,0,0,0,0,0,0,0
0,0,0,0,0,0,0,0,0,0,0,0,0,0,0,0,0,0
0,0,0,0,0,0,0,0,0,0,0,0,0,0,0,0,0,0
0,0,0,0,0,0,0,0,0,0,0,0,0,0,0,0,0,0
0,0,0,0,0,0,0,0,0,0,0,0,0,0,0,0,0,0
0,0,0,0,0,0,0,0,0,0,0,0,0,0,0,0,0,0
0,0,0,0,0,0,0,0,0,0,0,0,0,0,0,0,0,0
0,0,0,0,0,0,0,0,0,0,0,0,0,0,0,0,0,0
0,0,0,0,0,0,0,0,0,0,0,0,0,0,0,0,0,0
:endlayer
layer: 30
0,0,0,0,0,0,0,0,0,0,0,0,0,0,0,0,0,0
0,0,0,0,0,0,0,0,0,0,0,0,0,0,0,0,0,0
0,0,0,0,0,0,0,0,15,2,14,0,0,0,0,0,0,0
0,0,0,0,0,0,0,0,70,74,66,0,0,0,0,0,0,0
0,0,0,0,0,0,0,0,70,74,66,0,0,0,0,0,0,0
0,0,0,0,0,0,0,0,15,2,14,0,0,0,0,0,0,0
0,0,0,0,0,0,0,0,70,74,66,0,0,0,0,0,0,0
0,0,0,0,0,0,0,0,70,74,66,0,0,0,0,0,0,0
0,0,0,0,0,0,0,0,70,74,66,0,0,0,0,0,0,0
0,0,0,0,0,0,0,0,70,74,66,0,0,0,0,0,0,0
0,0,0,0,0,0,0,0,15,74,14,0,0,0,0,0,0,0
0,0,0,0,0,0,0,0,15,74,14,0,0,0,0,0,0,0
0,0,0,0,0,0,0,0,70,74,66,0,0,0,0,0,0,0
0,0,0,0,0,0,0,0,70,74,66,0,0,0,0,0,0,0
0,0,0,0,0,0,0,0,70,74,66,0,0,0,0,0,0,0
0,0,0,0,0,0,0,0,15,74,14,0,0,0,0,0,0,0
0,0,0,0,0,0,0,0,15,74,14,0,0,0,0,0,0,0
0,0,0,0,0,0,0,0,70,74,66,0,0,0,0,0,0,0
0,0,0,0,0,0,0,0,70,74,66,0,0,0,0,0,0,0
0,0,0,0,0,0,0,0,70,74,66,0,0,0,0,0,0,0
0,0,0,0,0,0,0,0,15,74,14,0,0,0,0,0,0,0
0,0,0,0,0,0,0,0,15,74,14,0,0,0,0,0,0,0
0,0,0,0,0,0,0,0,70,74,66,0,0,0,0,0,0,0
0,0,0,0,0,0,0,0,70,74,66,0,0,0,0,0,0,0
0,0,0,0,0,0,0,0,70,74,66,0,0,0,0,0,0,0
0,0,0,0,0,0,0,0,15,74,14,0,0,0,0,0,0,0
0,0,0,0,0,0,0,0,15,74,14,0,0,0,0,0,0,0
0,0,0,0,0,0,0,0,70,74,66,0,0,0,0,0,0,0
0,0,0,0,0,0,0,0,70,74,66,0,0,0,0,0,0,0
0,0,0,0,0,0,0,0,70,74,66,0,0,0,0,0,0,0
0,0,0,0,0,0,0,0,15,74,14,0,0,0,0,0,0,0
0,0,0,0,0,0,0,0,15,74,14,0,0,0,0,0,0,0
0,0,0,0,0,0,0,0,70,74,66,0,0,0,0,0,0,0
0,0,0,0,0,0,0,0,70,74,66,0,0,0,0,0,0,0
0,0,0,0,0,0,0,0,70,74,66,0,0,0,0,0,0,0
0,0,0,0,0,0,0,0,15,74,14,0,0,0,0,0,0,0
0,0,0,0,0,0,0,0,15,74,14,0,0,0,0,0,0,0
0,0,0,0,0,0,0,0,70,74,66,0,0,0,0,0,0,0
0,0,0,0,0,0,0,0,70,74,66,0,0,0,0,0,0,0
0,0,0,0,0,0,0,0,70,74,66,0,0,0,0,0,0,0
0,0,0,0,0,0,0,0,70,74,66,0,0,0,0,0,0,0
0,0,0,0,0,0,0,0,15,2,14,0,0,0,0,0,0,0
0,0,0,0,0,0,0,0,70,74,66,0,0,0,0,0,0,0
0,0,0,0,0,0,0,0,70,74,66,0,0,0,0,0,0,0
0,0,0,0,0,0,0,0,15,2,14,0,0,0,0,0,0,0
0,0,0,0,0,0,0,0,0,0,0,0,0,0,0,0,0,0
0,0,0,0,0,0,0,0,0,0,0,0,0,0,0,0,0,0
0,0,0,0,0,0,0,0,0,0,0,0,0,0,0,0,0,0
0,0,0,0,0,0,0,0,0,0,0,0,0,0,0,0,0,0
0,0,0,0,0,0,0,0,0,0,0,0,0,0,0,0,0,0
0,0,0,0,0,0,0,0,0,0,0,0,0,0,0,0,0,0
0,0,0,0,0,0,0,0,0,0,0,0,0,0,0,0,0,0
0,0,0,0,0,0,0,0,0,0,0,0,0,0,0,0,0,0
0,0,0,0,0,0,0,0,0,0,0,0,0,0,0,0,0,0
0,0,0,0,0,0,0,0,0,0,0,0,0,0,0,0,0,0
0,0,0,0,0,0,0,0,0,0,0,0,0,0,0,0,0,0
0,0,0,0,0,0,0,0,0,0,0,0,0,0,0,0,0,0
0,0,0,0,0,0,0,0,0,0,0,0,0,0,0,0,0,0
0,0,0,0,0,0,0,0,0,0,0,0,0,0,0,0,0,0
0,0,0,0,0,0,0,0,0,0,0,0,0,0,0,0,0,0
0,0,0,0,0,0,0,0,0,0,0,0,0,0,0,0,0,0
0,0,0,0,0,0,0,0,0,0,0,0,0,0,0,0,0,0
0,0,0,0,0,0,0,0,0,0,0,0,0,0,0,0,0,0
:endlayer
layer: 31
0,0,0,0,0,0,0,0,0,0,0,0,0,0,0,0,0,0
0,0,0,0,0,0,0,0,0,0,0,0,0,0,0,0,0,0
0,0,0,0,0,0,0,0,0,45,0,0,0,0,0,0,0,0
0,0,0,0,0,0,0,0,0,461,0,0,0,0,0,0,0,0
0,0,0,0,0,0,0,0,0,461,0,0,0,0,0,0,0,0
0,0,0,0,0,0,0,0,0,45,0,0,0,0,0,0,0,0
0,0,0,0,0,0,0,0,0,461,0,0,0,0,0,0,0,0
0,0,0,0,0,0,0,0,0,461,0,0,0,0,0,0,0,0
0,0,0,0,0,0,0,0,0,461,0,0,0,0,0,0,0,0
0,0,0,0,0,0,0,0,0,461,0,0,0,0,0,0,0,0
0,0,0,0,0,0,0,0,0,45,0,0,0,0,0,0,0,0
0,0,0,0,0,0,0,0,0,45,0,0,0,0,0,0,0,0
0,0,0,0,0,0,0,0,0,461,0,0,0,0,0,0,0,0
0,0,0,0,0,0,0,0,0,461,0,0,0,0,0,0,0,0
0,0,0,0,0,0,0,0,0,461,0,0,0,0,0,0,0,0
0,0,0,0,0,0,0,0,0,45,0,0,0,0,0,0,0,0
0,0,0,0,0,0,0,0,0,45,0,0,0,0,0,0,0,0
0,0,0,0,0,0,0,0,0,461,0,0,0,0,0,0,0,0
0,0,0,0,0,0,0,0,0,461,0,0,0,0,0,0,0,0
0,0,0,0,0,0,0,0,0,461,0,0,0,0,0,0,0,0
0,0,0,0,0,0,0,0,0,45,0,0,0,0,0,0,0,0
0,0,0,0,0,0,0,0,0,45,0,0,0,0,0,0,0,0
0,0,0,0,0,0,0,0,0,461,0,0,0,0,0,0,0,0
0,0,0,0,0,0,0,0,0,461,0,0,0,0,0,0,0,0
0,0,0,0,0,0,0,0,0,461,0,0,0,0,0,0,0,0
0,0,0,0,0,0,0,0,0,45,0,0,0,0,0,0,0,0
0,0,0,0,0,0,0,0,0,45,0,0,0,0,0,0,0,0
0,0,0,0,0,0,0,0,0,461,0,0,0,0,0,0,0,0
0,0,0,0,0,0,0,0,0,461,0,0,0,0,0,0,0,0
0,0,0,0,0,0,0,0,0,461,0,0,0,0,0,0,0,0
0,0,0,0,0,0,0,0,0,45,0,0,0,0,0,0,0,0
0,0,0,0,0,0,0,0,0,45,0,0,0,0,0,0,0,0
0,0,0,0,0,0,0,0,0,461,0,0,0,0,0,0,0,0
0,0,0,0,0,0,0,0,0,461,0,0,0,0,0,0,0,0
0,0,0,0,0,0,0,0,0,461,0,0,0,0,0,0,0,0
0,0,0,0,0,0,0,0,0,45,0,0,0,0,0,0,0,0
0,0,0,0,0,0,0,0,0,45,0,0,0,0,0,0,0,0
0,0,0,0,0,0,0,0,0,461,0,0,0,0,0,0,0,0
0,0,0,0,0,0,0,0,0,461,0,0,0,0,0,0,0,0
0,0,0,0,0,0,0,0,0,461,0,0,0,0,0,0,0,0
0,0,0,0,0,0,0,0,0,461,0,0,0,0,0,0,0,0
0,0,0,0,0,0,0,0,0,45,0,0,0,0,0,0,0,0
0,0,0,0,0,0,0,0,0,461,0,0,0,0,0,0,0,0
0,0,0,0,0,0,0,0,0,461,0,0,0,0,0,0,0,0
0,0,0,0,0,0,0,0,0,45,0,0,0,0,0,0,0,0
0,0,0,0,0,0,0,0,0,0,0,0,0,0,0,0,0,0
0,0,0,0,0,0,0,0,0,0,0,0,0,0,0,0,0,0
0,0,0,0,0,0,0,0,0,0,0,0,0,0,0,0,0,0
0,0,0,0,0,0,0,0,0,0,0,0,0,0,0,0,0,0
0,0,0,0,0,0,0,0,0,0,0,0,0,0,0,0,0,0
0,0,0,0,0,0,0,0,0,0,0,0,0,0,0,0,0,0
0,0,0,0,0,0,0,0,0,0,0,0,0,0,0,0,0,0
0,0,0,0,0,0,0,0,0,0,0,0,0,0,0,0,0,0
0,0,0,0,0,0,0,0,0,0,0,0,0,0,0,0,0,0
0,0,0,0,0,0,0,0,0,0,0,0,0,0,0,0,0,0
0,0,0,0,0,0,0,0,0,0,0,0,0,0,0,0,0,0
0,0,0,0,0,0,0,0,0,0,0,0,0,0,0,0,0,0
0,0,0,0,0,0,0,0,0,0,0,0,0,0,0,0,0,0
0,0,0,0,0,0,0,0,0,0,0,0,0,0,0,0,0,0
0,0,0,0,0,0,0,0,0,0,0,0,0,0,0,0,0,0
0,0,0,0,0,0,0,0,0,0,0,0,0,0,0,0,0,0
0,0,0,0,0,0,0,0,0,0,0,0,0,0,0,0,0,0
0,0,0,0,0,0,0,0,0,0,0,0,0,0,0,0,0,0
:endlayer
layer: 32
0,0,0,0,0,0,0,0,0,0,0,0,0,0,0,0,0,0
0,0,0,0,0,0,0,0,0,0,0,0,0,0,0,0,0,0
0,0,0,0,0,0,0,0,0,0,0,0,0,0,0,0,0,0
0,0,0,0,0,0,0,0,0,0,0,0,0,0,0,0,0,0
0,0,0,0,0,0,0,0,0,0,0,0,0,0,0,0,0,0
0,0,0,0,0,0,0,0,0,0,0,0,0,0,0,0,0,0
0,0,0,0,0,0,0,0,0,0,0,0,0,0,0,0,0,0
0,0,0,0,0,0,0,0,0,0,0,0,0,0,0,0,0,0
0,0,0,0,0,0,0,0,0,0,0,0,0,0,0,0,0,0
0,0,0,0,0,0,0,0,0,0,0,0,0,0,0,0,0,0
0,0,0,0,0,0,0,0,0,0,0,0,0,0,0,0,0,0
0,0,0,0,0,0,0,0,0,0,0,0,0,0,0,0,0,0
0,0,0,0,0,0,0,0,0,0,0,0,0,0,0,0,0,0
0,0,0,0,0,0,0,0,0,0,0,0,0,0,0,0,0,0
0,0,0,0,0,0,0,0,0,0,0,0,0,0,0,0,0,0
0,0,0,0,0,0,0,0,0,0,0,0,0,0,0,0,0,0
0,0,0,0,0,0,0,0,0,0,0,0,0,0,0,0,0,0
0,0,0,0,0,0,0,0,0,0,0,0,0,0,0,0,0,0
0,0,0,0,0,0,0,0,0,0,0,0,0,0,0,0,0,0
0,0,0,0,0,0,0,0,0,0,0,0,0,0,0,0,0,0
0,0,0,0,0,0,0,0,0,0,0,0,0,0,0,0,0,0
0,0,0,0,0,0,0,0,0,0,0,0,0,0,0,0,0,0
0,0,0,0,0,0,0,0,0,0,0,0,0,0,0,0,0,0
0,0,0,0,0,0,0,0,0,0,0,0,0,0,0,0,0,0
0,0,0,0,0,0,0,0,0,0,0,0,0,0,0,0,0,0
0,0,0,0,0,0,0,0,0,0,0,0,0,0,0,0,0,0
0,0,0,0,0,0,0,0,0,0,0,0,0,0,0,0,0,0
0,0,0,0,0,0,0,0,0,0,0,0,0,0,0,0,0,0
0,0,0,0,0,0,0,0,0,0,0,0,0,0,0,0,0,0
0,0,0,0,0,0,0,0,0,0,0,0,0,0,0,0,0,0
0,0,0,0,0,0,0,0,0,0,0,0,0,0,0,0,0,0
0,0,0,0,0,0,0,0,0,0,0,0,0,0,0,0,0,0
0,0,0,0,0,0,0,0,0,0,0,0,0,0,0,0,0,0
0,0,0,0,0,0,0,0,0,0,0,0,0,0,0,0,0,0
0,0,0,0,0,0,0,0,0,0,0,0,0,0,0,0,0,0
0,0,0,0,0,0,0,0,0,0,0,0,0,0,0,0,0,0
0,0,0,0,0,0,0,0,0,0,0,0,0,0,0,0,0,0
0,0,0,0,0,0,0,0,0,0,0,0,0,0,0,0,0,0
0,0,0,0,0,0,0,0,0,0,0,0,0,0,0,0,0,0
0,0,0,0,0,0,0,0,0,0,0,0,0,0,0,0,0,0
0,0,0,0,0,0,0,0,0,0,0,0,0,0,0,0,0,0
0,0,0,0,0,0,0,0,0,0,0,0,0,0,0,0,0,0
0,0,0,0,0,0,0,0,0,0,0,0,0,0,0,0,0,0
0,0,0,0,0,0,0,0,0,0,0,0,0,0,0,0,0,0
0,0,0,0,0,0,0,0,0,0,0,0,0,0,0,0,0,0
0,0,0,0,0,0,0,0,0,0,0,0,0,0,0,0,0,0
0,0,0,0,0,0,0,0,0,0,0,0,0,0,0,0,0,0
0,0,0,0,0,0,0,0,0,0,0,0,0,0,0,0,0,0
0,0,0,0,0,0,0,0,0,0,0,0,0,0,0,0,0,0
0,0,0,0,0,0,0,0,0,0,0,0,0,0,0,0,0,0
0,0,0,0,0,0,0,0,0,0,0,0,0,0,0,0,0,0
0,0,0,0,0,0,0,0,0,0,0,0,0,0,0,0,0,0
0,0,0,0,0,0,0,0,0,0,0,0,0,0,0,0,0,0
0,0,0,0,0,0,0,0,0,0,0,0,0,0,0,0,0,0
0,0,0,0,0,0,0,0,0,0,0,0,0,0,0,0,0,0
0,0,0,0,0,0,0,0,0,0,0,0,0,0,0,0,0,0
0,0,0,0,0,0,0,0,0,0,0,0,0,0,0,0,0,0
0,0,0,0,0,0,0,0,0,0,0,0,0,0,0,0,0,0
0,0,0,0,0,0,0,0,0,0,0,0,0,0,0,0,0,0
0,0,0,0,0,0,0,0,0,0,0,0,0,0,0,0,0,0
0,0,0,0,0,0,0,0,0,0,0,0,0,0,0,0,0,0
0,0,0,0,0,0,0,0,0,0,0,0,0,0,0,0,0,0
0,0,0,0,0,0,0,0,0,0,0,0,0,0,0,0,0,0
:endlayer
layer: 33
0,0,0,0,0,0,0,0,0,0,0,0,0,0,0,0,0,0
0,0,0,0,0,0,0,0,0,0,0,0,0,0,0,0,0,0
0,0,0,0,0,0,0,0,0,0,0,0,0,0,0,0,0,0
0,0,0,0,0,0,0,0,0,0,0,0,0,0,0,0,0,0
0,0,0,0,0,0,0,0,0,0,0,0,0,0,0,0,0,0
0,0,0,0,0,0,0,0,0,0,0,0,0,0,0,0,0,0
0,0,0,0,0,0,0,0,0,0,0,0,0,0,0,0,0,0
0,0,0,0,0,0,0,0,0,0,0,0,0,0,0,0,0,0
0,0,0,0,0,0,0,0,0,0,0,0,0,0,0,0,0,0
0,0,0,0,0,0,0,0,0,0,0,0,0,0,0,0,0,0
0,0,0,0,0,0,0,0,0,0,0,0,0,0,0,0,0,0
0,0,0,0,0,0,0,0,0,0,0,0,0,0,0,0,0,0
0,0,0,0,0,0,0,0,0,0,0,0,0,0,0,0,0,0
0,0,0,0,0,0,0,0,0,0,0,0,0,0,0,0,0,0
0,0,0,0,0,0,0,0,0,0,0,0,0,0,0,0,0,0
0,0,0,0,0,0,0,0,0,0,0,0,0,0,0,0,0,0
0,0,0,0,0,0,0,0,0,0,0,0,0,0,0,0,0,0
0,0,0,0,0,0,0,0,0,0,0,0,0,0,0,0,0,0
0,0,0,0,0,0,0,0,0,0,0,0,0,0,0,0,0,0
0,0,0,0,0,0,0,0,0,0,0,0,0,0,0,0,0,0
0,0,0,0,0,0,0,0,0,0,0,0,0,0,0,0,0,0
0,0,0,0,0,0,0,0,0,0,0,0,0,0,0,0,0,0
0,0,0,0,0,0,0,0,0,0,0,0,0,0,0,0,0,0
0,0,0,0,0,0,0,0,0,0,0,0,0,0,0,0,0,0
0,0,0,0,0,0,0,0,0,0,0,0,0,0,0,0,0,0
0,0,0,0,0,0,0,0,0,0,0,0,0,0,0,0,0,0
0,0,0,0,0,0,0,0,0,0,0,0,0,0,0,0,0,0
0,0,0,0,0,0,0,0,0,0,0,0,0,0,0,0,0,0
0,0,0,0,0,0,0,0,0,0,0,0,0,0,0,0,0,0
0,0,0,0,0,0,0,0,0,0,0,0,0,0,0,0,0,0
0,0,0,0,0,0,0,0,0,0,0,0,0,0,0,0,0,0
0,0,0,0,0,0,0,0,0,0,0,0,0,0,0,0,0,0
0,0,0,0,0,0,0,0,0,0,0,0,0,0,0,0,0,0
0,0,0,0,0,0,0,0,0,0,0,0,0,0,0,0,0,0
0,0,0,0,0,0,0,0,0,0,0,0,0,0,0,0,0,0
0,0,0,0,0,0,0,0,0,0,0,0,0,0,0,0,0,0
0,0,0,0,0,0,0,0,0,0,0,0,0,0,0,0,0,0
0,0,0,0,0,0,0,0,0,0,0,0,0,0,0,0,0,0
0,0,0,0,0,0,0,0,0,0,0,0,0,0,0,0,0,0
0,0,0,0,0,0,0,0,0,0,0,0,0,0,0,0,0,0
0,0,0,0,0,0,0,0,0,0,0,0,0,0,0,0,0,0
0,0,0,0,0,0,0,0,0,0,0,0,0,0,0,0,0,0
0,0,0,0,0,0,0,0,0,0,0,0,0,0,0,0,0,0
0,0,0,0,0,0,0,0,0,0,0,0,0,0,0,0,0,0
0,0,0,0,0,0,0,0,0,0,0,0,0,0,0,0,0,0
0,0,0,0,0,0,0,0,0,0,0,0,0,0,0,0,0,0
0,0,0,0,0,0,0,0,0,0,0,0,0,0,0,0,0,0
0,0,0,0,0,0,0,0,0,0,0,0,0,0,0,0,0,0
0,0,0,0,0,0,0,0,0,0,0,0,0,0,0,0,0,0
0,0,0,0,0,0,0,0,0,0,0,0,0,0,0,0,0,0
0,0,0,0,0,0,0,0,0,0,0,0,0,0,0,0,0,0
0,0,0,0,0,0,0,0,0,0,0,0,0,0,0,0,0,0
0,0,0,0,0,0,0,0,0,0,0,0,0,0,0,0,0,0
0,0,0,0,0,0,0,0,0,0,0,0,0,0,0,0,0,0
0,0,0,0,0,0,0,0,0,0,0,0,0,0,0,0,0,0
0,0,0,0,0,0,0,0,0,0,0,0,0,0,0,0,0,0
0,0,0,0,0,0,0,0,0,0,0,0,0,0,0,0,0,0
0,0,0,0,0,0,0,0,0,0,0,0,0,0,0,0,0,0
0,0,0,0,0,0,0,0,0,0,0,0,0,0,0,0,0,0
0,0,0,0,0,0,0,0,0,0,0,0,0,0,0,0,0,0
0,0,0,0,0,0,0,0,0,0,0,0,0,0,0,0,0,0
0,0,0,0,0,0,0,0,0,0,0,0,0,0,0,0,0,0
0,0,0,0,0,0,0,0,0,0,0,0,0,0,0,0,0,0
:endlayer
layer: 34
0,0,0,0,0,0,0,0,0,0,0,0,0,0,0,0,0,0
0,0,0,0,0,0,0,0,0,0,0,0,0,0,0,0,0,0
0,0,0,0,0,0,0,0,0,0,0,0,0,0,0,0,0,0
0,0,0,0,0,0,0,0,0,0,0,0,0,0,0,0,0,0
0,0,0,0,0,0,0,0,0,0,0,0,0,0,0,0,0,0
0,0,0,0,0,0,0,0,0,0,0,0,0,0,0,0,0,0
0,0,0,0,0,0,0,0,0,0,0,0,0,0,0,0,0,0
0,0,0,0,0,0,0,0,0,0,0,0,0,0,0,0,0,0
0,0,0,0,0,0,0,0,0,0,0,0,0,0,0,0,0,0
0,0,0,0,0,0,0,0,0,0,0,0,0,0,0,0,0,0
0,0,0,0,0,0,0,0,0,0,0,0,0,0,0,0,0,0
0,0,0,0,0,0,0,0,0,0,0,0,0,0,0,0,0,0
0,0,0,0,0,0,0,0,0,0,0,0,0,0,0,0,0,0
0,0,0,0,0,0,0,0,0,0,0,0,0,0,0,0,0,0
0,0,0,0,0,0,0,0,0,0,0,0,0,0,0,0,0,0
0,0,0,0,0,0,0,0,0,0,0,0,0,0,0,0,0,0
0,0,0,0,0,0,0,0,0,0,0,0,0,0,0,0,0,0
0,0,0,0,0,0,0,0,0,0,0,0,0,0,0,0,0,0
0,0,0,0,0,0,0,0,0,0,0,0,0,0,0,0,0,0
0,0,0,0,0,0,0,0,0,0,0,0,0,0,0,0,0,0
0,0,0,0,0,0,0,0,0,0,0,0,0,0,0,0,0,0
0,0,0,0,0,0,0,0,0,0,0,0,0,0,0,0,0,0
0,0,0,0,0,0,0,0,0,0,0,0,0,0,0,0,0,0
0,0,0,0,0,0,0,0,0,0,0,0,0,0,0,0,0,0
0,0,0,0,0,0,0,0,0,0,0,0,0,0,0,0,0,0
0,0,0,0,0,0,0,0,0,0,0,0,0,0,0,0,0,0
0,0,0,0,0,0,0,0,0,0,0,0,0,0,0,0,0,0
0,0,0,0,0,0,0,0,0,0,0,0,0,0,0,0,0,0
0,0,0,0,0,0,0,0,0,0,0,0,0,0,0,0,0,0
0,0,0,0,0,0,0,0,0,0,0,0,0,0,0,0,0,0
0,0,0,0,0,0,0,0,0,0,0,0,0,0,0,0,0,0
0,0,0,0,0,0,0,0,0,0,0,0,0,0,0,0,0,0
0,0,0,0,0,0,0,0,0,0,0,0,0,0,0,0,0,0
0,0,0,0,0,0,0,0,0,0,0,0,0,0,0,0,0,0
0,0,0,0,0,0,0,0,0,0,0,0,0,0,0,0,0,0
0,0,0,0,0,0,0,0,0,0,0,0,0,0,0,0,0,0
0,0,0,0,0,0,0,0,0,0,0,0,0,0,0,0,0,0
0,0,0,0,0,0,0,0,0,0,0,0,0,0,0,0,0,0
0,0,0,0,0,0,0,0,0,0,0,0,0,0,0,0,0,0
0,0,0,0,0,0,0,0,0,0,0,0,0,0,0,0,0,0
0,0,0,0,0,0,0,0,0,0,0,0,0,0,0,0,0,0
0,0,0,0,0,0,0,0,0,0,0,0,0,0,0,0,0,0
0,0,0,0,0,0,0,0,0,0,0,0,0,0,0,0,0,0
0,0,0,0,0,0,0,0,0,0,0,0,0,0,0,0,0,0
0,0,0,0,0,0,0,0,0,0,0,0,0,0,0,0,0,0
0,0,0,0,0,0,0,0,0,0,0,0,0,0,0,0,0,0
0,0,0,0,0,0,0,0,0,0,0,0,0,0,0,0,0,0
0,0,0,0,0,0,0,0,0,0,0,0,0,0,0,0,0,0
0,0,0,0,0,0,0,0,0,0,0,0,0,0,0,0,0,0
0,0,0,0,0,0,0,0,0,0,0,0,0,0,0,0,0,0
0,0,0,0,0,0,0,0,0,0,0,0,0,0,0,0,0,0
0,0,0,0,0,0,0,0,0,0,0,0,0,0,0,0,0,0
0,0,0,0,0,0,0,0,0,0,0,0,0,0,0,0,0,0
0,0,0,0,0,0,0,0,0,0,0,0,0,0,0,0,0,0
0,0,0,0,0,0,0,0,0,0,0,0,0,0,0,0,0,0
0,0,0,0,0,0,0,0,0,0,0,0,0,0,0,0,0,0
0,0,0,0,0,0,0,0,0,0,0,0,0,0,0,0,0,0
0,0,0,0,0,0,0,0,0,0,0,0,0,0,0,0,0,0
0,0,0,0,0,0,0,0,0,0,0,0,0,0,0,0,0,0
0,0,0,0,0,0,0,0,0,0,0,0,0,0,0,0,0,0
0,0,0,0,0,0,0,0,0,0,0,0,0,0,0,0,0,0
0,0,0,0,0,0,0,0,0,0,0,0,0,0,0,0,0,0
0,0,0,0,0,0,0,0,0,0,0,0,0,0,0,0,0,0
:endlayer
layer: 35
0,0,0,0,0,0,0,0,0,0,0,0,0,0,0,0,0,0
0,0,0,0,0,0,0,0,0,0,0,0,0,0,0,0,0,0
0,0,0,0,0,0,0,0,0,0,0,0,0,0,0,0,0,0
0,0,0,0,0,0,0,0,0,0,0,0,0,0,0,0,0,0
0,0,0,0,0,0,0,0,0,0,0,0,0,0,0,0,0,0
0,0,0,0,0,0,0,0,0,0,0,0,0,0,0,0,0,0
0,0,0,0,0,0,0,0,0,0,0,0,0,0,0,0,0,0
0,0,0,0,0,0,0,0,0,0,0,0,0,0,0,0,0,0
0,0,0,0,0,0,0,0,0,0,0,0,0,0,0,0,0,0
0,0,0,0,0,0,0,0,0,0,0,0,0,0,0,0,0,0
0,0,0,0,0,0,0,0,0,0,0,0,0,0,0,0,0,0
0,0,0,0,0,0,0,0,0,0,0,0,0,0,0,0,0,0
0,0,0,0,0,0,0,0,0,0,0,0,0,0,0,0,0,0
0,0,0,0,0,0,0,0,0,0,0,0,0,0,0,0,0,0
0,0,0,0,0,0,0,0,0,0,0,0,0,0,0,0,0,0
0,0,0,0,0,0,0,0,0,0,0,0,0,0,0,0,0,0
0,0,0,0,0,0,0,0,0,0,0,0,0,0,0,0,0,0
0,0,0,0,0,0,0,0,0,0,0,0,0,0,0,0,0,0
0,0,0,0,0,0,0,0,0,0,0,0,0,0,0,0,0,0
0,0,0,0,0,0,0,0,0,0,0,0,0,0,0,0,0,0
0,0,0,0,0,0,0,0,0,0,0,0,0,0,0,0,0,0
0,0,0,0,0,0,0,0,0,0,0,0,0,0,0,0,0,0
0,0,0,0,0,0,0,0,0,0,0,0,0,0,0,0,0,0
0,0,0,0,0,0,0,0,0,0,0,0,0,0,0,0,0,0
0,0,0,0,0,0,0,0,0,0,0,0,0,0,0,0,0,0
0,0,0,0,0,0,0,0,0,0,0,0,0,0,0,0,0,0
0,0,0,0,0,0,0,0,0,0,0,0,0,0,0,0,0,0
0,0,0,0,0,0,0,0,0,0,0,0,0,0,0,0,0,0
0,0,0,0,0,0,0,0,0,0,0,0,0,0,0,0,0,0
0,0,0,0,0,0,0,0,0,0,0,0,0,0,0,0,0,0
0,0,0,0,0,0,0,0,0,0,0,0,0,0,0,0,0,0
0,0,0,0,0,0,0,0,0,0,0,0,0,0,0,0,0,0
0,0,0,0,0,0,0,0,0,0,0,0,0,0,0,0,0,0
0,0,0,0,0,0,0,0,0,0,0,0,0,0,0,0,0,0
0,0,0,0,0,0,0,0,0,0,0,0,0,0,0,0,0,0
0,0,0,0,0,0,0,0,0,0,0,0,0,0,0,0,0,0
0,0,0,0,0,0,0,0,0,0,0,0,0,0,0,0,0,0
0,0,0,0,0,0,0,0,0,0,0,0,0,0,0,0,0,0
0,0,0,0,0,0,0,0,0,0,0,0,0,0,0,0,0,0
0,0,0,0,0,0,0,0,0,0,0,0,0,0,0,0,0,0
0,0,0,0,0,0,0,0,0,0,0,0,0,0,0,0,0,0
0,0,0,0,0,0,0,0,0,0,0,0,0,0,0,0,0,0
0,0,0,0,0,0,0,0,0,0,0,0,0,0,0,0,0,0
0,0,0,0,0,0,0,0,0,0,0,0,0,0,0,0,0,0
0,0,0,0,0,0,0,0,0,0,0,0,0,0,0,0,0,0
0,0,0,0,0,0,0,0,0,0,0,0,0,0,0,0,0,0
0,0,0,0,0,0,0,0,0,0,0,0,0,0,0,0,0,0
0,0,0,0,0,0,0,0,0,0,0,0,0,0,0,0,0,0
0,0,0,0,0,0,0,0,0,0,0,0,0,0,0,0,0,0
0,0,0,0,0,0,0,0,0,0,0,0,0,0,0,0,0,0
0,0,0,0,0,0,0,0,0,0,0,0,0,0,0,0,0,0
0,0,0,0,0,0,0,0,0,0,0,0,0,0,0,0,0,0
0,0,0,0,0,0,0,0,0,0,0,0,0,0,0,0,0,0
0,0,0,0,0,0,0,0,0,0,0,0,0,0,0,0,0,0
0,0,0,0,0,0,0,0,0,0,0,0,0,0,0,0,0,0
0,0,0,0,0,0,0,0,0,0,0,0,0,0,0,0,0,0
0,0,0,0,0,0,0,0,0,0,0,0,0,0,0,0,0,0
0,0,0,0,0,0,0,0,0,0,0,0,0,0,0,0,0,0
0,0,0,0,0,0,0,0,0,0,0,0,0,0,0,0,0,0
0,0,0,0,0,0,0,0,0,0,0,0,0,0,0,0,0,0
0,0,0,0,0,0,0,0,0,0,0,0,0,0,0,0,0,0
0,0,0,0,0,0,0,0,0,0,0,0,0,0,0,0,0,0
0,0,0,0,0,0,0,0,0,0,0,0,0,0,0,0,0,0
:endlayer
layer: 36
0,0,0,0,0,0,0,0,0,0,0,0,0,0,0,0,0,0
0,0,0,0,0,0,0,0,0,0,0,0,0,0,0,0,0,0
0,0,0,0,0,0,0,0,0,0,0,0,0,0,0,0,0,0
0,0,0,0,0,0,0,0,0,0,0,0,0,0,0,0,0,0
0,0,0,0,0,0,0,0,0,0,0,0,0,0,0,0,0,0
0,0,0,0,0,0,0,0,0,0,0,0,0,0,0,0,0,0
0,0,0,0,0,0,0,0,0,0,0,0,0,0,0,0,0,0
0,0,0,0,0,0,0,0,0,0,0,0,0,0,0,0,0,0
0,0,0,0,0,0,0,0,0,0,0,0,0,0,0,0,0,0
0,0,0,0,0,0,0,0,0,0,0,0,0,0,0,0,0,0
0,0,0,0,0,0,0,0,0,0,0,0,0,0,0,0,0,0
0,0,0,0,0,0,0,0,0,0,0,0,0,0,0,0,0,0
0,0,0,0,0,0,0,0,0,0,0,0,0,0,0,0,0,0
0,0,0,0,0,0,0,0,0,0,0,0,0,0,0,0,0,0
0,0,0,0,0,0,0,0,0,0,0,0,0,0,0,0,0,0
0,0,0,0,0,0,0,0,0,0,0,0,0,0,0,0,0,0
0,0,0,0,0,0,0,0,0,0,0,0,0,0,0,0,0,0
0,0,0,0,0,0,0,0,0,0,0,0,0,0,0,0,0,0
0,0,0,0,0,0,0,0,0,0,0,0,0,0,0,0,0,0
0,0,0,0,0,0,0,0,0,0,0,0,0,0,0,0,0,0
0,0,0,0,0,0,0,0,0,0,0,0,0,0,0,0,0,0
0,0,0,0,0,0,0,0,0,0,0,0,0,0,0,0,0,0
0,0,0,0,0,0,0,0,0,0,0,0,0,0,0,0,0,0
0,0,0,0,0,0,0,0,0,0,0,0,0,0,0,0,0,0
0,0,0,0,0,0,0,0,0,0,0,0,0,0,0,0,0,0
0,0,0,0,0,0,0,0,0,0,0,0,0,0,0,0,0,0
0,0,0,0,0,0,0,0,0,0,0,0,0,0,0,0,0,0
0,0,0,0,0,0,0,0,0,0,0,0,0,0,0,0,0,0
0,0,0,0,0,0,0,0,0,0,0,0,0,0,0,0,0,0
0,0,0,0,0,0,0,0,0,0,0,0,0,0,0,0,0,0
0,0,0,0,0,0,0,0,0,0,0,0,0,0,0,0,0,0
0,0,0,0,0,0,0,0,0,0,0,0,0,0,0,0,0,0
0,0,0,0,0,0,0,0,0,0,0,0,0,0,0,0,0,0
0,0,0,0,0,0,0,0,0,0,0,0,0,0,0,0,0,0
0,0,0,0,0,0,0,0,0,0,0,0,0,0,0,0,0,0
0,0,0,0,0,0,0,0,0,0,0,0,0,0,0,0,0,0
0,0,0,0,0,0,0,0,0,0,0,0,0,0,0,0,0,0
0,0,0,0,0,0,0,0,0,0,0,0,0,0,0,0,0,0
0,0,0,0,0,0,0,0,0,0,0,0,0,0,0,0,0,0
0,0,0,0,0,0,0,0,0,0,0,0,0,0,0,0,0,0
0,0,0,0,0,0,0,0,0,0,0,0,0,0,0,0,0,0
0,0,0,0,0,0,0,0,0,0,0,0,0,0,0,0,0,0
0,0,0,0,0,0,0,0,0,0,0,0,0,0,0,0,0,0
0,0,0,0,0,0,0,0,0,0,0,0,0,0,0,0,0,0
0,0,0,0,0,0,0,0,0,0,0,0,0,0,0,0,0,0
0,0,0,0,0,0,0,0,0,0,0,0,0,0,0,0,0,0
0,0,0,0,0,0,0,0,0,0,0,0,0,0,0,0,0,0
0,0,0,0,0,0,0,0,0,0,0,0,0,0,0,0,0,0
0,0,0,0,0,0,0,0,0,0,0,0,0,0,0,0,0,0
0,0,0,0,0,0,0,0,0,0,0,0,0,0,0,0,0,0
0,0,0,0,0,0,0,0,0,0,0,0,0,0,0,0,0,0
0,0,0,0,0,0,0,0,0,0,0,0,0,0,0,0,0,0
0,0,0,0,0,0,0,0,0,0,0,0,0,0,0,0,0,0
0,0,0,0,0,0,0,0,0,0,0,0,0,0,0,0,0,0
0,0,0,0,0,0,0,0,0,0,0,0,0,0,0,0,0,0
0,0,0,0,0,0,0,0,0,0,0,0,0,0,0,0,0,0
0,0,0,0,0,0,0,0,0,0,0,0,0,0,0,0,0,0
0,0,0,0,0,0,0,0,0,0,0,0,0,0,0,0,0,0
0,0,0,0,0,0,0,0,0,0,0,0,0,0,0,0,0,0
0,0,0,0,0,0,0,0,0,0,0,0,0,0,0,0,0,0
0,0,0,0,0,0,0,0,0,0,0,0,0,0,0,0,0,0
0,0,0,0,0,0,0,0,0,0,0,0,0,0,0,0,0,0
0,0,0,0,0,0,0,0,0,0,0,0,0,0,0,0,0,0
:endlayer
layer: 37
0,0,0,0,0,0,0,0,0,0,0,0,0,0,0,0,0,0
0,0,0,0,0,0,0,0,0,0,0,0,0,0,0,0,0,0
0,0,0,0,0,0,0,0,0,0,0,0,0,0,0,0,0,0
0,0,0,0,0,0,0,0,0,0,0,0,0,0,0,0,0,0
0,0,0,0,0,0,0,0,0,0,0,0,0,0,0,0,0,0
0,0,0,0,0,0,0,0,0,0,0,0,0,0,0,0,0,0
0,0,0,0,0,0,0,0,0,0,0,0,0,0,0,0,0,0
0,0,0,0,0,0,0,0,0,0,0,0,0,0,0,0,0,0
0,0,0,0,0,0,0,0,0,0,0,0,0,0,0,0,0,0
0,0,0,0,0,0,0,0,0,0,0,0,0,0,0,0,0,0
0,0,0,0,0,0,0,0,0,0,0,0,0,0,0,0,0,0
0,0,0,0,0,0,0,0,0,0,0,0,0,0,0,0,0,0
0,0,0,0,0,0,0,0,0,0,0,0,0,0,0,0,0,0
0,0,0,0,0,0,0,0,0,0,0,0,0,0,0,0,0,0
0,0,0,0,0,0,0,0,0,0,0,0,0,0,0,0,0,0
0,0,0,0,0,0,0,0,0,0,0,0,0,0,0,0,0,0
0,0,0,0,0,0,0,0,0,0,0,0,0,0,0,0,0,0
0,0,0,0,0,0,0,0,0,0,0,0,0,0,0,0,0,0
0,0,0,0,0,0,0,0,0,0,0,0,0,0,0,0,0,0
0,0,0,0,0,0,0,0,0,0,0,0,0,0,0,0,0,0
0,0,0,0,0,0,0,0,0,0,0,0,0,0,0,0,0,0
0,0,0,0,0,0,0,0,0,0,0,0,0,0,0,0,0,0
0,0,0,0,0,0,0,0,0,0,0,0,0,0,0,0,0,0
0,0,0,0,0,0,0,0,0,0,0,0,0,0,0,0,0,0
0,0,0,0,0,0,0,0,0,0,0,0,0,0,0,0,0,0
0,0,0,0,0,0,0,0,0,0,0,0,0,0,0,0,0,0
0,0,0,0,0,0,0,0,0,0,0,0,0,0,0,0,0,0
0,0,0,0,0,0,0,0,0,0,0,0,0,0,0,0,0,0
0,0,0,0,0,0,0,0,0,0,0,0,0,0,0,0,0,0
0,0,0,0,0,0,0,0,0,0,0,0,0,0,0,0,0,0
0,0,0,0,0,0,0,0,0,0,0,0,0,0,0,0,0,0
0,0,0,0,0,0,0,0,0,0,0,0,0,0,0,0,0,0
0,0,0,0,0,0,0,0,0,0,0,0,0,0,0,0,0,0
0,0,0,0,0,0,0,0,0,0,0,0,0,0,0,0,0,0
0,0,0,0,0,0,0,0,0,0,0,0,0,0,0,0,0,0
0,0,0,0,0,0,0,0,0,0,0,0,0,0,0,0,0,0
0,0,0,0,0,0,0,0,0,0,0,0,0,0,0,0,0,0
0,0,0,0,0,0,0,0,0,0,0,0,0,0,0,0,0,0
0,0,0,0,0,0,0,0,0,0,0,0,0,0,0,0,0,0
0,0,0,0,0,0,0,0,0,0,0,0,0,0,0,0,0,0
0,0,0,0,0,0,0,0,0,0,0,0,0,0,0,0,0,0
0,0,0,0,0,0,0,0,0,0,0,0,0,0,0,0,0,0
0,0,0,0,0,0,0,0,0,0,0,0,0,0,0,0,0,0
0,0,0,0,0,0,0,0,0,0,0,0,0,0,0,0,0,0
0,0,0,0,0,0,0,0,0,0,0,0,0,0,0,0,0,0
0,0,0,0,0,0,0,0,0,0,0,0,0,0,0,0,0,0
0,0,0,0,0,0,0,0,0,0,0,0,0,0,0,0,0,0
0,0,0,0,0,0,0,0,0,0,0,0,0,0,0,0,0,0
0,0,0,0,0,0,0,0,0,0,0,0,0,0,0,0,0,0
0,0,0,0,0,0,0,0,0,0,0,0,0,0,0,0,0,0
0,0,0,0,0,0,0,0,0,0,0,0,0,0,0,0,0,0
0,0,0,0,0,0,0,0,0,0,0,0,0,0,0,0,0,0
0,0,0,0,0,0,0,0,0,0,0,0,0,0,0,0,0,0
0,0,0,0,0,0,0,0,0,0,0,0,0,0,0,0,0,0
0,0,0,0,0,0,0,0,0,0,0,0,0,0,0,0,0,0
0,0,0,0,0,0,0,0,0,0,0,0,0,0,0,0,0,0
0,0,0,0,0,0,0,0,0,0,0,0,0,0,0,0,0,0
0,0,0,0,0,0,0,0,0,0,0,0,0,0,0,0,0,0
0,0,0,0,0,0,0,0,0,0,0,0,0,0,0,0,0,0
0,0,0,0,0,0,0,0,0,0,0,0,0,0,0,0,0,0
0,0,0,0,0,0,0,0,0,0,0,0,0,0,0,0,0,0
0,0,0,0,0,0,0,0,0,0,0,0,0,0,0,0,0,0
0,0,0,0,0,0,0,0,0,0,0,0,0,0,0,0,0,0
:endlayer
layer: 38
0,0,0,0,0,0,0,0,0,0,0,0,0,0,0,0,0,0
0,0,0,0,0,0,0,0,0,0,0,0,0,0,0,0,0,0
0,0,0,0,0,0,0,0,0,0,0,0,0,0,0,0,0,0
0,0,0,0,0,0,0,0,0,0,0,0,0,0,0,0,0,0
0,0,0,0,0,0,0,0,0,0,0,0,0,0,0,0,0,0
0,0,0,0,0,0,0,0,0,0,0,0,0,0,0,0,0,0
0,0,0,0,0,0,0,0,0,0,0,0,0,0,0,0,0,0
0,0,0,0,0,0,0,0,0,0,0,0,0,0,0,0,0,0
0,0,0,0,0,0,0,0,0,0,0,0,0,0,0,0,0,0
0,0,0,0,0,0,0,0,0,0,0,0,0,0,0,0,0,0
0,0,0,0,0,0,0,0,0,0,0,0,0,0,0,0,0,0
0,0,0,0,0,0,0,0,0,0,0,0,0,0,0,0,0,0
0,0,0,0,0,0,0,0,0,0,0,0,0,0,0,0,0,0
0,0,0,0,0,0,0,0,0,0,0,0,0,0,0,0,0,0
0,0,0,0,0,0,0,0,0,0,0,0,0,0,0,0,0,0
0,0,0,0,0,0,0,0,0,0,0,0,0,0,0,0,0,0
0,0,0,0,0,0,0,0,0,0,0,0,0,0,0,0,0,0
0,0,0,0,0,0,0,0,0,0,0,0,0,0,0,0,0,0
0,0,0,0,0,0,0,0,0,0,0,0,0,0,0,0,0,0
0,0,0,0,0,0,0,0,0,0,0,0,0,0,0,0,0,0
0,0,0,0,0,0,0,0,0,0,0,0,0,0,0,0,0,0
0,0,0,0,0,0,0,0,0,0,0,0,0,0,0,0,0,0
0,0,0,0,0,0,0,0,0,0,0,0,0,0,0,0,0,0
0,0,0,0,0,0,0,0,0,0,0,0,0,0,0,0,0,0
0,0,0,0,0,0,0,0,0,0,0,0,0,0,0,0,0,0
0,0,0,0,0,0,0,0,0,0,0,0,0,0,0,0,0,0
0,0,0,0,0,0,0,0,0,0,0,0,0,0,0,0,0,0
0,0,0,0,0,0,0,0,0,0,0,0,0,0,0,0,0,0
0,0,0,0,0,0,0,0,0,0,0,0,0,0,0,0,0,0
0,0,0,0,0,0,0,0,0,0,0,0,0,0,0,0,0,0
0,0,0,0,0,0,0,0,0,0,0,0,0,0,0,0,0,0
0,0,0,0,0,0,0,0,0,0,0,0,0,0,0,0,0,0
0,0,0,0,0,0,0,0,0,0,0,0,0,0,0,0,0,0
0,0,0,0,0,0,0,0,0,0,0,0,0,0,0,0,0,0
0,0,0,0,0,0,0,0,0,0,0,0,0,0,0,0,0,0
0,0,0,0,0,0,0,0,0,0,0,0,0,0,0,0,0,0
0,0,0,0,0,0,0,0,0,0,0,0,0,0,0,0,0,0
0,0,0,0,0,0,0,0,0,0,0,0,0,0,0,0,0,0
0,0,0,0,0,0,0,0,0,0,0,0,0,0,0,0,0,0
0,0,0,0,0,0,0,0,0,0,0,0,0,0,0,0,0,0
0,0,0,0,0,0,0,0,0,0,0,0,0,0,0,0,0,0
0,0,0,0,0,0,0,0,0,0,0,0,0,0,0,0,0,0
0,0,0,0,0,0,0,0,0,0,0,0,0,0,0,0,0,0
0,0,0,0,0,0,0,0,0,0,0,0,0,0,0,0,0,0
0,0,0,0,0,0,0,0,0,0,0,0,0,0,0,0,0,0
0,0,0,0,0,0,0,0,0,0,0,0,0,0,0,0,0,0
0,0,0,0,0,0,0,0,0,0,0,0,0,0,0,0,0,0
0,0,0,0,0,0,0,0,0,0,0,0,0,0,0,0,0,0
0,0,0,0,0,0,0,0,0,0,0,0,0,0,0,0,0,0
0,0,0,0,0,0,0,0,0,0,0,0,0,0,0,0,0,0
0,0,0,0,0,0,0,0,0,0,0,0,0,0,0,0,0,0
0,0,0,0,0,0,0,0,0,0,0,0,0,0,0,0,0,0
0,0,0,0,0,0,0,0,0,0,0,0,0,0,0,0,0,0
0,0,0,0,0,0,0,0,0,0,0,0,0,0,0,0,0,0
0,0,0,0,0,0,0,0,0,0,0,0,0,0,0,0,0,0
0,0,0,0,0,0,0,0,0,0,0,0,0,0,0,0,0,0
0,0,0,0,0,0,0,0,0,0,0,0,0,0,0,0,0,0
0,0,0,0,0,0,0,0,0,0,0,0,0,0,0,0,0,0
0,0,0,0,0,0,0,0,0,0,0,0,0,0,0,0,0,0
0,0,0,0,0,0,0,0,0,0,0,0,0,0,0,0,0,0
0,0,0,0,0,0,0,0,0,0,0,0,0,0,0,0,0,0
0,0,0,0,0,0,0,0,0,0,0,0,0,0,0,0,0,0
0,0,0,0,0,0,0,0,0,0,0,0,0,0,0,0,0,0
:endlayer
layer: 39
0,0,0,0,0,0,0,0,0,0,0,0,0,0,0,0,0,0
0,0,0,0,0,0,0,0,0,0,0,0,0,0,0,0,0,0
0,0,0,0,0,0,0,0,0,0,0,0,0,0,0,0,0,0
0,0,0,0,0,0,0,0,0,0,0,0,0,0,0,0,0,0
0,0,0,0,0,0,0,0,0,0,0,0,0,0,0,0,0,0
0,0,0,0,0,0,0,0,0,0,0,0,0,0,0,0,0,0
0,0,0,0,0,0,0,0,0,0,0,0,0,0,0,0,0,0
0,0,0,0,0,0,0,0,0,0,0,0,0,0,0,0,0,0
0,0,0,0,0,0,0,0,0,0,0,0,0,0,0,0,0,0
0,0,0,0,0,0,0,0,0,0,0,0,0,0,0,0,0,0
0,0,0,0,0,0,0,0,0,0,0,0,0,0,0,0,0,0
0,0,0,0,0,0,0,0,0,0,0,0,0,0,0,0,0,0
0,0,0,0,0,0,0,0,0,0,0,0,0,0,0,0,0,0
0,0,0,0,0,0,0,0,0,0,0,0,0,0,0,0,0,0
0,0,0,0,0,0,0,0,0,0,0,0,0,0,0,0,0,0
0,0,0,0,0,0,0,0,0,0,0,0,0,0,0,0,0,0
0,0,0,0,0,0,0,0,0,0,0,0,0,0,0,0,0,0
0,0,0,0,0,0,0,0,0,0,0,0,0,0,0,0,0,0
0,0,0,0,0,0,0,0,0,0,0,0,0,0,0,0,0,0
0,0,0,0,0,0,0,0,0,0,0,0,0,0,0,0,0,0
0,0,0,0,0,0,0,0,0,0,0,0,0,0,0,0,0,0
0,0,0,0,0,0,0,0,0,0,0,0,0,0,0,0,0,0
0,0,0,0,0,0,0,0,0,0,0,0,0,0,0,0,0,0
0,0,0,0,0,0,0,0,0,0,0,0,0,0,0,0,0,0
0,0,0,0,0,0,0,0,0,0,0,0,0,0,0,0,0,0
0,0,0,0,0,0,0,0,0,0,0,0,0,0,0,0,0,0
0,0,0,0,0,0,0,0,0,0,0,0,0,0,0,0,0,0
0,0,0,0,0,0,0,0,0,0,0,0,0,0,0,0,0,0
0,0,0,0,0,0,0,0,0,0,0,0,0,0,0,0,0,0
0,0,0,0,0,0,0,0,0,0,0,0,0,0,0,0,0,0
0,0,0,0,0,0,0,0,0,0,0,0,0,0,0,0,0,0
0,0,0,0,0,0,0,0,0,0,0,0,0,0,0,0,0,0
0,0,0,0,0,0,0,0,0,0,0,0,0,0,0,0,0,0
0,0,0,0,0,0,0,0,0,0,0,0,0,0,0,0,0,0
0,0,0,0,0,0,0,0,0,0,0,0,0,0,0,0,0,0
0,0,0,0,0,0,0,0,0,0,0,0,0,0,0,0,0,0
0,0,0,0,0,0,0,0,0,0,0,0,0,0,0,0,0,0
0,0,0,0,0,0,0,0,0,0,0,0,0,0,0,0,0,0
0,0,0,0,0,0,0,0,0,0,0,0,0,0,0,0,0,0
0,0,0,0,0,0,0,0,0,0,0,0,0,0,0,0,0,0
0,0,0,0,0,0,0,0,0,0,0,0,0,0,0,0,0,0
0,0,0,0,0,0,0,0,0,0,0,0,0,0,0,0,0,0
0,0,0,0,0,0,0,0,0,0,0,0,0,0,0,0,0,0
0,0,0,0,0,0,0,0,0,0,0,0,0,0,0,0,0,0
0,0,0,0,0,0,0,0,0,0,0,0,0,0,0,0,0,0
0,0,0,0,0,0,0,0,0,0,0,0,0,0,0,0,0,0
0,0,0,0,0,0,0,0,0,0,0,0,0,0,0,0,0,0
