# Ancient Warfare Structure Template File
# Auto-generated structure template file. created on: 3/2/2017 at: 13:10:59
# Lines beginning with # denote comments

header:
version=2.1
name=ReignImperialMerchant
size=17,35,25
offset=8,4,18
:endheader

#### VALIDATION ####
validation:
type=ground
survival=true
worldGenEnabled=true
unique=false
preserveBlocks=false
selectionWeight=90
clusterValue=80
minDuplicateDistance=100
dimensionWhiteList=false
dimensionList=
biomeWhiteList=true
biomeList=highlands_lowlands,origin valley,highlands_valley,orchard,meadow,lavender fields,flower field,meadow forest,highlands_meadow,green hills
leveling=4
fill=4
border=4
validTargetBlocks=minecraft:dirt,minecraft:sand,minecraft:stone,minecraft:diamond_ore,minecraft:gravel,minecraft:lapis_ore,minecraft:redstone_ore,minecraft:stained_hardened_clay,minecraft:gold_ore,minecraft:clay,minecraft:coal_ore,minecraft:iron_ore,minecraft:grass
blockSwap=false
data:
:enddata
:endvalidation

#### LAYERS ####
layer: 0
1,1,1,1,1,1,1,1,1,1,1,1,1,1,1,1,1
1,1,1,1,1,1,1,1,1,1,1,1,2,2,1,1,1
1,1,1,1,1,1,1,1,1,1,1,1,1,1,1,1,1
1,1,1,1,1,1,1,1,1,1,1,1,1,1,1,1,1
1,1,1,1,1,1,1,1,1,1,1,1,1,1,1,1,1
1,1,1,1,1,1,1,1,1,1,1,1,1,1,1,1,1
1,1,1,1,1,1,1,1,1,1,1,1,1,1,1,1,1
1,1,1,1,1,1,1,1,1,1,1,1,1,1,1,1,1
1,1,1,1,1,1,1,1,1,1,1,1,1,1,1,1,1
1,1,1,1,1,1,1,1,1,1,1,1,1,1,1,1,1
1,1,1,1,1,1,1,1,1,1,2,2,1,1,1,1,1
1,1,1,3,1,3,3,1,1,1,2,2,1,1,1,1,1
1,1,3,3,3,3,3,3,3,1,1,1,1,1,1,1,1
1,1,1,1,3,3,3,3,3,3,1,1,1,1,1,1,1
1,1,1,1,3,3,3,3,3,3,3,1,1,1,1,1,1
1,1,1,1,1,3,3,3,3,3,3,3,1,1,1,1,1
1,1,1,1,1,1,1,3,3,3,3,1,1,1,1,1,1
4,4,4,4,4,4,4,4,4,4,1,1,1,1,1,1,1
4,4,4,4,4,4,4,4,4,4,4,4,4,4,4,4,4
4,4,4,4,4,4,4,4,4,4,4,4,4,4,4,4,4
4,4,4,4,4,4,4,4,4,4,4,4,4,4,4,4,4
4,4,4,4,4,4,4,4,4,4,4,4,4,4,4,4,4
4,4,4,4,4,4,4,4,4,4,4,4,4,4,4,4,4
4,4,4,4,4,4,4,4,4,4,4,4,4,4,4,4,4
4,4,4,4,4,4,4,4,4,4,4,4,4,4,4,4,4
:endlayer
layer: 1
5,5,5,5,5,1,1,1,1,1,1,1,1,1,1,1,1
5,5,1,1,1,1,1,1,1,1,1,1,1,1,1,1,1
1,1,1,1,1,1,1,1,1,1,1,1,1,1,1,1,1
1,1,1,1,1,1,1,1,1,1,1,1,1,1,1,1,1
1,1,1,1,1,1,1,1,1,1,1,1,1,1,1,1,1
1,1,1,1,1,1,1,1,1,1,1,1,1,1,1,1,1
1,1,1,1,1,1,1,1,1,1,1,1,1,1,1,1,1
1,1,1,1,1,1,1,1,1,1,1,1,1,1,1,1,1
1,1,1,1,1,1,1,1,1,1,1,1,1,1,1,1,1
4,4,4,4,4,4,4,4,1,1,1,1,1,1,1,1,1
4,4,4,4,4,4,4,4,4,4,4,2,4,4,4,4,4
4,4,4,4,4,4,4,4,4,4,4,4,4,4,4,4,4
4,4,4,4,4,4,4,4,4,4,4,4,4,4,4,4,4
4,4,4,4,4,4,4,4,4,4,4,4,4,4,4,4,4
4,4,4,4,4,4,4,4,4,4,4,4,4,4,4,4,4
4,4,4,4,4,4,4,4,4,4,4,4,4,4,4,4,4
4,4,4,4,4,4,4,4,4,4,4,4,4,4,4,4,4
4,4,4,4,4,4,4,4,4,4,4,4,4,4,4,4,4
4,4,4,4,4,4,4,4,4,4,4,4,4,4,4,4,4
4,4,4,4,4,4,4,4,4,4,4,4,4,4,4,4,4
4,4,4,4,4,4,4,4,4,4,4,4,4,4,4,4,4
4,4,4,4,4,4,4,4,4,4,4,4,4,4,4,4,4
4,4,4,4,4,4,4,4,4,4,4,4,4,4,4,4,4
4,4,4,4,4,4,4,4,4,4,4,4,4,4,4,4,4
4,4,4,4,4,4,4,4,4,4,4,4,4,4,4,4,4
:endlayer
layer: 2
4,4,4,4,4,4,4,4,4,4,4,4,4,4,4,4,4
4,4,4,4,4,4,4,4,4,4,4,4,4,4,4,4,4
4,4,4,4,4,4,4,4,4,4,4,4,4,4,4,4,4
4,4,4,4,4,4,4,4,4,4,4,4,4,4,4,4,4
4,4,4,4,6,4,4,4,4,4,4,4,4,4,4,4,4
4,4,4,4,4,4,4,4,4,4,4,4,4,4,4,4,4
4,4,4,4,4,4,7,7,7,7,7,4,4,4,4,4,4
4,4,4,4,4,4,7,7,7,7,7,8,4,4,4,4,4
4,4,4,4,4,4,7,7,7,7,7,4,4,4,4,4,4
4,4,4,4,4,4,7,7,7,7,7,4,4,4,4,4,4
4,4,4,4,4,4,7,7,7,7,7,4,4,4,4,4,4
4,4,4,4,4,4,7,7,7,7,7,4,4,4,4,4,4
4,4,4,4,4,4,7,7,7,7,7,4,4,4,4,4,4
4,4,4,4,4,4,4,4,4,4,4,4,4,4,4,4,4
4,4,4,4,4,4,4,4,4,4,4,4,4,4,4,4,4
4,4,4,4,4,4,4,4,4,4,4,4,4,4,4,4,4
4,4,4,4,4,4,4,4,4,4,4,4,4,4,4,4,4
4,4,4,4,4,4,4,4,4,4,4,4,4,4,4,4,4
4,4,4,4,4,4,4,4,4,4,4,4,4,4,4,4,4
4,4,4,4,4,4,4,4,4,4,4,4,4,4,4,4,4
4,4,4,4,4,4,4,4,4,4,4,4,4,4,4,4,4
4,4,4,4,4,4,4,4,4,4,4,4,4,4,4,4,4
4,4,4,4,4,4,4,4,4,4,4,4,4,4,4,4,4
4,4,4,4,4,4,4,4,4,4,4,4,4,4,4,4,4
4,4,4,4,4,4,4,4,4,4,4,4,4,4,4,4,4
:endlayer
layer: 3
9,9,9,9,9,9,9,9,3,9,9,9,9,9,9,9,9
9,9,9,9,9,9,9,9,3,9,9,9,9,9,9,9,9
9,9,9,9,9,3,3,3,3,3,3,3,3,3,9,9,9
9,9,9,9,9,9,3,3,3,3,3,3,3,3,3,9,9
9,9,9,9,9,8,9,8,3,8,3,8,3,3,3,9,9
9,9,9,9,8,8,8,8,3,8,8,8,8,3,3,9,9
9,9,9,9,9,8,0,0,10,0,11,8,3,3,9,9,9
9,9,9,3,8,8,0,0,0,0,12,8,8,3,9,9,9
9,9,9,3,3,8,13,0,0,0,14,8,3,9,9,9,9
9,9,9,9,8,8,15,0,0,0,16,8,8,9,9,9,9
9,9,9,9,3,8,15,0,0,0,17,8,3,9,9,9,9
9,9,9,9,8,8,18,0,0,0,19,8,8,9,9,9,9
9,9,9,9,3,8,20,0,0,0,21,8,9,9,9,9,9
9,9,9,9,8,8,8,8,8,8,8,8,9,9,9,9,9
9,9,9,3,3,8,3,8,3,8,3,9,9,9,9,9,9
9,9,9,9,3,3,3,3,3,3,3,9,9,9,9,9,9
9,9,9,9,3,3,3,3,3,3,3,3,9,9,9,9,9
9,9,9,9,3,3,3,3,3,3,3,9,9,9,9,9,9
9,9,9,9,9,9,9,9,3,9,9,9,9,9,9,9,9
9,9,9,9,9,9,9,9,3,9,9,9,9,9,9,9,9
9,9,9,9,9,9,9,9,9,9,9,9,9,9,9,9,9
9,9,9,9,9,9,9,9,9,9,9,9,9,9,9,9,9
9,9,9,9,9,9,9,9,9,9,9,9,9,9,9,9,9
9,9,9,9,9,9,9,9,9,9,9,9,9,9,9,9,9
9,9,9,9,9,9,9,9,9,9,9,9,9,9,9,9,9
:endlayer
layer: 4
0,0,0,0,0,0,22,22,0,0,0,22,23,22,0,0,0
0,24,24,24,24,24,24,24,25,24,24,24,24,24,24,24,0
0,24,0,0,23,0,0,0,0,0,0,0,0,0,0,24,22
22,24,22,0,22,22,0,0,0,0,0,0,0,0,0,24,22
22,24,0,23,0,26,0,26,0,26,0,26,0,0,0,24,22
22,24,22,22,27,8,8,8,28,8,8,8,29,0,0,24,0
0,24,22,0,0,8,0,0,0,0,0,8,0,0,0,24,0
22,24,22,0,27,8,0,0,0,0,0,8,29,0,22,24,0
22,24,0,0,0,8,0,0,0,0,0,8,0,0,22,24,22
0,24,22,0,27,8,13,0,0,0,30,8,29,0,22,24,22
22,24,22,22,0,8,15,0,0,0,0,8,0,0,22,24,0
22,24,22,22,27,8,31,0,0,0,30,8,29,22,22,24,0
22,24,22,22,0,8,31,0,0,0,0,8,0,22,22,24,22
22,24,22,22,27,8,8,32,8,32,8,8,29,22,0,24,22
0,24,0,0,0,10,0,10,0,10,0,10,22,22,22,24,0
0,24,0,0,0,0,0,0,24,0,0,22,22,22,22,24,22
0,24,0,0,0,0,0,0,0,0,0,0,22,22,22,24,0
22,24,22,0,0,0,0,0,0,0,0,22,0,22,0,24,0
22,24,24,24,24,24,24,24,33,24,24,24,24,24,24,24,0
0,22,0,22,0,0,0,0,0,0,0,0,22,0,0,0,0
0,0,0,0,34,22,0,0,0,35,22,0,22,22,0,34,0
34,34,34,0,0,22,0,22,0,35,0,22,0,22,22,22,0
34,22,0,0,0,0,22,0,0,22,22,22,22,22,35,0,0
0,22,0,34,34,22,0,22,22,22,34,22,22,0,36,0,0
0,22,0,0,22,22,22,22,22,22,0,0,0,22,0,22,22
:endlayer
layer: 5
0,0,0,0,0,0,0,0,0,0,0,0,0,0,0,0,0
0,37,0,0,0,0,0,37,0,37,0,0,0,0,0,37,0
0,0,0,0,0,0,0,0,0,0,0,0,0,0,0,0,0
0,0,0,0,0,0,0,0,0,0,0,0,0,0,0,0,0
0,0,0,0,0,0,0,0,0,0,0,0,0,0,0,0,0
0,0,0,0,0,8,24,8,38,8,24,8,0,0,0,0,0
0,0,0,0,0,8,0,0,0,39,0,8,0,0,0,0,0
0,0,0,0,0,8,0,0,0,0,0,8,0,0,0,0,0
0,0,0,0,0,24,0,0,0,0,0,24,0,0,0,0,0
0,0,0,0,0,8,0,0,0,0,30,8,0,0,0,0,0
0,0,0,0,0,8,13,0,0,0,0,24,0,0,0,0,0
0,0,0,0,0,8,40,0,0,0,30,8,0,0,0,0,0
0,0,0,0,0,8,41,0,0,0,42,8,0,0,0,0,0
0,0,0,0,0,8,8,32,43,32,8,8,0,0,0,0,0
0,0,0,0,0,0,0,0,0,0,0,0,0,0,0,0,0
0,0,0,0,0,0,0,0,0,0,0,0,0,0,0,0,0
0,0,0,0,0,0,0,0,0,0,0,0,0,0,0,0,0
0,0,0,0,0,0,0,0,0,0,0,0,0,0,0,0,0
0,37,0,0,0,0,0,37,0,37,0,0,0,0,0,37,0
0,0,0,0,0,0,0,0,0,0,0,0,0,0,0,0,0
0,0,0,0,0,0,0,0,0,0,0,0,0,0,0,0,0
0,0,0,0,0,0,0,0,0,0,0,0,0,0,0,0,0
0,0,0,0,0,0,0,0,0,0,0,0,0,0,0,0,0
0,0,0,0,0,0,0,0,0,0,0,0,0,0,0,0,0
0,0,0,0,0,0,0,0,0,0,0,0,0,0,0,0,0
:endlayer
layer: 6
0,0,0,0,0,0,0,0,0,0,0,0,0,0,0,0,0
0,0,0,0,0,0,0,0,0,0,0,0,0,0,0,0,0
0,0,0,0,0,0,0,0,0,0,0,0,0,0,0,0,0
0,0,0,0,0,0,0,0,0,0,0,0,0,0,0,0,0
0,0,0,0,0,44,45,44,46,44,45,44,0,0,0,0,0
0,0,0,0,47,8,8,8,8,8,8,8,48,0,0,0,0
0,0,0,0,45,8,49,49,49,49,40,8,45,0,0,0,0
0,0,0,0,47,8,49,49,49,49,40,8,48,0,0,0,0
0,0,0,0,45,8,0,49,49,49,40,8,45,0,0,0,0
0,0,0,0,47,8,0,49,49,49,40,8,48,0,0,0,0
0,0,0,0,45,8,0,49,49,49,40,8,45,0,0,0,0
0,0,0,0,47,8,13,49,49,49,40,8,48,0,0,0,0
0,0,0,0,45,8,49,49,49,49,40,8,45,0,0,0,0
0,0,0,0,47,8,8,32,8,32,8,8,48,0,0,0,0
0,0,0,0,0,50,45,50,0,50,0,50,0,0,0,0,0
0,0,0,0,0,0,0,0,0,0,0,0,0,0,0,0,0
0,0,0,0,0,0,0,0,0,0,0,0,0,0,0,0,0
0,0,0,0,0,0,0,0,0,0,0,0,0,0,0,0,0
0,0,0,0,0,0,0,0,0,0,0,0,0,0,0,0,0
0,0,0,0,0,0,0,0,0,0,0,0,0,0,0,0,0
0,0,0,0,0,0,0,0,0,0,0,0,0,0,0,0,0
0,0,0,0,0,0,0,0,0,0,0,0,0,0,0,0,0
0,0,0,0,0,0,0,0,0,0,0,0,0,0,0,0,0
0,0,0,0,0,0,0,0,0,0,0,0,0,0,0,0,0
0,0,0,0,0,0,0,0,0,0,0,0,0,0,0,0,0
:endlayer
layer: 7
0,0,0,0,0,0,0,0,0,0,0,0,0,0,0,0,0
0,0,0,0,0,0,0,0,0,0,0,0,0,0,0,0,0
0,0,0,0,0,0,0,0,0,0,0,0,0,0,0,0,0
0,0,0,0,0,0,0,0,0,0,0,0,0,0,0,0,0
0,0,0,0,0,30,0,30,0,30,0,30,0,0,0,0,0
0,0,0,0,30,32,13,32,13,32,13,32,30,0,0,0,0
0,0,0,0,0,51,15,15,15,52,0,52,0,0,0,0,0
0,0,0,0,30,32,53,0,54,0,0,32,30,0,0,0,0
0,0,0,0,0,43,0,0,0,0,0,43,0,0,0,0,0
0,0,0,0,30,32,0,0,0,0,55,32,30,0,0,0,0
0,0,0,0,0,51,0,0,0,56,57,52,0,0,0,0,0
0,0,0,0,30,32,58,0,0,56,57,32,30,0,0,0,0
0,0,0,0,0,51,0,0,0,0,55,52,0,0,0,0,0
0,0,0,0,30,32,59,32,59,32,59,32,30,0,0,0,0
0,0,0,0,0,30,0,30,0,30,0,30,0,0,0,0,0
0,0,0,0,0,0,0,0,0,0,0,0,0,0,0,0,0
0,0,0,0,0,0,0,0,0,0,0,0,0,0,0,0,0
0,0,0,0,0,0,0,0,0,0,0,0,0,0,0,0,0
0,0,0,0,0,0,0,0,0,0,0,0,0,0,0,0,0
0,0,0,0,0,0,0,0,0,0,0,0,0,0,0,0,0
0,0,0,0,0,0,0,0,0,0,0,0,0,0,0,0,0
0,0,0,0,0,0,0,0,0,0,0,0,0,0,0,0,0
0,0,0,0,0,0,0,0,0,0,0,0,0,0,0,0,0
0,0,0,0,0,0,0,0,0,0,0,0,0,0,0,0,0
0,0,0,0,0,0,0,0,0,0,0,0,0,0,0,0,0
:endlayer
layer: 8
0,0,0,0,0,0,0,0,0,0,0,0,0,0,0,0,0
0,0,0,0,0,0,0,0,0,0,0,0,0,0,0,0,0
0,0,0,0,0,0,0,0,0,0,0,0,0,0,0,0,0
0,0,0,0,0,0,0,0,0,0,0,0,0,0,0,0,0
0,0,0,0,0,30,0,30,0,30,0,30,0,0,0,0,0
0,0,0,0,30,32,60,32,60,32,60,32,30,0,0,0,0
0,0,0,0,0,14,15,15,52,0,0,31,0,0,0,0,0
0,0,0,0,30,32,0,0,0,0,0,32,30,0,0,0,0
0,0,0,0,0,43,0,0,0,0,0,43,0,0,0,0,0
0,0,0,0,30,32,0,0,0,0,37,32,30,0,0,0,0
0,0,0,0,0,14,0,0,0,0,0,31,0,0,0,0,0
0,0,0,0,30,32,0,0,0,0,0,32,30,0,0,0,0
0,0,0,0,0,14,0,0,0,0,37,31,0,0,0,0,0
0,0,0,0,30,32,61,32,61,32,61,32,30,0,0,0,0
0,0,0,0,0,30,0,30,0,30,0,30,0,0,0,0,0
0,0,0,0,0,0,0,0,0,0,0,0,0,0,0,0,0
0,0,0,0,0,0,0,0,0,0,0,0,0,0,0,0,0
0,0,0,0,0,0,0,0,0,0,0,0,0,0,0,0,0
0,0,0,0,0,0,0,0,0,0,0,0,0,0,0,0,0
0,0,0,0,0,0,0,0,0,0,0,0,0,0,0,0,0
0,0,0,0,0,0,0,0,0,0,0,0,0,0,0,0,0
0,0,0,0,0,0,0,0,0,0,0,0,0,0,0,0,0
0,0,0,0,0,0,0,0,0,0,0,0,0,0,0,0,0
0,0,0,0,0,0,0,0,0,0,0,0,0,0,0,0,0
0,0,0,0,0,0,0,0,0,0,0,0,0,0,0,0,0
:endlayer
layer: 9
0,0,0,0,0,0,0,0,0,0,0,0,0,0,0,0,0
0,0,0,0,0,0,0,0,0,0,0,0,0,0,0,0,0
0,0,0,0,0,0,0,0,0,0,0,0,0,0,0,0,0
0,0,0,0,0,0,0,0,0,0,0,0,0,0,0,0,0
0,0,0,0,0,13,62,13,62,13,62,13,0,0,0,0,0
0,0,0,0,51,32,63,63,63,63,63,32,52,0,0,0,0
0,0,0,0,62,64,49,52,0,0,0,64,62,0,0,0,0
0,0,0,0,51,64,49,49,49,49,49,64,52,0,0,0,0
0,0,0,0,62,64,49,49,49,49,49,64,62,0,0,0,0
0,0,0,0,51,64,49,49,49,49,49,64,52,0,0,0,0
0,0,0,0,62,64,49,49,49,49,49,64,62,0,0,0,0
0,0,0,0,51,32,49,49,49,49,49,32,52,0,0,0,0
0,0,0,0,62,64,49,49,49,49,49,64,62,0,0,0,0
0,0,0,0,51,32,63,63,63,63,63,32,52,0,0,0,0
0,0,0,0,0,59,62,59,62,59,62,59,0,0,0,0,0
0,0,0,0,0,0,0,0,0,0,0,0,0,0,0,0,0
0,0,0,0,0,0,0,0,0,0,0,0,0,0,0,0,0
0,0,0,0,0,0,0,0,0,0,0,0,0,0,0,0,0
0,0,0,0,0,0,0,0,0,0,0,0,0,0,0,0,0
0,0,0,0,0,0,0,0,0,0,0,0,0,0,0,0,0
0,0,0,0,0,0,0,0,0,0,0,0,0,0,0,0,0
0,0,0,0,0,0,0,0,0,0,0,0,0,0,0,0,0
0,0,0,0,0,0,0,0,0,0,0,0,0,0,0,0,0
0,0,0,0,0,0,0,0,0,0,0,0,0,0,0,0,0
0,0,0,0,0,0,0,0,0,0,0,0,0,0,0,0,0
:endlayer
layer: 10
0,0,0,0,0,0,0,0,0,0,0,0,0,0,0,0,0
0,0,0,0,0,0,0,0,0,0,0,0,0,0,0,0,0
0,0,0,0,0,0,0,0,0,0,0,0,0,0,0,0,0
0,0,0,0,0,0,0,0,0,0,0,0,0,0,0,0,0
0,0,0,0,0,0,0,0,0,0,0,0,0,0,0,0,0
0,0,0,0,0,32,15,32,15,32,15,32,0,0,0,0,0
0,0,0,0,0,15,0,0,0,0,0,15,0,0,0,0,0
0,0,0,0,0,32,0,0,0,0,0,32,0,0,0,0,0
0,0,0,0,0,15,0,0,0,0,0,15,0,0,0,0,0
0,0,0,0,0,32,0,0,0,0,0,32,0,0,0,0,0
0,0,0,0,0,15,0,0,0,0,0,15,0,0,0,0,0
0,0,0,0,0,32,0,0,0,0,0,32,0,0,0,0,0
0,0,0,0,0,15,0,0,65,0,0,15,0,0,0,0,0
0,0,0,0,0,32,15,32,15,32,15,32,0,0,0,0,0
0,0,0,0,0,0,0,0,0,0,0,0,0,0,0,0,0
0,0,0,0,0,0,0,0,0,0,0,0,0,0,0,0,0
0,0,0,0,0,0,0,0,0,0,0,0,0,0,0,0,0
0,0,0,0,0,0,0,0,0,0,0,0,0,0,0,0,0
0,0,0,0,0,0,0,0,0,0,0,0,0,0,0,0,0
0,0,0,0,0,0,0,0,0,0,0,0,0,0,0,0,0
0,0,0,0,0,0,0,0,0,0,0,0,0,0,0,0,0
0,0,0,0,0,0,0,0,0,0,0,0,0,0,0,0,0
0,0,0,0,0,0,0,0,0,0,0,0,0,0,0,0,0
0,0,0,0,0,0,0,0,0,0,0,0,0,0,0,0,0
0,0,0,0,0,0,0,0,0,0,0,0,0,0,0,0,0
:endlayer
layer: 11
0,0,0,0,0,0,0,0,0,0,0,0,0,0,0,0,0
0,0,0,0,0,0,0,0,0,0,0,0,0,0,0,0,0
0,0,0,0,0,0,0,0,0,0,0,0,0,0,0,0,0
0,0,0,0,0,0,0,0,0,0,0,0,0,0,0,0,0
0,0,0,0,51,31,0,0,0,0,0,14,52,0,0,0,0
0,0,0,0,51,32,15,32,66,32,15,32,52,0,0,0,0
0,0,0,0,51,15,0,0,0,0,0,15,52,0,0,0,0
0,0,0,0,51,32,0,0,0,0,0,32,52,0,0,0,0
0,0,0,0,51,15,0,0,0,0,0,15,52,0,0,0,0
0,0,0,0,51,32,0,0,0,0,0,32,52,0,0,0,0
0,0,0,0,51,15,0,0,0,0,0,15,52,0,0,0,0
0,0,0,0,51,32,0,0,0,0,0,32,52,0,0,0,0
0,0,0,0,51,15,0,0,0,0,0,15,52,0,0,0,0
0,0,0,0,51,32,15,32,15,32,15,32,52,0,0,0,0
0,0,0,0,51,31,0,0,0,0,0,14,52,0,0,0,0
0,0,0,0,0,0,0,0,0,0,0,0,0,0,0,0,0
0,0,0,0,0,0,0,0,0,0,0,0,0,0,0,0,0
0,0,0,0,0,0,0,0,0,0,0,0,0,0,0,0,0
0,0,0,0,0,0,0,0,0,0,0,0,0,0,0,0,0
0,0,0,0,0,0,0,0,0,0,0,0,0,0,0,0,0
0,0,0,0,0,0,0,0,0,0,0,0,0,0,0,0,0
0,0,0,0,0,0,0,0,0,0,0,0,0,0,0,0,0
0,0,0,0,0,0,0,0,0,0,0,0,0,0,0,0,0
0,0,0,0,0,0,0,0,0,0,0,0,0,0,0,0,0
0,0,0,0,0,0,0,0,0,0,0,0,0,0,0,0,0
:endlayer
layer: 12
0,0,0,0,0,0,0,0,0,0,0,0,0,0,0,0,0
0,0,0,0,0,0,0,0,0,0,0,0,0,0,0,0,0
0,0,0,0,0,0,0,0,0,0,0,0,0,0,0,0,0
0,0,0,0,0,0,0,0,0,0,0,0,0,0,0,0,0
0,0,0,0,0,51,31,0,0,0,14,52,0,0,0,0,0
0,0,0,0,0,51,63,32,63,32,63,52,0,0,0,0,0
0,0,0,0,0,51,31,0,39,0,14,52,0,0,0,0,0
0,0,0,0,0,51,31,0,0,0,14,52,0,0,0,0,0
0,0,0,0,0,51,31,0,0,0,14,52,0,0,0,0,0
0,0,0,0,0,51,31,0,0,0,14,52,0,0,0,0,0
0,0,0,0,0,51,31,0,0,0,14,52,0,0,0,0,0
0,0,0,0,0,51,31,0,0,0,14,52,0,0,0,0,0
0,0,0,0,0,51,31,0,42,0,14,52,0,0,0,0,0
0,0,0,0,0,51,63,32,63,32,63,52,0,0,0,0,0
0,0,0,0,0,51,31,0,0,0,14,52,0,0,0,0,0
0,0,0,0,0,0,0,0,0,0,0,0,0,0,0,0,0
0,0,0,0,0,0,0,0,0,0,0,0,0,0,0,0,0
0,0,0,0,0,0,0,0,0,0,0,0,0,0,0,0,0
0,0,0,0,0,0,0,0,0,0,0,0,0,0,0,0,0
0,0,0,0,0,0,0,0,0,0,0,0,0,0,0,0,0
0,0,0,0,0,0,0,0,0,0,0,0,0,0,0,0,0
0,0,0,0,0,0,0,0,0,0,0,0,0,0,0,0,0
0,0,0,0,0,0,0,0,0,0,0,0,0,0,0,0,0
0,0,0,0,0,0,0,0,0,0,0,0,0,0,0,0,0
0,0,0,0,0,0,0,0,0,0,0,0,0,0,0,0,0
:endlayer
layer: 13
0,0,0,0,0,0,0,0,0,0,0,0,0,0,0,0,0
0,0,0,0,0,0,0,0,0,0,0,0,0,0,0,0,0
0,0,0,0,0,0,0,0,0,0,0,0,0,0,0,0,0
0,0,0,0,0,0,0,0,0,0,0,0,0,0,0,0,0
0,0,0,0,0,0,51,40,40,40,52,0,0,0,0,0,0
0,0,0,0,0,0,51,15,15,15,52,0,0,0,0,0,0
0,0,0,0,0,0,51,31,49,14,52,0,0,0,0,0,0
0,0,0,0,0,0,51,0,0,0,52,0,0,0,0,0,0
0,0,0,0,0,0,51,31,49,14,52,0,0,0,0,0,0
0,0,0,0,0,0,51,0,0,0,52,0,0,0,0,0,0
0,0,0,0,0,0,51,31,49,14,52,0,0,0,0,0,0
0,0,0,0,0,0,51,0,0,0,7,0,0,0,0,0,0
0,0,0,0,0,0,51,31,49,14,52,0,0,0,0,0,0
0,0,0,0,0,0,51,15,15,15,52,0,0,0,0,0,0
0,0,0,0,0,0,51,40,40,40,52,0,0,0,0,0,0
0,0,0,0,0,0,0,0,0,0,0,0,0,0,0,0,0
0,0,0,0,0,0,0,0,0,0,0,0,0,0,0,0,0
0,0,0,0,0,0,0,0,0,0,0,0,0,0,0,0,0
0,0,0,0,0,0,0,0,0,0,0,0,0,0,0,0,0
0,0,0,0,0,0,0,0,0,0,0,0,0,0,0,0,0
0,0,0,0,0,0,0,0,0,0,0,0,0,0,0,0,0
0,0,0,0,0,0,0,0,0,0,0,0,0,0,0,0,0
0,0,0,0,0,0,0,0,0,0,0,0,0,0,0,0,0
0,0,0,0,0,0,0,0,0,0,0,0,0,0,0,0,0
0,0,0,0,0,0,0,0,0,0,0,0,0,0,0,0,0
:endlayer
layer: 14
0,0,0,0,0,0,0,0,0,0,0,0,0,0,0,0,0
0,0,0,0,0,0,0,0,0,0,0,0,0,0,0,0,0
0,0,0,0,0,0,0,0,0,0,0,0,0,0,0,0,0
0,0,0,0,0,0,0,0,0,0,0,0,0,0,0,0,0
0,0,0,0,0,0,0,51,15,52,0,0,0,0,0,0,0
0,0,0,0,0,0,0,51,15,52,0,0,0,0,0,0,0
0,0,0,0,0,0,0,51,15,52,0,0,0,0,0,0,0
0,0,0,0,0,0,0,51,15,52,0,0,0,0,0,0,0
0,0,0,0,0,0,0,51,15,52,0,0,0,0,0,0,0
0,0,0,0,0,0,0,51,15,52,0,0,0,0,0,0,0
0,0,0,0,0,0,0,51,15,52,0,0,0,0,0,0,0
0,0,0,0,0,0,0,51,15,52,7,0,0,0,0,0,0
0,0,0,0,0,0,0,51,15,52,0,0,0,0,0,0,0
0,0,0,0,0,0,0,51,15,52,0,0,0,0,0,0,0
0,0,0,0,0,0,0,51,15,52,0,0,0,0,0,0,0
0,0,0,0,0,0,0,0,0,0,0,0,0,0,0,0,0
0,0,0,0,0,0,0,0,0,0,0,0,0,0,0,0,0
0,0,0,0,0,0,0,0,0,0,0,0,0,0,0,0,0
0,0,0,0,0,0,0,0,0,0,0,0,0,0,0,0,0
0,0,0,0,0,0,0,0,0,0,0,0,0,0,0,0,0
0,0,0,0,0,0,0,0,0,0,0,0,0,0,0,0,0
0,0,0,0,0,0,0,0,0,0,0,0,0,0,0,0,0
0,0,0,0,0,0,0,0,0,0,0,0,0,0,0,0,0
0,0,0,0,0,0,0,0,0,0,0,0,0,0,0,0,0
0,0,0,0,0,0,0,0,0,0,0,0,0,0,0,0,0
:endlayer
layer: 15
0,0,0,0,0,0,0,0,0,0,0,0,0,0,0,0,0
0,0,0,0,0,0,0,0,0,0,0,0,0,0,0,0,0
0,0,0,0,0,0,0,0,0,0,0,0,0,0,0,0,0
0,0,0,0,0,0,0,0,60,0,0,0,0,0,0,0,0
0,0,0,0,0,0,0,0,15,0,0,0,0,0,0,0,0
0,0,0,0,0,0,0,0,59,0,0,0,0,0,0,0,0
0,0,0,0,0,0,0,0,62,0,0,0,0,0,0,0,0
0,0,0,0,0,0,0,0,62,0,0,0,0,0,0,0,0
0,0,0,0,0,0,0,0,62,0,0,0,0,0,0,0,0
0,0,0,0,0,0,0,0,62,0,0,0,0,0,0,0,0
0,0,0,0,0,0,0,0,62,0,0,0,0,0,0,0,0
0,0,0,0,0,0,0,0,62,0,30,0,0,0,0,0,0
0,0,0,0,0,0,0,0,62,0,0,0,0,0,0,0,0
0,0,0,0,0,0,0,0,13,0,0,0,0,0,0,0,0
0,0,0,0,0,0,0,0,15,0,0,0,0,0,0,0,0
0,0,0,0,0,0,0,0,61,0,0,0,0,0,0,0,0
0,0,0,0,0,0,0,0,0,0,0,0,0,0,0,0,0
0,0,0,0,0,0,0,0,0,0,0,0,0,0,0,0,0
0,0,0,0,0,0,0,0,0,0,0,0,0,0,0,0,0
0,0,0,0,0,0,0,0,0,0,0,0,0,0,0,0,0
0,0,0,0,0,0,0,0,0,0,0,0,0,0,0,0,0
0,0,0,0,0,0,0,0,0,0,0,0,0,0,0,0,0
0,0,0,0,0,0,0,0,0,0,0,0,0,0,0,0,0
0,0,0,0,0,0,0,0,0,0,0,0,0,0,0,0,0
0,0,0,0,0,0,0,0,0,0,0,0,0,0,0,0,0
:endlayer
layer: 16
0,0,0,0,0,0,0,0,0,0,0,0,0,0,0,0,0
0,0,0,0,0,0,0,0,0,0,0,0,0,0,0,0,0
0,0,0,0,0,0,0,0,0,0,0,0,0,0,0,0,0
0,0,0,0,0,0,0,0,0,0,0,0,0,0,0,0,0
0,0,0,0,0,0,0,0,37,0,0,0,0,0,0,0,0
0,0,0,0,0,0,0,0,0,0,0,0,0,0,0,0,0
0,0,0,0,0,0,0,0,0,0,0,0,0,0,0,0,0
0,0,0,0,0,0,0,0,0,0,0,0,0,0,0,0,0
0,0,0,0,0,0,0,0,0,0,0,0,0,0,0,0,0
0,0,0,0,0,0,0,0,0,0,0,0,0,0,0,0,0
0,0,0,0,0,0,0,0,0,0,0,0,0,0,0,0,0
0,0,0,0,0,0,0,0,0,0,0,0,0,0,0,0,0
0,0,0,0,0,0,0,0,0,0,0,0,0,0,0,0,0
0,0,0,0,0,0,0,0,0,0,0,0,0,0,0,0,0
0,0,0,0,0,0,0,0,37,0,0,0,0,0,0,0,0
0,0,0,0,0,0,0,0,0,0,0,0,0,0,0,0,0
0,0,0,0,0,0,0,0,0,0,0,0,0,0,0,0,0
0,0,0,0,0,0,0,0,0,0,0,0,0,0,0,0,0
0,0,0,0,0,0,0,0,0,0,0,0,0,0,0,0,0
0,0,0,0,0,0,0,0,0,0,0,0,0,0,0,0,0
0,0,0,0,0,0,0,0,0,0,0,0,0,0,0,0,0
0,0,0,0,0,0,0,0,0,0,0,0,0,0,0,0,0
0,0,0,0,0,0,0,0,0,0,0,0,0,0,0,0,0
0,0,0,0,0,0,0,0,0,0,0,0,0,0,0,0,0
0,0,0,0,0,0,0,0,0,0,0,0,0,0,0,0,0
:endlayer
layer: 17
0,0,0,0,0,0,0,0,0,0,0,0,0,0,0,0,0
0,0,0,0,0,0,0,0,0,0,0,0,0,0,0,0,0
0,0,0,0,0,0,0,0,0,0,0,0,0,0,0,0,0
0,0,0,0,0,0,0,0,0,0,0,0,0,0,0,0,0
0,0,0,0,0,0,0,0,0,0,0,0,0,0,0,0,0
0,0,0,0,0,0,0,0,0,0,0,0,0,0,0,0,0
0,0,0,0,0,0,0,0,0,0,0,0,0,0,0,0,0
0,0,0,0,0,0,0,0,0,0,0,0,0,0,0,0,0
0,0,0,0,0,0,0,0,0,0,0,0,0,0,0,0,0
0,0,0,0,0,0,0,0,0,0,0,0,0,0,0,0,0
0,0,0,0,0,0,0,0,0,0,0,0,0,0,0,0,0
0,0,0,0,0,0,0,0,0,0,0,0,0,0,0,0,0
0,0,0,0,0,0,0,0,0,0,0,0,0,0,0,0,0
0,0,0,0,0,0,0,0,0,0,0,0,0,0,0,0,0
0,0,0,0,0,0,0,0,0,0,0,0,0,0,0,0,0
0,0,0,0,0,0,0,0,0,0,0,0,0,0,0,0,0
0,0,0,0,0,0,0,0,0,0,0,0,0,0,0,0,0
0,0,0,0,0,0,0,0,0,0,0,0,0,0,0,0,0
0,0,0,0,0,0,0,0,0,0,0,0,0,0,0,0,0
0,0,0,0,0,0,0,0,0,0,0,0,0,0,0,0,0
0,0,0,0,0,0,0,0,0,0,0,0,0,0,0,0,0
0,0,0,0,0,0,0,0,0,0,0,0,0,0,0,0,0
0,0,0,0,0,0,0,0,0,0,0,0,0,0,0,0,0
0,0,0,0,0,0,0,0,0,0,0,0,0,0,0,0,0
0,0,0,0,0,0,0,0,0,0,0,0,0,0,0,0,0
:endlayer
layer: 18
0,0,0,0,0,0,0,0,0,0,0,0,0,0,0,0,0
0,0,0,0,0,0,0,0,0,0,0,0,0,0,0,0,0
0,0,0,0,0,0,0,0,0,0,0,0,0,0,0,0,0
0,0,0,0,0,0,0,0,0,0,0,0,0,0,0,0,0
0,0,0,0,0,0,0,0,0,0,0,0,0,0,0,0,0
0,0,0,0,0,0,0,0,0,0,0,0,0,0,0,0,0
0,0,0,0,0,0,0,0,0,0,0,0,0,0,0,0,0
0,0,0,0,0,0,0,0,0,0,0,0,0,0,0,0,0
0,0,0,0,0,0,0,0,0,0,0,0,0,0,0,0,0
0,0,0,0,0,0,0,0,0,0,0,0,0,0,0,0,0
0,0,0,0,0,0,0,0,0,0,0,0,0,0,0,0,0
0,0,0,0,0,0,0,0,0,0,0,0,0,0,0,0,0
0,0,0,0,0,0,0,0,0,0,0,0,0,0,0,0,0
0,0,0,0,0,0,0,0,0,0,0,0,0,0,0,0,0
0,0,0,0,0,0,0,0,0,0,0,0,0,0,0,0,0
0,0,0,0,0,0,0,0,0,0,0,0,0,0,0,0,0
0,0,0,0,0,0,0,0,0,0,0,0,0,0,0,0,0
0,0,0,0,0,0,0,0,0,0,0,0,0,0,0,0,0
0,0,0,0,0,0,0,0,0,0,0,0,0,0,0,0,0
0,0,0,0,0,0,0,0,0,0,0,0,0,0,0,0,0
0,0,0,0,0,0,0,0,0,0,0,0,0,0,0,0,0
0,0,0,0,0,0,0,0,0,0,0,0,0,0,0,0,0
0,0,0,0,0,0,0,0,0,0,0,0,0,0,0,0,0
0,0,0,0,0,0,0,0,0,0,0,0,0,0,0,0,0
0,0,0,0,0,0,0,0,0,0,0,0,0,0,0,0,0
:endlayer
layer: 19
0,0,0,0,0,0,0,0,0,0,0,0,0,0,0,0,0
0,0,0,0,0,0,0,0,0,0,0,0,0,0,0,0,0
0,0,0,0,0,0,0,0,0,0,0,0,0,0,0,0,0
0,0,0,0,0,0,0,0,0,0,0,0,0,0,0,0,0
0,0,0,0,0,0,0,0,0,0,0,0,0,0,0,0,0
0,0,0,0,0,0,0,0,0,0,0,0,0,0,0,0,0
0,0,0,0,0,0,0,0,0,0,0,0,0,0,0,0,0
0,0,0,0,0,0,0,0,0,0,0,0,0,0,0,0,0
0,0,0,0,0,0,0,0,0,0,0,0,0,0,0,0,0
0,0,0,0,0,0,0,0,0,0,0,0,0,0,0,0,0
0,0,0,0,0,0,0,0,0,0,0,0,0,0,0,0,0
0,0,0,0,0,0,0,0,0,0,0,0,0,0,0,0,0
0,0,0,0,0,0,0,0,0,0,0,0,0,0,0,0,0
0,0,0,0,0,0,0,0,0,0,0,0,0,0,0,0,0
0,0,0,0,0,0,0,0,0,0,0,0,0,0,0,0,0
0,0,0,0,0,0,0,0,0,0,0,0,0,0,0,0,0
0,0,0,0,0,0,0,0,0,0,0,0,0,0,0,0,0
0,0,0,0,0,0,0,0,0,0,0,0,0,0,0,0,0
0,0,0,0,0,0,0,0,0,0,0,0,0,0,0,0,0
0,0,0,0,0,0,0,0,0,0,0,0,0,0,0,0,0
0,0,0,0,0,0,0,0,0,0,0,0,0,0,0,0,0
0,0,0,0,0,0,0,0,0,0,0,0,0,0,0,0,0
0,0,0,0,0,0,0,0,0,0,0,0,0,0,0,0,0
0,0,0,0,0,0,0,0,0,0,0,0,0,0,0,0,0
0,0,0,0,0,0,0,0,0,0,0,0,0,0,0,0,0
:endlayer
layer: 20
0,0,0,0,0,0,0,0,0,0,0,0,0,0,0,0,0
0,0,0,0,0,0,0,0,0,0,0,0,0,0,0,0,0
0,0,0,0,0,0,0,0,0,0,0,0,0,0,0,0,0
0,0,0,0,0,0,0,0,0,0,0,0,0,0,0,0,0
0,0,0,0,0,0,0,0,0,0,0,0,0,0,0,0,0
0,0,0,0,0,0,0,0,0,0,0,0,0,0,0,0,0
0,0,0,0,0,0,0,0,0,0,0,0,0,0,0,0,0
0,0,0,0,0,0,0,0,0,0,0,0,0,0,0,0,0
0,0,0,0,0,0,0,0,0,0,0,0,0,0,0,0,0
0,0,0,0,0,0,0,0,0,0,0,0,0,0,0,0,0
0,0,0,0,0,0,0,0,0,0,0,0,0,0,0,0,0
0,0,0,0,0,0,0,0,0,0,0,0,0,0,0,0,0
0,0,0,0,0,0,0,0,0,0,0,0,0,0,0,0,0
0,0,0,0,0,0,0,0,0,0,0,0,0,0,0,0,0
0,0,0,0,0,0,0,0,0,0,0,0,0,0,0,0,0
0,0,0,0,0,0,0,0,0,0,0,0,0,0,0,0,0
0,0,0,0,0,0,0,0,0,0,0,0,0,0,0,0,0
0,0,0,0,0,0,0,0,0,0,0,0,0,0,0,0,0
0,0,0,0,0,0,0,0,0,0,0,0,0,0,0,0,0
0,0,0,0,0,0,0,0,0,0,0,0,0,0,0,0,0
0,0,0,0,0,0,0,0,0,0,0,0,0,0,0,0,0
0,0,0,0,0,0,0,0,0,0,0,0,0,0,0,0,0
0,0,0,0,0,0,0,0,0,0,0,0,0,0,0,0,0
0,0,0,0,0,0,0,0,0,0,0,0,0,0,0,0,0
0,0,0,0,0,0,0,0,0,0,0,0,0,0,0,0,0
:endlayer
layer: 21
0,0,0,0,0,0,0,0,0,0,0,0,0,0,0,0,0
0,0,0,0,0,0,0,0,0,0,0,0,0,0,0,0,0
0,0,0,0,0,0,0,0,0,0,0,0,0,0,0,0,0
0,0,0,0,0,0,0,0,0,0,0,0,0,0,0,0,0
0,0,0,0,0,0,0,0,0,0,0,0,0,0,0,0,0
0,0,0,0,0,0,0,0,0,0,0,0,0,0,0,0,0
0,0,0,0,0,0,0,0,0,0,0,0,0,0,0,0,0
0,0,0,0,0,0,0,0,0,0,0,0,0,0,0,0,0
0,0,0,0,0,0,0,0,0,0,0,0,0,0,0,0,0
0,0,0,0,0,0,0,0,0,0,0,0,0,0,0,0,0
0,0,0,0,0,0,0,0,0,0,0,0,0,0,0,0,0
0,0,0,0,0,0,0,0,0,0,0,0,0,0,0,0,0
0,0,0,0,0,0,0,0,0,0,0,0,0,0,0,0,0
0,0,0,0,0,0,0,0,0,0,0,0,0,0,0,0,0
0,0,0,0,0,0,0,0,0,0,0,0,0,0,0,0,0
0,0,0,0,0,0,0,0,0,0,0,0,0,0,0,0,0
0,0,0,0,0,0,0,0,0,0,0,0,0,0,0,0,0
0,0,0,0,0,0,0,0,0,0,0,0,0,0,0,0,0
0,0,0,0,0,0,0,0,0,0,0,0,0,0,0,0,0
0,0,0,0,0,0,0,0,0,0,0,0,0,0,0,0,0
0,0,0,0,0,0,0,0,0,0,0,0,0,0,0,0,0
0,0,0,0,0,0,0,0,0,0,0,0,0,0,0,0,0
0,0,0,0,0,0,0,0,0,0,0,0,0,0,0,0,0
0,0,0,0,0,0,0,0,0,0,0,0,0,0,0,0,0
0,0,0,0,0,0,0,0,0,0,0,0,0,0,0,0,0
:endlayer
layer: 22
0,0,0,0,0,0,0,0,0,0,0,0,0,0,0,0,0
0,0,0,0,0,0,0,0,0,0,0,0,0,0,0,0,0
0,0,0,0,0,0,0,0,0,0,0,0,0,0,0,0,0
0,0,0,0,0,0,0,0,0,0,0,0,0,0,0,0,0
0,0,0,0,0,0,0,0,0,0,0,0,0,0,0,0,0
0,0,0,0,0,0,0,0,0,0,0,0,0,0,0,0,0
0,0,0,0,0,0,0,0,0,0,0,0,0,0,0,0,0
0,0,0,0,0,0,0,0,0,0,0,0,0,0,0,0,0
0,0,0,0,0,0,0,0,0,0,0,0,0,0,0,0,0
0,0,0,0,0,0,0,0,0,0,0,0,0,0,0,0,0
0,0,0,0,0,0,0,0,0,0,0,0,0,0,0,0,0
0,0,0,0,0,0,0,0,0,0,0,0,0,0,0,0,0
0,0,0,0,0,0,0,0,0,0,0,0,0,0,0,0,0
0,0,0,0,0,0,0,0,0,0,0,0,0,0,0,0,0
0,0,0,0,0,0,0,0,0,0,0,0,0,0,0,0,0
0,0,0,0,0,0,0,0,0,0,0,0,0,0,0,0,0
0,0,0,0,0,0,0,0,0,0,0,0,0,0,0,0,0
0,0,0,0,0,0,0,0,0,0,0,0,0,0,0,0,0
0,0,0,0,0,0,0,0,0,0,0,0,0,0,0,0,0
0,0,0,0,0,0,0,0,0,0,0,0,0,0,0,0,0
0,0,0,0,0,0,0,0,0,0,0,0,0,0,0,0,0
0,0,0,0,0,0,0,0,0,0,0,0,0,0,0,0,0
0,0,0,0,0,0,0,0,0,0,0,0,0,0,0,0,0
0,0,0,0,0,0,0,0,0,0,0,0,0,0,0,0,0
0,0,0,0,0,0,0,0,0,0,0,0,0,0,0,0,0
:endlayer
layer: 23
0,0,0,0,0,0,0,0,0,0,0,0,0,0,0,0,0
0,0,0,0,0,0,0,0,0,0,0,0,0,0,0,0,0
0,0,0,0,0,0,0,0,0,0,0,0,0,0,0,0,0
0,0,0,0,0,0,0,0,0,0,0,0,0,0,0,0,0
0,0,0,0,0,0,0,0,0,0,0,0,0,0,0,0,0
0,0,0,0,0,0,0,0,0,0,0,0,0,0,0,0,0
0,0,0,0,0,0,0,0,0,0,0,0,0,0,0,0,0
0,0,0,0,0,0,0,0,0,0,0,0,0,0,0,0,0
0,0,0,0,0,0,0,0,0,0,0,0,0,0,0,0,0
0,0,0,0,0,0,0,0,0,0,0,0,0,0,0,0,0
0,0,0,0,0,0,0,0,0,0,0,0,0,0,0,0,0
0,0,0,0,0,0,0,0,0,0,0,0,0,0,0,0,0
0,0,0,0,0,0,0,0,0,0,0,0,0,0,0,0,0
0,0,0,0,0,0,0,0,0,0,0,0,0,0,0,0,0
0,0,0,0,0,0,0,0,0,0,0,0,0,0,0,0,0
0,0,0,0,0,0,0,0,0,0,0,0,0,0,0,0,0
0,0,0,0,0,0,0,0,0,0,0,0,0,0,0,0,0
0,0,0,0,0,0,0,0,0,0,0,0,0,0,0,0,0
0,0,0,0,0,0,0,0,0,0,0,0,0,0,0,0,0
0,0,0,0,0,0,0,0,0,0,0,0,0,0,0,0,0
0,0,0,0,0,0,0,0,0,0,0,0,0,0,0,0,0
0,0,0,0,0,0,0,0,0,0,0,0,0,0,0,0,0
0,0,0,0,0,0,0,0,0,0,0,0,0,0,0,0,0
0,0,0,0,0,0,0,0,0,0,0,0,0,0,0,0,0
0,0,0,0,0,0,0,0,0,0,0,0,0,0,0,0,0
:endlayer
layer: 24
0,0,0,0,0,0,0,0,0,0,0,0,0,0,0,0,0
0,0,0,0,0,0,0,0,0,0,0,0,0,0,0,0,0
0,0,0,0,0,0,0,0,0,0,0,0,0,0,0,0,0
0,0,0,0,0,0,0,0,0,0,0,0,0,0,0,0,0
0,0,0,0,0,0,0,0,0,0,0,0,0,0,0,0,0
0,0,0,0,0,0,0,0,0,0,0,0,0,0,0,0,0
0,0,0,0,0,0,0,0,0,0,0,0,0,0,0,0,0
0,0,0,0,0,0,0,0,0,0,0,0,0,0,0,0,0
0,0,0,0,0,0,0,0,0,0,0,0,0,0,0,0,0
0,0,0,0,0,0,0,0,0,0,0,0,0,0,0,0,0
0,0,0,0,0,0,0,0,0,0,0,0,0,0,0,0,0
0,0,0,0,0,0,0,0,0,0,0,0,0,0,0,0,0
0,0,0,0,0,0,0,0,0,0,0,0,0,0,0,0,0
0,0,0,0,0,0,0,0,0,0,0,0,0,0,0,0,0
0,0,0,0,0,0,0,0,0,0,0,0,0,0,0,0,0
0,0,0,0,0,0,0,0,0,0,0,0,0,0,0,0,0
0,0,0,0,0,0,0,0,0,0,0,0,0,0,0,0,0
0,0,0,0,0,0,0,0,0,0,0,0,0,0,0,0,0
0,0,0,0,0,0,0,0,0,0,0,0,0,0,0,0,0
0,0,0,0,0,0,0,0,0,0,0,0,0,0,0,0,0
0,0,0,0,0,0,0,0,0,0,0,0,0,0,0,0,0
0,0,0,0,0,0,0,0,0,0,0,0,0,0,0,0,0
0,0,0,0,0,0,0,0,0,0,0,0,0,0,0,0,0
0,0,0,0,0,0,0,0,0,0,0,0,0,0,0,0,0
0,0,0,0,0,0,0,0,0,0,0,0,0,0,0,0,0
:endlayer
layer: 25
0,0,0,0,0,0,0,0,0,0,0,0,0,0,0,0,0
0,0,0,0,0,0,0,0,0,0,0,0,0,0,0,0,0
0,0,0,0,0,0,0,0,0,0,0,0,0,0,0,0,0
0,0,0,0,0,0,0,0,0,0,0,0,0,0,0,0,0
0,0,0,0,0,0,0,0,0,0,0,0,0,0,0,0,0
0,0,0,0,0,0,0,0,0,0,0,0,0,0,0,0,0
0,0,0,0,0,0,0,0,0,0,0,0,0,0,0,0,0
0,0,0,0,0,0,0,0,0,0,0,0,0,0,0,0,0
0,0,0,0,0,0,0,0,0,0,0,0,0,0,0,0,0
0,0,0,0,0,0,0,0,0,0,0,0,0,0,0,0,0
0,0,0,0,0,0,0,0,0,0,0,0,0,0,0,0,0
0,0,0,0,0,0,0,0,0,0,0,0,0,0,0,0,0
0,0,0,0,0,0,0,0,0,0,0,0,0,0,0,0,0
0,0,0,0,0,0,0,0,0,0,0,0,0,0,0,0,0
0,0,0,0,0,0,0,0,0,0,0,0,0,0,0,0,0
0,0,0,0,0,0,0,0,0,0,0,0,0,0,0,0,0
0,0,0,0,0,0,0,0,0,0,0,0,0,0,0,0,0
0,0,0,0,0,0,0,0,0,0,0,0,0,0,0,0,0
0,0,0,0,0,0,0,0,0,0,0,0,0,0,0,0,0
0,0,0,0,0,0,0,0,0,0,0,0,0,0,0,0,0
0,0,0,0,0,0,0,0,0,0,0,0,0,0,0,0,0
0,0,0,0,0,0,0,0,0,0,0,0,0,0,0,0,0
0,0,0,0,0,0,0,0,0,0,0,0,0,0,0,0,0
0,0,0,0,0,0,0,0,0,0,0,0,0,0,0,0,0
0,0,0,0,0,0,0,0,0,0,0,0,0,0,0,0,0
:endlayer
layer: 26
0,0,0,0,0,0,0,0,0,0,0,0,0,0,0,0,0
0,0,0,0,0,0,0,0,0,0,0,0,0,0,0,0,0
0,0,0,0,0,0,0,0,0,0,0,0,0,0,0,0,0
0,0,0,0,0,0,0,0,0,0,0,0,0,0,0,0,0
0,0,0,0,0,0,0,0,0,0,0,0,0,0,0,0,0
0,0,0,0,0,0,0,0,0,0,0,0,0,0,0,0,0
0,0,0,0,0,0,0,0,0,0,0,0,0,0,0,0,0
0,0,0,0,0,0,0,0,0,0,0,0,0,0,0,0,0
0,0,0,0,0,0,0,0,0,0,0,0,0,0,0,0,0
0,0,0,0,0,0,0,0,0,0,0,0,0,0,0,0,0
0,0,0,0,0,0,0,0,0,0,0,0,0,0,0,0,0
0,0,0,0,0,0,0,0,0,0,0,0,0,0,0,0,0
0,0,0,0,0,0,0,0,0,0,0,0,0,0,0,0,0
0,0,0,0,0,0,0,0,0,0,0,0,0,0,0,0,0
0,0,0,0,0,0,0,0,0,0,0,0,0,0,0,0,0
0,0,0,0,0,0,0,0,0,0,0,0,0,0,0,0,0
0,0,0,0,0,0,0,0,0,0,0,0,0,0,0,0,0
0,0,0,0,0,0,0,0,0,0,0,0,0,0,0,0,0
0,0,0,0,0,0,0,0,0,0,0,0,0,0,0,0,0
0,0,0,0,0,0,0,0,0,0,0,0,0,0,0,0,0
0,0,0,0,0,0,0,0,0,0,0,0,0,0,0,0,0
0,0,0,0,0,0,0,0,0,0,0,0,0,0,0,0,0
0,0,0,0,0,0,0,0,0,0,0,0,0,0,0,0,0
0,0,0,0,0,0,0,0,0,0,0,0,0,0,0,0,0
0,0,0,0,0,0,0,0,0,0,0,0,0,0,0,0,0
:endlayer
layer: 27
0,0,0,0,0,0,0,0,0,0,0,0,0,0,0,0,0
0,0,0,0,0,0,0,0,0,0,0,0,0,0,0,0,0
0,0,0,0,0,0,0,0,0,0,0,0,0,0,0,0,0
0,0,0,0,0,0,0,0,0,0,0,0,0,0,0,0,0
0,0,0,0,0,0,0,0,0,0,0,0,0,0,0,0,0
0,0,0,0,0,0,0,0,0,0,0,0,0,0,0,0,0
0,0,0,0,0,0,0,0,0,0,0,0,0,0,0,0,0
0,0,0,0,0,0,0,0,0,0,0,0,0,0,0,0,0
0,0,0,0,0,0,0,0,0,0,0,0,0,0,0,0,0
0,0,0,0,0,0,0,0,0,0,0,0,0,0,0,0,0
0,0,0,0,0,0,0,0,0,0,0,0,0,0,0,0,0
0,0,0,0,0,0,0,0,0,0,0,0,0,0,0,0,0
0,0,0,0,0,0,0,0,0,0,0,0,0,0,0,0,0
0,0,0,0,0,0,0,0,0,0,0,0,0,0,0,0,0
0,0,0,0,0,0,0,0,0,0,0,0,0,0,0,0,0
0,0,0,0,0,0,0,0,0,0,0,0,0,0,0,0,0
0,0,0,0,0,0,0,0,0,0,0,0,0,0,0,0,0
0,0,0,0,0,0,0,0,0,0,0,0,0,0,0,0,0
0,0,0,0,0,0,0,0,0,0,0,0,0,0,0,0,0
0,0,0,0,0,0,0,0,0,0,0,0,0,0,0,0,0
0,0,0,0,0,0,0,0,0,0,0,0,0,0,0,0,0
0,0,0,0,0,0,0,0,0,0,0,0,0,0,0,0,0
0,0,0,0,0,0,0,0,0,0,0,0,0,0,0,0,0
0,0,0,0,0,0,0,0,0,0,0,0,0,0,0,0,0
0,0,0,0,0,0,0,0,0,0,0,0,0,0,0,0,0
:endlayer
layer: 28
0,0,0,0,0,0,0,0,0,0,0,0,0,0,0,0,0
0,0,0,0,0,0,0,0,0,0,0,0,0,0,0,0,0
0,0,0,0,0,0,0,0,0,0,0,0,0,0,0,0,0
0,0,0,0,0,0,0,0,0,0,0,0,0,0,0,0,0
0,0,0,0,0,0,0,0,0,0,0,0,0,0,0,0,0
0,0,0,0,0,0,0,0,0,0,0,0,0,0,0,0,0
0,0,0,0,0,0,0,0,0,0,0,0,0,0,0,0,0
0,0,0,0,0,0,0,0,0,0,0,0,0,0,0,0,0
0,0,0,0,0,0,0,0,0,0,0,0,0,0,0,0,0
0,0,0,0,0,0,0,0,0,0,0,0,0,0,0,0,0
0,0,0,0,0,0,0,0,0,0,0,0,0,0,0,0,0
0,0,0,0,0,0,0,0,0,0,0,0,0,0,0,0,0
0,0,0,0,0,0,0,0,0,0,0,0,0,0,0,0,0
0,0,0,0,0,0,0,0,0,0,0,0,0,0,0,0,0
0,0,0,0,0,0,0,0,0,0,0,0,0,0,0,0,0
0,0,0,0,0,0,0,0,0,0,0,0,0,0,0,0,0
0,0,0,0,0,0,0,0,0,0,0,0,0,0,0,0,0
0,0,0,0,0,0,0,0,0,0,0,0,0,0,0,0,0
0,0,0,0,0,0,0,0,0,0,0,0,0,0,0,0,0
0,0,0,0,0,0,0,0,0,0,0,0,0,0,0,0,0
0,0,0,0,0,0,0,0,0,0,0,0,0,0,0,0,0
0,0,0,0,0,0,0,0,0,0,0,0,0,0,0,0,0
0,0,0,0,0,0,0,0,0,0,0,0,0,0,0,0,0
0,0,0,0,0,0,0,0,0,0,0,0,0,0,0,0,0
0,0,0,0,0,0,0,0,0,0,0,0,0,0,0,0,0
:endlayer
layer: 29
0,0,0,0,0,0,0,0,0,0,0,0,0,0,0,0,0
0,0,0,0,0,0,0,0,0,0,0,0,0,0,0,0,0
0,0,0,0,0,0,0,0,0,0,0,0,0,0,0,0,0
0,0,0,0,0,0,0,0,0,0,0,0,0,0,0,0,0
0,0,0,0,0,0,0,0,0,0,0,0,0,0,0,0,0
0,0,0,0,0,0,0,0,0,0,0,0,0,0,0,0,0
0,0,0,0,0,0,0,0,0,0,0,0,0,0,0,0,0
0,0,0,0,0,0,0,0,0,0,0,0,0,0,0,0,0
0,0,0,0,0,0,0,0,0,0,0,0,0,0,0,0,0
0,0,0,0,0,0,0,0,0,0,0,0,0,0,0,0,0
0,0,0,0,0,0,0,0,0,0,0,0,0,0,0,0,0
0,0,0,0,0,0,0,0,0,0,0,0,0,0,0,0,0
0,0,0,0,0,0,0,0,0,0,0,0,0,0,0,0,0
0,0,0,0,0,0,0,0,0,0,0,0,0,0,0,0,0
0,0,0,0,0,0,0,0,0,0,0,0,0,0,0,0,0
0,0,0,0,0,0,0,0,0,0,0,0,0,0,0,0,0
0,0,0,0,0,0,0,0,0,0,0,0,0,0,0,0,0
0,0,0,0,0,0,0,0,0,0,0,0,0,0,0,0,0
0,0,0,0,0,0,0,0,0,0,0,0,0,0,0,0,0
0,0,0,0,0,0,0,0,0,0,0,0,0,0,0,0,0
0,0,0,0,0,0,0,0,0,0,0,0,0,0,0,0,0
0,0,0,0,0,0,0,0,0,0,0,0,0,0,0,0,0
0,0,0,0,0,0,0,0,0,0,0,0,0,0,0,0,0
0,0,0,0,0,0,0,0,0,0,0,0,0,0,0,0,0
0,0,0,0,0,0,0,0,0,0,0,0,0,0,0,0,0
:endlayer
layer: 30
0,0,0,0,0,0,0,0,0,0,0,0,0,0,0,0,0
0,0,0,0,0,0,0,0,0,0,0,0,0,0,0,0,0
0,0,0,0,0,0,0,0,0,0,0,0,0,0,0,0,0
0,0,0,0,0,0,0,0,0,0,0,0,0,0,0,0,0
0,0,0,0,0,0,0,0,0,0,0,0,0,0,0,0,0
0,0,0,0,0,0,0,0,0,0,0,0,0,0,0,0,0
0,0,0,0,0,0,0,0,0,0,0,0,0,0,0,0,0
0,0,0,0,0,0,0,0,0,0,0,0,0,0,0,0,0
0,0,0,0,0,0,0,0,0,0,0,0,0,0,0,0,0
0,0,0,0,0,0,0,0,0,0,0,0,0,0,0,0,0
0,0,0,0,0,0,0,0,0,0,0,0,0,0,0,0,0
0,0,0,0,0,0,0,0,0,0,0,0,0,0,0,0,0
0,0,0,0,0,0,0,0,0,0,0,0,0,0,0,0,0
0,0,0,0,0,0,0,0,0,0,0,0,0,0,0,0,0
0,0,0,0,0,0,0,0,0,0,0,0,0,0,0,0,0
0,0,0,0,0,0,0,0,0,0,0,0,0,0,0,0,0
0,0,0,0,0,0,0,0,0,0,0,0,0,0,0,0,0
0,0,0,0,0,0,0,0,0,0,0,0,0,0,0,0,0
0,0,0,0,0,0,0,0,0,0,0,0,0,0,0,0,0
0,0,0,0,0,0,0,0,0,0,0,0,0,0,0,0,0
0,0,0,0,0,0,0,0,0,0,0,0,0,0,0,0,0
0,0,0,0,0,0,0,0,0,0,0,0,0,0,0,0,0
0,0,0,0,0,0,0,0,0,0,0,0,0,0,0,0,0
0,0,0,0,0,0,0,0,0,0,0,0,0,0,0,0,0
0,0,0,0,0,0,0,0,0,0,0,0,0,0,0,0,0
:endlayer
layer: 31
0,0,0,0,0,0,0,0,0,0,0,0,0,0,0,0,0
0,0,0,0,0,0,0,0,0,0,0,0,0,0,0,0,0
0,0,0,0,0,0,0,0,0,0,0,0,0,0,0,0,0
0,0,0,0,0,0,0,0,0,0,0,0,0,0,0,0,0
0,0,0,0,0,0,0,0,0,0,0,0,0,0,0,0,0
0,0,0,0,0,0,0,0,0,0,0,0,0,0,0,0,0
0,0,0,0,0,0,0,0,0,0,0,0,0,0,0,0,0
0,0,0,0,0,0,0,0,0,0,0,0,0,0,0,0,0
0,0,0,0,0,0,0,0,0,0,0,0,0,0,0,0,0
0,0,0,0,0,0,0,0,0,0,0,0,0,0,0,0,0
0,0,0,0,0,0,0,0,0,0,0,0,0,0,0,0,0
0,0,0,0,0,0,0,0,0,0,0,0,0,0,0,0,0
0,0,0,0,0,0,0,0,0,0,0,0,0,0,0,0,0
0,0,0,0,0,0,0,0,0,0,0,0,0,0,0,0,0
0,0,0,0,0,0,0,0,0,0,0,0,0,0,0,0,0
0,0,0,0,0,0,0,0,0,0,0,0,0,0,0,0,0
0,0,0,0,0,0,0,0,0,0,0,0,0,0,0,0,0
0,0,0,0,0,0,0,0,0,0,0,0,0,0,0,0,0
0,0,0,0,0,0,0,0,0,0,0,0,0,0,0,0,0
0,0,0,0,0,0,0,0,0,0,0,0,0,0,0,0,0
0,0,0,0,0,0,0,0,0,0,0,0,0,0,0,0,0
0,0,0,0,0,0,0,0,0,0,0,0,0,0,0,0,0
0,0,0,0,0,0,0,0,0,0,0,0,0,0,0,0,0
0,0,0,0,0,0,0,0,0,0,0,0,0,0,0,0,0
0,0,0,0,0,0,0,0,0,0,0,0,0,0,0,0,0
:endlayer
layer: 32
0,0,0,0,0,0,0,0,0,0,0,0,0,0,0,0,0
0,0,0,0,0,0,0,0,0,0,0,0,0,0,0,0,0
0,0,0,0,0,0,0,0,0,0,0,0,0,0,0,0,0
0,0,0,0,0,0,0,0,0,0,0,0,0,0,0,0,0
0,0,0,0,0,0,0,0,0,0,0,0,0,0,0,0,0
0,0,0,0,0,0,0,0,0,0,0,0,0,0,0,0,0
0,0,0,0,0,0,0,0,0,0,0,0,0,0,0,0,0
0,0,0,0,0,0,0,0,0,0,0,0,0,0,0,0,0
0,0,0,0,0,0,0,0,0,0,0,0,0,0,0,0,0
0,0,0,0,0,0,0,0,0,0,0,0,0,0,0,0,0
0,0,0,0,0,0,0,0,0,0,0,0,0,0,0,0,0
0,0,0,0,0,0,0,0,0,0,0,0,0,0,0,0,0
0,0,0,0,0,0,0,0,0,0,0,0,0,0,0,0,0
0,0,0,0,0,0,0,0,0,0,0,0,0,0,0,0,0
0,0,0,0,0,0,0,0,0,0,0,0,0,0,0,0,0
0,0,0,0,0,0,0,0,0,0,0,0,0,0,0,0,0
0,0,0,0,0,0,0,0,0,0,0,0,0,0,0,0,0
0,0,0,0,0,0,0,0,0,0,0,0,0,0,0,0,0
0,0,0,0,0,0,0,0,0,0,0,0,0,0,0,0,0
0,0,0,0,0,0,0,0,0,0,0,0,0,0,0,0,0
0,0,0,0,0,0,0,0,0,0,0,0,0,0,0,0,0
0,0,0,0,0,0,0,0,0,0,0,0,0,0,0,0,0
0,0,0,0,0,0,0,0,0,0,0,0,0,0,0,0,0
0,0,0,0,0,0,0,0,0,0,0,0,0,0,0,0,0
0,0,0,0,0,0,0,0,0,0,0,0,0,0,0,0,0
:endlayer
layer: 33
0,0,0,0,0,0,0,0,0,0,0,0,0,0,0,0,0
0,0,0,0,0,0,0,0,0,0,0,0,0,0,0,0,0
0,0,0,0,0,0,0,0,0,0,0,0,0,0,0,0,0
0,0,0,0,0,0,0,0,0,0,0,0,0,0,0,0,0
0,0,0,0,0,0,0,0,0,0,0,0,0,0,0,0,0
0,0,0,0,0,0,0,0,0,0,0,0,0,0,0,0,0
0,0,0,0,0,0,0,0,0,0,0,0,0,0,0,0,0
0,0,0,0,0,0,0,0,0,0,0,0,0,0,0,0,0
0,0,0,0,0,0,0,0,0,0,0,0,0,0,0,0,0
0,0,0,0,0,0,0,0,0,0,0,0,0,0,0,0,0
0,0,0,0,0,0,0,0,0,0,0,0,0,0,0,0,0
0,0,0,0,0,0,0,0,0,0,0,0,0,0,0,0,0
0,0,0,0,0,0,0,0,0,0,0,0,0,0,0,0,0
0,0,0,0,0,0,0,0,0,0,0,0,0,0,0,0,0
0,0,0,0,0,0,0,0,0,0,0,0,0,0,0,0,0
0,0,0,0,0,0,0,0,0,0,0,0,0,0,0,0,0
0,0,0,0,0,0,0,0,0,0,0,0,0,0,0,0,0
0,0,0,0,0,0,0,0,0,0,0,0,0,0,0,0,0
0,0,0,0,0,0,0,0,0,0,0,0,0,0,0,0,0
0,0,0,0,0,0,0,0,0,0,0,0,0,0,0,0,0
0,0,0,0,0,0,0,0,0,0,0,0,0,0,0,0,0
0,0,0,0,0,0,0,0,0,0,0,0,0,0,0,0,0
0,0,0,0,0,0,0,0,0,0,0,0,0,0,0,0,0
0,0,0,0,0,0,0,0,0,0,0,0,0,0,0,0,0
0,0,0,0,0,0,0,0,0,0,0,0,0,0,0,0,0
:endlayer
layer: 34
0,0,0,0,0,0,0,0,0,0,0,0,0,0,0,0,0
0,0,0,0,0,0,0,0,0,0,0,0,0,0,0,0,0
0,0,0,0,0,0,0,0,0,0,0,0,0,0,0,0,0
0,0,0,0,0,0,0,0,0,0,0,0,0,0,0,0,0
0,0,0,0,0,0,0,0,0,0,0,0,0,0,0,0,0
0,0,0,0,0,0,0,0,0,0,0,0,0,0,0,0,0
0,0,0,0,0,0,0,0,0,0,0,0,0,0,0,0,0
0,0,0,0,0,0,0,0,0,0,0,0,0,0,0,0,0
0,0,0,0,0,0,0,0,0,0,0,0,0,0,0,0,0
0,0,0,0,0,0,0,0,0,0,0,0,0,0,0,0,0
0,0,0,0,0,0,0,0,0,0,0,0,0,0,0,0,0
0,0,0,0,0,0,0,0,0,0,0,0,0,0,0,0,0
0,0,0,0,0,0,0,0,0,0,0,0,0,0,0,0,0
0,0,0,0,0,0,0,0,0,0,0,0,0,0,0,0,0
0,0,0,0,0,0,0,0,0,0,0,0,0,0,0,0,0
0,0,0,0,0,0,0,0,0,0,0,0,0,0,0,0,0
0,0,0,0,0,0,0,0,0,0,0,0,0,0,0,0,0
0,0,0,0,0,0,0,0,0,0,0,0,0,0,0,0,0
0,0,0,0,0,0,0,0,0,0,0,0,0,0,0,0,0
0,0,0,0,0,0,0,0,0,0,0,0,0,0,0,0,0
0,0,0,0,0,0,0,0,0,0,0,0,0,0,0,0,0
0,0,0,0,0,0,0,0,0,0,0,0,0,0,0,0,0
0,0,0,0,0,0,0,0,0,0,0,0,0,0,0,0,0
0,0,0,0,0,0,0,0,0,0,0,0,0,0,0,0,0
0,0,0,0,0,0,0,0,0,0,0,0,0,0,0,0,0
:endlayer

#### RULES ####
rule:
plugin=modBlockDefault
number=1
data:
JSON:{{"val":{"blockName":{"val":"UndergroundBiomes:igneousStone","id":"ss"},"meta":{"val":"2","id":"pi"}},"id":"ct"}}
:enddata
:endrule

rule:
plugin=vanillaBlocks
number=2
data:
JSON:{{"val":{"buildPass":{"val":"0","id":"pi"},"blockName":{"val":"minecraft:clay","id":"ss"},"meta":{"val":"0","id":"pi"}},"id":"ct"}}
:enddata
:endrule

rule:
plugin=vanillaBlocks
number=3
data:
JSON:{{"val":{"buildPass":{"val":"0","id":"pi"},"blockName":{"val":"minecraft:gravel","id":"ss"},"meta":{"val":"0","id":"pi"}},"id":"ct"}}
:enddata
:endrule

rule:
plugin=vanillaBlocks
number=4
data:
JSON:{{"val":{"buildPass":{"val":"0","id":"pi"},"blockName":{"val":"minecraft:dirt","id":"ss"},"meta":{"val":"0","id":"pi"}},"id":"ct"}}
:enddata
:endrule

rule:
plugin=modBlockDefault
number=5
data:
JSON:{{"val":{"blockName":{"val":"UndergroundBiomes:sedimentaryStone","id":"ss"},"meta":{"val":"6","id":"pi"}},"id":"ct"}}
:enddata
:endrule

rule:
plugin=vanillaBlocks
number=6
data:
JSON:{{"val":{"buildPass":{"val":"0","id":"pi"},"blockName":{"val":"minecraft:double_wooden_slab","id":"ss"},"meta":{"val":"1","id":"pi"}},"id":"ct"}}
:enddata
:endrule

rule:
plugin=vanillaBlocks
number=7
data:
JSON:{{"val":{"buildPass":{"val":"0","id":"pi"},"blockName":{"val":"minecraft:cobblestone","id":"ss"},"meta":{"val":"0","id":"pi"}},"id":"ct"}}
:enddata
:endrule

rule:
plugin=vanillaBlocks
number=8
data:
JSON:{{"val":{"buildPass":{"val":"0","id":"pi"},"blockName":{"val":"minecraft:stonebrick","id":"ss"},"meta":{"val":"0","id":"pi"}},"id":"ct"}}
:enddata
:endrule

rule:
plugin=vanillaBlocks
number=9
data:
JSON:{{"val":{"buildPass":{"val":"0","id":"pi"},"blockName":{"val":"minecraft:grass","id":"ss"},"meta":{"val":"0","id":"pi"}},"id":"ct"}}
:enddata
:endrule

rule:
plugin=vanillaBlocks
number=10
data:
JSON:{{"val":{"buildPass":{"val":"0","id":"pi"},"blockName":{"val":"minecraft:stone_brick_stairs","id":"ss"},"meta":{"val":"3","id":"pi"}},"id":"ct"}}
:enddata
:endrule

rule:
plugin=vanillaInventory
number=11
data:
JSON:{{"val":{"buildPass":{"val":"0","id":"pi"},"blockName":{"val":"minecraft:chest","id":"ss"},"meta":{"val":"4","id":"pi"},"lootLevel":{"val":"0","id":"pi"},"teData":{"val":{"x":{"val":"-191","id":"pi"},"y":{"val":"70","id":"pi"},"z":{"val":"139","id":"pi"},"id":{"val":"Chest","id":"ss"}},"id":"ct"},"inventoryData":{"val":{"length":{"val":"27","id":"pi"},"inventoryContents":{"val":[],"id":"ls"}},"id":"ct"}},"id":"ct"}}
:enddata
:endrule

rule:
plugin=vanillaInventory
number=12
data:
JSON:{{"val":{"buildPass":{"val":"0","id":"pi"},"blockName":{"val":"minecraft:chest","id":"ss"},"meta":{"val":"4","id":"pi"},"lootLevel":{"val":"0","id":"pi"},"teData":{"val":{"x":{"val":"-191","id":"pi"},"y":{"val":"70","id":"pi"},"z":{"val":"140","id":"pi"},"id":{"val":"Chest","id":"ss"}},"id":"ct"},"inventoryData":{"val":{"length":{"val":"27","id":"pi"},"inventoryContents":{"val":[],"id":"ls"}},"id":"ct"}},"id":"ct"}}
:enddata
:endrule

rule:
plugin=vanillaBlocks
number=13
data:
JSON:{{"val":{"buildPass":{"val":"0","id":"pi"},"blockName":{"val":"minecraft:oak_stairs","id":"ss"},"meta":{"val":"2","id":"pi"}},"id":"ct"}}
:enddata
:endrule

rule:
plugin=vanillaBlocks
number=14
data:
JSON:{{"val":{"buildPass":{"val":"0","id":"pi"},"blockName":{"val":"minecraft:oak_stairs","id":"ss"},"meta":{"val":"4","id":"pi"}},"id":"ct"}}
:enddata
:endrule

rule:
plugin=vanillaBlocks
number=15
data:
JSON:{{"val":{"buildPass":{"val":"0","id":"pi"},"blockName":{"val":"minecraft:planks","id":"ss"},"meta":{"val":"0","id":"pi"}},"id":"ct"}}
:enddata
:endrule

rule:
plugin=vanillaLogic
number=16
data:
JSON:{{"val":{"buildPass":{"val":"0","id":"pi"},"blockName":{"val":"minecraft:furnace","id":"ss"},"meta":{"val":"4","id":"pi"},"teData":{"val":{"CookTime":{"val":"0","id":"ps"},"BurnTime":{"val":"0","id":"ps"},"Items":{"val":[{"val":{"Slot":{"val":"1","id":"pb"},"id":{"val":"263","id":"ps"},"Count":{"val":"4","id":"pb"},"Damage":{"val":"0","id":"ps"}},"id":"ct"}],"id":"ls"},"id":{"val":"Furnace","id":"ss"}},"id":"ct"}},"id":"ct"}}
:enddata
:endrule

rule:
plugin=vanillaLogic
number=17
data:
JSON:{{"val":{"buildPass":{"val":"0","id":"pi"},"blockName":{"val":"exnihilo:crucible","id":"ss"},"meta":{"val":"0","id":"pi"},"teData":{"val":{"mode":{"val":"1","id":"pi"},"contentMeta":{"val":"0","id":"pi"},"solidVolume":{"val":"0.0","id":"pf"},"fluidVolume":{"val":"10000.0","id":"pf"},"fluid":{"val":"1","id":"ps"},"id":{"val":"tile.exnihilo.crucible","id":"ss"},"airVolume":{"val":"0.0","id":"pf"},"content":{"val":"","id":"ss"}},"id":"ct"}},"id":"ct"}}
:enddata
:endrule

rule:
plugin=vanillaInventory
number=18
data:
JSON:{{"val":{"buildPass":{"val":"0","id":"pi"},"blockName":{"val":"minecraft:chest","id":"ss"},"meta":{"val":"5","id":"pi"},"lootLevel":{"val":"0","id":"pi"},"teData":{"val":{"x":{"val":"-195","id":"pi"},"y":{"val":"70","id":"pi"},"z":{"val":"144","id":"pi"},"id":{"val":"Chest","id":"ss"}},"id":"ct"},"inventoryData":{"val":{"length":{"val":"27","id":"pi"},"inventoryContents":{"val":[],"id":"ls"}},"id":"ct"}},"id":"ct"}}
:enddata
:endrule

rule:
plugin=vanillaLogic
number=19
data:
JSON:{{"val":{"buildPass":{"val":"0","id":"pi"},"blockName":{"val":"minecraft:furnace","id":"ss"},"meta":{"val":"4","id":"pi"},"teData":{"val":{"CookTime":{"val":"0","id":"ps"},"BurnTime":{"val":"0","id":"ps"},"Items":{"val":[{"val":{"Slot":{"val":"1","id":"pb"},"id":{"val":"263","id":"ps"},"Count":{"val":"4","id":"pb"},"Damage":{"val":"0","id":"ps"}},"id":"ct"}],"id":"ls"},"id":{"val":"Furnace","id":"ss"}},"id":"ct"}},"id":"ct"}}
:enddata
:endrule

rule:
plugin=vanillaInventory
number=20
data:
JSON:{{"val":{"buildPass":{"val":"0","id":"pi"},"blockName":{"val":"minecraft:chest","id":"ss"},"meta":{"val":"5","id":"pi"},"lootLevel":{"val":"0","id":"pi"},"teData":{"val":{"x":{"val":"-195","id":"pi"},"y":{"val":"70","id":"pi"},"z":{"val":"145","id":"pi"},"id":{"val":"Chest","id":"ss"}},"id":"ct"},"inventoryData":{"val":{"length":{"val":"27","id":"pi"},"inventoryContents":{"val":[],"id":"ls"}},"id":"ct"}},"id":"ct"}}
:enddata
:endrule

rule:
plugin=vanillaBlocks
number=21
data:
JSON:{{"val":{"buildPass":{"val":"0","id":"pi"},"blockName":{"val":"minecraft:crafting_table","id":"ss"},"meta":{"val":"0","id":"pi"}},"id":"ct"}}
:enddata
:endrule

rule:
plugin=vanillaBlocks
number=22
data:
JSON:{{"val":{"buildPass":{"val":"2","id":"pi"},"blockName":{"val":"minecraft:tallgrass","id":"ss"},"meta":{"val":"1","id":"pi"}},"id":"ct"}}
:enddata
:endrule

rule:
plugin=vanillaBlocks
number=23
data:
JSON:{{"val":{"buildPass":{"val":"2","id":"pi"},"blockName":{"val":"minecraft:red_flower","id":"ss"},"meta":{"val":"0","id":"pi"}},"id":"ct"}}
:enddata
:endrule

rule:
plugin=vanillaBlocks
number=24
data:
JSON:{{"val":{"buildPass":{"val":"0","id":"pi"},"blockName":{"val":"minecraft:fence","id":"ss"},"meta":{"val":"0","id":"pi"}},"id":"ct"}}
:enddata
:endrule

rule:
plugin=vanillaBlocks
number=25
data:
JSON:{{"val":{"buildPass":{"val":"0","id":"pi"},"blockName":{"val":"minecraft:fence_gate","id":"ss"},"meta":{"val":"0","id":"pi"}},"id":"ct"}}
:enddata
:endrule

rule:
plugin=vanillaBlocks
number=26
data:
JSON:{{"val":{"buildPass":{"val":"0","id":"pi"},"blockName":{"val":"minecraft:stone_brick_stairs","id":"ss"},"meta":{"val":"2","id":"pi"}},"id":"ct"}}
:enddata
:endrule

rule:
plugin=vanillaBlocks
number=27
data:
JSON:{{"val":{"buildPass":{"val":"0","id":"pi"},"blockName":{"val":"minecraft:stone_brick_stairs","id":"ss"},"meta":{"val":"0","id":"pi"}},"id":"ct"}}
:enddata
:endrule

rule:
plugin=vanillaDoors
number=28
data:
JSON:{{"val":{"buildPass":{"val":"2","id":"pi"},"blockName":{"val":"minecraft:wooden_door","id":"ss"},"meta":{"val":"7","id":"pi"},"sideFlag":{"val":"8","id":"pb"}},"id":"ct"}}
:enddata
:endrule

rule:
plugin=vanillaBlocks
number=29
data:
JSON:{{"val":{"buildPass":{"val":"0","id":"pi"},"blockName":{"val":"minecraft:stone_brick_stairs","id":"ss"},"meta":{"val":"1","id":"pi"}},"id":"ct"}}
:enddata
:endrule

rule:
plugin=vanillaBlocks
number=30
data:
JSON:{{"val":{"buildPass":{"val":"0","id":"pi"},"blockName":{"val":"minecraft:cobblestone_wall","id":"ss"},"meta":{"val":"0","id":"pi"}},"id":"ct"}}
:enddata
:endrule

rule:
plugin=vanillaBlocks
number=31
data:
JSON:{{"val":{"buildPass":{"val":"0","id":"pi"},"blockName":{"val":"minecraft:oak_stairs","id":"ss"},"meta":{"val":"5","id":"pi"}},"id":"ct"}}
:enddata
:endrule

rule:
plugin=vanillaBlocks
number=32
data:
JSON:{{"val":{"buildPass":{"val":"0","id":"pi"},"blockName":{"val":"minecraft:log","id":"ss"},"meta":{"val":"0","id":"pi"}},"id":"ct"}}
:enddata
:endrule

rule:
plugin=vanillaBlocks
number=33
data:
JSON:{{"val":{"buildPass":{"val":"0","id":"pi"},"blockName":{"val":"minecraft:fence_gate","id":"ss"},"meta":{"val":"2","id":"pi"}},"id":"ct"}}
:enddata
:endrule

rule:
plugin=modBlockDefault
number=34
data:
JSON:{{"val":{"blockName":{"val":"BiomesOPlenty:foliage","id":"ss"},"meta":{"val":"10","id":"pi"}},"id":"ct"}}
:enddata
:endrule

rule:
plugin=modBlockDefault
number=35
data:
JSON:{{"val":{"blockName":{"val":"BiomesOPlenty:foliage","id":"ss"},"meta":{"val":"11","id":"pi"}},"id":"ct"}}
:enddata
:endrule

rule:
plugin=modBlockDefault
number=36
data:
JSON:{{"val":{"blockName":{"val":"BiomesOPlenty:foliage","id":"ss"},"meta":{"val":"13","id":"pi"}},"id":"ct"}}
:enddata
:endrule

rule:
plugin=vanillaBlocks
number=37
data:
JSON:{{"val":{"buildPass":{"val":"2","id":"pi"},"blockName":{"val":"minecraft:torch","id":"ss"},"meta":{"val":"5","id":"pi"}},"id":"ct"}}
:enddata
:endrule

rule:
plugin=vanillaDoors
number=38
data:
JSON:{{"val":{"buildPass":{"val":"2","id":"pi"},"blockName":{"val":"minecraft:wooden_door","id":"ss"},"meta":{"val":"8","id":"pi"},"sideFlag":{"val":"0","id":"pb"}},"id":"ct"}}
:enddata
:endrule

rule:
plugin=vanillaBlocks
number=39
data:
JSON:{{"val":{"buildPass":{"val":"2","id":"pi"},"blockName":{"val":"minecraft:torch","id":"ss"},"meta":{"val":"3","id":"pi"}},"id":"ct"}}
:enddata
:endrule

rule:
plugin=vanillaBlocks
number=40
data:
JSON:{{"val":{"buildPass":{"val":"0","id":"pi"},"blockName":{"val":"minecraft:double_wooden_slab","id":"ss"},"meta":{"val":"0","id":"pi"}},"id":"ct"}}
:enddata
:endrule

rule:
plugin=vanillaInventory
number=41
data:
JSON:{{"val":{"buildPass":{"val":"3","id":"pi"},"blockName":{"val":"minecraft:chest","id":"ss"},"meta":{"val":"5","id":"pi"},"lootLevel":{"val":"0","id":"pi"},"teData":{"val":{"x":{"val":"-195","id":"pi"},"y":{"val":"72","id":"pi"},"z":{"val":"145","id":"pi"},"id":{"val":"Chest","id":"ss"}},"id":"ct"},"inventoryData":{"val":{"length":{"val":"27","id":"pi"},"inventoryContents":{"val":[{"val":{"item":{"val":"minecraft:emerald","id":"ss"},"damage":{"val":"0","id":"pi"},"quantity":{"val":"1","id":"pi"},"slot":{"val":"0","id":"pi"}},"id":"ct"}],"id":"ls"}},"id":"ct"},"teData":{"val":{"id":{"val":"Chest","id":"ss"},"z":{"val":"1179","id":"pi"},"y":{"val":"75","id":"pi"},"x":{"val":"1307","id":"pi"}},"id":"ct"},"blockName":{"val":"minecraft:chest","id":"ss"},"meta":{"val":"5","id":"pi"},"buildPass":{"val":"0","id":"pi"}},"id":"ct"}}
:enddata
:endrule

rule:
plugin=vanillaBlocks
number=42
data:
JSON:{{"val":{"buildPass":{"val":"2","id":"pi"},"blockName":{"val":"minecraft:torch","id":"ss"},"meta":{"val":"4","id":"pi"}},"id":"ct"}}
:enddata
:endrule

rule:
plugin=vanillaBlocks
number=43
data:
JSON:{{"val":{"buildPass":{"val":"0","id":"pi"},"blockName":{"val":"minecraft:glass_pane","id":"ss"},"meta":{"val":"0","id":"pi"}},"id":"ct"}}
:enddata
:endrule

rule:
plugin=vanillaBlocks
number=44
data:
JSON:{{"val":{"buildPass":{"val":"0","id":"pi"},"blockName":{"val":"minecraft:stone_stairs","id":"ss"},"meta":{"val":"6","id":"pi"}},"id":"ct"}}
:enddata
:endrule

rule:
plugin=vanillaBlocks
number=45
data:
JSON:{{"val":{"buildPass":{"val":"0","id":"pi"},"blockName":{"val":"minecraft:stone_slab","id":"ss"},"meta":{"val":"11","id":"pi"}},"id":"ct"}}
:enddata
:endrule

rule:
plugin=vanillaSign
number=46
data:
JSON:{{"val":{"signContents0":{"val":"","id":"ss"},"signContents2":{"val":"House","id":"ss"},"buildPass":{"val":"2","id":"pi"},"signContents1":{"val":"Merchants","id":"ss"},"blockName":{"val":"minecraft:wall_sign","id":"ss"},"signContents3":{"val":"","id":"ss"},"meta":{"val":"2","id":"pi"}},"id":"ct"}}
:enddata
:endrule

rule:
plugin=vanillaBlocks
number=47
data:
JSON:{{"val":{"buildPass":{"val":"0","id":"pi"},"blockName":{"val":"minecraft:stone_stairs","id":"ss"},"meta":{"val":"4","id":"pi"}},"id":"ct"}}
:enddata
:endrule

rule:
plugin=vanillaBlocks
number=48
data:
JSON:{{"val":{"buildPass":{"val":"0","id":"pi"},"blockName":{"val":"minecraft:stone_stairs","id":"ss"},"meta":{"val":"5","id":"pi"}},"id":"ct"}}
:enddata
:endrule

rule:
plugin=vanillaBlocks
number=49
data:
JSON:{{"val":{"buildPass":{"val":"0","id":"pi"},"blockName":{"val":"minecraft:wooden_slab","id":"ss"},"meta":{"val":"8","id":"pi"}},"id":"ct"}}
:enddata
:endrule

rule:
plugin=vanillaBlocks
number=50
data:
JSON:{{"val":{"buildPass":{"val":"0","id":"pi"},"blockName":{"val":"minecraft:stone_stairs","id":"ss"},"meta":{"val":"7","id":"pi"}},"id":"ct"}}
:enddata
:endrule

rule:
plugin=vanillaBlocks
number=51
data:
JSON:{{"val":{"buildPass":{"val":"0","id":"pi"},"blockName":{"val":"minecraft:oak_stairs","id":"ss"},"meta":{"val":"0","id":"pi"}},"id":"ct"}}
:enddata
:endrule

rule:
plugin=vanillaBlocks
number=52
data:
JSON:{{"val":{"buildPass":{"val":"0","id":"pi"},"blockName":{"val":"minecraft:oak_stairs","id":"ss"},"meta":{"val":"1","id":"pi"}},"id":"ct"}}
:enddata
:endrule

rule:
plugin=vanillaInventory
number=53
data:
JSON:{{"val":{"buildPass":{"val":"0","id":"pi"},"blockName":{"val":"minecraft:chest","id":"ss"},"meta":{"val":"5","id":"pi"},"lootLevel":{"val":"0","id":"pi"},"teData":{"val":{"x":{"val":"-195","id":"pi"},"y":{"val":"74","id":"pi"},"z":{"val":"140","id":"pi"},"id":{"val":"Chest","id":"ss"}},"id":"ct"},"inventoryData":{"val":{"length":{"val":"27","id":"pi"},"inventoryContents":{"val":[],"id":"ls"}},"id":"ct"}},"id":"ct"}}
:enddata
:endrule

rule:
plugin=vanillaInventory
number=54
data:
JSON:{{"val":{"buildPass":{"val":"0","id":"pi"},"blockName":{"val":"minecraft:chest","id":"ss"},"meta":{"val":"3","id":"pi"},"lootLevel":{"val":"3","id":"pi"},"teData":{"val":{"x":{"val":"-193","id":"pi"},"y":{"val":"74","id":"pi"},"z":{"val":"140","id":"pi"},"id":{"val":"Chest","id":"ss"}},"id":"ct"},"inventoryData":{"val":{"length":{"val":"27","id":"pi"},"inventoryContents":{"val":[{"val":{"item":{"val":"minecraft:gold_ingot","id":"ss"},"damage":{"val":"0","id":"pi"},"quantity":{"val":"1","id":"pi"},"slot":{"val":"0","id":"pi"}},"id":"ct"}],"id":"ls"}},"id":"ct"},"teData":{"val":{"id":{"val":"Chest","id":"ss"},"z":{"val":"1174","id":"pi"},"y":{"val":"77","id":"pi"},"x":{"val":"1309","id":"pi"}},"id":"ct"},"blockName":{"val":"minecraft:chest","id":"ss"},"meta":{"val":"3","id":"pi"},"buildPass":{"val":"0","id":"pi"}},"id":"ct"}}
:enddata
:endrule

rule:
plugin=vanillaBlocks
number=55
data:
JSON:{{"val":{"buildPass":{"val":"0","id":"pi"},"blockName":{"val":"minecraft:bookshelf","id":"ss"},"meta":{"val":"0","id":"pi"}},"id":"ct"}}
:enddata
:endrule

rule:
plugin=vanillaBlocks
number=56
data:
JSON:{{"val":{"buildPass":{"val":"2","id":"pi"},"blockName":{"val":"minecraft:bed","id":"ss"},"meta":{"val":"3","id":"pi"}},"id":"ct"}}
:enddata
:endrule

rule:
plugin=vanillaBlocks
number=57
data:
JSON:{{"val":{"buildPass":{"val":"2","id":"pi"},"blockName":{"val":"minecraft:bed","id":"ss"},"meta":{"val":"11","id":"pi"}},"id":"ct"}}
:enddata
:endrule

rule:
plugin=vanillaBlocks
number=58
data:
JSON:{{"val":{"buildPass":{"val":"2","id":"pi"},"blockName":{"val":"minecraft:torch","id":"ss"},"meta":{"val":"1","id":"pi"}},"id":"ct"}}
:enddata
:endrule

rule:
plugin=vanillaBlocks
number=59
data:
JSON:{{"val":{"buildPass":{"val":"0","id":"pi"},"blockName":{"val":"minecraft:oak_stairs","id":"ss"},"meta":{"val":"3","id":"pi"}},"id":"ct"}}
:enddata
:endrule

rule:
plugin=vanillaBlocks
number=60
data:
JSON:{{"val":{"buildPass":{"val":"0","id":"pi"},"blockName":{"val":"minecraft:oak_stairs","id":"ss"},"meta":{"val":"6","id":"pi"}},"id":"ct"}}
:enddata
:endrule

rule:
plugin=vanillaBlocks
number=61
data:
JSON:{{"val":{"buildPass":{"val":"0","id":"pi"},"blockName":{"val":"minecraft:oak_stairs","id":"ss"},"meta":{"val":"7","id":"pi"}},"id":"ct"}}
:enddata
:endrule

rule:
plugin=vanillaBlocks
number=62
data:
JSON:{{"val":{"buildPass":{"val":"0","id":"pi"},"blockName":{"val":"minecraft:wooden_slab","id":"ss"},"meta":{"val":"0","id":"pi"}},"id":"ct"}}
:enddata
:endrule

rule:
plugin=vanillaBlocks
number=63
data:
JSON:{{"val":{"buildPass":{"val":"0","id":"pi"},"blockName":{"val":"minecraft:log","id":"ss"},"meta":{"val":"4","id":"pi"}},"id":"ct"}}
:enddata
:endrule

rule:
plugin=vanillaBlocks
number=64
data:
JSON:{{"val":{"buildPass":{"val":"0","id":"pi"},"blockName":{"val":"minecraft:log","id":"ss"},"meta":{"val":"8","id":"pi"}},"id":"ct"}}
:enddata
:endrule

rule:
plugin=vanillaInventory
number=65
data:
JSON:{{"val":{"buildPass":{"val":"0","id":"pi"},"blockName":{"val":"minecraft:chest","id":"ss"},"meta":{"val":"2","id":"pi"},"lootLevel":{"val":"0","id":"pi"},"teData":{"val":{"x":{"val":"-193","id":"pi"},"y":{"val":"77","id":"pi"},"z":{"val":"145","id":"pi"},"id":{"val":"Chest","id":"ss"}},"id":"ct"},"inventoryData":{"val":{"length":{"val":"27","id":"pi"},"inventoryContents":{"val":[],"id":"ls"}},"id":"ct"}},"id":"ct"}}
:enddata
:endrule

rule:
plugin=vanillaBlocks
number=66
data:
JSON:{{"val":{"buildPass":{"val":"0","id":"pi"},"blockName":{"val":"minecraft:glass","id":"ss"},"meta":{"val":"0","id":"pi"}},"id":"ct"}}
:enddata
:endrule

#### ENTITIES ####
entity:
plugin=AWNpc
number=0
data:
position=6,10,8
JSON:{{"val":{"xOffset":{"val":"0.3","id":"pf"},"equipmentData":{"val":{"length":{"val":"5","id":"pi"},"equipmentContents":{"val":[{"val":{"damage":{"val":"0","id":"pi"},"item":{"val":"minecraft:diamond_sword","id":"ss"},"quantity":{"val":"1","id":"pi"},"slot":{"val":"0","id":"pi"}},"id":"ct"},{"val":{"damage":{"val":"0","id":"pi"},"item":{"val":"minecraft:chainmail_boots","id":"ss"},"quantity":{"val":"1","id":"pi"},"slot":{"val":"1","id":"pi"}},"id":"ct"},{"val":{"damage":{"val":"0","id":"pi"},"item":{"val":"minecraft:chainmail_leggings","id":"ss"},"quantity":{"val":"1","id":"pi"},"slot":{"val":"2","id":"pi"}},"id":"ct"},{"val":{"damage":{"val":"0","id":"pi"},"item":{"val":"minecraft:chainmail_chestplate","id":"ss"},"quantity":{"val":"1","id":"pi"},"slot":{"val":"3","id":"pi"}},"id":"ct"}],"id":"ls"}},"id":"ct"},"rotation":{"val":"6.1595793","id":"pf"},"mobID":{"val":"AncientWarfareNpc.custom_3.leader","id":"ss"},"zOffset":{"val":"0.3302015","id":"pf"},"entityData":{"val":{"bedDirection":{"val":"0","id":"pi"},"ForgeData":{"val":{"MP|Init":{"val":"1","id":"pb"},"ESM_MODIFIED":{"val":"1","id":"pb"},"sAI":{"val":{"Fiddling":{"val":"0","id":"pb"},"AvoidExplosions":{"val":"1","id":"pb"},"DefendVillage":{"val":"0","id":"pb"},"Griefing":{"val":"0","id":"pb"},"uAI":{"val":{},"id":"ct"},"Rider":{"val":"0","id":"pb"}},"id":"ct"},"ORIGINAL_SPAWN_POS":{"val":["-192","77","143"],"id":"ai"}},"id":"ct"},"Attributes":{"val":[{"val":{"Base":{"val":"80.0","id":"pd"},"Modifiers":{"val":[{"val":{"UUIDMost":{"val":"975508744037082","id":"pl"},"UUIDLeast":{"val":"-5808302152317363023","id":"pl"},"Amount":{"val":"0.0","id":"pd"},"Operation":{"val":"1","id":"pi"},"Name":{"val":"ESM_TWEAK_1","id":"ss"}},"id":"ct"}],"id":"ls"},"Name":{"val":"generic.maxHealth","id":"ss"}},"id":"ct"},{"val":{"Base":{"val":"0.0","id":"pd"},"Modifiers":{"val":[{"val":{"UUIDMost":{"val":"975508744042504","id":"pl"},"UUIDLeast":{"val":"-7957234151486806740","id":"pl"},"Amount":{"val":"0.0","id":"pd"},"Operation":{"val":"1","id":"pi"},"Name":{"val":"ESM_TWEAK_4","id":"ss"}},"id":"ct"}],"id":"ls"},"Name":{"val":"generic.knockbackResistance","id":"ss"}},"id":"ct"},{"val":{"Base":{"val":"0.325","id":"pd"},"Modifiers":{"val":[{"val":{"UUIDMost":{"val":"975508744041299","id":"pl"},"UUIDLeast":{"val":"-8894256512251485951","id":"pl"},"Amount":{"val":"0.0","id":"pd"},"Operation":{"val":"1","id":"pi"},"Name":{"val":"ESM_TWEAK_2","id":"ss"}},"id":"ct"}],"id":"ls"},"Name":{"val":"generic.movementSpeed","id":"ss"}},"id":"ct"},{"val":{"Base":{"val":"60.0","id":"pd"},"Name":{"val":"generic.followRange","id":"ss"}},"id":"ct"},{"val":{"Base":{"val":"1.0","id":"pd"},"Modifiers":{"val":[{"val":{"UUIDMost":{"val":"975508744041902","id":"pl"},"UUIDLeast":{"val":"-3029140739374235485","id":"pl"},"Amount":{"val":"0.0","id":"pd"},"Operation":{"val":"1","id":"pi"},"Name":{"val":"ESM_TWEAK_3","id":"ss"}},"id":"ct"}],"id":"ls"},"Name":{"val":"generic.attackDamage","id":"ss"}},"id":"ct"}],"id":"ls"},"Invulnerable":{"val":"0","id":"pb"},"PortalCooldown":{"val":"0","id":"pi"},"AbsorptionAmount":{"val":"0.0","id":"pf"},"FallDistance":{"val":"0.0","id":"pf"},"levelingStats":{"val":{"level":{"val":"0","id":"pi"},"xp":{"val":"0","id":"pi"},"entryList":{"val":[],"id":"ls"}},"id":"ct"},"DeathTime":{"val":"0","id":"ps"},"DropChances":{"val":[{"val":"1.0","id":"pf"},{"val":"1.0","id":"pf"},{"val":"1.0","id":"pf"},{"val":"1.0","id":"pf"},{"val":"1.0","id":"pf"}],"id":"ls"},"PersistenceRequired":{"val":"1","id":"pb"},"maxHealth":{"val":"80.0","id":"pf"},"HealF":{"val":"80.0","id":"pf"},"owner":{"val":"Dulciphi","id":"ss"},"Motion":{"val":[{"val":"0.0","id":"pd"},{"val":"-0.0784000015258789","id":"pd"},{"val":"0.0","id":"pd"}],"id":"ls"},"armorValueOverride":{"val":"-1","id":"pi"},"Leashed":{"val":"0","id":"pb"},"Health":{"val":"80","id":"ps"},"aiEnabled":{"val":"0","id":"pb"},"isSleeping":{"val":"0","id":"pb"},"health":{"val":"80.0","id":"pf"},"Air":{"val":"300","id":"ps"},"OnGround":{"val":"1","id":"pb"},"Dimension":{"val":"0","id":"pi"},"bedPos":{"val":["0","0","0"],"id":"ai"},"Rotation":{"val":[{"val":"6.1595793","id":"pf"},{"val":"0.0","id":"pf"}],"id":"ls"},"food":{"val":"0","id":"pi"},"home":{"val":["-193","77","143","5"],"id":"ai"},"foundBed":{"val":"0","id":"pb"},"CustomName":{"val":"","id":"ss"},"Pos":{"val":[{"val":"-194.69999998807907","id":"pd"},{"val":"77.0","id":"pd"},{"val":"141.33020149339092","id":"pd"}],"id":"ls"},"Fire":{"val":"-1","id":"ps"},"attackDamageOverride":{"val":"-1","id":"pi"},"customTex":{"val":"","id":"ss"},"CanPickUpLoot":{"val":"0","id":"pb"},"HurtTime":{"val":"0","id":"ps"},"AttackTime":{"val":"0","id":"ps"},"CustomNameVisible":{"val":"0","id":"pb"}},"id":"ct"}},"id":"ct"}}
:enddata
:endentity

entity:
plugin=AWNpc
number=1
data:
position=4,4,16
JSON:{{"val":{"xOffset":{"val":"0.6489815","id":"pf"},"equipmentData":{"val":{"length":{"val":"5","id":"pi"},"equipmentContents":{"val":[{"val":{"damage":{"val":"0","id":"pi"},"item":{"val":"minecraft:bow","id":"ss"},"quantity":{"val":"1","id":"pi"},"slot":{"val":"0","id":"pi"}},"id":"ct"}],"id":"ls"}},"id":"ct"},"rotation":{"val":"1.3370653","id":"pf"},"mobID":{"val":"AncientWarfareNpc.custom_3.archer.elite","id":"ss"},"zOffset":{"val":"0.42314637","id":"pf"},"entityData":{"val":{"bedDirection":{"val":"0","id":"pi"},"ForgeData":{"val":{"MP|Init":{"val":"1","id":"pb"},"ESM_MODIFIED":{"val":"1","id":"pb"},"WITCInitialWidth":{"val":"0.6","id":"pf"},"sAI":{"val":{"Fiddling":{"val":"0","id":"pb"},"AvoidExplosions":{"val":"1","id":"pb"},"DefendVillage":{"val":"0","id":"pb"},"Griefing":{"val":"0","id":"pb"},"uAI":{"val":{},"id":"ct"},"Rider":{"val":"0","id":"pb"}},"id":"ct"},"ORIGINAL_SPAWN_POS":{"val":["-196","71","149"],"id":"ai"},"WITCInitialHeight":{"val":"1.8","id":"pf"},"HungerOverhaulCheck":{"val":"2","id":"pi"}},"id":"ct"},"Attributes":{"val":[{"val":{"Base":{"val":"30.0","id":"pd"},"Modifiers":{"val":[{"val":{"UUIDMost":{"val":"975309863753966","id":"pl"},"UUIDLeast":{"val":"7246094970497479734","id":"pl"},"Amount":{"val":"0.0","id":"pd"},"Operation":{"val":"1","id":"pi"},"Name":{"val":"ESM_TWEAK_1","id":"ss"}},"id":"ct"}],"id":"ls"},"Name":{"val":"generic.maxHealth","id":"ss"}},"id":"ct"},{"val":{"Base":{"val":"0.0","id":"pd"},"Modifiers":{"val":[{"val":{"UUIDMost":{"val":"975309863756075","id":"pl"},"UUIDLeast":{"val":"4488635632444445003","id":"pl"},"Amount":{"val":"0.0","id":"pd"},"Operation":{"val":"1","id":"pi"},"Name":{"val":"ESM_TWEAK_4","id":"ss"}},"id":"ct"}],"id":"ls"},"Name":{"val":"generic.knockbackResistance","id":"ss"}},"id":"ct"},{"val":{"Base":{"val":"0.325","id":"pd"},"Modifiers":{"val":[{"val":{"UUIDMost":{"val":"975309863755171","id":"pl"},"UUIDLeast":{"val":"1798802831565387168","id":"pl"},"Amount":{"val":"0.0","id":"pd"},"Operation":{"val":"1","id":"pi"},"Name":{"val":"ESM_TWEAK_2","id":"ss"}},"id":"ct"}],"id":"ls"},"Name":{"val":"generic.movementSpeed","id":"ss"}},"id":"ct"},{"val":{"Base":{"val":"60.0","id":"pd"},"Name":{"val":"generic.followRange","id":"ss"}},"id":"ct"},{"val":{"Base":{"val":"1.0","id":"pd"},"Modifiers":{"val":[{"val":{"UUIDMost":{"val":"975309863755773","id":"pl"},"UUIDLeast":{"val":"-2444255847393709892","id":"pl"},"Amount":{"val":"0.0","id":"pd"},"Operation":{"val":"1","id":"pi"},"Name":{"val":"ESM_TWEAK_3","id":"ss"}},"id":"ct"}],"id":"ls"},"Name":{"val":"generic.attackDamage","id":"ss"}},"id":"ct"}],"id":"ls"},"Invulnerable":{"val":"0","id":"pb"},"PortalCooldown":{"val":"0","id":"pi"},"AbsorptionAmount":{"val":"0.0","id":"pf"},"FallDistance":{"val":"0.0","id":"pf"},"levelingStats":{"val":{"level":{"val":"0","id":"pi"},"xp":{"val":"0","id":"pi"},"entryList":{"val":[],"id":"ls"}},"id":"ct"},"DeathTime":{"val":"0","id":"ps"},"DropChances":{"val":[{"val":"1.0","id":"pf"},{"val":"1.0","id":"pf"},{"val":"1.0","id":"pf"},{"val":"1.0","id":"pf"},{"val":"1.0","id":"pf"}],"id":"ls"},"ordersStack":{"val":{"damage":{"val":"0","id":"pi"},"item":{"val":"minecraft:bow","id":"ss"},"quantity":{"val":"1","id":"pi"}},"id":"ct"},"PersistenceRequired":{"val":"1","id":"pb"},"maxHealth":{"val":"30.0","id":"pf"},"HealF":{"val":"30.0","id":"pf"},"upkeepStack":{"val":{"damage":{"val":"0","id":"pi"},"item":{"val":"minecraft:arrow","id":"ss"},"quantity":{"val":"1","id":"pi"}},"id":"ct"},"owner":{"val":"OldMiniCollector","id":"ss"},"Motion":{"val":[{"val":"0.0","id":"pd"},{"val":"-0.0784000015258789","id":"pd"},{"val":"0.0","id":"pd"}],"id":"ls"},"armorValueOverride":{"val":"-1","id":"pi"},"Leashed":{"val":"0","id":"pb"},"Health":{"val":"30","id":"ps"},"aiEnabled":{"val":"1","id":"pb"},"isSleeping":{"val":"0","id":"pb"},"health":{"val":"30.0","id":"pf"},"Air":{"val":"300","id":"ps"},"OnGround":{"val":"1","id":"pb"},"Dimension":{"val":"0","id":"pi"},"bedPos":{"val":["0","0","0"],"id":"ai"},"Rotation":{"val":[{"val":"1.3370653","id":"pf"},{"val":"0.0","id":"pf"}],"id":"ls"},"food":{"val":"0","id":"pi"},"home":{"val":["-197","71","149","5"],"id":"ai"},"foundBed":{"val":"0","id":"pb"},"CustomName":{"val":"","id":"ss"},"Pos":{"val":[{"val":"-196.35101848158365","id":"pd"},{"val":"71.0","id":"pd"},{"val":"149.4231463617835","id":"pd"}],"id":"ls"},"Fire":{"val":"-1","id":"ps"},"attackDamageOverride":{"val":"-1","id":"pi"},"customTex":{"val":"","id":"ss"},"CanPickUpLoot":{"val":"0","id":"pb"},"HurtTime":{"val":"0","id":"ps"},"AttackTime":{"val":"0","id":"ps"},"CustomNameVisible":{"val":"0","id":"pb"}},"id":"ct"}},"id":"ct"}}
:enddata
:endentity

entity:
plugin=AWNpc
number=2
data:
position=5,4,16
JSON:{{"val":{"xOffset":{"val":"0.61432445","id":"pf"},"equipmentData":{"val":{"length":{"val":"5","id":"pi"},"equipmentContents":{"val":[{"val":{"damage":{"val":"0","id":"pi"},"item":{"val":"minecraft:bow","id":"ss"},"quantity":{"val":"1","id":"pi"},"slot":{"val":"0","id":"pi"}},"id":"ct"}],"id":"ls"}},"id":"ct"},"rotation":{"val":"3.8734722","id":"pf"},"mobID":{"val":"AncientWarfareNpc.custom_3.archer.elite","id":"ss"},"zOffset":{"val":"0.69298464","id":"pf"},"entityData":{"val":{"bedDirection":{"val":"0","id":"pi"},"ForgeData":{"val":{"MP|Init":{"val":"1","id":"pb"},"ESM_MODIFIED":{"val":"1","id":"pb"},"WITCInitialWidth":{"val":"0.6","id":"pf"},"sAI":{"val":{"Fiddling":{"val":"0","id":"pb"},"AvoidExplosions":{"val":"1","id":"pb"},"DefendVillage":{"val":"0","id":"pb"},"Griefing":{"val":"0","id":"pb"},"uAI":{"val":{},"id":"ct"},"Rider":{"val":"0","id":"pb"}},"id":"ct"},"ORIGINAL_SPAWN_POS":{"val":["-195","71","149"],"id":"ai"},"WITCInitialHeight":{"val":"1.8","id":"pf"},"HungerOverhaulCheck":{"val":"2","id":"pi"}},"id":"ct"},"Attributes":{"val":[{"val":{"Base":{"val":"30.0","id":"pd"},"Modifiers":{"val":[{"val":{"UUIDMost":{"val":"975309864114880","id":"pl"},"UUIDLeast":{"val":"4440042789134558086","id":"pl"},"Amount":{"val":"0.0","id":"pd"},"Operation":{"val":"1","id":"pi"},"Name":{"val":"ESM_TWEAK_1","id":"ss"}},"id":"ct"}],"id":"ls"},"Name":{"val":"generic.maxHealth","id":"ss"}},"id":"ct"},{"val":{"Base":{"val":"0.0","id":"pd"},"Modifiers":{"val":[{"val":{"UUIDMost":{"val":"975309864117290","id":"pl"},"UUIDLeast":{"val":"-1013308957410457479","id":"pl"},"Amount":{"val":"0.0","id":"pd"},"Operation":{"val":"1","id":"pi"},"Name":{"val":"ESM_TWEAK_4","id":"ss"}},"id":"ct"}],"id":"ls"},"Name":{"val":"generic.knockbackResistance","id":"ss"}},"id":"ct"},{"val":{"Base":{"val":"0.325","id":"pd"},"Modifiers":{"val":[{"val":{"UUIDMost":{"val":"975309864116085","id":"pl"},"UUIDLeast":{"val":"2234991806728024139","id":"pl"},"Amount":{"val":"0.0","id":"pd"},"Operation":{"val":"1","id":"pi"},"Name":{"val":"ESM_TWEAK_2","id":"ss"}},"id":"ct"}],"id":"ls"},"Name":{"val":"generic.movementSpeed","id":"ss"}},"id":"ct"},{"val":{"Base":{"val":"60.0","id":"pd"},"Name":{"val":"generic.followRange","id":"ss"}},"id":"ct"},{"val":{"Base":{"val":"1.0","id":"pd"},"Modifiers":{"val":[{"val":{"UUIDMost":{"val":"975309864116989","id":"pl"},"UUIDLeast":{"val":"5260044580915939748","id":"pl"},"Amount":{"val":"0.0","id":"pd"},"Operation":{"val":"1","id":"pi"},"Name":{"val":"ESM_TWEAK_3","id":"ss"}},"id":"ct"}],"id":"ls"},"Name":{"val":"generic.attackDamage","id":"ss"}},"id":"ct"}],"id":"ls"},"Invulnerable":{"val":"0","id":"pb"},"PortalCooldown":{"val":"0","id":"pi"},"AbsorptionAmount":{"val":"0.0","id":"pf"},"FallDistance":{"val":"0.0","id":"pf"},"levelingStats":{"val":{"level":{"val":"0","id":"pi"},"xp":{"val":"0","id":"pi"},"entryList":{"val":[],"id":"ls"}},"id":"ct"},"DeathTime":{"val":"0","id":"ps"},"DropChances":{"val":[{"val":"1.0","id":"pf"},{"val":"1.0","id":"pf"},{"val":"1.0","id":"pf"},{"val":"1.0","id":"pf"},{"val":"1.0","id":"pf"}],"id":"ls"},"ordersStack":{"val":{"damage":{"val":"0","id":"pi"},"item":{"val":"minecraft:bow","id":"ss"},"quantity":{"val":"1","id":"pi"}},"id":"ct"},"PersistenceRequired":{"val":"1","id":"pb"},"maxHealth":{"val":"30.0","id":"pf"},"HealF":{"val":"30.0","id":"pf"},"upkeepStack":{"val":{"damage":{"val":"0","id":"pi"},"item":{"val":"minecraft:arrow","id":"ss"},"quantity":{"val":"1","id":"pi"}},"id":"ct"},"owner":{"val":"OldMiniCollector","id":"ss"},"Motion":{"val":[{"val":"0.0","id":"pd"},{"val":"-0.0784000015258789","id":"pd"},{"val":"0.0","id":"pd"}],"id":"ls"},"armorValueOverride":{"val":"-1","id":"pi"},"Leashed":{"val":"0","id":"pb"},"Health":{"val":"30","id":"ps"},"aiEnabled":{"val":"1","id":"pb"},"isSleeping":{"val":"0","id":"pb"},"health":{"val":"30.0","id":"pf"},"Air":{"val":"300","id":"ps"},"OnGround":{"val":"1","id":"pb"},"Dimension":{"val":"0","id":"pi"},"bedPos":{"val":["0","0","0"],"id":"ai"},"Rotation":{"val":[{"val":"3.8734722","id":"pf"},{"val":"0.0","id":"pf"}],"id":"ls"},"food":{"val":"0","id":"pi"},"home":{"val":["-196","71","149","5"],"id":"ai"},"foundBed":{"val":"0","id":"pb"},"CustomName":{"val":"","id":"ss"},"Pos":{"val":[{"val":"-195.38567556137124","id":"pd"},{"val":"71.0","id":"pd"},{"val":"149.69298463206286","id":"pd"}],"id":"ls"},"Fire":{"val":"-1","id":"ps"},"attackDamageOverride":{"val":"-1","id":"pi"},"customTex":{"val":"","id":"ss"},"CanPickUpLoot":{"val":"0","id":"pb"},"HurtTime":{"val":"0","id":"ps"},"AttackTime":{"val":"0","id":"ps"},"CustomNameVisible":{"val":"0","id":"pb"}},"id":"ct"}},"id":"ct"}}
:enddata
:endentity

entity:
plugin=AWNpc
number=3
data:
position=8,3,12
JSON:{{"val":{"xOffset":{"val":"0.4987228","id":"pf"},"equipmentData":{"val":{"length":{"val":"5","id":"pi"},"equipmentContents":{"val":[],"id":"ls"}},"id":"ct"},"rotation":{"val":"-0.115356445","id":"pf"},"mobID":{"val":"AncientWarfareNpc.custom_3.soldier","id":"ss"},"zOffset":{"val":"0.0119293","id":"pf"},"entityData":{"val":{"bedDirection":{"val":"0","id":"pi"},"ForgeData":{"val":{"MP|Init":{"val":"1","id":"pb"},"ESM_MODIFIED":{"val":"1","id":"pb"},"WITCInitialWidth":{"val":"0.6","id":"pf"},"sAI":{"val":{"Fiddling":{"val":"0","id":"pb"},"AvoidExplosions":{"val":"1","id":"pb"},"DefendVillage":{"val":"0","id":"pb"},"Griefing":{"val":"0","id":"pb"},"uAI":{"val":{},"id":"ct"},"Rider":{"val":"0","id":"pb"}},"id":"ct"},"ORIGINAL_SPAWN_POS":{"val":["-193","71","149"],"id":"ai"},"WITCInitialHeight":{"val":"1.8","id":"pf"},"HungerOverhaulCheck":{"val":"2","id":"pi"}},"id":"ct"},"Attributes":{"val":[{"val":{"Base":{"val":"20.0","id":"pd"},"Modifiers":{"val":[{"val":{"UUIDMost":{"val":"975309863150835","id":"pl"},"UUIDLeast":{"val":"9132463152882637877","id":"pl"},"Amount":{"val":"0.0","id":"pd"},"Operation":{"val":"1","id":"pi"},"Name":{"val":"ESM_TWEAK_1","id":"ss"}},"id":"ct"}],"id":"ls"},"Name":{"val":"generic.maxHealth","id":"ss"}},"id":"ct"},{"val":{"Base":{"val":"0.0","id":"pd"},"Modifiers":{"val":[{"val":{"UUIDMost":{"val":"975309863154450","id":"pl"},"UUIDLeast":{"val":"5636971196659646800","id":"pl"},"Amount":{"val":"0.0","id":"pd"},"Operation":{"val":"1","id":"pi"},"Name":{"val":"ESM_TWEAK_4","id":"ss"}},"id":"ct"}],"id":"ls"},"Name":{"val":"generic.knockbackResistance","id":"ss"}},"id":"ct"},{"val":{"Base":{"val":"0.325","id":"pd"},"Modifiers":{"val":[{"val":{"UUIDMost":{"val":"975309863153547","id":"pl"},"UUIDLeast":{"val":"-7245771823143774867","id":"pl"},"Amount":{"val":"0.0","id":"pd"},"Operation":{"val":"1","id":"pi"},"Name":{"val":"ESM_TWEAK_2","id":"ss"}},"id":"ct"}],"id":"ls"},"Name":{"val":"generic.movementSpeed","id":"ss"}},"id":"ct"},{"val":{"Base":{"val":"60.0","id":"pd"},"Name":{"val":"generic.followRange","id":"ss"}},"id":"ct"},{"val":{"Base":{"val":"1.0","id":"pd"},"Modifiers":{"val":[{"val":{"UUIDMost":{"val":"975309863153848","id":"pl"},"UUIDLeast":{"val":"2364016383947654494","id":"pl"},"Amount":{"val":"0.0","id":"pd"},"Operation":{"val":"1","id":"pi"},"Name":{"val":"ESM_TWEAK_3","id":"ss"}},"id":"ct"}],"id":"ls"},"Name":{"val":"generic.attackDamage","id":"ss"}},"id":"ct"}],"id":"ls"},"Invulnerable":{"val":"0","id":"pb"},"PortalCooldown":{"val":"0","id":"pi"},"AbsorptionAmount":{"val":"0.0","id":"pf"},"FallDistance":{"val":"0.0","id":"pf"},"levelingStats":{"val":{"level":{"val":"0","id":"pi"},"xp":{"val":"0","id":"pi"},"entryList":{"val":[],"id":"ls"}},"id":"ct"},"DeathTime":{"val":"0","id":"ps"},"DropChances":{"val":[{"val":"1.0","id":"pf"},{"val":"1.0","id":"pf"},{"val":"1.0","id":"pf"},{"val":"1.0","id":"pf"},{"val":"1.0","id":"pf"}],"id":"ls"},"PersistenceRequired":{"val":"1","id":"pb"},"maxHealth":{"val":"20.0","id":"pf"},"HealF":{"val":"20.0","id":"pf"},"owner":{"val":"OldMiniCollector","id":"ss"},"Motion":{"val":[{"val":"0.0","id":"pd"},{"val":"-0.0784000015258789","id":"pd"},{"val":"0.0","id":"pd"}],"id":"ls"},"armorValueOverride":{"val":"-1","id":"pi"},"Leashed":{"val":"0","id":"pb"},"Health":{"val":"20","id":"ps"},"aiEnabled":{"val":"1","id":"pb"},"isSleeping":{"val":"0","id":"pb"},"health":{"val":"20.0","id":"pf"},"Air":{"val":"300","id":"ps"},"OnGround":{"val":"1","id":"pb"},"Dimension":{"val":"0","id":"pi"},"bedPos":{"val":["0","0","0"],"id":"ai"},"Rotation":{"val":[{"val":"-1800.1154","id":"pf"},{"val":"-10.3093815","id":"pf"}],"id":"ls"},"food":{"val":"0","id":"pi"},"home":{"val":["-194","71","149","5"],"id":"ai"},"foundBed":{"val":"0","id":"pb"},"CustomName":{"val":"","id":"ss"},"Pos":{"val":[{"val":"-192.50127721244678","id":"pd"},{"val":"70.0","id":"pd"},{"val":"145.01192929930573","id":"pd"}],"id":"ls"},"Fire":{"val":"-1","id":"ps"},"attackDamageOverride":{"val":"-1","id":"pi"},"customTex":{"val":"","id":"ss"},"CanPickUpLoot":{"val":"0","id":"pb"},"HurtTime":{"val":"0","id":"ps"},"AttackTime":{"val":"0","id":"ps"},"CustomNameVisible":{"val":"0","id":"pb"}},"id":"ct"}},"id":"ct"}}
:enddata
:endentity

entity:
plugin=vanillaLogicEntity
number=4
data:
position=2,4,17
JSON:{{"val":{"xOffset":{"val":"0.5276022","id":"pf"},"equipmentData":{"val":{"length":{"val":"5","id":"pi"},"equipmentContents":{"val":[],"id":"ls"}},"id":"ct"},"rotation":{"val":"4.5045166","id":"pf"},"mobID":{"val":"Villager","id":"ss"},"zOffset":{"val":"0.27062204","id":"pf"},"entityData":{"val":{"ForgeData":{"val":{"MP|Init":{"val":"1","id":"pb"},"ESM_MODIFIED":{"val":"1","id":"pb"},"WITCInitialWidth":{"val":"0.6","id":"pf"},"sAI":{"val":{"Fiddling":{"val":"0","id":"pb"},"AvoidExplosions":{"val":"1","id":"pb"},"DefendVillage":{"val":"1","id":"pb"},"Griefing":{"val":"0","id":"pb"},"uAI":{"val":{},"id":"ct"},"Rider":{"val":"0","id":"pb"}},"id":"ct"},"ORIGINAL_SPAWN_POS":{"val":["-192","71","139"],"id":"ai"},"WITCInitialHeight":{"val":"1.8","id":"pf"},"HungerOverhaulCheck":{"val":"2","id":"pi"}},"id":"ct"},"Attributes":{"val":[{"val":{"Base":{"val":"20.0","id":"pd"},"Modifiers":{"val":[{"val":{"UUIDMost":{"val":"975309864328476","id":"pl"},"UUIDLeast":{"val":"-55533830962244620","id":"pl"},"Amount":{"val":"0.0","id":"pd"},"Operation":{"val":"1","id":"pi"},"Name":{"val":"ESM_TWEAK_1","id":"ss"}},"id":"ct"}],"id":"ls"},"Name":{"val":"generic.maxHealth","id":"ss"}},"id":"ct"},{"val":{"Base":{"val":"0.0","id":"pd"},"Modifiers":{"val":[{"val":{"UUIDMost":{"val":"975309864329982","id":"pl"},"UUIDLeast":{"val":"1660668064674696058","id":"pl"},"Amount":{"val":"0.0","id":"pd"},"Operation":{"val":"1","id":"pi"},"Name":{"val":"ESM_TWEAK_4","id":"ss"}},"id":"ct"}],"id":"ls"},"Name":{"val":"generic.knockbackResistance","id":"ss"}},"id":"ct"},{"val":{"Base":{"val":"0.5","id":"pd"},"Modifiers":{"val":[{"val":{"UUIDMost":{"val":"975309864329681","id":"pl"},"UUIDLeast":{"val":"-4350006475330952208","id":"pl"},"Amount":{"val":"0.0","id":"pd"},"Operation":{"val":"1","id":"pi"},"Name":{"val":"ESM_TWEAK_2","id":"ss"}},"id":"ct"}],"id":"ls"},"Name":{"val":"generic.movementSpeed","id":"ss"}},"id":"ct"},{"val":{"Base":{"val":"32.0","id":"pd"},"Modifiers":{"val":[{"val":{"UUIDMost":{"val":"357715359752059","id":"pl"},"UUIDLeast":{"val":"7310125783540251311","id":"pl"},"Amount":{"val":"-0.01333415566538001","id":"pd"},"Operation":{"val":"1","id":"pi"},"Name":{"val":"Random spawn bonus","id":"ss"}},"id":"ct"}],"id":"ls"},"Name":{"val":"generic.followRange","id":"ss"}},"id":"ct"}],"id":"ls"},"Riches":{"val":"0","id":"pi"},"Invulnerable":{"val":"0","id":"pb"},"PortalCooldown":{"val":"0","id":"pi"},"AbsorptionAmount":{"val":"0.0","id":"pf"},"FallDistance":{"val":"0.0","id":"pf"},"DeathTime":{"val":"0","id":"ps"},"DropChances":{"val":[{"val":"0.085","id":"pf"},{"val":"0.085","id":"pf"},{"val":"0.085","id":"pf"},{"val":"0.085","id":"pf"},{"val":"0.085","id":"pf"}],"id":"ls"},"PersistenceRequired":{"val":"0","id":"pb"},"HealF":{"val":"20.0","id":"pf"},"Age":{"val":"0","id":"pi"},"Motion":{"val":[{"val":"0.0","id":"pd"},{"val":"-0.0784000015258789","id":"pd"},{"val":"0.0","id":"pd"}],"id":"ls"},"Leashed":{"val":"0","id":"pb"},"Health":{"val":"20","id":"ps"},"Air":{"val":"300","id":"ps"},"OnGround":{"val":"1","id":"pb"},"Dimension":{"val":"0","id":"pi"},"Rotation":{"val":[{"val":"364.50452","id":"pf"},{"val":"0.0","id":"pf"}],"id":"ls"},"Profession":{"val":"1","id":"pi"},"CustomName":{"val":"","id":"ss"},"Pos":{"val":[{"val":"-198.47239777783642","id":"pd"},{"val":"71.0","id":"pd"},{"val":"150.2706220479483","id":"pd"}],"id":"ls"},"Fire":{"val":"-1","id":"ps"},"CanPickUpLoot":{"val":"0","id":"pb"},"HurtTime":{"val":"0","id":"ps"},"AttackTime":{"val":"0","id":"ps"},"CustomNameVisible":{"val":"0","id":"pb"}},"id":"ct"}},"id":"ct"}}
:enddata
:endentity

entity:
plugin=vanillaLogicEntity
number=5
data:
position=14,4,17
JSON:{{"val":{"xOffset":{"val":"0.5000764","id":"pf"},"equipmentData":{"val":{"length":{"val":"5","id":"pi"},"equipmentContents":{"val":[],"id":"ls"}},"id":"ct"},"rotation":{"val":"0.0072021484","id":"pf"},"mobID":{"val":"Villager","id":"ss"},"zOffset":{"val":"0.25108218","id":"pf"},"entityData":{"val":{"ForgeData":{"val":{"MP|Init":{"val":"1","id":"pb"},"ESM_MODIFIED":{"val":"1","id":"pb"},"sAI":{"val":{"Fiddling":{"val":"0","id":"pb"},"AvoidExplosions":{"val":"1","id":"pb"},"DefendVillage":{"val":"1","id":"pb"},"Griefing":{"val":"0","id":"pb"},"uAI":{"val":{},"id":"ct"},"Rider":{"val":"0","id":"pb"}},"id":"ct"},"ORIGINAL_SPAWN_POS":{"val":["-190","77","143"],"id":"ai"}},"id":"ct"},"Attributes":{"val":[{"val":{"Base":{"val":"20.0","id":"pd"},"Modifiers":{"val":[{"val":{"UUIDMost":{"val":"975582242042111","id":"pl"},"UUIDLeast":{"val":"-2157473849674594314","id":"pl"},"Amount":{"val":"0.0","id":"pd"},"Operation":{"val":"1","id":"pi"},"Name":{"val":"ESM_TWEAK_1","id":"ss"}},"id":"ct"}],"id":"ls"},"Name":{"val":"generic.maxHealth","id":"ss"}},"id":"ct"},{"val":{"Base":{"val":"0.0","id":"pd"},"Modifiers":{"val":[{"val":{"UUIDMost":{"val":"975582242046329","id":"pl"},"UUIDLeast":{"val":"-2346826154437879892","id":"pl"},"Amount":{"val":"0.0","id":"pd"},"Operation":{"val":"1","id":"pi"},"Name":{"val":"ESM_TWEAK_4","id":"ss"}},"id":"ct"}],"id":"ls"},"Name":{"val":"generic.knockbackResistance","id":"ss"}},"id":"ct"},{"val":{"Base":{"val":"0.5","id":"pd"},"Modifiers":{"val":[{"val":{"UUIDMost":{"val":"975582242045425","id":"pl"},"UUIDLeast":{"val":"-4277248540054102087","id":"pl"},"Amount":{"val":"0.0","id":"pd"},"Operation":{"val":"1","id":"pi"},"Name":{"val":"ESM_TWEAK_2","id":"ss"}},"id":"ct"}],"id":"ls"},"Name":{"val":"generic.movementSpeed","id":"ss"}},"id":"ct"},{"val":{"Base":{"val":"32.0","id":"pd"},"Modifiers":{"val":[{"val":{"UUIDMost":{"val":"975582241952034","id":"pl"},"UUIDLeast":{"val":"5651429252495995472","id":"pl"},"Amount":{"val":"0.03294900466126324","id":"pd"},"Operation":{"val":"1","id":"pi"},"Name":{"val":"Random spawn bonus","id":"ss"}},"id":"ct"}],"id":"ls"},"Name":{"val":"generic.followRange","id":"ss"}},"id":"ct"}],"id":"ls"},"Riches":{"val":"0","id":"pi"},"Invulnerable":{"val":"0","id":"pb"},"PortalCooldown":{"val":"0","id":"pi"},"AbsorptionAmount":{"val":"0.0","id":"pf"},"FallDistance":{"val":"0.0","id":"pf"},"DeathTime":{"val":"0","id":"ps"},"DropChances":{"val":[{"val":"0.085","id":"pf"},{"val":"0.085","id":"pf"},{"val":"0.085","id":"pf"},{"val":"0.085","id":"pf"},{"val":"0.085","id":"pf"}],"id":"ls"},"PersistenceRequired":{"val":"0","id":"pb"},"HealF":{"val":"20.0","id":"pf"},"Age":{"val":"0","id":"pi"},"Motion":{"val":[{"val":"0.0","id":"pd"},{"val":"-0.0784000015258789","id":"pd"},{"val":"0.0","id":"pd"}],"id":"ls"},"Leashed":{"val":"0","id":"pb"},"Health":{"val":"20","id":"ps"},"Air":{"val":"300","id":"ps"},"OnGround":{"val":"1","id":"pb"},"Dimension":{"val":"0","id":"pi"},"Rotation":{"val":[{"val":"1080.0072","id":"pf"},{"val":"0.0","id":"pf"}],"id":"ls"},"Profession":{"val":"10","id":"pi"},"CustomName":{"val":"","id":"ss"},"Pos":{"val":[{"val":"-186.4999235688752","id":"pd"},{"val":"71.0","id":"pd"},{"val":"150.25108218345503","id":"pd"}],"id":"ls"},"Fire":{"val":"-1","id":"ps"},"CanPickUpLoot":{"val":"0","id":"pb"},"HurtTime":{"val":"0","id":"ps"},"AttackTime":{"val":"0","id":"ps"},"CustomNameVisible":{"val":"0","id":"pb"}},"id":"ct"}},"id":"ct"}}
:enddata
:endentity

