# Ancient Warfare Structure Template File
# Auto-generated structure template file. created on: 12/15/2016 at: 23:17:21
# Lines beginning with # denote comments

header:
version=2.1
name=ReignCoachingInn
size=53,38,44
offset=22,3,33
:endheader

#### VALIDATION ####
validation:
type=ground
survival=true
worldGenEnabled=true
unique=false
preserveBlocks=false
selectionWeight=100
clusterValue=200
minDuplicateDistance=400
dimensionWhiteList=false
dimensionList=
biomeWhiteList=true
biomeList=savanna,shrubland,scrubland,prairie,steppe, meadow
leveling=12
fill=8
border=8
validTargetBlocks=minecraft:stained_hardened_clay,minecraft:dirt,minecraft:coal_ore,minecraft:lapis_ore,minecraft:diamond_ore,minecraft:gravel,minecraft:stone,minecraft:sand,minecraft:clay,minecraft:gold_ore,minecraft:redstone_ore,minecraft:grass,minecraft:iron_ore
blockSwap=false
data:
:enddata
:endvalidation

#### LAYERS ####
layer: 0
1,1,1,1,1,1,1,1,1,1,1,1,1,1,1,1,1,1,1,1,1,1,1,1,1,1,1,1,1,1,1,1,1,1,1,1,1,1,1,1,1,1,1,1,1,1,1,1,1,1,1,1,1
1,1,1,1,1,1,1,1,1,1,1,1,1,1,1,1,1,1,1,1,1,1,1,1,1,1,1,1,1,1,1,1,1,1,1,1,1,1,1,1,1,1,1,1,1,1,1,1,1,1,1,1,1
1,1,1,1,1,1,1,1,1,1,1,1,1,1,1,1,1,1,1,1,1,1,1,1,1,1,1,1,1,1,1,1,1,1,1,1,1,1,1,1,1,1,1,1,1,1,1,1,1,1,1,1,1
1,1,1,1,1,1,1,1,1,1,1,1,1,1,1,1,1,1,1,1,1,1,1,1,1,1,1,1,1,1,1,1,1,1,1,1,1,1,1,1,1,1,1,1,1,1,1,1,1,1,1,1,1
1,1,1,1,1,1,1,1,1,1,1,1,1,1,1,1,1,1,1,1,1,1,1,1,1,1,1,1,1,1,1,1,1,1,1,1,1,1,1,1,1,1,1,1,1,1,1,1,1,1,1,1,1
1,1,1,1,1,1,1,1,1,1,1,1,1,1,1,1,1,1,1,1,1,1,1,1,1,1,1,1,1,1,1,1,1,1,1,1,1,1,1,1,1,1,1,1,1,1,1,1,1,1,1,1,1
1,1,1,1,1,1,1,1,1,1,1,1,1,1,1,1,1,1,1,1,1,1,1,1,1,1,1,1,1,1,1,1,1,1,1,1,1,1,1,1,1,1,1,1,1,1,1,1,1,1,1,1,1
1,1,1,1,1,1,1,1,1,1,1,1,1,1,1,1,1,1,1,1,1,1,1,1,1,1,1,1,1,1,1,1,1,1,1,1,1,1,1,1,1,1,1,1,1,1,1,1,1,1,1,1,1
1,1,1,1,1,1,1,1,1,1,1,1,1,1,1,1,1,1,1,1,1,1,1,1,1,1,1,1,1,1,1,1,1,1,1,1,1,1,1,1,1,1,1,1,1,1,1,1,1,1,1,1,1
1,1,1,1,1,1,1,1,1,1,1,1,1,1,1,1,1,1,1,1,1,1,1,1,1,1,1,1,1,1,1,1,1,1,1,1,1,1,1,1,1,1,1,1,1,1,1,1,1,1,1,1,1
1,1,1,1,1,1,1,1,1,1,1,1,1,1,1,1,1,1,1,1,1,1,1,1,1,1,1,1,1,1,1,1,1,1,1,1,1,1,1,1,1,1,1,1,1,1,1,1,1,1,1,1,1
1,1,1,1,1,1,1,1,1,1,1,1,1,1,1,1,1,1,1,1,1,1,1,1,1,1,1,1,1,1,1,1,1,1,1,1,1,1,1,1,1,1,1,1,1,1,1,1,1,1,1,1,1
1,1,1,1,1,1,1,1,1,1,1,1,1,1,1,1,1,1,1,1,1,1,1,1,1,1,1,1,1,1,1,1,1,1,1,1,1,1,1,1,1,1,1,1,1,1,1,1,1,1,1,1,1
1,1,1,1,1,1,1,1,1,1,1,1,1,1,1,1,1,1,1,1,1,1,1,1,1,1,1,1,1,1,1,1,1,1,1,1,1,1,1,1,1,1,1,1,1,1,1,1,1,1,1,1,1
1,1,1,1,1,1,1,1,1,1,1,1,1,1,1,1,1,1,1,1,1,1,1,1,1,1,1,1,1,1,1,1,1,1,1,1,1,1,1,1,1,1,1,1,1,1,1,1,1,1,1,1,1
1,1,1,1,1,1,1,1,1,1,1,1,1,1,1,1,1,1,1,1,1,1,1,1,1,1,1,1,1,1,1,1,1,1,1,1,1,1,1,1,1,1,1,1,1,1,1,1,1,1,1,1,1
1,1,1,1,1,1,1,1,1,1,1,1,1,1,1,1,1,1,1,1,1,1,1,1,1,1,1,1,1,1,1,1,1,1,1,1,1,1,1,1,1,1,1,1,1,1,1,1,1,1,1,1,1
1,1,1,1,1,1,1,1,1,1,1,1,1,1,1,1,1,1,1,1,1,1,1,1,1,1,1,1,1,1,1,1,1,1,1,1,1,1,1,1,1,1,1,1,1,1,1,1,1,1,1,1,1
1,1,1,1,1,1,1,1,1,1,1,1,1,1,1,1,1,1,1,1,1,1,1,1,1,1,1,1,1,1,1,1,1,1,1,1,1,1,1,1,1,1,1,1,1,1,1,1,1,1,1,1,1
1,1,1,1,1,1,1,1,1,1,1,1,1,1,1,1,1,1,1,1,1,1,1,1,1,1,1,1,1,1,1,1,1,1,1,1,1,1,1,1,1,1,1,1,1,1,1,1,1,1,1,1,1
1,1,1,1,1,1,1,1,1,1,1,1,1,1,1,1,1,1,1,1,1,1,1,1,1,1,1,1,1,1,1,1,1,1,1,1,1,1,1,1,1,1,1,1,1,1,1,1,1,1,1,1,1
1,1,1,1,1,1,1,1,1,1,1,1,1,1,1,1,1,1,1,1,1,1,1,1,1,1,1,1,1,1,1,1,1,1,1,1,1,1,1,1,1,1,1,1,1,1,1,1,1,1,1,1,1
1,1,1,1,1,1,1,1,1,1,1,1,1,1,1,1,1,1,1,1,1,1,1,1,1,1,1,1,1,1,1,1,1,1,1,1,1,1,1,1,1,1,1,1,1,1,1,1,1,1,1,1,1
1,1,1,1,1,1,1,1,1,1,1,1,1,1,1,1,1,1,1,1,1,1,1,1,1,1,1,1,1,1,1,1,1,1,1,1,1,1,1,1,1,1,1,1,1,1,1,1,1,1,1,1,1
1,1,1,1,1,1,1,1,1,1,1,1,1,1,1,1,1,1,1,1,1,1,1,1,1,1,1,1,1,1,1,1,1,1,1,1,1,1,1,1,1,1,1,1,1,1,1,1,1,1,1,2,1
1,1,1,1,1,1,1,1,1,1,1,1,1,1,1,1,1,1,1,1,1,1,1,1,1,1,1,1,1,1,1,1,1,1,1,1,1,1,1,1,1,1,1,1,1,1,1,1,1,1,1,1,1
1,1,1,1,1,1,1,1,1,1,1,1,1,1,1,1,1,1,1,1,1,1,1,1,1,1,1,1,1,1,1,1,1,1,1,1,1,1,1,1,1,1,1,1,1,1,1,1,1,1,1,1,1
1,1,1,1,1,1,1,1,1,1,1,1,1,1,1,1,1,1,1,1,1,1,1,1,1,1,1,1,1,1,1,1,1,1,1,1,1,1,1,1,1,1,1,1,1,1,1,1,1,1,1,1,1
1,1,1,1,1,1,1,1,1,1,1,1,1,1,1,1,1,1,1,1,1,1,1,1,1,1,1,1,1,1,1,1,1,1,1,1,1,1,1,1,1,1,1,1,1,1,1,1,1,1,1,1,1
1,1,1,1,1,1,1,1,1,1,1,1,1,1,1,1,1,1,1,1,1,1,1,1,1,1,1,1,1,1,1,1,1,1,1,1,1,1,1,1,1,1,1,1,1,1,1,1,1,1,1,1,1
1,1,1,1,1,1,1,1,1,1,1,1,1,1,1,1,1,1,1,1,1,1,1,1,1,1,1,1,1,1,1,1,1,1,1,1,1,1,1,1,1,1,1,1,1,1,1,1,1,1,1,1,1
1,1,1,1,1,1,1,1,1,1,1,1,1,1,1,1,1,1,1,1,1,1,1,1,1,1,1,1,1,1,1,1,1,1,1,1,1,1,1,1,1,1,1,1,1,1,1,1,1,1,1,1,1
1,1,1,1,1,1,1,1,1,1,1,1,1,1,1,1,1,1,1,1,1,1,1,1,1,1,1,1,1,1,1,1,1,1,1,1,1,1,1,1,1,1,1,1,1,1,1,1,1,1,1,1,1
1,1,1,1,1,1,1,1,1,1,1,1,1,1,1,1,1,1,1,1,1,1,1,1,1,1,1,1,1,1,1,1,1,1,1,1,1,1,1,1,1,1,1,1,1,1,1,1,1,1,1,1,1
1,1,1,1,1,1,1,1,1,1,1,1,1,1,1,1,1,1,1,1,1,1,1,1,1,1,1,1,1,1,1,1,1,1,1,1,1,1,1,1,1,1,1,1,1,1,1,1,1,1,1,1,1
1,1,1,1,1,1,1,1,1,1,1,1,1,1,1,1,1,1,1,1,1,1,1,1,1,1,1,1,1,1,1,1,1,1,1,1,1,1,1,1,1,1,1,1,1,1,1,1,1,1,1,1,1
1,1,1,1,1,1,1,1,1,1,1,1,1,1,1,1,1,1,1,1,1,1,1,1,1,1,1,1,1,1,1,1,1,1,1,1,1,1,1,1,1,1,1,1,1,1,1,1,1,1,1,1,1
1,1,1,1,1,1,1,1,1,1,1,1,1,1,1,1,1,1,1,1,1,1,1,1,1,1,1,1,1,1,1,1,1,1,1,1,1,1,1,1,1,1,1,1,1,1,1,1,1,1,1,1,1
1,1,1,1,1,1,1,1,1,1,1,1,1,1,1,1,1,1,1,1,1,1,1,1,1,1,1,1,1,1,1,1,1,1,1,1,1,1,1,1,1,1,1,1,1,1,1,1,1,1,1,1,1
1,1,1,1,1,1,1,1,1,1,1,1,1,1,1,1,1,1,1,1,1,1,1,1,1,1,1,1,1,1,1,1,1,1,1,1,1,1,1,1,1,1,1,1,1,1,1,1,1,1,1,1,1
1,1,1,1,1,1,1,1,1,1,1,1,1,1,1,1,1,1,1,1,1,1,1,1,1,1,1,1,1,1,1,1,1,1,1,1,1,1,1,1,1,1,1,1,1,1,1,1,1,1,1,1,1
1,1,1,1,1,1,1,1,1,1,1,1,1,1,1,1,1,1,1,1,1,1,1,1,1,1,1,1,1,1,1,1,1,1,1,1,1,1,1,1,1,1,1,1,1,1,1,1,1,1,1,1,1
1,1,1,1,1,1,1,1,1,1,1,1,1,1,1,1,1,1,1,1,1,1,1,1,1,1,1,1,1,1,1,1,1,1,1,1,1,1,1,1,1,1,1,1,1,1,1,1,1,1,1,1,1
1,1,1,1,1,1,1,1,1,1,1,1,1,1,1,1,1,1,1,1,1,1,1,1,1,1,1,1,1,1,1,1,1,1,1,1,1,1,1,1,1,1,1,1,1,1,1,1,1,1,1,1,1
:endlayer
layer: 1
1,1,1,1,1,1,1,1,1,1,1,1,1,1,1,1,1,1,1,1,1,1,1,1,1,1,1,1,1,1,1,1,1,1,1,1,1,1,1,1,1,1,1,1,1,1,1,1,1,1,1,1,1
1,1,1,1,1,1,1,1,1,1,1,1,1,1,1,1,1,1,1,1,1,1,1,1,1,1,1,1,1,1,1,1,1,1,1,1,1,1,1,1,1,1,1,1,1,1,1,1,1,1,1,1,1
1,1,1,1,1,1,1,1,1,1,1,1,1,1,1,1,1,1,1,1,1,1,1,1,1,1,1,1,1,1,1,1,1,1,1,1,1,1,1,1,1,1,1,1,1,1,1,1,1,1,1,1,1
1,1,1,1,1,1,1,1,1,1,1,1,1,1,1,1,1,1,1,1,1,1,1,1,1,1,1,1,1,1,1,1,1,1,1,1,1,1,1,1,1,1,1,1,1,1,1,1,1,1,1,1,1
1,1,1,1,1,1,1,1,1,1,1,1,1,1,1,1,1,1,1,1,1,1,1,1,1,1,1,1,1,1,1,1,1,1,1,1,1,1,1,1,1,1,1,1,1,1,1,1,1,1,1,1,1
1,1,1,1,1,1,1,1,1,1,1,1,1,1,1,1,1,1,1,1,1,1,1,1,1,1,1,1,1,1,1,1,1,1,1,1,1,1,1,1,1,1,1,1,1,1,1,1,1,1,1,1,1
1,1,1,1,1,1,1,1,1,1,1,1,1,1,1,1,1,1,1,1,1,1,1,1,1,1,1,1,1,1,1,1,1,1,1,1,1,1,1,1,1,1,1,1,1,1,1,1,1,1,1,1,1
1,1,1,1,1,1,1,1,1,1,1,1,1,1,1,1,1,1,1,1,1,1,1,1,1,1,1,1,1,1,1,1,1,1,1,1,1,1,1,1,1,1,1,1,1,1,1,1,1,1,1,1,1
1,1,1,1,1,1,1,1,1,1,1,1,1,1,1,1,1,1,1,1,1,1,1,1,1,1,1,1,1,1,1,1,1,1,1,1,1,1,1,1,1,1,1,1,1,1,1,1,1,1,1,1,1
1,1,1,1,1,1,1,1,1,1,1,1,1,1,1,1,1,1,1,1,1,1,1,1,1,1,1,1,1,1,1,1,1,1,1,1,1,1,1,1,1,1,1,1,1,1,1,1,1,1,1,1,1
1,1,1,1,1,1,1,1,1,1,1,1,1,1,1,1,1,1,1,1,1,1,1,1,1,1,1,1,1,1,1,1,1,1,1,1,1,1,1,1,1,1,1,1,1,1,1,1,1,1,1,1,1
1,1,1,1,1,1,1,1,1,1,1,1,1,1,1,1,1,1,1,1,1,1,1,1,1,1,1,1,1,1,1,1,1,1,1,1,1,1,1,1,1,1,1,1,1,1,1,1,1,1,1,1,1
1,1,1,1,1,1,1,1,1,1,1,1,1,1,1,1,1,1,1,1,1,1,1,1,1,1,1,1,1,1,1,1,1,1,1,1,1,1,1,1,1,1,1,1,1,1,1,1,1,1,1,1,1
1,1,1,1,1,1,1,1,1,1,1,1,1,1,1,1,1,1,1,1,1,1,1,1,1,1,1,1,1,1,1,1,1,1,1,1,1,1,1,1,1,1,1,1,1,1,1,1,1,1,1,1,1
1,1,1,1,1,1,1,1,1,1,1,1,1,1,1,1,1,1,1,1,1,1,1,1,1,1,1,1,1,1,1,1,1,1,1,1,1,1,1,1,1,1,1,1,1,1,1,1,1,1,1,1,1
1,1,1,1,1,1,1,1,1,1,1,1,1,1,1,1,1,1,1,1,1,1,1,1,1,1,1,1,1,1,1,1,1,1,1,1,1,1,1,1,1,1,1,1,1,1,1,1,1,1,1,1,1
1,1,1,1,1,1,1,1,1,1,1,1,1,1,1,1,1,1,1,1,1,1,1,1,1,1,1,1,1,1,1,1,1,1,1,1,1,1,1,1,1,1,1,1,1,1,1,1,1,1,1,1,1
1,1,1,1,1,1,1,1,1,1,1,1,1,1,1,1,1,1,1,1,1,1,1,1,1,1,1,1,1,1,1,1,1,1,1,1,1,1,1,1,1,1,1,1,1,1,1,1,1,1,1,1,1
1,1,1,1,1,1,1,1,1,1,1,1,1,1,1,1,1,1,1,1,1,1,1,1,1,1,1,1,1,1,1,1,1,1,1,1,1,1,1,1,1,1,1,1,1,1,1,1,1,1,1,1,1
1,1,1,1,1,1,1,1,1,1,1,1,1,1,1,1,1,1,1,1,1,1,1,1,1,1,1,1,1,1,1,1,1,1,1,1,1,1,1,1,1,1,1,1,1,1,1,1,1,1,1,1,1
1,1,1,1,1,1,1,1,1,1,1,1,1,1,1,1,1,1,1,1,3,3,1,1,1,1,1,1,1,1,1,1,1,1,1,1,1,1,1,1,1,1,1,1,1,1,1,1,1,1,1,1,1
1,1,1,1,1,1,1,1,1,1,1,1,1,1,1,1,1,1,1,3,4,4,3,1,1,1,1,1,1,1,1,1,1,1,1,1,1,1,1,1,1,1,1,1,1,1,1,1,1,1,1,1,1
1,1,1,1,1,1,1,1,1,1,1,1,1,1,1,1,1,1,1,3,4,4,3,1,1,1,1,1,1,1,1,1,1,1,1,1,1,1,1,1,1,1,1,1,1,1,1,1,1,1,1,1,1
1,1,1,1,1,1,1,1,1,1,1,1,1,1,1,1,1,1,1,1,3,3,1,1,1,1,1,1,1,1,1,1,1,1,1,1,1,1,1,1,1,1,1,1,1,1,1,1,1,1,1,1,1
1,1,1,1,1,1,1,1,1,1,1,1,1,1,1,1,1,1,1,1,1,1,1,1,1,1,1,1,1,1,1,1,1,1,1,1,1,1,1,1,1,1,1,1,1,1,1,1,1,1,1,2,1
1,1,1,1,1,1,1,1,1,1,1,1,1,1,1,1,1,1,1,1,1,1,1,1,1,1,1,1,1,1,1,1,1,1,1,1,1,1,1,1,1,1,1,1,1,1,1,1,1,1,1,1,1
1,1,1,1,1,1,1,1,1,1,1,1,1,1,1,1,1,1,1,1,1,1,1,1,1,1,1,1,1,1,1,1,1,1,1,1,1,1,1,1,1,1,1,1,1,1,1,1,1,1,1,1,1
1,1,1,1,1,1,1,1,1,1,1,1,1,1,1,1,1,1,1,1,1,1,1,1,1,1,1,1,1,1,1,1,1,1,1,1,1,1,1,1,1,1,1,1,1,1,1,1,1,1,1,1,1
1,1,1,1,1,1,1,1,1,1,1,1,1,1,1,1,1,1,1,1,1,1,1,1,1,1,1,1,1,1,1,1,1,1,1,1,1,1,1,1,1,1,1,1,1,1,1,1,1,1,1,1,1
1,1,1,1,1,1,1,1,1,1,1,1,1,1,1,1,1,1,1,1,1,1,1,1,1,1,1,1,1,1,1,1,1,1,1,1,1,1,1,1,1,1,1,1,1,1,1,1,1,1,1,1,1
1,1,1,1,1,1,1,1,1,1,1,1,1,1,1,1,1,1,1,1,1,1,1,1,1,1,1,1,1,1,1,1,1,1,1,1,1,1,1,1,1,1,1,1,1,1,1,1,1,1,1,1,1
1,1,1,1,1,1,1,1,1,1,1,1,1,1,1,1,1,1,1,1,1,1,1,1,1,1,1,1,1,1,1,1,1,1,1,1,1,1,1,1,1,1,1,1,1,1,1,1,1,1,1,1,1
1,1,1,1,1,1,1,1,1,1,1,1,1,1,1,1,1,1,1,1,1,1,1,1,1,1,1,1,1,1,1,1,1,1,1,1,1,1,1,1,1,1,1,1,1,1,1,1,1,1,1,1,1
1,1,1,1,1,1,1,1,1,1,1,1,1,1,1,1,1,1,1,1,1,1,1,1,1,1,1,1,1,1,1,1,1,1,1,1,1,1,1,1,1,1,1,1,1,1,1,1,1,1,1,1,1
1,1,1,1,1,1,1,1,1,1,1,1,1,1,1,1,1,1,1,1,1,1,1,1,1,1,1,1,1,1,1,1,1,1,1,1,1,1,1,1,1,1,1,1,1,1,1,1,1,1,1,1,1
1,1,1,1,1,1,1,1,1,1,1,1,1,1,1,1,1,1,1,1,1,1,1,1,1,1,1,1,1,1,1,1,1,1,1,1,1,1,1,1,1,1,1,1,1,1,1,1,1,1,1,1,1
1,1,1,1,1,1,1,1,1,1,1,1,1,1,1,1,1,1,1,1,1,1,1,1,1,1,1,1,1,1,1,1,1,1,1,1,1,1,1,1,1,1,1,1,1,1,1,1,1,1,1,1,1
1,1,1,1,1,1,1,1,1,1,1,1,1,1,1,1,1,1,1,1,1,1,1,1,1,1,1,1,1,1,1,1,1,1,1,1,1,1,1,1,1,1,1,1,1,1,1,1,1,1,1,1,1
1,1,1,1,1,1,1,1,1,1,1,1,1,1,1,1,1,1,1,1,1,1,1,1,1,1,1,1,1,1,1,1,1,1,1,1,1,1,1,1,1,1,1,1,1,1,1,1,1,1,1,1,1
1,1,1,1,1,1,1,1,1,1,1,1,1,1,1,1,1,1,1,1,1,1,1,1,1,1,1,1,1,1,1,1,1,1,1,1,1,1,1,1,1,1,1,1,1,1,1,1,1,1,1,1,1
1,1,1,1,1,1,1,1,1,1,1,1,1,1,1,1,1,1,1,1,1,1,1,1,1,1,1,1,1,1,1,1,1,1,1,1,1,1,1,1,1,1,1,1,1,1,1,1,1,1,1,1,1
1,1,1,1,1,1,1,1,1,1,1,1,1,1,1,1,1,1,1,1,1,1,1,1,1,1,1,1,1,1,1,1,1,1,1,1,1,1,1,1,1,1,1,1,1,1,1,1,1,1,1,1,1
1,1,1,1,1,1,1,1,1,1,1,1,1,1,1,1,1,1,1,1,1,1,1,1,1,1,1,1,1,1,1,1,1,1,1,1,1,1,1,1,1,1,1,1,1,1,1,1,1,1,1,1,1
1,1,1,1,1,1,1,1,1,1,1,1,1,1,1,1,1,1,1,1,1,1,1,1,1,1,1,1,1,1,1,1,1,1,1,1,1,1,1,1,1,1,1,1,1,1,1,1,1,1,1,1,1
:endlayer
layer: 2
5,5,5,5,5,5,5,5,5,5,5,5,5,5,5,5,5,5,5,5,5,5,5,5,5,5,5,5,5,5,5,5,5,5,5,5,5,5,5,5,5,5,5,5,5,5,5,5,5,5,5,5,5
5,5,5,5,5,5,5,5,5,5,5,5,5,5,5,5,5,5,5,5,5,5,5,5,5,5,5,5,3,3,5,5,5,5,5,5,5,5,5,5,5,5,5,5,5,5,5,5,5,5,5,5,5
5,5,5,5,5,5,5,5,5,5,5,5,5,5,5,5,5,5,5,5,5,5,5,5,5,5,5,5,3,3,5,5,5,5,5,5,5,5,5,5,5,5,5,5,5,5,5,5,5,5,5,5,5
5,5,5,5,7,7,7,7,7,7,7,7,7,7,7,7,1,1,1,1,1,1,1,1,1,1,1,1,7,7,1,1,1,1,1,1,1,1,1,1,1,1,1,1,1,1,1,1,1,1,5,5,5
5,5,5,5,7,3,3,3,3,3,3,3,3,7,3,3,1,1,1,1,1,1,1,5,5,5,5,5,3,3,3,3,3,3,3,3,3,3,5,1,3,3,3,3,3,3,1,5,5,1,5,5,5
5,5,5,5,7,3,3,3,3,3,3,3,3,7,3,3,1,1,1,1,1,1,1,1,3,3,3,3,3,3,3,3,3,3,3,3,3,3,5,1,3,3,3,3,3,3,8,3,5,1,5,5,5
5,5,5,5,7,3,3,3,3,3,3,3,3,7,3,3,1,1,1,1,1,1,1,5,5,5,5,5,3,3,3,3,3,3,3,3,3,3,5,1,3,3,3,3,3,3,3,3,5,1,5,5,5
5,5,5,5,7,3,3,3,3,3,3,3,3,7,3,3,1,1,1,1,1,1,1,5,5,5,5,5,5,5,5,5,5,5,5,3,3,3,5,3,3,3,3,3,3,3,3,3,5,1,5,5,5
5,5,5,5,7,3,3,3,3,3,3,3,3,7,3,3,1,1,1,1,1,1,1,1,1,1,1,1,1,1,1,1,1,1,5,3,3,3,5,1,3,3,3,3,3,3,3,3,5,1,5,5,5
5,5,5,1,7,3,3,3,3,3,3,3,3,7,3,3,1,1,1,1,1,1,1,1,1,1,1,1,1,1,1,1,1,1,5,3,3,3,5,1,1,1,3,3,3,3,8,3,5,1,5,5,5
5,5,5,5,7,3,3,3,3,3,3,3,3,7,3,3,1,1,1,1,1,1,1,1,1,1,1,1,1,1,1,1,1,1,5,3,3,3,3,3,3,3,3,3,3,3,3,3,5,1,5,5,5
5,5,5,5,7,3,3,3,3,3,3,3,3,7,3,3,1,1,1,1,1,1,1,1,1,1,1,1,1,1,1,1,1,1,5,3,3,3,3,3,3,3,3,3,3,3,3,3,5,1,5,5,5
5,5,5,5,7,3,3,3,3,3,3,3,3,7,3,3,1,1,1,1,1,1,1,1,1,1,1,1,1,1,1,1,1,1,5,3,3,3,3,3,3,3,3,3,3,3,3,3,5,1,5,5,5
5,5,5,5,7,3,3,3,3,3,3,3,3,7,3,3,1,1,1,1,1,1,1,1,1,1,1,1,1,1,1,1,1,1,5,3,3,3,3,3,3,3,3,3,3,3,3,3,5,1,5,5,5
5,5,5,1,7,3,3,3,3,3,3,3,3,7,5,5,5,5,5,5,5,5,1,5,5,5,5,1,5,5,5,5,5,5,5,3,3,3,3,1,3,3,3,3,3,3,1,3,5,1,5,5,5
5,5,5,5,7,3,3,3,3,3,3,3,3,7,5,5,5,3,3,3,3,3,3,3,3,3,3,3,3,3,3,3,3,3,3,3,3,3,3,3,3,3,3,3,3,3,3,3,1,1,5,5,5
5,5,5,1,7,3,3,3,3,3,3,3,3,7,5,5,5,3,3,3,3,3,3,3,3,3,3,3,3,3,3,3,3,3,3,3,3,3,3,3,3,3,3,3,3,3,3,3,1,5,5,5,5
5,5,1,1,7,3,3,3,3,3,3,3,3,7,5,5,5,3,3,3,3,3,3,3,3,3,3,3,3,3,3,3,3,3,3,3,3,3,3,3,3,3,3,3,3,3,3,3,3,3,3,3,5
5,5,5,5,7,3,3,3,3,3,3,3,3,7,5,5,5,3,3,3,3,3,3,3,3,3,3,3,3,3,3,3,3,3,3,3,3,3,3,3,3,3,3,3,3,3,3,3,3,3,3,3,5
5,5,5,1,7,3,3,3,3,3,3,3,3,7,5,5,5,3,3,3,3,3,3,3,3,3,3,3,3,3,3,3,3,3,3,3,3,3,3,3,3,5,5,5,5,1,5,3,1,5,5,5,5
5,5,5,5,7,7,1,1,7,7,7,7,7,7,7,7,7,3,3,7,7,7,7,3,3,3,3,3,5,1,5,5,5,5,5,5,5,1,1,3,3,1,1,1,1,1,1,3,3,1,5,5,5
5,5,5,5,7,3,3,3,3,3,3,3,3,3,3,3,7,3,3,7,4,4,7,3,3,3,3,3,1,1,1,1,1,1,1,1,1,3,3,3,3,1,1,1,1,1,1,3,5,5,5,5,5
5,5,5,5,7,3,3,3,3,3,3,3,3,3,3,3,7,3,3,7,4,4,7,3,3,3,3,3,3,1,3,3,3,3,3,3,3,3,3,3,3,1,1,1,1,1,1,3,5,5,5,5,5
5,5,5,5,7,3,3,3,3,3,3,3,3,3,3,3,7,3,3,7,7,7,7,3,3,3,3,3,3,3,3,3,3,3,3,3,3,3,3,3,3,1,1,1,1,1,1,3,5,5,5,5,5
5,5,5,5,7,3,3,3,3,3,3,3,3,3,3,3,7,3,3,3,3,3,3,3,3,3,3,3,3,1,3,3,3,3,3,3,3,3,3,3,3,1,1,1,1,1,1,3,5,5,5,5,5
5,5,5,5,7,3,3,3,3,3,3,3,3,3,3,3,7,3,3,3,3,3,3,3,3,3,3,3,1,1,3,3,3,3,3,3,3,1,1,7,1,1,1,1,1,1,1,3,5,5,5,5,5
5,5,5,5,7,3,3,3,3,3,3,3,3,3,3,3,7,3,3,3,3,3,3,3,3,3,3,3,5,3,7,3,3,3,3,3,3,3,3,3,3,1,1,1,1,1,1,3,5,5,5,5,5
5,5,5,5,7,3,3,3,3,3,3,3,3,3,3,3,7,3,3,3,3,3,3,3,3,3,9,9,5,8,7,3,3,3,3,3,3,3,3,3,3,1,1,1,1,1,1,3,5,5,5,5,5
5,5,5,5,7,3,3,3,3,3,3,3,3,3,3,3,7,3,3,3,3,3,3,3,3,3,3,3,5,8,1,3,3,3,3,3,3,3,3,3,3,1,1,1,1,1,1,3,5,5,5,5,5
5,5,5,5,7,3,3,3,3,3,3,3,3,3,3,3,3,3,3,3,3,3,3,3,3,3,3,3,5,8,1,3,3,3,3,3,3,3,3,3,3,3,3,3,3,3,1,3,5,5,5,5,5
5,5,5,5,7,3,3,3,3,3,3,3,3,3,3,3,3,3,3,3,3,3,3,3,1,1,1,1,1,1,1,3,3,3,3,3,3,3,3,3,3,3,3,3,3,3,1,3,5,5,5,5,5
5,5,5,5,7,3,3,3,3,3,3,3,3,3,3,3,3,3,3,3,3,3,3,3,1,1,1,1,1,1,1,3,3,3,3,3,3,3,3,3,3,3,3,3,3,3,1,3,5,5,5,5,5
5,5,5,5,7,3,3,3,3,3,3,3,3,3,3,3,3,3,3,3,3,3,3,3,1,1,1,1,1,1,1,3,3,3,3,3,3,3,3,3,3,3,3,3,3,3,1,3,5,5,5,5,5
5,5,5,5,7,3,3,3,3,3,3,3,3,3,3,3,7,7,7,7,1,3,3,1,1,1,1,1,1,1,1,3,3,3,3,3,3,3,3,3,3,3,3,3,3,3,1,3,5,5,5,5,5
5,5,5,5,7,7,7,7,7,7,7,7,7,7,7,7,7,1,1,1,5,3,3,5,1,1,1,1,1,1,1,1,1,1,1,1,1,1,1,1,1,1,1,1,1,1,1,1,1,1,5,5,5
5,5,5,5,5,5,5,5,6,6,6,6,5,5,5,5,5,5,5,5,6,6,6,6,5,5,5,5,5,5,5,5,5,5,5,5,5,5,5,5,5,5,5,5,5,5,5,5,5,5,5,5,5
5,5,5,5,5,5,5,5,6,6,6,6,6,6,6,6,6,6,6,6,6,6,6,6,5,5,5,5,5,5,5,5,5,5,5,5,5,5,5,5,5,5,5,5,5,5,5,5,5,5,5,5,5
5,5,5,5,5,5,5,5,6,6,6,6,6,6,6,6,6,6,6,6,6,6,6,6,5,5,5,5,5,5,5,5,5,5,5,5,5,5,5,5,5,5,5,5,5,5,5,5,5,5,5,5,5
5,5,5,5,5,5,5,5,6,6,6,6,6,6,6,6,6,6,6,6,6,6,6,6,5,5,5,5,5,5,5,5,5,5,5,5,5,5,5,5,5,5,5,5,5,5,5,5,5,5,5,5,5
5,5,5,5,5,5,5,5,6,6,6,6,5,5,5,5,5,5,5,5,6,6,6,6,5,5,5,5,5,5,5,5,5,5,5,5,5,5,5,5,5,5,5,5,5,5,5,5,5,5,5,5,5
5,5,5,5,5,5,5,5,6,6,6,6,5,5,5,5,5,5,5,5,6,6,6,6,5,5,5,5,5,5,5,5,5,5,5,5,5,5,5,5,5,5,5,5,5,5,5,5,5,5,5,5,5
5,5,5,5,5,5,5,5,5,5,5,5,5,5,5,5,5,5,5,5,5,5,5,5,5,5,5,5,5,5,5,5,5,5,5,5,5,5,5,5,5,5,5,5,5,5,5,5,5,5,5,5,5
5,5,5,5,5,5,5,5,5,5,5,5,5,5,5,5,5,5,5,5,5,5,5,5,5,5,5,5,5,5,5,5,5,5,5,5,5,5,5,5,5,5,5,5,5,5,5,5,5,5,5,5,5
5,5,5,5,5,5,5,5,5,5,5,5,5,5,5,5,5,5,5,5,5,5,5,5,5,5,5,5,5,5,5,5,5,5,5,5,5,5,5,5,5,5,5,5,5,5,5,5,5,5,5,5,5
:endlayer
layer: 3
0,0,0,0,0,0,0,0,0,0,0,0,0,0,0,0,0,0,0,0,0,0,0,0,0,0,0,0,0,0,0,0,0,0,0,0,0,0,0,0,0,0,0,0,0,0,0,0,0,0,0,0,0
0,0,0,0,0,10,0,10,0,0,10,10,0,10,0,10,10,10,0,0,10,10,10,0,0,10,10,10,0,0,0,0,0,10,10,0,0,0,10,10,10,0,0,0,0,0,0,0,0,10,0,10,0
0,10,0,10,10,10,10,0,0,10,10,10,10,10,10,0,10,0,0,10,10,10,0,10,10,10,10,10,0,0,0,0,0,10,10,0,0,0,10,10,10,0,0,0,0,0,0,0,0,0,10,10,0
0,10,0,0,7,7,7,7,7,7,7,7,7,7,7,7,7,7,7,7,7,7,7,7,7,7,7,7,18,19,7,7,7,7,7,7,7,7,7,7,7,7,7,7,7,7,7,7,7,7,10,10,0
0,10,0,10,7,78,0,0,17,77,17,0,0,7,17,17,17,17,17,17,17,17,7,0,0,0,0,0,0,0,0,0,0,0,0,0,0,0,0,8,76,75,22,74,73,72,8,0,55,7,10,10,0
0,10,10,0,7,71,0,0,0,0,0,0,25,7,17,17,17,17,17,17,17,17,7,24,0,0,0,0,0,0,0,0,0,0,0,0,0,0,0,7,0,0,0,0,0,0,7,0,0,7,0,10,0
0,10,0,10,7,22,0,0,0,0,0,0,0,7,17,17,17,17,17,17,17,17,7,0,0,0,0,0,0,0,0,0,0,0,0,0,0,0,0,7,70,0,0,0,0,0,7,0,0,7,0,0,0
0,0,0,0,7,69,0,0,0,0,0,0,0,7,17,17,17,17,17,17,17,17,7,68,0,0,0,0,0,0,0,0,0,0,65,0,0,0,0,7,0,0,0,0,0,23,7,0,0,7,0,0,0
0,10,0,0,7,11,11,11,11,0,0,11,11,7,17,17,17,17,17,17,17,17,7,7,7,7,7,7,7,7,7,7,7,7,0,0,0,0,0,7,0,0,0,67,66,7,7,0,0,7,10,0,0
0,10,10,10,7,0,0,0,11,0,0,0,0,7,17,17,17,17,17,17,17,17,17,17,7,7,7,7,7,7,7,7,7,7,0,0,0,0,65,8,7,7,51,7,7,7,8,0,0,7,10,10,0
0,10,10,10,7,0,0,0,12,0,0,0,0,7,17,17,17,17,17,17,17,17,17,17,7,7,7,7,7,7,7,7,7,7,0,0,0,0,0,7,0,0,0,0,0,0,7,0,0,7,10,10,0
0,10,10,10,7,11,11,11,11,0,0,11,11,7,17,17,17,17,17,17,17,17,17,17,7,7,7,7,7,7,7,7,7,7,0,0,0,0,0,7,0,0,0,20,11,26,7,0,0,7,10,0,0
0,10,10,10,7,0,0,0,11,0,0,0,0,7,17,17,17,17,17,17,17,17,17,17,7,7,7,7,7,7,7,7,7,7,0,0,0,0,0,51,0,0,0,20,11,26,7,0,0,7,0,0,0
0,10,10,10,7,0,0,0,12,0,0,0,0,7,7,7,7,7,7,7,7,7,7,7,7,7,7,7,7,7,7,7,7,7,0,0,0,0,0,7,0,64,63,20,11,26,7,0,0,7,10,0,0
0,10,10,10,7,11,11,11,11,0,0,11,11,7,58,57,57,56,56,56,58,62,61,62,0,0,60,61,60,0,0,0,0,0,0,0,0,0,0,8,7,7,7,7,7,7,8,0,55,7,0,10,0
0,10,10,10,7,0,0,0,11,0,0,0,0,7,57,30,56,0,0,0,0,0,0,0,0,0,0,0,0,0,0,0,0,0,0,0,0,0,0,0,0,0,0,0,0,0,0,0,7,7,10,10,0
0,0,10,0,7,0,0,0,12,0,0,0,0,7,57,60,59,0,0,0,0,0,0,0,0,0,0,0,0,0,0,0,0,0,0,0,0,0,0,0,0,0,0,0,0,0,0,0,7,10,10,10,0
0,0,10,10,7,11,11,11,11,0,0,11,11,7,57,60,59,0,0,0,0,0,0,0,0,0,0,0,0,0,0,0,0,0,0,0,0,0,0,0,0,0,0,0,0,0,0,0,18,0,0,0,0
0,10,10,10,7,0,0,0,12,0,0,0,0,7,57,30,56,0,0,0,0,0,0,0,0,0,0,0,0,0,0,0,0,0,0,0,0,0,0,0,0,0,0,0,0,0,0,0,19,0,0,0,0
0,0,10,10,7,0,0,0,11,0,0,0,0,7,58,57,56,0,0,0,0,0,0,0,0,0,0,0,0,0,0,0,0,0,0,0,0,0,0,0,0,25,23,23,23,23,23,0,7,0,0,0,0
0,0,10,10,7,7,7,7,7,0,0,7,7,7,7,7,7,0,0,7,7,7,7,0,0,0,0,0,55,7,23,23,23,23,23,23,23,23,7,0,0,7,7,7,7,7,7,0,7,7,0,0,0
0,10,0,0,7,52,54,0,0,0,0,0,0,0,0,0,7,0,0,7,0,0,7,0,0,0,0,0,7,7,7,7,7,7,7,7,7,7,7,0,0,7,3,3,3,3,7,0,0,14,0,0,0
0,0,10,0,7,53,53,0,0,0,0,0,0,0,0,0,51,0,0,7,0,0,7,0,0,0,0,0,0,7,0,0,47,47,47,47,47,47,7,0,0,7,3,3,3,3,7,0,0,14,0,0,0
0,10,10,0,7,52,0,0,0,0,0,0,0,0,0,0,7,0,0,7,7,7,7,0,0,0,0,0,0,51,0,0,0,0,0,0,0,26,7,0,0,7,3,3,3,3,7,0,0,14,10,0,0
0,0,10,10,7,50,49,48,0,0,0,0,0,0,0,0,7,0,0,0,0,0,0,0,0,0,0,0,0,7,0,0,0,0,47,0,0,26,7,23,23,7,3,3,3,3,7,0,0,14,10,0,0
0,10,10,0,7,46,45,44,0,0,0,0,0,0,0,0,7,0,0,0,0,0,0,0,0,0,0,0,7,7,20,0,0,20,11,26,0,7,7,7,7,3,3,3,3,3,7,0,0,14,10,10,0
0,10,10,10,7,43,42,41,0,0,0,0,0,0,0,0,7,0,0,0,0,0,0,0,0,0,0,0,30,7,7,0,0,0,16,0,0,35,3,3,3,7,3,3,3,3,7,0,0,14,10,10,0
0,0,0,10,7,40,39,38,0,0,0,0,0,0,0,0,7,0,0,0,0,0,0,0,0,0,0,0,37,29,7,16,0,0,0,0,0,35,3,3,3,3,3,3,3,3,7,0,0,14,0,0,0
0,10,10,0,7,17,0,0,0,0,0,0,0,0,7,7,7,7,7,7,0,0,0,0,0,0,0,0,36,29,7,17,0,0,0,0,0,35,3,3,3,7,3,3,7,7,7,0,0,14,0,0,0
0,10,10,0,7,34,0,0,0,0,0,0,0,0,7,33,32,0,0,31,0,0,0,0,0,0,23,0,30,29,7,17,20,11,26,0,0,0,17,0,0,7,3,3,3,3,7,0,0,14,0,10,0
0,10,10,10,7,17,0,0,0,0,0,0,0,0,0,0,0,0,0,28,0,0,0,0,7,7,27,7,7,7,7,17,20,0,26,0,0,0,17,0,0,25,3,3,3,3,3,24,0,14,10,10,0
0,10,10,10,7,0,0,0,0,0,0,0,0,0,0,0,0,23,23,7,0,0,0,0,7,7,7,7,7,7,7,20,0,0,0,0,0,0,17,0,0,7,3,3,3,3,7,0,0,14,10,10,0
0,0,10,10,7,0,0,0,0,0,0,0,0,0,7,22,7,21,21,7,0,0,0,0,7,7,7,7,7,7,7,20,0,11,0,0,0,0,17,0,0,7,3,3,3,3,7,0,0,14,10,10,0
0,10,10,10,7,0,0,0,0,0,0,0,0,0,7,7,7,7,7,7,7,19,18,7,7,7,7,7,7,7,7,17,16,16,0,0,0,0,15,0,0,7,3,3,3,3,7,0,0,14,0,10,0
0,0,10,10,7,7,7,7,0,0,0,0,0,7,7,7,7,7,7,7,0,0,0,0,7,7,7,7,7,7,7,7,7,7,7,7,7,7,7,7,7,7,7,7,7,7,7,7,7,7,0,0,0
0,10,10,10,11,0,0,0,0,0,0,0,0,0,0,10,10,0,10,0,0,0,0,0,11,0,0,0,0,0,0,0,0,0,0,0,0,0,0,0,0,0,0,0,0,0,0,0,0,11,0,0,0
0,0,0,10,11,10,0,0,0,0,0,0,0,0,0,0,0,0,0,0,0,0,0,0,11,0,0,0,0,0,0,0,0,0,0,10,0,10,0,0,0,0,0,10,0,0,0,0,0,11,0,0,0
0,10,10,0,11,10,0,0,0,0,0,0,0,0,0,0,0,0,0,0,0,0,0,0,13,10,0,0,0,0,10,0,0,0,0,0,0,0,0,0,0,0,0,0,10,0,0,0,0,12,10,10,0
0,10,0,10,11,0,0,0,0,0,0,0,0,0,0,0,0,0,0,0,0,0,0,0,11,0,10,0,10,0,0,0,10,0,0,0,0,0,0,0,0,0,10,0,0,0,0,10,0,11,0,10,0
0,10,10,10,11,11,11,11,0,0,0,0,11,11,11,11,11,11,11,11,0,0,0,0,11,11,11,11,11,11,11,11,11,11,11,11,11,11,11,11,11,11,11,11,11,11,11,11,11,11,10,10,0
0,0,10,10,10,10,0,0,0,0,0,0,0,0,0,10,0,0,0,0,0,0,0,0,10,10,10,10,0,0,10,10,10,10,10,0,0,0,0,0,10,10,10,0,10,0,10,0,10,0,10,0,0
0,0,0,0,0,0,0,0,0,0,0,0,0,0,0,0,0,0,0,0,0,0,0,0,0,0,0,0,0,0,0,0,0,0,0,0,0,0,0,0,0,0,0,0,0,0,0,0,0,0,0,0,0
0,0,0,0,0,0,0,0,0,0,0,0,0,0,0,0,0,0,0,0,0,0,0,0,0,0,0,0,0,0,0,0,0,0,0,0,0,0,0,0,0,0,0,0,0,0,0,0,0,0,0,0,0
0,0,0,0,0,0,0,0,0,0,0,0,0,0,0,0,0,0,0,0,0,0,0,0,0,0,0,0,0,0,0,0,0,0,0,0,0,0,0,0,0,0,0,0,0,0,0,0,0,0,0,0,0
:endlayer
layer: 4
0,0,0,0,0,0,0,0,0,0,0,0,0,0,0,0,0,0,0,0,0,0,0,0,0,0,0,0,0,0,0,0,0,0,0,0,0,0,0,0,0,0,0,0,0,0,0,0,0,0,0,0,0
0,0,0,0,0,0,0,0,0,0,0,0,0,0,0,0,0,0,0,0,0,0,0,0,0,0,0,0,0,0,0,0,0,0,0,0,0,0,0,0,0,0,0,0,0,0,0,0,0,0,0,0,0
0,0,0,0,0,0,0,0,0,0,0,0,0,0,0,0,0,0,0,0,0,0,0,0,0,0,0,142,0,0,0,0,0,0,0,0,0,0,0,0,0,0,0,0,0,0,0,0,0,0,0,0,0
0,0,0,0,8,7,7,7,7,7,7,7,7,8,7,7,7,7,7,7,7,7,8,7,7,7,7,7,141,140,7,7,7,7,7,7,7,7,7,7,7,7,7,7,7,7,7,7,7,7,0,0,0
0,0,0,0,7,0,0,0,17,77,17,0,0,7,0,0,17,139,138,137,22,136,7,0,0,0,0,0,0,0,0,0,0,0,0,80,0,0,0,8,0,0,0,0,0,0,8,0,121,7,0,0,0
0,0,0,0,7,0,0,0,80,0,80,0,0,51,0,0,51,0,0,0,0,0,51,0,0,0,0,0,0,0,0,0,0,0,0,0,0,0,0,7,0,0,0,0,0,0,7,135,0,7,0,0,0
0,0,0,0,7,0,0,0,0,0,0,0,0,7,17,17,17,0,0,0,0,0,7,0,0,0,0,0,0,0,0,0,0,0,0,0,0,0,0,7,0,0,0,0,0,0,7,0,0,7,0,0,0
0,0,0,0,7,0,0,0,0,0,0,0,0,7,17,17,17,128,17,17,17,134,7,115,0,0,0,0,0,0,0,0,0,0,0,0,0,0,0,133,0,0,0,0,0,0,133,0,0,7,0,0,0
0,0,0,0,7,0,0,11,11,0,0,11,0,7,132,47,17,0,0,0,0,0,7,7,7,7,7,7,7,7,7,7,7,7,0,0,0,0,0,7,0,0,0,0,0,23,7,0,0,7,0,0,0
0,0,0,0,7,0,0,0,11,0,0,0,0,7,0,0,17,0,0,0,0,0,0,131,0,7,0,0,0,0,130,124,123,7,0,0,0,0,0,8,7,7,129,7,7,7,8,0,0,7,0,0,0
0,0,0,0,7,0,0,0,0,0,0,0,0,7,0,0,17,128,17,17,0,0,0,17,0,7,0,0,0,0,0,0,105,7,0,0,0,0,0,7,0,0,0,0,0,0,7,0,0,7,0,0,0
0,0,0,0,7,0,0,11,11,0,0,11,0,7,0,0,51,0,0,17,0,0,0,17,0,7,0,0,0,0,0,0,105,7,0,0,0,0,0,7,0,0,0,0,90,0,120,0,0,7,0,0,0
0,0,0,0,7,0,0,0,11,0,0,0,0,7,0,0,17,127,0,17,0,0,0,17,126,7,0,0,0,0,125,124,123,7,0,0,0,0,0,122,0,0,0,0,90,0,7,0,0,7,0,0,0
0,0,0,0,7,0,0,0,0,0,0,0,0,7,7,7,7,7,7,7,7,7,51,7,7,7,7,51,7,7,7,7,7,7,0,0,0,0,0,7,0,0,0,0,90,0,7,0,0,7,0,0,0
0,0,0,0,7,0,0,11,11,0,0,11,0,7,117,121,121,0,0,80,121,0,0,0,0,80,0,0,0,0,0,0,0,80,0,0,0,0,0,8,7,7,120,7,7,7,8,0,115,7,0,0,0
0,0,0,0,7,0,0,0,11,0,0,0,0,7,117,0,0,0,0,0,0,0,0,0,0,0,0,0,0,0,0,0,0,0,0,0,0,0,0,0,0,0,0,0,0,0,0,0,7,7,0,0,0
0,0,0,0,7,0,0,0,0,0,0,0,0,7,117,0,0,0,0,0,0,0,0,0,0,0,0,0,0,0,0,0,0,0,0,0,0,0,0,0,0,0,0,0,0,0,0,0,7,0,0,0,0
0,0,0,0,7,0,0,0,11,0,0,11,0,7,117,0,0,0,0,0,0,0,0,0,0,0,0,0,0,0,0,0,0,0,0,0,0,0,0,0,0,0,0,0,0,0,0,0,119,0,0,0,0
0,0,0,0,7,0,0,0,0,0,0,0,0,7,117,0,0,0,0,0,0,0,0,0,0,0,0,0,0,0,0,0,0,0,0,0,0,0,0,0,0,0,0,0,0,0,0,0,118,0,0,0,0
0,0,0,0,7,0,0,0,11,0,0,114,0,7,117,115,0,0,0,0,0,0,0,0,0,0,0,0,0,0,0,0,0,0,0,0,0,0,0,0,0,0,114,0,0,114,0,0,7,116,0,0,0
0,0,0,0,8,7,7,7,7,0,0,7,7,7,7,7,8,0,0,11,0,0,11,0,0,0,0,0,115,7,0,0,0,114,0,0,0,114,7,0,0,8,7,7,7,7,8,0,7,7,0,0,0
0,0,0,0,7,54,54,0,0,0,0,0,0,0,0,0,7,113,0,0,0,0,0,0,0,0,0,0,7,7,7,7,7,7,7,7,7,7,7,0,0,7,47,47,0,105,7,0,0,14,0,0,0
0,0,0,0,7,53,0,0,0,0,0,0,0,0,0,0,112,0,0,0,0,0,0,0,0,0,0,0,0,7,0,0,0,0,0,0,0,0,7,0,0,7,11,11,0,111,7,0,0,14,0,0,0
0,0,0,0,7,0,0,0,0,0,0,0,0,0,0,0,7,0,0,11,0,0,11,0,0,0,0,0,0,110,0,0,0,0,0,0,0,0,7,0,0,7,0,0,0,105,7,0,0,14,0,0,0
0,0,0,0,7,109,108,107,0,0,0,0,0,0,0,0,106,0,0,0,0,0,0,0,0,0,0,0,0,7,0,0,0,0,0,0,0,0,7,0,0,7,0,0,0,105,7,0,0,14,0,0,0
0,0,0,0,7,104,103,102,0,0,0,0,0,0,0,0,7,0,0,0,0,0,0,0,0,0,0,0,7,7,0,0,0,0,90,0,101,7,7,100,51,7,0,0,0,17,7,0,0,14,0,0,0
0,0,0,0,7,99,98,97,0,0,0,0,0,0,0,0,8,0,0,0,0,0,0,0,0,0,0,0,0,7,7,0,0,0,0,0,0,0,0,0,0,7,0,0,0,17,7,0,0,14,0,0,0
0,0,0,0,8,96,95,94,0,0,0,0,0,0,0,0,7,0,0,0,0,0,0,0,0,0,0,0,0,0,8,0,0,0,0,0,0,0,0,0,0,51,0,0,26,17,7,0,0,14,0,0,0
0,0,0,0,7,17,0,0,0,0,0,0,0,0,7,7,7,7,7,7,0,0,0,0,0,0,0,0,0,0,7,16,0,0,0,0,0,0,17,17,17,7,7,51,7,7,7,0,0,14,0,0,0
0,0,0,0,7,34,0,0,0,0,0,0,0,0,7,0,0,0,0,93,0,0,0,0,0,0,0,0,0,0,7,17,0,90,0,0,0,0,0,0,0,7,0,0,0,0,7,0,0,14,0,0,0
0,0,0,0,7,17,0,0,0,0,0,0,0,0,0,0,0,0,0,92,0,0,0,0,8,17,51,17,17,8,7,17,0,0,0,0,0,0,0,0,0,0,51,0,0,0,51,0,0,14,0,0,0
0,0,0,0,7,0,0,0,0,0,0,0,0,0,0,0,0,0,0,7,0,0,0,0,17,0,0,0,0,0,7,0,0,0,0,0,0,0,0,0,0,7,0,0,0,91,7,0,0,14,0,0,0
0,0,0,0,7,0,0,0,0,0,0,0,0,0,7,0,7,0,0,7,0,0,0,0,17,0,0,0,0,0,7,0,0,90,0,0,0,0,11,0,0,7,0,0,0,89,7,0,0,14,0,0,0
0,0,0,0,7,0,0,0,0,0,0,0,0,0,7,7,7,7,7,7,7,88,87,7,17,11,86,85,84,22,7,17,0,0,0,0,0,0,0,0,0,7,83,82,22,81,7,0,0,14,0,0,0
0,0,0,0,8,7,7,8,0,0,0,0,0,8,7,7,8,7,7,8,0,0,0,0,8,7,7,7,7,7,8,7,7,7,7,7,7,7,7,7,7,8,7,7,7,7,8,14,14,7,0,0,0
0,0,0,0,0,0,0,0,0,0,0,0,0,0,0,0,0,0,0,0,0,0,0,0,0,0,0,80,0,0,0,0,80,0,0,0,0,80,0,0,0,0,0,0,0,0,0,0,0,0,0,0,0
0,0,0,0,0,0,0,0,0,0,0,0,0,0,0,0,0,0,0,0,0,0,0,0,0,0,0,0,0,0,0,0,0,0,0,0,0,0,0,0,0,0,0,0,0,0,0,0,0,0,0,0,0
0,0,0,0,0,0,0,0,0,0,0,0,0,0,0,0,0,0,0,0,0,0,0,0,0,0,0,0,0,0,0,0,0,0,0,0,0,0,0,0,0,0,0,0,0,0,0,0,0,0,0,0,0
0,0,0,0,0,0,0,0,0,0,0,0,0,0,0,0,0,0,0,0,0,0,0,0,0,0,0,0,0,0,0,0,0,0,0,0,0,0,0,0,0,0,0,0,0,0,0,0,0,0,0,0,0
0,0,0,0,79,0,0,79,0,0,0,0,79,0,0,0,0,0,0,79,0,0,0,0,79,0,0,0,0,0,0,0,0,0,0,0,0,0,0,0,0,0,0,0,0,0,0,0,0,79,0,0,0
0,0,0,0,0,0,0,0,0,0,0,0,0,0,0,0,0,0,0,0,0,0,0,0,0,0,0,0,0,0,0,0,0,0,0,0,0,0,0,0,0,0,0,0,0,0,0,0,0,0,0,0,0
0,0,0,0,0,0,0,0,0,0,0,0,0,0,0,0,0,0,0,0,0,0,0,0,0,0,0,0,0,0,0,0,0,0,0,0,0,0,0,0,0,0,0,0,0,0,0,0,0,0,0,0,0
0,0,0,0,0,0,0,0,0,0,0,0,0,0,0,0,0,0,0,0,0,0,0,0,0,0,0,0,0,0,0,0,0,0,0,0,0,0,0,0,0,0,0,0,0,0,0,0,0,0,0,0,0
0,0,0,0,0,0,0,0,0,0,0,0,0,0,0,0,0,0,0,0,0,0,0,0,0,0,0,0,0,0,0,0,0,0,0,0,0,0,0,0,0,0,0,0,0,0,0,0,0,0,0,0,0
:endlayer
layer: 5
0,0,0,0,0,0,0,0,0,0,0,0,0,0,0,0,0,0,0,0,0,0,0,0,0,0,0,0,0,0,0,0,0,0,0,0,0,0,0,0,0,0,0,0,0,0,0,0,0,0,0,0,0
0,0,0,0,0,0,0,0,0,0,0,0,0,0,0,0,0,0,0,0,0,0,0,0,0,0,0,0,0,0,0,0,0,0,0,0,0,0,0,0,0,0,0,0,0,0,0,0,0,0,0,0,0
0,0,0,0,0,0,0,0,0,0,0,0,0,0,0,0,114,0,0,0,0,0,0,0,0,0,0,114,148,148,114,0,0,0,0,0,0,0,0,0,0,0,0,0,0,0,0,0,0,0,0,0,0
0,0,0,0,8,7,7,7,7,7,7,7,7,8,7,7,7,7,7,7,7,7,8,7,11,11,11,7,7,7,7,11,11,11,11,11,11,11,16,16,16,16,16,16,16,16,16,16,0,79,0,0,0
0,0,0,0,7,135,0,0,17,77,17,0,101,7,0,80,17,0,0,0,0,0,7,135,0,0,0,80,146,146,80,0,0,0,0,0,0,0,0,8,80,0,0,0,0,101,8,0,0,0,0,0,0
0,0,0,0,7,0,0,0,0,0,0,0,0,165,0,0,164,0,0,0,0,0,163,0,0,0,0,0,0,0,0,0,0,0,0,0,0,0,0,7,0,0,0,0,0,0,7,0,0,0,0,0,0
0,0,0,0,120,0,0,0,0,0,0,0,0,7,17,17,17,0,0,0,0,0,7,0,0,0,0,0,0,0,0,0,0,0,0,0,0,0,0,7,0,0,0,0,0,0,7,0,0,0,0,0,0
0,0,0,0,7,0,0,0,0,0,0,0,0,7,17,47,17,0,0,0,0,0,7,0,0,114,0,0,0,0,0,0,0,0,0,0,0,0,0,7,0,0,0,0,0,0,7,0,0,0,0,0,0
0,0,0,0,7,11,11,11,11,0,0,11,11,7,0,0,17,0,0,0,0,101,17,7,7,7,17,120,120,17,120,120,17,7,0,0,0,0,0,7,0,114,0,0,114,0,7,0,0,0,0,0,0
0,0,0,0,120,0,0,0,11,0,0,0,101,7,0,0,17,0,0,0,0,0,0,0,0,17,0,0,0,0,0,0,0,17,0,0,0,0,101,8,7,7,7,7,7,23,8,135,0,0,0,0,0
0,0,0,0,7,135,0,0,0,0,0,0,0,7,0,0,17,0,0,0,0,0,0,0,0,17,0,0,0,0,0,0,0,120,0,0,0,0,0,7,135,0,0,0,0,101,7,0,0,0,0,0,0
0,0,0,0,7,11,11,11,11,0,0,11,11,7,0,0,162,0,0,0,0,0,0,0,0,17,0,0,0,0,0,0,0,120,0,0,0,0,0,7,0,0,0,0,0,0,7,0,0,0,0,0,0
0,0,0,0,120,0,0,0,11,0,0,0,101,7,0,114,17,0,0,0,0,114,0,0,0,17,0,0,0,0,0,0,0,17,0,0,0,0,0,7,0,0,0,0,0,0,7,0,0,0,0,0,0
0,0,0,0,7,135,0,0,0,0,0,0,0,7,7,7,7,17,8,120,8,17,161,17,7,7,17,160,17,120,120,120,17,7,0,0,0,0,0,7,114,0,0,0,0,101,7,0,0,0,0,0,0
0,0,0,0,7,11,11,11,11,0,0,11,11,7,0,80,0,0,0,0,0,159,0,80,0,0,0,0,0,0,0,0,0,0,0,0,0,0,101,8,7,7,7,7,7,7,8,135,0,0,0,0,0
0,0,0,0,120,0,0,0,11,0,0,0,101,7,0,0,0,0,0,0,0,0,0,0,0,0,0,0,0,0,0,0,0,0,0,0,0,0,0,80,0,0,0,80,0,0,80,0,0,79,0,0,0
0,0,0,0,7,135,0,0,0,0,0,0,0,120,0,0,0,0,0,0,0,0,0,0,0,0,0,0,0,0,0,0,0,0,0,0,0,0,0,0,0,0,0,0,0,0,0,0,7,135,0,0,0
0,0,0,0,7,11,11,11,11,0,0,11,11,7,0,0,0,0,0,0,0,0,0,0,0,0,0,0,0,0,0,0,0,0,0,0,0,0,0,0,0,0,0,0,0,0,0,158,7,157,0,0,0
0,0,0,0,120,0,0,0,0,0,0,0,0,7,135,0,0,0,0,0,0,0,0,0,0,0,0,0,0,0,0,0,0,0,0,0,0,0,0,0,0,0,0,0,0,0,0,158,7,157,0,0,0
0,0,0,0,7,135,0,0,11,0,0,0,0,7,0,0,114,0,0,0,0,0,0,0,0,0,0,0,0,114,0,0,0,0,0,0,0,0,0,0,0,0,0,0,0,0,0,0,7,135,0,0,0
0,0,0,0,8,7,7,7,7,0,0,7,7,7,7,7,8,135,0,11,0,0,11,0,0,0,0,0,0,7,0,0,0,0,0,0,0,0,7,0,0,8,17,120,120,17,8,0,0,0,0,0,0
0,0,0,0,7,53,53,0,80,0,0,80,0,0,0,0,7,0,0,0,11,11,0,0,0,0,0,0,7,7,7,120,7,7,7,120,7,7,7,0,0,17,0,0,0,105,17,0,0,0,0,0,0
0,0,0,0,7,0,0,0,0,0,0,0,0,0,0,101,7,0,0,0,11,11,0,0,0,0,0,0,101,7,0,0,0,0,0,0,0,0,7,0,0,120,156,90,0,0,120,0,0,0,0,0,0
0,0,0,0,7,0,0,0,0,0,0,0,0,0,0,0,7,0,0,11,0,0,11,0,0,0,0,0,0,7,0,0,0,0,0,0,0,0,120,0,0,120,0,0,0,105,17,0,0,0,0,0,0
0,0,0,0,7,0,0,0,0,0,0,0,0,0,0,0,7,0,0,0,0,0,0,0,0,0,0,0,101,7,0,0,0,0,0,0,0,0,7,0,0,17,0,0,0,105,17,0,0,0,0,0,0
0,0,0,0,7,0,0,0,0,0,0,0,0,0,0,0,7,0,0,0,0,0,0,0,0,0,0,0,7,7,0,0,0,0,0,0,0,7,7,155,154,7,135,0,0,17,17,0,0,0,0,0,0
0,0,0,0,7,0,0,0,0,0,0,0,0,0,0,101,8,135,0,0,0,0,0,0,0,0,0,0,0,7,7,0,0,0,0,0,0,0,0,0,0,7,0,0,0,47,17,0,0,0,0,0,0
0,0,0,0,8,114,0,0,0,0,0,0,0,0,0,0,7,0,0,114,0,0,0,0,0,0,0,0,0,0,8,0,0,0,0,0,0,0,0,0,0,153,0,0,0,0,7,0,0,0,0,0,0
0,0,0,0,7,17,135,0,0,0,0,0,0,0,7,7,7,106,106,7,135,0,0,0,0,0,0,0,0,0,7,0,0,0,0,0,0,0,17,11,11,7,7,152,7,7,7,0,0,0,0,0,0
0,0,0,0,7,34,0,0,0,0,0,0,0,101,7,135,0,0,0,106,0,0,0,0,114,0,0,114,0,0,7,16,0,0,0,0,0,0,11,0,0,7,0,0,0,0,7,135,0,0,0,0,0
0,0,0,0,7,17,135,0,0,0,0,0,0,0,0,0,0,0,0,106,0,0,0,0,8,17,151,17,17,8,7,17,135,0,0,0,0,0,11,0,0,0,150,0,0,0,149,0,0,0,0,0,0
0,0,0,0,7,0,0,0,0,0,0,0,0,0,0,0,106,106,106,7,0,0,0,0,17,0,0,0,0,80,7,17,0,0,0,0,0,0,11,0,0,7,0,0,0,0,7,135,0,0,0,0,0
0,0,0,0,7,0,0,0,0,0,0,0,0,101,7,114,7,0,0,7,114,148,148,114,120,0,0,0,0,0,7,17,0,0,0,0,0,0,11,0,101,7,0,0,0,0,120,0,0,0,0,0,0
0,0,0,0,7,0,114,0,0,0,0,0,0,0,7,7,7,7,7,7,7,7,7,7,17,90,0,0,0,0,7,17,0,0,0,0,0,0,11,0,0,7,147,0,0,0,7,0,0,0,0,0,0
0,0,0,0,8,7,7,8,0,0,0,0,0,8,7,7,8,7,7,8,80,146,146,80,8,7,7,7,7,7,8,7,7,7,120,7,120,7,120,7,7,8,7,7,120,7,8,0,0,0,0,0,0
0,0,0,0,0,0,0,0,0,0,0,0,0,145,0,0,0,0,0,144,0,0,0,0,143,0,0,0,0,0,0,0,0,0,0,0,0,0,0,0,0,0,0,0,0,0,0,0,0,0,0,0,0
0,0,0,0,0,0,0,0,0,0,0,0,0,0,0,0,0,0,0,0,0,0,0,0,0,0,0,0,0,0,0,0,0,0,0,0,0,0,0,0,0,0,0,0,0,0,0,0,0,0,0,0,0
0,0,0,0,0,0,0,0,0,0,0,0,0,0,0,0,0,0,0,0,0,0,0,0,0,0,0,0,0,0,0,0,0,0,0,0,0,0,0,0,0,0,0,0,0,0,0,0,0,0,0,0,0
0,0,0,0,0,0,0,0,0,0,0,0,0,0,0,0,0,0,0,0,0,0,0,0,0,0,0,0,0,0,0,0,0,0,0,0,0,0,0,0,0,0,0,0,0,0,0,0,0,0,0,0,0
0,0,0,0,0,0,0,0,0,0,0,0,0,0,0,0,0,0,0,0,0,0,0,0,0,0,0,0,0,0,0,0,0,0,0,0,0,0,0,0,0,0,0,0,0,0,0,0,0,0,0,0,0
0,0,0,0,0,0,0,0,0,0,0,0,0,0,0,0,0,0,0,0,0,0,0,0,0,0,0,0,0,0,0,0,0,0,0,0,0,0,0,0,0,0,0,0,0,0,0,0,0,0,0,0,0
0,0,0,0,0,0,0,0,0,0,0,0,0,0,0,0,0,0,0,0,0,0,0,0,0,0,0,0,0,0,0,0,0,0,0,0,0,0,0,0,0,0,0,0,0,0,0,0,0,0,0,0,0
0,0,0,0,0,0,0,0,0,0,0,0,0,0,0,0,0,0,0,0,0,0,0,0,0,0,0,0,0,0,0,0,0,0,0,0,0,0,0,0,0,0,0,0,0,0,0,0,0,0,0,0,0
0,0,0,0,0,0,0,0,0,0,0,0,0,0,0,0,0,0,0,0,0,0,0,0,0,0,0,0,0,0,0,0,0,0,0,0,0,0,0,0,0,0,0,0,0,0,0,0,0,0,0,0,0
:endlayer
layer: 6
0,0,0,0,0,0,0,0,0,0,0,0,0,0,0,0,0,0,0,0,0,0,0,0,0,0,0,0,0,0,0,0,0,0,0,0,0,0,0,0,0,0,0,0,0,0,0,0,0,0,0,0,0
0,0,0,0,0,0,0,0,0,0,0,0,0,0,0,0,0,0,0,0,0,0,0,0,0,0,0,0,0,0,0,0,0,0,0,0,0,0,0,0,0,0,0,0,0,0,0,0,0,0,0,0,0
0,0,0,0,114,0,0,0,0,0,0,0,0,114,0,0,0,0,0,0,0,0,0,20,0,0,0,16,16,16,16,0,0,0,0,0,0,0,0,0,0,0,0,0,0,0,0,0,0,0,0,0,0
0,0,0,101,8,7,7,7,7,7,7,7,7,8,8,8,8,8,8,8,8,8,8,20,0,0,26,7,7,7,7,20,0,0,0,0,0,0,0,0,0,0,0,0,0,0,0,0,0,0,0,0,0
0,0,0,0,7,17,17,17,17,77,17,17,17,7,17,17,17,135,169,168,167,101,7,20,0,0,0,47,47,47,47,0,0,0,0,0,0,0,16,16,16,16,16,16,16,16,16,16,0,0,0,0,0
0,0,0,0,7,17,17,17,17,17,17,17,17,7,17,17,17,0,0,0,0,0,7,20,0,0,0,0,0,0,0,0,0,0,0,0,0,0,0,8,3,3,3,3,3,3,8,0,0,0,0,0,0
0,0,0,0,7,17,17,17,17,17,17,17,17,7,17,47,17,0,0,0,0,0,7,20,0,0,0,0,0,0,0,0,0,0,0,0,0,0,0,8,3,3,3,3,3,0,8,0,0,0,0,0,0
0,0,0,0,7,17,17,17,17,0,0,17,17,7,17,0,17,11,11,11,11,11,7,20,0,0,0,0,0,0,0,0,0,0,0,0,0,0,0,8,3,3,3,3,3,0,8,0,0,0,0,0,0
0,0,0,0,7,17,17,17,17,0,0,17,17,7,0,0,17,0,0,0,0,0,17,7,7,7,17,17,17,17,17,17,17,7,0,0,0,0,0,8,3,3,3,3,3,0,8,0,0,0,0,0,0
0,0,0,0,7,17,17,17,17,0,0,17,17,7,0,0,17,0,0,0,0,0,0,11,0,17,0,0,0,0,0,0,0,17,0,0,0,0,0,8,3,3,3,3,3,0,8,0,0,0,0,0,0
0,0,0,0,7,17,17,17,17,0,0,17,17,7,0,0,17,11,11,11,0,0,0,11,0,17,0,0,0,0,0,0,0,120,0,0,0,0,0,8,3,3,3,3,3,23,8,0,0,0,0,0,0
0,0,0,101,7,17,17,17,17,0,0,17,17,7,0,0,17,0,0,11,0,0,0,11,0,17,0,0,0,0,0,0,0,120,0,0,0,0,0,8,3,3,3,3,3,3,8,0,0,0,0,0,0
0,0,0,0,7,17,17,17,17,0,0,17,17,7,0,0,17,114,0,11,0,0,0,11,0,17,0,0,114,0,0,0,114,17,0,0,0,0,0,8,3,3,3,3,3,3,8,0,0,0,0,0,0
0,0,0,0,7,17,17,17,17,0,0,17,17,7,7,7,7,17,17,17,17,17,17,17,7,7,17,17,17,120,120,120,17,7,135,0,0,0,0,8,3,3,3,3,3,3,8,0,0,0,0,0,0
0,0,0,0,7,17,17,17,17,0,0,17,17,7,47,47,47,47,47,47,47,47,47,47,47,0,0,0,0,0,0,0,0,0,0,0,0,0,0,8,8,8,8,8,8,8,8,0,0,0,0,0,0
0,0,0,0,7,17,17,17,17,0,0,17,17,7,0,0,0,0,0,0,0,0,0,0,0,0,0,0,0,0,0,0,0,0,0,0,0,0,166,166,166,166,166,166,166,166,166,166,16,0,0,0,0
0,0,0,0,7,17,17,17,17,0,0,17,17,7,0,0,0,0,0,0,0,0,0,0,0,0,0,0,0,0,0,0,0,0,0,0,0,0,0,0,0,0,0,0,0,0,0,26,7,20,0,0,0
0,0,0,101,7,17,17,17,17,0,0,17,17,7,0,0,0,0,0,0,0,0,0,0,0,0,0,0,0,0,0,0,0,0,0,0,0,0,0,0,0,0,0,0,0,0,0,26,7,20,0,0,0
0,0,0,0,7,17,17,17,17,17,17,17,17,7,0,0,0,0,0,0,0,0,0,0,0,0,0,0,0,0,0,0,0,0,0,0,0,0,0,0,0,0,0,0,0,0,0,26,7,20,0,0,0
0,0,0,0,7,17,17,17,17,17,17,17,17,7,0,0,0,0,0,114,0,0,114,0,0,0,0,0,0,0,0,0,0,0,0,0,0,0,0,0,0,114,0,0,0,0,0,26,7,20,0,0,0
0,0,0,0,8,7,7,7,7,7,7,7,7,7,7,7,8,0,0,7,7,7,7,135,0,0,0,0,0,7,0,0,0,0,0,0,0,0,7,0,101,8,17,120,120,17,8,135,47,0,0,0,0
0,0,0,0,7,0,53,0,0,0,0,0,0,0,0,0,7,0,0,7,7,7,7,0,0,0,0,0,7,7,7,120,7,7,7,120,7,7,7,0,0,17,0,0,0,105,17,0,0,0,0,0,0
0,0,0,0,7,0,0,0,0,0,0,0,0,0,0,0,7,0,0,7,7,7,7,0,0,0,0,0,0,7,0,0,0,0,0,0,80,0,7,0,0,120,0,0,0,0,120,0,0,0,0,0,0
0,0,0,0,7,0,0,0,0,0,0,0,0,0,0,0,7,0,0,7,7,7,7,135,0,0,0,0,0,7,135,0,0,0,0,0,0,0,120,0,0,120,0,0,0,105,17,135,0,0,0,0,0
0,0,0,0,7,0,0,0,0,0,0,0,0,0,0,0,7,0,0,0,0,0,0,0,0,0,0,0,0,7,0,0,0,0,0,0,0,0,7,114,114,17,0,0,0,105,17,0,0,0,0,0,0
0,0,0,0,7,0,0,0,0,0,0,0,0,0,0,0,7,0,0,0,0,0,0,0,0,0,0,0,7,7,114,0,0,0,0,0,101,7,7,7,7,7,0,0,0,47,17,0,0,0,0,0,0
0,0,0,0,7,0,0,0,0,0,0,0,0,0,0,0,8,0,0,0,0,0,0,0,0,0,0,0,0,7,7,135,0,0,0,0,0,80,0,80,0,7,0,0,0,0,17,135,0,0,0,0,0
0,0,0,0,8,0,0,0,0,0,0,0,0,0,0,0,7,0,0,0,0,0,0,0,0,0,0,0,0,0,8,0,0,0,0,0,0,0,0,0,101,7,0,0,0,0,7,0,0,0,0,0,0
0,0,0,0,7,17,0,0,0,0,0,0,0,0,7,7,7,7,7,7,0,0,0,0,0,0,0,0,0,0,7,0,0,0,0,0,0,0,17,11,11,7,7,7,7,7,7,0,0,0,0,0,0
0,0,0,0,7,34,0,0,0,0,0,0,0,0,7,7,7,0,0,7,81,81,81,81,81,81,166,81,81,81,7,0,0,0,0,0,0,0,80,0,0,7,0,0,80,0,7,0,0,0,0,0,0
0,0,0,0,7,17,0,0,0,0,0,0,0,0,7,7,7,0,0,7,0,0,0,101,8,17,17,17,17,8,7,16,0,0,0,0,0,0,0,0,0,7,0,0,0,101,7,0,0,0,0,0,0
0,0,0,0,7,0,0,0,0,0,0,0,0,0,7,7,7,106,106,7,0,0,0,0,17,0,0,0,0,0,7,17,0,0,0,0,0,0,0,0,0,7,0,0,0,0,7,0,0,0,0,0,0
0,0,0,0,7,0,0,0,0,0,0,0,0,0,7,7,7,0,0,7,0,0,0,0,17,0,0,0,0,0,7,17,0,0,0,0,0,0,0,0,0,7,0,0,0,0,120,0,0,0,0,0,0
0,0,0,0,7,0,0,0,0,0,0,0,0,0,7,7,7,7,7,7,7,7,7,7,17,0,0,0,0,0,7,17,0,114,0,114,0,114,0,114,0,7,135,0,0,114,7,0,0,0,0,0,0
0,0,0,0,8,7,7,8,0,0,0,0,0,8,7,7,8,7,7,8,0,0,0,0,8,7,7,7,7,7,8,7,7,7,120,7,120,7,120,7,7,8,7,7,120,7,8,0,0,0,0,0,0
0,0,0,0,0,0,80,0,0,0,0,0,0,0,80,0,0,0,0,0,0,0,0,0,0,0,0,0,0,0,0,0,0,0,0,0,0,0,0,0,0,80,0,0,0,0,80,0,0,0,0,0,0
0,0,0,0,0,0,0,0,0,0,0,0,0,0,0,0,0,0,0,0,0,0,0,0,0,0,0,0,0,0,0,0,0,0,0,0,0,0,0,0,0,0,0,0,0,0,0,0,0,0,0,0,0
0,0,0,0,0,0,0,0,0,0,0,0,0,0,0,0,0,0,0,0,0,0,0,0,0,0,0,0,0,0,0,0,0,0,0,0,0,0,0,0,0,0,0,0,0,0,0,0,0,0,0,0,0
0,0,0,0,0,0,0,0,0,0,0,0,0,0,0,0,0,0,0,0,0,0,0,0,0,0,0,0,0,0,0,0,0,0,0,0,0,0,0,0,0,0,0,0,0,0,0,0,0,0,0,0,0
0,0,0,0,0,0,0,0,0,0,0,0,0,0,0,0,0,0,0,0,0,0,0,0,0,0,0,0,0,0,0,0,0,0,0,0,0,0,0,0,0,0,0,0,0,0,0,0,0,0,0,0,0
0,0,0,0,0,0,0,0,0,0,0,0,0,0,0,0,0,0,0,0,0,0,0,0,0,0,0,0,0,0,0,0,0,0,0,0,0,0,0,0,0,0,0,0,0,0,0,0,0,0,0,0,0
0,0,0,0,0,0,0,0,0,0,0,0,0,0,0,0,0,0,0,0,0,0,0,0,0,0,0,0,0,0,0,0,0,0,0,0,0,0,0,0,0,0,0,0,0,0,0,0,0,0,0,0,0
0,0,0,0,0,0,0,0,0,0,0,0,0,0,0,0,0,0,0,0,0,0,0,0,0,0,0,0,0,0,0,0,0,0,0,0,0,0,0,0,0,0,0,0,0,0,0,0,0,0,0,0,0
0,0,0,0,0,0,0,0,0,0,0,0,0,0,0,0,0,0,0,0,0,0,0,0,0,0,0,0,0,0,0,0,0,0,0,0,0,0,0,0,0,0,0,0,0,0,0,0,0,0,0,0,0
:endlayer
layer: 7
0,0,0,0,0,0,0,0,0,0,0,0,0,0,0,0,0,0,0,0,0,0,0,0,0,0,0,0,0,0,0,0,0,0,0,0,0,0,0,0,0,0,0,0,0,0,0,0,0,0,0,0,0
0,0,0,0,0,0,0,0,0,0,0,0,0,0,0,0,0,0,0,0,0,0,0,0,0,0,0,0,0,0,0,0,0,0,0,0,0,0,0,0,0,0,0,0,0,0,0,0,0,0,0,0,0
0,0,0,26,0,0,0,0,0,0,0,0,0,0,0,0,0,0,0,0,0,0,20,0,0,0,0,0,0,0,0,0,0,0,0,0,0,0,0,0,0,0,0,0,0,0,0,0,0,0,0,0,0
0,0,0,26,8,8,8,8,8,8,8,8,8,8,17,17,17,17,17,120,17,17,20,0,0,0,0,174,174,174,174,0,0,0,0,0,0,0,0,0,0,0,0,0,0,0,0,0,0,0,0,0,0
0,0,0,26,7,0,0,0,0,77,0,0,0,7,0,0,17,0,0,0,0,0,20,0,0,0,0,0,0,0,0,0,0,0,0,0,0,0,0,0,0,0,0,0,0,0,0,0,0,0,0,0,0
0,0,0,26,7,0,0,0,0,0,0,0,0,51,0,0,26,0,0,0,0,0,20,0,0,0,0,0,0,0,0,0,0,0,0,0,0,0,16,16,16,16,16,16,16,16,16,16,0,0,0,0,0
0,0,0,26,7,0,0,0,11,11,11,11,0,7,0,0,17,0,0,0,0,0,20,0,0,0,0,0,0,0,0,0,0,0,0,0,0,0,174,7,0,0,0,181,3,0,7,0,0,0,0,0,0
0,0,0,26,7,0,0,0,11,0,0,11,0,7,0,0,17,11,11,11,11,11,20,0,0,0,0,0,0,0,0,0,0,114,0,0,0,0,174,7,180,179,0,0,11,0,7,0,0,0,0,0,0
0,0,0,26,7,0,0,0,11,0,0,11,0,7,0,0,17,0,0,0,0,0,20,16,7,7,17,17,17,17,17,17,17,7,135,0,0,0,174,7,0,0,0,0,11,0,7,0,0,0,0,0,0
0,0,0,26,7,0,0,0,11,0,0,11,0,7,0,0,17,0,0,0,0,0,0,11,0,17,80,0,0,0,0,0,80,17,0,0,0,0,174,7,0,0,0,0,0,0,7,0,0,0,0,0,0
0,0,0,26,7,0,0,0,11,0,0,11,0,7,0,0,17,11,11,11,0,0,0,11,0,17,0,0,0,0,0,0,0,17,0,0,0,0,174,7,0,0,0,0,0,0,7,0,0,0,0,0,0
0,0,0,26,7,0,0,0,11,0,0,11,0,7,0,0,17,0,0,11,0,0,0,11,0,17,0,0,0,0,0,0,0,17,0,0,0,0,174,7,0,0,178,178,0,0,7,0,0,0,0,0,0
0,0,0,26,7,0,0,0,11,0,0,11,0,7,0,0,17,0,0,11,0,0,0,11,0,17,0,0,0,0,0,0,0,17,0,0,0,0,174,7,177,0,176,176,0,175,7,0,0,0,0,0,0
0,0,0,26,7,0,0,0,11,0,0,11,0,7,17,47,47,47,47,47,47,47,47,47,7,7,17,17,17,17,17,17,17,7,0,0,0,0,174,7,7,7,7,7,7,7,7,0,0,0,0,0,0
0,0,0,26,7,0,0,0,11,0,0,11,0,7,20,0,0,0,0,0,0,0,0,0,0,0,0,0,0,0,0,0,0,0,0,0,0,0,47,47,47,47,47,47,47,47,47,47,0,0,0,0,0
0,0,0,26,7,0,0,0,11,0,0,11,0,7,20,0,0,0,0,0,0,0,0,0,0,0,0,0,0,0,0,0,0,0,0,0,0,0,0,0,0,0,0,0,0,0,0,0,0,0,0,0,0
0,0,0,26,7,0,0,0,11,0,0,11,0,7,20,0,0,0,0,0,0,0,0,0,0,0,0,0,0,0,0,0,0,0,0,0,0,0,0,0,0,0,0,0,0,0,0,0,174,0,0,0,0
0,0,0,26,7,0,0,0,11,0,0,11,0,7,20,0,0,0,0,0,0,0,0,0,0,0,0,0,0,0,0,0,0,0,0,0,0,0,0,0,0,0,0,0,0,0,0,0,174,0,0,0,0
0,0,0,26,7,0,0,0,11,11,11,11,0,7,20,0,0,0,0,0,0,0,0,0,0,0,0,0,0,0,0,0,0,0,0,0,0,0,0,0,0,0,0,0,0,0,0,0,174,0,0,0,0
0,0,0,26,7,0,0,0,0,0,0,0,0,7,20,0,0,0,0,0,0,0,0,0,0,0,0,0,0,0,0,0,0,0,0,0,0,0,0,0,0,0,0,0,0,0,114,0,174,0,0,0,0
0,0,0,101,8,7,16,7,7,7,7,7,7,7,7,7,8,0,0,79,0,0,79,0,0,0,0,0,0,7,0,0,0,0,0,0,0,0,7,0,0,8,17,17,17,17,8,0,0,0,0,0,0
0,0,0,0,7,0,52,0,0,0,0,0,0,0,0,0,7,0,0,0,0,0,0,0,0,0,0,0,7,7,7,7,7,7,7,7,7,7,7,7,7,17,17,17,17,17,17,0,0,0,0,0,0
0,0,0,0,7,0,0,0,0,0,0,0,0,0,0,0,7,0,0,0,0,0,0,0,0,0,0,173,7,7,7,7,7,172,0,0,0,172,7,0,0,17,17,17,17,17,17,0,0,0,0,0,0
0,0,0,0,7,0,0,0,0,0,0,0,0,0,0,0,7,0,0,79,0,0,79,0,0,0,0,173,7,7,7,7,7,172,0,0,0,172,7,0,0,17,17,17,17,17,17,0,0,0,0,0,0
0,0,0,0,7,0,0,0,0,0,0,0,0,0,0,0,7,0,0,0,0,0,0,0,0,0,0,173,7,7,7,7,7,172,0,0,0,172,7,0,0,17,17,17,17,47,17,0,0,0,0,0,0
0,0,0,0,7,0,0,0,0,0,171,0,0,0,0,0,7,0,0,0,0,0,0,0,0,0,0,0,7,7,170,170,170,170,170,170,170,7,7,7,7,7,17,17,17,0,17,0,0,0,0,0,0
0,0,0,0,7,0,0,0,0,0,0,0,0,0,0,0,8,0,0,0,0,0,0,0,0,0,0,0,0,7,7,0,0,0,0,0,0,0,0,0,0,17,17,17,0,0,17,0,0,0,0,0,0
0,0,0,101,8,0,0,0,0,0,0,0,0,0,0,0,7,0,0,0,0,0,0,0,0,0,0,0,0,0,8,0,0,0,0,0,0,0,0,0,0,17,17,17,0,0,7,0,0,0,0,0,0
0,0,0,0,7,17,0,0,0,0,0,0,0,0,7,7,7,23,23,23,0,0,0,0,0,0,0,0,0,0,7,0,0,0,0,0,0,0,17,11,11,7,7,7,7,7,7,0,0,0,0,0,0
0,0,0,0,7,34,0,0,0,0,0,0,0,0,7,7,7,7,7,7,0,0,0,0,0,0,0,0,0,0,7,0,0,0,0,0,0,0,0,0,0,7,17,17,17,17,7,0,0,0,0,0,0
0,0,0,0,7,17,0,0,0,0,0,0,0,0,7,7,7,7,7,7,16,16,16,16,16,16,16,16,16,16,7,0,0,0,0,0,0,0,0,0,0,7,17,17,17,17,7,0,0,0,0,0,0
0,0,0,0,7,0,0,0,0,0,0,0,0,0,7,7,7,7,7,7,7,7,7,7,8,0,0,0,0,0,7,16,0,0,0,0,0,0,0,0,0,7,17,17,17,17,7,0,0,0,0,0,0
0,0,0,0,7,0,0,0,0,0,0,0,0,0,7,7,7,0,0,7,7,7,7,7,8,0,0,0,0,0,7,17,0,0,0,0,0,0,0,0,0,7,17,17,17,17,7,0,0,0,0,0,0
0,0,0,0,7,0,0,0,0,0,0,0,0,0,7,7,7,7,7,7,7,7,7,7,8,0,0,0,0,0,7,17,0,0,0,0,0,0,0,0,0,7,17,17,17,17,7,0,0,0,0,0,0
0,0,0,101,8,7,7,8,7,7,7,7,7,8,7,7,8,61,61,61,47,47,47,47,47,47,47,47,47,47,8,7,7,7,120,7,120,7,120,7,7,8,7,7,7,7,8,0,0,0,0,0,0
0,0,0,0,80,0,0,0,0,0,0,0,0,0,0,0,80,0,0,0,0,0,0,0,0,0,0,0,0,0,0,0,0,0,0,0,0,0,0,0,0,0,0,0,0,0,0,0,0,0,0,0,0
0,0,0,0,0,0,0,0,0,0,0,0,0,0,0,0,0,0,0,0,0,0,0,0,0,0,0,0,0,0,0,0,0,0,0,0,0,0,0,0,0,0,0,0,0,0,0,0,0,0,0,0,0
0,0,0,0,0,0,0,0,0,0,0,0,0,0,0,0,0,0,0,0,0,0,0,0,0,0,0,0,0,0,0,0,0,0,0,0,0,0,0,0,0,0,0,0,0,0,0,0,0,0,0,0,0
0,0,0,0,0,0,0,0,0,0,0,0,0,0,0,0,0,0,0,0,0,0,0,0,0,0,0,0,0,0,0,0,0,0,0,0,0,0,0,0,0,0,0,0,0,0,0,0,0,0,0,0,0
0,0,0,0,0,0,0,0,0,0,0,0,0,0,0,0,0,0,0,0,0,0,0,0,0,0,0,0,0,0,0,0,0,0,0,0,0,0,0,0,0,0,0,0,0,0,0,0,0,0,0,0,0
0,0,0,0,0,0,0,0,0,0,0,0,0,0,0,0,0,0,0,0,0,0,0,0,0,0,0,0,0,0,0,0,0,0,0,0,0,0,0,0,0,0,0,0,0,0,0,0,0,0,0,0,0
0,0,0,0,0,0,0,0,0,0,0,0,0,0,0,0,0,0,0,0,0,0,0,0,0,0,0,0,0,0,0,0,0,0,0,0,0,0,0,0,0,0,0,0,0,0,0,0,0,0,0,0,0
0,0,0,0,0,0,0,0,0,0,0,0,0,0,0,0,0,0,0,0,0,0,0,0,0,0,0,0,0,0,0,0,0,0,0,0,0,0,0,0,0,0,0,0,0,0,0,0,0,0,0,0,0
0,0,0,0,0,0,0,0,0,0,0,0,0,0,0,0,0,0,0,0,0,0,0,0,0,0,0,0,0,0,0,0,0,0,0,0,0,0,0,0,0,0,0,0,0,0,0,0,0,0,0,0,0
:endlayer
layer: 8
0,0,0,0,0,0,0,0,0,0,0,0,0,0,0,0,0,0,0,0,0,0,0,0,0,0,0,0,0,0,0,0,0,0,0,0,0,0,0,0,0,0,0,0,0,0,0,0,0,0,0,0,0
0,0,0,0,0,0,0,0,0,0,0,0,0,0,0,0,0,0,0,0,0,0,0,0,0,0,0,0,0,0,0,0,0,0,0,0,0,0,0,0,0,0,0,0,0,0,0,0,0,0,0,0,0
0,0,0,0,26,0,0,0,0,0,0,0,0,0,0,0,0,0,0,0,0,20,0,0,0,0,0,0,0,0,0,0,0,0,0,0,0,0,0,0,0,0,0,0,0,0,0,0,0,0,0,0,0
0,0,0,0,26,17,17,17,17,17,17,17,17,17,17,120,17,17,17,17,17,20,0,0,0,0,0,0,0,0,0,0,0,0,0,0,0,0,0,0,0,0,0,0,0,0,0,0,0,0,0,0,0
0,0,0,0,26,0,80,0,0,0,0,80,0,17,0,0,17,17,17,17,17,20,0,0,0,0,0,0,0,0,0,0,0,0,0,0,0,0,0,0,0,0,0,0,0,0,0,0,0,0,0,0,0
0,0,0,0,26,0,0,0,0,0,0,0,0,187,0,0,0,26,17,17,17,20,0,0,0,0,0,0,0,0,0,0,0,0,0,0,0,0,0,0,0,0,0,0,0,0,0,0,0,0,0,0,0
0,0,0,0,26,0,0,0,79,0,0,0,0,17,0,0,17,17,17,17,17,20,0,0,0,0,0,0,0,0,0,0,0,0,0,0,0,0,16,16,16,16,16,16,16,16,16,16,0,0,0,0,0
0,0,0,0,26,0,0,0,0,0,0,0,0,17,114,0,17,17,17,17,17,20,0,0,16,16,16,16,16,16,16,16,16,16,16,0,0,0,0,7,0,0,0,0,0,0,7,0,0,0,0,0,0
0,0,0,0,26,0,0,0,0,0,0,0,0,17,17,17,17,17,17,17,17,20,0,0,0,7,7,7,7,7,7,7,7,7,0,0,0,0,0,7,0,0,0,0,0,0,7,0,0,0,0,0,0
0,0,0,0,26,0,0,0,0,0,0,0,0,17,17,17,17,17,17,17,17,20,16,16,16,7,7,7,7,7,7,7,7,7,0,0,0,0,0,133,0,0,0,0,0,0,133,0,0,0,0,0,0
0,0,0,0,26,0,0,0,0,0,0,0,0,17,17,17,17,17,17,17,17,17,17,17,17,7,7,7,7,7,7,7,7,7,0,0,0,0,0,133,0,0,0,0,0,0,133,0,0,0,0,0,0
0,0,0,0,26,0,0,0,0,0,0,0,0,17,17,17,17,17,17,17,17,17,17,17,17,7,7,7,7,7,7,7,7,7,0,0,0,0,0,7,0,0,0,0,0,0,7,0,0,0,0,0,0
0,0,0,0,26,0,0,0,0,0,0,0,0,17,47,47,47,47,47,47,47,47,47,47,47,7,7,7,7,7,7,7,7,7,0,0,0,0,0,7,135,0,0,0,0,101,7,0,0,0,0,0,0
0,0,0,0,26,135,0,0,0,0,0,0,101,20,0,0,0,0,0,0,0,0,0,0,0,7,7,7,7,7,7,7,7,7,0,0,0,0,47,47,47,47,7,7,47,47,47,47,0,0,0,0,0
0,0,0,0,26,0,0,0,0,0,0,0,0,20,0,0,0,0,0,0,0,0,0,0,47,47,47,47,47,47,47,47,47,47,47,0,0,0,0,0,0,0,0,0,0,0,0,0,0,0,0,0,0
0,0,0,0,26,0,0,0,0,0,0,0,0,20,0,0,0,0,0,0,0,0,0,0,0,0,0,0,0,0,0,0,0,0,0,0,0,0,0,0,0,0,0,0,0,0,0,0,0,0,0,0,0
0,0,0,0,26,0,0,0,0,0,0,0,0,20,0,0,0,0,0,0,0,0,0,0,0,0,0,0,0,0,0,0,0,0,0,0,0,0,0,0,0,0,0,0,0,0,0,0,0,0,0,0,0
0,0,0,0,26,0,0,0,0,0,0,0,0,20,0,0,0,0,0,0,0,0,0,0,0,0,0,0,0,0,0,0,0,0,0,0,0,0,0,0,0,0,0,0,0,0,0,0,0,0,0,0,0
0,0,0,0,26,0,0,0,0,0,0,0,0,20,0,0,0,0,0,0,0,0,0,0,0,0,0,0,0,0,0,0,0,0,0,0,0,0,0,0,0,0,0,0,0,0,0,0,0,0,0,0,0
0,0,0,0,26,0,0,0,0,0,0,114,0,20,0,0,0,0,0,0,0,0,0,0,0,0,0,0,0,0,0,0,0,0,0,0,0,0,0,0,0,0,0,0,0,0,0,20,0,0,0,0,0
0,0,0,0,8,7,0,7,7,7,7,7,7,8,8,8,8,0,0,0,0,0,0,0,0,0,0,0,182,23,23,23,23,23,23,23,23,23,23,23,23,8,7,7,7,7,8,20,0,0,0,0,0
0,0,0,0,8,17,16,17,17,17,17,17,17,17,17,17,8,0,0,0,0,0,0,0,0,0,0,0,25,7,7,7,7,7,7,7,7,7,7,7,7,8,47,47,0,186,17,20,0,0,0,0,0
0,0,0,0,8,17,17,17,17,17,17,17,17,17,17,17,8,0,0,0,0,0,0,0,0,0,0,0,25,7,0,0,0,7,7,7,7,7,7,7,7,7,0,0,0,0,17,20,0,0,0,0,0
0,0,0,0,8,17,17,17,17,17,17,17,17,17,17,17,8,0,0,0,0,0,0,0,0,0,0,0,25,7,0,0,0,7,7,7,7,7,7,7,7,7,0,0,0,0,17,20,0,0,0,0,0
0,0,0,0,8,17,17,17,17,17,17,17,17,17,17,17,8,0,0,0,0,0,0,0,0,0,0,0,25,7,0,0,185,7,7,7,7,7,7,7,7,7,0,0,0,0,17,20,0,0,0,0,0
0,0,0,0,8,17,17,17,17,17,17,17,17,17,17,17,8,0,0,0,0,0,0,0,0,0,0,0,25,7,7,0,7,7,7,7,7,7,7,7,7,7,0,11,11,0,17,20,0,0,0,0,0
0,0,0,0,8,17,17,0,0,0,0,0,0,0,17,17,8,0,0,0,0,0,0,0,0,0,0,0,182,25,7,23,7,7,7,7,7,7,7,7,7,7,0,11,0,0,17,20,0,0,0,0,0
0,0,0,0,8,17,17,0,0,0,0,0,0,0,17,17,8,0,0,0,0,0,0,0,0,0,0,0,0,25,8,170,170,170,170,170,170,170,170,170,170,7,0,11,0,114,17,20,0,0,0,0,0
0,0,0,0,8,17,17,0,0,0,0,0,0,0,17,17,8,0,0,0,0,0,0,0,0,0,0,0,0,25,7,0,172,0,0,0,0,0,17,11,11,7,51,7,7,7,7,20,0,0,0,0,0
0,0,0,0,8,34,17,0,0,0,0,0,0,0,17,17,8,0,0,0,0,0,0,0,0,0,0,0,0,25,7,0,172,0,0,0,0,0,0,0,0,7,0,0,0,105,7,20,0,0,0,0,0
0,0,0,0,8,17,17,0,0,0,0,0,0,0,17,17,8,0,0,0,0,0,0,0,0,0,0,0,0,25,7,0,172,170,170,170,170,170,170,170,170,7,0,0,124,123,7,20,0,0,0,0,0
0,0,0,0,8,17,17,0,0,0,0,0,0,0,17,17,8,23,7,23,16,16,16,16,16,16,16,16,16,17,7,0,172,0,0,80,0,80,0,0,0,7,0,0,124,184,7,20,0,0,0,0,0
0,0,0,0,8,17,17,17,17,17,17,17,17,17,17,17,8,7,0,7,17,17,17,17,17,17,17,17,17,17,7,16,172,0,0,0,0,0,0,0,0,7,0,0,0,105,7,20,0,0,0,0,0
0,0,0,0,8,17,17,17,17,17,17,17,17,17,17,17,8,61,7,61,47,47,47,47,47,47,47,47,47,17,7,17,170,170,170,170,170,170,170,170,170,7,0,0,0,183,7,20,0,0,0,0,0
0,0,0,0,8,8,8,8,8,8,8,8,8,8,8,8,8,0,0,0,0,0,0,0,0,0,0,0,0,25,8,7,7,7,7,7,7,7,7,7,7,8,7,7,7,7,7,20,0,0,0,0,0
0,0,0,0,0,0,0,0,0,0,11,0,0,0,0,0,0,0,0,0,0,0,0,0,0,0,0,0,0,182,61,61,61,61,61,61,61,61,61,61,61,7,61,61,61,61,17,20,0,0,0,0,0
0,0,0,0,0,0,0,0,0,0,0,0,0,0,0,0,0,0,0,0,0,0,0,0,0,0,0,0,0,0,0,0,0,0,0,0,0,0,0,0,0,0,0,0,0,0,0,0,0,0,0,0,0
0,0,0,0,0,0,0,0,0,0,0,0,0,0,0,0,0,0,0,0,0,0,0,0,0,0,0,0,0,0,0,0,0,0,0,0,0,0,0,0,0,0,0,0,0,0,0,0,0,0,0,0,0
0,0,0,0,0,0,0,0,0,0,0,0,0,0,0,0,0,0,0,0,0,0,0,0,0,0,0,0,0,0,0,0,0,0,0,0,0,0,0,0,0,0,0,0,0,0,0,0,0,0,0,0,0
0,0,0,0,0,0,0,0,0,0,0,0,0,0,0,0,0,0,0,0,0,0,0,0,0,0,0,0,0,0,0,0,0,0,0,0,0,0,0,0,0,0,0,0,0,0,0,0,0,0,0,0,0
0,0,0,0,0,0,0,0,0,0,0,0,0,0,0,0,0,0,0,0,0,0,0,0,0,0,0,0,0,0,0,0,0,0,0,0,0,0,0,0,0,0,0,0,0,0,0,0,0,0,0,0,0
0,0,0,0,0,0,0,0,0,0,0,0,0,0,0,0,0,0,0,0,0,0,0,0,0,0,0,0,0,0,0,0,0,0,0,0,0,0,0,0,0,0,0,0,0,0,0,0,0,0,0,0,0
0,0,0,0,0,0,0,0,0,0,0,0,0,0,0,0,0,0,0,0,0,0,0,0,0,0,0,0,0,0,0,0,0,0,0,0,0,0,0,0,0,0,0,0,0,0,0,0,0,0,0,0,0
0,0,0,0,0,0,0,0,0,0,0,0,0,0,0,0,0,0,0,0,0,0,0,0,0,0,0,0,0,0,0,0,0,0,0,0,0,0,0,0,0,0,0,0,0,0,0,0,0,0,0,0,0
:endlayer
layer: 9
0,0,0,0,0,0,0,0,0,0,0,0,0,0,0,0,0,0,0,0,0,0,0,0,0,0,0,0,0,0,0,0,0,0,0,0,0,0,0,0,0,0,0,0,0,0,0,0,0,0,0,0,0
0,0,0,0,0,0,0,0,0,0,0,0,0,0,0,0,0,0,0,0,0,0,0,0,0,0,0,0,0,0,0,0,0,0,0,0,0,0,0,0,0,0,0,0,0,0,0,0,0,0,0,0,0
0,0,0,0,0,17,0,0,0,0,0,0,17,190,174,174,174,174,174,174,174,0,0,0,0,0,0,0,0,0,0,0,0,0,0,0,0,0,0,0,0,0,0,0,0,0,0,0,0,0,0,0,0
0,0,0,0,0,17,17,120,17,17,120,17,17,17,8,17,17,17,17,17,8,0,0,0,0,0,0,0,0,0,0,0,0,0,0,0,0,0,0,0,0,0,0,0,0,0,0,0,0,0,0,0,0
0,0,0,0,0,17,0,0,0,0,0,0,17,17,0,80,11,0,0,189,17,0,0,0,0,0,0,0,0,0,0,0,0,0,0,0,0,0,0,0,0,0,0,0,0,0,0,0,0,0,0,0,0
0,0,0,0,0,17,0,0,0,0,0,0,17,17,0,0,0,0,0,0,17,0,0,0,0,0,0,0,0,0,0,0,0,0,0,0,0,0,0,0,0,0,0,0,0,0,0,0,0,0,0,0,0
0,0,0,0,0,17,0,0,0,0,0,0,17,17,0,0,11,0,0,0,17,0,0,0,0,0,0,0,0,0,0,0,0,0,0,0,0,0,0,0,0,0,0,0,0,0,0,0,0,0,0,0,0
0,0,0,0,0,17,0,0,0,0,0,0,17,17,0,0,11,0,0,0,17,0,0,0,0,0,0,0,0,0,0,0,0,0,0,0,0,0,16,16,16,16,16,16,16,16,16,16,0,0,0,0,0
0,0,0,0,0,17,0,0,0,0,0,0,17,17,11,11,11,0,0,0,17,0,0,0,16,16,16,16,16,16,16,16,16,16,16,0,0,0,0,7,135,0,0,0,0,0,7,0,0,0,0,0,0
0,0,0,0,0,17,0,0,0,0,0,0,17,17,0,0,0,0,178,178,17,0,0,0,0,7,7,7,7,7,7,7,7,7,0,0,0,0,0,7,0,0,0,0,0,0,7,135,0,0,0,0,0
0,0,0,0,0,17,0,0,0,0,0,0,17,17,0,0,0,0,176,176,17,16,16,16,16,7,7,7,7,7,7,7,7,7,0,0,0,0,0,7,0,0,0,0,0,0,7,135,0,0,0,0,0
0,0,0,0,0,17,0,0,0,0,0,0,17,17,8,17,17,17,17,17,8,47,47,47,47,7,7,7,7,7,7,7,7,7,0,0,0,0,0,7,0,0,0,0,0,0,7,0,0,0,0,0,0
0,0,0,0,0,17,0,0,0,0,0,0,17,0,0,0,0,0,0,0,0,0,0,0,0,7,7,7,7,7,7,7,7,7,0,0,0,0,47,47,47,47,47,47,47,47,47,47,0,0,0,0,0
0,0,0,0,0,17,0,0,0,0,0,0,17,0,0,0,0,0,0,0,0,0,0,0,47,47,47,47,47,47,47,47,47,47,47,0,0,0,0,0,0,0,7,7,0,0,0,0,0,0,0,0,0
0,0,0,0,0,17,0,0,0,0,0,0,17,0,0,0,0,0,0,0,0,0,0,0,0,0,0,0,0,0,0,0,0,0,0,0,0,0,0,0,0,0,0,0,0,0,0,0,0,0,0,0,0
0,0,0,0,0,17,0,0,0,0,0,0,17,0,0,0,0,0,0,0,0,0,0,0,0,0,0,0,0,0,0,0,0,0,0,0,0,0,0,0,0,0,0,0,0,0,0,0,0,0,0,0,0
0,0,0,0,0,17,0,0,0,0,0,0,17,0,0,0,0,0,0,0,0,0,0,0,0,0,0,0,0,0,0,0,0,0,0,0,0,0,0,0,0,0,0,0,0,0,0,0,0,0,0,0,0
0,0,0,0,0,17,0,0,0,0,0,0,17,0,0,0,0,0,0,0,0,0,0,0,0,0,0,0,0,0,0,0,0,0,0,0,0,0,0,0,0,0,0,0,0,0,0,0,0,0,0,0,0
0,0,0,0,0,17,0,0,0,0,0,0,17,0,0,0,0,0,0,0,0,0,0,0,0,0,0,0,0,0,0,0,0,0,0,0,0,0,0,0,0,0,0,0,0,0,0,0,0,0,0,0,0
0,0,0,0,0,17,0,114,0,0,0,0,17,0,0,114,0,0,0,0,0,0,0,0,0,0,0,0,0,0,0,0,0,0,0,0,0,0,0,0,0,26,0,0,0,0,20,0,0,0,0,0,0
0,0,0,0,17,17,0,17,17,17,17,17,17,17,17,17,17,0,0,0,0,0,0,0,0,0,0,0,0,0,0,0,0,0,0,0,0,0,0,0,0,26,7,120,120,7,20,0,0,0,0,0,0
0,0,0,0,17,52,0,0,0,0,0,54,54,52,0,0,17,0,0,0,0,0,0,0,0,0,0,0,0,8,7,120,7,7,7,7,7,7,7,7,7,8,0,0,0,0,20,0,0,0,0,0,0
0,0,0,0,17,52,0,0,52,53,0,53,0,0,0,0,17,0,0,0,0,0,0,0,0,0,0,0,0,7,0,0,0,7,17,17,17,17,17,17,17,7,0,0,0,0,20,0,0,0,0,0,0
0,0,0,0,17,52,0,0,52,52,0,0,0,0,0,0,17,0,0,0,0,0,0,0,0,0,0,0,0,120,0,0,0,7,17,17,17,17,17,17,17,7,0,0,0,0,20,0,0,0,0,0,0
0,0,0,0,17,0,0,0,0,0,0,0,54,52,0,0,17,0,0,0,0,0,0,0,0,0,0,0,0,7,0,0,185,7,17,17,17,17,17,17,17,7,0,0,0,0,20,0,0,0,0,0,0
0,0,0,0,17,0,11,11,11,11,0,11,11,11,11,0,17,0,0,0,0,0,0,0,0,0,0,0,0,8,7,0,7,17,17,17,17,17,17,17,17,7,0,0,0,0,20,0,0,0,0,0,0
0,0,0,0,17,0,11,0,0,0,0,0,0,0,11,0,17,0,0,0,0,0,0,0,0,0,0,0,0,0,7,0,7,17,17,17,17,17,17,17,17,7,0,0,0,0,20,0,0,0,0,0,0
0,0,0,0,17,0,11,0,0,0,0,0,0,0,11,0,17,0,0,0,0,0,0,0,0,0,0,0,0,0,8,23,7,17,17,17,17,17,17,17,17,7,0,0,0,0,20,0,0,0,0,0,0
0,0,0,0,17,0,11,0,0,0,0,0,0,0,11,0,17,0,0,0,0,0,0,0,0,0,0,0,0,0,7,17,17,17,17,17,17,17,17,17,17,7,188,7,7,7,20,0,0,0,0,0,0
0,0,0,0,17,34,11,0,0,0,0,0,0,0,11,0,17,0,0,0,0,0,0,0,0,0,0,0,0,0,7,7,7,17,17,17,17,17,17,17,17,7,0,0,0,79,20,0,0,0,0,0,0
0,0,0,0,17,0,11,0,0,0,0,0,0,0,11,0,17,0,0,0,0,0,0,0,0,0,0,0,0,0,7,0,17,17,17,17,17,17,17,17,17,7,0,0,0,0,20,0,0,0,0,0,0
0,0,0,0,17,0,11,0,0,0,0,0,0,0,11,0,17,0,7,0,0,0,0,0,0,0,0,0,0,0,7,0,17,17,17,17,17,17,17,17,17,7,0,0,0,0,20,0,0,0,0,0,0
0,0,0,0,17,0,11,11,11,11,0,11,11,11,11,0,17,7,0,7,0,0,0,0,0,0,0,0,79,0,7,0,17,17,17,17,17,17,17,17,17,7,0,0,0,79,20,0,0,0,0,0,0
0,0,0,0,17,0,0,0,0,0,0,0,0,0,0,0,17,0,7,0,0,0,0,0,0,0,0,0,0,0,7,0,26,17,17,17,17,17,17,17,17,7,114,0,0,0,20,0,0,0,0,0,0
0,0,0,0,17,17,17,17,17,17,0,17,17,17,17,17,17,0,0,0,0,0,0,0,0,0,0,0,0,0,8,7,7,7,7,7,7,7,7,7,7,8,7,120,120,7,20,0,0,0,0,0,0
0,0,0,0,0,0,0,0,0,0,0,0,0,0,0,0,0,0,0,0,0,0,0,0,0,0,0,0,0,0,0,0,0,0,0,0,0,0,0,0,0,26,0,0,0,0,20,0,0,0,0,0,0
0,0,0,0,0,0,0,0,0,0,0,0,0,0,0,0,0,0,0,0,0,0,0,0,0,0,0,0,0,0,0,0,0,0,0,0,0,0,0,0,0,0,0,0,0,0,0,0,0,0,0,0,0
0,0,0,0,0,0,0,0,0,0,0,0,0,0,0,0,0,0,0,0,0,0,0,0,0,0,0,0,0,0,0,0,0,0,0,0,0,0,0,0,0,0,0,0,0,0,0,0,0,0,0,0,0
0,0,0,0,0,0,0,0,0,0,0,0,0,0,0,0,0,0,0,0,0,0,0,0,0,0,0,0,0,0,0,0,0,0,0,0,0,0,0,0,0,0,0,0,0,0,0,0,0,0,0,0,0
0,0,0,0,0,0,0,0,0,0,0,0,0,0,0,0,0,0,0,0,0,0,0,0,0,0,0,0,0,0,0,0,0,0,0,0,0,0,0,0,0,0,0,0,0,0,0,0,0,0,0,0,0
0,0,0,0,0,0,0,0,0,0,0,0,0,0,0,0,0,0,0,0,0,0,0,0,0,0,0,0,0,0,0,0,0,0,0,0,0,0,0,0,0,0,0,0,0,0,0,0,0,0,0,0,0
0,0,0,0,0,0,0,0,0,0,0,0,0,0,0,0,0,0,0,0,0,0,0,0,0,0,0,0,0,0,0,0,0,0,0,0,0,0,0,0,0,0,0,0,0,0,0,0,0,0,0,0,0
0,0,0,0,0,0,0,0,0,0,0,0,0,0,0,0,0,0,0,0,0,0,0,0,0,0,0,0,0,0,0,0,0,0,0,0,0,0,0,0,0,0,0,0,0,0,0,0,0,0,0,0,0
0,0,0,0,0,0,0,0,0,0,0,0,0,0,0,0,0,0,0,0,0,0,0,0,0,0,0,0,0,0,0,0,0,0,0,0,0,0,0,0,0,0,0,0,0,0,0,0,0,0,0,0,0
:endlayer
layer: 10
0,0,0,0,0,0,0,0,0,0,0,0,0,0,0,0,0,0,0,0,0,0,0,0,0,0,0,0,0,0,0,0,0,0,0,0,0,0,0,0,0,0,0,0,0,0,0,0,0,0,0,0,0
0,0,0,0,0,0,0,0,0,0,0,0,0,0,0,0,0,0,0,0,0,0,0,0,0,0,0,0,0,0,0,0,0,0,0,0,0,0,0,0,0,0,0,0,0,0,0,0,0,0,0,0,0
0,0,0,0,0,26,0,0,0,0,0,0,20,0,0,0,0,0,0,0,0,0,0,0,0,0,0,0,0,0,0,0,0,0,0,0,0,0,0,0,0,0,0,0,0,0,0,0,0,0,0,0,0
0,0,0,0,0,26,17,17,17,17,17,17,20,17,8,17,17,17,120,17,8,0,0,0,0,0,0,0,0,0,0,0,0,0,0,0,0,0,0,0,0,0,0,0,0,0,0,0,0,0,0,0,0
0,0,0,0,0,26,0,0,0,0,0,0,20,17,0,0,0,0,0,0,17,0,0,0,0,0,0,0,0,0,0,0,0,0,0,0,0,0,0,0,0,0,0,0,0,0,0,0,0,0,0,0,0
0,0,0,0,0,26,0,0,0,0,0,0,20,17,0,0,0,0,0,0,17,0,0,0,0,0,0,0,0,0,0,0,0,0,0,0,0,0,0,0,0,0,0,0,0,0,0,0,0,0,0,0,0
0,0,0,0,0,26,0,0,0,0,0,0,20,17,0,0,0,0,0,0,120,0,0,0,0,0,0,0,0,0,0,0,0,0,0,0,0,0,0,0,0,0,0,0,0,0,0,0,0,0,0,0,0
0,0,0,0,0,26,0,0,0,0,0,0,20,17,0,0,0,0,0,0,17,0,0,0,0,0,0,0,0,0,0,0,0,0,0,0,0,0,0,0,0,0,0,0,0,0,0,0,0,0,0,0,0
0,0,0,0,0,26,0,0,0,0,0,0,20,17,0,0,0,0,0,0,17,0,0,0,0,0,0,0,0,0,0,0,0,0,0,0,0,0,197,197,197,197,197,197,197,197,197,197,0,0,0,0,0
0,0,0,0,0,26,0,0,0,0,0,0,20,17,0,0,0,0,0,0,120,0,0,0,16,16,16,16,16,16,16,16,16,16,16,0,0,0,16,16,16,16,16,16,16,16,16,16,0,0,0,0,0
0,0,0,0,0,26,0,0,0,0,0,0,20,17,0,0,0,0,0,0,17,0,0,0,0,7,7,7,7,7,7,7,7,7,0,0,0,0,47,47,47,47,47,47,47,47,47,47,0,0,0,0,0
0,0,0,0,0,26,0,0,0,0,0,0,20,17,8,17,120,17,120,17,8,0,0,0,101,7,7,7,7,7,7,7,7,7,0,0,0,0,197,197,197,197,197,197,197,197,197,197,0,0,0,0,0
0,0,0,0,0,26,0,0,0,0,0,0,20,0,0,0,0,80,0,0,0,0,0,0,47,47,47,47,47,47,47,47,47,47,47,0,0,0,0,0,0,0,114,114,0,0,0,0,0,0,0,0,0
0,0,0,0,0,26,0,0,0,0,0,0,20,0,0,0,0,0,0,0,0,0,0,0,0,0,0,0,0,0,0,0,0,0,0,0,0,0,0,0,0,0,7,7,0,0,0,0,0,0,0,0,0
0,0,0,0,0,26,0,0,0,0,0,0,20,0,0,0,0,0,0,0,0,0,0,0,0,0,0,0,0,0,0,0,0,0,0,0,0,0,0,0,0,0,0,0,0,0,0,0,0,0,0,0,0
0,0,0,0,0,26,0,0,0,0,0,0,20,0,0,0,0,0,0,0,0,0,0,0,0,0,0,0,0,0,0,0,0,0,0,0,0,0,0,0,0,0,0,0,0,0,0,0,0,0,0,0,0
0,0,0,0,0,26,0,0,0,0,0,0,20,0,0,0,0,0,0,0,0,0,0,0,0,0,0,0,0,0,0,0,0,0,0,0,0,0,0,0,0,0,0,0,0,0,0,0,0,0,0,0,0
0,0,0,0,0,26,0,0,0,0,0,0,20,0,0,0,0,0,0,0,0,0,0,0,0,0,0,0,0,0,0,0,0,0,0,0,0,0,0,0,0,0,0,0,0,0,0,0,0,0,0,0,0
0,0,0,0,0,26,0,0,0,0,0,0,20,0,0,0,0,0,0,0,0,0,0,0,0,0,0,0,0,0,0,0,0,0,0,0,0,0,0,0,0,0,0,0,0,0,0,0,0,0,0,0,0
0,0,0,0,0,26,0,0,0,0,0,0,20,0,0,0,0,20,0,0,0,0,0,0,0,0,0,0,0,0,0,0,0,0,0,0,0,0,0,0,0,0,26,0,0,20,0,0,0,0,0,0,0
0,0,0,26,17,17,0,17,17,17,17,17,17,17,17,17,17,20,0,0,0,0,0,0,0,0,0,0,0,0,0,0,0,0,0,0,0,0,0,0,0,0,16,7,7,20,0,0,0,0,0,0,0
0,0,0,26,17,52,0,0,0,0,0,54,54,52,0,0,17,20,0,0,0,0,0,0,0,0,0,0,0,8,7,120,7,7,7,7,7,7,7,7,7,8,0,80,0,20,0,0,0,0,0,0,0
0,0,0,26,17,52,0,0,52,52,0,52,0,0,0,0,17,20,0,0,0,0,0,0,0,0,0,0,0,7,0,0,0,7,194,0,196,17,194,0,195,7,0,0,0,20,0,0,0,0,0,0,0
0,0,0,26,17,0,0,0,52,52,0,0,0,0,0,0,17,20,0,0,0,0,0,0,0,0,0,0,0,120,0,0,0,7,192,0,0,17,192,0,0,7,0,0,0,20,0,0,0,0,0,0,0
0,0,0,26,17,0,0,0,0,0,0,0,52,52,0,0,17,20,0,0,0,0,0,0,0,0,0,0,0,7,0,0,185,7,0,0,0,17,0,0,0,7,0,0,0,20,0,0,0,0,0,0,0
0,0,0,26,17,0,0,0,0,79,0,0,0,0,0,0,17,20,0,0,0,0,0,0,0,0,0,0,0,8,7,0,7,17,17,51,17,17,17,51,17,7,0,0,0,20,0,0,0,0,0,0,0
0,0,0,26,17,0,0,0,0,0,0,0,0,0,0,0,17,20,0,0,0,0,0,0,0,0,0,0,0,0,133,0,7,0,0,0,0,0,0,0,0,7,0,0,0,20,0,0,0,0,0,0,0
0,0,0,26,17,0,0,0,0,0,0,0,0,0,0,0,17,20,0,0,0,0,0,0,0,0,0,0,0,0,8,0,7,0,0,0,17,17,17,17,17,7,0,0,114,20,0,0,0,0,0,0,0
0,0,0,26,17,0,0,0,0,0,0,0,0,0,0,0,17,20,0,0,0,0,0,0,0,0,0,0,0,0,7,0,51,0,0,0,17,0,194,194,193,7,17,7,7,20,0,0,0,0,0,0,0
0,0,0,26,17,0,0,0,0,0,0,0,0,0,0,0,17,20,0,0,0,0,0,0,0,0,0,0,0,0,7,7,7,0,0,0,17,0,192,192,0,7,0,0,0,20,0,0,0,0,0,0,0
0,0,0,26,17,0,0,0,0,0,0,0,0,0,0,0,17,20,0,0,0,0,0,0,0,0,0,0,0,0,7,0,11,0,0,0,51,0,0,0,0,7,0,0,0,20,0,0,0,0,0,0,0
0,0,0,26,17,0,0,0,0,0,0,0,0,0,0,0,17,20,7,0,0,0,0,0,0,0,0,0,0,0,7,0,11,0,0,0,17,17,17,17,17,7,0,0,0,20,0,0,0,0,0,0,0
0,0,0,26,17,0,0,0,0,0,0,0,0,0,0,0,17,7,0,7,0,0,0,0,0,0,0,0,0,0,7,0,11,0,0,0,51,0,0,0,191,7,0,0,0,20,0,0,0,0,0,0,0
0,0,0,26,17,0,0,0,0,0,0,0,0,0,0,0,17,20,7,0,0,0,0,0,0,0,0,0,0,0,7,0,0,0,0,0,17,0,0,124,123,7,0,0,0,20,0,0,0,0,0,0,0
0,0,0,26,17,17,17,17,17,17,0,17,17,17,17,17,17,20,0,0,0,0,0,0,0,0,0,0,0,0,8,7,7,7,7,7,7,7,7,7,7,8,17,7,7,20,0,0,0,0,0,0,0
0,0,0,26,0,0,0,0,0,0,0,0,0,0,0,0,0,20,0,0,0,0,0,0,0,0,0,0,0,0,0,0,0,0,0,0,0,0,0,0,0,0,26,0,0,20,0,0,0,0,0,0,0
0,0,0,0,0,0,0,0,0,0,0,0,0,0,0,0,0,0,0,0,0,0,0,0,0,0,0,0,0,0,0,0,0,0,0,0,0,0,0,0,0,0,0,0,0,0,0,0,0,0,0,0,0
0,0,0,0,0,0,0,0,0,0,0,0,0,0,0,0,0,0,0,0,0,0,0,0,0,0,0,0,0,0,0,0,0,0,0,0,0,0,0,0,0,0,0,0,0,0,0,0,0,0,0,0,0
0,0,0,0,0,0,0,0,0,0,0,0,0,0,0,0,0,0,0,0,0,0,0,0,0,0,0,0,0,0,0,0,0,0,0,0,0,0,0,0,0,0,0,0,0,0,0,0,0,0,0,0,0
0,0,0,0,0,0,0,0,0,0,0,0,0,0,0,0,0,0,0,0,0,0,0,0,0,0,0,0,0,0,0,0,0,0,0,0,0,0,0,0,0,0,0,0,0,0,0,0,0,0,0,0,0
0,0,0,0,0,0,0,0,0,0,0,0,0,0,0,0,0,0,0,0,0,0,0,0,0,0,0,0,0,0,0,0,0,0,0,0,0,0,0,0,0,0,0,0,0,0,0,0,0,0,0,0,0
0,0,0,0,0,0,0,0,0,0,0,0,0,0,0,0,0,0,0,0,0,0,0,0,0,0,0,0,0,0,0,0,0,0,0,0,0,0,0,0,0,0,0,0,0,0,0,0,0,0,0,0,0
0,0,0,0,0,0,0,0,0,0,0,0,0,0,0,0,0,0,0,0,0,0,0,0,0,0,0,0,0,0,0,0,0,0,0,0,0,0,0,0,0,0,0,0,0,0,0,0,0,0,0,0,0
0,0,0,0,0,0,0,0,0,0,0,0,0,0,0,0,0,0,0,0,0,0,0,0,0,0,0,0,0,0,0,0,0,0,0,0,0,0,0,0,0,0,0,0,0,0,0,0,0,0,0,0,0
:endlayer
layer: 11
0,0,0,0,0,0,0,0,0,0,0,0,0,0,0,0,0,0,0,0,0,0,0,0,0,0,0,0,0,0,0,0,0,0,0,0,0,0,0,0,0,0,0,0,0,0,0,0,0,0,0,0,0
0,0,0,0,0,0,0,0,0,0,0,0,0,0,0,0,0,0,0,0,0,0,0,0,0,0,0,0,0,0,0,0,0,0,0,0,0,0,0,0,0,0,0,0,0,0,0,0,0,0,0,0,0
0,0,0,0,0,0,26,0,0,0,0,20,0,26,0,0,0,0,0,0,0,20,0,0,0,0,0,0,0,0,0,0,0,0,0,0,0,0,0,0,0,0,0,0,0,0,0,0,0,0,0,0,0
0,0,0,0,0,0,26,17,17,17,17,20,0,26,8,8,8,8,8,8,8,20,0,0,0,0,0,0,0,0,0,0,0,0,0,0,0,0,0,0,0,0,0,0,0,0,0,0,0,0,0,0,0
0,0,0,0,0,0,26,0,0,0,0,20,0,26,17,0,0,0,80,0,17,20,0,0,0,0,0,0,0,0,0,0,0,0,0,0,0,0,0,0,0,0,0,0,0,0,0,0,0,0,0,0,0
0,0,0,0,0,0,26,0,0,0,0,20,0,26,17,0,0,0,0,0,17,20,0,0,0,0,0,0,0,0,0,0,0,0,0,0,0,0,0,0,0,0,0,0,0,0,0,0,0,0,0,0,0
0,0,0,0,0,0,26,0,0,0,0,20,0,26,17,0,0,0,0,0,17,20,0,0,0,0,0,0,0,0,0,0,0,0,0,0,0,0,0,0,0,0,0,0,0,0,0,0,0,0,0,0,0
0,0,0,0,0,0,26,0,0,0,0,20,0,26,17,0,0,0,0,0,17,20,0,0,0,0,0,0,0,0,0,0,0,0,0,0,0,0,0,0,0,0,0,0,0,0,0,0,0,0,0,0,0
0,0,0,0,0,0,26,0,0,0,0,20,0,26,17,135,0,0,0,0,17,20,0,0,0,0,0,0,0,0,0,0,0,0,0,0,0,0,0,0,0,0,0,0,0,0,0,0,0,0,0,0,0
0,0,0,0,0,0,26,0,0,0,0,20,0,26,17,0,0,0,0,0,17,20,0,0,0,0,0,0,0,0,0,0,0,0,0,0,0,0,0,0,0,0,0,0,0,0,0,0,0,0,0,0,0
0,0,0,0,0,0,26,0,0,0,0,20,0,26,17,0,0,0,0,114,17,20,0,0,16,16,16,16,16,16,16,16,16,16,16,0,0,0,0,0,0,0,0,0,0,0,0,0,0,0,0,0,0
0,0,0,0,0,0,26,0,0,0,0,20,0,26,8,8,8,8,8,8,8,20,0,0,47,47,47,47,47,47,47,47,47,47,47,0,0,0,0,0,0,0,0,0,0,0,0,0,0,0,0,0,0
0,0,0,0,0,0,26,0,0,0,0,20,0,26,0,0,0,0,0,0,0,20,0,0,0,0,0,0,0,0,0,0,0,0,0,0,0,0,0,0,0,0,0,0,0,0,0,0,0,0,0,0,0
0,0,0,0,0,0,26,0,0,0,0,20,0,0,0,0,0,0,0,0,0,0,0,0,0,0,0,0,0,0,0,0,0,0,0,0,0,0,0,0,0,0,7,7,0,0,0,0,0,0,0,0,0
0,0,0,0,0,0,26,0,0,0,0,20,0,0,0,0,0,0,0,0,0,0,0,0,0,0,0,0,0,0,0,0,0,0,0,0,0,0,0,0,0,0,0,0,0,0,0,0,0,0,0,0,0
0,0,0,0,0,0,26,0,0,0,0,20,0,0,0,0,0,0,0,0,0,0,0,0,0,0,0,0,0,0,0,0,0,0,0,0,0,0,0,0,0,0,0,0,0,0,0,0,0,0,0,0,0
0,0,0,0,0,0,26,0,0,0,0,20,0,0,0,0,0,0,0,0,0,0,0,0,0,0,0,0,0,0,0,0,0,0,0,0,0,0,0,0,0,0,0,0,0,0,0,0,0,0,0,0,0
0,0,0,0,0,0,26,0,0,0,0,20,0,0,0,0,0,0,0,0,0,0,0,0,0,0,0,0,0,0,0,0,0,0,0,0,0,0,0,0,0,0,0,0,0,0,0,0,0,0,0,0,0
0,0,0,0,0,0,26,0,0,0,0,20,0,0,0,0,0,0,0,0,0,0,0,0,0,0,0,0,0,0,0,0,0,0,0,0,0,0,0,0,0,0,0,0,0,0,0,0,0,0,0,0,0
0,0,0,0,0,0,26,0,0,0,0,17,17,17,17,17,20,0,0,0,0,0,0,0,0,0,0,0,0,0,0,0,0,0,0,0,0,0,0,0,0,0,0,26,20,0,0,0,0,0,0,0,0
0,0,0,0,26,17,17,17,17,17,17,17,17,17,17,17,20,0,0,0,0,0,0,0,0,0,0,0,0,0,0,0,0,0,0,0,0,0,0,0,0,0,0,26,20,0,0,0,0,0,0,0,0
0,0,0,0,26,0,80,0,0,0,0,53,53,53,80,0,20,0,0,0,0,0,0,0,0,0,0,0,0,8,7,7,7,7,7,120,7,7,7,120,7,8,174,26,20,0,0,0,0,0,0,0,0
0,0,0,0,26,52,0,0,0,0,0,0,0,0,0,0,20,0,0,0,0,0,0,0,0,0,0,0,0,7,0,0,0,7,0,0,0,17,0,0,0,7,174,26,20,0,0,0,0,0,0,0,0
0,0,0,0,26,0,0,0,0,0,0,0,0,0,0,0,20,0,0,0,0,0,0,0,0,0,0,0,0,7,135,0,0,7,135,0,0,17,0,0,0,120,174,26,20,0,0,0,0,0,0,0,0
0,0,0,0,26,0,0,0,0,0,0,0,0,0,0,0,20,0,0,0,0,0,0,0,0,0,0,0,0,7,0,0,185,7,0,0,0,17,0,0,0,7,174,26,20,0,0,0,0,0,0,0,0
0,0,0,0,26,0,0,0,0,0,0,0,0,0,0,0,20,0,0,0,0,0,0,0,0,0,0,0,0,8,7,7,7,17,17,202,17,17,17,201,17,7,174,26,20,0,0,0,0,0,0,0,0
0,0,0,0,26,0,0,0,0,0,0,0,0,0,0,0,20,0,0,0,0,0,0,0,0,0,0,0,0,0,133,80,7,0,0,0,0,0,0,0,0,7,174,26,20,0,0,0,0,0,0,0,0
0,0,0,0,26,0,0,0,0,0,0,0,0,0,0,0,20,0,0,0,0,0,0,0,0,0,0,0,0,0,8,0,7,0,0,0,17,17,17,17,17,7,174,26,20,0,0,0,0,0,0,0,0
0,0,0,0,26,0,0,0,0,0,0,0,0,0,0,0,20,0,0,0,0,0,0,0,0,0,0,0,0,0,7,0,200,0,0,0,17,0,0,0,0,120,174,26,20,0,0,0,0,0,0,0,0
0,0,0,0,26,135,0,0,0,0,0,0,0,0,0,101,20,0,0,0,0,0,0,0,0,0,0,0,0,0,7,7,7,0,0,0,17,135,0,0,0,7,174,26,20,0,0,0,0,0,0,0,0
0,0,0,0,26,0,0,0,0,0,0,0,0,0,0,0,20,0,114,0,0,0,0,0,0,0,0,0,0,0,7,0,0,0,0,0,199,0,0,0,0,120,174,26,20,0,0,0,0,0,0,0,0
0,0,0,0,26,0,0,0,0,0,0,0,0,0,0,0,20,0,7,0,0,0,0,0,0,0,0,0,0,0,120,0,0,0,0,0,17,17,17,17,17,7,174,26,20,0,0,0,0,0,0,0,0
0,0,0,0,26,0,0,0,0,0,0,0,0,0,0,0,20,7,0,7,135,0,0,0,0,0,0,0,0,0,120,0,0,0,0,0,198,0,0,0,0,7,174,26,20,0,0,0,0,0,0,0,0
0,0,0,0,26,0,0,0,0,114,0,114,0,0,0,0,20,0,7,0,0,0,0,0,0,0,0,0,0,0,7,0,0,0,0,0,17,0,0,0,0,7,174,26,20,0,0,0,0,0,0,0,0
0,0,0,0,26,17,17,17,17,17,17,17,17,17,17,17,20,0,80,0,0,0,0,0,0,0,0,0,0,0,8,7,7,120,7,120,7,120,7,120,7,8,0,26,20,0,0,0,0,0,0,0,0
0,0,0,0,26,0,0,0,0,0,11,0,0,0,0,0,20,0,0,0,0,0,0,0,0,0,0,0,0,0,0,0,0,0,0,0,0,0,0,0,0,0,0,26,20,0,0,0,0,0,0,0,0
0,0,0,0,0,0,0,0,0,0,0,0,0,0,0,0,0,0,0,0,0,0,0,0,0,0,0,0,0,0,0,0,0,0,0,0,0,0,0,0,0,0,0,0,0,0,0,0,0,0,0,0,0
0,0,0,0,0,0,0,0,0,0,0,0,0,0,0,0,0,0,0,0,0,0,0,0,0,0,0,0,0,0,0,0,0,0,0,0,0,0,0,0,0,0,0,0,0,0,0,0,0,0,0,0,0
0,0,0,0,0,0,0,0,0,0,0,0,0,0,0,0,0,0,0,0,0,0,0,0,0,0,0,0,0,0,0,0,0,0,0,0,0,0,0,0,0,0,0,0,0,0,0,0,0,0,0,0,0
0,0,0,0,0,0,0,0,0,0,0,0,0,0,0,0,0,0,0,0,0,0,0,0,0,0,0,0,0,0,0,0,0,0,0,0,0,0,0,0,0,0,0,0,0,0,0,0,0,0,0,0,0
0,0,0,0,0,0,0,0,0,0,0,0,0,0,0,0,0,0,0,0,0,0,0,0,0,0,0,0,0,0,0,0,0,0,0,0,0,0,0,0,0,0,0,0,0,0,0,0,0,0,0,0,0
0,0,0,0,0,0,0,0,0,0,0,0,0,0,0,0,0,0,0,0,0,0,0,0,0,0,0,0,0,0,0,0,0,0,0,0,0,0,0,0,0,0,0,0,0,0,0,0,0,0,0,0,0
0,0,0,0,0,0,0,0,0,0,0,0,0,0,0,0,0,0,0,0,0,0,0,0,0,0,0,0,0,0,0,0,0,0,0,0,0,0,0,0,0,0,0,0,0,0,0,0,0,0,0,0,0
0,0,0,0,0,0,0,0,0,0,0,0,0,0,0,0,0,0,0,0,0,0,0,0,0,0,0,0,0,0,0,0,0,0,0,0,0,0,0,0,0,0,0,0,0,0,0,0,0,0,0,0,0
:endlayer
layer: 12
0,0,0,0,0,0,0,0,0,0,0,0,0,0,0,0,0,0,0,0,0,0,0,0,0,0,0,0,0,0,0,0,0,0,0,0,0,0,0,0,0,0,0,0,0,0,0,0,0,0,0,0,0
0,0,0,0,0,0,0,0,0,0,0,0,0,0,0,0,0,0,0,0,0,0,0,0,0,0,0,0,0,0,0,0,0,0,0,0,0,0,0,0,0,0,0,0,0,0,0,0,0,0,0,0,0
0,0,0,0,0,0,0,26,0,0,20,0,0,0,26,0,0,0,0,0,20,0,0,0,0,0,0,0,0,0,0,0,0,0,0,0,0,0,0,0,0,0,0,0,0,0,0,0,0,0,0,0,0
0,0,0,0,0,0,0,26,17,17,20,0,0,0,26,17,17,17,17,17,20,0,0,0,0,0,0,0,0,0,0,0,0,0,0,0,0,0,0,0,0,0,0,0,0,0,0,0,0,0,0,0,0
0,0,0,0,0,0,0,26,0,0,20,0,0,0,26,0,0,0,0,0,20,0,0,0,0,0,0,0,0,0,0,0,0,0,0,0,0,0,0,0,0,0,0,0,0,0,0,0,0,0,0,0,0
0,0,0,0,0,0,0,26,0,0,20,0,0,0,26,0,0,0,0,0,20,0,0,0,0,0,0,0,0,0,0,0,0,0,0,0,0,0,0,0,0,0,0,0,0,0,0,0,0,0,0,0,0
0,0,0,0,0,0,0,26,0,0,20,0,0,0,26,0,0,0,0,0,20,0,0,0,0,0,0,0,0,0,0,0,0,0,0,0,0,0,0,0,0,0,0,0,0,0,0,0,0,0,0,0,0
0,0,0,0,0,0,0,26,0,0,20,0,0,0,26,0,0,0,0,0,20,0,0,0,0,0,0,0,0,0,0,0,0,0,0,0,0,0,0,0,0,0,0,0,0,0,0,0,0,0,0,0,0
0,0,0,0,0,0,0,26,0,0,20,0,0,0,26,0,0,0,0,0,20,0,0,0,0,0,0,0,0,0,0,0,0,0,0,0,0,0,0,0,0,0,0,0,0,0,0,0,0,0,0,0,0
0,0,0,0,0,0,0,26,0,0,20,0,0,0,26,0,0,0,0,0,20,0,0,0,0,0,0,0,0,0,0,0,0,0,0,0,0,0,0,0,0,0,0,0,0,0,0,0,0,0,0,0,0
0,0,0,0,0,0,0,26,0,0,20,0,0,0,26,0,0,0,0,0,20,0,0,0,0,0,0,0,0,0,0,0,0,0,0,0,0,0,0,0,0,0,0,0,0,0,0,0,0,0,0,0,0
0,0,0,0,0,0,0,26,0,0,20,0,0,0,26,17,17,17,17,17,20,0,0,0,0,0,0,0,0,0,0,0,0,0,0,0,0,0,0,0,0,0,0,0,0,0,0,0,0,0,0,0,0
0,0,0,0,0,0,0,26,0,0,20,0,0,0,26,0,0,0,0,0,20,0,0,0,0,0,0,0,0,0,0,0,0,0,0,0,0,0,0,0,0,0,0,0,0,0,0,0,0,0,0,0,0
0,0,0,0,0,0,0,26,0,0,20,0,0,0,0,0,0,0,0,0,0,0,0,0,0,0,0,0,0,0,0,0,0,0,0,0,0,0,0,0,0,0,7,0,0,0,0,0,0,0,0,0,0
0,0,0,0,0,0,0,26,0,0,20,0,0,0,0,0,0,0,0,0,0,0,0,0,0,0,0,0,0,0,0,0,0,0,0,0,0,0,0,0,0,0,0,0,0,0,0,0,0,0,0,0,0
0,0,0,0,0,0,0,26,0,0,20,0,0,0,0,0,0,0,0,0,0,0,0,0,0,0,0,0,0,0,0,0,0,0,0,0,0,0,0,0,0,0,0,0,0,0,0,0,0,0,0,0,0
0,0,0,0,0,0,0,26,0,0,20,0,0,0,0,0,0,0,0,0,0,0,0,0,0,0,0,0,0,0,0,0,0,0,0,0,0,0,0,0,0,0,0,0,0,0,0,0,0,0,0,0,0
0,0,0,0,0,0,0,26,0,0,20,0,0,0,0,0,0,0,0,0,0,0,0,0,0,0,0,0,0,0,0,0,0,0,0,0,0,0,0,0,0,0,0,0,0,0,0,0,0,0,0,0,0
0,0,0,0,0,0,0,26,0,0,20,0,0,0,0,0,0,0,0,0,0,0,0,0,0,0,0,0,0,0,0,0,0,0,0,0,0,0,0,0,0,0,0,0,0,0,0,0,0,0,0,0,0
0,0,0,0,0,0,0,26,0,0,20,0,0,114,0,0,0,0,0,0,0,0,0,0,0,0,0,0,0,0,0,0,0,0,0,0,0,0,0,0,0,0,0,0,0,0,0,0,0,0,0,0,0
0,0,0,0,0,26,17,17,17,17,17,17,17,17,17,20,0,0,0,0,0,0,0,0,0,0,0,0,0,0,0,0,0,0,0,0,0,0,0,0,0,0,0,0,0,0,0,0,0,0,0,0,0
0,0,0,0,0,26,0,0,0,0,0,52,53,0,0,20,0,0,0,0,0,0,0,0,0,0,0,0,0,8,7,7,7,7,7,120,7,7,7,120,7,8,0,0,0,0,0,0,0,0,0,0,0
0,0,0,0,0,26,0,0,0,0,0,0,0,0,0,20,0,0,0,0,0,0,0,0,0,0,0,0,0,7,7,7,7,7,0,0,0,17,0,0,0,7,0,0,0,0,0,0,0,0,0,0,0
0,0,0,0,0,26,0,0,0,0,0,0,0,0,0,20,0,0,0,0,0,0,0,0,0,0,0,0,0,7,7,7,7,7,0,0,0,17,0,0,0,120,0,0,0,0,0,0,0,0,0,0,0
0,0,0,0,0,26,0,0,0,0,0,0,0,0,0,20,0,0,0,0,0,0,0,0,0,0,0,0,0,7,7,7,185,7,0,0,0,17,0,0,114,7,0,0,0,0,0,0,0,0,0,0,0
0,0,0,0,0,26,0,0,0,0,0,0,0,0,0,20,0,0,0,0,0,0,0,0,0,0,0,0,0,8,7,7,7,17,17,17,17,17,17,17,17,7,0,0,0,0,0,0,0,0,0,0,0
0,0,0,0,0,26,0,0,0,0,0,0,0,0,0,20,0,0,0,0,0,0,0,0,0,0,0,0,0,0,7,7,7,0,0,0,0,0,0,0,101,7,0,0,0,0,0,0,0,0,0,0,0
0,0,0,0,0,26,0,0,0,0,0,0,0,0,0,20,0,0,0,0,0,0,0,0,0,0,0,0,0,0,8,7,7,0,0,0,17,17,17,17,17,7,135,0,0,0,0,0,0,0,0,0,0
0,0,0,0,0,26,0,0,0,0,0,0,0,0,0,20,0,0,0,0,0,0,0,0,0,0,0,0,0,0,7,114,7,135,0,0,17,0,0,0,0,120,0,0,0,0,0,0,0,0,0,0,0
0,0,0,0,0,26,0,0,0,0,0,0,0,0,0,20,0,0,0,0,0,0,0,0,0,0,0,0,0,0,7,7,7,0,0,0,17,0,0,0,0,7,0,0,0,0,0,0,0,0,0,0,0
0,0,0,0,0,26,0,0,0,0,0,0,0,0,0,20,0,0,0,0,0,0,0,0,0,0,0,0,0,0,7,80,0,0,0,0,17,0,0,0,0,120,0,0,0,0,0,0,0,0,0,0,0
0,0,0,0,0,26,0,0,0,0,0,0,0,0,0,20,0,0,7,0,0,0,0,0,0,0,0,0,0,0,120,0,0,0,0,0,17,17,17,17,17,7,0,0,0,0,0,0,0,0,0,0,0
0,0,0,0,0,26,0,0,0,0,0,0,0,0,0,20,0,7,0,7,0,0,0,0,0,0,0,0,0,0,120,0,0,0,0,0,17,0,0,0,0,7,0,0,0,0,0,0,0,0,0,0,0
0,0,0,0,0,26,0,0,0,0,0,0,0,0,0,20,0,0,7,0,0,0,0,0,0,0,0,0,0,0,7,0,114,0,114,0,17,0,0,0,114,7,0,0,0,0,0,0,0,0,0,0,0
0,0,0,0,0,26,17,17,17,17,17,17,17,17,17,20,0,0,0,0,0,0,0,0,0,0,0,0,0,0,8,7,7,120,7,120,7,120,7,120,7,8,135,0,0,0,0,0,0,0,0,0,0
0,0,0,0,0,26,0,0,0,0,0,0,0,0,0,20,0,0,0,0,0,0,0,0,0,0,0,0,0,0,0,0,0,0,0,0,0,0,0,0,0,80,0,0,0,0,0,0,0,0,0,0,0
0,0,0,0,0,0,0,0,0,0,0,0,0,0,0,0,0,0,0,0,0,0,0,0,0,0,0,0,0,0,0,0,0,0,0,0,0,0,0,0,0,0,0,0,0,0,0,0,0,0,0,0,0
0,0,0,0,0,0,0,0,0,0,0,0,0,0,0,0,0,0,0,0,0,0,0,0,0,0,0,0,0,0,0,0,0,0,0,0,0,0,0,0,0,0,0,0,0,0,0,0,0,0,0,0,0
0,0,0,0,0,0,0,0,0,0,0,0,0,0,0,0,0,0,0,0,0,0,0,0,0,0,0,0,0,0,0,0,0,0,0,0,0,0,0,0,0,0,0,0,0,0,0,0,0,0,0,0,0
0,0,0,0,0,0,0,0,0,0,0,0,0,0,0,0,0,0,0,0,0,0,0,0,0,0,0,0,0,0,0,0,0,0,0,0,0,0,0,0,0,0,0,0,0,0,0,0,0,0,0,0,0
0,0,0,0,0,0,0,0,0,0,0,0,0,0,0,0,0,0,0,0,0,0,0,0,0,0,0,0,0,0,0,0,0,0,0,0,0,0,0,0,0,0,0,0,0,0,0,0,0,0,0,0,0
0,0,0,0,0,0,0,0,0,0,0,0,0,0,0,0,0,0,0,0,0,0,0,0,0,0,0,0,0,0,0,0,0,0,0,0,0,0,0,0,0,0,0,0,0,0,0,0,0,0,0,0,0
0,0,0,0,0,0,0,0,0,0,0,0,0,0,0,0,0,0,0,0,0,0,0,0,0,0,0,0,0,0,0,0,0,0,0,0,0,0,0,0,0,0,0,0,0,0,0,0,0,0,0,0,0
0,0,0,0,0,0,0,0,0,0,0,0,0,0,0,0,0,0,0,0,0,0,0,0,0,0,0,0,0,0,0,0,0,0,0,0,0,0,0,0,0,0,0,0,0,0,0,0,0,0,0,0,0
:endlayer
layer: 13
0,0,0,0,0,0,0,0,0,0,0,0,0,0,0,0,0,0,0,0,0,0,0,0,0,0,0,0,0,0,0,0,0,0,0,0,0,0,0,0,0,0,0,0,0,0,0,0,0,0,0,0,0
0,0,0,0,0,0,0,0,0,0,0,0,0,0,0,0,0,0,0,0,0,0,0,0,0,0,0,0,0,0,0,0,0,0,0,0,0,0,0,0,0,0,0,0,0,0,0,0,0,0,0,0,0
0,0,0,0,0,0,0,0,17,17,0,0,0,0,0,26,0,0,0,20,0,0,0,0,0,0,0,0,0,0,0,0,0,0,0,0,0,0,0,0,0,0,0,0,0,0,0,0,0,0,0,0,0
0,0,0,0,0,0,0,0,26,20,0,0,0,0,0,26,17,17,17,20,0,0,0,0,0,0,0,0,0,0,0,0,0,0,0,0,0,0,0,0,0,0,0,0,0,0,0,0,0,0,0,0,0
0,0,0,0,0,0,0,0,26,20,0,0,0,0,0,26,0,0,0,20,0,0,0,0,0,0,0,0,0,0,0,0,0,0,0,0,0,0,0,0,0,0,0,0,0,0,0,0,0,0,0,0,0
0,0,0,0,0,0,0,0,26,20,0,0,0,0,0,26,0,0,0,20,0,0,0,0,0,0,0,0,0,0,0,0,0,0,0,0,0,0,0,0,0,0,0,0,0,0,0,0,0,0,0,0,0
0,0,0,0,0,0,0,0,26,20,0,0,0,0,0,26,0,0,0,20,0,0,0,0,0,0,0,0,0,0,0,0,0,0,0,0,0,0,0,0,0,0,0,0,0,0,0,0,0,0,0,0,0
0,0,0,0,0,0,0,0,26,20,0,0,0,0,0,26,0,0,0,20,0,0,0,0,0,0,0,0,0,0,0,0,0,0,0,0,0,0,0,0,0,0,0,0,0,0,0,0,0,0,0,0,0
0,0,0,0,0,0,0,0,26,20,0,0,0,0,0,26,0,0,0,20,0,0,0,0,0,0,0,0,0,0,0,0,0,0,0,0,0,0,0,0,0,0,0,0,0,0,0,0,0,0,0,0,0
0,0,0,0,0,0,0,0,26,20,0,0,0,0,0,26,0,0,0,20,0,0,0,0,0,0,0,0,0,0,0,0,0,0,0,0,0,0,0,0,0,0,0,0,0,0,0,0,0,0,0,0,0
0,0,0,0,0,0,0,0,26,20,0,0,0,0,0,26,0,0,0,20,0,0,0,0,0,0,0,0,0,0,0,0,0,0,0,0,0,0,0,0,0,0,0,0,0,0,0,0,0,0,0,0,0
0,0,0,0,0,0,0,0,26,20,0,0,0,0,0,26,17,17,17,20,0,0,0,0,0,0,0,0,0,0,0,0,0,0,0,0,0,0,0,0,0,0,0,0,0,0,0,0,0,0,0,0,0
0,0,0,0,0,0,0,0,26,20,0,0,0,0,0,26,0,0,0,20,0,0,0,0,0,0,0,0,0,0,0,0,0,0,0,0,0,0,0,0,0,0,0,0,0,0,0,0,0,0,0,0,0
0,0,0,0,0,0,0,0,26,20,0,0,0,0,0,0,0,0,0,0,0,0,0,0,0,0,0,0,0,0,0,0,0,0,0,0,0,0,0,0,0,0,203,0,0,0,0,0,0,0,0,0,0
0,0,0,0,0,0,0,0,26,20,0,0,0,0,0,0,0,0,0,0,0,0,0,0,0,0,0,0,0,0,0,0,0,0,0,0,0,0,0,0,0,0,0,0,0,0,0,0,0,0,0,0,0
0,0,0,0,0,0,0,0,26,20,0,0,0,0,0,0,0,0,0,0,0,0,0,0,0,0,0,0,0,0,0,0,0,0,0,0,0,0,0,0,0,0,0,0,0,0,0,0,0,0,0,0,0
0,0,0,0,0,0,0,0,26,20,0,0,0,0,0,0,0,0,0,0,0,0,0,0,0,0,0,0,0,0,0,0,0,0,0,0,0,0,0,0,0,0,0,0,0,0,0,0,0,0,0,0,0
0,0,0,0,0,0,0,0,26,20,0,0,0,0,0,0,0,0,0,0,0,0,0,0,0,0,0,0,0,0,0,0,0,0,0,0,0,0,0,0,0,0,0,0,0,0,0,0,0,0,0,0,0
0,0,0,0,0,0,0,0,26,20,0,0,0,0,0,0,0,0,0,0,0,0,0,0,0,0,0,0,0,0,0,0,0,0,0,0,0,0,0,0,0,0,0,0,0,0,0,0,0,0,0,0,0
0,0,0,0,0,0,0,0,26,20,0,0,0,0,0,0,0,0,0,0,0,0,0,0,0,0,0,0,0,0,0,0,0,0,0,0,0,0,0,0,0,0,0,0,0,0,0,0,0,0,0,0,0
0,0,0,0,0,0,26,17,17,17,120,17,17,17,20,0,0,0,0,0,0,0,0,0,0,0,0,0,174,16,16,16,16,16,16,16,16,16,16,16,16,16,174,0,0,0,0,0,0,0,0,0,0
0,0,0,0,0,0,26,0,0,0,0,53,0,0,20,0,0,0,0,0,0,0,0,0,0,0,0,0,26,7,7,7,7,7,7,7,7,7,7,7,7,7,20,0,0,0,0,0,0,0,0,0,0
0,0,0,0,0,0,26,0,0,0,0,0,0,0,20,0,0,0,0,0,0,0,0,0,0,0,0,0,26,7,0,0,0,7,0,0,0,17,0,0,0,7,20,0,0,0,0,0,0,0,0,0,0
0,0,0,0,0,0,26,0,0,0,0,0,0,0,20,0,0,0,0,0,0,0,0,0,0,0,0,0,26,7,0,0,0,7,0,0,0,17,0,0,0,7,20,0,0,0,0,0,0,0,0,0,0
0,0,0,0,0,0,26,0,0,0,0,0,0,0,20,0,0,0,0,0,0,0,0,0,0,0,0,0,26,7,0,0,0,7,0,0,0,17,0,0,0,7,20,0,0,0,0,0,0,0,0,0,0
0,0,0,0,0,0,26,0,0,0,0,0,0,0,20,0,0,0,0,0,0,0,0,0,0,0,0,0,26,7,0,0,0,7,17,17,17,17,17,17,17,7,20,0,0,0,0,0,0,0,0,0,0
0,0,0,0,0,0,26,0,0,0,0,0,0,0,20,0,0,0,0,0,0,0,0,0,0,0,0,0,174,17,7,7,7,0,0,0,172,0,0,172,0,7,20,0,0,0,0,0,0,0,0,0,0
0,0,0,0,0,0,26,0,0,0,0,0,0,0,20,0,0,0,0,0,0,0,0,0,0,0,0,0,0,26,7,7,7,0,0,0,17,17,17,17,17,7,20,0,0,0,0,0,0,0,0,0,0
0,0,0,0,0,0,26,0,0,0,0,0,0,0,20,0,0,0,0,0,0,0,0,0,0,0,0,0,0,26,7,7,7,0,0,0,17,0,0,0,0,7,20,0,0,0,0,0,0,0,0,0,0
0,0,0,0,0,0,26,0,0,0,0,0,0,0,20,0,0,0,0,0,0,0,0,0,0,0,0,0,0,26,7,7,7,0,0,0,17,0,0,0,0,7,20,0,0,0,0,0,0,0,0,0,0
0,0,0,0,0,0,26,0,0,0,0,0,0,0,20,0,0,0,0,0,0,0,0,0,0,0,0,0,0,26,7,0,0,0,0,0,17,0,0,0,0,7,20,0,0,0,0,0,0,0,0,0,0
0,0,0,0,0,0,26,0,0,0,0,0,0,0,20,0,0,0,0,0,0,0,0,0,0,0,0,0,0,26,7,0,0,0,0,0,17,17,17,17,17,7,20,0,0,0,0,0,0,0,0,0,0
0,0,0,0,0,0,26,0,0,0,0,0,0,0,20,0,0,0,0,0,0,0,0,0,0,0,0,0,0,26,7,0,0,0,0,0,17,0,0,0,0,7,20,0,0,0,0,0,0,0,0,0,0
0,0,0,0,0,0,26,0,0,0,0,0,0,0,20,0,0,0,0,0,0,0,0,0,0,0,0,0,0,26,7,0,0,0,0,0,17,0,0,0,0,7,20,0,0,0,0,0,0,0,0,0,0
0,0,0,0,0,0,26,17,17,17,120,17,17,17,20,0,0,0,0,0,0,0,0,0,0,0,0,0,0,26,7,7,7,7,7,7,7,7,7,7,7,7,20,0,0,0,0,0,0,0,0,0,0
0,0,0,0,0,0,26,0,0,0,0,0,0,0,20,0,0,0,0,0,0,0,0,0,0,0,0,0,0,174,47,47,47,47,47,47,47,47,47,47,47,47,174,0,0,0,0,0,0,0,0,0,0
0,0,0,0,0,0,0,0,0,0,0,0,0,0,0,0,0,0,0,0,0,0,0,0,0,0,0,0,0,0,0,0,0,0,0,0,0,0,0,0,0,0,0,0,0,0,0,0,0,0,0,0,0
0,0,0,0,0,0,0,0,0,0,0,0,0,0,0,0,0,0,0,0,0,0,0,0,0,0,0,0,0,0,0,0,0,0,0,0,0,0,0,0,0,0,0,0,0,0,0,0,0,0,0,0,0
0,0,0,0,0,0,0,0,0,0,0,0,0,0,0,0,0,0,0,0,0,0,0,0,0,0,0,0,0,0,0,0,0,0,0,0,0,0,0,0,0,0,0,0,0,0,0,0,0,0,0,0,0
0,0,0,0,0,0,0,0,0,0,0,0,0,0,0,0,0,0,0,0,0,0,0,0,0,0,0,0,0,0,0,0,0,0,0,0,0,0,0,0,0,0,0,0,0,0,0,0,0,0,0,0,0
0,0,0,0,0,0,0,0,0,0,0,0,0,0,0,0,0,0,0,0,0,0,0,0,0,0,0,0,0,0,0,0,0,0,0,0,0,0,0,0,0,0,0,0,0,0,0,0,0,0,0,0,0
0,0,0,0,0,0,0,0,0,0,0,0,0,0,0,0,0,0,0,0,0,0,0,0,0,0,0,0,0,0,0,0,0,0,0,0,0,0,0,0,0,0,0,0,0,0,0,0,0,0,0,0,0
0,0,0,0,0,0,0,0,0,0,0,0,0,0,0,0,0,0,0,0,0,0,0,0,0,0,0,0,0,0,0,0,0,0,0,0,0,0,0,0,0,0,0,0,0,0,0,0,0,0,0,0,0
0,0,0,0,0,0,0,0,0,0,0,0,0,0,0,0,0,0,0,0,0,0,0,0,0,0,0,0,0,0,0,0,0,0,0,0,0,0,0,0,0,0,0,0,0,0,0,0,0,0,0,0,0
:endlayer
layer: 14
0,0,0,0,0,0,0,0,0,0,0,0,0,0,0,0,0,0,0,0,0,0,0,0,0,0,0,0,0,0,0,0,0,0,0,0,0,0,0,0,0,0,0,0,0,0,0,0,0,0,0,0,0
0,0,0,0,0,0,0,0,0,0,0,0,0,0,0,0,0,0,0,0,0,0,0,0,0,0,0,0,0,0,0,0,0,0,0,0,0,0,0,0,0,0,0,0,0,0,0,0,0,0,0,0,0
0,0,0,0,0,0,0,0,79,79,0,0,0,0,0,0,26,17,20,0,0,0,0,0,0,0,0,0,0,0,0,0,0,0,0,0,0,0,0,0,0,0,0,0,0,0,0,0,0,0,0,0,0
0,0,0,0,0,0,0,0,0,0,0,0,0,0,0,0,26,17,20,0,0,0,0,0,0,0,0,0,0,0,0,0,0,0,0,0,0,0,0,0,0,0,0,0,0,0,0,0,0,0,0,0,0
0,0,0,0,0,0,0,0,0,0,0,0,0,0,0,0,26,17,20,0,0,0,0,0,0,0,0,0,0,0,0,0,0,0,0,0,0,0,0,0,0,0,0,0,0,0,0,0,0,0,0,0,0
0,0,0,0,0,0,0,0,0,0,0,0,0,0,0,0,26,17,20,0,0,0,0,0,0,0,0,0,0,0,0,0,0,0,0,0,0,0,0,0,0,0,0,0,0,0,0,0,0,0,0,0,0
0,0,0,0,0,0,0,0,0,0,0,0,0,0,0,0,26,17,20,0,0,0,0,0,0,0,0,0,0,0,0,0,0,0,0,0,0,0,0,0,0,0,0,0,0,0,0,0,0,0,0,0,0
0,0,0,0,0,0,0,0,0,0,0,0,0,0,0,0,26,17,20,0,0,0,0,0,0,0,0,0,0,0,0,0,0,0,0,0,0,0,0,0,0,0,0,0,0,0,0,0,0,0,0,0,0
0,0,0,0,0,0,0,0,0,0,0,0,0,0,0,0,26,17,20,0,0,0,0,0,0,0,0,0,0,0,0,0,0,0,0,0,0,0,0,0,0,0,0,0,0,0,0,0,0,0,0,0,0
0,0,0,0,0,0,0,0,0,0,0,0,0,0,0,0,26,17,20,0,0,0,0,0,0,0,0,0,0,0,0,0,0,0,0,0,0,0,0,0,0,0,0,0,0,0,0,0,0,0,0,0,0
0,0,0,0,0,0,0,0,0,0,0,0,0,0,0,0,26,17,20,0,0,0,0,0,0,0,0,0,0,0,0,0,0,0,0,0,0,0,0,0,0,0,0,0,0,0,0,0,0,0,0,0,0
0,0,0,0,0,0,0,0,0,0,0,0,0,0,0,0,26,17,20,0,0,0,0,0,0,0,0,0,0,0,0,0,0,0,0,0,0,0,0,0,0,0,0,0,0,0,0,0,0,0,0,0,0
0,0,0,0,0,0,0,0,0,0,0,0,0,0,0,0,26,17,20,0,0,0,0,0,0,0,0,0,0,0,0,0,0,0,0,0,0,0,0,0,0,0,0,0,0,0,0,0,0,0,0,0,0
0,0,0,0,0,0,0,0,0,0,0,0,0,0,0,0,0,0,0,0,0,0,0,0,0,0,0,0,0,0,0,0,0,0,0,0,0,0,0,0,0,0,0,0,0,0,0,0,0,0,0,0,0
0,0,0,0,0,0,0,0,0,0,0,0,0,0,0,0,0,0,0,0,0,0,0,0,0,0,0,0,0,0,0,0,0,0,0,0,0,0,0,0,0,0,0,0,0,0,0,0,0,0,0,0,0
0,0,0,0,0,0,0,0,0,0,0,0,0,0,0,0,0,0,0,0,0,0,0,0,0,0,0,0,0,0,0,0,0,0,0,0,0,0,0,0,0,0,0,0,0,0,0,0,0,0,0,0,0
0,0,0,0,0,0,0,0,0,0,0,0,0,0,0,0,0,0,0,0,0,0,0,0,0,0,0,0,0,0,0,0,0,0,0,0,0,0,0,0,0,0,0,0,0,0,0,0,0,0,0,0,0
0,0,0,0,0,0,0,0,0,0,0,0,0,0,0,0,0,0,0,0,0,0,0,0,0,0,0,0,0,0,0,0,0,0,0,0,0,0,0,0,0,0,0,0,0,0,0,0,0,0,0,0,0
0,0,0,0,0,0,0,0,0,0,0,0,0,0,0,0,0,0,0,0,0,0,0,0,0,0,0,0,0,0,0,0,0,0,0,0,0,0,0,0,0,0,0,0,0,0,0,0,0,0,0,0,0
0,0,0,0,0,0,0,0,0,0,0,0,0,0,0,0,0,0,0,0,0,0,0,0,0,0,0,0,0,0,0,0,0,0,0,0,0,0,0,0,0,0,0,0,0,0,0,0,0,0,0,0,0
0,0,0,0,0,0,0,26,17,17,17,17,17,20,0,0,0,0,0,0,0,0,0,0,0,0,0,0,0,0,0,0,0,0,0,0,0,0,0,0,0,0,0,0,0,0,0,0,0,0,0,0,0
0,0,0,0,0,0,0,26,17,17,0,17,17,20,0,0,0,0,0,0,0,0,0,0,0,0,0,0,0,7,204,7,204,7,174,174,174,174,174,174,174,17,0,0,0,0,0,0,0,0,0,0,0
0,0,0,0,0,0,0,26,17,0,0,0,17,20,0,0,0,0,0,0,0,0,0,0,0,0,0,0,0,204,0,0,0,204,174,174,174,174,174,174,174,174,0,0,0,0,0,0,0,0,0,0,0
0,0,0,0,0,0,0,26,17,0,0,0,17,20,0,0,0,0,0,0,0,0,0,0,0,0,0,0,0,7,0,0,0,7,174,174,174,174,174,174,174,174,0,0,0,0,0,0,0,0,0,0,0
0,0,0,0,0,0,0,26,17,0,0,0,17,20,0,0,0,0,0,0,0,0,0,0,0,0,0,0,0,204,0,0,0,204,174,174,174,174,174,174,174,174,0,0,0,0,0,0,0,0,0,0,0
0,0,0,0,0,0,0,26,17,0,0,0,17,20,0,0,0,0,0,0,0,0,0,0,0,0,0,0,0,7,0,0,0,7,174,174,174,174,174,174,174,174,0,0,0,0,0,0,0,0,0,0,0
0,0,0,0,0,0,0,26,17,0,0,0,17,20,0,0,0,0,0,0,0,0,0,0,0,0,0,0,0,204,204,7,204,7,174,174,174,174,174,174,174,174,0,0,0,0,0,0,0,0,0,0,0
0,0,0,0,0,0,0,26,17,0,0,0,17,20,0,0,0,0,0,0,0,0,0,0,0,0,0,0,0,0,174,16,16,16,16,16,16,16,16,16,16,16,0,0,0,0,0,0,0,0,0,0,0
0,0,0,0,0,0,0,26,17,0,0,0,17,20,0,0,0,0,0,0,0,0,0,0,0,0,0,0,0,0,26,17,17,17,17,17,17,17,17,17,17,20,0,0,0,0,0,0,0,0,0,0,0
0,0,0,0,0,0,0,26,17,0,0,0,17,20,0,0,0,0,0,0,0,0,0,0,0,0,0,0,0,0,26,17,7,170,170,170,17,0,0,0,17,20,0,0,0,0,0,0,0,0,0,0,0
0,0,0,0,0,0,0,26,17,0,0,0,17,20,0,0,0,0,0,0,0,0,0,0,0,0,0,0,0,0,26,17,0,0,0,0,17,0,0,0,17,20,0,0,0,0,0,0,0,0,0,0,0
0,0,0,0,0,0,0,26,17,0,0,0,17,20,0,0,0,0,0,0,0,0,0,0,0,0,0,0,0,0,26,17,0,0,0,0,17,17,17,17,17,20,0,0,0,0,0,0,0,0,0,0,0
0,0,0,0,0,0,0,26,17,0,0,0,17,20,0,0,0,0,0,0,0,0,0,0,0,0,0,0,0,0,26,17,170,170,170,170,17,0,0,0,17,20,0,0,0,0,0,0,0,0,0,0,0
0,0,0,0,0,0,0,26,17,17,0,17,17,20,0,0,0,0,0,0,0,0,0,0,0,0,0,0,0,0,26,17,17,17,17,17,17,17,17,17,17,20,0,0,0,0,0,0,0,0,0,0,0
0,0,0,0,0,0,0,26,17,17,17,17,17,20,0,0,0,0,0,0,0,0,0,0,0,0,0,0,0,0,174,47,47,47,47,47,47,47,47,47,47,174,0,0,0,0,0,0,0,0,0,0,0
0,0,0,0,0,0,0,26,166,166,0,166,166,20,0,0,0,0,0,0,0,0,0,0,0,0,0,0,0,0,0,0,0,0,0,0,0,0,0,0,0,0,0,0,0,0,0,0,0,0,0,0,0
0,0,0,0,0,0,0,0,0,0,0,0,0,0,0,0,0,0,0,0,0,0,0,0,0,0,0,0,0,0,0,0,0,0,0,0,0,0,0,0,0,0,0,0,0,0,0,0,0,0,0,0,0
0,0,0,0,0,0,0,0,0,0,0,0,0,0,0,0,0,0,0,0,0,0,0,0,0,0,0,0,0,0,0,0,0,0,0,0,0,0,0,0,0,0,0,0,0,0,0,0,0,0,0,0,0
0,0,0,0,0,0,0,0,0,0,0,0,0,0,0,0,0,0,0,0,0,0,0,0,0,0,0,0,0,0,0,0,0,0,0,0,0,0,0,0,0,0,0,0,0,0,0,0,0,0,0,0,0
0,0,0,0,0,0,0,0,0,0,0,0,0,0,0,0,0,0,0,0,0,0,0,0,0,0,0,0,0,0,0,0,0,0,0,0,0,0,0,0,0,0,0,0,0,0,0,0,0,0,0,0,0
0,0,0,0,0,0,0,0,0,0,0,0,0,0,0,0,0,0,0,0,0,0,0,0,0,0,0,0,0,0,0,0,0,0,0,0,0,0,0,0,0,0,0,0,0,0,0,0,0,0,0,0,0
0,0,0,0,0,0,0,0,0,0,0,0,0,0,0,0,0,0,0,0,0,0,0,0,0,0,0,0,0,0,0,0,0,0,0,0,0,0,0,0,0,0,0,0,0,0,0,0,0,0,0,0,0
0,0,0,0,0,0,0,0,0,0,0,0,0,0,0,0,0,0,0,0,0,0,0,0,0,0,0,0,0,0,0,0,0,0,0,0,0,0,0,0,0,0,0,0,0,0,0,0,0,0,0,0,0
0,0,0,0,0,0,0,0,0,0,0,0,0,0,0,0,0,0,0,0,0,0,0,0,0,0,0,0,0,0,0,0,0,0,0,0,0,0,0,0,0,0,0,0,0,0,0,0,0,0,0,0,0
:endlayer
layer: 15
0,0,0,0,0,0,0,0,0,0,0,0,0,0,0,0,0,0,0,0,0,0,0,0,0,0,0,0,0,0,0,0,0,0,0,0,0,0,0,0,0,0,0,0,0,0,0,0,0,0,0,0,0
0,0,0,0,0,0,0,0,0,0,0,0,0,0,0,0,0,0,0,0,0,0,0,0,0,0,0,0,0,0,0,0,0,0,0,0,0,0,0,0,0,0,0,0,0,0,0,0,0,0,0,0,0
0,0,0,0,0,0,0,0,0,0,0,0,0,0,0,0,0,79,0,0,0,0,0,0,0,0,0,0,0,0,0,0,0,0,0,0,0,0,0,0,0,0,0,0,0,0,0,0,0,0,0,0,0
0,0,0,0,0,0,0,0,0,0,0,0,0,0,0,0,0,0,0,0,0,0,0,0,0,0,0,0,0,0,0,0,0,0,0,0,0,0,0,0,0,0,0,0,0,0,0,0,0,0,0,0,0
0,0,0,0,0,0,0,0,0,0,0,0,0,0,0,0,0,0,0,0,0,0,0,0,0,0,0,0,0,0,0,0,0,0,0,0,0,0,0,0,0,0,0,0,0,0,0,0,0,0,0,0,0
0,0,0,0,0,0,0,0,0,0,0,0,0,0,0,0,0,0,0,0,0,0,0,0,0,0,0,0,0,0,0,0,0,0,0,0,0,0,0,0,0,0,0,0,0,0,0,0,0,0,0,0,0
0,0,0,0,0,0,0,0,0,0,0,0,0,0,0,0,0,0,0,0,0,0,0,0,0,0,0,0,0,0,0,0,0,0,0,0,0,0,0,0,0,0,0,0,0,0,0,0,0,0,0,0,0
0,0,0,0,0,0,0,0,0,0,0,0,0,0,0,0,0,0,0,0,0,0,0,0,0,0,0,0,0,0,0,0,0,0,0,0,0,0,0,0,0,0,0,0,0,0,0,0,0,0,0,0,0
0,0,0,0,0,0,0,0,0,0,0,0,0,0,0,0,0,0,0,0,0,0,0,0,0,0,0,0,0,0,0,0,0,0,0,0,0,0,0,0,0,0,0,0,0,0,0,0,0,0,0,0,0
0,0,0,0,0,0,0,0,0,0,0,0,0,0,0,0,0,0,0,0,0,0,0,0,0,0,0,0,0,0,0,0,0,0,0,0,0,0,0,0,0,0,0,0,0,0,0,0,0,0,0,0,0
0,0,0,0,0,0,0,0,0,0,0,0,0,0,0,0,0,0,0,0,0,0,0,0,0,0,0,0,0,0,0,0,0,0,0,0,0,0,0,0,0,0,0,0,0,0,0,0,0,0,0,0,0
0,0,0,0,0,0,0,0,0,0,0,0,0,0,0,0,0,0,0,0,0,0,0,0,0,0,0,0,0,0,0,0,0,0,0,0,0,0,0,0,0,0,0,0,0,0,0,0,0,0,0,0,0
0,0,0,0,0,0,0,0,0,0,0,0,0,0,0,0,0,79,0,0,0,0,0,0,0,0,0,0,0,0,0,0,0,0,0,0,0,0,0,0,0,0,0,0,0,0,0,0,0,0,0,0,0
0,0,0,0,0,0,0,0,0,0,0,0,0,0,0,0,0,0,0,0,0,0,0,0,0,0,0,0,0,0,0,0,0,0,0,0,0,0,0,0,0,0,0,0,0,0,0,0,0,0,0,0,0
0,0,0,0,0,0,0,0,0,0,0,0,0,0,0,0,0,0,0,0,0,0,0,0,0,0,0,0,0,0,0,0,0,0,0,0,0,0,0,0,0,0,0,0,0,0,0,0,0,0,0,0,0
0,0,0,0,0,0,0,0,0,0,0,0,0,0,0,0,0,0,0,0,0,0,0,0,0,0,0,0,0,0,0,0,0,0,0,0,0,0,0,0,0,0,0,0,0,0,0,0,0,0,0,0,0
0,0,0,0,0,0,0,0,0,0,0,0,0,0,0,0,0,0,0,0,0,0,0,0,0,0,0,0,0,0,0,0,0,0,0,0,0,0,0,0,0,0,0,0,0,0,0,0,0,0,0,0,0
0,0,0,0,0,0,0,0,0,0,0,0,0,0,0,0,0,0,0,0,0,0,0,0,0,0,0,0,0,0,0,0,0,0,0,0,0,0,0,0,0,0,0,0,0,0,0,0,0,0,0,0,0
0,0,0,0,0,0,0,0,0,0,0,0,0,0,0,0,0,0,0,0,0,0,0,0,0,0,0,0,0,0,0,0,0,0,0,0,0,0,0,0,0,0,0,0,0,0,0,0,0,0,0,0,0
0,0,0,0,0,0,0,0,0,0,0,0,0,0,0,0,0,0,0,0,0,0,0,0,0,0,0,0,0,0,0,0,0,0,0,0,0,0,0,0,0,0,0,0,0,0,0,0,0,0,0,0,0
0,0,0,0,0,0,0,0,0,174,17,174,0,0,0,0,0,0,0,0,0,0,0,0,0,0,0,0,0,0,0,0,0,0,0,0,0,0,0,0,0,0,0,0,0,0,0,0,0,0,0,0,0
0,0,0,0,0,0,0,0,0,26,17,20,0,0,0,0,0,0,0,0,0,0,0,0,0,0,0,0,0,7,207,7,207,7,0,0,0,0,0,0,0,79,0,0,0,0,0,0,0,0,0,0,0
0,0,0,0,0,0,0,0,0,26,17,20,0,0,0,0,0,0,0,0,0,0,0,0,0,0,0,0,0,206,0,0,0,204,0,0,0,0,0,0,0,0,0,0,0,0,0,0,0,0,0,0,0
0,0,0,0,0,0,0,0,0,26,17,20,0,0,0,0,0,0,0,0,0,0,0,0,0,0,0,0,0,7,0,0,0,7,0,0,0,0,0,0,0,0,0,0,0,0,0,0,0,0,0,0,0
0,0,0,0,0,0,0,0,0,26,17,20,0,0,0,0,0,0,0,0,0,0,0,0,0,0,0,0,0,206,0,0,0,204,0,0,0,0,0,0,0,0,0,0,0,0,0,0,0,0,0,0,0
0,0,0,0,0,0,0,0,0,26,17,20,0,0,0,0,0,0,0,0,0,0,0,0,0,0,0,0,0,7,205,7,205,7,0,0,0,0,0,0,0,0,0,0,0,0,0,0,0,0,0,0,0
0,0,0,0,0,0,0,0,0,26,17,20,0,0,0,0,0,0,0,0,0,0,0,0,0,0,0,0,0,204,204,7,204,7,0,0,0,0,0,0,0,0,0,0,0,0,0,0,0,0,0,0,0
0,0,0,0,0,0,0,0,0,26,17,20,0,0,0,0,0,0,0,0,0,0,0,0,0,0,0,0,0,0,0,0,0,0,0,0,0,0,0,0,0,0,0,0,0,0,0,0,0,0,0,0,0
0,0,0,0,0,0,0,0,0,26,17,20,0,0,0,0,0,0,0,0,0,0,0,0,0,0,0,0,0,0,0,174,16,16,16,16,16,16,16,16,20,0,0,0,0,0,0,0,0,0,0,0,0
0,0,0,0,0,0,0,0,0,26,17,20,0,0,0,0,0,0,0,0,0,0,0,0,0,0,0,0,0,0,0,26,17,17,17,17,17,17,17,17,20,0,0,0,0,0,0,0,0,0,0,0,0
0,0,0,0,0,0,0,0,0,26,17,20,0,0,0,0,0,0,0,0,0,0,0,0,0,0,0,0,0,0,0,26,17,0,0,17,17,17,17,17,20,0,0,0,0,0,0,0,0,0,0,0,0
0,0,0,0,0,0,0,0,0,26,17,20,0,0,0,0,0,0,0,0,0,0,0,0,0,0,0,0,0,0,0,26,17,0,0,17,17,17,17,17,20,0,0,0,0,0,0,0,0,0,0,0,0
0,0,0,0,0,0,0,0,0,26,17,20,0,0,0,0,0,0,0,0,0,0,0,0,0,0,0,0,0,0,0,26,17,17,17,17,17,17,17,17,20,0,0,0,0,0,0,0,0,0,0,0,0
0,0,0,0,0,0,0,0,0,26,17,20,0,0,0,0,0,0,0,0,0,0,0,0,0,0,0,0,0,0,0,174,47,47,47,47,47,47,47,47,174,0,0,0,0,0,0,0,0,0,0,0,0
0,0,0,0,0,0,0,0,0,174,17,174,0,0,0,0,0,0,0,0,0,0,0,0,0,0,0,0,0,0,0,0,0,0,0,0,0,0,0,0,0,0,0,0,0,0,0,0,0,0,0,0,0
0,0,0,0,0,0,0,0,0,174,17,174,0,0,0,0,0,0,0,0,0,0,0,0,0,0,0,0,0,0,0,0,0,0,0,0,0,0,0,0,0,0,0,0,0,0,0,0,0,0,0,0,0
0,0,0,0,0,0,0,0,0,0,0,0,0,0,0,0,0,0,0,0,0,0,0,0,0,0,0,0,0,0,0,0,0,0,0,0,0,0,0,0,0,0,0,0,0,0,0,0,0,0,0,0,0
0,0,0,0,0,0,0,0,0,0,0,0,0,0,0,0,0,0,0,0,0,0,0,0,0,0,0,0,0,0,0,0,0,0,0,0,0,0,0,0,0,0,0,0,0,0,0,0,0,0,0,0,0
0,0,0,0,0,0,0,0,0,0,0,0,0,0,0,0,0,0,0,0,0,0,0,0,0,0,0,0,0,0,0,0,0,0,0,0,0,0,0,0,0,0,0,0,0,0,0,0,0,0,0,0,0
0,0,0,0,0,0,0,0,0,0,0,0,0,0,0,0,0,0,0,0,0,0,0,0,0,0,0,0,0,0,0,0,0,0,0,0,0,0,0,0,0,0,0,0,0,0,0,0,0,0,0,0,0
0,0,0,0,0,0,0,0,0,0,0,0,0,0,0,0,0,0,0,0,0,0,0,0,0,0,0,0,0,0,0,0,0,0,0,0,0,0,0,0,0,0,0,0,0,0,0,0,0,0,0,0,0
0,0,0,0,0,0,0,0,0,0,0,0,0,0,0,0,0,0,0,0,0,0,0,0,0,0,0,0,0,0,0,0,0,0,0,0,0,0,0,0,0,0,0,0,0,0,0,0,0,0,0,0,0
0,0,0,0,0,0,0,0,0,0,0,0,0,0,0,0,0,0,0,0,0,0,0,0,0,0,0,0,0,0,0,0,0,0,0,0,0,0,0,0,0,0,0,0,0,0,0,0,0,0,0,0,0
0,0,0,0,0,0,0,0,0,0,0,0,0,0,0,0,0,0,0,0,0,0,0,0,0,0,0,0,0,0,0,0,0,0,0,0,0,0,0,0,0,0,0,0,0,0,0,0,0,0,0,0,0
:endlayer
layer: 16
0,0,0,0,0,0,0,0,0,0,0,0,0,0,0,0,0,0,0,0,0,0,0,0,0,0,0,0,0,0,0,0,0,0,0,0,0,0,0,0,0,0,0,0,0,0,0,0,0,0,0,0,0
0,0,0,0,0,0,0,0,0,0,0,0,0,0,0,0,0,0,0,0,0,0,0,0,0,0,0,0,0,0,0,0,0,0,0,0,0,0,0,0,0,0,0,0,0,0,0,0,0,0,0,0,0
0,0,0,0,0,0,0,0,0,0,0,0,0,0,0,0,0,0,0,0,0,0,0,0,0,0,0,0,0,0,0,0,0,0,0,0,0,0,0,0,0,0,0,0,0,0,0,0,0,0,0,0,0
0,0,0,0,0,0,0,0,0,0,0,0,0,0,0,0,0,0,0,0,0,0,0,0,0,0,0,0,0,0,0,0,0,0,0,0,0,0,0,0,0,0,0,0,0,0,0,0,0,0,0,0,0
0,0,0,0,0,0,0,0,0,0,0,0,0,0,0,0,0,0,0,0,0,0,0,0,0,0,0,0,0,0,0,0,0,0,0,0,0,0,0,0,0,0,0,0,0,0,0,0,0,0,0,0,0
0,0,0,0,0,0,0,0,0,0,0,0,0,0,0,0,0,0,0,0,0,0,0,0,0,0,0,0,0,0,0,0,0,0,0,0,0,0,0,0,0,0,0,0,0,0,0,0,0,0,0,0,0
0,0,0,0,0,0,0,0,0,0,0,0,0,0,0,0,0,0,0,0,0,0,0,0,0,0,0,0,0,0,0,0,0,0,0,0,0,0,0,0,0,0,0,0,0,0,0,0,0,0,0,0,0
0,0,0,0,0,0,0,0,0,0,0,0,0,0,0,0,0,0,0,0,0,0,0,0,0,0,0,0,0,0,0,0,0,0,0,0,0,0,0,0,0,0,0,0,0,0,0,0,0,0,0,0,0
0,0,0,0,0,0,0,0,0,0,0,0,0,0,0,0,0,0,0,0,0,0,0,0,0,0,0,0,0,0,0,0,0,0,0,0,0,0,0,0,0,0,0,0,0,0,0,0,0,0,0,0,0
0,0,0,0,0,0,0,0,0,0,0,0,0,0,0,0,0,0,0,0,0,0,0,0,0,0,0,0,0,0,0,0,0,0,0,0,0,0,0,0,0,0,0,0,0,0,0,0,0,0,0,0,0
0,0,0,0,0,0,0,0,0,0,0,0,0,0,0,0,0,0,0,0,0,0,0,0,0,0,0,0,0,0,0,0,0,0,0,0,0,0,0,0,0,0,0,0,0,0,0,0,0,0,0,0,0
0,0,0,0,0,0,0,0,0,0,0,0,0,0,0,0,0,0,0,0,0,0,0,0,0,0,0,0,0,0,0,0,0,0,0,0,0,0,0,0,0,0,0,0,0,0,0,0,0,0,0,0,0
0,0,0,0,0,0,0,0,0,0,0,0,0,0,0,0,0,0,0,0,0,0,0,0,0,0,0,0,0,0,0,0,0,0,0,0,0,0,0,0,0,0,0,0,0,0,0,0,0,0,0,0,0
0,0,0,0,0,0,0,0,0,0,0,0,0,0,0,0,0,0,0,0,0,0,0,0,0,0,0,0,0,0,0,0,0,0,0,0,0,0,0,0,0,0,0,0,0,0,0,0,0,0,0,0,0
0,0,0,0,0,0,0,0,0,0,0,0,0,0,0,0,0,0,0,0,0,0,0,0,0,0,0,0,0,0,0,0,0,0,0,0,0,0,0,0,0,0,0,0,0,0,0,0,0,0,0,0,0
0,0,0,0,0,0,0,0,0,0,0,0,0,0,0,0,0,0,0,0,0,0,0,0,0,0,0,0,0,0,0,0,0,0,0,0,0,0,0,0,0,0,0,0,0,0,0,0,0,0,0,0,0
0,0,0,0,0,0,0,0,0,0,0,0,0,0,0,0,0,0,0,0,0,0,0,0,0,0,0,0,0,0,0,0,0,0,0,0,0,0,0,0,0,0,0,0,0,0,0,0,0,0,0,0,0
0,0,0,0,0,0,0,0,0,0,0,0,0,0,0,0,0,0,0,0,0,0,0,0,0,0,0,0,0,0,0,0,0,0,0,0,0,0,0,0,0,0,0,0,0,0,0,0,0,0,0,0,0
0,0,0,0,0,0,0,0,0,0,0,0,0,0,0,0,0,0,0,0,0,0,0,0,0,0,0,0,0,0,0,0,0,0,0,0,0,0,0,0,0,0,0,0,0,0,0,0,0,0,0,0,0
0,0,0,0,0,0,0,0,0,0,0,0,0,0,0,0,0,0,0,0,0,0,0,0,0,0,0,0,0,0,0,0,0,0,0,0,0,0,0,0,0,0,0,0,0,0,0,0,0,0,0,0,0
0,0,0,0,0,0,0,0,0,0,79,0,0,0,0,0,0,0,0,0,0,0,0,0,0,0,0,0,26,16,16,16,16,16,20,0,0,0,0,0,0,0,0,0,0,0,0,0,0,0,0,0,0
0,0,0,0,0,0,0,0,0,0,0,0,0,0,0,0,0,0,0,0,0,0,0,0,0,0,0,0,26,7,7,7,7,7,20,0,0,0,0,0,0,0,0,0,0,0,0,0,0,0,0,0,0
0,0,0,0,0,0,0,0,0,0,0,0,0,0,0,0,0,0,0,0,0,0,0,0,0,0,0,0,26,7,0,0,0,7,20,0,0,0,0,0,0,0,0,0,0,0,0,0,0,0,0,0,0
0,0,0,0,0,0,0,0,0,0,0,0,0,0,0,0,0,0,0,0,0,0,0,0,0,0,0,0,26,7,135,0,0,7,20,0,0,0,0,0,0,0,0,0,0,0,0,0,0,0,0,0,0
0,0,0,0,0,0,0,0,0,0,0,0,0,0,0,0,0,0,0,0,0,0,0,0,0,0,0,0,26,7,0,114,0,7,20,0,0,0,0,0,0,0,0,0,0,0,0,0,0,0,0,0,0
0,0,0,0,0,0,0,0,0,0,79,0,0,0,0,0,0,0,0,0,0,0,0,0,0,0,0,0,26,7,7,7,7,7,20,0,0,0,0,0,0,0,0,0,0,0,0,0,0,0,0,0,0
0,0,0,0,0,0,0,0,0,0,0,0,0,0,0,0,0,0,0,0,0,0,0,0,0,0,0,0,26,47,47,47,47,47,20,0,0,0,0,0,0,0,0,0,0,0,0,0,0,0,0,0,0
0,0,0,0,0,0,0,0,0,0,0,0,0,0,0,0,0,0,0,0,0,0,0,0,0,0,0,0,0,0,0,0,0,0,0,0,0,0,0,0,0,0,0,0,0,0,0,0,0,0,0,0,0
0,0,0,0,0,0,0,0,0,0,0,0,0,0,0,0,0,0,0,0,0,0,0,0,0,0,0,0,0,0,0,0,0,0,0,0,0,0,0,0,0,0,0,0,0,0,0,0,0,0,0,0,0
0,0,0,0,0,0,0,0,0,0,0,0,0,0,0,0,0,0,0,0,0,0,0,0,0,0,0,0,0,0,0,0,174,16,16,16,16,16,16,20,0,0,0,0,0,0,0,0,0,0,0,0,0
0,0,0,0,0,0,0,0,0,0,79,0,0,0,0,0,0,0,0,0,0,0,0,0,0,0,0,0,0,0,0,0,26,17,17,17,17,17,17,20,0,0,0,0,0,0,0,0,0,0,0,0,0
0,0,0,0,0,0,0,0,0,0,0,0,0,0,0,0,0,0,0,0,0,0,0,0,0,0,0,0,0,0,0,0,26,17,17,17,17,17,17,20,0,0,0,0,0,0,0,0,0,0,0,0,0
0,0,0,0,0,0,0,0,0,0,0,0,0,0,0,0,0,0,0,0,0,0,0,0,0,0,0,0,0,0,0,0,174,47,47,47,47,47,47,174,0,0,0,0,0,0,0,0,0,0,0,0,0
0,0,0,0,0,0,0,0,0,0,0,0,0,0,0,0,0,0,0,0,0,0,0,0,0,0,0,0,0,0,0,0,0,0,0,0,0,0,0,0,0,0,0,0,0,0,0,0,0,0,0,0,0
0,0,0,0,0,0,0,0,0,0,0,0,0,0,0,0,0,0,0,0,0,0,0,0,0,0,0,0,0,0,0,0,0,0,0,0,0,0,0,0,0,0,0,0,0,0,0,0,0,0,0,0,0
0,0,0,0,0,0,0,0,0,0,79,0,0,0,0,0,0,0,0,0,0,0,0,0,0,0,0,0,0,0,0,0,0,0,0,0,0,0,0,0,0,0,0,0,0,0,0,0,0,0,0,0,0
0,0,0,0,0,0,0,0,0,0,0,0,0,0,0,0,0,0,0,0,0,0,0,0,0,0,0,0,0,0,0,0,0,0,0,0,0,0,0,0,0,0,0,0,0,0,0,0,0,0,0,0,0
0,0,0,0,0,0,0,0,0,0,0,0,0,0,0,0,0,0,0,0,0,0,0,0,0,0,0,0,0,0,0,0,0,0,0,0,0,0,0,0,0,0,0,0,0,0,0,0,0,0,0,0,0
0,0,0,0,0,0,0,0,0,0,0,0,0,0,0,0,0,0,0,0,0,0,0,0,0,0,0,0,0,0,0,0,0,0,0,0,0,0,0,0,0,0,0,0,0,0,0,0,0,0,0,0,0
0,0,0,0,0,0,0,0,0,0,0,0,0,0,0,0,0,0,0,0,0,0,0,0,0,0,0,0,0,0,0,0,0,0,0,0,0,0,0,0,0,0,0,0,0,0,0,0,0,0,0,0,0
0,0,0,0,0,0,0,0,0,0,0,0,0,0,0,0,0,0,0,0,0,0,0,0,0,0,0,0,0,0,0,0,0,0,0,0,0,0,0,0,0,0,0,0,0,0,0,0,0,0,0,0,0
0,0,0,0,0,0,0,0,0,0,0,0,0,0,0,0,0,0,0,0,0,0,0,0,0,0,0,0,0,0,0,0,0,0,0,0,0,0,0,0,0,0,0,0,0,0,0,0,0,0,0,0,0
0,0,0,0,0,0,0,0,0,0,0,0,0,0,0,0,0,0,0,0,0,0,0,0,0,0,0,0,0,0,0,0,0,0,0,0,0,0,0,0,0,0,0,0,0,0,0,0,0,0,0,0,0
0,0,0,0,0,0,0,0,0,0,0,0,0,0,0,0,0,0,0,0,0,0,0,0,0,0,0,0,0,0,0,0,0,0,0,0,0,0,0,0,0,0,0,0,0,0,0,0,0,0,0,0,0
:endlayer
layer: 17
0,0,0,0,0,0,0,0,0,0,0,0,0,0,0,0,0,0,0,0,0,0,0,0,0,0,0,0,0,0,0,0,0,0,0,0,0,0,0,0,0,0,0,0,0,0,0,0,0,0,0,0,0
0,0,0,0,0,0,0,0,0,0,0,0,0,0,0,0,0,0,0,0,0,0,0,0,0,0,0,0,0,0,0,0,0,0,0,0,0,0,0,0,0,0,0,0,0,0,0,0,0,0,0,0,0
0,0,0,0,0,0,0,0,0,0,0,0,0,0,0,0,0,0,0,0,0,0,0,0,0,0,0,0,0,0,0,0,0,0,0,0,0,0,0,0,0,0,0,0,0,0,0,0,0,0,0,0,0
0,0,0,0,0,0,0,0,0,0,0,0,0,0,0,0,0,0,0,0,0,0,0,0,0,0,0,0,0,0,0,0,0,0,0,0,0,0,0,0,0,0,0,0,0,0,0,0,0,0,0,0,0
0,0,0,0,0,0,0,0,0,0,0,0,0,0,0,0,0,0,0,0,0,0,0,0,0,0,0,0,0,0,0,0,0,0,0,0,0,0,0,0,0,0,0,0,0,0,0,0,0,0,0,0,0
0,0,0,0,0,0,0,0,0,0,0,0,0,0,0,0,0,0,0,0,0,0,0,0,0,0,0,0,0,0,0,0,0,0,0,0,0,0,0,0,0,0,0,0,0,0,0,0,0,0,0,0,0
0,0,0,0,0,0,0,0,0,0,0,0,0,0,0,0,0,0,0,0,0,0,0,0,0,0,0,0,0,0,0,0,0,0,0,0,0,0,0,0,0,0,0,0,0,0,0,0,0,0,0,0,0
0,0,0,0,0,0,0,0,0,0,0,0,0,0,0,0,0,0,0,0,0,0,0,0,0,0,0,0,0,0,0,0,0,0,0,0,0,0,0,0,0,0,0,0,0,0,0,0,0,0,0,0,0
0,0,0,0,0,0,0,0,0,0,0,0,0,0,0,0,0,0,0,0,0,0,0,0,0,0,0,0,0,0,0,0,0,0,0,0,0,0,0,0,0,0,0,0,0,0,0,0,0,0,0,0,0
0,0,0,0,0,0,0,0,0,0,0,0,0,0,0,0,0,0,0,0,0,0,0,0,0,0,0,0,0,0,0,0,0,0,0,0,0,0,0,0,0,0,0,0,0,0,0,0,0,0,0,0,0
0,0,0,0,0,0,0,0,0,0,0,0,0,0,0,0,0,0,0,0,0,0,0,0,0,0,0,0,0,0,0,0,0,0,0,0,0,0,0,0,0,0,0,0,0,0,0,0,0,0,0,0,0
0,0,0,0,0,0,0,0,0,0,0,0,0,0,0,0,0,0,0,0,0,0,0,0,0,0,0,0,0,0,0,0,0,0,0,0,0,0,0,0,0,0,0,0,0,0,0,0,0,0,0,0,0
0,0,0,0,0,0,0,0,0,0,0,0,0,0,0,0,0,0,0,0,0,0,0,0,0,0,0,0,0,0,0,0,0,0,0,0,0,0,0,0,0,0,0,0,0,0,0,0,0,0,0,0,0
0,0,0,0,0,0,0,0,0,0,0,0,0,0,0,0,0,0,0,0,0,0,0,0,0,0,0,0,0,0,0,0,0,0,0,0,0,0,0,0,0,0,0,0,0,0,0,0,0,0,0,0,0
0,0,0,0,0,0,0,0,0,0,0,0,0,0,0,0,0,0,0,0,0,0,0,0,0,0,0,0,0,0,0,0,0,0,0,0,0,0,0,0,0,0,0,0,0,0,0,0,0,0,0,0,0
0,0,0,0,0,0,0,0,0,0,0,0,0,0,0,0,0,0,0,0,0,0,0,0,0,0,0,0,0,0,0,0,0,0,0,0,0,0,0,0,0,0,0,0,0,0,0,0,0,0,0,0,0
0,0,0,0,0,0,0,0,0,0,0,0,0,0,0,0,0,0,0,0,0,0,0,0,0,0,0,0,0,0,0,0,0,0,0,0,0,0,0,0,0,0,0,0,0,0,0,0,0,0,0,0,0
0,0,0,0,0,0,0,0,0,0,0,0,0,0,0,0,0,0,0,0,0,0,0,0,0,0,0,0,0,0,0,0,0,0,0,0,0,0,0,0,0,0,0,0,0,0,0,0,0,0,0,0,0
0,0,0,0,0,0,0,0,0,0,0,0,0,0,0,0,0,0,0,0,0,0,0,0,0,0,0,0,0,0,0,0,0,0,0,0,0,0,0,0,0,0,0,0,0,0,0,0,0,0,0,0,0
0,0,0,0,0,0,0,0,0,0,0,0,0,0,0,0,0,0,0,0,0,0,0,0,0,0,0,0,0,0,0,0,0,0,0,0,0,0,0,0,0,0,0,0,0,0,0,0,0,0,0,0,0
0,0,0,0,0,0,0,0,0,0,0,0,0,0,0,0,0,0,0,0,0,0,0,0,0,0,0,0,0,0,0,0,0,0,0,0,0,0,0,0,0,0,0,0,0,0,0,0,0,0,0,0,0
0,0,0,0,0,0,0,0,0,0,0,0,0,0,0,0,0,0,0,0,0,0,0,0,0,0,0,0,0,16,16,16,16,20,0,0,0,0,0,0,0,0,0,0,0,0,0,0,0,0,0,0,0
0,0,0,0,0,0,0,0,0,0,0,0,0,0,0,0,0,0,0,0,0,0,0,0,0,0,0,0,0,26,17,0,17,20,0,0,0,0,0,0,0,0,0,0,0,0,0,0,0,0,0,0,0
0,0,0,0,0,0,0,0,0,0,0,0,0,0,0,0,0,0,0,0,0,0,0,0,0,0,0,0,0,26,0,0,0,20,0,0,0,0,0,0,0,0,0,0,0,0,0,0,0,0,0,0,0
0,0,0,0,0,0,0,0,0,0,0,0,0,0,0,0,0,0,0,0,0,0,0,0,0,0,0,0,0,26,17,0,17,20,0,0,0,0,0,0,0,0,0,0,0,0,0,0,0,0,0,0,0
0,0,0,0,0,0,0,0,0,0,0,0,0,0,0,0,0,0,0,0,0,0,0,0,0,0,0,0,0,26,47,47,47,47,0,0,0,0,0,0,0,0,0,0,0,0,0,0,0,0,0,0,0
0,0,0,0,0,0,0,0,0,0,0,0,0,0,0,0,0,0,0,0,0,0,0,0,0,0,0,0,0,0,0,0,0,0,0,0,0,0,0,0,0,0,0,0,0,0,0,0,0,0,0,0,0
0,0,0,0,0,0,0,0,0,0,0,0,0,0,0,0,0,0,0,0,0,0,0,0,0,0,0,0,0,0,0,0,0,0,0,0,0,0,0,0,0,0,0,0,0,0,0,0,0,0,0,0,0
0,0,0,0,0,0,0,0,0,0,0,0,0,0,0,0,0,0,0,0,0,0,0,0,0,0,0,0,0,0,0,0,0,0,0,0,0,0,0,0,0,0,0,0,0,0,0,0,0,0,0,0,0
0,0,0,0,0,0,0,0,0,0,0,0,0,0,0,0,0,0,0,0,0,0,0,0,0,0,0,0,0,0,0,0,0,0,0,0,0,0,0,0,0,0,0,0,0,0,0,0,0,0,0,0,0
0,0,0,0,0,0,0,0,0,0,0,0,0,0,0,0,0,0,0,0,0,0,0,0,0,0,0,0,0,0,0,0,0,174,16,16,16,16,174,0,0,0,0,0,0,0,0,0,0,0,0,0,0
0,0,0,0,0,0,0,0,0,0,0,0,0,0,0,0,0,0,0,0,0,0,0,0,0,0,0,0,0,0,0,0,0,174,47,47,47,47,174,0,0,0,0,0,0,0,0,0,0,0,0,0,0
0,0,0,0,0,0,0,0,0,0,0,0,0,0,0,0,0,0,0,0,0,0,0,0,0,0,0,0,0,0,0,0,0,0,0,0,0,0,0,0,0,0,0,0,0,0,0,0,0,0,0,0,0
0,0,0,0,0,0,0,0,0,0,0,0,0,0,0,0,0,0,0,0,0,0,0,0,0,0,0,0,0,0,0,0,0,0,0,0,0,0,0,0,0,0,0,0,0,0,0,0,0,0,0,0,0
0,0,0,0,0,0,0,0,0,0,0,0,0,0,0,0,0,0,0,0,0,0,0,0,0,0,0,0,0,0,0,0,0,0,0,0,0,0,0,0,0,0,0,0,0,0,0,0,0,0,0,0,0
0,0,0,0,0,0,0,0,0,0,0,0,0,0,0,0,0,0,0,0,0,0,0,0,0,0,0,0,0,0,0,0,0,0,0,0,0,0,0,0,0,0,0,0,0,0,0,0,0,0,0,0,0
0,0,0,0,0,0,0,0,0,0,0,0,0,0,0,0,0,0,0,0,0,0,0,0,0,0,0,0,0,0,0,0,0,0,0,0,0,0,0,0,0,0,0,0,0,0,0,0,0,0,0,0,0
0,0,0,0,0,0,0,0,0,0,0,0,0,0,0,0,0,0,0,0,0,0,0,0,0,0,0,0,0,0,0,0,0,0,0,0,0,0,0,0,0,0,0,0,0,0,0,0,0,0,0,0,0
0,0,0,0,0,0,0,0,0,0,0,0,0,0,0,0,0,0,0,0,0,0,0,0,0,0,0,0,0,0,0,0,0,0,0,0,0,0,0,0,0,0,0,0,0,0,0,0,0,0,0,0,0
0,0,0,0,0,0,0,0,0,0,0,0,0,0,0,0,0,0,0,0,0,0,0,0,0,0,0,0,0,0,0,0,0,0,0,0,0,0,0,0,0,0,0,0,0,0,0,0,0,0,0,0,0
0,0,0,0,0,0,0,0,0,0,0,0,0,0,0,0,0,0,0,0,0,0,0,0,0,0,0,0,0,0,0,0,0,0,0,0,0,0,0,0,0,0,0,0,0,0,0,0,0,0,0,0,0
0,0,0,0,0,0,0,0,0,0,0,0,0,0,0,0,0,0,0,0,0,0,0,0,0,0,0,0,0,0,0,0,0,0,0,0,0,0,0,0,0,0,0,0,0,0,0,0,0,0,0,0,0
0,0,0,0,0,0,0,0,0,0,0,0,0,0,0,0,0,0,0,0,0,0,0,0,0,0,0,0,0,0,0,0,0,0,0,0,0,0,0,0,0,0,0,0,0,0,0,0,0,0,0,0,0
0,0,0,0,0,0,0,0,0,0,0,0,0,0,0,0,0,0,0,0,0,0,0,0,0,0,0,0,0,0,0,0,0,0,0,0,0,0,0,0,0,0,0,0,0,0,0,0,0,0,0,0,0
:endlayer
layer: 18
0,0,0,0,0,0,0,0,0,0,0,0,0,0,0,0,0,0,0,0,0,0,0,0,0,0,0,0,0,0,0,0,0,0,0,0,0,0,0,0,0,0,0,0,0,0,0,0,0,0,0,0,0
0,0,0,0,0,0,0,0,0,0,0,0,0,0,0,0,0,0,0,0,0,0,0,0,0,0,0,0,0,0,0,0,0,0,0,0,0,0,0,0,0,0,0,0,0,0,0,0,0,0,0,0,0
0,0,0,0,0,0,0,0,0,0,0,0,0,0,0,0,0,0,0,0,0,0,0,0,0,0,0,0,0,0,0,0,0,0,0,0,0,0,0,0,0,0,0,0,0,0,0,0,0,0,0,0,0
0,0,0,0,0,0,0,0,0,0,0,0,0,0,0,0,0,0,0,0,0,0,0,0,0,0,0,0,0,0,0,0,0,0,0,0,0,0,0,0,0,0,0,0,0,0,0,0,0,0,0,0,0
0,0,0,0,0,0,0,0,0,0,0,0,0,0,0,0,0,0,0,0,0,0,0,0,0,0,0,0,0,0,0,0,0,0,0,0,0,0,0,0,0,0,0,0,0,0,0,0,0,0,0,0,0
0,0,0,0,0,0,0,0,0,0,0,0,0,0,0,0,0,0,0,0,0,0,0,0,0,0,0,0,0,0,0,0,0,0,0,0,0,0,0,0,0,0,0,0,0,0,0,0,0,0,0,0,0
0,0,0,0,0,0,0,0,0,0,0,0,0,0,0,0,0,0,0,0,0,0,0,0,0,0,0,0,0,0,0,0,0,0,0,0,0,0,0,0,0,0,0,0,0,0,0,0,0,0,0,0,0
0,0,0,0,0,0,0,0,0,0,0,0,0,0,0,0,0,0,0,0,0,0,0,0,0,0,0,0,0,0,0,0,0,0,0,0,0,0,0,0,0,0,0,0,0,0,0,0,0,0,0,0,0
0,0,0,0,0,0,0,0,0,0,0,0,0,0,0,0,0,0,0,0,0,0,0,0,0,0,0,0,0,0,0,0,0,0,0,0,0,0,0,0,0,0,0,0,0,0,0,0,0,0,0,0,0
0,0,0,0,0,0,0,0,0,0,0,0,0,0,0,0,0,0,0,0,0,0,0,0,0,0,0,0,0,0,0,0,0,0,0,0,0,0,0,0,0,0,0,0,0,0,0,0,0,0,0,0,0
0,0,0,0,0,0,0,0,0,0,0,0,0,0,0,0,0,0,0,0,0,0,0,0,0,0,0,0,0,0,0,0,0,0,0,0,0,0,0,0,0,0,0,0,0,0,0,0,0,0,0,0,0
0,0,0,0,0,0,0,0,0,0,0,0,0,0,0,0,0,0,0,0,0,0,0,0,0,0,0,0,0,0,0,0,0,0,0,0,0,0,0,0,0,0,0,0,0,0,0,0,0,0,0,0,0
0,0,0,0,0,0,0,0,0,0,0,0,0,0,0,0,0,0,0,0,0,0,0,0,0,0,0,0,0,0,0,0,0,0,0,0,0,0,0,0,0,0,0,0,0,0,0,0,0,0,0,0,0
0,0,0,0,0,0,0,0,0,0,0,0,0,0,0,0,0,0,0,0,0,0,0,0,0,0,0,0,0,0,0,0,0,0,0,0,0,0,0,0,0,0,0,0,0,0,0,0,0,0,0,0,0
0,0,0,0,0,0,0,0,0,0,0,0,0,0,0,0,0,0,0,0,0,0,0,0,0,0,0,0,0,0,0,0,0,0,0,0,0,0,0,0,0,0,0,0,0,0,0,0,0,0,0,0,0
0,0,0,0,0,0,0,0,0,0,0,0,0,0,0,0,0,0,0,0,0,0,0,0,0,0,0,0,0,0,0,0,0,0,0,0,0,0,0,0,0,0,0,0,0,0,0,0,0,0,0,0,0
0,0,0,0,0,0,0,0,0,0,0,0,0,0,0,0,0,0,0,0,0,0,0,0,0,0,0,0,0,0,0,0,0,0,0,0,0,0,0,0,0,0,0,0,0,0,0,0,0,0,0,0,0
0,0,0,0,0,0,0,0,0,0,0,0,0,0,0,0,0,0,0,0,0,0,0,0,0,0,0,0,0,0,0,0,0,0,0,0,0,0,0,0,0,0,0,0,0,0,0,0,0,0,0,0,0
0,0,0,0,0,0,0,0,0,0,0,0,0,0,0,0,0,0,0,0,0,0,0,0,0,0,0,0,0,0,0,0,0,0,0,0,0,0,0,0,0,0,0,0,0,0,0,0,0,0,0,0,0
0,0,0,0,0,0,0,0,0,0,0,0,0,0,0,0,0,0,0,0,0,0,0,0,0,0,0,0,0,0,0,0,0,0,0,0,0,0,0,0,0,0,0,0,0,0,0,0,0,0,0,0,0
0,0,0,0,0,0,0,0,0,0,0,0,0,0,0,0,0,0,0,0,0,0,0,0,0,0,0,0,0,0,0,0,0,0,0,0,0,0,0,0,0,0,0,0,0,0,0,0,0,0,0,0,0
0,0,0,0,0,0,0,0,0,0,0,0,0,0,0,0,0,0,0,0,0,0,0,0,0,0,0,0,0,0,0,0,0,0,0,0,0,0,0,0,0,0,0,0,0,0,0,0,0,0,0,0,0
0,0,0,0,0,0,0,0,0,0,0,0,0,0,0,0,0,0,0,0,0,0,0,0,0,0,0,0,0,0,16,16,16,0,0,0,0,0,0,0,0,0,0,0,0,0,0,0,0,0,0,0,0
0,0,0,0,0,0,0,0,0,0,0,0,0,0,0,0,0,0,0,0,0,0,0,0,0,0,0,0,0,0,26,17,20,0,0,0,0,0,0,0,0,0,0,0,0,0,0,0,0,0,0,0,0
0,0,0,0,0,0,0,0,0,0,0,0,0,0,0,0,0,0,0,0,0,0,0,0,0,0,0,0,0,0,47,47,47,0,0,0,0,0,0,0,0,0,0,0,0,0,0,0,0,0,0,0,0
0,0,0,0,0,0,0,0,0,0,0,0,0,0,0,0,0,0,0,0,0,0,0,0,0,0,0,0,0,0,0,0,0,0,0,0,0,0,0,0,0,0,0,0,0,0,0,0,0,0,0,0,0
0,0,0,0,0,0,0,0,0,0,0,0,0,0,0,0,0,0,0,0,0,0,0,0,0,0,0,0,0,0,0,0,0,0,0,0,0,0,0,0,0,0,0,0,0,0,0,0,0,0,0,0,0
0,0,0,0,0,0,0,0,0,0,0,0,0,0,0,0,0,0,0,0,0,0,0,0,0,0,0,0,0,0,0,0,0,0,0,0,0,0,0,0,0,0,0,0,0,0,0,0,0,0,0,0,0
0,0,0,0,0,0,0,0,0,0,0,0,0,0,0,0,0,0,0,0,0,0,0,0,0,0,0,0,0,0,0,0,0,0,0,0,0,0,0,0,0,0,0,0,0,0,0,0,0,0,0,0,0
0,0,0,0,0,0,0,0,0,0,0,0,0,0,0,0,0,0,0,0,0,0,0,0,0,0,0,0,0,0,0,0,0,0,0,0,0,0,0,0,0,0,0,0,0,0,0,0,0,0,0,0,0
0,0,0,0,0,0,0,0,0,0,0,0,0,0,0,0,0,0,0,0,0,0,0,0,0,0,0,0,0,0,0,0,0,0,0,0,0,0,0,0,0,0,0,0,0,0,0,0,0,0,0,0,0
0,0,0,0,0,0,0,0,0,0,0,0,0,0,0,0,0,0,0,0,0,0,0,0,0,0,0,0,0,0,0,0,0,0,0,0,0,0,0,0,0,0,0,0,0,0,0,0,0,0,0,0,0
0,0,0,0,0,0,0,0,0,0,0,0,0,0,0,0,0,0,0,0,0,0,0,0,0,0,0,0,0,0,0,0,0,0,0,0,0,0,0,0,0,0,0,0,0,0,0,0,0,0,0,0,0
0,0,0,0,0,0,0,0,0,0,0,0,0,0,0,0,0,0,0,0,0,0,0,0,0,0,0,0,0,0,0,0,0,0,0,0,0,0,0,0,0,0,0,0,0,0,0,0,0,0,0,0,0
0,0,0,0,0,0,0,0,0,0,0,0,0,0,0,0,0,0,0,0,0,0,0,0,0,0,0,0,0,0,0,0,0,0,0,0,0,0,0,0,0,0,0,0,0,0,0,0,0,0,0,0,0
0,0,0,0,0,0,0,0,0,0,0,0,0,0,0,0,0,0,0,0,0,0,0,0,0,0,0,0,0,0,0,0,0,0,0,0,0,0,0,0,0,0,0,0,0,0,0,0,0,0,0,0,0
0,0,0,0,0,0,0,0,0,0,0,0,0,0,0,0,0,0,0,0,0,0,0,0,0,0,0,0,0,0,0,0,0,0,0,0,0,0,0,0,0,0,0,0,0,0,0,0,0,0,0,0,0
0,0,0,0,0,0,0,0,0,0,0,0,0,0,0,0,0,0,0,0,0,0,0,0,0,0,0,0,0,0,0,0,0,0,0,0,0,0,0,0,0,0,0,0,0,0,0,0,0,0,0,0,0
0,0,0,0,0,0,0,0,0,0,0,0,0,0,0,0,0,0,0,0,0,0,0,0,0,0,0,0,0,0,0,0,0,0,0,0,0,0,0,0,0,0,0,0,0,0,0,0,0,0,0,0,0
0,0,0,0,0,0,0,0,0,0,0,0,0,0,0,0,0,0,0,0,0,0,0,0,0,0,0,0,0,0,0,0,0,0,0,0,0,0,0,0,0,0,0,0,0,0,0,0,0,0,0,0,0
0,0,0,0,0,0,0,0,0,0,0,0,0,0,0,0,0,0,0,0,0,0,0,0,0,0,0,0,0,0,0,0,0,0,0,0,0,0,0,0,0,0,0,0,0,0,0,0,0,0,0,0,0
0,0,0,0,0,0,0,0,0,0,0,0,0,0,0,0,0,0,0,0,0,0,0,0,0,0,0,0,0,0,0,0,0,0,0,0,0,0,0,0,0,0,0,0,0,0,0,0,0,0,0,0,0
0,0,0,0,0,0,0,0,0,0,0,0,0,0,0,0,0,0,0,0,0,0,0,0,0,0,0,0,0,0,0,0,0,0,0,0,0,0,0,0,0,0,0,0,0,0,0,0,0,0,0,0,0
0,0,0,0,0,0,0,0,0,0,0,0,0,0,0,0,0,0,0,0,0,0,0,0,0,0,0,0,0,0,0,0,0,0,0,0,0,0,0,0,0,0,0,0,0,0,0,0,0,0,0,0,0
:endlayer
layer: 19
0,0,0,0,0,0,0,0,0,0,0,0,0,0,0,0,0,0,0,0,0,0,0,0,0,0,0,0,0,0,0,0,0,0,0,0,0,0,0,0,0,0,0,0,0,0,0,0,0,0,0,0,0
0,0,0,0,0,0,0,0,0,0,0,0,0,0,0,0,0,0,0,0,0,0,0,0,0,0,0,0,0,0,0,0,0,0,0,0,0,0,0,0,0,0,0,0,0,0,0,0,0,0,0,0,0
0,0,0,0,0,0,0,0,0,0,0,0,0,0,0,0,0,0,0,0,0,0,0,0,0,0,0,0,0,0,0,0,0,0,0,0,0,0,0,0,0,0,0,0,0,0,0,0,0,0,0,0,0
0,0,0,0,0,0,0,0,0,0,0,0,0,0,0,0,0,0,0,0,0,0,0,0,0,0,0,0,0,0,0,0,0,0,0,0,0,0,0,0,0,0,0,0,0,0,0,0,0,0,0,0,0
0,0,0,0,0,0,0,0,0,0,0,0,0,0,0,0,0,0,0,0,0,0,0,0,0,0,0,0,0,0,0,0,0,0,0,0,0,0,0,0,0,0,0,0,0,0,0,0,0,0,0,0,0
0,0,0,0,0,0,0,0,0,0,0,0,0,0,0,0,0,0,0,0,0,0,0,0,0,0,0,0,0,0,0,0,0,0,0,0,0,0,0,0,0,0,0,0,0,0,0,0,0,0,0,0,0
0,0,0,0,0,0,0,0,0,0,0,0,0,0,0,0,0,0,0,0,0,0,0,0,0,0,0,0,0,0,0,0,0,0,0,0,0,0,0,0,0,0,0,0,0,0,0,0,0,0,0,0,0
0,0,0,0,0,0,0,0,0,0,0,0,0,0,0,0,0,0,0,0,0,0,0,0,0,0,0,0,0,0,0,0,0,0,0,0,0,0,0,0,0,0,0,0,0,0,0,0,0,0,0,0,0
0,0,0,0,0,0,0,0,0,0,0,0,0,0,0,0,0,0,0,0,0,0,0,0,0,0,0,0,0,0,0,0,0,0,0,0,0,0,0,0,0,0,0,0,0,0,0,0,0,0,0,0,0
0,0,0,0,0,0,0,0,0,0,0,0,0,0,0,0,0,0,0,0,0,0,0,0,0,0,0,0,0,0,0,0,0,0,0,0,0,0,0,0,0,0,0,0,0,0,0,0,0,0,0,0,0
0,0,0,0,0,0,0,0,0,0,0,0,0,0,0,0,0,0,0,0,0,0,0,0,0,0,0,0,0,0,0,0,0,0,0,0,0,0,0,0,0,0,0,0,0,0,0,0,0,0,0,0,0
0,0,0,0,0,0,0,0,0,0,0,0,0,0,0,0,0,0,0,0,0,0,0,0,0,0,0,0,0,0,0,0,0,0,0,0,0,0,0,0,0,0,0,0,0,0,0,0,0,0,0,0,0
0,0,0,0,0,0,0,0,0,0,0,0,0,0,0,0,0,0,0,0,0,0,0,0,0,0,0,0,0,0,0,0,0,0,0,0,0,0,0,0,0,0,0,0,0,0,0,0,0,0,0,0,0
0,0,0,0,0,0,0,0,0,0,0,0,0,0,0,0,0,0,0,0,0,0,0,0,0,0,0,0,0,0,0,0,0,0,0,0,0,0,0,0,0,0,0,0,0,0,0,0,0,0,0,0,0
0,0,0,0,0,0,0,0,0,0,0,0,0,0,0,0,0,0,0,0,0,0,0,0,0,0,0,0,0,0,0,0,0,0,0,0,0,0,0,0,0,0,0,0,0,0,0,0,0,0,0,0,0
0,0,0,0,0,0,0,0,0,0,0,0,0,0,0,0,0,0,0,0,0,0,0,0,0,0,0,0,0,0,0,0,0,0,0,0,0,0,0,0,0,0,0,0,0,0,0,0,0,0,0,0,0
0,0,0,0,0,0,0,0,0,0,0,0,0,0,0,0,0,0,0,0,0,0,0,0,0,0,0,0,0,0,0,0,0,0,0,0,0,0,0,0,0,0,0,0,0,0,0,0,0,0,0,0,0
0,0,0,0,0,0,0,0,0,0,0,0,0,0,0,0,0,0,0,0,0,0,0,0,0,0,0,0,0,0,0,0,0,0,0,0,0,0,0,0,0,0,0,0,0,0,0,0,0,0,0,0,0
0,0,0,0,0,0,0,0,0,0,0,0,0,0,0,0,0,0,0,0,0,0,0,0,0,0,0,0,0,0,0,0,0,0,0,0,0,0,0,0,0,0,0,0,0,0,0,0,0,0,0,0,0
0,0,0,0,0,0,0,0,0,0,0,0,0,0,0,0,0,0,0,0,0,0,0,0,0,0,0,0,0,0,0,0,0,0,0,0,0,0,0,0,0,0,0,0,0,0,0,0,0,0,0,0,0
0,0,0,0,0,0,0,0,0,0,0,0,0,0,0,0,0,0,0,0,0,0,0,0,0,0,0,0,0,0,0,0,0,0,0,0,0,0,0,0,0,0,0,0,0,0,0,0,0,0,0,0,0
0,0,0,0,0,0,0,0,0,0,0,0,0,0,0,0,0,0,0,0,0,0,0,0,0,0,0,0,0,0,0,0,0,0,0,0,0,0,0,0,0,0,0,0,0,0,0,0,0,0,0,0,0
0,0,0,0,0,0,0,0,0,0,0,0,0,0,0,0,0,0,0,0,0,0,0,0,0,0,0,0,0,0,0,0,0,0,0,0,0,0,0,0,0,0,0,0,0,0,0,0,0,0,0,0,0
0,0,0,0,0,0,0,0,0,0,0,0,0,0,0,0,0,0,0,0,0,0,0,0,0,0,0,0,0,0,0,17,0,0,0,0,0,0,0,0,0,0,0,0,0,0,0,0,0,0,0,0,0
0,0,0,0,0,0,0,0,0,0,0,0,0,0,0,0,0,0,0,0,0,0,0,0,0,0,0,0,0,0,0,0,0,0,0,0,0,0,0,0,0,0,0,0,0,0,0,0,0,0,0,0,0
0,0,0,0,0,0,0,0,0,0,0,0,0,0,0,0,0,0,0,0,0,0,0,0,0,0,0,0,0,0,0,0,0,0,0,0,0,0,0,0,0,0,0,0,0,0,0,0,0,0,0,0,0
0,0,0,0,0,0,0,0,0,0,0,0,0,0,0,0,0,0,0,0,0,0,0,0,0,0,0,0,0,0,0,0,0,0,0,0,0,0,0,0,0,0,0,0,0,0,0,0,0,0,0,0,0
0,0,0,0,0,0,0,0,0,0,0,0,0,0,0,0,0,0,0,0,0,0,0,0,0,0,0,0,0,0,0,0,0,0,0,0,0,0,0,0,0,0,0,0,0,0,0,0,0,0,0,0,0
0,0,0,0,0,0,0,0,0,0,0,0,0,0,0,0,0,0,0,0,0,0,0,0,0,0,0,0,0,0,0,0,0,0,0,0,0,0,0,0,0,0,0,0,0,0,0,0,0,0,0,0,0
0,0,0,0,0,0,0,0,0,0,0,0,0,0,0,0,0,0,0,0,0,0,0,0,0,0,0,0,0,0,0,0,0,0,0,0,0,0,0,0,0,0,0,0,0,0,0,0,0,0,0,0,0
0,0,0,0,0,0,0,0,0,0,0,0,0,0,0,0,0,0,0,0,0,0,0,0,0,0,0,0,0,0,0,0,0,0,0,0,0,0,0,0,0,0,0,0,0,0,0,0,0,0,0,0,0
0,0,0,0,0,0,0,0,0,0,0,0,0,0,0,0,0,0,0,0,0,0,0,0,0,0,0,0,0,0,0,0,0,0,0,0,0,0,0,0,0,0,0,0,0,0,0,0,0,0,0,0,0
0,0,0,0,0,0,0,0,0,0,0,0,0,0,0,0,0,0,0,0,0,0,0,0,0,0,0,0,0,0,0,0,0,0,0,0,0,0,0,0,0,0,0,0,0,0,0,0,0,0,0,0,0
0,0,0,0,0,0,0,0,0,0,0,0,0,0,0,0,0,0,0,0,0,0,0,0,0,0,0,0,0,0,0,0,0,0,0,0,0,0,0,0,0,0,0,0,0,0,0,0,0,0,0,0,0
0,0,0,0,0,0,0,0,0,0,0,0,0,0,0,0,0,0,0,0,0,0,0,0,0,0,0,0,0,0,0,0,0,0,0,0,0,0,0,0,0,0,0,0,0,0,0,0,0,0,0,0,0
0,0,0,0,0,0,0,0,0,0,0,0,0,0,0,0,0,0,0,0,0,0,0,0,0,0,0,0,0,0,0,0,0,0,0,0,0,0,0,0,0,0,0,0,0,0,0,0,0,0,0,0,0
0,0,0,0,0,0,0,0,0,0,0,0,0,0,0,0,0,0,0,0,0,0,0,0,0,0,0,0,0,0,0,0,0,0,0,0,0,0,0,0,0,0,0,0,0,0,0,0,0,0,0,0,0
0,0,0,0,0,0,0,0,0,0,0,0,0,0,0,0,0,0,0,0,0,0,0,0,0,0,0,0,0,0,0,0,0,0,0,0,0,0,0,0,0,0,0,0,0,0,0,0,0,0,0,0,0
0,0,0,0,0,0,0,0,0,0,0,0,0,0,0,0,0,0,0,0,0,0,0,0,0,0,0,0,0,0,0,0,0,0,0,0,0,0,0,0,0,0,0,0,0,0,0,0,0,0,0,0,0
0,0,0,0,0,0,0,0,0,0,0,0,0,0,0,0,0,0,0,0,0,0,0,0,0,0,0,0,0,0,0,0,0,0,0,0,0,0,0,0,0,0,0,0,0,0,0,0,0,0,0,0,0
0,0,0,0,0,0,0,0,0,0,0,0,0,0,0,0,0,0,0,0,0,0,0,0,0,0,0,0,0,0,0,0,0,0,0,0,0,0,0,0,0,0,0,0,0,0,0,0,0,0,0,0,0
0,0,0,0,0,0,0,0,0,0,0,0,0,0,0,0,0,0,0,0,0,0,0,0,0,0,0,0,0,0,0,0,0,0,0,0,0,0,0,0,0,0,0,0,0,0,0,0,0,0,0,0,0
0,0,0,0,0,0,0,0,0,0,0,0,0,0,0,0,0,0,0,0,0,0,0,0,0,0,0,0,0,0,0,0,0,0,0,0,0,0,0,0,0,0,0,0,0,0,0,0,0,0,0,0,0
