# Ancient Warfare Structure Template File
# Auto-generated structure template file. created on: 2/18/2017 at: 12:24:21
# Lines beginning with # denote comments

header:
version=2.1
name=ReignVillageLoftLibrary
size=13,31,16
offset=6,4,14
:endheader

#### VALIDATION ####
validation:
type=ground
survival=false
worldGenEnabled=false
unique=false
preserveBlocks=false
selectionWeight=0
clusterValue=0
minDuplicateDistance=0
dimensionWhiteList=false
dimensionList=
biomeWhiteList=false
biomeList=
leveling=0
fill=0
border=0
validTargetBlocks=
blockSwap=false
data:
:enddata
:endvalidation

#### LAYERS ####
layer: 0
1,1,1,1,1,1,1,1,1,1,1,1,1
1,1,1,1,1,1,1,1,1,1,1,1,1
1,1,2,3,3,3,3,3,3,3,2,1,1
1,1,3,3,3,3,3,3,3,5,3,1,1
1,1,3,3,3,3,3,3,3,3,3,1,1
1,1,3,3,3,3,3,3,3,3,3,1,1
1,1,3,3,3,3,3,3,3,3,3,1,1
1,1,3,3,3,3,3,3,3,3,3,1,1
1,1,3,3,3,3,3,3,3,3,3,1,1
1,1,3,3,3,3,3,3,3,3,3,1,1
1,1,3,3,3,3,3,3,3,3,3,1,1
1,1,3,3,3,3,3,3,3,3,3,1,1
1,1,3,3,3,3,3,3,3,5,3,1,1
1,1,2,3,3,3,3,3,3,3,4,1,1
1,1,1,1,1,1,1,1,1,1,1,1,1
1,1,1,1,1,1,1,1,1,1,1,1,1
:endlayer
layer: 1
1,1,1,1,1,1,1,1,1,1,1,1,1
1,1,1,1,1,1,1,1,1,1,1,1,1
1,1,2,3,3,3,3,3,3,3,2,1,1
1,1,3,11,0,0,0,0,0,0,3,1,1
1,1,3,11,0,0,0,0,0,0,3,1,1
1,1,3,11,0,0,0,0,0,0,3,1,1
1,1,3,11,0,0,0,2,9,6,3,1,1
1,1,3,11,0,0,0,10,7,7,3,1,1
1,1,3,11,0,0,0,0,8,8,3,1,1
1,1,3,11,0,0,0,0,0,0,3,1,1
1,1,3,11,0,0,0,0,0,0,3,1,1
1,1,3,11,0,0,0,0,0,0,3,1,1
1,1,3,11,0,0,0,0,0,0,3,1,1
1,1,2,3,3,3,3,3,3,3,2,1,1
1,1,1,1,1,1,1,1,1,1,1,1,1
1,1,1,1,1,1,1,1,1,1,1,1,1
:endlayer
layer: 2
1,1,1,1,1,1,1,1,1,1,1,1,1
1,1,1,1,1,1,1,1,1,1,1,1,1
1,1,2,3,3,3,3,3,3,3,2,1,1
1,1,3,11,0,0,0,0,0,0,3,1,1
1,1,3,11,0,0,0,0,0,0,3,1,1
1,1,3,11,0,0,0,0,0,0,3,1,1
1,1,3,11,0,0,0,2,7,7,3,1,1
1,1,3,11,0,0,0,0,8,8,3,1,1
1,1,3,5,0,0,0,0,0,0,3,1,1
1,1,3,11,0,0,0,0,0,0,3,1,1
1,1,3,11,0,0,0,0,0,0,3,1,1
1,1,3,11,0,0,0,0,0,0,3,1,1
1,1,3,11,0,0,0,0,0,0,3,1,1
1,1,2,3,3,3,3,3,3,3,2,1,1
1,1,1,1,1,1,1,1,1,1,1,1,1
1,1,1,1,1,1,1,1,1,1,1,1,1
:endlayer
layer: 3
12,12,12,12,12,12,12,12,12,12,12,12,12
12,12,12,12,12,12,12,12,12,12,12,12,12
12,12,2,3,3,3,3,3,3,3,2,12,12
12,12,3,11,0,0,0,0,0,0,3,12,12
12,12,3,11,0,0,0,0,0,0,3,12,12
12,12,3,11,0,0,0,0,0,0,3,12,12
12,12,3,11,0,0,0,2,8,8,3,12,12
12,12,3,11,0,0,0,0,0,0,3,12,12
12,12,3,11,0,0,0,0,0,0,3,12,12
12,12,3,11,0,0,0,0,0,0,3,12,12
12,12,3,11,0,0,0,0,0,0,3,12,12
12,12,3,11,0,0,0,0,0,0,3,12,12
12,12,3,11,0,0,0,0,0,0,3,12,12
12,12,2,3,3,3,3,3,3,3,2,12,12
12,12,12,12,12,12,12,12,12,12,12,12,12
12,12,12,12,12,12,12,12,12,12,12,12,12
:endlayer
layer: 4
0,0,20,0,0,0,0,0,0,0,0,0,0
0,0,14,0,0,0,0,0,0,0,14,0,0
0,14,2,3,3,3,3,3,3,3,2,14,0
0,0,3,16,19,18,19,16,17,16,3,0,0
0,0,3,17,18,19,18,17,16,17,3,0,0
0,0,3,16,19,18,19,16,8,8,3,13,0
0,0,3,17,18,19,18,17,0,0,3,0,0
0,0,3,16,19,18,19,18,0,0,3,0,0
0,0,3,17,18,19,18,19,0,0,3,15,0
0,0,3,16,19,18,19,18,19,18,3,0,0
0,0,3,17,18,19,18,19,18,19,3,15,0
0,0,3,16,19,18,19,18,19,18,3,15,0
0,0,3,17,18,19,18,19,18,19,3,15,13
0,14,2,3,3,3,3,3,3,3,2,15,13
0,0,14,0,0,23,22,21,0,13,13,0,13
0,0,0,0,0,15,0,13,0,20,13,0,0
:endlayer
layer: 5
0,0,0,0,0,0,0,0,0,0,0,0,0
0,0,14,0,0,0,0,0,0,0,14,0,0
0,14,2,3,3,3,3,3,3,3,2,14,0
0,0,3,11,0,11,0,0,0,0,3,0,0
0,0,3,0,0,25,0,0,0,0,3,0,0
0,0,3,0,0,11,0,0,0,0,3,0,0
0,0,3,11,11,11,0,0,0,0,3,0,0
0,0,3,0,0,0,0,0,0,0,3,0,0
0,0,3,27,0,0,0,0,8,8,3,0,0
0,0,3,28,26,0,0,0,0,0,3,0,0
0,0,3,29,0,0,0,0,0,0,3,0,0
0,0,3,0,0,0,0,0,0,0,3,0,0
0,0,3,11,11,11,0,0,0,0,3,0,0
0,14,2,3,3,3,24,3,3,3,2,0,0
0,0,14,0,0,0,0,0,0,0,0,0,0
0,0,0,0,0,0,0,0,0,0,0,0,0
:endlayer
layer: 6
0,0,0,0,0,0,0,0,0,0,0,0,0
0,0,14,0,0,0,0,0,0,0,14,0,0
0,14,2,3,30,30,3,30,30,3,2,14,0
0,0,3,11,0,14,0,0,0,0,3,0,0
0,0,30,0,0,0,0,0,0,0,30,0,0
0,0,30,0,0,0,0,0,0,0,3,0,0
0,0,3,0,0,14,0,0,0,0,3,0,0
0,0,30,0,0,0,0,0,8,8,3,0,0
0,0,30,0,0,0,0,0,0,0,3,0,0
0,0,3,0,0,0,0,0,0,0,3,0,0
0,0,30,0,0,0,0,0,0,0,3,0,0
0,0,30,0,0,0,0,0,0,0,30,0,0
0,0,3,0,0,0,0,0,0,0,3,0,0
0,14,2,3,30,3,31,3,30,3,2,0,0
0,0,14,0,0,0,0,0,0,0,0,0,0
0,0,0,0,0,0,0,0,0,0,0,0,0
:endlayer
layer: 7
0,0,0,0,0,0,0,0,0,0,0,0,0
0,0,14,0,0,0,0,0,0,0,14,0,0
0,14,2,3,3,3,3,3,3,3,2,14,0
0,0,3,0,0,14,34,0,0,32,3,0,0
0,0,3,0,0,14,0,0,0,0,3,0,0
0,0,3,0,0,14,0,0,0,0,3,0,0
0,0,3,14,14,14,0,0,8,8,3,0,0
0,0,3,0,0,0,0,0,0,0,3,0,0
0,0,3,0,0,0,0,0,0,0,3,0,0
0,0,3,0,0,0,0,0,0,0,3,0,0
0,0,3,0,0,0,0,0,0,32,3,0,0
0,0,3,0,0,0,0,0,0,0,3,0,0
0,0,3,0,0,33,0,33,0,0,3,0,0
0,14,2,3,3,3,3,3,3,3,2,0,0
0,0,14,0,0,0,0,0,0,0,0,0,0
0,0,0,0,0,0,0,0,0,0,0,0,0
:endlayer
layer: 8
0,0,0,0,0,0,0,0,0,0,0,0,0
0,0,36,0,0,0,0,0,0,0,36,0,0
0,35,36,35,35,35,35,35,35,35,35,35,0
0,0,36,19,19,19,36,19,19,19,36,0,0
0,0,36,19,5,19,36,19,19,19,36,0,0
0,0,36,19,19,19,36,19,8,8,36,0,0
0,0,36,19,19,19,36,19,0,0,36,0,0
0,0,36,19,5,19,36,19,0,0,36,0,0
0,0,36,19,19,19,36,19,0,0,36,0,0
0,0,36,19,19,19,36,19,0,0,36,0,0
0,0,36,19,19,19,36,19,19,19,36,0,0
0,0,36,19,5,19,36,19,19,19,36,0,0
0,0,36,19,19,19,36,19,19,19,36,0,0
0,35,35,35,35,35,35,35,35,35,36,35,0
0,0,36,0,0,0,0,0,0,0,36,0,0
0,0,0,0,0,0,0,0,0,0,0,0,0
:endlayer
layer: 9
0,0,0,0,0,0,0,0,0,0,0,0,0
0,0,14,0,0,0,0,0,0,0,14,0,0
0,14,2,37,37,37,2,37,37,37,2,14,0
0,0,37,11,40,11,11,11,11,11,37,0,0
0,0,37,43,0,0,0,0,0,0,37,0,0
0,0,37,11,0,0,0,0,0,0,37,0,0
0,0,2,11,0,0,0,14,0,0,2,0,0
0,0,37,44,41,0,0,14,0,0,37,0,0
0,0,37,11,0,0,0,14,0,0,37,0,0
0,0,2,11,0,0,0,14,0,0,2,0,0
0,0,37,11,0,0,0,14,14,11,37,0,0
0,0,37,45,0,0,0,0,0,38,37,0,0
0,0,37,11,42,11,11,11,39,11,37,0,0
0,14,2,37,37,37,2,37,37,37,2,0,0
0,0,14,0,0,0,0,0,0,0,0,0,0
0,0,0,0,0,0,0,0,0,0,0,0,0
:endlayer
layer: 10
0,0,0,0,0,0,0,0,0,0,0,0,0
0,0,14,0,0,0,0,0,0,0,14,0,0
0,14,2,37,30,37,2,37,30,37,2,14,0
0,0,37,11,0,11,11,11,0,11,37,0,0
0,0,30,0,0,0,0,0,0,0,30,0,0
0,0,37,11,0,0,0,0,0,0,37,0,0
0,0,2,11,0,0,0,0,0,0,2,0,0
0,0,37,0,0,0,0,0,0,0,37,0,0
0,0,37,11,0,0,0,0,0,0,37,0,0
0,0,2,11,0,0,0,0,0,0,2,0,0
0,0,37,11,0,0,0,0,0,11,37,0,0
0,0,30,0,0,0,0,0,0,38,30,0,0
0,0,37,11,0,11,11,11,0,11,37,0,0
0,14,2,37,30,37,2,37,30,37,2,0,0
0,0,0,0,0,0,0,0,0,0,0,0,0
0,0,0,0,0,0,0,0,0,0,0,0,0
:endlayer
layer: 11
0,0,0,0,0,0,0,0,0,0,0,0,0
0,0,14,0,0,0,0,0,0,0,14,0,0
0,14,2,37,30,37,2,37,30,37,2,14,0
0,0,37,11,0,11,11,11,0,11,37,0,0
0,0,30,0,0,0,0,0,0,0,30,0,0
0,0,37,11,0,0,0,0,0,0,37,0,0
0,0,2,11,0,0,0,0,0,0,2,0,0
0,0,37,11,0,0,0,0,0,0,37,0,0
0,0,37,11,0,0,0,0,0,0,37,0,0
0,0,2,11,0,0,0,0,0,0,2,0,0
0,0,37,11,0,0,0,0,0,11,37,0,0
0,0,30,0,0,0,0,0,0,38,30,0,0
0,0,37,11,0,11,11,11,0,11,37,0,0
0,14,2,37,30,37,2,37,30,37,2,0,0
0,0,0,0,0,0,0,0,0,0,0,0,0
0,0,0,0,0,0,0,0,0,0,0,0,0
:endlayer
layer: 12
0,0,0,0,0,0,0,0,0,0,0,0,0
0,0,14,0,0,0,0,0,0,0,14,0,0
0,14,2,37,37,37,2,37,37,37,2,14,0
0,0,37,11,11,11,11,11,11,11,37,0,0
0,0,37,11,0,0,0,0,0,0,37,0,0
0,0,37,11,0,0,0,0,0,0,37,0,0
0,0,2,11,0,0,0,0,0,0,2,0,0
0,0,37,11,0,0,0,0,0,0,37,0,0
0,0,37,11,0,0,0,0,0,0,37,0,0
0,0,2,11,0,0,0,0,0,0,2,0,0
0,0,37,11,0,0,0,0,0,11,37,0,0
0,0,37,11,0,0,0,0,0,38,37,0,0
0,0,37,11,11,11,11,11,11,11,37,0,0
0,14,2,37,37,37,2,37,37,37,2,0,0
0,0,0,0,0,0,0,0,0,0,0,0,0
0,0,0,0,0,0,0,0,0,0,0,0,0
:endlayer
layer: 13
0,0,0,0,0,0,0,0,0,0,0,0,0
0,48,36,0,0,0,0,0,0,0,36,46,0
0,35,35,35,35,35,35,35,35,35,36,35,0
0,0,36,5,47,47,36,47,47,5,36,0,0
0,0,36,47,47,47,36,47,47,5,36,0,0
0,0,36,47,47,47,36,47,47,47,36,0,0
0,48,36,35,35,35,5,35,35,35,36,46,0
0,0,36,47,47,47,36,47,47,47,36,0,0
0,0,36,47,47,47,36,47,47,47,36,0,0
0,48,36,35,35,35,5,35,35,35,36,46,0
0,0,36,47,47,47,36,47,47,47,36,0,0
0,0,36,47,47,47,36,47,47,38,36,0,0
0,0,36,5,47,47,36,47,47,5,36,0,0
0,35,36,35,35,35,35,35,35,35,35,35,0
0,48,36,0,0,0,0,0,0,0,36,0,0
0,0,0,0,0,0,0,0,0,0,0,0,0
:endlayer
layer: 14
0,0,0,0,0,0,0,0,0,0,0,0,0
0,52,46,0,0,0,0,0,0,0,48,49,0
0,52,37,37,37,37,2,37,37,37,37,49,0
0,52,0,0,0,0,0,0,0,0,0,49,0
0,52,0,0,0,0,0,0,0,0,0,49,0
0,52,0,0,0,0,0,0,0,0,0,49,0
0,52,0,0,0,0,2,0,0,0,0,49,0
0,52,0,0,0,0,50,0,0,0,0,49,0
0,52,0,0,0,0,51,0,0,0,0,49,0
0,52,0,0,0,0,2,0,0,0,0,49,0
0,52,0,0,0,0,0,0,0,0,0,49,0
0,52,0,0,0,0,0,0,0,0,0,49,0
0,52,0,0,0,0,0,0,0,0,0,49,0
0,52,37,37,37,37,2,37,37,37,37,49,0
0,0,46,0,0,0,0,0,0,0,0,0,0
0,0,0,0,0,0,0,0,0,0,0,0,0
:endlayer
layer: 15
0,0,0,0,0,0,0,0,0,0,0,0,0
0,0,52,46,0,0,0,0,0,48,49,0,0
0,0,52,37,30,37,2,37,30,37,49,0,0
0,0,52,0,0,0,0,0,0,0,49,0,0
0,0,52,0,0,0,0,0,0,0,49,0,0
0,0,52,0,0,0,0,0,0,0,49,0,0
0,0,52,0,0,0,2,0,0,0,49,0,0
0,0,52,0,0,0,0,0,0,0,49,0,0
0,0,52,0,0,0,0,0,0,0,49,0,0
0,0,52,0,0,0,2,0,0,0,49,0,0
0,0,52,0,0,0,0,0,0,0,49,0,0
0,0,52,0,0,0,0,0,0,0,49,0,0
0,0,52,0,0,0,0,0,0,0,49,0,0
0,0,52,37,30,37,2,37,30,37,49,0,0
0,0,0,0,0,0,0,0,0,0,0,0,0
0,0,0,0,0,0,0,0,0,0,0,0,0
:endlayer
layer: 16
0,0,0,0,0,0,0,0,0,0,0,0,0
0,0,0,52,46,0,0,0,48,49,0,0,0
0,0,0,52,37,37,2,37,37,49,0,0,0
0,0,0,52,0,0,0,0,0,49,0,0,0
0,0,0,52,0,0,0,0,0,49,0,0,0
0,0,0,52,0,0,0,0,0,49,0,0,0
0,0,0,52,0,0,2,0,0,49,0,0,0
0,0,0,52,0,0,0,0,0,49,0,0,0
0,0,0,52,0,0,0,0,0,49,0,0,0
0,0,0,52,0,0,2,0,0,49,0,0,0
0,0,0,52,0,0,0,0,0,49,0,0,0
0,0,0,52,0,0,0,0,0,49,0,0,0
0,0,0,52,0,0,0,0,0,49,0,0,0
0,0,0,52,37,37,2,37,37,49,0,0,0
0,0,0,0,0,0,0,0,0,0,0,0,0
0,0,0,0,0,0,0,0,0,0,0,0,0
:endlayer
layer: 17
0,0,0,0,0,0,0,0,0,0,0,0,0
0,0,0,0,52,46,7,48,49,0,0,0,0
0,0,0,0,52,37,2,37,49,0,0,0,0
0,0,0,0,52,0,0,0,49,0,0,0,0
0,0,0,0,52,0,0,0,49,0,0,0,0
0,0,0,0,52,0,0,0,49,0,0,0,0
0,0,0,0,52,0,2,0,49,0,0,0,0
0,0,0,0,52,0,0,0,49,0,0,0,0
0,0,0,0,52,0,0,0,49,0,0,0,0
0,0,0,0,52,0,2,0,49,0,0,0,0
0,0,0,0,52,0,0,0,49,0,0,0,0
0,0,0,0,52,0,0,0,49,0,0,0,0
0,0,0,0,52,0,0,0,49,0,0,0,0
0,0,0,0,52,37,2,37,49,0,0,0,0
0,0,0,0,0,0,0,0,0,0,0,0,0
0,0,0,0,0,0,0,0,0,0,0,0,0
:endlayer
layer: 18
0,0,0,0,0,0,0,0,0,0,0,0,0
0,0,0,0,0,52,36,49,0,0,0,0,0
0,0,0,0,0,52,36,49,0,0,0,0,0
0,0,0,0,0,52,36,49,0,0,0,0,0
0,0,0,0,0,52,36,49,0,0,0,0,0
0,0,0,0,0,52,36,49,0,0,0,0,0
0,0,0,0,0,52,36,49,0,0,0,0,0
0,0,0,0,0,52,36,49,0,0,0,0,0
0,0,0,0,0,52,36,49,0,0,0,0,0
0,0,0,0,0,52,36,49,0,0,0,0,0
0,0,0,0,0,52,36,49,0,0,0,0,0
0,0,0,0,0,52,36,49,0,0,0,0,0
0,0,0,0,0,52,36,49,0,0,0,0,0
0,0,0,0,0,52,36,49,0,0,0,0,0
0,0,0,0,0,0,36,0,0,0,0,0,0
0,0,0,0,0,0,0,0,0,0,0,0,0
:endlayer
layer: 19
0,0,0,0,0,0,7,0,0,0,0,0,0
0,0,0,0,0,0,8,0,0,0,0,0,0
0,0,0,0,0,0,53,0,0,0,0,0,0
0,0,0,0,0,0,53,0,0,0,0,0,0
0,0,0,0,0,0,53,0,0,0,0,0,0
0,0,0,0,0,0,53,0,0,0,0,0,0
0,0,0,0,0,0,53,0,0,0,0,0,0
0,0,0,0,0,0,53,0,0,0,0,0,0
0,0,0,0,0,0,53,0,0,0,0,0,0
0,0,0,0,0,0,53,0,0,0,0,0,0
0,0,0,0,0,0,53,0,0,0,0,0,0
0,0,0,0,0,0,53,0,0,0,0,0,0
0,0,0,0,0,0,53,0,0,0,0,0,0
0,0,0,0,0,0,53,0,0,0,0,0,0
0,0,0,0,0,0,54,0,0,0,0,0,0
0,0,0,0,0,0,0,0,0,0,0,0,0
:endlayer
layer: 20
0,0,0,0,0,0,0,0,0,0,0,0,0
0,0,0,0,0,0,0,0,0,0,0,0,0
0,0,0,0,0,0,0,0,0,0,0,0,0
0,0,0,0,0,0,0,0,0,0,0,0,0
0,0,0,0,0,0,0,0,0,0,0,0,0
0,0,0,0,0,0,0,0,0,0,0,0,0
0,0,0,0,0,0,0,0,0,0,0,0,0
0,0,0,0,0,0,0,0,0,0,0,0,0
0,0,0,0,0,0,0,0,0,0,0,0,0
0,0,0,0,0,0,0,0,0,0,0,0,0
0,0,0,0,0,0,0,0,0,0,0,0,0
0,0,0,0,0,0,0,0,0,0,0,0,0
0,0,0,0,0,0,0,0,0,0,0,0,0
0,0,0,0,0,0,0,0,0,0,0,0,0
0,0,0,0,0,0,0,0,0,0,0,0,0
0,0,0,0,0,0,0,0,0,0,0,0,0
:endlayer
layer: 21
0,0,0,0,0,0,0,0,0,0,0,0,0
0,0,0,0,0,0,0,0,0,0,0,0,0
0,0,0,0,0,0,0,0,0,0,0,0,0
0,0,0,0,0,0,0,0,0,0,0,0,0
0,0,0,0,0,0,0,0,0,0,0,0,0
0,0,0,0,0,0,0,0,0,0,0,0,0
0,0,0,0,0,0,0,0,0,0,0,0,0
0,0,0,0,0,0,0,0,0,0,0,0,0
0,0,0,0,0,0,0,0,0,0,0,0,0
0,0,0,0,0,0,0,0,0,0,0,0,0
0,0,0,0,0,0,0,0,0,0,0,0,0
0,0,0,0,0,0,0,0,0,0,0,0,0
0,0,0,0,0,0,0,0,0,0,0,0,0
0,0,0,0,0,0,0,0,0,0,0,0,0
0,0,0,0,0,0,0,0,0,0,0,0,0
0,0,0,0,0,0,0,0,0,0,0,0,0
:endlayer
layer: 22
0,0,0,0,0,0,0,0,0,0,0,0,0
0,0,0,0,0,0,0,0,0,0,0,0,0
0,0,0,0,0,0,0,0,0,0,0,0,0
0,0,0,0,0,0,0,0,0,0,0,0,0
0,0,0,0,0,0,0,0,0,0,0,0,0
0,0,0,0,0,0,0,0,0,0,0,0,0
0,0,0,0,0,0,0,0,0,0,0,0,0
0,0,0,0,0,0,0,0,0,0,0,0,0
0,0,0,0,0,0,0,0,0,0,0,0,0
0,0,0,0,0,0,0,0,0,0,0,0,0
0,0,0,0,0,0,0,0,0,0,0,0,0
0,0,0,0,0,0,0,0,0,0,0,0,0
0,0,0,0,0,0,0,0,0,0,0,0,0
0,0,0,0,0,0,0,0,0,0,0,0,0
0,0,0,0,0,0,0,0,0,0,0,0,0
0,0,0,0,0,0,0,0,0,0,0,0,0
:endlayer
layer: 23
0,0,0,0,0,0,0,0,0,0,0,0,0
0,0,0,0,0,0,0,0,0,0,0,0,0
0,0,0,0,0,0,0,0,0,0,0,0,0
0,0,0,0,0,0,0,0,0,0,0,0,0
0,0,0,0,0,0,0,0,0,0,0,0,0
0,0,0,0,0,0,0,0,0,0,0,0,0
0,0,0,0,0,0,0,0,0,0,0,0,0
0,0,0,0,0,0,0,0,0,0,0,0,0
0,0,0,0,0,0,0,0,0,0,0,0,0
0,0,0,0,0,0,0,0,0,0,0,0,0
0,0,0,0,0,0,0,0,0,0,0,0,0
0,0,0,0,0,0,0,0,0,0,0,0,0
0,0,0,0,0,0,0,0,0,0,0,0,0
0,0,0,0,0,0,0,0,0,0,0,0,0
0,0,0,0,0,0,0,0,0,0,0,0,0
0,0,0,0,0,0,0,0,0,0,0,0,0
:endlayer
layer: 24
0,0,0,0,0,0,0,0,0,0,0,0,0
0,0,0,0,0,0,0,0,0,0,0,0,0
0,0,0,0,0,0,0,0,0,0,0,0,0
0,0,0,0,0,0,0,0,0,0,0,0,0
0,0,0,0,0,0,0,0,0,0,0,0,0
0,0,0,0,0,0,0,0,0,0,0,0,0
0,0,0,0,0,0,0,0,0,0,0,0,0
0,0,0,0,0,0,0,0,0,0,0,0,0
0,0,0,0,0,0,0,0,0,0,0,0,0
0,0,0,0,0,0,0,0,0,0,0,0,0
0,0,0,0,0,0,0,0,0,0,0,0,0
0,0,0,0,0,0,0,0,0,0,0,0,0
0,0,0,0,0,0,0,0,0,0,0,0,0
0,0,0,0,0,0,0,0,0,0,0,0,0
0,0,0,0,0,0,0,0,0,0,0,0,0
0,0,0,0,0,0,0,0,0,0,0,0,0
:endlayer
layer: 25
0,0,0,0,0,0,0,0,0,0,0,0,0
0,0,0,0,0,0,0,0,0,0,0,0,0
0,0,0,0,0,0,0,0,0,0,0,0,0
0,0,0,0,0,0,0,0,0,0,0,0,0
0,0,0,0,0,0,0,0,0,0,0,0,0
0,0,0,0,0,0,0,0,0,0,0,0,0
0,0,0,0,0,0,0,0,0,0,0,0,0
0,0,0,0,0,0,0,0,0,0,0,0,0
0,0,0,0,0,0,0,0,0,0,0,0,0
0,0,0,0,0,0,0,0,0,0,0,0,0
0,0,0,0,0,0,0,0,0,0,0,0,0
0,0,0,0,0,0,0,0,0,0,0,0,0
0,0,0,0,0,0,0,0,0,0,0,0,0
0,0,0,0,0,0,0,0,0,0,0,0,0
0,0,0,0,0,0,0,0,0,0,0,0,0
0,0,0,0,0,0,0,0,0,0,0,0,0
:endlayer
layer: 26
0,0,0,0,0,0,0,0,0,0,0,0,0
0,0,0,0,0,0,0,0,0,0,0,0,0
0,0,0,0,0,0,0,0,0,0,0,0,0
0,0,0,0,0,0,0,0,0,0,0,0,0
0,0,0,0,0,0,0,0,0,0,0,0,0
0,0,0,0,0,0,0,0,0,0,0,0,0
0,0,0,0,0,0,0,0,0,0,0,0,0
0,0,0,0,0,0,0,0,0,0,0,0,0
0,0,0,0,0,0,0,0,0,0,0,0,0
0,0,0,0,0,0,0,0,0,0,0,0,0
0,0,0,0,0,0,0,0,0,0,0,0,0
0,0,0,0,0,0,0,0,0,0,0,0,0
0,0,0,0,0,0,0,0,0,0,0,0,0
0,0,0,0,0,0,0,0,0,0,0,0,0
0,0,0,0,0,0,0,0,0,0,0,0,0
0,0,0,0,0,0,0,0,0,0,0,0,0
:endlayer
layer: 27
0,0,0,0,0,0,0,0,0,0,0,0,0
0,0,0,0,0,0,0,0,0,0,0,0,0
0,0,0,0,0,0,0,0,0,0,0,0,0
0,0,0,0,0,0,0,0,0,0,0,0,0
0,0,0,0,0,0,0,0,0,0,0,0,0
0,0,0,0,0,0,0,0,0,0,0,0,0
0,0,0,0,0,0,0,0,0,0,0,0,0
0,0,0,0,0,0,0,0,0,0,0,0,0
0,0,0,0,0,0,0,0,0,0,0,0,0
0,0,0,0,0,0,0,0,0,0,0,0,0
0,0,0,0,0,0,0,0,0,0,0,0,0
0,0,0,0,0,0,0,0,0,0,0,0,0
0,0,0,0,0,0,0,0,0,0,0,0,0
0,0,0,0,0,0,0,0,0,0,0,0,0
0,0,0,0,0,0,0,0,0,0,0,0,0
0,0,0,0,0,0,0,0,0,0,0,0,0
:endlayer
layer: 28
0,0,0,0,0,0,0,0,0,0,0,0,0
0,0,0,0,0,0,0,0,0,0,0,0,0
0,0,0,0,0,0,0,0,0,0,0,0,0
0,0,0,0,0,0,0,0,0,0,0,0,0
0,0,0,0,0,0,0,0,0,0,0,0,0
0,0,0,0,0,0,0,0,0,0,0,0,0
0,0,0,0,0,0,0,0,0,0,0,0,0
0,0,0,0,0,0,0,0,0,0,0,0,0
0,0,0,0,0,0,0,0,0,0,0,0,0
0,0,0,0,0,0,0,0,0,0,0,0,0
0,0,0,0,0,0,0,0,0,0,0,0,0
0,0,0,0,0,0,0,0,0,0,0,0,0
0,0,0,0,0,0,0,0,0,0,0,0,0
0,0,0,0,0,0,0,0,0,0,0,0,0
0,0,0,0,0,0,0,0,0,0,0,0,0
0,0,0,0,0,0,0,0,0,0,0,0,0
:endlayer
layer: 29
0,0,0,0,0,0,0,0,0,0,0,0,0
0,0,0,0,0,0,0,0,0,0,0,0,0
0,0,0,0,0,0,0,0,0,0,0,0,0
0,0,0,0,0,0,0,0,0,0,0,0,0
0,0,0,0,0,0,0,0,0,0,0,0,0
0,0,0,0,0,0,0,0,0,0,0,0,0
0,0,0,0,0,0,0,0,0,0,0,0,0
0,0,0,0,0,0,0,0,0,0,0,0,0
0,0,0,0,0,0,0,0,0,0,0,0,0
0,0,0,0,0,0,0,0,0,0,0,0,0
0,0,0,0,0,0,0,0,0,0,0,0,0
0,0,0,0,0,0,0,0,0,0,0,0,0
0,0,0,0,0,0,0,0,0,0,0,0,0
0,0,0,0,0,0,0,0,0,0,0,0,0
0,0,0,0,0,0,0,0,0,0,0,0,0
0,0,0,0,0,0,0,0,0,0,0,0,0
:endlayer
layer: 30
0,0,0,0,0,0,0,0,0,0,0,0,0
0,0,0,0,0,0,0,0,0,0,0,0,0
0,0,0,0,0,0,0,0,0,0,0,0,0
0,0,0,0,0,0,0,0,0,0,0,0,0
0,0,0,0,0,0,0,0,0,0,0,0,0
0,0,0,0,0,0,0,0,0,0,0,0,0
0,0,0,0,0,0,0,0,0,0,0,0,0
0,0,0,0,0,0,0,0,0,0,0,0,0
0,0,0,0,0,0,0,0,0,0,0,0,0
0,0,0,0,0,0,0,0,0,0,0,0,0
0,0,0,0,0,0,0,0,0,0,0,0,0
0,0,0,0,0,0,0,0,0,0,0,0,0
0,0,0,0,0,0,0,0,0,0,0,0,0
0,0,0,0,0,0,0,0,0,0,0,0,0
0,0,0,0,0,0,0,0,0,0,0,0,0
0,0,0,0,0,0,0,0,0,0,0,0,0
:endlayer

#### RULES ####
rule:
plugin=vanillaBlocks
number=1
data:
JSON:{{"val":{"buildPass":{"val":"0","id":"pi"},"blockName":{"val":"minecraft:dirt","id":"ss"},"meta":{"val":"0","id":"pi"}},"id":"ct"}}
:enddata
:endrule

rule:
plugin=vanillaBlocks
number=2
data:
JSON:{{"val":{"buildPass":{"val":"0","id":"pi"},"blockName":{"val":"minecraft:log","id":"ss"},"meta":{"val":"0","id":"pi"}},"id":"ct"}}
:enddata
:endrule

rule:
plugin=vanillaBlocks
number=3
data:
JSON:{{"val":{"buildPass":{"val":"0","id":"pi"},"blockName":{"val":"minecraft:cobblestone","id":"ss"},"meta":{"val":"0","id":"pi"}},"id":"ct"}}
:enddata
:endrule

rule:
plugin=modBlockDefault
number=4
data:
JSON:{{"val":{"blockName":{"val":"UndergroundBiomes:metamorphicStone","id":"ss"},"meta":{"val":"0","id":"pi"}},"id":"ct"}}
:enddata
:endrule

rule:
plugin=modBlockDefault
number=5
data:
JSON:{{"val":{"blockName":{"val":"ganyssurface:inverted_redstone_lamp_on","id":"ss"},"meta":{"val":"0","id":"pi"}},"id":"ct"}}
:enddata
:endrule

rule:
plugin=vanillaInventory
number=6
data:
JSON:{{"val":{"buildPass":{"val":"0","id":"pi"},"blockName":{"val":"minecraft:chest","id":"ss"},"meta":{"val":"2","id":"pi"},"lootLevel":{"val":"0","id":"pi"},"teData":{"val":{"x":{"val":"-588","id":"pi"},"y":{"val":"61","id":"pi"},"z":{"val":"-2735","id":"pi"},"id":{"val":"Chest","id":"ss"}},"id":"ct"},"inventoryData":{"val":{"length":{"val":"27","id":"pi"},"inventoryContents":{"val":[],"id":"ls"}},"id":"ct"}},"id":"ct"}}
:enddata
:endrule

rule:
plugin=vanillaBlocks
number=7
data:
JSON:{{"val":{"buildPass":{"val":"0","id":"pi"},"blockName":{"val":"minecraft:oak_stairs","id":"ss"},"meta":{"val":"6","id":"pi"}},"id":"ct"}}
:enddata
:endrule

rule:
plugin=vanillaBlocks
number=8
data:
JSON:{{"val":{"buildPass":{"val":"0","id":"pi"},"blockName":{"val":"minecraft:oak_stairs","id":"ss"},"meta":{"val":"3","id":"pi"}},"id":"ct"}}
:enddata
:endrule

rule:
plugin=vanillaInventory
number=9
data:
JSON:{{"val":{"buildPass":{"val":"0","id":"pi"},"blockName":{"val":"minecraft:chest","id":"ss"},"meta":{"val":"2","id":"pi"},"lootLevel":{"val":"2","id":"pi"},"teData":{"val":{"x":{"val":"-588","id":"pi"},"y":{"val":"61","id":"pi"},"z":{"val":"-2734","id":"pi"},"id":{"val":"Chest","id":"ss"}},"id":"ct"},"inventoryData":{"val":{"length":{"val":"27","id":"pi"},"inventoryContents":{"val":[],"id":"ls"}},"id":"ct"}},"id":"ct"}}
:enddata
:endrule

rule:
plugin=vanillaBlocks
number=10
data:
JSON:{{"val":{"buildPass":{"val":"0","id":"pi"},"blockName":{"val":"minecraft:crafting_table","id":"ss"},"meta":{"val":"0","id":"pi"}},"id":"ct"}}
:enddata
:endrule

rule:
plugin=vanillaBlocks
number=11
data:
JSON:{{"val":{"buildPass":{"val":"0","id":"pi"},"blockName":{"val":"minecraft:bookshelf","id":"ss"},"meta":{"val":"0","id":"pi"}},"id":"ct"}}
:enddata
:endrule

rule:
plugin=vanillaBlocks
number=12
data:
JSON:{{"val":{"buildPass":{"val":"0","id":"pi"},"blockName":{"val":"minecraft:grass","id":"ss"},"meta":{"val":"0","id":"pi"}},"id":"ct"}}
:enddata
:endrule

rule:
plugin=modBlockDefault
number=13
data:
JSON:{{"val":{"blockName":{"val":"BiomesOPlenty:foliage","id":"ss"},"meta":{"val":"11","id":"pi"}},"id":"ct"}}
:enddata
:endrule

rule:
plugin=vanillaBlocks
number=14
data:
JSON:{{"val":{"buildPass":{"val":"0","id":"pi"},"blockName":{"val":"minecraft:fence","id":"ss"},"meta":{"val":"0","id":"pi"}},"id":"ct"}}
:enddata
:endrule

rule:
plugin=vanillaBlocks
number=15
data:
JSON:{{"val":{"buildPass":{"val":"2","id":"pi"},"blockName":{"val":"minecraft:tallgrass","id":"ss"},"meta":{"val":"1","id":"pi"}},"id":"ct"}}
:enddata
:endrule

rule:
plugin=vanillaBlocks
number=16
data:
JSON:{{"val":{"buildPass":{"val":"0","id":"pi"},"blockName":{"val":"minecraft:double_wooden_slab","id":"ss"},"meta":{"val":"2","id":"pi"}},"id":"ct"}}
:enddata
:endrule

rule:
plugin=vanillaBlocks
number=17
data:
JSON:{{"val":{"buildPass":{"val":"0","id":"pi"},"blockName":{"val":"minecraft:double_wooden_slab","id":"ss"},"meta":{"val":"0","id":"pi"}},"id":"ct"}}
:enddata
:endrule

rule:
plugin=vanillaBlocks
number=18
data:
JSON:{{"val":{"buildPass":{"val":"0","id":"pi"},"blockName":{"val":"minecraft:wooden_slab","id":"ss"},"meta":{"val":"10","id":"pi"}},"id":"ct"}}
:enddata
:endrule

rule:
plugin=vanillaBlocks
number=19
data:
JSON:{{"val":{"buildPass":{"val":"0","id":"pi"},"blockName":{"val":"minecraft:wooden_slab","id":"ss"},"meta":{"val":"8","id":"pi"}},"id":"ct"}}
:enddata
:endrule

rule:
plugin=modBlockDefault
number=20
data:
JSON:{{"val":{"blockName":{"val":"BiomesOPlenty:foliage","id":"ss"},"meta":{"val":"1","id":"pi"}},"id":"ct"}}
:enddata
:endrule

rule:
plugin=vanillaBlocks
number=21
data:
JSON:{{"val":{"buildPass":{"val":"0","id":"pi"},"blockName":{"val":"minecraft:stone_stairs","id":"ss"},"meta":{"val":"1","id":"pi"}},"id":"ct"}}
:enddata
:endrule

rule:
plugin=vanillaBlocks
number=22
data:
JSON:{{"val":{"buildPass":{"val":"0","id":"pi"},"blockName":{"val":"minecraft:stone_stairs","id":"ss"},"meta":{"val":"3","id":"pi"}},"id":"ct"}}
:enddata
:endrule

rule:
plugin=vanillaBlocks
number=23
data:
JSON:{{"val":{"buildPass":{"val":"0","id":"pi"},"blockName":{"val":"minecraft:stone_stairs","id":"ss"},"meta":{"val":"0","id":"pi"}},"id":"ct"}}
:enddata
:endrule

rule:
plugin=vanillaDoors
number=24
data:
JSON:{{"val":{"buildPass":{"val":"2","id":"pi"},"blockName":{"val":"minecraft:wooden_door","id":"ss"},"meta":{"val":"3","id":"pi"},"sideFlag":{"val":"8","id":"pb"}},"id":"ct"}}
:enddata
:endrule

rule:
plugin=vanillaBlocks
number=25
data:
JSON:{{"val":{"buildPass":{"val":"2","id":"pi"},"blockName":{"val":"minecraft:trapdoor","id":"ss"},"meta":{"val":"9","id":"pi"}},"id":"ct"}}
:enddata
:endrule

rule:
plugin=modBlockDefault
number=26
data:
JSON:{{"val":{"blockName":{"val":"cfm:coffetablestone","id":"ss"},"meta":{"val":"2","id":"pi"}},"id":"ct"}}
:enddata
:endrule

rule:
plugin=vanillaLogic
number=27
data:
JSON:{{"val":{"buildPass":{"val":"0","id":"pi"},"blockName":{"val":"customnpcs:npcCouchWool","id":"ss"},"meta":{"val":"1","id":"pi"},"teData":{"val":{"BannerColor":{"val":"14","id":"pi"},"CouchLeft":{"val":"0","id":"pb"},"BannerRotation":{"val":"0","id":"pi"},"CouchCornerLeft":{"val":"0","id":"pb"},"id":{"val":"TileNPCCouchWool","id":"ss"},"CouchRight":{"val":"1","id":"pb"},"CouchCornerRight":{"val":"0","id":"pb"}},"id":"ct"}},"id":"ct"}}
:enddata
:endrule

rule:
plugin=vanillaLogic
number=28
data:
JSON:{{"val":{"buildPass":{"val":"0","id":"pi"},"blockName":{"val":"customnpcs:npcCouchWool","id":"ss"},"meta":{"val":"1","id":"pi"},"teData":{"val":{"BannerColor":{"val":"14","id":"pi"},"CouchLeft":{"val":"1","id":"pb"},"BannerRotation":{"val":"0","id":"pi"},"CouchCornerLeft":{"val":"0","id":"pb"},"id":{"val":"TileNPCCouchWool","id":"ss"},"CouchRight":{"val":"1","id":"pb"},"CouchCornerRight":{"val":"0","id":"pb"}},"id":"ct"}},"id":"ct"}}
:enddata
:endrule

rule:
plugin=vanillaLogic
number=29
data:
JSON:{{"val":{"buildPass":{"val":"0","id":"pi"},"blockName":{"val":"customnpcs:npcCouchWool","id":"ss"},"meta":{"val":"1","id":"pi"},"teData":{"val":{"BannerColor":{"val":"14","id":"pi"},"CouchLeft":{"val":"1","id":"pb"},"BannerRotation":{"val":"0","id":"pi"},"CouchCornerLeft":{"val":"0","id":"pb"},"id":{"val":"TileNPCCouchWool","id":"ss"},"CouchRight":{"val":"0","id":"pb"},"CouchCornerRight":{"val":"0","id":"pb"}},"id":"ct"}},"id":"ct"}}
:enddata
:endrule

rule:
plugin=vanillaBlocks
number=30
data:
JSON:{{"val":{"buildPass":{"val":"0","id":"pi"},"blockName":{"val":"minecraft:glass","id":"ss"},"meta":{"val":"0","id":"pi"}},"id":"ct"}}
:enddata
:endrule

rule:
plugin=vanillaDoors
number=31
data:
JSON:{{"val":{"buildPass":{"val":"2","id":"pi"},"blockName":{"val":"minecraft:wooden_door","id":"ss"},"meta":{"val":"8","id":"pi"},"sideFlag":{"val":"0","id":"pb"}},"id":"ct"}}
:enddata
:endrule

rule:
plugin=vanillaBlocks
number=32
data:
JSON:{{"val":{"buildPass":{"val":"2","id":"pi"},"blockName":{"val":"minecraft:torch","id":"ss"},"meta":{"val":"2","id":"pi"}},"id":"ct"}}
:enddata
:endrule

rule:
plugin=vanillaBlocks
number=33
data:
JSON:{{"val":{"buildPass":{"val":"2","id":"pi"},"blockName":{"val":"minecraft:torch","id":"ss"},"meta":{"val":"4","id":"pi"}},"id":"ct"}}
:enddata
:endrule

rule:
plugin=vanillaBlocks
number=34
data:
JSON:{{"val":{"buildPass":{"val":"2","id":"pi"},"blockName":{"val":"minecraft:torch","id":"ss"},"meta":{"val":"3","id":"pi"}},"id":"ct"}}
:enddata
:endrule

rule:
plugin=vanillaBlocks
number=35
data:
JSON:{{"val":{"buildPass":{"val":"0","id":"pi"},"blockName":{"val":"minecraft:log","id":"ss"},"meta":{"val":"4","id":"pi"}},"id":"ct"}}
:enddata
:endrule

rule:
plugin=vanillaBlocks
number=36
data:
JSON:{{"val":{"buildPass":{"val":"0","id":"pi"},"blockName":{"val":"minecraft:log","id":"ss"},"meta":{"val":"8","id":"pi"}},"id":"ct"}}
:enddata
:endrule

rule:
plugin=vanillaBlocks
number=37
data:
JSON:{{"val":{"buildPass":{"val":"0","id":"pi"},"blockName":{"val":"minecraft:stained_hardened_clay","id":"ss"},"meta":{"val":"0","id":"pi"}},"id":"ct"}}
:enddata
:endrule

rule:
plugin=vanillaBlocks
number=38
data:
JSON:{{"val":{"buildPass":{"val":"2","id":"pi"},"blockName":{"val":"minecraft:ladder","id":"ss"},"meta":{"val":"3","id":"pi"}},"id":"ct"}}
:enddata
:endrule

rule:
plugin=vanillaLogic
number=39
data:
JSON:{{"val":{"buildPass":{"val":"0","id":"pi"},"blockName":{"val":"customnpcs:npcCouchWool","id":"ss"},"meta":{"val":"1","id":"pi"},"teData":{"val":{"BannerColor":{"val":"14","id":"pi"},"CouchLeft":{"val":"0","id":"pb"},"BannerRotation":{"val":"3","id":"pi"},"CouchCornerLeft":{"val":"0","id":"pb"},"id":{"val":"TileNPCCouchWool","id":"ss"},"CouchRight":{"val":"0","id":"pb"},"CouchCornerRight":{"val":"0","id":"pb"}},"id":"ct"}},"id":"ct"}}
:enddata
:endrule

rule:
plugin=vanillaLogic
number=40
data:
JSON:{{"val":{"buildPass":{"val":"0","id":"pi"},"blockName":{"val":"customnpcs:npcCouchWool","id":"ss"},"meta":{"val":"1","id":"pi"},"teData":{"val":{"BannerColor":{"val":"14","id":"pi"},"CouchLeft":{"val":"0","id":"pb"},"BannerRotation":{"val":"1","id":"pi"},"CouchCornerLeft":{"val":"0","id":"pb"},"id":{"val":"TileNPCCouchWool","id":"ss"},"CouchRight":{"val":"0","id":"pb"},"CouchCornerRight":{"val":"0","id":"pb"}},"id":"ct"}},"id":"ct"}}
:enddata
:endrule

rule:
plugin=vanillaLogic
number=41
data:
JSON:{{"val":{"buildPass":{"val":"0","id":"pi"},"blockName":{"val":"props:blockProps","id":"ss"},"meta":{"val":"0","id":"pi"},"teData":{"val":{"slaves":{"val":[{"val":["-808","14","1353"],"id":"ai"}],"id":"ls"},"BlockType":{"val":"232","id":"pi"},"isRunning":{"val":"0","id":"pb"},"id":{"val":"com.mia.props.common.entities.TileChair","id":"ss"},"BlockRotation":{"val":"8","id":"pi"}},"id":"ct"}},"id":"ct"}}
:enddata
:endrule

rule:
plugin=vanillaLogic
number=42
data:
JSON:{{"val":{"buildPass":{"val":"0","id":"pi"},"blockName":{"val":"customnpcs:npcCouchWool","id":"ss"},"meta":{"val":"1","id":"pi"},"teData":{"val":{"BannerColor":{"val":"14","id":"pi"},"CouchLeft":{"val":"0","id":"pb"},"BannerRotation":{"val":"3","id":"pi"},"CouchCornerLeft":{"val":"0","id":"pb"},"id":{"val":"TileNPCCouchWool","id":"ss"},"CouchRight":{"val":"0","id":"pb"},"CouchCornerRight":{"val":"0","id":"pb"}},"id":"ct"}},"id":"ct"}}
:enddata
:endrule

rule:
plugin=vanillaLogic
number=43
data:
JSON:{{"val":{"buildPass":{"val":"0","id":"pi"},"blockName":{"val":"customnpcs:npcCouchWool","id":"ss"},"meta":{"val":"1","id":"pi"},"teData":{"val":{"BannerColor":{"val":"14","id":"pi"},"CouchLeft":{"val":"0","id":"pb"},"BannerRotation":{"val":"0","id":"pi"},"CouchCornerLeft":{"val":"0","id":"pb"},"id":{"val":"TileNPCCouchWool","id":"ss"},"CouchRight":{"val":"0","id":"pb"},"CouchCornerRight":{"val":"0","id":"pb"}},"id":"ct"}},"id":"ct"}}
:enddata
:endrule

rule:
plugin=vanillaLogic
number=44
data:
JSON:{{"val":{"buildPass":{"val":"0","id":"pi"},"blockName":{"val":"BiblioCraft:BiblioDesk","id":"ss"},"meta":{"val":"0","id":"pi"},"teData":{"val":{"rightBookStack":{"val":"0","id":"pi"},"leftBookStack":{"val":"0","id":"pi"},"deskAngle":{"val":"1","id":"pi"},"hasMap":{"val":"0","id":"pb"},"isVanilla":{"val":"1","id":"pb"},"customTexture":{"val":"none","id":"ss"},"hasCarpet":{"val":"0","id":"pb"},"hasWrittenBook":{"val":"0","id":"pb"},"CurrentPage":{"val":"0","id":"pi"},"carpetColor":{"val":"-1","id":"pi"},"singleLeftRightCenter":{"val":"0","id":"pi"},"id":{"val":"WritingDeskTile","id":"ss"},"locked":{"val":"0","id":"pb"},"lockee":{"val":"","id":"ss"},"Inventory":{"val":[],"id":"ls"}},"id":"ct"}},"id":"ct"}}
:enddata
:endrule

rule:
plugin=vanillaLogic
number=45
data:
JSON:{{"val":{"buildPass":{"val":"0","id":"pi"},"blockName":{"val":"customnpcs:npcCouchWool","id":"ss"},"meta":{"val":"1","id":"pi"},"teData":{"val":{"BannerColor":{"val":"14","id":"pi"},"CouchLeft":{"val":"0","id":"pb"},"BannerRotation":{"val":"0","id":"pi"},"CouchCornerLeft":{"val":"0","id":"pb"},"id":{"val":"TileNPCCouchWool","id":"ss"},"CouchRight":{"val":"0","id":"pb"},"CouchCornerRight":{"val":"0","id":"pb"}},"id":"ct"}},"id":"ct"}}
:enddata
:endrule

rule:
plugin=vanillaBlocks
number=46
data:
JSON:{{"val":{"buildPass":{"val":"0","id":"pi"},"blockName":{"val":"minecraft:dark_oak_stairs","id":"ss"},"meta":{"val":"5","id":"pi"}},"id":"ct"}}
:enddata
:endrule

rule:
plugin=vanillaBlocks
number=47
data:
JSON:{{"val":{"buildPass":{"val":"0","id":"pi"},"blockName":{"val":"minecraft:planks","id":"ss"},"meta":{"val":"0","id":"pi"}},"id":"ct"}}
:enddata
:endrule

rule:
plugin=vanillaBlocks
number=48
data:
JSON:{{"val":{"buildPass":{"val":"0","id":"pi"},"blockName":{"val":"minecraft:dark_oak_stairs","id":"ss"},"meta":{"val":"4","id":"pi"}},"id":"ct"}}
:enddata
:endrule

rule:
plugin=vanillaBlocks
number=49
data:
JSON:{{"val":{"buildPass":{"val":"0","id":"pi"},"blockName":{"val":"minecraft:oak_stairs","id":"ss"},"meta":{"val":"1","id":"pi"}},"id":"ct"}}
:enddata
:endrule

rule:
plugin=vanillaBlocks
number=50
data:
JSON:{{"val":{"buildPass":{"val":"2","id":"pi"},"blockName":{"val":"minecraft:bed","id":"ss"},"meta":{"val":"0","id":"pi"}},"id":"ct"}}
:enddata
:endrule

rule:
plugin=vanillaBlocks
number=51
data:
JSON:{{"val":{"buildPass":{"val":"2","id":"pi"},"blockName":{"val":"minecraft:bed","id":"ss"},"meta":{"val":"8","id":"pi"}},"id":"ct"}}
:enddata
:endrule

rule:
plugin=vanillaBlocks
number=52
data:
JSON:{{"val":{"buildPass":{"val":"0","id":"pi"},"blockName":{"val":"minecraft:oak_stairs","id":"ss"},"meta":{"val":"0","id":"pi"}},"id":"ct"}}
:enddata
:endrule

rule:
plugin=vanillaBlocks
number=53
data:
JSON:{{"val":{"buildPass":{"val":"0","id":"pi"},"blockName":{"val":"minecraft:wooden_slab","id":"ss"},"meta":{"val":"0","id":"pi"}},"id":"ct"}}
:enddata
:endrule

rule:
plugin=vanillaBlocks
number=54
data:
JSON:{{"val":{"buildPass":{"val":"0","id":"pi"},"blockName":{"val":"minecraft:oak_stairs","id":"ss"},"meta":{"val":"2","id":"pi"}},"id":"ct"}}
:enddata
:endrule

#### ENTITIES ####
entity:
plugin=vanillaLogicEntity
number=0
data:
position=4,5,4
JSON:{{"val":{"xOffset":{"val":"0.7","id":"pf"},"equipmentData":{"val":{"length":{"val":"5","id":"pi"},"equipmentContents":{"val":[],"id":"ls"}},"id":"ct"},"rotation":{"val":"-90.00055","id":"pf"},"mobID":{"val":"Villager","id":"ss"},"zOffset":{"val":"0.5000077","id":"pf"},"entityData":{"val":{"ForgeData":{"val":{"MP|Init":{"val":"1","id":"pb"},"ESM_MODIFIED":{"val":"1","id":"pb"},"Apocalypse|Init":{"val":"1","id":"pb"},"sAI":{"val":{"Fiddling":{"val":"0","id":"pb"},"AvoidExplosions":{"val":"1","id":"pb"},"DefendVillage":{"val":"1","id":"pb"},"Griefing":{"val":"0","id":"pb"},"uAI":{"val":{},"id":"ct"},"Rider":{"val":"0","id":"pb"}},"id":"ct"},"ORIGINAL_SPAWN_POS":{"val":["-589","65","-2729"],"id":"ai"},"HungerOverhaulCheck":{"val":"3","id":"pi"}},"id":"ct"},"Attributes":{"val":[{"val":{"Base":{"val":"20.0","id":"pd"},"Modifiers":{"val":[{"val":{"UUIDMost":{"val":"21883516770130","id":"pl"},"UUIDLeast":{"val":"8950412973843917987","id":"pl"},"Amount":{"val":"0.0","id":"pd"},"Operation":{"val":"1","id":"pi"},"Name":{"val":"ESM_TWEAK_1","id":"ss"}},"id":"ct"}],"id":"ls"},"Name":{"val":"generic.maxHealth","id":"ss"}},"id":"ct"},{"val":{"Base":{"val":"0.0","id":"pd"},"Modifiers":{"val":[{"val":{"UUIDMost":{"val":"21883516773143","id":"pl"},"UUIDLeast":{"val":"-4860956302364606656","id":"pl"},"Amount":{"val":"0.0","id":"pd"},"Operation":{"val":"1","id":"pi"},"Name":{"val":"ESM_TWEAK_4","id":"ss"}},"id":"ct"}],"id":"ls"},"Name":{"val":"generic.knockbackResistance","id":"ss"}},"id":"ct"},{"val":{"Base":{"val":"0.5","id":"pd"},"Modifiers":{"val":[{"val":{"UUIDMost":{"val":"21883516772239","id":"pl"},"UUIDLeast":{"val":"7572583026771718158","id":"pl"},"Amount":{"val":"0.0","id":"pd"},"Operation":{"val":"1","id":"pi"},"Name":{"val":"ESM_TWEAK_2","id":"ss"}},"id":"ct"}],"id":"ls"},"Name":{"val":"generic.movementSpeed","id":"ss"}},"id":"ct"},{"val":{"Base":{"val":"32.0","id":"pd"},"Name":{"val":"generic.followRange","id":"ss"}},"id":"ct"}],"id":"ls"},"Riches":{"val":"0","id":"pi"},"Invulnerable":{"val":"0","id":"pb"},"PortalCooldown":{"val":"0","id":"pi"},"AbsorptionAmount":{"val":"0.0","id":"pf"},"FallDistance":{"val":"0.0","id":"pf"},"DeathTime":{"val":"0","id":"ps"},"DropChances":{"val":[{"val":"0.085","id":"pf"},{"val":"0.085","id":"pf"},{"val":"0.085","id":"pf"},{"val":"0.085","id":"pf"},{"val":"0.085","id":"pf"}],"id":"ls"},"PersistenceRequired":{"val":"0","id":"pb"},"HealF":{"val":"20.0","id":"pf"},"Age":{"val":"0","id":"pi"},"Motion":{"val":[{"val":"0.0","id":"pd"},{"val":"-0.0784000015258789","id":"pd"},{"val":"0.0","id":"pd"}],"id":"ls"},"Leashed":{"val":"0","id":"pb"},"Health":{"val":"20","id":"ps"},"Air":{"val":"300","id":"ps"},"OnGround":{"val":"1","id":"pb"},"Dimension":{"val":"0","id":"pi"},"Rotation":{"val":[{"val":"-180.00055","id":"pf"},{"val":"0.0","id":"pf"}],"id":"ls"},"Profession":{"val":"1","id":"pi"},"CustomName":{"val":"","id":"ss"},"Pos":{"val":[{"val":"-589.4999923237472","id":"pd"},{"val":"65.0","id":"pd"},{"val":"-2729.699999988079","id":"pd"}],"id":"ls"},"Fire":{"val":"-1","id":"ps"},"CanPickUpLoot":{"val":"0","id":"pb"},"HurtTime":{"val":"0","id":"ps"},"AttackTime":{"val":"0","id":"ps"},"CustomNameVisible":{"val":"0","id":"pb"}},"id":"ct"}},"id":"ct"}}
:enddata
:endentity

