# Ancient Warfare Structure Template File
# Auto-generated structure template file. created on: 3/9/2017 at: 21:58:36
# Lines beginning with # denote comments

header:
version=2.1
name=ReignThaumCouncil
size=41,51,49
offset=18,3,48
:endheader

#### VALIDATION ####
validation:
type=ground
survival=false
worldGenEnabled=false
unique=false
preserveBlocks=false
selectionWeight=0
clusterValue=0
minDuplicateDistance=0
dimensionWhiteList=false
dimensionList=
biomeWhiteList=false
biomeList=
leveling=0
fill=0
border=0
validTargetBlocks=
blockSwap=false
data:
:enddata
:endvalidation

#### LAYERS ####
layer: 0
1,1,1,1,1,1,1,1,1,1,1,1,1,1,1,1,1,1,1,1,1,1,1,1,1,1,1,1,1,1,1,1,1,1,1,1,1,1,1,1,1
1,1,1,1,1,1,1,1,1,1,1,1,1,1,1,1,1,1,1,1,1,1,1,1,1,1,1,1,1,1,1,1,1,1,1,1,1,1,1,1,1
1,1,1,1,1,1,1,1,1,1,1,1,1,1,1,1,1,1,1,1,1,1,1,1,1,1,1,1,1,1,1,1,1,1,1,1,1,1,1,1,1
1,1,1,1,1,1,1,1,1,1,1,1,1,1,1,1,1,1,1,1,1,1,1,1,1,1,1,1,1,1,1,1,1,1,1,1,1,1,1,1,1
1,1,1,1,1,1,1,1,1,1,1,1,1,1,1,1,1,1,1,1,1,1,1,1,1,1,1,1,1,1,1,1,1,1,1,1,1,1,1,1,1
1,1,1,1,1,1,1,1,1,1,1,1,1,1,1,1,1,1,1,1,1,1,1,1,1,1,1,1,1,1,1,1,1,1,1,1,1,1,1,1,1
1,1,1,1,1,1,1,1,1,1,1,1,1,1,1,1,1,1,1,1,1,1,1,1,1,1,1,1,1,1,1,1,1,1,1,1,1,1,1,1,1
1,1,1,1,1,1,1,1,1,1,1,1,1,1,1,1,1,1,1,1,1,1,1,1,1,1,1,1,1,1,1,1,1,1,1,1,1,1,1,1,1
1,1,1,1,1,1,1,1,1,1,1,1,1,1,1,1,1,1,1,1,1,1,1,1,1,1,1,1,1,1,1,1,1,1,1,1,1,1,1,1,1
1,1,1,1,1,1,1,1,1,1,1,1,1,1,1,1,1,1,1,1,1,1,1,1,1,1,1,1,1,1,1,1,1,1,1,1,1,1,1,1,1
1,1,1,1,1,1,1,1,1,1,1,1,1,1,1,1,1,1,1,1,1,1,1,1,1,1,1,1,1,1,1,1,1,1,1,1,1,1,1,1,1
1,1,1,1,1,1,1,1,1,1,1,1,1,1,1,1,1,1,1,1,1,1,1,1,1,1,1,1,1,1,1,1,1,1,1,1,1,1,1,1,1
1,1,1,1,1,1,1,1,1,1,1,1,1,1,1,1,1,1,1,1,1,1,1,1,1,1,1,1,1,1,1,1,1,1,1,1,1,1,1,1,1
1,1,1,1,1,1,1,1,1,1,1,1,1,1,1,1,1,1,1,1,1,1,1,1,1,1,1,1,1,1,1,1,1,1,1,1,1,1,1,1,1
1,1,1,1,1,1,1,1,1,1,1,1,1,1,1,1,1,1,1,1,1,1,1,1,1,1,1,1,1,1,1,1,1,1,1,1,1,1,1,1,1
1,1,1,1,1,1,1,1,1,1,1,1,1,1,1,1,1,1,1,1,1,1,1,1,1,1,1,1,1,1,1,1,1,1,1,1,1,1,1,1,1
1,1,1,1,1,1,1,1,1,1,1,1,1,1,1,1,1,1,1,1,1,1,1,1,1,1,1,1,1,1,1,1,1,1,1,1,1,1,1,1,1
1,1,1,1,1,1,1,1,1,1,1,1,1,1,1,1,1,1,1,1,1,1,1,1,1,1,1,1,1,1,1,1,1,1,1,1,1,1,1,1,1
1,1,1,1,1,1,1,1,1,1,1,1,1,1,1,1,1,1,1,1,1,1,1,1,1,1,1,1,1,1,1,1,1,1,1,1,1,1,1,1,1
1,1,1,1,1,1,1,1,1,1,1,1,1,1,1,1,1,1,1,1,1,1,1,1,1,1,1,1,1,1,1,1,1,1,1,1,1,1,1,1,1
1,1,1,1,1,1,1,1,1,1,1,1,1,1,1,1,1,1,1,1,1,1,1,1,1,1,1,1,1,1,1,1,1,1,1,1,1,1,1,1,1
1,1,1,1,1,1,1,1,1,1,1,1,1,1,1,1,1,1,1,1,1,1,1,1,1,1,1,1,1,1,1,1,1,1,1,1,1,1,1,1,1
1,1,1,1,1,1,1,1,1,1,1,1,1,1,1,1,1,1,1,1,1,1,1,1,1,1,1,1,1,1,1,1,1,1,1,1,1,1,1,1,1
1,1,1,1,1,1,1,1,1,1,1,1,1,1,1,1,1,1,1,1,1,1,1,1,1,1,1,1,1,1,1,1,1,1,1,1,1,1,1,1,1
1,1,1,1,1,1,1,1,1,1,1,1,1,1,1,1,1,1,1,1,1,1,1,1,1,1,1,1,1,1,1,1,1,1,1,1,1,1,1,1,1
1,1,1,1,1,1,1,1,1,1,1,1,1,1,1,1,1,1,1,1,1,1,1,1,1,1,1,1,1,1,1,1,1,1,1,1,1,1,1,1,1
1,1,1,1,1,1,1,1,1,1,1,1,1,1,1,1,1,1,1,1,1,1,1,1,1,1,1,1,1,1,1,1,1,1,1,1,1,1,1,1,1
1,1,1,1,1,1,1,1,1,1,1,1,1,1,1,1,1,1,1,1,1,1,1,1,1,1,1,1,1,1,1,1,1,1,1,1,1,1,1,1,1
1,1,1,1,1,1,1,1,1,1,1,1,1,1,1,1,1,1,1,1,1,1,1,1,1,1,1,1,1,1,1,1,1,1,1,1,1,1,1,1,1
1,1,1,1,1,1,1,1,1,1,1,1,1,1,1,1,1,1,1,1,1,1,1,1,1,1,1,1,1,1,1,1,1,1,1,1,1,1,1,1,1
1,1,1,1,1,1,1,1,1,1,1,1,1,1,1,1,1,1,1,1,1,1,1,1,1,1,1,1,1,1,1,1,1,1,1,1,1,1,1,1,1
1,1,1,1,1,1,1,1,1,1,1,1,1,1,1,1,1,1,1,1,1,1,1,1,1,1,1,1,1,1,1,1,1,1,1,1,1,1,1,1,1
1,1,1,1,1,1,1,1,1,1,1,1,1,1,1,1,1,1,1,1,1,1,1,1,1,1,1,1,1,1,1,1,1,1,1,1,1,1,1,1,1
1,1,1,1,1,1,1,1,1,1,1,1,1,1,1,1,1,1,1,1,1,1,1,1,1,1,1,1,1,1,1,1,1,1,1,1,1,1,1,1,1
1,1,1,2,1,1,1,1,1,1,1,1,1,1,1,1,1,1,1,1,1,1,1,1,1,1,1,1,1,1,1,1,1,1,1,1,1,1,1,1,1
1,1,1,1,2,1,1,1,1,1,1,1,1,1,1,1,1,1,1,1,1,1,1,1,1,1,1,1,1,1,1,1,1,1,1,1,1,1,1,1,1
1,1,1,1,1,1,1,1,1,1,1,1,1,1,1,1,1,1,1,1,1,1,1,1,1,1,1,1,1,1,1,1,1,1,1,1,1,1,1,1,1
1,1,1,1,1,1,1,1,1,1,1,1,1,1,1,1,1,1,1,1,1,1,1,1,1,1,1,1,1,1,1,1,1,1,1,1,1,1,1,1,1
1,1,1,1,1,1,1,1,1,1,1,1,1,1,1,1,1,1,1,1,1,1,1,1,1,1,1,1,1,1,1,1,1,1,1,1,1,1,1,1,1
1,1,1,1,1,1,1,1,1,1,1,1,1,1,1,1,1,1,1,1,1,1,1,1,1,1,1,1,1,1,1,1,1,1,1,1,1,1,1,1,1
1,1,1,1,1,1,1,1,1,1,1,1,1,1,1,1,1,1,1,1,1,1,1,1,1,1,1,1,1,1,1,1,1,1,1,1,1,1,1,1,1
1,1,1,1,1,1,1,1,1,1,1,1,1,1,1,1,1,1,1,1,1,1,1,1,1,1,1,1,1,1,1,1,1,1,1,1,1,1,1,1,1
1,1,1,1,1,1,1,1,1,1,1,1,1,1,1,1,1,1,1,1,1,1,1,1,1,1,1,1,1,1,1,1,1,1,1,1,1,1,1,1,1
1,1,1,1,1,1,1,1,1,1,1,1,1,1,1,1,1,1,1,1,1,1,1,1,1,1,1,1,1,1,1,1,1,1,1,1,1,1,1,1,1
1,1,1,1,1,1,1,1,1,1,1,1,1,1,1,1,1,1,1,1,1,1,1,1,1,1,2,2,1,1,1,1,1,1,1,1,1,1,1,1,1
1,1,1,1,1,1,1,1,1,1,1,1,1,1,1,1,1,1,1,1,1,1,1,1,1,1,1,1,1,1,1,1,1,1,1,1,1,1,1,1,1
1,1,1,1,1,1,1,1,1,1,1,1,1,1,1,1,1,1,1,1,1,1,1,1,1,1,1,1,1,1,1,1,1,1,1,1,1,1,1,1,1
1,1,1,1,1,1,1,1,1,1,1,1,1,1,1,1,1,1,1,1,1,1,1,1,1,1,1,1,1,1,1,1,1,1,1,1,1,1,1,1,1
1,1,1,1,1,1,1,1,1,1,1,1,1,1,1,1,1,1,1,1,1,1,1,1,1,1,1,1,1,1,1,1,1,1,1,1,1,1,1,1,1
:endlayer
layer: 1
1,1,1,1,1,1,1,1,1,1,1,1,1,1,1,1,1,1,1,1,1,1,1,1,1,1,1,1,1,1,1,1,1,1,1,1,1,1,1,1,1
1,1,1,1,1,1,1,1,1,1,1,1,1,1,1,1,1,1,1,1,1,1,1,1,1,1,1,1,1,1,1,1,1,1,1,1,1,1,1,1,1
1,1,1,1,1,1,1,1,1,1,1,1,1,1,1,1,1,1,1,1,1,1,1,1,1,1,1,1,1,1,1,1,1,1,1,1,1,1,1,1,1
1,1,1,1,1,1,1,1,1,1,1,1,1,1,1,1,1,1,1,1,1,1,1,1,1,1,1,1,1,1,1,1,1,1,1,1,1,1,1,1,1
1,1,1,1,1,1,1,1,1,1,1,1,1,1,1,1,1,1,1,1,1,1,1,1,1,1,1,1,1,1,1,1,1,1,1,1,1,1,1,1,1
1,1,1,1,1,1,1,1,1,1,1,1,1,1,1,1,1,1,1,1,1,1,1,1,1,1,1,1,1,1,1,1,1,1,1,1,1,1,1,1,1
1,1,1,1,1,1,1,1,1,1,1,1,1,1,1,1,1,1,1,1,1,1,1,1,1,1,1,1,1,1,1,1,1,1,1,1,1,1,1,1,1
1,1,1,1,1,1,1,1,1,1,1,1,1,1,1,1,1,1,1,1,1,1,1,1,1,1,1,1,1,1,1,1,1,1,1,1,1,1,1,1,1
1,1,1,1,1,1,1,1,1,1,1,1,1,1,1,1,1,1,1,1,1,1,1,1,1,1,1,1,1,1,1,1,1,1,1,1,1,1,1,1,1
1,1,1,1,1,1,1,1,1,1,1,1,1,1,1,1,1,1,1,1,1,1,1,1,1,1,1,1,1,1,1,1,1,1,1,1,1,1,1,1,1
1,1,1,1,1,1,1,1,1,1,1,2,1,1,1,1,1,1,1,1,1,1,1,1,1,1,1,1,1,1,1,1,1,1,1,1,1,1,1,1,1
1,1,1,1,1,1,1,1,1,1,1,1,1,1,1,1,1,1,1,1,1,1,1,1,1,1,1,1,1,1,1,1,1,1,1,1,1,1,1,1,1
1,1,1,1,1,1,1,1,1,1,1,1,1,1,1,1,1,1,1,1,1,1,1,1,1,1,1,1,1,1,1,1,1,1,1,1,1,1,1,1,1
1,1,1,1,1,1,1,1,1,1,1,1,1,1,1,1,1,1,1,1,1,1,1,1,1,1,1,1,1,1,1,1,1,1,1,1,1,1,1,1,1
1,1,1,1,1,1,1,1,1,1,1,1,1,1,1,1,1,1,1,1,1,1,1,1,1,1,1,1,1,1,1,1,1,1,1,1,1,1,1,1,1
1,1,1,1,1,1,1,1,1,1,1,1,1,1,1,1,1,1,1,1,1,1,1,1,1,1,1,1,1,1,1,1,1,1,1,1,1,1,1,1,1
1,1,1,1,1,1,1,1,1,1,1,1,1,1,1,1,1,1,1,1,1,1,1,1,1,1,1,1,1,1,1,1,1,1,1,1,1,1,1,1,1
1,1,1,1,1,1,1,1,1,1,1,1,1,1,1,1,1,1,1,1,1,1,1,1,1,1,1,1,1,1,1,1,1,1,1,1,1,1,1,1,1
1,1,1,1,1,1,1,1,1,1,1,1,1,1,1,1,1,1,1,1,1,1,1,1,1,1,1,1,1,1,1,1,1,1,1,1,1,1,1,1,1
1,1,1,1,1,1,1,1,1,1,1,1,1,1,1,1,1,1,1,1,1,1,1,1,1,1,1,1,1,1,1,1,1,1,1,1,1,1,1,1,1
1,1,1,1,1,1,1,1,1,1,1,1,1,1,1,1,1,1,1,1,1,1,1,1,1,1,1,1,1,1,1,1,1,1,1,1,1,1,1,1,1
1,1,1,1,1,1,1,1,1,1,1,1,1,1,2,1,1,1,1,1,1,1,1,1,1,1,1,1,1,1,1,1,1,1,1,1,1,1,1,1,1
1,1,1,1,1,1,1,1,1,1,1,1,1,1,1,1,1,1,1,1,1,1,1,1,1,1,1,1,1,1,1,1,1,1,1,1,1,1,1,1,1
1,1,1,1,1,1,1,1,1,1,1,1,1,1,1,1,1,1,1,1,1,1,1,1,1,1,1,1,1,1,1,1,1,1,1,1,1,1,1,1,1
1,1,1,1,1,1,1,1,1,1,1,1,1,1,1,1,1,1,1,1,1,1,1,1,1,1,1,1,1,1,1,1,1,1,1,1,1,1,1,1,1
1,1,1,1,1,1,1,1,1,1,1,1,1,1,1,1,1,1,1,1,1,1,1,1,1,1,1,1,1,1,1,1,1,1,1,1,1,1,1,1,1
1,1,1,1,1,1,1,1,1,1,1,1,1,1,1,1,1,1,1,1,1,1,1,1,1,1,1,1,1,1,1,1,1,1,1,1,1,1,1,1,1
1,1,1,1,1,1,1,1,1,1,1,1,1,1,1,1,1,1,1,1,1,1,1,1,1,1,1,1,1,1,1,1,1,1,1,1,1,1,1,1,1
1,1,1,1,1,1,1,1,1,1,1,1,1,1,1,1,1,1,1,1,1,1,1,1,1,1,1,1,1,1,1,1,1,1,1,1,1,1,1,1,1
1,1,1,1,1,1,1,1,1,1,1,1,1,1,1,1,1,1,1,1,1,1,1,1,1,1,1,1,1,1,1,1,1,1,1,1,1,1,1,1,1
1,1,1,1,1,1,1,1,1,1,1,1,1,1,1,1,1,1,1,1,1,1,1,1,1,1,1,1,1,1,1,1,1,1,1,1,1,1,1,1,1
1,1,1,1,1,1,1,1,1,1,1,1,1,1,1,1,1,1,1,1,1,1,1,1,1,1,1,1,1,1,1,1,1,1,1,1,1,1,1,1,1
1,1,1,1,1,1,1,1,1,1,1,1,1,1,1,1,1,1,1,1,1,1,1,1,1,1,1,1,1,1,1,1,1,1,1,1,1,1,1,1,1
1,1,1,1,1,1,1,1,1,1,1,1,1,1,1,1,1,1,1,1,1,1,1,1,1,1,1,1,1,1,1,1,1,1,1,1,1,1,1,1,1
1,1,1,1,1,1,1,1,1,1,1,1,1,1,1,1,1,1,1,1,1,1,1,1,1,1,1,1,1,1,1,1,1,1,1,1,1,1,1,1,1
1,1,1,1,1,1,1,1,1,1,1,1,1,1,1,1,1,1,1,1,1,1,1,1,1,1,1,1,1,1,1,1,1,1,1,1,1,1,1,1,1
1,1,1,1,1,1,1,1,1,1,1,1,1,1,1,1,1,1,1,1,1,1,1,1,1,1,1,1,1,1,1,1,1,1,1,1,1,1,1,1,1
1,1,1,1,1,1,1,1,1,1,1,1,1,1,1,1,1,1,1,1,1,1,1,1,1,1,1,1,1,1,1,1,1,1,1,1,1,1,1,1,1
1,1,1,1,1,1,1,1,1,1,1,1,1,1,1,1,1,1,1,1,1,1,1,1,1,1,1,1,1,1,1,1,1,1,1,1,1,1,1,1,1
1,1,1,1,1,1,1,1,1,1,1,1,1,1,1,1,1,1,1,1,1,1,1,1,1,1,1,1,1,1,1,1,1,1,1,1,1,1,1,1,1
1,1,1,1,1,1,1,1,1,1,1,1,1,1,1,1,1,1,1,1,1,1,1,1,1,1,1,1,1,1,1,1,1,1,1,1,1,1,1,1,1
1,1,1,1,1,1,1,1,1,1,1,1,1,1,1,1,1,1,1,1,1,1,1,1,1,1,1,1,1,1,1,1,1,1,1,1,1,1,1,1,1
1,1,1,1,1,1,1,1,1,1,1,1,1,1,1,1,1,1,1,1,1,1,1,1,1,1,1,1,1,1,1,1,1,1,1,1,1,1,1,1,1
1,1,1,1,1,1,1,1,1,1,1,1,1,1,1,1,1,1,1,1,1,1,1,1,1,1,2,1,1,1,1,1,1,1,1,1,1,1,1,1,1
1,1,1,1,1,1,1,1,1,1,1,1,1,1,1,1,1,1,1,1,1,1,1,1,1,1,1,1,1,1,1,1,1,1,1,1,1,1,1,1,1
1,1,1,1,1,1,1,1,1,1,1,1,1,1,1,1,1,1,1,1,1,1,1,1,1,1,1,1,1,1,1,1,1,1,1,1,1,1,1,1,1
1,1,1,1,1,1,1,1,1,1,1,1,1,1,1,1,1,1,1,1,1,1,1,1,1,1,1,1,1,1,1,1,1,1,1,1,1,1,1,1,1
1,1,1,1,1,1,1,1,1,1,1,1,1,1,1,1,1,1,1,1,1,1,1,1,1,1,1,1,1,1,1,1,1,1,1,1,1,1,1,1,1
1,1,1,1,1,1,1,1,1,1,1,1,1,1,1,1,1,1,1,1,1,1,1,1,1,1,1,1,1,1,1,1,1,1,1,1,1,1,1,1,1
:endlayer
layer: 2
3,3,3,3,3,3,3,3,3,3,3,3,3,3,3,3,3,3,3,3,3,3,3,3,3,3,3,3,3,3,3,3,3,3,3,3,3,3,3,3,3
3,3,3,3,1,3,1,3,1,3,3,3,3,3,3,3,3,3,3,3,3,3,3,3,3,3,3,3,3,3,3,3,1,3,1,3,1,3,3,3,3
3,3,3,1,1,1,1,1,1,1,3,3,3,3,3,3,3,3,3,3,3,3,3,3,3,3,3,3,3,3,3,1,1,1,1,1,1,1,3,3,3
3,3,1,1,4,4,4,4,4,4,4,4,4,4,4,4,4,4,4,4,4,4,4,4,4,4,4,4,4,4,4,4,4,4,4,4,4,4,1,3,3
3,1,1,1,4,4,4,4,4,4,4,4,4,4,4,4,4,4,4,4,4,4,4,4,4,4,4,4,4,4,4,4,4,4,4,4,4,4,1,1,3
3,3,1,1,4,4,4,4,4,4,4,4,4,4,4,4,4,4,4,4,4,4,4,4,4,4,4,4,4,4,4,4,4,4,4,4,4,4,1,3,3
3,1,1,1,4,4,4,4,4,4,4,4,4,4,4,4,4,4,4,4,4,4,4,4,4,4,4,4,4,4,4,4,4,4,4,4,4,4,1,1,3
3,3,1,1,4,4,4,4,4,4,4,4,4,4,4,4,4,4,4,4,4,4,4,4,4,4,4,4,4,4,4,4,4,4,4,4,4,4,1,3,3
3,1,1,1,4,4,4,4,4,4,4,4,4,4,4,4,4,4,4,4,4,4,4,4,4,4,4,4,4,4,4,4,4,4,4,4,4,4,1,1,3
3,3,1,1,4,4,4,4,4,4,4,4,4,4,4,4,4,4,4,4,4,4,4,4,4,4,4,4,4,4,4,4,4,4,4,4,4,4,1,3,3
3,3,3,1,4,4,4,4,4,4,5,4,4,4,4,4,5,4,4,4,4,4,4,4,5,4,4,4,4,4,5,4,4,4,4,4,4,4,3,3,3
3,3,3,3,4,4,4,4,4,4,4,4,4,4,4,4,4,4,4,4,4,4,4,4,4,4,4,4,4,4,4,4,4,4,4,4,4,4,3,3,3
3,3,3,3,4,4,4,4,4,4,4,4,4,4,4,4,4,4,4,4,4,4,4,4,4,4,4,4,4,4,4,4,4,4,4,4,4,4,3,3,3
3,3,3,3,4,4,4,4,4,4,4,4,4,4,4,4,4,4,4,4,4,4,4,4,4,4,4,4,4,4,4,4,4,4,4,4,4,4,3,3,3
3,3,3,3,4,4,4,4,4,4,4,4,4,4,4,4,4,4,4,4,4,4,4,4,4,4,4,4,4,4,4,4,4,4,4,4,4,4,3,3,3
3,3,3,3,4,4,4,4,4,4,4,4,4,4,4,4,4,4,4,4,4,4,4,4,4,4,4,4,4,4,4,4,4,4,4,4,4,4,3,3,3
3,3,3,3,4,4,4,4,4,4,5,4,4,4,4,4,4,4,4,4,5,4,4,4,4,4,4,4,4,4,5,4,4,4,4,4,4,4,3,3,3
3,3,3,3,4,4,4,4,4,4,4,4,4,4,4,4,4,4,4,4,4,4,4,4,4,4,4,4,4,4,4,4,4,4,4,4,4,4,3,3,3
3,3,3,3,4,4,4,4,4,4,4,4,4,4,4,4,4,4,4,4,4,4,4,4,4,4,4,4,4,4,4,4,4,4,4,4,4,4,3,3,3
3,3,3,3,4,4,4,4,4,4,4,4,4,4,4,4,4,4,4,4,4,4,4,4,4,4,4,4,4,4,4,4,4,4,4,4,4,4,3,3,3
3,3,3,3,4,4,4,4,4,4,4,4,4,4,4,4,4,4,4,4,4,4,4,4,4,4,4,4,4,4,4,4,4,4,4,4,4,4,3,3,3
3,3,3,3,4,4,4,4,4,4,4,4,4,4,4,4,4,4,4,4,4,4,4,4,4,4,4,4,4,4,4,4,4,4,4,4,4,4,3,3,3
3,3,3,3,4,4,4,4,4,4,4,4,4,4,4,4,4,4,4,4,4,4,4,4,4,4,4,4,4,4,4,4,4,4,4,4,4,4,3,3,3
3,3,3,3,4,4,4,4,4,4,4,4,4,4,4,4,4,4,4,4,4,4,4,4,4,4,4,4,4,4,4,4,4,4,4,4,4,4,3,3,3
3,3,3,3,4,4,4,4,4,4,5,4,4,4,4,4,4,4,4,4,5,4,4,4,4,4,4,4,4,4,5,4,4,4,4,4,4,4,3,3,3
3,3,3,3,4,4,4,4,4,4,4,4,4,4,4,4,4,4,4,4,4,4,4,4,4,4,4,4,4,4,4,4,4,4,4,4,4,4,3,3,3
3,3,3,3,4,4,4,4,4,4,4,4,4,4,4,4,4,4,4,4,4,4,4,4,4,4,4,4,4,4,4,4,4,4,4,4,4,4,3,3,3
3,3,3,3,4,4,4,4,4,4,4,4,4,4,4,4,4,4,4,4,4,4,4,4,4,4,4,4,4,4,4,4,4,4,4,4,4,4,3,3,3
3,3,3,3,4,4,4,4,4,4,4,4,4,4,4,4,4,4,4,4,4,4,4,4,4,4,4,4,4,4,4,4,4,4,4,4,4,4,3,3,3
3,3,3,3,4,4,4,4,4,4,4,4,4,4,4,4,4,4,4,4,4,4,4,4,4,4,4,4,4,4,4,4,4,4,4,4,4,4,3,3,3
3,3,3,1,4,4,4,4,4,4,5,4,4,4,4,4,5,4,4,4,4,4,4,4,5,4,4,4,4,4,5,4,4,4,4,4,4,4,3,3,3
3,3,1,1,4,4,4,4,4,4,4,4,4,4,4,4,4,4,4,4,4,4,4,4,4,4,4,4,4,4,4,4,4,4,4,4,4,4,1,3,3
3,1,1,1,4,4,4,4,4,4,4,4,4,4,4,4,4,4,4,4,4,4,4,4,4,4,4,4,4,4,4,4,4,4,4,4,4,4,1,1,3
3,3,1,1,4,4,4,4,4,4,4,4,4,4,4,4,4,4,4,4,4,4,4,4,4,4,4,4,4,4,4,4,4,4,4,4,4,4,1,3,3
3,1,1,1,4,4,4,4,4,4,4,4,4,4,4,4,4,4,4,4,4,4,4,4,4,4,4,4,4,4,4,4,4,4,4,4,4,4,1,1,3
3,3,1,1,4,4,4,4,4,4,4,4,4,4,4,4,4,4,4,4,4,4,4,4,4,4,4,4,4,4,4,4,4,4,4,4,4,4,1,3,3
3,1,1,1,4,4,4,4,4,4,4,4,3,3,3,3,3,4,4,4,4,4,4,4,3,3,3,3,3,4,4,4,4,4,4,4,4,4,1,1,3
3,3,1,1,1,1,1,1,1,1,1,3,3,3,3,3,3,3,6,3,3,3,3,3,3,3,3,3,3,3,3,3,3,3,3,3,3,3,1,3,3
3,3,3,1,1,1,1,1,1,1,3,3,3,3,3,3,3,1,1,6,3,6,1,3,3,3,3,3,3,3,3,1,3,1,3,1,3,1,3,3,3
3,3,3,3,1,3,1,3,1,3,3,3,3,3,3,3,3,3,1,3,3,3,3,3,3,3,3,3,3,3,3,3,3,3,3,3,3,3,3,3,3
3,3,3,3,3,3,3,3,3,3,3,3,3,3,3,3,3,7,7,7,7,7,3,1,3,3,3,3,3,3,3,3,3,3,3,3,3,3,3,3,3
3,3,3,3,3,3,3,3,3,3,3,3,3,3,3,3,3,3,3,7,7,7,3,3,3,3,3,3,3,3,3,3,3,3,3,3,3,3,3,3,3
3,3,3,3,3,3,3,3,3,3,3,3,3,3,3,3,3,7,7,7,7,7,1,1,3,3,3,3,3,3,3,3,3,3,3,3,3,3,3,3,3
3,3,3,3,3,3,3,3,3,3,3,3,3,3,3,3,3,3,7,7,7,7,3,3,3,3,3,3,3,3,3,3,3,3,3,3,3,3,3,3,3
3,3,3,3,3,3,3,3,3,3,3,3,3,3,3,3,3,3,3,3,3,3,3,3,3,3,3,3,3,3,3,3,3,3,3,3,3,3,3,3,3
3,3,3,3,3,3,3,3,3,3,3,3,3,3,3,3,3,3,3,3,3,3,3,3,3,3,3,3,3,3,3,3,3,3,3,3,3,3,3,3,3
3,3,3,3,3,3,3,3,3,3,3,3,3,3,3,3,3,3,3,3,3,3,3,3,3,3,3,3,3,3,3,3,3,3,3,3,3,3,3,3,3
3,3,3,3,3,3,3,3,3,3,3,3,3,3,3,3,3,3,3,3,3,3,3,3,3,3,3,3,3,3,3,3,3,3,3,3,3,3,3,3,3
3,3,3,3,3,3,3,3,3,3,3,3,3,3,3,3,3,3,3,3,3,3,3,3,3,3,3,3,3,3,3,3,3,3,3,3,3,3,3,3,3
:endlayer
layer: 3
0,0,0,0,0,0,0,0,0,0,0,0,0,0,0,0,0,0,0,0,0,0,0,0,0,0,0,0,0,0,0,0,0,0,0,0,0,0,0,0,0
0,0,0,0,6,12,6,12,6,0,0,0,0,0,0,0,0,0,0,0,0,0,0,0,0,0,0,0,0,0,0,0,6,12,6,12,6,0,0,0,0
0,0,0,6,6,6,6,6,6,6,0,0,0,0,0,0,0,0,0,0,0,0,0,0,0,0,0,0,0,0,0,6,6,6,6,6,6,6,0,0,0
0,0,6,6,6,6,6,6,6,6,6,0,0,0,0,0,0,0,0,0,0,0,0,0,0,0,0,0,0,0,6,6,6,6,6,6,6,6,6,0,0
0,6,6,6,6,11,11,11,6,6,6,6,0,0,0,0,0,0,0,0,0,0,0,0,0,0,0,0,0,6,6,6,6,11,11,11,6,6,6,6,0
0,23,6,6,0,0,11,11,11,6,6,0,6,12,6,12,6,12,6,12,6,12,6,12,6,12,6,12,6,0,6,6,11,11,0,0,0,6,6,9,0
0,6,6,6,0,0,14,15,15,6,6,6,6,6,6,6,6,6,6,6,6,6,6,6,6,6,6,6,6,6,6,6,15,15,14,0,0,6,6,6,0
0,23,6,6,0,0,0,0,0,6,6,6,6,6,6,6,6,6,6,6,6,6,6,6,6,6,6,6,6,6,6,6,0,0,0,0,0,6,6,9,0
0,6,6,6,6,0,0,0,0,0,0,0,0,0,0,0,0,0,0,0,0,0,0,0,0,0,0,0,0,0,0,0,0,0,0,0,6,6,6,6,0
0,0,6,6,6,6,6,6,0,0,0,0,0,0,0,0,0,0,0,0,0,0,0,0,0,0,0,0,0,0,0,0,0,6,6,6,6,6,6,0,0
0,0,0,6,6,6,6,6,0,0,0,0,0,0,0,0,0,0,0,0,0,0,0,0,0,0,0,0,0,0,0,0,0,6,6,6,6,6,0,0,0
0,0,0,0,6,0,6,6,0,0,0,0,0,0,0,0,0,0,0,0,0,0,0,0,0,0,0,0,0,0,0,0,0,6,6,0,6,0,0,0,0
0,0,0,0,0,6,6,6,0,0,0,0,0,0,0,0,0,0,0,0,0,0,0,0,0,0,0,0,0,0,0,0,0,6,6,6,0,0,0,0,0
0,0,0,0,0,23,6,6,0,0,0,0,0,0,0,0,0,0,0,0,0,0,0,0,0,0,0,0,0,0,0,0,0,6,6,9,0,0,0,0,0
0,0,0,0,0,6,6,6,0,0,0,0,0,0,0,0,0,0,0,0,0,0,0,0,0,0,0,0,0,0,0,0,0,6,6,6,0,0,0,0,0
0,0,0,0,0,23,6,6,0,0,0,0,0,0,0,0,0,0,0,0,0,0,0,0,0,0,0,0,0,0,0,0,0,6,6,9,0,0,0,0,0
0,0,0,0,0,6,6,6,0,0,0,0,0,0,0,0,0,0,0,0,0,0,0,0,0,0,0,0,0,0,0,0,0,6,6,6,0,0,0,0,0
0,0,0,0,0,23,6,6,0,0,0,0,0,0,0,0,0,0,0,0,0,0,0,0,0,0,0,0,0,0,0,0,0,6,6,9,0,0,0,0,0
0,0,0,0,0,6,6,6,0,0,0,0,0,0,0,0,0,0,0,0,0,0,0,0,0,0,0,0,0,0,0,0,0,6,6,6,0,0,0,0,0
0,0,0,0,0,23,6,6,0,0,0,0,0,0,0,0,0,0,0,0,0,0,0,0,0,0,0,0,0,0,0,0,0,6,6,9,0,0,0,0,0
0,0,0,0,0,6,6,6,0,0,0,0,0,0,0,0,0,0,0,0,20,0,0,0,0,0,0,0,0,0,0,0,0,6,6,6,0,0,0,0,0
0,0,0,0,0,23,6,6,0,0,0,0,0,0,0,0,0,0,0,0,0,0,0,0,0,0,0,0,0,0,0,0,0,6,6,9,0,0,0,0,0
0,0,0,0,0,6,6,6,0,0,0,0,0,0,0,0,0,0,0,0,0,0,0,0,0,0,0,0,0,0,0,0,0,6,6,6,0,0,0,0,0
0,0,0,0,0,23,6,6,0,0,0,0,0,0,0,0,0,0,0,0,0,0,0,0,0,0,0,0,0,0,0,0,0,6,6,9,0,0,0,0,0
0,0,0,0,0,6,6,6,0,0,0,0,0,0,0,0,0,0,0,0,0,0,0,0,0,0,0,0,0,0,0,0,0,6,6,6,0,0,0,0,0
0,0,0,0,0,23,6,6,0,0,0,0,0,0,0,0,0,0,0,0,0,0,0,0,0,0,0,0,0,0,0,0,0,6,6,9,0,0,0,0,0
0,0,0,0,0,6,6,6,0,0,0,0,0,0,0,0,0,0,0,0,0,0,0,0,0,0,0,0,0,0,0,0,0,6,6,6,0,0,0,0,0
0,0,0,0,0,23,6,6,0,0,0,0,0,0,0,0,0,0,0,0,0,0,0,0,0,0,0,0,0,0,0,0,0,6,6,9,0,0,0,0,0
0,0,0,0,0,6,6,6,0,0,0,0,0,0,0,0,0,0,0,0,0,0,0,0,0,0,0,0,0,0,0,0,0,6,6,6,0,0,0,0,0
0,0,0,0,6,0,6,6,0,0,0,0,0,0,0,0,0,0,0,0,0,0,0,0,0,0,0,0,0,0,0,0,0,6,6,0,6,0,0,0,0
0,0,0,6,6,6,6,6,0,0,0,0,0,0,0,0,0,0,0,0,0,0,0,0,0,0,0,0,0,0,0,0,0,6,6,6,6,6,0,0,0
0,0,6,6,6,6,6,6,0,0,0,0,0,0,0,0,0,0,0,0,0,0,0,0,0,0,0,0,0,0,0,0,0,6,6,6,6,6,6,0,0
0,6,6,6,6,15,15,0,0,0,0,0,0,0,0,0,0,0,0,0,0,0,0,0,0,0,0,0,0,0,0,0,0,0,15,11,6,6,6,6,0
0,23,6,6,11,11,15,0,0,6,6,6,6,6,6,6,6,6,6,6,6,6,6,6,6,6,6,6,6,6,6,6,0,0,15,11,0,6,6,9,0
0,6,6,6,11,11,14,0,0,6,6,6,6,6,6,6,6,6,6,6,6,6,6,6,6,6,6,6,6,6,6,6,0,0,14,0,11,6,6,6,0
0,23,6,6,11,11,0,0,0,6,6,0,6,13,6,13,6,0,21,0,0,0,17,0,6,13,6,13,6,0,6,6,0,0,0,0,0,6,6,9,0
0,6,6,6,6,11,0,0,6,6,6,6,0,0,0,0,0,6,6,0,0,0,6,6,0,0,0,0,0,6,6,6,6,0,0,0,6,6,6,6,0
8,8,6,6,6,6,6,6,6,6,6,0,0,0,0,0,0,0,21,0,0,0,17,0,0,0,0,0,0,0,6,6,6,6,6,6,6,6,6,8,8
8,0,0,6,6,6,6,6,6,6,0,0,0,0,0,0,0,6,6,0,0,0,6,6,0,0,0,0,0,0,0,6,6,6,6,6,6,6,0,0,8
8,0,0,0,6,13,6,13,6,0,0,0,0,0,0,0,0,0,21,0,0,0,17,0,0,0,0,0,0,0,0,0,6,13,6,13,6,0,0,0,8
8,0,0,0,0,0,0,0,0,0,0,0,0,0,0,0,0,6,6,0,0,0,6,6,0,0,0,0,0,0,0,0,0,0,0,0,0,0,0,0,8
8,0,0,0,0,0,0,0,0,0,0,0,0,0,0,0,0,0,21,0,0,0,17,0,0,0,0,0,0,0,0,0,0,0,0,0,0,0,0,0,8
8,0,0,0,0,0,0,0,0,0,0,0,0,0,0,0,0,6,6,18,18,18,6,6,0,0,0,0,0,0,0,0,0,0,0,0,0,0,0,0,8
8,0,0,0,0,0,0,0,0,0,0,0,0,0,0,0,0,0,6,19,19,19,6,0,0,0,0,0,0,0,0,0,0,0,0,0,0,0,0,0,8
8,24,0,0,0,0,0,0,0,0,0,0,22,0,0,0,0,0,0,0,0,0,0,0,0,0,0,0,0,16,0,0,0,0,0,0,0,0,0,10,8
8,0,0,0,0,0,0,0,0,0,0,0,0,0,0,0,0,0,0,0,0,0,0,0,0,0,0,0,0,0,0,0,0,0,0,0,0,0,0,0,8
8,0,0,0,0,0,0,0,0,0,0,0,0,0,0,0,0,0,0,0,0,0,0,0,0,0,0,0,0,0,0,0,0,0,0,0,0,0,0,0,8
8,0,0,0,0,0,0,0,0,0,0,0,0,0,0,0,0,0,0,0,0,0,0,0,0,0,0,0,0,0,0,0,0,0,0,0,0,0,0,0,8
8,8,8,8,8,8,8,8,8,8,8,8,8,8,8,8,8,8,6,0,0,0,6,8,8,8,8,8,8,8,8,8,8,8,8,8,8,8,8,8,8
:endlayer
layer: 4
0,0,0,0,0,0,0,0,0,0,0,0,0,0,0,0,0,0,0,0,0,0,0,0,0,0,0,0,0,0,0,0,0,0,0,0,0,0,0,0,0
0,0,0,0,6,0,6,0,6,0,0,0,0,0,0,0,0,0,0,0,0,0,0,0,0,0,0,0,0,0,0,0,6,0,6,0,6,0,0,0,0
0,0,0,6,6,6,6,6,6,6,0,0,0,0,0,0,0,0,0,0,0,0,0,0,0,0,0,0,0,0,0,6,6,6,6,6,6,6,0,0,0
0,0,6,6,6,6,6,6,6,6,6,0,0,0,0,0,0,0,0,0,0,0,0,0,0,0,0,0,0,0,6,6,6,6,6,6,6,6,6,0,0
0,6,6,6,6,11,15,0,6,6,6,6,0,0,0,0,0,0,0,0,0,0,0,0,0,0,0,0,0,6,6,6,6,0,15,11,6,6,6,6,0
0,0,6,6,11,11,15,0,0,6,6,0,6,0,6,0,6,0,6,0,6,0,6,0,6,0,6,0,6,0,6,6,0,0,15,11,11,6,6,0,0
0,6,6,6,0,0,14,0,0,6,6,6,6,6,6,6,6,6,6,6,6,6,6,6,6,6,6,6,6,6,6,6,0,0,14,0,0,6,6,6,0
0,0,6,6,0,0,0,0,0,6,6,6,6,6,6,6,6,6,6,6,6,6,6,6,6,6,6,6,6,6,6,6,0,0,0,0,0,6,6,0,0
0,6,6,6,6,0,0,0,0,0,0,0,0,0,0,0,0,0,0,0,0,0,0,0,0,0,0,0,0,0,0,0,0,0,0,0,6,6,6,6,0
0,0,6,6,6,6,6,6,0,0,0,0,0,0,0,0,0,0,0,0,0,0,0,0,0,0,0,0,0,0,0,0,0,6,6,6,6,6,6,0,0
0,0,0,6,6,6,6,6,0,0,0,0,0,0,0,0,0,0,0,0,0,0,0,0,0,0,0,0,0,0,0,0,0,6,6,6,6,6,0,0,0
0,0,0,0,6,0,6,6,0,0,0,0,0,0,0,0,0,0,0,0,0,0,0,0,0,0,0,0,0,0,0,0,0,6,6,0,6,0,0,0,0
0,0,0,0,0,6,6,6,0,0,0,0,0,0,0,0,0,0,0,0,0,0,0,0,0,0,0,0,0,0,0,0,0,6,6,6,0,0,0,0,0
0,0,0,0,0,0,6,6,0,0,0,0,0,0,0,0,0,0,0,0,0,0,0,0,0,0,0,0,0,0,0,0,0,6,6,0,0,0,0,0,0
0,0,0,0,0,6,6,6,0,0,0,0,0,0,0,0,0,0,0,0,0,0,0,0,0,0,0,0,0,0,0,0,0,6,6,6,0,0,0,0,0
0,0,0,0,0,0,6,6,0,0,0,0,0,0,0,0,0,0,0,0,0,0,0,0,0,0,0,0,0,0,0,0,0,6,6,0,0,0,0,0,0
0,0,0,0,0,6,6,6,0,0,0,0,0,0,0,0,0,0,0,0,0,0,0,0,0,0,0,0,0,0,0,0,0,6,6,6,0,0,0,0,0
0,0,0,0,0,0,6,6,0,0,0,0,0,0,0,0,0,0,0,0,0,0,0,0,0,0,0,0,0,0,0,0,0,6,6,0,0,0,0,0,0
0,0,0,0,0,6,6,6,0,0,0,0,0,0,0,0,0,0,0,0,0,0,0,0,0,0,0,0,0,0,0,0,0,6,6,6,0,0,0,0,0
0,0,0,0,0,0,6,6,0,0,0,0,0,0,0,0,0,0,0,0,0,0,0,0,0,0,0,0,0,0,0,0,0,6,6,0,0,0,0,0,0
0,0,0,0,0,6,6,6,0,0,0,0,0,0,0,0,0,0,0,0,0,0,0,0,0,0,0,0,0,0,0,0,0,6,6,6,0,0,0,0,0
0,0,0,0,0,0,6,6,0,0,0,0,0,0,0,0,0,0,0,0,0,0,0,0,0,0,0,0,0,0,0,0,0,6,6,0,0,0,0,0,0
0,0,0,0,0,6,6,6,0,0,0,0,0,0,0,0,0,0,0,0,0,0,0,0,0,0,0,0,0,0,0,0,0,6,6,6,0,0,0,0,0
0,0,0,0,0,0,6,6,0,0,0,0,0,0,0,0,0,0,0,0,0,0,0,0,0,0,0,0,0,0,0,0,0,6,6,0,0,0,0,0,0
0,0,0,0,0,6,6,6,0,0,0,0,0,0,0,0,0,0,0,0,0,0,0,0,0,0,0,0,0,0,0,0,0,6,6,6,0,0,0,0,0
0,0,0,0,0,0,6,6,0,0,0,0,0,0,0,0,0,0,0,0,0,0,0,0,0,0,0,0,0,0,0,0,0,6,6,0,0,0,0,0,0
0,0,0,0,0,6,6,6,0,0,0,0,0,0,0,0,0,0,0,0,0,0,0,0,0,0,0,0,0,0,0,0,0,6,6,6,0,0,0,0,0
0,0,0,0,0,0,6,6,0,0,0,0,0,0,0,0,0,0,0,0,0,0,0,0,0,0,0,0,0,0,0,0,0,6,6,0,0,0,0,0,0
0,0,0,0,0,6,6,6,0,0,0,0,0,0,0,0,0,0,0,0,0,0,0,0,0,0,0,0,0,0,0,0,0,6,6,6,0,0,0,0,0
0,0,0,0,6,0,6,6,0,0,0,0,0,0,0,0,0,0,0,0,0,0,0,0,0,0,0,0,0,0,0,0,0,6,6,0,6,0,0,0,0
0,0,0,6,6,6,6,6,0,0,0,0,0,0,0,0,0,0,0,0,0,0,0,0,0,0,0,0,0,0,0,0,0,6,6,6,6,6,0,0,0
0,0,6,6,6,6,6,6,0,0,0,0,0,0,0,0,0,0,0,0,0,0,0,0,0,0,0,0,0,0,0,0,0,6,6,6,6,6,6,0,0
0,6,6,6,6,0,0,0,0,0,0,0,0,0,0,0,0,0,0,0,0,0,0,0,0,0,0,0,0,0,0,0,0,0,0,0,6,6,6,6,0
0,0,6,6,0,0,0,0,0,6,6,6,6,6,6,6,6,6,6,6,6,6,6,6,6,6,6,6,6,6,6,6,0,0,0,0,15,6,6,0,0
0,6,6,6,15,15,14,0,0,6,6,6,6,6,6,6,6,6,6,6,6,6,6,6,6,6,6,6,6,6,6,6,0,0,14,15,15,6,6,6,0
0,0,6,6,11,11,11,0,0,6,6,0,6,0,6,0,6,0,23,0,0,0,9,0,6,0,6,0,6,0,6,6,0,0,0,11,11,6,6,0,0
0,6,6,6,6,11,11,11,6,6,6,6,0,0,0,0,0,6,6,0,0,0,6,6,0,0,0,0,0,6,6,6,6,0,0,11,6,6,6,6,0
0,0,6,6,6,6,6,6,6,6,6,0,0,0,0,0,0,0,23,0,0,0,9,0,0,0,0,0,0,0,6,6,6,6,6,6,6,6,6,0,0
0,0,0,6,6,6,6,6,6,6,0,0,0,0,0,0,0,6,6,0,0,0,6,6,0,0,0,0,0,0,0,6,6,6,6,6,6,6,0,0,0
0,0,0,0,6,0,6,0,6,0,0,0,0,0,0,0,0,0,23,0,0,0,9,0,0,0,0,0,0,0,0,0,6,0,6,0,6,0,0,0,0
0,0,0,0,0,0,0,0,0,0,0,0,0,0,0,0,0,6,6,0,0,0,6,6,0,0,0,0,0,0,0,0,0,0,0,0,0,0,0,0,0
0,0,0,0,0,0,0,0,0,0,0,0,0,0,0,0,0,0,6,18,18,18,6,0,0,0,0,0,0,0,0,0,0,0,0,0,0,0,0,0,0
0,0,0,0,0,0,0,0,0,0,0,0,0,0,0,0,0,23,6,19,19,19,6,9,0,0,0,0,0,0,0,0,0,0,0,0,0,0,0,0,0
0,0,0,0,0,0,0,0,0,0,0,0,0,0,0,0,0,0,6,0,0,0,6,0,0,0,0,0,0,0,0,0,0,0,0,0,0,0,0,0,0
0,0,0,0,0,0,0,0,0,0,0,0,0,0,0,0,0,0,0,0,0,0,0,0,0,0,0,0,0,0,0,0,0,0,0,0,0,0,0,0,0
0,0,0,0,0,0,0,0,0,0,0,0,0,0,0,0,0,0,0,0,0,0,0,0,0,0,0,0,0,0,0,0,0,0,0,0,0,0,0,0,0
0,0,0,0,0,0,0,0,0,0,0,0,0,0,0,0,0,0,0,0,0,0,0,0,0,0,0,0,0,0,0,0,0,0,0,0,0,0,0,0,0
0,0,0,0,0,0,0,0,0,0,0,0,0,0,0,0,0,0,26,0,0,0,26,0,0,0,0,0,0,0,0,0,0,0,0,0,0,0,0,0,0
25,0,0,0,0,0,25,0,0,0,0,0,0,0,0,0,0,0,6,0,0,0,6,0,0,0,0,0,0,0,0,0,0,0,25,0,0,0,0,0,25
:endlayer
layer: 5
0,0,0,0,26,0,26,0,26,0,0,0,0,0,0,0,0,0,0,0,0,0,0,0,0,0,0,0,0,0,0,0,26,0,0,0,0,0,0,0,0
0,0,0,0,6,0,6,0,6,0,0,0,0,0,0,0,0,0,0,0,0,0,0,0,0,0,0,0,0,0,0,0,6,0,6,0,6,0,0,0,0
0,0,29,6,6,6,6,6,6,6,0,0,0,0,0,0,0,0,0,0,0,0,0,0,0,0,0,0,0,0,0,6,6,6,6,6,6,6,0,0,0
0,29,6,6,6,6,6,6,6,6,6,0,0,0,0,0,0,0,0,0,0,0,0,0,0,0,0,0,0,0,6,6,6,6,6,6,6,6,6,0,0
29,6,6,6,6,0,0,0,6,6,6,6,27,0,0,0,0,0,0,0,0,0,0,0,0,0,0,0,29,6,6,6,6,0,0,0,6,6,6,6,27
0,0,6,6,0,0,0,0,0,6,6,0,6,26,6,26,6,26,6,26,6,26,6,26,6,26,6,26,6,0,6,6,0,0,0,0,0,6,6,0,0
29,6,6,6,15,15,5,0,0,6,6,6,6,6,6,6,6,6,6,6,6,6,6,6,6,6,6,6,6,6,6,6,0,0,5,15,15,6,6,6,27
0,0,6,6,11,11,0,0,0,6,6,6,6,6,6,6,6,6,6,6,6,6,6,6,6,6,6,6,6,6,6,6,0,0,0,11,11,6,6,0,0
29,6,6,6,6,11,0,0,0,0,0,0,0,0,0,0,0,0,0,0,0,0,0,0,0,0,0,0,0,0,0,0,0,0,0,11,6,6,6,6,27
0,28,6,6,6,6,6,6,0,0,0,0,0,0,0,0,0,0,0,0,0,0,0,0,0,0,0,0,0,0,0,0,0,6,6,6,6,6,6,0,0
0,0,28,6,6,6,6,6,0,0,0,0,0,0,0,0,0,0,0,0,0,0,0,0,0,0,0,0,0,0,0,0,0,6,6,6,6,6,0,0,0
0,0,0,28,6,0,6,6,0,0,0,0,0,0,0,0,0,0,0,0,0,0,0,0,0,0,0,0,0,0,0,0,0,6,6,0,6,27,0,0,0
0,0,0,0,28,6,6,6,0,0,0,0,0,0,0,0,0,0,0,0,0,0,0,0,0,0,0,0,0,0,0,0,0,6,6,6,0,0,0,0,0
0,0,0,0,0,29,6,6,0,0,0,0,0,0,0,0,0,0,0,0,0,0,0,0,0,0,0,0,0,0,0,0,0,6,6,27,0,0,0,0,0
0,0,0,0,0,6,6,6,0,0,0,0,0,0,0,0,0,0,0,0,0,0,0,0,0,0,0,0,0,0,0,0,0,6,6,6,0,0,0,0,0
0,0,0,0,0,29,6,6,0,0,0,0,0,0,0,0,0,0,0,0,0,0,0,0,0,0,0,0,0,0,0,0,0,6,6,27,0,0,0,0,0
0,0,0,0,0,6,6,6,0,0,0,0,0,0,0,0,0,0,0,0,0,0,0,0,0,0,0,0,0,0,0,0,0,6,6,6,0,0,0,0,0
0,0,0,0,0,29,6,6,0,0,0,0,0,0,0,0,0,0,0,0,0,0,0,0,0,0,0,0,0,0,0,0,0,6,6,27,0,0,0,0,0
0,0,0,0,0,6,6,6,0,0,0,0,0,0,0,0,0,0,0,0,0,0,0,0,0,0,0,0,0,0,0,0,0,6,6,6,0,0,0,0,0
0,0,0,0,0,29,6,6,0,0,0,0,0,0,0,0,0,0,0,0,0,0,0,0,0,0,0,0,0,0,0,0,0,6,6,27,0,0,0,0,0
0,0,0,0,0,6,6,6,0,0,0,0,0,0,0,0,0,0,0,0,0,0,0,0,0,0,0,0,0,0,0,0,0,6,6,6,0,0,0,0,0
0,0,0,0,0,29,6,6,0,0,0,0,0,0,0,0,0,0,0,0,0,0,0,0,0,0,0,0,0,0,0,0,0,6,6,27,0,0,0,0,0
0,0,0,0,0,6,6,6,0,0,0,0,0,0,0,0,0,0,0,0,0,0,0,0,0,0,0,0,0,0,0,0,0,6,6,6,0,0,0,0,0
0,0,0,0,0,29,6,6,0,0,0,0,0,0,0,0,0,0,0,0,0,0,0,0,0,0,0,0,0,0,0,0,0,6,6,27,0,0,0,0,0
0,0,0,0,0,6,6,6,0,0,0,0,0,0,0,0,0,0,0,0,0,0,0,0,0,0,0,0,0,0,0,0,0,6,6,6,0,0,0,0,0
0,0,0,0,0,29,6,6,0,0,0,0,0,0,0,0,0,0,0,0,0,0,0,0,0,0,0,0,0,0,0,0,0,6,6,27,0,0,0,0,0
0,0,0,0,0,6,6,6,0,0,0,0,0,0,0,0,0,0,0,0,0,0,0,0,0,0,0,0,0,0,0,0,0,6,6,6,0,0,0,0,0
0,0,0,0,0,29,6,6,0,0,0,0,0,0,0,0,0,0,0,0,0,0,0,0,0,0,0,0,0,0,0,0,0,6,6,27,0,0,0,0,0
0,0,0,0,26,6,6,6,0,0,0,0,0,0,0,0,0,0,0,0,0,0,0,0,0,0,0,0,0,0,0,0,0,6,6,6,0,0,0,0,0
0,0,0,26,6,0,6,6,0,0,0,0,0,0,0,0,0,0,0,0,0,0,0,0,0,0,0,0,0,0,0,0,0,6,6,0,6,0,0,0,0
0,0,26,6,6,6,6,6,0,0,0,0,0,0,0,0,0,0,0,0,0,0,0,0,0,0,0,0,0,0,0,0,0,6,6,6,6,6,27,0,0
0,26,6,6,6,6,6,6,0,0,0,0,0,0,0,0,0,0,0,0,0,0,0,0,0,0,0,0,0,0,0,0,0,6,6,6,6,6,6,0,0
29,6,6,6,6,0,0,0,0,0,0,0,0,0,0,0,0,0,0,0,0,0,0,0,0,0,0,0,0,0,0,0,0,0,0,0,6,6,6,6,27
0,0,6,6,0,0,0,0,0,6,6,6,6,6,6,6,6,6,6,6,6,6,6,6,6,6,6,6,6,6,6,6,0,0,0,0,0,6,6,0,0
29,6,6,6,0,0,5,0,0,6,6,6,6,6,6,6,6,6,6,6,6,6,6,6,6,6,6,6,6,6,6,6,0,0,5,0,0,6,6,6,27
0,0,6,6,0,0,15,11,11,6,6,0,6,28,6,28,6,0,21,0,0,0,17,0,6,28,6,28,6,0,6,6,11,11,15,0,0,6,6,0,0
29,6,6,6,6,0,15,11,6,6,6,6,0,0,0,0,29,6,6,0,0,0,6,6,27,0,0,0,0,6,6,6,6,11,15,0,6,6,6,6,27
0,29,6,6,6,6,6,6,6,6,6,0,0,0,0,0,0,0,21,0,0,0,17,0,0,0,0,0,0,0,6,6,6,6,6,6,6,6,6,0,0
0,0,29,6,6,6,6,6,6,6,28,0,0,0,0,0,29,6,6,0,0,0,6,6,27,0,0,0,0,0,0,6,6,6,6,6,6,6,0,0,0
0,0,0,0,6,28,6,28,6,0,0,0,0,0,0,0,0,0,21,0,0,0,17,0,0,0,0,0,0,0,0,0,6,0,6,0,6,0,0,0,0
0,0,0,0,0,0,0,0,0,0,0,0,0,0,0,0,0,6,6,18,18,18,6,6,0,0,0,0,0,0,0,0,28,0,28,0,28,0,0,0,0
0,0,0,0,0,0,0,0,0,0,0,0,0,0,0,0,0,28,6,19,19,19,6,28,0,0,0,0,0,0,0,0,0,0,0,0,0,0,0,0,0
0,0,0,0,0,0,0,0,0,0,0,0,0,0,0,0,0,0,6,0,0,0,6,0,0,0,0,0,0,0,0,0,0,0,0,0,0,0,0,0,0
0,0,0,0,0,0,0,0,0,0,0,0,0,0,0,0,0,0,13,0,0,0,13,0,0,0,0,0,0,0,0,0,0,0,0,0,0,0,0,0,0
0,0,0,0,0,0,0,0,0,0,0,0,0,0,0,0,0,0,0,0,0,0,0,0,0,0,0,0,0,0,0,0,0,0,0,0,0,0,0,0,0
0,0,0,0,0,0,0,0,0,0,0,0,0,0,0,0,0,0,0,0,0,0,0,0,0,0,0,0,0,0,0,0,0,0,0,0,0,0,0,0,0
0,0,0,0,0,0,0,0,0,0,0,0,0,0,0,0,0,0,0,0,0,0,0,0,0,0,0,0,0,0,0,0,0,0,0,0,0,0,0,0,0
0,0,0,0,0,0,0,0,0,0,0,0,0,0,0,0,0,0,0,0,0,0,0,0,0,0,0,0,0,0,0,0,0,0,0,0,0,0,0,0,0
0,0,0,0,0,0,0,0,0,0,0,0,0,0,0,0,0,0,30,0,0,0,30,0,0,0,0,0,0,0,0,0,0,0,0,0,0,0,0,0,0
:endlayer
layer: 6
0,0,0,0,0,0,0,0,0,0,0,0,0,0,0,0,0,0,0,0,0,0,0,0,0,0,0,0,0,0,0,0,0,0,0,0,0,0,0,0,0
0,0,0,0,12,0,12,0,12,0,0,0,0,0,0,0,0,0,0,0,0,0,0,0,0,0,0,0,0,0,0,0,12,0,12,0,12,0,0,0,0
0,0,0,23,6,6,6,6,6,9,0,0,0,0,0,0,0,0,0,0,0,0,0,0,0,0,0,0,0,0,0,23,6,6,6,6,6,9,0,0,0
0,0,12,6,6,6,6,6,6,6,12,0,0,0,0,0,0,0,0,0,0,0,0,0,0,0,0,0,0,0,12,6,6,6,6,6,6,6,12,0,0
0,23,6,6,6,0,0,0,6,6,6,9,0,0,0,0,0,0,0,0,0,0,0,0,0,0,0,0,0,23,6,6,6,0,0,0,6,6,6,9,0
0,0,6,6,0,0,0,0,0,6,6,0,12,0,12,0,12,0,12,0,12,0,12,0,12,0,12,0,12,0,6,6,0,0,0,0,0,6,6,0,0
0,23,6,6,0,0,14,0,0,6,6,6,6,6,6,6,6,6,6,6,6,6,6,6,6,6,6,6,6,6,6,6,0,0,14,0,0,6,6,9,0
0,0,6,6,0,0,15,11,11,6,6,6,6,6,6,6,6,6,6,6,6,6,6,6,6,6,6,6,6,6,6,6,11,11,15,0,0,6,6,0,0
0,23,6,6,6,0,15,11,11,6,0,0,0,0,0,0,0,0,0,0,0,0,0,0,0,0,0,0,0,0,0,6,11,11,15,0,6,6,6,9,0
0,0,13,6,6,6,6,6,6,0,0,0,0,0,0,0,0,0,0,0,0,0,0,0,0,0,0,0,0,0,0,0,6,6,6,6,6,6,13,0,0
0,0,0,23,6,6,6,6,0,0,0,0,0,0,0,0,0,0,0,0,0,0,0,0,0,0,0,0,0,0,0,0,0,6,6,6,6,9,0,0,0
0,0,0,0,13,0,6,6,0,0,0,0,0,0,0,0,0,0,0,0,0,0,0,0,0,0,0,0,0,0,0,0,0,6,6,0,13,0,0,0,0
0,0,0,0,0,23,6,6,0,0,0,0,0,0,0,0,0,0,0,0,0,0,0,0,0,0,0,0,0,0,0,0,0,6,6,9,0,0,0,0,0
0,0,0,0,0,0,6,6,0,0,0,0,0,0,0,0,0,0,0,0,0,0,0,0,0,0,0,0,0,0,0,0,0,6,6,0,0,0,0,0,0
0,0,0,0,0,23,6,6,0,0,0,0,0,0,0,0,0,0,0,0,0,0,0,0,0,0,0,0,0,0,0,0,0,6,6,9,0,0,0,0,0
0,0,0,0,0,0,6,6,0,0,0,0,0,0,0,0,0,0,0,0,0,0,0,0,0,0,0,0,0,0,0,0,0,6,6,0,0,0,0,0,0
0,0,0,0,0,23,6,6,0,0,0,0,0,0,0,0,0,0,0,0,0,0,0,0,0,0,0,0,0,0,0,0,0,6,6,9,0,0,0,0,0
0,0,0,0,0,0,6,6,0,0,0,0,0,0,0,0,0,0,0,0,0,0,0,0,0,0,0,0,0,0,0,0,0,6,6,0,0,0,0,0,0
0,0,0,0,0,23,6,6,0,0,0,0,0,0,0,0,0,0,0,0,0,0,0,0,0,0,0,0,0,0,0,0,0,6,6,9,0,0,0,0,0
0,0,0,0,0,0,6,6,0,0,0,0,0,0,0,0,0,0,0,0,0,0,0,0,0,0,0,0,0,0,0,0,0,6,6,0,0,0,0,0,0
0,0,0,0,0,23,6,6,0,0,0,0,0,0,0,0,0,0,0,0,0,0,0,0,0,0,0,0,0,0,0,0,0,6,6,9,0,0,0,0,0
0,0,0,0,0,0,6,6,0,0,0,0,0,0,0,0,0,0,0,0,0,0,0,0,0,0,0,0,0,0,0,0,0,6,6,0,0,0,0,0,0
0,0,0,0,0,23,6,6,0,0,0,0,0,0,0,0,0,0,0,0,0,0,0,0,0,0,0,0,0,0,0,0,0,6,6,9,0,0,0,0,0
0,0,0,0,0,0,6,6,0,0,0,0,0,0,0,0,0,0,0,0,0,0,0,0,0,0,0,0,0,0,0,0,0,6,6,0,0,0,0,0,0
0,0,0,0,0,23,6,6,0,0,0,0,0,0,0,0,0,0,0,0,0,0,0,0,0,0,0,0,0,0,0,0,0,6,6,9,0,0,0,0,0
0,0,0,0,0,0,6,6,0,0,0,0,0,0,0,0,0,0,0,0,0,0,0,0,0,0,0,0,0,0,0,0,0,6,6,0,0,0,0,0,0
0,0,0,0,0,23,6,6,0,0,0,0,0,0,0,0,0,0,0,0,0,0,0,0,0,0,0,0,0,0,0,0,0,6,6,9,0,0,0,0,0
0,0,0,0,0,0,6,6,0,0,0,0,0,0,0,0,0,0,0,0,0,0,0,0,0,0,0,0,0,0,0,0,0,6,6,0,0,0,0,0,0
0,0,0,0,0,23,6,6,0,0,0,0,0,0,0,0,0,0,0,0,0,0,0,0,0,0,0,0,0,0,0,0,0,6,6,9,0,0,0,0,0
0,0,0,0,12,0,6,6,0,0,0,0,0,0,0,0,0,0,0,0,0,0,0,0,0,0,0,0,0,0,0,0,0,6,6,0,12,0,0,0,0
0,0,0,23,6,6,6,6,0,0,0,0,0,0,0,0,0,0,0,0,0,0,0,0,0,0,0,0,0,0,0,0,0,6,6,6,6,9,0,0,0
0,0,12,6,6,6,6,6,6,0,0,0,0,0,0,0,0,0,0,0,0,0,0,0,0,0,0,0,0,0,0,0,6,6,6,6,6,6,12,0,0
0,23,6,6,6,0,0,11,11,6,0,0,0,0,0,0,0,0,0,0,0,0,0,0,0,0,0,0,0,0,0,6,15,11,0,0,6,6,6,9,0
0,0,6,6,0,0,0,11,11,6,6,6,6,6,6,6,6,6,6,6,6,6,6,6,6,6,6,6,6,6,6,6,15,11,0,0,0,6,6,0,0
0,23,6,6,0,0,14,15,15,6,6,6,6,6,6,6,6,6,6,6,6,6,6,6,6,6,6,6,6,6,6,6,15,15,14,0,0,6,6,9,0
0,0,6,6,0,0,0,0,0,6,6,0,13,0,13,0,13,0,23,0,0,0,9,0,13,0,13,0,13,0,6,6,0,0,0,0,0,6,6,0,0
0,23,6,6,6,0,0,0,6,6,6,9,0,0,0,0,0,23,6,0,0,0,6,9,0,0,0,0,0,23,6,6,6,0,0,0,6,6,6,9,0
0,0,13,6,6,6,6,6,6,6,13,0,0,0,0,0,0,0,23,0,0,0,9,0,0,0,0,0,0,0,13,6,6,6,6,6,6,6,13,0,0
0,0,0,23,6,6,6,6,6,9,0,0,0,0,0,0,0,23,6,0,0,0,6,9,0,0,0,0,0,0,0,23,6,6,6,6,6,9,0,0,0
0,0,0,0,13,0,13,0,13,0,0,0,0,0,0,0,0,0,23,18,18,18,9,0,0,0,0,0,0,0,0,0,13,0,13,0,13,0,0,0,0
0,0,0,0,0,0,0,0,0,0,0,0,0,0,0,0,0,23,6,19,19,19,6,9,0,0,0,0,0,0,0,0,0,0,0,0,0,0,0,0,0
0,0,0,0,0,0,0,0,0,0,0,0,0,0,0,0,0,0,6,0,0,0,6,0,0,0,0,0,0,0,0,0,0,0,0,0,0,0,0,0,0
0,0,0,0,0,0,0,0,0,0,0,0,0,0,0,0,0,0,13,0,0,0,13,0,0,0,0,0,0,0,0,0,0,0,0,0,0,0,0,0,0
0,0,0,0,0,0,0,0,0,0,0,0,0,0,0,0,0,0,0,0,0,0,0,0,0,0,0,0,0,0,0,0,0,0,0,0,0,0,0,0,0
0,0,0,0,0,0,0,0,0,0,0,0,0,0,0,0,0,0,0,0,0,0,0,0,0,0,0,0,0,31,0,0,0,0,0,0,0,0,0,0,0
0,0,0,0,0,0,0,0,0,0,0,0,0,0,0,0,0,0,0,0,0,0,0,0,0,0,0,0,0,0,0,0,0,0,0,0,0,0,0,0,0
0,0,0,0,0,0,0,0,0,0,0,0,0,0,0,0,0,0,0,0,0,0,0,0,0,0,0,0,0,0,0,0,0,0,0,0,0,0,0,0,0
0,0,0,0,0,0,0,0,0,0,0,0,0,0,0,0,0,0,0,0,0,0,0,0,0,0,0,0,0,0,0,0,0,0,0,0,0,0,0,0,0
0,0,0,0,0,0,0,0,0,0,0,0,0,0,0,0,0,0,0,0,0,0,0,0,0,0,0,0,0,0,0,0,0,0,0,0,0,0,0,0,0
:endlayer
layer: 7
0,0,0,0,0,0,0,0,0,0,0,0,0,0,0,0,0,0,0,0,0,0,0,0,0,0,0,0,0,0,0,0,0,0,0,0,0,0,0,0,0
0,0,0,0,32,32,32,32,32,0,0,0,0,0,0,0,0,0,0,0,0,0,0,0,0,0,0,0,0,0,0,0,32,32,32,32,32,0,0,0,0
0,0,0,32,6,6,6,6,6,32,0,0,0,0,0,0,0,0,0,0,0,0,0,0,0,0,0,0,0,0,0,32,6,6,6,6,6,32,0,0,0
0,0,32,6,6,6,6,6,6,6,32,0,0,0,0,0,0,0,0,0,0,0,0,0,0,0,0,0,0,0,32,6,6,6,6,6,6,6,32,0,0
0,32,6,6,6,0,0,11,6,6,6,32,0,0,0,0,0,0,0,0,0,0,0,0,0,0,0,0,0,32,6,6,6,11,0,0,6,6,6,32,0
0,32,6,6,0,0,0,11,11,6,6,32,32,32,0,0,0,32,32,32,0,32,32,32,0,0,0,32,32,32,6,6,11,11,0,0,0,6,6,32,0
0,32,6,6,0,0,14,15,15,6,6,6,6,6,6,6,6,6,6,6,6,6,6,6,6,6,6,6,6,6,6,6,15,15,14,0,0,6,6,32,0
0,32,6,6,0,0,0,0,0,6,6,6,6,6,6,6,6,6,6,6,6,6,6,6,6,6,6,6,6,6,6,6,0,0,0,0,0,6,6,32,0
0,32,6,6,6,0,0,0,0,6,0,0,0,0,0,0,0,0,0,0,0,0,0,0,0,0,0,0,0,0,0,6,0,0,0,0,6,6,6,32,0
0,0,32,6,6,6,6,6,6,0,0,0,0,0,0,0,0,0,0,0,0,0,0,0,0,0,0,0,0,0,0,0,6,6,6,6,6,6,32,0,0
0,0,0,32,6,6,6,6,0,0,0,0,0,0,0,0,0,0,0,0,0,0,0,0,0,0,0,0,0,0,0,0,0,6,6,6,6,32,0,0,0
0,0,0,0,32,32,6,6,0,0,0,0,0,0,0,0,0,0,0,0,0,0,0,0,0,0,0,0,0,0,0,0,0,6,6,32,32,0,0,0,0
0,0,0,0,0,32,6,6,0,0,0,0,0,0,0,0,0,0,0,0,0,0,0,0,0,0,0,0,0,0,0,0,0,6,6,32,0,0,0,0,0
0,0,0,0,0,32,6,6,0,0,0,0,0,0,0,0,0,0,0,0,0,0,0,0,0,0,0,0,0,0,0,0,0,6,6,32,0,0,0,0,0
0,0,0,0,0,0,6,6,0,0,0,0,0,0,0,0,0,0,0,0,0,0,0,0,0,0,0,0,0,0,0,0,0,6,6,0,0,0,0,0,0
0,0,0,0,0,0,6,6,0,0,0,0,0,0,0,0,0,0,0,0,0,0,0,0,0,0,0,0,0,0,0,0,0,6,6,0,0,0,0,0,0
0,0,0,0,0,0,6,6,0,0,0,0,0,0,0,0,0,0,0,0,0,0,0,0,0,0,0,0,0,0,0,0,0,6,6,0,0,0,0,0,0
0,0,0,0,0,32,6,6,0,0,0,0,0,0,0,0,0,0,0,0,0,0,0,0,0,0,0,0,0,0,0,0,0,6,6,32,0,0,0,0,0
0,0,0,0,0,32,6,6,0,0,0,0,0,0,0,0,0,0,0,0,0,0,0,0,0,0,0,0,0,0,0,0,0,6,6,32,0,0,0,0,0
0,0,0,0,0,32,6,6,0,0,0,0,0,0,0,0,0,0,0,0,0,0,0,0,0,0,0,0,0,0,0,0,0,6,6,32,0,0,0,0,0
0,0,0,0,0,0,6,6,0,0,0,0,0,0,0,0,0,0,0,0,0,0,0,0,0,0,0,0,0,0,0,0,0,6,6,0,0,0,0,0,0
0,0,0,0,0,32,6,6,0,0,0,0,0,0,0,0,0,0,0,0,0,0,0,0,0,0,0,0,0,0,0,0,0,6,6,32,0,0,0,0,0
0,0,0,0,0,32,6,6,0,0,0,0,0,0,0,0,0,0,0,0,0,0,0,0,0,0,0,0,0,0,0,0,0,6,6,32,0,0,0,0,0
0,0,0,0,0,32,6,6,0,0,0,0,0,0,0,0,0,0,0,0,0,0,0,0,0,0,0,0,0,0,0,0,0,6,6,32,0,0,0,0,0
0,0,0,0,0,0,6,6,0,0,0,0,0,0,0,0,0,0,0,0,0,0,0,0,0,0,0,0,0,0,0,0,0,6,6,0,0,0,0,0,0
0,0,0,0,0,0,6,6,0,0,0,0,0,0,0,0,0,0,0,0,0,0,0,0,0,0,0,0,0,0,0,0,0,6,6,0,0,0,0,0,0
0,0,0,0,0,0,6,6,0,0,0,0,0,0,0,0,0,0,0,0,0,0,0,0,0,0,0,0,0,0,0,0,0,6,6,0,0,0,0,0,0
0,0,0,0,0,32,6,6,0,0,0,0,0,0,0,0,0,0,0,0,0,0,0,0,0,0,0,0,0,0,0,0,0,6,6,32,0,0,0,0,0
0,0,0,0,0,32,6,6,0,0,0,0,0,0,0,0,0,0,0,0,0,0,0,0,0,0,0,0,0,0,0,0,0,6,6,32,0,0,0,0,0
0,0,0,0,32,32,6,6,0,0,0,0,0,0,0,0,0,0,0,0,0,0,0,0,0,0,0,0,0,0,0,0,0,6,6,32,32,0,0,0,0
0,0,0,32,6,6,6,6,0,0,0,0,0,0,0,0,0,0,0,0,0,0,0,0,0,0,0,0,0,0,0,0,0,6,6,6,6,32,0,0,0
0,0,32,6,6,6,6,6,6,0,0,0,0,0,0,0,0,0,0,0,0,0,0,0,0,0,0,0,0,0,0,0,6,6,6,6,6,6,32,0,0
0,32,6,6,6,11,15,0,0,6,0,0,0,0,0,0,0,0,0,0,0,0,0,0,0,0,0,0,0,0,0,6,0,0,15,11,6,6,6,32,0
0,32,6,6,11,11,15,0,0,6,6,6,6,6,6,6,6,6,6,6,6,6,6,6,6,6,6,6,6,6,6,6,0,0,15,11,11,6,6,32,0
0,32,6,6,0,0,14,0,0,6,6,6,6,6,6,6,6,6,6,6,6,6,6,6,6,6,6,6,6,6,6,6,0,0,14,0,0,6,33,32,0
0,32,6,6,0,0,0,0,0,6,6,32,32,32,0,0,0,0,6,0,0,0,6,0,0,0,0,32,32,32,6,6,0,0,0,0,0,6,6,32,0
0,32,6,6,6,0,0,0,6,6,6,32,0,0,0,0,0,0,21,0,0,0,17,0,0,0,0,0,0,32,6,6,6,0,0,0,6,6,6,32,0
0,0,32,6,6,6,6,6,6,6,32,0,0,0,0,0,0,0,6,0,0,0,6,0,0,0,0,0,0,0,32,6,6,6,6,6,6,6,32,0,0
0,0,0,32,6,6,6,6,6,32,0,0,0,0,0,0,0,0,21,18,18,18,17,0,0,0,0,0,0,0,0,32,6,6,33,6,6,32,0,0,0
0,0,0,0,32,32,32,32,32,0,0,0,0,0,0,0,0,0,6,19,19,19,6,0,0,0,0,0,0,0,0,0,32,32,32,32,32,0,0,0,0
0,0,0,0,0,0,0,0,0,0,0,0,0,0,0,0,0,0,6,0,0,0,6,0,0,0,0,0,0,0,0,0,0,0,0,0,0,0,0,0,0
0,0,0,0,0,0,0,0,0,0,0,0,0,0,0,0,0,0,13,0,0,0,13,0,0,0,0,0,0,0,0,0,0,0,0,0,0,0,0,0,0
0,0,0,0,0,0,0,0,0,0,0,0,0,0,0,0,0,0,0,0,0,0,0,0,0,0,0,0,0,0,0,0,0,0,0,0,0,0,0,0,0
0,0,0,0,0,0,0,0,0,0,0,0,0,0,0,0,0,0,0,0,0,0,0,0,0,0,0,0,0,0,0,0,0,0,0,0,0,0,0,0,0
0,0,0,0,0,0,0,0,0,0,0,0,0,0,0,0,0,0,0,0,0,0,0,0,0,0,0,0,0,0,0,0,0,0,0,0,0,0,0,0,0
0,0,0,0,0,0,0,0,0,0,0,0,0,0,0,0,0,0,0,0,0,0,0,0,0,0,0,0,0,0,0,0,0,0,0,0,0,0,0,0,0
0,0,0,0,0,0,0,0,0,0,0,0,0,0,0,0,0,0,0,0,0,0,0,0,0,0,0,0,0,0,0,0,0,0,0,0,0,0,0,0,0
0,0,0,0,0,0,0,0,0,0,0,0,0,0,0,0,0,0,0,0,0,0,0,0,0,0,0,0,0,0,0,0,0,0,0,0,0,0,0,0,0
0,0,0,0,0,0,0,0,0,0,0,0,0,0,0,0,0,0,0,0,0,0,0,0,0,0,0,0,0,0,0,0,0,0,0,0,0,0,0,0,0
:endlayer
layer: 8
0,0,0,0,0,0,0,0,0,0,0,0,0,0,0,0,0,0,0,0,0,0,0,0,0,0,0,0,0,0,0,0,0,0,0,0,0,0,0,0,0
0,0,0,0,32,32,32,32,32,0,0,0,0,0,0,0,0,0,0,0,0,0,0,0,0,0,0,0,0,0,0,0,32,32,32,32,32,0,0,0,0
0,0,0,32,6,6,33,6,6,32,0,0,0,0,0,0,0,0,0,0,0,0,0,0,0,0,0,0,0,0,0,32,6,6,33,6,6,32,0,0,0
0,0,32,6,6,6,6,6,6,6,32,0,0,0,0,0,0,0,0,0,0,0,0,0,0,0,0,0,0,0,32,6,6,6,6,6,6,6,32,0,0
0,32,6,6,6,11,15,0,6,6,6,32,0,0,0,0,0,0,0,0,0,0,0,0,0,0,0,0,0,32,6,6,6,0,15,11,6,6,6,32,0
0,32,6,6,11,11,15,0,0,6,6,32,32,32,30,30,30,32,32,32,30,32,32,32,30,30,30,32,32,32,6,6,0,0,15,11,11,6,6,32,0
0,32,33,6,11,11,14,0,0,6,6,6,6,6,6,6,6,6,6,6,6,6,6,6,6,6,6,6,6,6,6,6,0,0,5,0,0,6,33,32,0
0,32,6,6,11,0,0,0,0,6,6,6,6,6,6,6,6,6,6,6,6,6,6,6,6,6,6,6,6,6,6,6,0,0,0,0,0,6,6,32,0
0,32,6,6,6,0,0,0,0,6,11,11,11,11,11,11,11,11,11,11,11,11,11,11,11,11,11,11,11,11,11,6,0,0,0,0,6,6,6,32,0
0,0,32,6,6,6,6,6,6,11,11,11,11,11,11,11,11,11,11,11,11,11,11,11,11,11,11,11,11,11,11,11,6,6,6,6,6,6,32,0,0
0,0,0,32,6,6,6,6,11,11,11,11,11,5,11,11,11,11,11,11,11,11,11,11,11,11,11,5,11,11,11,11,11,6,6,6,6,32,0,0,0
0,0,0,0,32,32,6,6,11,11,11,11,11,11,11,11,11,11,11,11,11,11,11,11,11,11,11,11,11,11,11,11,11,6,6,32,32,0,0,0,0
0,0,0,0,0,32,6,6,11,11,11,11,11,11,11,11,11,11,11,11,11,11,11,11,11,11,11,11,11,11,11,11,11,6,6,32,0,0,0,0,0
0,0,0,0,0,32,6,6,11,11,11,11,11,11,11,11,11,11,11,11,11,11,11,11,11,11,11,11,11,11,11,11,11,6,6,32,0,0,0,0,0
0,0,0,0,0,30,6,6,11,11,11,11,11,11,11,11,11,11,11,11,5,11,11,11,11,11,11,11,11,11,11,11,11,6,6,30,0,0,0,0,0
0,0,0,0,0,30,6,6,11,11,11,11,11,11,11,11,11,11,11,11,11,11,11,11,11,11,11,11,11,11,11,11,11,6,6,30,0,0,0,0,0
0,0,0,0,0,30,6,6,11,11,11,11,11,11,11,11,11,11,11,11,11,11,11,11,11,11,11,11,11,11,11,11,11,6,6,30,0,0,0,0,0
0,0,0,0,0,32,6,6,11,11,11,11,11,11,11,11,11,11,11,11,11,11,11,11,11,11,11,11,11,11,11,11,11,6,6,32,0,0,0,0,0
0,0,0,0,0,32,6,6,11,11,11,11,11,11,11,11,11,11,11,11,11,11,11,11,11,11,11,11,11,11,11,11,11,6,6,32,0,0,0,0,0
0,0,0,0,0,32,6,6,11,11,11,11,11,11,11,11,11,11,11,11,11,11,11,11,11,11,11,11,11,11,11,11,11,6,6,32,0,0,0,0,0
0,0,0,0,0,30,6,6,11,11,11,11,11,11,11,5,11,11,11,11,11,11,11,11,11,5,11,11,11,11,11,11,11,6,6,30,0,0,0,0,0
0,0,0,0,0,32,6,6,11,11,11,11,11,11,11,11,11,11,11,11,11,11,11,11,11,11,11,11,11,11,11,11,11,6,6,32,0,0,0,0,0
0,0,0,0,0,32,6,6,11,11,11,11,11,11,11,11,11,11,11,11,11,11,11,11,11,11,11,11,11,11,11,11,11,6,6,32,0,0,0,0,0
0,0,0,0,0,32,6,6,11,11,11,11,11,11,11,11,11,11,11,11,11,11,11,11,11,11,11,11,11,11,11,11,11,6,6,32,0,0,0,0,0
0,0,0,0,0,30,6,6,11,11,11,11,11,11,11,11,11,11,11,11,5,11,11,11,11,11,11,11,11,11,11,11,11,6,6,30,0,0,0,0,0
0,0,0,0,0,30,6,6,11,11,11,11,11,11,11,11,11,11,11,11,11,11,11,11,11,11,11,11,11,11,11,11,11,6,6,30,0,0,0,0,0
0,0,0,0,0,30,6,6,11,11,11,11,11,11,11,11,11,11,11,11,11,11,11,11,11,11,11,11,11,11,11,11,11,6,6,30,0,0,0,0,0
0,0,0,0,0,32,6,6,11,11,11,11,11,11,11,11,11,11,11,11,11,11,11,11,11,11,11,11,11,11,11,11,11,6,6,32,0,0,0,0,0
0,0,0,0,0,32,6,6,11,11,11,11,11,11,11,11,11,11,11,11,11,11,11,11,11,11,11,11,11,11,11,11,11,6,6,32,0,0,0,0,0
0,0,0,0,32,32,6,6,11,11,11,11,11,11,11,11,11,11,11,11,11,11,11,11,11,11,11,11,11,11,11,11,11,6,6,32,32,0,0,0,0
0,0,0,32,6,6,6,6,11,11,11,11,11,11,5,11,11,11,11,11,11,11,11,11,11,11,5,11,11,11,11,11,11,6,6,6,6,32,0,0,0
0,0,32,6,6,6,6,6,6,11,11,11,11,11,11,11,11,11,11,11,11,11,11,11,11,11,11,11,11,11,11,11,6,6,6,6,6,6,32,0,0
0,32,6,6,6,0,0,0,0,6,11,11,11,11,11,11,11,11,11,11,11,11,11,11,11,11,11,11,11,11,11,6,0,0,0,0,6,6,6,32,0
0,32,6,6,0,0,0,0,0,6,6,6,6,6,6,6,6,6,6,11,11,11,6,6,6,6,6,6,6,6,6,6,0,0,0,0,0,6,6,32,0
0,32,33,6,15,15,14,0,0,6,6,6,6,6,6,6,6,6,6,11,11,11,6,6,6,6,6,6,6,6,6,6,0,0,14,15,15,6,33,32,0
0,32,6,6,11,11,11,0,0,6,6,32,32,32,30,30,30,30,6,11,11,11,6,30,30,30,30,32,32,32,6,6,0,0,11,11,11,6,6,32,0
0,32,6,6,6,11,11,11,6,6,6,32,0,0,0,0,0,32,6,11,11,11,6,32,0,0,0,0,0,32,6,6,6,11,11,11,6,6,6,32,0
0,0,32,6,6,6,6,6,6,6,32,0,0,0,0,0,0,30,6,11,11,11,6,30,0,0,0,0,0,0,32,6,6,6,6,6,6,6,32,0,0
0,0,0,32,6,6,33,6,6,32,0,0,0,0,0,0,0,30,6,19,19,19,6,30,0,0,0,0,0,0,0,32,6,6,33,6,6,32,0,0,0
0,0,0,0,32,32,32,32,32,0,0,0,0,0,0,0,0,30,6,0,0,0,6,30,0,0,0,0,0,0,0,0,32,32,32,32,32,0,0,0,0
0,0,0,0,0,0,0,0,0,0,0,0,0,0,0,0,0,0,13,0,0,0,13,0,0,0,0,0,0,0,0,0,0,0,0,0,0,0,0,0,0
0,0,0,0,0,0,0,0,0,0,0,0,0,0,0,0,0,0,0,0,0,0,0,0,0,0,0,0,0,0,0,0,0,0,0,0,0,0,0,0,0
0,0,0,0,0,0,0,0,0,0,0,0,0,0,0,0,0,0,0,0,0,0,0,0,0,0,0,0,0,0,0,0,0,0,0,0,0,0,0,0,0
0,0,0,0,0,0,0,0,0,0,0,0,0,0,0,0,0,0,0,0,0,0,0,0,0,0,0,0,0,0,0,0,0,0,0,0,0,0,0,0,0
0,0,0,0,0,0,0,0,0,0,0,0,0,0,0,0,0,0,0,0,0,0,0,0,0,0,0,0,0,0,0,0,0,0,0,0,0,0,0,0,0
0,0,0,0,0,0,0,0,0,0,0,0,0,0,0,0,0,0,0,0,0,0,0,0,0,0,0,0,0,0,0,0,0,0,0,0,0,0,0,0,0
0,0,0,0,0,0,0,0,0,0,0,0,0,0,0,0,0,0,0,0,0,0,0,0,0,0,0,0,0,0,0,0,0,0,0,0,0,0,0,0,0
0,0,0,0,0,0,0,0,0,0,0,0,0,0,0,0,0,0,0,0,0,0,0,0,0,0,0,0,0,0,0,0,0,0,0,0,0,0,0,0,0
0,0,0,0,0,0,0,0,0,0,0,0,0,0,0,0,0,0,0,0,0,0,0,0,0,0,0,0,0,0,0,0,0,0,0,0,0,0,0,0,0
:endlayer
layer: 9
0,0,0,0,0,0,0,0,0,0,0,0,0,0,0,0,0,0,0,0,0,0,0,0,0,0,0,0,0,0,0,0,0,0,0,0,0,0,0,0,0
0,0,0,0,0,0,0,0,0,0,0,0,0,0,0,0,0,0,0,0,0,0,0,0,0,0,0,0,0,0,0,0,0,0,0,0,0,0,0,0,0
0,0,0,21,6,9,34,23,6,17,0,0,0,0,0,0,0,0,0,0,0,0,0,0,0,0,0,0,0,0,0,21,6,9,34,23,6,17,0,0,0
0,0,34,6,6,6,6,6,6,6,34,0,0,0,0,0,0,0,0,0,0,0,0,0,0,0,0,0,0,0,34,6,6,6,6,6,6,6,34,0,0
0,0,6,6,6,0,0,0,6,6,6,0,0,0,0,0,0,0,0,0,0,0,0,0,0,0,0,0,0,0,6,6,6,0,0,0,6,6,6,0,0
0,0,13,6,0,0,0,0,0,6,13,0,0,0,30,30,30,0,0,0,30,0,0,0,30,30,30,0,0,0,13,6,0,0,0,0,0,6,13,0,0
0,0,21,6,15,15,5,0,0,6,6,37,37,37,6,6,6,37,37,37,33,37,37,37,6,6,6,37,37,37,6,6,0,0,14,15,15,6,17,0,0
0,0,12,6,11,11,36,0,0,6,6,6,6,6,6,6,6,6,6,6,6,6,6,6,6,6,6,6,6,6,6,6,0,0,0,11,11,6,12,0,0
0,0,6,6,6,11,36,0,0,6,6,15,0,0,0,38,44,39,39,39,39,39,39,39,43,38,0,0,0,0,15,6,36,0,36,11,6,6,6,0,0
0,0,35,6,6,6,6,6,6,38,15,0,0,0,0,0,44,39,39,39,39,39,39,39,43,0,0,0,0,0,0,38,6,6,6,6,6,6,35,0,0
0,0,0,21,6,9,6,6,6,15,0,0,0,0,0,0,44,39,39,39,39,39,39,39,43,0,0,0,0,0,0,0,15,6,6,23,6,17,0,0,0
0,0,0,0,0,0,37,6,15,0,0,0,0,0,0,0,44,39,39,39,39,39,39,39,43,0,0,0,0,0,0,0,0,6,37,0,0,0,0,0,0
0,0,0,0,0,0,37,6,0,0,0,0,0,40,0,0,6,41,41,41,41,41,41,41,6,0,0,40,0,0,0,0,0,6,37,0,0,0,0,0,0
0,0,0,0,0,0,37,6,0,0,0,0,39,39,39,0,0,42,42,42,42,42,42,42,0,0,39,39,39,0,0,0,0,6,37,0,0,0,0,0,0
0,0,0,0,0,30,6,6,0,0,0,0,39,39,39,39,43,42,45,45,45,45,45,42,44,39,39,39,39,0,0,0,0,6,6,30,0,0,0,0,0
0,0,0,0,0,30,6,6,38,0,0,0,39,39,39,39,43,42,45,46,46,46,45,42,44,39,39,39,39,0,0,0,38,6,6,30,0,0,0,0,0
0,0,0,0,0,30,6,6,0,0,0,0,39,39,39,39,43,42,45,46,46,46,45,42,44,39,39,39,39,0,0,0,0,6,6,30,0,0,0,0,0
0,0,0,0,0,0,37,6,0,0,0,0,39,39,39,39,43,42,45,46,46,46,45,42,44,39,39,39,39,0,0,0,0,6,37,0,0,0,0,0,0
0,0,0,0,0,0,37,6,0,0,0,0,39,39,39,5,43,42,45,46,47,46,45,42,44,5,39,39,39,0,0,0,0,6,37,0,0,0,0,0,0
0,0,0,0,0,0,37,6,0,0,0,0,39,39,39,39,43,42,45,46,46,46,45,42,44,39,39,39,39,0,0,0,0,6,37,0,0,0,0,0,0
0,0,0,0,0,30,33,6,38,0,0,0,39,39,39,39,43,42,45,46,46,46,45,42,44,39,39,39,39,0,0,0,38,6,33,30,0,0,0,0,0
0,0,0,0,0,0,37,6,0,0,0,0,39,39,39,39,43,42,45,46,46,46,45,42,44,39,39,39,39,0,0,0,0,6,37,0,0,0,0,0,0
0,0,0,0,0,0,37,6,0,0,0,0,39,39,39,39,43,42,45,45,45,45,45,42,44,39,39,39,39,0,0,0,0,6,37,0,0,0,0,0,0
0,0,0,0,0,0,37,6,0,0,0,0,39,39,39,39,43,42,42,42,42,42,42,42,44,39,39,39,39,0,0,0,0,6,37,0,0,0,0,0,0
0,0,0,0,0,30,6,6,0,0,0,0,39,39,39,41,39,42,42,42,42,42,42,42,39,41,39,39,39,0,0,0,0,6,6,30,0,0,0,0,0
0,0,0,0,0,30,6,6,38,0,0,0,0,41,42,42,42,42,42,42,42,42,42,42,42,42,42,41,0,0,0,0,38,6,6,30,0,0,0,0,0
0,0,0,0,0,30,6,6,6,0,0,0,6,0,6,6,6,6,6,42,42,42,6,6,6,6,6,0,6,0,0,0,6,6,6,30,0,0,0,0,0
0,0,0,0,0,0,37,6,0,0,0,0,0,0,0,0,0,0,33,42,42,42,33,0,0,0,0,0,0,0,0,0,0,6,37,0,0,0,0,0,0
0,0,0,0,0,0,37,6,0,0,0,0,0,0,0,0,0,0,0,0,0,0,0,0,0,0,0,0,0,0,0,0,0,6,37,0,0,0,0,0,0
0,0,0,0,0,0,37,6,0,0,0,0,0,0,0,0,0,0,0,0,0,0,0,0,0,0,0,0,0,0,0,0,0,6,37,0,0,0,0,0,0
0,0,0,21,6,9,6,6,15,0,0,0,0,0,0,0,0,0,0,0,0,0,0,0,0,0,0,0,0,0,0,0,15,6,6,23,6,17,0,0,0
0,0,34,6,6,6,6,6,6,15,0,0,0,0,0,0,0,0,0,0,0,0,0,0,0,0,0,0,0,0,0,15,6,6,6,6,6,6,34,0,0
0,0,6,6,6,0,0,0,36,6,15,0,0,0,0,0,0,0,0,6,48,6,0,0,0,0,0,0,0,0,15,6,36,0,0,0,6,6,6,0,0
0,0,13,6,0,0,0,0,0,6,6,6,6,6,6,6,6,6,6,0,0,0,6,6,6,6,6,6,6,6,6,6,0,0,0,0,0,6,13,0,0
0,0,21,6,0,0,5,36,36,6,6,37,37,37,6,6,6,37,6,0,0,0,6,37,6,6,6,37,37,37,6,6,36,36,5,0,0,6,17,0,0
0,0,12,6,0,0,15,11,11,6,12,0,0,0,30,30,30,30,6,0,0,0,6,30,30,30,30,0,0,0,12,6,11,11,15,0,0,6,12,0,0
0,0,6,6,6,0,15,11,6,6,6,0,0,0,0,0,0,32,6,0,0,0,6,32,0,0,0,0,0,0,6,6,6,11,15,0,6,6,6,0,0
0,0,35,6,6,6,6,6,6,6,35,0,0,0,0,0,0,30,6,0,0,0,6,30,0,0,0,0,0,0,35,6,6,6,6,6,6,6,35,0,0
0,0,0,21,6,9,35,23,6,17,0,0,0,0,0,0,0,30,6,0,0,0,6,30,0,0,0,0,0,0,0,21,6,9,35,23,6,17,0,0,0
0,0,0,0,0,0,0,0,0,0,0,0,0,0,0,0,0,0,13,0,0,0,13,0,0,0,0,0,0,0,0,0,0,0,0,0,0,0,0,0,0
0,0,0,0,0,0,0,0,0,0,0,0,0,0,0,0,0,0,0,0,0,0,0,0,0,0,0,0,0,0,0,0,0,0,0,0,0,0,0,0,0
0,0,0,0,0,0,0,0,0,0,0,0,0,0,0,0,0,0,0,0,0,0,0,0,0,0,0,0,0,0,0,0,0,0,0,0,0,0,0,0,0
0,0,0,0,0,0,0,0,0,0,0,0,0,0,0,0,0,0,0,0,0,0,0,0,0,0,0,0,0,0,0,0,0,0,0,0,0,0,0,0,0
0,0,0,0,0,0,0,0,0,0,0,0,0,0,0,0,0,0,0,0,0,0,0,0,0,0,0,0,0,0,0,0,0,0,0,0,0,0,0,0,0
0,0,0,0,0,0,0,0,0,0,0,0,0,0,0,0,0,0,0,0,0,0,0,0,0,0,0,0,0,0,0,0,0,0,0,0,0,0,0,0,0
0,0,0,0,0,0,0,0,0,0,0,0,0,0,0,0,0,0,0,0,0,0,0,0,0,0,0,0,0,0,0,0,0,0,0,0,0,0,0,0,0
0,0,0,0,0,0,0,0,0,0,0,0,0,0,0,0,0,0,0,0,0,0,0,0,0,0,0,0,0,0,0,0,0,0,0,0,0,0,0,0,0
0,0,0,0,0,0,0,0,0,0,0,0,0,0,0,0,0,0,0,0,0,0,0,0,0,0,0,0,0,0,0,0,0,0,0,0,0,0,0,0,0
0,0,0,0,0,0,0,0,0,0,0,0,0,0,0,0,0,0,0,0,0,0,0,0,0,0,0,0,0,0,0,0,0,0,0,0,0,0,0,0,0
:endlayer
layer: 10
0,0,0,0,0,0,0,0,0,0,0,0,0,0,0,0,0,0,0,0,0,0,0,0,0,0,0,0,0,0,0,0,0,0,0,0,0,0,0,0,0
0,0,0,0,0,0,0,0,0,0,0,0,0,0,0,0,0,0,0,0,0,0,0,0,0,0,0,0,0,0,0,0,0,0,0,0,0,0,0,0,0
0,0,0,23,6,34,0,34,6,9,0,0,0,0,0,0,0,0,0,0,0,0,0,0,0,0,0,0,0,0,0,23,6,34,0,34,6,9,0,0,0
0,0,12,6,6,6,49,6,6,6,12,0,0,0,0,0,0,0,0,0,0,0,0,0,0,0,0,0,0,0,12,6,6,6,49,6,6,6,12,0,0
0,0,6,6,6,0,0,29,6,6,6,27,0,0,0,0,0,0,0,0,0,0,0,0,0,0,0,0,0,29,6,6,6,27,0,0,6,6,6,0,0
0,0,21,6,0,0,0,0,0,6,17,0,0,0,0,0,0,0,0,0,26,0,0,0,0,0,0,0,0,0,21,6,0,0,0,0,0,6,17,0,0
0,0,0,49,0,0,14,36,36,6,6,21,50,17,23,34,9,21,50,17,33,21,50,17,23,34,9,34,50,17,6,6,36,36,14,0,0,49,0,0,0
0,0,21,6,0,0,15,11,11,6,6,6,6,6,6,6,6,6,6,6,6,6,6,6,6,6,6,6,6,6,6,6,11,11,15,0,0,6,17,0,0
0,0,6,6,6,0,15,11,11,15,0,0,0,0,0,38,0,52,0,0,54,0,0,52,0,38,0,0,0,0,0,0,15,11,15,0,6,6,6,0,0
0,0,13,6,6,6,6,6,15,38,0,0,0,0,0,0,0,45,45,0,55,0,45,45,0,0,0,0,0,0,0,38,0,6,6,6,6,6,13,0,0
0,0,0,23,6,35,6,6,0,0,0,0,0,0,0,0,0,45,45,0,0,0,45,45,0,0,0,0,0,0,0,0,0,6,6,35,6,9,0,0,0
0,0,0,0,28,0,34,6,0,0,0,0,0,0,0,0,0,45,45,53,53,53,45,45,0,0,0,0,0,0,0,0,0,6,34,0,28,0,0,0,0
0,0,0,0,0,0,50,6,0,0,0,0,0,0,0,0,52,0,0,0,0,0,0,0,52,0,0,0,0,0,0,0,0,6,50,0,0,0,0,0,0
0,0,0,0,0,0,21,6,0,0,0,0,39,40,39,0,0,0,0,0,0,0,0,0,0,0,39,40,39,0,0,0,0,6,35,0,0,0,0,0,0
0,0,0,0,0,0,12,6,0,0,0,0,39,39,43,42,0,0,0,0,0,0,0,0,0,42,44,39,39,0,0,0,0,6,12,0,0,0,0,0,0
0,0,0,0,0,0,21,6,5,0,0,0,39,39,43,42,0,0,0,0,0,0,0,0,0,42,44,39,39,0,0,0,5,6,17,0,0,0,0,0,0
0,0,0,0,0,0,13,6,0,0,0,0,39,39,43,42,0,0,0,0,0,0,0,0,0,42,44,39,39,0,0,0,0,6,13,0,0,0,0,0,0
0,0,0,0,0,0,34,6,0,0,0,0,39,39,43,42,0,0,0,0,0,0,0,0,0,42,44,39,39,0,0,0,0,6,34,0,0,0,0,0,0
0,0,0,0,0,0,50,6,0,0,0,0,39,39,43,57,0,0,0,0,0,0,0,0,0,0,44,39,39,0,0,0,0,6,50,0,0,0,0,0,0
0,0,0,0,0,0,35,6,0,0,0,0,39,39,43,42,0,0,0,0,0,0,0,0,0,42,44,39,39,0,0,0,0,6,35,0,0,0,0,0,0
0,0,0,0,0,29,33,6,5,0,0,0,39,39,43,42,0,0,0,0,0,0,0,0,0,42,44,39,39,0,0,0,5,6,33,27,0,0,0,0,0
0,0,0,0,0,0,34,6,0,0,0,0,39,39,43,42,0,0,0,0,0,0,0,0,0,42,44,39,39,0,0,0,0,6,34,0,0,0,0,0,0
0,0,0,0,0,0,50,6,0,0,0,0,39,39,43,42,0,0,0,0,0,0,0,0,0,42,44,39,39,0,0,0,0,6,50,0,0,0,0,0,0
0,0,0,0,0,0,35,6,0,0,0,0,39,39,43,42,0,0,0,0,0,0,0,0,0,42,44,39,39,0,0,0,0,6,35,0,0,0,0,0,0
0,0,0,0,0,0,12,6,0,0,0,0,39,41,39,0,52,0,0,0,0,0,0,0,52,0,39,41,39,0,0,0,0,6,12,0,0,0,0,0,0
0,0,0,0,0,0,21,6,5,0,0,0,0,0,0,0,0,0,0,0,0,0,0,0,0,0,0,0,0,0,0,0,5,6,17,0,0,0,0,0,0
0,0,0,0,0,0,13,6,6,0,0,0,6,0,6,6,6,6,6,0,0,0,6,6,6,6,6,0,6,0,0,0,6,6,13,0,0,0,0,0,0
0,0,0,0,0,0,34,6,0,0,0,0,0,0,0,0,0,0,33,0,0,0,33,0,0,0,0,0,0,0,0,0,0,6,17,0,0,0,0,0,0
0,0,0,0,0,0,50,6,0,0,0,0,0,0,0,0,0,0,0,0,0,0,0,0,0,0,0,0,0,0,0,0,0,6,50,0,0,0,0,0,0
0,0,0,0,26,0,35,6,0,0,0,0,0,0,0,0,0,0,0,0,0,0,0,0,0,0,0,0,0,0,0,0,0,6,35,0,0,0,0,0,0
0,0,0,23,6,34,6,6,0,0,0,0,0,0,0,0,0,0,0,0,0,0,0,0,0,0,0,0,0,0,0,0,0,6,6,34,6,9,0,0,0
0,0,12,6,6,6,6,6,0,0,0,0,0,0,0,0,0,0,0,0,0,0,0,0,0,0,0,0,0,0,0,0,0,6,6,6,6,6,12,0,0
0,0,6,6,6,0,36,11,15,0,0,0,0,0,0,0,0,0,0,6,56,6,0,0,0,0,0,0,0,0,0,0,15,11,36,0,6,6,6,0,0
0,0,21,6,28,0,36,11,11,6,6,6,6,6,6,6,6,6,6,28,0,28,6,6,6,6,6,6,6,6,6,6,11,11,36,0,0,6,17,0,0
0,0,0,49,0,0,14,15,15,6,6,21,50,35,23,35,9,21,12,0,0,0,12,17,23,35,9,21,50,17,6,6,15,15,14,0,0,49,0,0,0
0,0,21,6,0,0,0,0,0,6,17,0,0,0,0,0,0,0,12,0,0,0,12,0,0,0,0,0,0,0,21,6,0,0,0,0,0,6,17,0,0
0,0,6,6,6,0,0,0,6,6,6,0,0,0,0,0,0,0,12,0,0,0,12,0,0,0,0,0,0,0,6,6,6,0,0,0,6,6,6,0,0
0,0,13,6,6,6,49,6,6,6,13,0,0,0,0,0,0,0,12,0,0,0,12,0,0,0,0,0,0,0,13,6,6,6,49,6,6,6,13,0,0
0,0,0,23,6,35,51,35,6,9,0,0,0,0,0,0,0,0,13,0,0,0,13,0,0,0,0,0,0,0,0,23,6,35,51,35,6,9,0,0,0
0,0,0,0,0,0,0,0,0,0,0,0,0,0,0,0,0,0,0,0,0,0,0,0,0,0,0,0,0,0,0,0,0,0,0,0,0,0,0,0,0
0,0,0,0,0,0,0,0,0,0,0,0,0,0,0,0,0,0,0,0,0,0,0,0,0,0,0,0,0,0,0,0,0,0,0,0,0,0,0,0,0
0,0,0,0,0,0,0,0,0,0,0,0,0,0,0,0,0,0,0,0,0,0,0,0,0,0,0,0,0,0,0,0,0,0,0,0,0,0,0,0,0
0,0,0,0,0,0,0,0,0,0,0,0,0,0,0,0,0,0,0,0,0,0,0,0,0,0,0,0,0,0,0,0,0,0,0,0,0,0,0,0,0
0,0,0,0,0,0,0,0,0,0,0,0,0,0,0,0,0,0,0,0,0,0,0,0,0,0,0,0,0,0,0,0,0,0,0,0,0,0,0,0,0
0,0,0,0,0,0,0,0,0,0,0,0,0,0,0,0,0,0,0,0,0,0,0,0,0,0,0,0,0,0,0,0,0,0,0,0,0,0,0,0,0
0,0,0,0,0,0,0,0,0,0,0,0,0,0,0,0,0,0,0,0,0,0,0,0,0,0,0,0,0,0,0,0,0,0,0,0,0,0,0,0,0
0,0,0,0,0,0,0,0,0,0,0,0,0,0,0,0,0,0,0,0,0,0,0,0,0,0,0,0,0,0,0,0,0,0,0,0,0,0,0,0,0
0,0,0,0,0,0,0,0,0,0,0,0,0,0,0,0,0,0,0,0,0,0,0,0,0,0,0,0,0,0,0,0,0,0,0,0,0,0,0,0,0
0,0,0,0,0,0,0,0,0,0,0,0,0,0,0,0,0,0,0,0,0,0,0,0,0,0,0,0,0,0,0,0,0,0,0,0,0,0,0,0,0
:endlayer
layer: 11
0,0,0,0,0,0,0,0,0,0,0,0,0,0,0,0,0,0,0,0,0,0,0,0,0,0,0,0,0,0,0,0,0,0,0,0,0,0,0,0,0
0,0,0,0,0,0,0,0,0,0,0,0,0,0,0,0,0,0,0,0,0,0,0,0,0,0,0,0,0,0,0,0,0,0,0,0,0,0,0,0,0
0,0,0,0,6,58,0,58,6,0,0,0,0,0,0,0,0,0,0,0,0,0,0,0,0,0,0,0,0,0,0,0,6,58,0,58,6,0,0,0,0
0,0,0,6,6,6,49,6,6,6,0,0,0,0,0,0,0,0,0,0,0,0,0,0,0,0,0,0,0,0,0,6,6,6,49,6,6,6,0,0,0
0,0,6,6,6,0,36,11,6,6,6,0,0,0,0,0,0,0,0,0,0,0,0,0,0,0,0,0,0,0,6,6,6,11,36,0,6,6,6,0,0
0,0,58,6,0,0,36,11,11,6,58,0,0,0,0,0,0,0,0,0,0,0,0,0,0,0,0,0,0,0,58,6,11,11,36,0,0,6,58,0,0
0,0,0,49,0,0,14,15,15,6,6,58,0,58,0,12,0,58,0,58,33,58,0,58,0,12,0,58,0,58,6,6,15,15,14,0,0,49,0,0,0
0,0,58,6,0,0,0,0,0,6,6,6,49,6,6,6,6,6,49,6,6,6,49,6,6,6,6,6,49,6,6,6,0,0,0,0,0,6,58,0,0
0,0,6,6,6,0,0,0,0,0,0,0,0,0,0,38,0,51,0,0,54,0,0,51,0,38,0,0,0,0,0,0,0,0,0,0,6,6,6,0,0
0,0,0,6,6,6,6,6,0,5,0,0,0,0,0,62,0,0,0,0,0,0,0,0,0,59,0,0,0,0,0,5,0,6,6,6,6,6,0,0,0
0,0,0,0,6,58,6,6,0,0,0,0,0,0,0,0,0,0,0,0,0,0,0,0,0,0,0,0,0,0,0,0,0,6,6,58,6,0,0,0,0
0,0,0,0,0,0,58,6,0,0,0,0,0,0,0,0,0,0,0,60,60,60,0,0,0,0,0,0,0,0,0,0,0,6,58,0,0,0,0,0,0
0,0,0,0,0,0,0,49,0,0,0,0,0,0,0,0,25,0,0,0,0,0,0,0,25,0,0,0,0,0,0,0,0,49,0,0,0,0,0,0,0
0,0,0,0,0,0,58,6,0,0,0,29,39,0,52,0,0,0,0,0,0,0,0,0,0,0,52,0,39,27,0,0,0,6,58,0,0,0,0,0,0
0,0,0,0,0,0,0,6,0,0,0,0,43,42,0,0,0,0,0,0,0,0,0,0,0,0,0,42,44,0,0,0,0,6,0,0,0,0,0,0,0
0,0,0,0,0,0,23,6,38,0,0,29,43,42,0,0,0,0,0,0,0,0,0,0,0,0,0,42,44,27,0,0,38,6,9,0,0,0,0,0,0
0,0,0,0,0,0,0,6,0,0,0,0,43,42,0,0,0,0,0,0,0,0,0,0,0,0,0,42,44,0,0,0,0,6,0,0,0,0,0,0,0
0,0,0,0,0,0,58,6,0,0,0,0,43,42,0,0,0,0,0,0,0,0,0,0,0,0,0,42,44,0,0,0,0,6,58,0,0,0,0,0,0
0,0,0,0,0,0,0,49,0,0,0,0,43,42,0,0,0,0,0,0,61,0,0,0,0,0,0,42,44,0,0,0,0,49,0,0,0,0,0,0,0
0,0,0,0,0,0,58,6,0,0,0,0,43,42,0,0,0,0,0,0,0,0,0,0,0,0,0,42,44,0,0,0,0,6,58,0,0,0,0,0,0
0,0,0,0,0,0,33,6,38,0,0,29,43,42,0,0,0,0,0,0,0,0,0,0,0,0,0,42,44,27,0,0,38,6,33,0,0,0,0,0,0
0,0,0,0,0,0,58,6,0,0,0,0,43,42,0,0,0,0,0,0,0,0,0,0,0,0,0,42,44,0,0,0,0,6,58,0,0,0,0,0,0
0,0,0,0,0,0,0,49,0,0,0,0,43,42,0,0,0,0,0,0,0,0,0,0,0,0,0,42,44,0,0,0,0,49,0,0,0,0,0,0,0
0,0,0,0,0,0,58,6,0,0,0,0,43,42,0,0,0,0,0,0,0,0,0,0,0,0,0,42,44,0,0,0,0,6,58,0,0,0,0,0,0
0,0,0,0,0,0,0,6,0,0,0,29,39,0,52,0,25,0,0,0,0,0,0,0,25,0,52,0,39,27,0,0,0,6,0,0,0,0,0,0,0
0,0,0,0,0,0,23,6,38,0,0,0,0,0,0,0,0,0,0,0,0,0,0,0,0,0,0,0,0,0,0,0,38,6,9,0,0,0,0,0,0
0,0,0,0,0,0,0,6,6,0,0,0,6,0,6,6,6,6,6,0,0,0,6,6,6,6,6,0,6,0,0,0,6,6,0,0,0,0,0,0,0
0,0,0,0,0,0,58,6,0,0,0,0,0,0,0,0,0,0,33,0,0,0,33,0,0,0,0,0,0,0,0,0,0,6,58,0,0,0,0,0,0
0,0,0,0,0,0,0,49,0,0,0,0,0,0,0,0,0,0,0,0,0,0,0,0,0,0,0,0,0,0,0,0,0,49,0,0,0,0,0,0,0
0,0,0,0,0,0,58,6,0,0,0,0,0,0,0,0,0,0,0,0,0,0,0,0,0,0,0,0,0,0,0,0,0,6,58,0,0,0,0,0,0
0,0,0,0,6,58,6,6,0,0,0,0,0,0,0,0,0,0,0,0,0,0,0,0,0,0,0,0,0,0,0,0,0,6,6,58,6,0,0,0,0
0,0,0,6,6,6,6,6,0,0,0,0,0,0,0,0,0,0,0,26,0,26,0,0,0,0,0,0,0,0,0,0,0,6,6,6,6,6,0,0,0
0,0,6,6,6,11,15,0,0,0,0,0,0,0,0,0,0,0,0,6,35,6,0,0,0,0,0,0,0,0,0,0,0,0,15,11,6,6,6,0,0
0,0,58,6,11,11,15,0,0,6,6,6,49,6,6,6,6,6,6,0,0,0,6,6,6,6,6,6,49,6,6,6,0,0,15,11,11,6,58,0,0
0,0,0,49,36,36,14,0,0,6,6,58,0,58,0,13,0,58,28,0,0,0,28,58,0,13,0,58,0,58,6,6,0,0,14,36,36,49,0,0,0
0,0,58,6,0,0,0,0,0,6,58,0,0,0,0,0,0,0,0,0,0,0,0,0,0,0,0,0,0,0,58,6,0,0,0,0,0,6,58,0,0
0,0,6,6,6,0,0,0,6,6,6,27,0,0,0,0,0,0,0,0,0,0,0,0,0,0,0,0,0,29,6,6,6,0,0,0,6,6,6,0,0
0,0,0,6,6,6,49,6,6,6,0,0,0,0,0,0,0,0,0,0,0,0,0,0,0,0,0,0,0,0,0,6,6,6,49,6,6,6,0,0,0
0,0,0,0,6,58,0,58,6,0,0,0,0,0,0,0,0,0,0,0,0,0,0,0,0,0,0,0,0,0,0,0,6,58,0,58,6,0,0,0,0
0,0,0,0,0,0,0,0,0,0,0,0,0,0,0,0,0,0,0,0,0,0,0,0,0,0,0,0,0,0,0,0,0,0,0,0,0,0,0,0,0
0,0,0,0,0,0,0,0,0,0,0,0,0,0,0,0,0,0,0,0,0,0,0,0,0,0,0,0,0,0,0,0,0,0,0,0,0,0,0,0,0
0,0,0,0,0,0,0,0,0,0,0,0,0,0,0,0,0,0,0,0,0,0,0,0,0,0,0,0,0,0,0,0,0,0,0,0,0,0,0,0,0
0,0,0,0,0,0,0,0,0,0,0,0,0,0,0,0,0,0,0,0,0,0,0,0,0,0,0,0,0,0,0,0,0,0,0,0,0,0,0,0,0
0,0,0,0,0,0,0,0,0,0,0,0,0,0,0,0,0,0,0,0,0,0,0,0,0,0,0,0,0,0,0,0,0,0,0,0,0,0,0,0,0
0,0,0,0,0,0,0,0,0,0,0,0,0,0,0,0,0,0,0,0,0,0,0,0,0,0,0,0,0,0,0,0,0,0,0,0,0,0,0,0,0
0,0,0,0,0,0,0,0,0,0,0,0,0,0,0,0,0,0,0,0,0,0,0,0,0,0,0,0,0,0,0,0,0,0,0,0,0,0,0,0,0
0,0,0,0,0,0,0,0,0,0,0,0,0,0,0,0,0,0,0,0,0,0,0,0,0,0,0,0,0,0,0,0,0,0,0,0,0,0,0,0,0
0,0,0,0,0,0,0,0,0,0,0,0,0,0,0,0,0,0,0,0,0,0,0,0,0,0,0,0,0,0,0,0,0,0,0,0,0,0,0,0,0
0,0,0,0,0,0,0,0,0,0,0,0,0,0,0,0,0,0,0,0,0,0,0,0,0,0,0,0,0,0,0,0,0,0,0,0,0,0,0,0,0
:endlayer
layer: 12
0,0,0,0,0,0,0,0,0,0,0,0,0,0,0,0,0,0,0,0,0,0,0,0,0,0,0,0,0,0,0,0,0,0,0,0,0,0,0,0,0
0,0,0,0,26,0,0,0,26,0,0,0,0,0,0,0,0,0,0,0,0,0,0,0,0,0,0,0,0,0,0,0,26,0,0,0,26,0,0,0,0
0,0,0,21,6,12,0,12,6,17,0,0,0,0,0,0,0,0,0,0,0,0,0,0,0,0,0,0,0,0,0,21,6,12,0,12,6,17,0,0,0
0,0,34,6,6,6,49,6,6,6,34,0,0,0,0,0,0,0,0,0,0,0,0,0,0,0,0,0,0,0,34,6,6,6,49,6,6,6,34,0,0
0,29,6,6,6,11,15,0,6,6,6,0,0,0,0,0,0,0,0,0,0,0,0,0,0,0,0,0,0,0,6,6,6,0,15,11,6,6,6,27,0
0,0,23,6,11,11,15,0,0,6,9,0,0,0,0,0,0,0,0,0,0,0,0,0,0,0,0,0,0,0,23,6,0,0,15,11,11,6,9,0,0
0,0,0,49,36,36,14,0,0,6,6,58,0,58,0,58,0,58,0,58,33,58,0,58,0,58,0,58,0,58,6,6,0,0,14,36,36,49,0,0,0
0,0,23,6,0,0,0,0,0,6,6,6,49,6,6,6,6,6,49,6,6,6,49,6,6,6,6,6,49,6,6,6,0,0,0,0,29,6,9,0,0
0,29,6,6,6,27,0,0,0,0,0,0,0,0,0,38,0,0,0,54,54,54,0,0,0,38,0,0,0,0,0,0,0,0,0,0,6,6,6,27,0
0,0,35,6,6,6,6,6,0,38,0,0,0,0,0,0,0,0,0,0,0,0,0,0,0,0,0,0,0,0,0,38,0,6,6,6,6,6,35,0,0
0,0,0,21,6,13,6,6,0,0,0,0,0,0,0,0,0,0,0,0,0,0,0,0,0,0,0,0,0,0,0,0,0,6,6,13,6,17,0,0,0
0,0,0,0,0,0,58,6,0,0,0,0,0,0,0,0,0,0,0,0,0,0,0,0,0,0,0,0,0,0,0,0,0,6,58,0,0,0,0,0,0
0,0,0,0,0,0,0,49,0,0,0,0,0,0,0,0,0,0,0,0,0,0,0,0,0,0,0,0,0,0,0,0,0,49,0,0,0,0,0,0,0
0,0,0,0,0,0,58,6,0,0,0,0,52,0,51,0,0,0,0,0,0,0,0,0,0,0,51,0,52,0,0,0,0,6,58,0,0,0,0,0,0
0,0,0,0,0,0,0,6,0,0,0,0,0,0,0,0,0,0,0,0,0,0,0,0,0,0,0,0,0,0,0,0,0,6,0,0,0,0,0,0,0
0,0,0,0,0,0,58,6,38,0,0,0,0,0,0,0,0,0,0,0,0,0,0,0,0,0,0,0,0,0,0,0,38,6,58,0,0,0,0,0,0
0,0,0,0,0,0,0,6,0,0,0,0,0,0,0,0,0,0,0,0,0,0,0,0,0,0,0,0,0,0,0,0,0,6,0,0,0,0,0,0,0
0,0,0,0,0,0,58,6,0,0,0,0,0,0,0,0,0,0,0,0,0,0,0,0,0,0,0,0,0,0,0,0,0,6,58,0,0,0,0,0,0
0,0,0,0,0,0,0,49,0,0,0,0,0,0,0,0,0,0,0,0,63,0,0,0,0,0,0,0,0,0,0,0,0,49,0,0,0,0,0,0,0
0,0,0,0,0,0,58,6,0,0,0,0,0,0,0,0,0,0,0,0,0,0,0,0,0,0,0,0,0,0,0,0,0,6,58,0,0,0,0,0,0
0,0,0,0,0,0,33,6,38,0,0,0,0,0,0,0,0,0,0,0,0,0,0,0,0,0,0,0,0,0,0,0,38,6,33,0,0,0,0,0,0
0,0,0,0,0,0,58,6,0,0,0,0,0,0,0,0,0,0,0,0,0,0,0,0,0,0,0,0,0,0,0,0,0,6,58,0,0,0,0,0,0
0,0,0,0,0,0,0,49,0,0,0,0,0,0,0,0,0,0,0,0,0,0,0,0,0,0,0,0,0,0,0,0,0,49,0,0,0,0,0,0,0
0,0,0,0,0,0,58,6,0,0,0,0,0,0,0,0,0,0,0,0,0,0,0,0,0,0,0,0,0,0,0,0,0,6,58,0,0,0,0,0,0
0,0,0,0,0,0,0,6,0,0,0,0,52,0,51,0,0,0,0,0,0,0,0,0,0,0,51,0,52,0,0,0,0,6,0,0,0,0,0,0,0
0,0,0,0,0,0,58,6,38,0,0,0,26,0,0,0,0,0,26,0,0,0,26,0,0,0,0,0,26,0,0,0,38,6,58,0,0,0,0,0,0
0,0,0,0,0,0,0,6,6,17,0,21,6,0,6,6,6,6,6,17,0,21,6,6,6,6,6,0,6,17,0,21,6,6,0,0,0,0,0,0,0
0,0,0,0,0,0,58,6,28,0,0,0,28,0,28,0,0,0,33,0,0,0,33,0,0,0,28,0,28,0,0,0,28,6,58,0,0,0,0,0,0
0,0,0,0,0,0,0,49,0,0,0,0,0,0,0,0,0,0,0,0,0,0,0,0,0,0,0,0,0,0,0,0,0,49,0,0,0,0,0,0,0
0,0,0,0,0,0,58,6,0,0,0,0,0,0,0,0,0,0,0,0,0,0,0,0,0,0,0,0,0,0,0,0,0,6,58,0,0,0,0,0,0
0,0,0,21,6,12,6,6,0,0,0,0,0,0,0,0,0,0,0,0,0,0,0,0,0,0,0,0,0,0,0,0,0,6,6,12,6,17,0,0,0
0,0,34,6,6,6,6,6,0,0,0,0,0,0,0,0,0,0,0,0,0,0,0,0,0,0,0,0,0,0,0,0,0,6,6,6,6,6,34,0,0
0,29,6,6,6,0,0,0,0,0,0,0,0,0,0,0,0,0,0,23,12,9,0,0,0,0,0,0,0,0,0,0,0,0,0,0,6,6,6,27,0
0,0,23,6,0,0,0,0,0,6,6,6,49,6,6,6,6,6,6,17,28,21,6,6,6,6,6,6,49,6,6,6,0,0,0,0,0,6,9,0,0
0,0,0,49,15,15,14,0,0,6,6,58,0,58,0,58,0,58,0,0,0,0,0,58,0,58,0,58,0,58,6,6,0,0,14,15,15,49,0,0,0
0,0,23,6,11,11,36,0,26,6,9,0,0,0,0,0,0,0,0,0,0,0,0,0,0,0,0,0,0,0,23,6,26,0,36,11,11,6,9,0,0
0,29,6,6,6,11,36,0,6,6,6,0,0,0,0,0,0,0,0,0,0,0,0,0,0,0,0,0,0,0,6,6,6,0,36,11,6,6,6,27,0
0,0,35,6,6,6,49,6,6,6,35,0,0,0,0,0,0,0,0,0,0,0,0,0,0,0,0,0,0,0,35,6,6,6,49,6,6,6,35,0,0
0,0,0,21,6,13,0,13,6,17,0,0,0,0,0,0,0,0,0,0,0,0,0,0,0,0,0,0,0,0,0,21,6,13,0,13,6,17,0,0,0
0,0,0,0,0,0,0,0,0,0,0,0,0,0,0,0,0,0,0,0,0,0,0,0,0,0,0,0,0,0,0,0,0,0,0,0,0,0,0,0,0
0,0,0,0,0,0,0,0,0,0,0,0,0,0,0,0,0,0,0,0,0,0,0,0,0,0,0,0,0,0,0,0,0,0,0,0,0,0,0,0,0
0,0,0,0,0,0,0,0,0,0,0,0,0,0,0,0,0,0,0,0,0,0,0,0,0,0,0,0,0,0,0,0,0,0,0,0,0,0,0,0,0
0,0,0,0,0,0,0,0,0,0,0,0,0,0,0,0,0,0,0,0,0,0,0,0,0,0,0,0,0,0,0,0,0,0,0,0,0,0,0,0,0
0,0,0,0,0,0,0,0,0,0,0,0,0,0,0,0,0,0,0,0,0,0,0,0,0,0,0,0,0,0,0,0,0,0,0,0,0,0,0,0,0
0,0,0,0,0,0,0,0,0,0,0,0,0,0,0,0,0,0,0,0,0,0,0,0,0,0,0,0,0,0,0,0,0,0,0,0,0,0,0,0,0
0,0,0,0,0,0,0,0,0,0,0,0,0,0,0,0,0,0,0,0,0,0,0,0,0,0,0,0,0,0,0,0,0,0,0,0,0,0,0,0,0
0,0,0,0,0,0,0,0,0,0,0,0,0,0,0,0,0,0,0,0,0,0,0,0,0,0,0,0,0,0,0,0,0,0,0,0,0,0,0,0,0
0,0,0,0,0,0,0,0,0,0,0,0,0,0,0,0,0,0,0,0,0,0,0,0,0,0,0,0,0,0,0,0,0,0,0,0,0,0,0,0,0
0,0,0,0,0,0,0,0,0,0,0,0,0,0,0,0,0,0,0,0,0,0,0,0,0,0,0,0,0,0,0,0,0,0,0,0,0,0,0,0,0
:endlayer
layer: 13
0,0,0,0,0,0,0,0,0,0,0,0,0,0,0,0,0,0,0,0,0,0,0,0,0,0,0,0,0,0,0,0,0,0,0,0,0,0,0,0,0
0,0,0,0,0,0,0,0,0,0,0,0,0,0,0,0,0,0,0,0,0,0,0,0,0,0,0,0,0,0,0,0,0,0,0,0,0,0,0,0,0
0,0,0,23,6,17,12,21,6,9,0,0,0,0,0,0,0,0,0,0,0,0,0,0,0,0,0,0,0,0,0,23,6,17,12,21,6,9,0,0,0
0,0,12,6,6,6,6,6,6,6,12,0,0,0,0,0,0,0,0,0,0,0,0,0,0,0,0,0,0,0,12,6,6,6,6,6,6,6,12,0,0
0,0,6,6,6,0,0,0,6,6,6,0,0,0,0,0,0,0,0,0,0,0,0,0,0,0,0,0,0,0,6,6,6,0,0,0,6,6,6,0,0
0,0,35,6,0,0,0,0,0,6,35,0,0,0,0,0,0,0,0,0,0,0,0,0,0,0,0,0,0,0,35,6,0,0,0,0,0,6,35,0,0
0,0,23,6,15,15,14,0,0,6,6,23,50,9,0,34,0,23,50,9,33,23,50,9,0,34,0,23,50,9,6,6,0,0,14,15,15,6,9,0,0
0,0,34,6,11,11,36,0,0,6,6,6,6,6,6,6,6,6,6,6,6,6,6,6,6,6,6,6,6,6,6,6,0,0,36,11,11,6,34,0,0
0,0,6,6,6,11,36,0,0,6,6,27,28,0,0,38,0,0,28,0,54,0,28,0,0,38,0,0,28,29,6,6,0,0,36,11,6,6,6,0,0
0,0,13,6,6,6,6,6,6,38,28,0,0,0,0,0,0,0,0,0,0,0,0,0,0,0,0,0,0,0,28,38,6,6,6,6,6,6,13,0,0
0,0,0,23,6,17,6,6,6,27,0,0,0,0,0,0,0,0,0,0,0,0,0,0,0,0,0,0,0,0,0,29,6,6,6,21,6,9,0,0,0
0,0,0,0,0,0,12,6,28,0,0,0,0,0,0,0,0,0,0,0,0,0,0,0,0,0,0,0,0,0,0,0,28,6,12,0,0,0,0,0,0
0,0,0,0,0,0,50,6,27,0,0,0,0,0,0,0,0,0,0,0,0,0,0,0,0,0,0,0,0,0,0,0,29,6,50,0,0,0,0,0,0
0,0,0,0,0,0,13,6,0,0,0,0,51,0,0,0,0,0,0,0,0,0,0,0,0,0,0,0,51,0,0,0,0,6,13,0,0,0,0,0,0
0,0,0,0,0,0,0,6,0,0,0,0,0,0,0,0,0,0,0,0,0,0,0,0,0,0,0,0,0,0,0,0,0,6,0,0,0,0,0,0,0
0,0,0,0,0,0,21,6,38,0,0,0,0,0,0,0,0,0,0,0,0,0,0,0,0,0,0,0,0,0,0,0,38,6,17,0,0,0,0,0,0
0,0,0,0,0,0,0,6,0,0,0,0,0,0,0,0,0,0,0,0,0,0,0,0,0,0,0,0,0,0,0,0,0,6,0,0,0,0,0,0,0
0,0,0,0,0,0,12,6,0,0,0,0,0,0,0,0,0,0,0,0,0,0,0,0,0,0,0,0,0,0,0,0,0,6,12,0,0,0,0,0,0
0,0,0,0,0,0,50,6,27,0,0,0,0,0,0,0,0,0,0,0,64,0,0,0,0,0,0,0,0,0,0,0,29,6,50,0,0,0,0,0,0
0,0,0,0,0,0,13,6,0,0,0,0,0,0,0,0,0,0,0,0,0,0,0,0,0,0,0,0,0,0,0,0,0,6,13,0,0,0,0,0,0
0,0,0,0,0,0,33,6,38,0,0,0,0,0,0,0,0,0,0,0,0,0,0,0,0,0,0,0,0,0,0,0,38,6,33,0,0,0,0,0,0
0,0,0,0,0,0,12,6,0,0,0,0,0,0,0,0,0,0,0,0,0,0,0,0,0,0,0,0,0,0,0,0,0,6,12,0,0,0,0,0,0
0,0,0,0,0,0,50,6,27,0,0,0,0,0,0,0,0,0,0,0,0,0,0,0,0,0,0,0,0,0,0,0,29,6,50,0,0,0,0,0,0
0,0,0,0,0,0,13,6,0,0,0,0,0,0,0,0,0,0,0,0,0,0,0,0,0,0,0,0,0,0,0,0,0,6,13,0,0,0,0,0,0
0,0,0,0,0,0,0,6,0,0,0,0,51,0,0,0,0,0,0,0,0,0,0,0,0,0,0,0,51,0,0,0,0,6,0,0,0,0,0,0,0
0,0,0,0,0,0,21,6,38,0,0,0,0,0,0,0,0,0,0,0,0,0,0,0,0,0,0,0,0,0,0,0,38,6,17,0,0,0,0,0,0
0,0,0,0,0,0,0,6,6,6,6,6,6,6,6,6,6,6,6,6,6,6,6,6,6,6,6,6,6,6,6,6,6,6,0,0,0,0,0,0,0
0,0,0,0,0,0,12,6,0,0,0,0,0,0,0,0,0,0,33,0,28,0,33,0,0,0,0,0,0,0,0,0,0,6,12,0,0,0,0,0,0
0,0,0,0,0,0,50,6,27,0,0,0,0,0,0,0,0,0,0,0,0,0,0,0,0,0,0,0,0,0,0,0,29,6,50,0,0,0,0,0,0
0,0,0,0,0,0,13,6,26,0,0,0,0,0,0,0,0,0,0,0,0,0,0,0,0,0,0,0,0,0,0,0,26,6,13,0,0,0,0,0,0
0,0,0,23,6,17,6,6,6,27,0,0,0,0,0,0,0,0,0,0,0,0,0,0,0,0,0,0,0,0,0,29,6,6,6,21,6,9,0,0,0
0,0,12,6,6,6,6,6,6,0,26,0,0,0,0,0,0,0,0,0,0,0,0,0,0,0,0,0,0,0,26,0,6,6,6,6,6,6,12,0,0
0,0,6,6,6,0,0,0,0,6,6,27,26,0,0,0,0,0,0,0,0,0,0,0,0,0,0,0,26,29,6,6,0,0,0,0,6,6,6,0,0
0,0,35,6,0,0,0,0,0,6,6,6,6,6,6,6,6,6,6,6,6,6,6,6,6,6,6,6,6,6,6,6,0,0,0,0,0,6,35,0,0
0,0,23,6,0,0,14,36,36,6,6,23,50,9,0,35,0,23,0,0,0,0,0,9,0,35,0,23,50,9,6,6,36,36,5,0,0,6,9,0,0
0,0,34,6,0,0,15,11,11,6,34,0,0,0,0,0,0,0,0,0,0,0,0,0,0,0,0,0,0,0,34,6,11,11,15,0,0,6,34,0,0
0,0,6,6,6,0,15,11,6,6,6,0,0,0,0,0,0,0,0,0,0,0,0,0,0,0,0,0,0,0,6,6,6,11,15,0,6,6,6,0,0
0,0,13,6,6,6,6,6,6,6,13,0,0,0,0,0,0,0,0,0,0,0,0,0,0,0,0,0,0,0,13,6,6,6,6,6,6,6,13,0,0
0,0,0,23,6,17,13,21,6,9,0,0,0,0,0,0,0,0,0,0,0,0,0,0,0,0,0,0,0,0,0,23,6,17,13,21,6,9,0,0,0
0,0,0,0,0,0,0,0,0,0,0,0,0,0,0,0,0,0,0,0,0,0,0,0,0,0,0,0,0,0,0,0,0,0,0,0,0,0,0,0,0
0,0,0,0,0,0,0,0,0,0,0,0,0,0,0,0,0,0,0,0,0,0,0,0,0,0,0,0,0,0,0,0,0,0,0,0,0,0,0,0,0
0,0,0,0,0,0,0,0,0,0,0,0,0,0,0,0,0,0,0,0,0,0,0,0,0,0,0,0,0,0,0,0,0,0,0,0,0,0,0,0,0
0,0,0,0,0,0,0,0,0,0,0,0,0,0,0,0,0,0,0,0,0,0,0,0,0,0,0,0,0,0,0,0,0,0,0,0,0,0,0,0,0
0,0,0,0,0,0,0,0,0,0,0,0,0,0,0,0,0,0,0,0,0,0,0,0,0,0,0,0,0,0,0,0,0,0,0,0,0,0,0,0,0
0,0,0,0,0,0,0,0,0,0,0,0,0,0,0,0,0,0,0,0,0,0,0,0,0,0,0,0,0,0,0,0,0,0,0,0,0,0,0,0,0
0,0,0,0,0,0,0,0,0,0,0,0,0,0,0,0,0,0,0,0,0,0,0,0,0,0,0,0,0,0,0,0,0,0,0,0,0,0,0,0,0
0,0,0,0,0,0,0,0,0,0,0,0,0,0,0,0,0,0,0,0,0,0,0,0,0,0,0,0,0,0,0,0,0,0,0,0,0,0,0,0,0
0,0,0,0,0,0,0,0,0,0,0,0,0,0,0,0,0,0,0,0,0,0,0,0,0,0,0,0,0,0,0,0,0,0,0,0,0,0,0,0,0
0,0,0,0,0,0,0,0,0,0,0,0,0,0,0,0,0,0,0,0,0,0,0,0,0,0,0,0,0,0,0,0,0,0,0,0,0,0,0,0,0
:endlayer
layer: 14
0,0,0,0,0,0,0,0,0,0,0,0,0,0,0,0,0,0,0,0,0,0,0,0,0,0,0,0,0,0,0,0,0,0,0,0,0,0,0,0,0
0,0,0,0,32,32,32,32,32,0,0,0,0,0,0,0,0,0,0,0,0,0,0,0,0,0,0,0,0,0,0,0,32,32,32,32,32,0,0,0,0
0,0,0,32,6,6,33,6,6,32,0,0,0,0,0,0,0,0,0,0,0,0,0,0,0,0,0,0,0,0,0,32,6,6,33,6,6,32,0,0,0
0,0,32,6,6,6,6,6,6,6,32,0,0,0,0,0,0,0,0,0,0,0,0,0,0,0,0,0,0,0,32,6,6,6,6,6,6,6,32,0,0
0,32,6,6,6,0,0,0,6,6,6,32,0,0,0,0,0,0,0,0,0,0,0,0,0,0,0,0,0,32,6,6,6,0,0,0,6,6,6,32,0
0,32,6,6,0,0,0,0,28,6,6,32,32,32,0,0,0,32,32,32,0,32,32,32,0,0,0,32,32,32,6,6,28,0,0,0,0,6,6,32,0
0,32,33,6,0,0,14,36,36,6,6,6,6,6,21,12,17,6,6,6,33,6,6,6,21,12,17,6,6,6,6,6,36,36,14,0,0,6,33,32,0
0,32,6,6,0,0,15,11,11,6,6,6,6,6,6,6,6,6,6,6,6,6,6,6,6,6,6,6,6,6,6,6,11,11,15,0,0,6,6,32,0
0,32,6,6,6,0,15,11,11,6,66,66,66,66,66,66,66,66,66,66,66,66,66,66,66,66,66,66,66,66,66,6,11,11,15,0,6,6,6,32,0
0,0,32,6,6,6,6,6,6,38,0,0,0,0,0,28,0,0,0,0,28,0,0,0,0,28,0,0,0,0,0,38,6,6,6,6,6,6,32,0,0
0,0,0,32,6,6,6,6,65,0,0,0,0,0,0,0,0,0,0,0,0,0,0,0,0,0,0,0,0,0,0,0,65,6,6,6,6,32,0,0,0
0,0,0,0,32,32,6,6,65,0,0,0,0,0,0,0,0,0,0,0,0,0,0,0,0,0,0,0,0,0,0,0,65,6,6,32,32,0,0,0,0
0,0,0,0,0,32,6,6,65,0,0,0,0,0,0,0,0,0,0,0,0,0,0,0,0,0,0,0,0,0,0,0,65,6,6,32,0,0,0,0,0
0,0,0,0,0,32,6,6,65,0,0,0,0,0,0,0,0,0,0,0,0,0,0,0,0,0,0,0,0,0,0,0,65,6,6,32,0,0,0,0,0
0,0,0,0,0,0,34,6,65,0,0,0,0,0,0,0,0,0,0,0,0,0,0,0,0,0,0,0,0,0,0,0,65,6,34,0,0,0,0,0,0
0,0,0,0,0,0,23,6,65,27,0,0,0,0,0,0,0,0,0,0,0,0,0,0,0,0,0,0,0,0,0,29,65,6,9,0,0,0,0,0,0
0,0,0,0,0,0,35,6,65,0,0,0,0,0,0,0,0,0,0,0,0,0,0,0,0,0,0,0,0,0,0,0,65,6,35,0,0,0,0,0,0
0,0,0,0,0,32,6,6,65,0,0,0,0,0,0,0,0,0,0,0,0,0,0,0,0,0,0,0,0,0,0,0,65,6,6,32,0,0,0,0,0
0,0,0,0,0,32,6,6,65,0,0,0,0,0,0,0,0,0,0,0,67,0,0,0,0,0,0,0,0,0,0,0,65,6,6,32,0,0,0,0,0
0,0,0,0,0,32,6,6,65,0,0,0,0,0,0,0,0,0,0,0,0,0,0,0,0,0,0,0,0,0,0,0,65,6,6,32,0,0,0,0,0
0,0,0,0,0,0,33,6,65,27,0,0,0,0,0,0,0,0,0,0,0,0,0,0,0,0,0,0,0,0,0,29,65,6,33,0,0,0,0,0,0
0,0,0,0,0,32,6,6,65,0,0,0,0,0,0,0,0,0,0,0,0,0,0,0,0,0,0,0,0,0,0,0,65,6,6,32,0,0,0,0,0
0,0,0,0,0,32,6,6,65,0,0,0,0,0,0,0,0,0,0,0,0,0,0,0,0,0,0,0,0,0,0,0,65,6,6,32,0,0,0,0,0
0,0,0,0,0,32,6,6,65,0,0,0,0,0,0,0,0,0,0,0,0,0,0,0,0,0,0,0,0,0,0,0,65,6,6,32,0,0,0,0,0
0,0,0,0,0,0,34,6,65,0,0,0,0,0,0,0,0,0,0,0,0,0,0,0,0,0,0,0,0,0,0,0,65,6,34,0,0,0,0,0,0
0,0,0,0,0,0,23,6,65,27,0,0,0,0,0,0,0,0,0,0,0,0,0,0,0,0,0,0,0,0,0,29,65,6,9,0,0,0,0,0,0
0,0,0,0,0,0,35,6,6,6,6,6,6,6,6,6,6,6,6,6,6,6,6,6,6,6,6,6,6,6,6,6,6,6,35,0,0,0,0,0,0
0,0,0,0,0,32,6,6,0,0,0,0,0,0,0,0,0,0,33,0,0,0,33,0,0,0,0,0,0,0,0,0,0,6,6,32,0,0,0,0,0
0,0,0,0,0,32,6,6,0,0,0,0,0,0,0,0,0,0,0,0,0,0,0,0,0,0,0,0,0,0,0,0,0,6,6,32,0,0,0,0,0
0,0,0,0,32,32,6,6,0,0,0,0,0,0,0,0,0,0,0,0,0,0,0,0,0,0,0,0,0,0,0,0,0,6,6,32,32,0,0,0,0
0,0,0,32,6,6,6,6,5,0,0,0,0,0,0,0,0,0,0,0,0,0,0,0,0,0,0,0,0,0,0,0,0,6,6,6,6,32,0,0,0
0,0,32,6,6,6,6,6,6,0,0,0,0,0,0,0,0,0,0,0,0,0,0,0,0,0,0,0,0,0,0,0,6,6,6,6,6,6,32,0,0
0,32,6,6,6,27,36,11,39,6,5,0,0,0,0,0,0,0,0,0,0,0,0,0,0,0,0,0,0,0,0,6,39,11,36,29,6,6,6,32,0
0,32,6,6,0,0,36,11,11,6,6,6,6,6,6,6,6,6,6,6,6,6,6,6,6,6,6,6,6,6,6,6,11,11,36,0,0,6,6,32,0
0,32,33,6,0,0,14,15,15,6,6,6,6,6,21,13,17,6,6,6,33,6,6,6,21,13,17,6,6,6,6,6,15,15,14,0,0,6,33,32,0
0,32,6,6,0,0,0,0,0,6,6,32,32,32,0,0,0,32,32,32,0,32,32,32,0,0,0,32,32,32,6,6,0,0,0,0,0,6,6,32,0
0,32,6,6,6,0,0,0,6,6,6,32,0,0,0,0,0,0,0,0,0,0,0,0,0,0,0,0,0,32,6,6,6,0,0,0,6,6,6,32,0
0,0,32,6,6,6,6,6,6,6,32,0,0,0,0,0,0,0,0,0,0,0,0,0,0,0,0,0,0,0,32,6,6,6,6,6,6,6,32,0,0
0,0,0,32,6,6,33,6,6,32,0,0,0,0,0,0,0,0,0,0,0,0,0,0,0,0,0,0,0,0,0,32,6,6,33,6,6,32,0,0,0
0,0,0,0,32,32,32,32,32,0,0,0,0,0,0,0,0,0,0,0,0,0,0,0,0,0,0,0,0,0,0,0,32,32,32,32,32,0,0,0,0
0,0,0,0,0,0,0,0,0,0,0,0,0,0,0,0,0,0,0,0,0,0,0,0,0,0,0,0,0,0,0,0,0,0,0,0,0,0,0,0,0
0,0,0,0,0,0,0,0,0,0,0,0,0,0,0,0,0,0,0,0,0,0,0,0,0,0,0,0,0,0,0,0,0,0,0,0,0,0,0,0,0
0,0,0,0,0,0,0,0,0,0,0,0,0,0,0,0,0,0,0,0,0,0,0,0,0,0,0,0,0,0,0,0,0,0,0,0,0,0,0,0,0
0,0,0,0,0,0,0,0,0,0,0,0,0,0,0,0,0,0,0,0,0,0,0,0,0,0,0,0,0,0,0,0,0,0,0,0,0,0,0,0,0
0,0,0,0,0,0,0,0,0,0,0,0,0,0,0,0,0,0,0,0,0,0,0,0,0,0,0,0,0,0,0,0,0,0,0,0,0,0,0,0,0
0,0,0,0,0,0,0,0,0,0,0,0,0,0,0,0,0,0,0,0,0,0,0,0,0,0,0,0,0,0,0,0,0,0,0,0,0,0,0,0,0
0,0,0,0,0,0,0,0,0,0,0,0,0,0,0,0,0,0,0,0,0,0,0,0,0,0,0,0,0,0,0,0,0,0,0,0,0,0,0,0,0
0,0,0,0,0,0,0,0,0,0,0,0,0,0,0,0,0,0,0,0,0,0,0,0,0,0,0,0,0,0,0,0,0,0,0,0,0,0,0,0,0
0,0,0,0,0,0,0,0,0,0,0,0,0,0,0,0,0,0,0,0,0,0,0,0,0,0,0,0,0,0,0,0,0,0,0,0,0,0,0,0,0
:endlayer
layer: 15
0,0,0,0,0,0,0,0,0,0,0,0,0,0,0,0,0,0,0,0,0,0,0,0,0,0,0,0,0,0,0,0,0,0,0,0,0,0,0,0,0
0,0,0,0,0,0,0,0,0,0,0,0,0,0,0,0,0,0,0,0,0,0,0,0,0,0,0,0,0,0,0,0,0,0,0,0,0,0,0,0,0
0,0,0,21,6,9,34,23,6,17,0,0,0,0,0,0,0,0,0,0,0,0,0,0,0,0,0,0,0,0,0,21,6,9,34,23,6,17,0,0,0
0,0,34,6,6,6,6,6,6,6,34,0,0,0,0,0,0,0,0,0,0,0,0,0,0,0,0,0,0,0,34,6,6,6,6,6,6,6,34,0,0
0,0,6,6,6,0,36,11,6,6,6,0,0,0,0,0,0,0,0,0,0,0,0,0,0,0,0,0,0,0,6,6,6,11,36,0,6,6,6,0,0
0,0,13,6,0,0,36,11,11,6,13,0,0,0,30,30,30,0,0,0,30,0,0,0,30,30,30,0,0,0,13,6,11,11,36,0,0,6,13,0,0
0,0,21,6,0,0,14,15,15,6,6,37,37,37,6,6,6,37,37,37,33,37,37,37,6,6,6,37,37,37,6,6,15,15,14,0,0,6,17,0,0
0,0,12,6,0,0,0,0,0,6,6,6,6,6,6,6,6,6,6,6,6,6,6,6,6,6,6,6,6,6,6,6,0,0,0,0,0,6,12,0,0
0,0,6,6,6,0,0,0,0,6,0,0,0,0,0,38,0,0,0,0,38,0,0,0,0,38,0,0,0,0,0,6,0,0,0,0,6,6,6,0,0
0,0,35,6,6,6,6,6,6,38,0,0,0,0,0,0,0,0,0,0,0,0,0,0,0,0,0,0,0,0,0,38,6,6,6,6,6,6,35,0,0
0,0,0,21,6,9,6,6,0,0,0,0,0,0,0,0,0,0,0,0,0,0,0,0,0,0,0,0,0,0,0,0,0,6,6,23,6,17,0,0,0
0,0,0,0,0,0,37,6,0,0,0,0,0,0,0,0,0,0,0,0,0,0,0,0,0,0,0,0,0,0,0,0,0,6,37,0,0,0,0,0,0
0,0,0,0,0,0,37,6,0,0,0,0,0,0,0,0,0,0,0,0,0,0,0,0,0,0,0,0,0,0,0,0,0,6,37,0,0,0,0,0,0
0,0,0,0,0,0,37,6,0,0,0,0,0,0,0,0,0,0,0,0,0,0,0,0,0,0,0,0,0,0,0,0,0,6,37,0,0,0,0,0,0
0,0,0,0,0,30,6,6,0,0,0,0,0,0,0,0,0,0,0,0,0,0,0,0,0,0,0,0,0,0,0,0,0,6,6,30,0,0,0,0,0
0,0,0,0,0,30,6,6,38,0,0,0,0,0,0,0,0,0,0,0,0,0,0,0,0,0,0,0,0,0,0,0,38,6,6,30,0,0,0,0,0
0,0,0,0,0,30,6,6,0,0,0,0,0,0,0,0,0,0,0,0,0,0,0,0,0,0,0,0,0,0,0,0,0,6,6,30,0,0,0,0,0
0,0,0,0,0,0,37,6,0,0,0,0,0,0,0,0,0,0,0,0,0,0,0,0,0,0,0,0,0,0,0,0,0,6,37,0,0,0,0,0,0
0,0,0,0,0,0,37,6,0,0,0,0,0,0,0,0,0,0,0,0,69,0,0,0,0,0,0,0,0,0,0,0,0,6,37,0,0,0,0,0,0
0,0,0,0,0,0,37,6,0,0,0,0,0,0,0,0,0,0,0,0,0,0,0,0,0,0,0,0,0,0,0,0,0,6,37,0,0,0,0,0,0
0,0,0,0,0,30,33,6,38,0,0,0,0,0,0,0,0,0,0,0,0,0,0,0,0,0,0,0,0,0,0,0,38,6,33,30,0,0,0,0,0
0,0,0,0,0,0,37,6,0,0,0,0,0,0,0,0,0,0,0,0,0,0,0,0,0,0,0,0,0,0,0,0,0,6,37,0,0,0,0,0,0
0,0,0,0,0,0,37,6,0,0,0,0,0,0,0,0,0,0,0,0,0,0,0,0,0,0,0,0,0,0,0,0,0,6,37,0,0,0,0,0,0
0,0,0,0,0,0,37,6,0,0,0,0,0,0,0,0,0,0,0,0,0,0,0,0,0,0,0,0,0,0,0,0,0,6,37,0,0,0,0,0,0
0,0,0,0,0,30,6,6,0,0,0,0,0,0,0,0,0,0,0,0,0,0,0,0,0,0,0,0,0,0,0,0,0,6,6,30,0,0,0,0,0
0,0,0,0,0,30,6,6,38,0,0,0,0,0,0,0,0,0,0,0,0,0,0,0,0,0,0,0,0,0,0,0,38,6,6,30,0,0,0,0,0
0,0,0,0,0,30,6,6,40,40,40,40,40,40,40,40,40,40,40,40,40,40,40,40,40,40,40,40,40,40,40,40,40,6,6,30,0,0,0,0,0
0,0,0,0,0,0,37,6,39,39,39,39,39,39,39,39,39,39,39,39,39,39,39,39,39,39,39,39,39,39,39,39,39,6,37,0,0,0,0,0,0
0,0,0,0,0,0,37,6,39,39,39,39,39,39,39,39,39,39,39,39,39,39,39,39,39,39,39,39,39,39,39,39,39,6,37,0,0,0,0,0,0
0,0,0,0,0,0,37,6,39,39,39,39,39,39,39,39,39,39,39,39,39,39,39,39,39,39,39,39,39,39,39,39,39,6,37,0,0,0,0,0,0
0,0,0,21,6,9,6,6,39,39,39,39,39,39,39,39,39,39,39,39,39,39,39,39,39,39,39,39,39,39,39,39,39,6,6,23,6,17,0,0,0
0,0,34,6,6,6,6,6,39,39,39,39,39,39,39,39,39,39,39,39,39,39,39,39,39,39,39,39,39,39,39,39,39,6,6,6,6,6,34,0,0
0,0,6,6,6,11,15,0,68,39,39,39,39,39,39,39,39,39,39,39,39,39,39,39,39,39,39,39,39,39,39,39,68,0,15,11,6,6,6,0,0
0,0,13,6,11,11,15,0,0,6,6,6,6,6,6,6,6,6,6,6,6,6,6,6,6,6,6,6,6,6,6,6,0,0,15,11,11,6,13,0,0
0,0,21,6,36,36,14,0,0,6,6,37,37,37,6,6,6,37,37,37,33,37,37,37,6,6,6,37,37,37,6,6,0,0,14,36,36,6,17,0,0
0,0,12,6,0,0,0,0,0,6,12,0,0,0,30,30,30,0,0,0,30,0,0,0,30,30,30,0,0,0,12,6,0,0,0,0,0,6,12,0,0
0,0,6,6,6,0,0,0,6,6,6,0,0,0,0,0,0,0,0,0,0,0,0,0,0,0,0,0,0,0,6,6,6,0,0,0,6,6,6,0,0
0,0,35,6,6,6,6,6,6,6,35,0,0,0,0,0,0,0,0,0,0,0,0,0,0,0,0,0,0,0,35,6,6,6,6,6,6,6,35,0,0
0,0,0,21,6,9,35,23,6,17,0,0,0,0,0,0,0,0,0,0,0,0,0,0,0,0,0,0,0,0,0,21,6,9,35,23,6,17,0,0,0
0,0,0,0,0,0,0,0,0,0,0,0,0,0,0,0,0,0,0,0,0,0,0,0,0,0,0,0,0,0,0,0,0,0,0,0,0,0,0,0,0
0,0,0,0,0,0,0,0,0,0,0,0,0,0,0,0,0,0,0,0,0,0,0,0,0,0,0,0,0,0,0,0,0,0,0,0,0,0,0,0,0
0,0,0,0,0,0,0,0,0,0,0,0,0,0,0,0,0,0,0,0,0,0,0,0,0,0,0,0,0,0,0,0,0,0,0,0,0,0,0,0,0
0,0,0,0,0,0,0,0,0,0,0,0,0,0,0,0,0,0,0,0,0,0,0,0,0,0,0,0,0,0,0,0,0,0,0,0,0,0,0,0,0
0,0,0,0,0,0,0,0,0,0,0,0,0,0,0,0,0,0,0,0,0,0,0,0,0,0,0,0,0,0,0,0,0,0,0,0,0,0,0,0,0
0,0,0,0,0,0,0,0,0,0,0,0,0,0,0,0,0,0,0,0,0,0,0,0,0,0,0,0,0,0,0,0,0,0,0,0,0,0,0,0,0
0,0,0,0,0,0,0,0,0,0,0,0,0,0,0,0,0,0,0,0,0,0,0,0,0,0,0,0,0,0,0,0,0,0,0,0,0,0,0,0,0
0,0,0,0,0,0,0,0,0,0,0,0,0,0,0,0,0,0,0,0,0,0,0,0,0,0,0,0,0,0,0,0,0,0,0,0,0,0,0,0,0
0,0,0,0,0,0,0,0,0,0,0,0,0,0,0,0,0,0,0,0,0,0,0,0,0,0,0,0,0,0,0,0,0,0,0,0,0,0,0,0,0
0,0,0,0,0,0,0,0,0,0,0,0,0,0,0,0,0,0,0,0,0,0,0,0,0,0,0,0,0,0,0,0,0,0,0,0,0,0,0,0,0
:endlayer
layer: 16
0,0,0,0,0,0,0,0,0,0,0,0,0,0,0,0,0,0,0,0,0,0,0,0,0,0,0,0,0,0,0,0,0,0,0,0,0,0,0,0,0
0,0,0,0,0,0,0,0,0,0,0,0,0,0,0,0,0,0,0,0,0,0,0,0,0,0,0,0,0,0,0,0,0,0,0,0,0,0,0,0,0
0,0,0,23,6,34,0,34,6,9,0,0,0,0,0,0,0,0,0,0,0,0,0,0,0,0,0,0,0,0,0,23,6,34,0,34,6,9,0,0,0
0,0,12,6,6,6,49,6,6,6,12,0,0,0,0,0,0,0,0,0,0,0,0,0,0,0,0,0,0,0,12,6,6,6,49,6,6,6,12,0,0
0,0,6,6,6,11,15,0,6,6,6,27,0,0,0,0,0,0,0,0,0,0,0,0,0,0,0,0,0,29,6,6,6,0,15,11,6,6,6,0,0
0,0,21,6,11,11,15,0,0,6,17,0,0,0,0,0,0,0,0,0,26,0,0,0,0,0,0,0,0,0,21,6,0,0,15,11,11,6,17,0,0
0,0,0,49,36,36,14,0,0,6,6,21,50,17,23,34,9,21,50,17,33,21,50,17,23,34,9,21,50,17,6,6,0,0,14,36,36,49,0,0,0
0,0,21,6,26,0,0,0,0,6,6,6,6,6,6,6,6,6,6,6,6,6,6,6,6,6,6,6,6,6,6,6,0,0,0,0,26,6,17,0,0
0,0,6,6,6,0,0,0,0,6,0,0,0,0,0,38,0,0,0,0,38,0,0,0,0,38,0,0,0,0,0,6,0,0,0,0,6,6,6,0,0
0,0,13,6,6,6,6,6,6,38,0,0,0,0,0,0,0,0,0,0,0,0,0,0,0,0,0,0,0,0,0,38,6,6,6,6,6,6,13,0,0
0,0,0,23,6,35,6,6,0,0,0,0,0,0,0,0,0,0,0,0,0,0,0,0,0,0,0,0,0,0,0,0,0,6,6,35,6,9,0,0,0
0,0,0,0,28,0,34,6,0,0,0,0,0,0,0,0,0,0,0,0,0,0,0,0,0,0,0,0,0,0,0,0,0,6,34,0,28,0,0,0,0
0,0,0,0,0,0,50,6,0,0,0,0,0,0,0,0,0,0,0,0,0,0,0,0,0,0,0,0,0,0,0,0,0,6,50,0,0,0,0,0,0
0,0,0,0,0,0,35,6,0,0,0,0,0,0,0,0,0,0,0,0,0,0,0,0,0,0,0,0,0,0,0,0,0,6,35,0,0,0,0,0,0
0,0,0,0,0,0,12,6,0,0,0,0,0,0,0,0,0,0,0,0,0,0,0,0,0,0,0,0,0,0,0,0,0,6,12,0,0,0,0,0,0
0,0,0,0,0,0,21,6,38,0,0,0,0,0,0,0,0,0,0,0,0,0,0,0,0,0,0,0,0,0,0,0,38,6,17,0,0,0,0,0,0
0,0,0,0,0,0,13,6,0,0,0,0,0,0,0,0,0,0,0,0,0,0,0,0,0,0,0,0,0,0,0,0,0,6,13,0,0,0,0,0,0
0,0,0,0,0,0,34,6,0,0,0,0,0,0,0,0,0,0,0,0,0,0,0,0,0,0,0,0,0,0,0,0,0,6,34,0,0,0,0,0,0
0,0,0,0,0,0,50,6,0,0,0,0,0,0,0,0,0,0,0,0,0,0,0,0,0,0,0,0,0,0,0,0,0,6,50,0,0,0,0,0,0
0,0,0,0,0,0,35,6,0,0,0,0,0,0,0,0,0,0,0,0,0,0,0,0,0,0,0,0,0,0,0,0,0,6,35,0,0,0,0,0,0
0,0,0,0,0,29,33,6,38,0,0,0,0,0,0,0,0,0,0,0,0,0,0,0,0,0,0,0,0,0,0,0,38,6,33,27,0,0,0,0,0
0,0,0,0,0,0,34,6,0,0,0,0,0,0,0,0,0,0,0,0,0,0,0,0,0,0,0,0,0,0,0,0,0,6,34,0,0,0,0,0,0
0,0,0,0,0,0,50,6,0,0,0,0,0,0,0,0,0,0,0,0,0,0,0,0,0,0,0,0,0,0,0,0,0,6,50,0,0,0,0,0,0
0,0,0,0,0,0,35,6,0,0,0,0,0,0,0,0,0,0,0,0,0,0,0,0,0,0,0,0,0,0,0,0,0,6,35,0,0,0,0,0,0
0,0,0,0,0,0,12,6,0,0,0,0,0,0,0,0,0,0,0,0,0,0,0,0,0,0,0,0,0,0,0,0,0,6,12,0,0,0,0,0,0
0,0,0,0,0,0,21,6,38,0,0,0,0,0,0,0,0,0,0,0,0,0,0,0,0,0,0,0,0,0,0,0,38,6,17,0,0,0,0,0,0
0,0,0,0,0,0,13,6,0,0,0,0,0,0,0,0,0,0,0,0,0,0,0,0,0,0,0,0,0,0,0,0,0,6,13,0,0,0,0,0,0
0,0,0,0,0,0,34,6,52,52,52,52,38,52,52,52,52,52,38,52,52,52,38,52,52,52,52,52,38,52,52,52,52,6,34,0,0,0,0,0,0
0,0,0,0,0,0,50,6,0,0,0,0,0,0,0,0,0,0,0,0,0,0,0,0,0,0,0,0,0,0,0,0,0,6,50,0,0,0,0,0,0
0,0,0,0,26,0,35,6,0,0,0,0,0,0,0,0,0,0,0,0,0,0,0,0,0,0,0,0,0,0,0,0,0,6,35,0,0,0,0,0,0
0,0,0,23,6,34,6,6,0,0,0,0,0,0,0,0,0,0,0,0,0,0,0,0,0,0,0,0,0,0,0,0,0,6,6,34,6,9,0,0,0
0,0,12,6,6,6,6,6,0,38,0,0,0,0,0,0,0,0,0,0,0,0,0,0,0,0,0,0,0,0,0,38,0,6,6,6,6,6,12,0,0
0,0,6,6,6,0,0,0,0,0,0,0,0,0,0,38,0,0,0,0,38,0,0,0,0,38,0,0,0,0,0,0,0,0,0,0,6,6,6,0,0
0,0,21,6,0,0,0,0,0,6,6,6,6,6,6,6,6,6,6,6,6,6,6,6,6,6,6,6,6,6,6,6,0,0,0,0,0,6,17,0,0
0,0,0,49,15,15,14,0,0,6,6,21,50,17,23,35,9,21,50,17,33,21,50,17,23,35,9,21,50,17,6,6,0,0,14,15,15,49,0,0,0
0,0,21,6,11,11,36,0,0,6,17,0,0,0,0,0,0,0,0,0,28,0,0,0,0,0,0,0,0,0,21,6,0,0,36,11,11,6,17,0,0
0,0,6,6,6,11,36,29,6,6,6,0,0,0,0,0,0,0,0,0,0,0,0,0,0,0,0,0,0,29,6,6,6,27,36,11,6,6,6,0,0
0,0,13,6,6,6,49,6,6,6,13,0,0,0,0,0,0,0,0,0,0,0,0,0,0,0,0,0,0,0,13,6,6,6,49,6,6,6,13,0,0
0,0,0,23,6,35,51,35,6,9,0,0,0,0,0,0,0,0,0,0,0,0,0,0,0,0,0,0,0,0,0,23,6,35,51,35,6,9,0,0,0
0,0,0,0,0,0,0,0,0,0,0,0,0,0,0,0,0,0,0,0,0,0,0,0,0,0,0,0,0,0,0,0,0,0,0,0,0,0,0,0,0
0,0,0,0,0,0,0,0,0,0,0,0,0,0,0,0,0,0,0,0,0,0,0,0,0,0,0,0,0,0,0,0,0,0,0,0,0,0,0,0,0
0,0,0,0,0,0,0,0,0,0,0,0,0,0,0,0,0,0,0,0,0,0,0,0,0,0,0,0,0,0,0,0,0,0,0,0,0,0,0,0,0
0,0,0,0,0,0,0,0,0,0,0,0,0,0,0,0,0,0,0,0,0,0,0,0,0,0,0,0,0,0,0,0,0,0,0,0,0,0,0,0,0
0,0,0,0,0,0,0,0,0,0,0,0,0,0,0,0,0,0,0,0,0,0,0,0,0,0,0,0,0,0,0,0,0,0,0,0,0,0,0,0,0
0,0,0,0,0,0,0,0,0,0,0,0,0,0,0,0,0,0,0,0,0,0,0,0,0,0,0,0,0,0,0,0,0,0,0,0,0,0,0,0,0
0,0,0,0,0,0,0,0,0,0,0,0,0,0,0,0,0,0,0,0,0,0,0,0,0,0,0,0,0,0,0,0,0,0,0,0,0,0,0,0,0
0,0,0,0,0,0,0,0,0,0,0,0,0,0,0,0,0,0,0,0,0,0,0,0,0,0,0,0,0,0,0,0,0,0,0,0,0,0,0,0,0
0,0,0,0,0,0,0,0,0,0,0,0,0,0,0,0,0,0,0,0,0,0,0,0,0,0,0,0,0,0,0,0,0,0,0,0,0,0,0,0,0
0,0,0,0,0,0,0,0,0,0,0,0,0,0,0,0,0,0,0,0,0,0,0,0,0,0,0,0,0,0,0,0,0,0,0,0,0,0,0,0,0
:endlayer
layer: 17
0,0,0,0,0,0,0,0,0,0,0,0,0,0,0,0,0,0,0,0,0,0,0,0,0,0,0,0,0,0,0,0,0,0,0,0,0,0,0,0,0
0,0,0,0,0,0,0,0,0,0,0,0,0,0,0,0,0,0,0,0,0,0,0,0,0,0,0,0,0,0,0,0,0,0,0,0,0,0,0,0,0
0,0,0,0,6,58,0,58,6,0,0,0,0,0,0,0,0,0,0,0,0,0,0,0,0,0,0,0,0,0,0,0,6,58,0,58,6,0,0,0,0
0,0,0,6,6,6,49,6,6,6,0,0,0,0,0,0,0,0,0,0,0,0,0,0,0,0,0,0,0,0,0,6,6,6,49,6,6,6,0,0,0
0,0,6,6,6,0,0,0,6,6,6,0,0,0,0,0,0,0,0,0,0,0,0,0,0,0,0,0,0,0,6,6,6,0,0,0,6,6,6,0,0
0,0,58,6,0,0,0,0,0,6,58,0,0,0,0,0,0,0,0,0,0,0,0,0,0,0,0,0,0,0,58,6,0,0,0,0,0,6,58,0,0
0,0,0,49,15,15,14,0,0,6,6,58,0,58,0,12,0,58,0,58,33,58,0,58,0,12,0,58,0,58,6,6,0,0,5,15,15,49,0,0,0
0,0,58,6,11,11,36,0,0,6,6,6,49,6,6,6,6,6,49,6,6,6,49,6,6,6,6,6,49,6,6,6,0,0,36,11,11,6,58,0,0
0,0,6,6,6,11,36,0,0,6,0,0,0,0,0,38,0,0,0,0,38,0,0,0,0,38,0,0,0,0,0,6,0,0,36,11,6,6,6,0,0
0,0,0,6,6,6,6,6,6,38,0,0,0,0,0,0,0,0,0,0,0,0,0,0,0,0,0,0,0,0,0,38,6,6,6,6,6,6,0,0,0
0,0,0,0,6,58,6,6,0,0,0,0,0,0,0,0,0,0,0,0,0,0,0,0,0,0,0,0,0,0,0,0,0,6,6,58,6,0,0,0,0
0,0,0,0,0,0,58,6,0,0,0,0,0,0,0,0,0,0,0,0,0,0,0,0,0,0,0,0,0,0,0,0,0,6,58,0,0,0,0,0,0
0,0,0,0,0,0,0,49,0,0,0,0,0,0,0,0,0,0,0,0,0,0,0,0,0,0,0,0,0,0,0,0,0,49,0,0,0,0,0,0,0
0,0,0,0,0,0,58,6,0,0,0,0,0,0,0,0,0,0,0,0,0,0,0,0,0,0,0,0,0,0,0,0,0,6,58,0,0,0,0,0,0
0,0,0,0,0,0,0,6,0,0,0,0,0,0,0,0,0,0,0,0,0,0,0,0,0,0,0,0,0,0,0,0,0,6,0,0,0,0,0,0,0
0,0,0,0,0,0,23,6,38,0,0,0,0,0,0,0,0,0,0,0,0,0,0,0,0,0,0,0,0,0,0,0,38,6,9,0,0,0,0,0,0
0,0,0,0,0,0,0,6,0,0,0,0,0,0,0,0,0,0,0,0,0,0,0,0,0,0,0,0,0,0,0,0,0,6,0,0,0,0,0,0,0
0,0,0,0,0,0,58,6,0,0,0,0,0,0,0,0,0,0,0,0,0,0,0,0,0,0,0,0,0,0,0,0,0,6,58,0,0,0,0,0,0
0,0,0,0,0,0,0,49,0,0,0,0,0,0,0,0,0,0,0,0,0,0,0,0,0,0,0,0,0,0,0,0,0,49,0,0,0,0,0,0,0
0,0,0,0,0,0,58,6,0,0,0,0,0,0,0,0,0,0,0,0,0,0,0,0,0,0,0,0,0,0,0,0,0,6,58,0,0,0,0,0,0
0,0,0,0,0,0,33,6,38,0,0,0,0,0,0,0,0,0,0,0,0,0,0,0,0,0,0,0,0,0,0,0,38,6,33,0,0,0,0,0,0
0,0,0,0,0,0,58,6,0,0,0,0,0,0,0,0,0,0,0,0,0,0,0,0,0,0,0,0,0,0,0,0,0,6,58,0,0,0,0,0,0
0,0,0,0,0,0,0,49,0,0,0,0,0,0,0,0,0,0,0,0,0,0,0,0,0,0,0,0,0,0,0,0,0,49,0,0,0,0,0,0,0
0,0,0,0,0,0,58,6,0,0,0,0,0,0,0,0,0,0,0,0,0,0,0,0,0,0,0,0,0,0,0,0,0,6,58,0,0,0,0,0,0
0,0,0,0,0,0,0,6,0,0,0,0,0,0,0,0,0,0,0,0,0,0,0,0,0,0,0,0,0,0,0,0,0,6,0,0,0,0,0,0,0
0,0,0,0,0,0,23,6,38,0,0,0,0,0,0,0,0,0,0,0,0,0,0,0,0,0,0,0,0,0,0,0,38,6,9,0,0,0,0,0,0
0,0,0,0,0,0,0,6,0,0,0,0,0,0,0,0,0,0,0,0,0,0,0,0,0,0,0,0,0,0,0,0,0,6,0,0,0,0,0,0,0
0,0,0,0,0,0,58,6,0,0,0,0,38,0,0,0,0,0,38,0,0,0,38,0,0,0,0,0,38,0,0,0,0,6,58,0,0,0,0,0,0
0,0,0,0,0,0,0,49,0,0,0,0,0,0,0,0,0,0,0,0,0,0,0,0,0,0,0,0,0,0,0,0,0,49,0,0,0,0,0,0,0
0,0,0,0,0,0,58,6,0,0,0,0,0,0,0,0,0,0,0,0,0,0,0,0,0,0,0,0,0,0,0,0,0,6,58,0,0,0,0,0,0
0,0,0,0,6,58,6,6,0,0,0,0,0,0,0,0,0,0,0,0,0,0,0,0,0,0,0,0,0,0,0,0,0,6,6,58,6,0,0,0,0
0,0,0,6,6,6,6,6,0,38,0,0,0,0,0,26,0,0,0,0,26,0,0,0,0,26,0,0,0,0,0,38,0,6,6,6,6,6,0,0,0
0,0,6,6,6,0,0,0,0,0,0,0,0,0,0,38,0,0,0,0,38,0,0,0,0,38,0,0,0,0,0,0,0,0,0,0,6,6,6,0,0
0,0,58,6,0,0,0,0,0,6,6,6,49,6,6,6,6,6,49,6,6,6,49,6,6,6,6,6,49,6,6,6,0,0,0,0,0,6,58,0,0
0,0,0,49,0,0,14,36,36,6,6,58,0,58,0,13,0,58,0,58,33,58,0,58,0,13,0,58,0,58,6,6,36,36,14,0,0,49,0,0,0
0,0,58,6,0,0,15,11,11,6,58,0,0,0,0,0,0,0,0,0,0,0,0,0,0,0,0,0,0,0,58,6,11,11,15,0,0,6,58,0,0
0,0,6,6,6,0,15,11,6,6,6,27,0,0,0,0,0,0,0,0,0,0,0,0,0,0,0,0,0,0,6,6,6,11,15,0,6,6,6,0,0
0,0,0,6,6,6,49,6,6,6,0,0,0,0,0,0,0,0,0,0,0,0,0,0,0,0,0,0,0,0,0,6,6,6,49,6,6,6,0,0,0
0,0,0,0,6,58,0,58,6,0,0,0,0,0,0,0,0,0,0,0,0,0,0,0,0,0,0,0,0,0,0,0,6,58,0,58,6,0,0,0,0
0,0,0,0,0,0,0,0,0,0,0,0,0,0,0,0,0,0,0,0,0,0,0,0,0,0,0,0,0,0,0,0,0,0,0,0,0,0,0,0,0
0,0,0,0,0,0,0,0,0,0,0,0,0,0,0,0,0,0,0,0,0,0,0,0,0,0,0,0,0,0,0,0,0,0,0,0,0,0,0,0,0
0,0,0,0,0,0,0,0,0,0,0,0,0,0,0,0,0,0,0,0,0,0,0,0,0,0,0,0,0,0,0,0,0,0,0,0,0,0,0,0,0
0,0,0,0,0,0,0,0,0,0,0,0,0,0,0,0,0,0,0,0,0,0,0,0,0,0,0,0,0,0,0,0,0,0,0,0,0,0,0,0,0
0,0,0,0,0,0,0,0,0,0,0,0,0,0,0,0,0,0,0,0,0,0,0,0,0,0,0,0,0,0,0,0,0,0,0,0,0,0,0,0,0
0,0,0,0,0,0,0,0,0,0,0,0,0,0,0,0,0,0,0,0,0,0,0,0,0,0,0,0,0,0,0,0,0,0,0,0,0,0,0,0,0
0,0,0,0,0,0,0,0,0,0,0,0,0,0,0,0,0,0,0,0,0,0,0,0,0,0,0,0,0,0,0,0,0,0,0,0,0,0,0,0,0
0,0,0,0,0,0,0,0,0,0,0,0,0,0,0,0,0,0,0,0,0,0,0,0,0,0,0,0,0,0,0,0,0,0,0,0,0,0,0,0,0
0,0,0,0,0,0,0,0,0,0,0,0,0,0,0,0,0,0,0,0,0,0,0,0,0,0,0,0,0,0,0,0,0,0,0,0,0,0,0,0,0
0,0,0,0,0,0,0,0,0,0,0,0,0,0,0,0,0,0,0,0,0,0,0,0,0,0,0,0,0,0,0,0,0,0,0,0,0,0,0,0,0
:endlayer
layer: 18
0,0,0,0,0,0,0,0,0,0,0,0,0,0,0,0,0,0,0,0,0,0,0,0,0,0,0,0,0,0,0,0,0,0,0,0,0,0,0,0,0
0,0,0,0,26,0,0,0,26,0,0,0,0,0,0,0,0,0,0,0,0,0,0,0,0,0,0,0,0,0,0,0,26,0,0,0,26,0,0,0,0
0,0,0,21,6,12,0,12,6,17,0,0,0,0,0,0,0,0,0,0,0,0,0,0,0,0,0,0,0,0,0,21,6,12,0,12,6,17,0,0,0
0,0,34,6,6,6,49,6,6,6,34,0,0,0,0,0,0,0,0,0,0,0,0,0,0,0,0,0,0,0,34,6,6,6,49,6,6,6,34,0,0
0,29,6,6,6,0,0,0,6,6,6,0,0,0,0,0,0,0,0,0,0,0,0,0,0,0,0,0,0,0,6,6,6,0,0,0,6,6,6,27,0
0,0,23,6,0,0,0,0,28,6,9,0,0,0,0,0,0,0,0,0,0,0,0,0,0,0,0,0,0,0,23,6,28,0,0,0,0,6,9,0,0
0,0,0,49,0,0,14,36,36,6,6,58,0,58,0,58,0,58,0,58,33,58,0,58,0,58,0,58,0,58,6,6,36,36,14,0,0,49,0,0,0
0,0,23,6,0,0,15,11,11,6,6,6,49,6,6,6,6,6,49,6,6,6,49,6,6,6,6,6,49,6,6,6,11,11,15,0,0,6,9,0,0
0,29,6,6,6,0,15,11,11,6,0,0,0,0,0,38,0,0,0,0,38,0,0,0,0,38,0,0,0,0,0,6,11,11,15,0,6,6,6,27,0
0,0,35,6,6,6,6,6,6,38,0,0,0,0,0,0,0,0,0,0,0,0,0,0,0,0,0,0,0,0,0,38,6,6,6,6,6,6,35,0,0
0,0,0,21,6,13,6,6,0,0,0,0,0,0,0,0,0,0,0,0,0,0,0,0,0,0,0,0,0,0,0,0,0,6,6,13,6,17,0,0,0
0,0,0,0,0,0,58,6,0,0,0,0,0,0,0,0,0,0,0,0,0,0,0,0,0,0,0,0,0,0,0,0,0,6,58,0,0,0,0,0,0
0,0,0,0,0,0,0,49,0,0,0,0,0,0,0,0,0,0,0,0,0,0,0,0,0,0,0,0,0,0,0,0,0,49,0,0,0,0,0,0,0
0,0,0,0,0,0,58,6,0,0,0,0,0,0,0,0,0,0,0,0,0,0,0,0,0,0,0,0,0,0,0,0,0,6,58,0,0,0,0,0,0
0,0,0,0,0,0,0,6,0,0,0,0,0,0,0,0,0,0,0,0,0,0,0,0,0,0,0,0,0,0,0,0,0,6,0,0,0,0,0,0,0
0,0,0,0,0,0,58,6,38,0,0,0,0,0,0,0,0,0,0,0,0,0,0,0,0,0,0,0,0,0,0,0,38,6,58,0,0,0,0,0,0
0,0,0,0,0,0,0,6,0,0,0,0,0,0,0,0,0,0,0,0,0,0,0,0,0,0,0,0,0,0,0,0,0,6,0,0,0,0,0,0,0
0,0,0,0,0,0,58,6,0,0,0,0,0,0,0,0,0,0,0,0,0,0,0,0,0,0,0,0,0,0,0,0,0,6,58,0,0,0,0,0,0
0,0,0,0,0,0,0,49,0,0,0,0,0,0,0,0,0,0,0,0,0,0,0,0,0,0,0,0,0,0,0,0,0,49,0,0,0,0,0,0,0
0,0,0,0,0,0,58,6,0,0,0,0,0,0,0,0,0,0,0,0,0,0,0,0,0,0,0,0,0,0,0,0,0,6,58,0,0,0,0,0,0
0,0,0,0,0,0,33,6,38,0,0,0,0,0,0,0,0,0,0,0,0,0,0,0,0,0,0,0,0,0,0,0,38,6,33,0,0,0,0,0,0
0,0,0,0,0,0,58,6,0,0,0,0,0,0,0,0,0,0,0,0,0,0,0,0,0,0,0,0,0,0,0,0,0,6,58,0,0,0,0,0,0
0,0,0,0,0,0,0,49,0,0,0,0,0,0,0,0,0,0,0,0,0,0,0,0,0,0,0,0,0,0,0,0,0,49,0,0,0,0,0,0,0
0,0,0,0,0,0,58,6,0,0,0,0,0,0,0,0,0,0,0,0,0,0,0,0,0,0,0,0,0,0,0,0,0,6,58,0,0,0,0,0,0
0,0,0,0,0,0,0,6,0,0,0,0,0,0,0,0,0,0,0,0,0,0,0,0,0,0,0,0,0,0,0,0,0,6,0,0,0,0,0,0,0
0,0,0,0,0,0,58,6,38,0,0,0,0,0,0,0,0,0,0,0,0,0,0,0,0,0,0,0,0,0,0,0,38,6,58,0,0,0,0,0,0
0,0,0,0,0,0,0,6,0,0,0,0,0,0,0,0,0,0,0,0,0,0,0,0,0,0,0,0,0,0,0,0,0,6,0,0,0,0,0,0,0
0,0,0,0,0,0,58,6,0,0,0,0,38,0,0,0,0,0,38,0,0,0,38,0,0,0,0,0,38,0,0,0,0,6,58,0,0,0,0,0,0
0,0,0,0,0,0,0,49,0,0,0,0,0,0,0,0,0,0,0,0,0,0,0,0,0,0,0,0,0,0,0,0,0,49,0,0,0,0,0,0,0
0,0,0,0,0,0,58,6,0,0,0,0,0,0,0,0,0,0,0,0,0,0,0,0,0,0,0,0,0,0,0,0,0,6,58,0,0,0,0,0,0
0,0,0,21,6,12,6,6,0,0,0,0,0,0,0,0,0,0,0,0,0,0,0,0,0,0,0,0,0,0,0,0,0,6,6,12,6,17,0,0,0
0,0,34,6,6,6,6,6,0,38,0,0,0,0,0,0,0,0,0,0,0,0,0,0,0,0,0,0,0,0,0,38,0,6,6,6,6,6,34,0,0
0,29,6,6,6,27,36,11,11,0,0,0,0,0,0,38,0,0,0,0,38,0,0,0,0,38,0,0,0,0,0,0,11,11,36,29,6,6,6,27,0
0,0,23,6,0,0,36,11,11,6,6,6,49,6,6,6,6,6,49,6,6,6,49,6,6,6,6,6,49,6,6,6,11,11,36,0,0,6,9,0,0
0,0,0,49,0,0,14,15,15,6,6,58,0,58,0,58,0,58,0,58,33,58,0,58,0,58,0,58,0,58,6,6,15,15,14,0,0,49,0,0,0
0,0,23,6,0,0,0,0,0,6,9,0,0,0,0,0,0,0,0,0,0,0,0,0,0,0,0,0,0,0,23,6,0,0,0,0,0,6,9,0,0
0,29,6,6,6,0,0,0,6,6,6,0,0,0,0,0,0,0,0,0,0,0,0,0,0,0,0,0,0,0,6,6,6,0,0,0,6,6,6,27,0
0,0,35,6,6,6,49,6,6,6,35,0,0,0,0,0,0,0,0,0,0,0,0,0,0,0,0,0,0,0,35,6,6,6,49,6,6,6,35,0,0
0,0,0,21,6,13,0,13,6,17,0,0,0,0,0,0,0,0,0,0,0,0,0,0,0,0,0,0,0,0,0,21,6,13,0,13,6,17,0,0,0
0,0,0,0,0,0,0,0,0,0,0,0,0,0,0,0,0,0,0,0,0,0,0,0,0,0,0,0,0,0,0,0,0,0,0,0,0,0,0,0,0
0,0,0,0,0,0,0,0,0,0,0,0,0,0,0,0,0,0,0,0,0,0,0,0,0,0,0,0,0,0,0,0,0,0,0,0,0,0,0,0,0
0,0,0,0,0,0,0,0,0,0,0,0,0,0,0,0,0,0,0,0,0,0,0,0,0,0,0,0,0,0,0,0,0,0,0,0,0,0,0,0,0
0,0,0,0,0,0,0,0,0,0,0,0,0,0,0,0,0,0,0,0,0,0,0,0,0,0,0,0,0,0,0,0,0,0,0,0,0,0,0,0,0
0,0,0,0,0,0,0,0,0,0,0,0,0,0,0,0,0,0,0,0,0,0,0,0,0,0,0,0,0,0,0,0,0,0,0,0,0,0,0,0,0
0,0,0,0,0,0,0,0,0,0,0,0,0,0,0,0,0,0,0,0,0,0,0,0,0,0,0,0,0,0,0,0,0,0,0,0,0,0,0,0,0
0,0,0,0,0,0,0,0,0,0,0,0,0,0,0,0,0,0,0,0,0,0,0,0,0,0,0,0,0,0,0,0,0,0,0,0,0,0,0,0,0
0,0,0,0,0,0,0,0,0,0,0,0,0,0,0,0,0,0,0,0,0,0,0,0,0,0,0,0,0,0,0,0,0,0,0,0,0,0,0,0,0
0,0,0,0,0,0,0,0,0,0,0,0,0,0,0,0,0,0,0,0,0,0,0,0,0,0,0,0,0,0,0,0,0,0,0,0,0,0,0,0,0
0,0,0,0,0,0,0,0,0,0,0,0,0,0,0,0,0,0,0,0,0,0,0,0,0,0,0,0,0,0,0,0,0,0,0,0,0,0,0,0,0
:endlayer
layer: 19
0,0,0,0,0,0,0,0,0,0,0,0,0,0,0,0,0,0,0,0,0,0,0,0,0,0,0,0,0,0,0,0,0,0,0,0,0,0,0,0,0
0,0,0,0,0,0,0,0,0,0,0,0,0,0,0,0,0,0,0,0,0,0,0,0,0,0,0,0,0,0,0,0,0,0,0,0,0,0,0,0,0
0,0,0,23,6,17,12,21,6,9,0,0,0,0,0,0,0,0,0,0,0,0,0,0,0,0,0,0,0,0,0,23,6,17,12,21,6,9,0,0,0
0,0,12,6,6,6,6,6,6,6,12,0,0,0,0,0,0,0,0,0,0,0,0,0,0,0,0,0,0,0,12,6,6,6,6,6,6,6,12,0,0
0,0,6,6,6,0,36,11,6,6,6,0,0,0,0,0,0,0,0,0,0,0,0,0,0,0,0,0,0,0,6,6,6,11,36,0,6,6,6,0,0
0,0,35,6,0,0,36,11,11,6,35,0,0,0,0,0,0,0,0,0,0,0,0,0,0,0,0,0,0,0,35,6,11,11,36,0,0,6,35,0,0
0,0,23,6,0,0,14,15,15,6,6,23,50,9,0,34,0,23,50,9,33,23,50,9,0,34,0,23,50,9,6,6,15,15,14,0,0,6,9,0,0
0,0,34,6,0,0,0,0,0,6,6,6,6,6,6,6,6,6,6,6,6,6,6,6,6,6,6,6,6,6,6,6,0,0,0,0,0,6,34,0,0
0,0,6,6,6,0,0,0,0,6,0,0,28,0,0,38,0,0,28,0,38,0,28,0,0,38,0,0,28,0,0,6,0,0,0,0,6,6,6,0,0
0,0,13,6,6,6,6,6,6,38,0,0,0,0,0,0,0,0,0,0,0,0,0,0,0,0,0,0,0,0,0,38,6,6,6,6,6,6,13,0,0
0,0,0,23,6,17,6,6,0,0,0,0,0,0,0,0,0,0,0,0,0,0,0,0,0,0,0,0,0,0,0,0,0,6,6,21,6,9,0,0,0
0,0,0,0,0,0,12,6,0,0,0,0,0,0,0,0,0,0,0,0,0,0,0,0,0,0,0,0,0,0,0,0,0,6,12,0,0,0,0,0,0
0,0,0,0,0,0,50,6,27,0,0,0,0,0,0,0,0,0,0,0,0,0,0,0,0,0,0,0,0,0,0,0,29,6,50,0,0,0,0,0,0
0,0,0,0,0,0,13,6,0,0,0,0,0,0,0,0,0,0,0,0,0,0,0,0,0,0,0,0,0,0,0,0,0,6,13,0,0,0,0,0,0
0,0,0,0,0,0,0,6,0,0,0,0,0,0,0,0,0,0,0,0,0,0,0,0,0,0,0,0,0,0,0,0,0,6,0,0,0,0,0,0,0
0,0,0,0,0,0,21,6,38,0,0,0,0,0,0,0,0,0,0,0,0,0,0,0,0,0,0,0,0,0,0,0,38,6,17,0,0,0,0,0,0
0,0,0,0,0,0,0,6,0,0,0,0,0,0,0,0,0,0,0,0,0,0,0,0,0,0,0,0,0,0,0,0,0,6,0,0,0,0,0,0,0
0,0,0,0,0,0,12,6,0,0,0,0,0,0,0,0,0,0,0,0,0,0,0,0,0,0,0,0,0,0,0,0,0,6,12,0,0,0,0,0,0
0,0,0,0,0,0,50,6,27,0,0,0,0,0,0,0,0,0,0,0,0,0,0,0,0,0,0,0,0,0,0,0,29,6,50,0,0,0,0,0,0
0,0,0,0,0,0,13,6,0,0,0,0,0,0,0,0,0,0,0,0,0,0,0,0,0,0,0,0,0,0,0,0,0,6,13,0,0,0,0,0,0
0,0,0,0,0,0,33,6,38,0,0,0,0,0,0,0,0,0,0,0,0,0,0,0,0,0,0,0,0,0,0,0,38,6,33,0,0,0,0,0,0
0,0,0,0,0,0,12,6,0,0,0,0,0,0,0,0,0,0,0,0,0,0,0,0,0,0,0,0,0,0,0,0,0,6,12,0,0,0,0,0,0
0,0,0,0,0,0,50,6,27,0,0,0,0,0,0,0,0,0,0,0,0,0,0,0,0,0,0,0,0,0,0,0,29,6,50,0,0,0,0,0,0
0,0,0,0,0,0,13,6,0,0,0,0,0,0,0,0,0,0,0,0,0,0,0,0,0,0,0,0,0,0,0,0,0,6,13,0,0,0,0,0,0
0,0,0,0,0,0,0,6,0,0,0,0,0,0,0,0,0,0,0,0,0,0,0,0,0,0,0,0,0,0,0,0,0,6,0,0,0,0,0,0,0
0,0,0,0,0,0,21,6,38,0,0,0,0,0,0,0,0,0,0,0,0,0,0,0,0,0,0,0,0,0,0,0,38,6,17,0,0,0,0,0,0
0,0,0,0,0,0,0,6,0,0,0,0,26,0,0,0,0,0,26,0,0,0,26,0,0,0,0,0,26,0,0,0,0,6,0,0,0,0,0,0,0
0,0,0,0,0,0,12,6,0,0,0,0,38,0,0,0,0,0,38,0,0,0,38,0,0,0,0,0,38,0,0,0,0,6,12,0,0,0,0,0,0
0,0,0,0,0,0,50,6,27,0,0,0,28,0,0,0,0,0,28,0,0,0,28,0,0,0,0,0,28,0,0,0,29,6,50,0,0,0,0,0,0
0,0,0,0,0,0,13,6,26,0,0,0,0,0,0,0,0,0,0,0,0,0,0,0,0,0,0,0,0,0,0,0,26,6,13,0,0,0,0,0,0
0,0,0,23,6,17,6,6,6,27,0,0,0,0,0,0,0,0,0,0,0,0,0,0,0,0,0,0,0,0,0,29,6,6,6,21,6,9,0,0,0
0,0,12,6,6,6,6,6,6,38,26,0,0,0,0,26,0,0,0,0,26,0,0,0,0,26,0,0,0,0,26,38,6,6,6,6,6,6,12,0,0
0,0,6,6,6,11,15,0,0,6,6,27,26,0,0,38,0,0,26,0,38,0,26,0,0,38,0,0,26,29,6,6,0,0,15,11,6,6,6,0,0
0,0,35,6,11,11,15,0,0,6,6,6,6,6,6,6,6,6,6,6,6,6,6,6,6,6,6,6,6,6,6,6,0,0,15,11,11,6,35,0,0
0,0,23,6,36,36,14,0,0,6,6,23,50,9,0,35,0,23,50,9,33,23,50,9,0,35,0,23,50,9,6,6,0,0,14,36,36,6,9,0,0
0,0,34,6,26,0,0,0,0,6,34,0,0,0,0,0,0,0,0,0,0,0,0,0,0,0,0,0,0,0,34,6,0,0,0,0,0,6,34,0,0
0,0,6,6,6,0,0,0,6,6,6,0,0,0,0,0,0,0,0,0,0,0,0,0,0,0,0,0,0,0,6,6,6,0,0,0,6,6,6,0,0
0,0,13,6,6,6,6,6,6,6,13,0,0,0,0,0,0,0,0,0,0,0,0,0,0,0,0,0,0,0,13,6,6,6,6,6,6,6,13,0,0
0,0,0,23,6,17,13,21,6,9,0,0,0,0,0,0,0,0,0,0,0,0,0,0,0,0,0,0,0,0,0,23,6,17,13,21,6,9,0,0,0
0,0,0,0,0,0,0,0,0,0,0,0,0,0,0,0,0,0,0,0,0,0,0,0,0,0,0,0,0,0,0,0,0,0,0,0,0,0,0,0,0
0,0,0,0,0,0,0,0,0,0,0,0,0,0,0,0,0,0,0,0,0,0,0,0,0,0,0,0,0,0,0,0,0,0,0,0,0,0,0,0,0
0,0,0,0,0,0,0,0,0,0,0,0,0,0,0,0,0,0,0,0,0,0,0,0,0,0,0,0,0,0,0,0,0,0,0,0,0,0,0,0,0
0,0,0,0,0,0,0,0,0,0,0,0,0,0,0,0,0,0,0,0,0,0,0,0,0,0,0,0,0,0,0,0,0,0,0,0,0,0,0,0,0
0,0,0,0,0,0,0,0,0,0,0,0,0,0,0,0,0,0,0,0,0,0,0,0,0,0,0,0,0,0,0,0,0,0,0,0,0,0,0,0,0
0,0,0,0,0,0,0,0,0,0,0,0,0,0,0,0,0,0,0,0,0,0,0,0,0,0,0,0,0,0,0,0,0,0,0,0,0,0,0,0,0
0,0,0,0,0,0,0,0,0,0,0,0,0,0,0,0,0,0,0,0,0,0,0,0,0,0,0,0,0,0,0,0,0,0,0,0,0,0,0,0,0
0,0,0,0,0,0,0,0,0,0,0,0,0,0,0,0,0,0,0,0,0,0,0,0,0,0,0,0,0,0,0,0,0,0,0,0,0,0,0,0,0
0,0,0,0,0,0,0,0,0,0,0,0,0,0,0,0,0,0,0,0,0,0,0,0,0,0,0,0,0,0,0,0,0,0,0,0,0,0,0,0,0
0,0,0,0,0,0,0,0,0,0,0,0,0,0,0,0,0,0,0,0,0,0,0,0,0,0,0,0,0,0,0,0,0,0,0,0,0,0,0,0,0
:endlayer
layer: 20
0,0,0,0,0,0,0,0,0,0,0,0,0,0,0,0,0,0,0,0,0,0,0,0,0,0,0,0,0,0,0,0,0,0,0,0,0,0,0,0,0
0,0,0,0,32,32,32,32,32,0,0,0,0,0,0,0,0,0,0,0,0,0,0,0,0,0,0,0,0,0,0,0,32,32,32,32,32,0,0,0,0
0,0,0,32,6,6,33,6,6,32,0,0,0,0,0,0,0,0,0,0,0,0,0,0,0,0,0,0,0,0,0,32,6,6,33,6,6,32,0,0,0
0,0,32,6,6,6,6,6,6,6,32,0,0,0,0,0,0,0,0,0,0,0,0,0,0,0,0,0,0,0,32,6,6,6,6,6,6,6,32,0,0
0,32,6,6,6,11,15,0,6,6,6,32,0,0,0,0,0,0,0,0,0,0,0,0,0,0,0,0,0,32,6,6,6,0,15,11,6,6,6,32,0
0,32,6,6,11,11,15,0,0,6,6,32,32,32,0,0,0,32,32,32,0,32,32,32,0,0,0,32,32,32,6,6,0,0,15,11,11,6,6,32,0
0,32,33,6,36,36,14,0,0,6,6,6,6,6,21,12,17,6,6,6,33,6,6,6,21,12,17,6,6,6,6,6,0,0,14,36,36,6,33,32,0
0,32,6,6,26,0,0,0,0,6,6,6,6,6,6,6,6,6,6,6,6,6,6,6,6,6,6,6,6,6,6,6,0,0,0,0,26,6,6,32,0
0,32,6,6,6,0,0,0,0,6,66,66,65,66,66,66,66,66,65,66,66,66,65,66,66,66,66,66,65,66,66,6,0,0,0,0,6,6,6,32,0
0,0,32,6,6,6,6,6,6,38,0,0,65,0,0,0,0,0,65,0,0,0,65,0,0,0,0,0,65,0,0,38,6,6,6,6,6,6,32,0,0
0,0,0,32,6,6,6,6,65,0,0,0,65,0,0,0,0,0,65,0,0,0,65,0,0,0,0,0,65,0,0,0,65,6,6,6,6,32,0,0,0
0,0,0,0,32,32,6,6,65,0,0,0,65,0,0,0,0,0,65,0,0,0,65,0,0,0,0,0,65,0,0,0,65,6,6,32,32,0,0,0,0
0,0,0,0,0,32,6,6,65,66,66,66,65,66,66,66,66,66,65,66,66,66,65,66,66,66,66,66,65,66,66,66,65,6,6,32,0,0,0,0,0
0,0,0,0,0,32,6,6,65,0,0,0,65,0,0,0,0,0,65,0,0,0,65,0,0,0,0,0,65,0,0,0,65,6,6,32,0,0,0,0,0
0,0,0,0,0,0,34,6,65,0,0,0,65,0,0,0,0,0,65,0,0,0,65,0,0,0,0,0,65,0,0,0,65,6,34,0,0,0,0,0,0
0,0,0,0,0,0,23,6,65,0,0,0,65,0,0,0,0,0,65,0,0,0,65,0,0,0,0,0,65,0,0,0,65,6,9,0,0,0,0,0,0
0,0,0,0,0,0,35,6,65,0,0,0,65,0,0,0,0,0,65,0,0,0,65,0,0,0,0,0,65,0,0,0,65,6,35,0,0,0,0,0,0
0,0,0,0,0,32,6,6,65,0,0,0,65,0,0,0,0,0,65,0,0,0,65,0,0,0,0,0,65,0,0,0,65,6,6,32,0,0,0,0,0
0,0,0,0,0,32,6,6,65,66,66,66,65,66,66,66,66,66,65,66,66,66,65,66,66,66,66,66,65,66,66,66,65,6,6,32,0,0,0,0,0
0,0,0,0,0,32,6,6,65,0,0,0,65,0,0,0,0,0,65,0,0,0,65,0,0,0,0,0,65,0,0,0,65,6,6,32,0,0,0,0,0
0,0,0,0,0,0,33,6,65,0,0,0,65,0,0,0,0,0,65,0,0,0,65,0,0,0,0,0,65,0,0,0,65,6,33,0,0,0,0,0,0
0,0,0,0,0,32,6,6,65,0,0,0,65,0,0,0,0,0,65,0,0,0,65,0,0,0,0,0,65,0,0,0,65,6,6,32,0,0,0,0,0
0,0,0,0,0,32,6,6,65,66,66,66,65,66,66,66,66,66,65,66,66,66,65,66,66,66,66,66,65,66,66,66,65,6,6,32,0,0,0,0,0
0,0,0,0,0,32,6,6,65,0,0,0,65,0,0,0,0,0,65,0,0,0,65,0,0,0,0,0,65,0,0,0,65,6,6,32,0,0,0,0,0
0,0,0,0,0,0,34,6,65,0,0,0,65,0,0,0,0,0,65,0,0,0,65,0,0,0,0,0,65,0,0,0,65,6,34,0,0,0,0,0,0
0,0,0,0,0,0,23,6,65,0,0,0,65,0,0,0,0,0,65,0,0,0,65,0,0,0,0,0,65,0,0,0,65,6,9,0,0,0,0,0,0
0,0,0,0,0,0,35,6,65,0,0,0,65,0,0,0,0,0,65,0,0,0,65,0,0,0,0,0,65,0,0,0,65,6,35,0,0,0,0,0,0
0,0,0,0,0,32,6,6,66,66,66,66,65,66,66,66,66,66,65,66,66,66,65,66,66,66,66,66,65,66,66,66,66,6,6,32,0,0,0,0,0
0,0,0,0,0,32,6,6,65,0,0,0,65,0,0,0,0,0,65,0,0,0,65,0,0,0,0,0,65,0,0,0,65,6,6,32,0,0,0,0,0
0,0,0,0,32,32,6,6,65,0,0,0,65,0,0,0,0,0,65,0,0,0,65,0,0,0,0,0,65,0,0,0,65,6,6,32,32,0,0,0,0
0,0,0,32,6,6,6,6,65,0,0,0,65,0,0,0,0,0,65,0,0,0,65,0,0,0,0,0,65,0,0,0,65,6,6,6,6,32,0,0,0
0,0,32,6,6,6,6,6,6,38,0,0,65,0,0,0,0,0,65,0,0,0,65,0,0,0,0,0,65,0,0,38,6,6,6,6,6,6,32,0,0
0,32,6,6,6,0,0,0,0,6,66,66,65,66,66,66,66,66,65,66,66,66,65,66,66,66,66,66,65,66,66,6,0,0,0,0,6,6,6,32,0
0,32,6,6,0,0,0,0,0,6,6,6,6,6,6,6,6,6,6,6,6,6,6,6,6,6,6,6,6,6,6,6,0,0,0,0,0,6,6,32,0
0,32,33,6,15,15,14,0,0,6,6,6,6,6,21,13,17,6,6,6,33,6,6,6,21,13,17,6,6,6,6,6,0,0,14,15,15,6,33,32,0
0,32,6,6,11,11,36,0,26,6,6,32,32,32,0,0,0,32,32,32,0,32,32,32,0,0,0,32,32,32,6,6,0,0,36,11,11,6,6,32,0
0,32,6,6,6,11,36,0,6,6,6,32,0,0,0,0,0,0,0,0,0,0,0,0,0,0,0,0,0,32,6,6,6,27,36,11,6,6,6,32,0
0,0,32,6,6,6,6,6,6,6,32,0,0,0,0,0,0,0,0,0,0,0,0,0,0,0,0,0,0,0,32,6,6,6,6,6,6,6,32,0,0
0,0,0,32,6,6,33,6,6,32,0,0,0,0,0,0,0,0,0,0,0,0,0,0,0,0,0,0,0,0,0,32,6,6,33,6,6,32,0,0,0
0,0,0,0,32,32,32,32,32,0,0,0,0,0,0,0,0,0,0,0,0,0,0,0,0,0,0,0,0,0,0,0,32,32,32,32,32,0,0,0,0
0,0,0,0,0,0,0,0,0,0,0,0,0,0,0,0,0,0,0,0,0,0,0,0,0,0,0,0,0,0,0,0,0,0,0,0,0,0,0,0,0
0,0,0,0,0,0,0,0,0,0,0,0,0,0,0,0,0,0,0,0,0,0,0,0,0,0,0,0,0,0,0,0,0,0,0,0,0,0,0,0,0
0,0,0,0,0,0,0,0,0,0,0,0,0,0,0,0,0,0,0,0,0,0,0,0,0,0,0,0,0,0,0,0,0,0,0,0,0,0,0,0,0
0,0,0,0,0,0,0,0,0,0,0,0,0,0,0,0,0,0,0,0,0,0,0,0,0,0,0,0,0,0,0,0,0,0,0,0,0,0,0,0,0
0,0,0,0,0,0,0,0,0,0,0,0,0,0,0,0,0,0,0,0,0,0,0,0,0,0,0,0,0,0,0,0,0,0,0,0,0,0,0,0,0
0,0,0,0,0,0,0,0,0,0,0,0,0,0,0,0,0,0,0,0,0,0,0,0,0,0,0,0,0,0,0,0,0,0,0,0,0,0,0,0,0
0,0,0,0,0,0,0,0,0,0,0,0,0,0,0,0,0,0,0,0,0,0,0,0,0,0,0,0,0,0,0,0,0,0,0,0,0,0,0,0,0
0,0,0,0,0,0,0,0,0,0,0,0,0,0,0,0,0,0,0,0,0,0,0,0,0,0,0,0,0,0,0,0,0,0,0,0,0,0,0,0,0
0,0,0,0,0,0,0,0,0,0,0,0,0,0,0,0,0,0,0,0,0,0,0,0,0,0,0,0,0,0,0,0,0,0,0,0,0,0,0,0,0
:endlayer
layer: 21
0,0,0,0,0,0,0,0,0,0,0,0,0,0,0,0,0,0,0,0,0,0,0,0,0,0,0,0,0,0,0,0,0,0,0,0,0,0,0,0,0
0,0,0,0,0,0,0,0,0,0,0,0,0,0,0,0,0,0,0,0,0,0,0,0,0,0,0,0,0,0,0,0,0,0,0,0,0,0,0,0,0
0,0,0,21,6,9,34,23,6,17,0,0,0,0,0,0,0,0,0,0,0,0,0,0,0,0,0,0,0,0,0,21,6,9,34,23,6,17,0,0,0
0,0,34,6,6,6,6,6,6,6,34,0,0,0,0,0,0,0,0,0,0,0,0,0,0,0,0,0,0,0,34,6,6,6,6,6,6,6,34,0,0
0,0,6,6,6,0,0,0,6,6,6,0,0,0,0,0,0,0,0,0,0,0,0,0,0,0,0,0,0,0,6,6,6,0,0,0,6,6,6,0,0
0,0,13,6,0,0,0,0,0,6,13,0,0,0,30,30,30,0,0,0,30,0,0,0,30,30,30,0,0,0,13,6,0,0,0,0,0,6,13,0,0
0,0,21,6,15,15,14,0,0,6,6,37,37,37,6,6,6,37,37,37,33,37,37,37,6,6,6,37,37,37,6,6,0,0,14,15,15,6,17,0,0
0,0,12,6,11,11,36,0,0,6,6,6,6,6,6,6,6,6,6,6,6,6,6,6,6,6,6,6,6,6,6,6,0,0,36,11,11,6,12,0,0
0,0,6,6,6,11,36,0,0,6,39,39,39,39,39,39,39,39,39,39,39,39,39,39,39,39,39,39,39,39,39,6,0,0,36,11,6,6,6,0,0
0,0,35,6,6,6,6,6,6,39,39,39,39,39,39,39,39,39,39,39,39,39,39,39,39,39,39,39,39,39,39,39,6,6,6,6,6,6,35,0,0
0,0,0,21,6,9,6,6,39,39,39,39,39,39,39,39,39,39,39,39,39,39,39,39,39,39,39,39,39,39,39,39,39,6,6,23,6,17,0,0,0
0,0,0,0,0,0,37,6,39,39,39,39,39,39,39,39,39,39,39,39,39,39,39,39,39,39,39,39,39,39,39,39,39,6,37,0,0,0,0,0,0
0,0,0,0,0,0,37,6,39,39,39,39,39,39,39,39,39,39,39,39,39,39,39,39,39,39,39,39,39,39,39,39,39,6,37,0,0,0,0,0,0
0,0,0,0,0,0,37,6,39,39,39,39,39,39,39,39,39,39,39,39,39,39,39,39,39,39,39,39,39,39,39,39,39,6,37,0,0,0,0,0,0
0,0,0,0,0,30,6,6,39,39,39,39,39,39,39,39,39,39,39,39,39,39,39,39,39,39,39,39,39,39,39,39,39,6,6,30,0,0,0,0,0
0,0,0,0,0,30,6,6,39,39,39,39,39,39,39,39,39,39,39,39,39,39,39,39,39,39,39,39,39,39,39,39,39,6,6,30,0,0,0,0,0
0,0,0,0,0,30,6,6,39,39,39,39,39,39,39,39,39,39,39,39,39,39,39,39,39,39,39,39,39,39,39,39,39,6,6,30,0,0,0,0,0
0,0,0,0,0,0,37,6,39,39,39,39,39,39,39,39,39,39,39,39,39,39,39,39,39,39,39,39,39,39,39,39,39,6,37,0,0,0,0,0,0
0,0,0,0,0,0,37,6,39,39,39,39,39,39,39,39,39,39,39,39,39,39,39,39,39,39,39,39,39,39,39,39,39,6,37,0,0,0,0,0,0
0,0,0,0,0,0,37,6,39,39,39,39,39,39,39,39,39,39,39,39,39,39,39,39,39,39,39,39,39,39,39,39,39,6,37,0,0,0,0,0,0
0,0,0,0,0,30,33,6,39,39,39,39,39,5,39,39,39,39,39,39,39,39,39,39,39,39,39,5,39,39,39,39,39,6,33,30,0,0,0,0,0
0,0,0,0,0,0,37,6,39,39,39,39,39,39,39,39,39,39,39,39,39,39,39,39,39,39,39,39,39,39,39,39,39,6,37,0,0,0,0,0,0
0,0,0,0,0,0,37,6,39,39,39,39,39,39,39,39,39,39,39,39,39,39,39,39,39,39,39,39,39,39,39,39,39,6,37,0,0,0,0,0,0
0,0,0,0,0,0,37,6,39,39,39,39,39,39,39,39,39,39,39,39,39,39,39,39,39,39,39,39,39,39,39,39,39,6,37,0,0,0,0,0,0
0,0,0,0,0,30,6,6,39,39,39,39,39,39,39,39,39,39,39,39,39,39,39,39,39,39,39,39,39,39,39,39,39,6,6,30,0,0,0,0,0
0,0,0,0,0,30,6,6,39,39,39,39,39,39,39,39,39,39,39,39,39,39,39,39,39,39,39,39,39,39,39,39,39,6,6,30,0,0,0,0,0
0,0,0,0,0,30,6,6,39,39,39,39,39,39,39,39,39,39,39,39,39,39,39,39,39,39,39,39,39,39,39,39,39,6,6,30,0,0,0,0,0
0,0,0,0,0,0,37,6,39,39,39,39,39,39,39,39,39,39,39,39,39,39,39,39,39,39,39,39,39,5,39,39,39,6,37,0,0,0,0,0,0
0,0,0,0,0,0,37,6,39,39,39,39,39,39,39,39,39,39,39,39,39,39,39,39,39,39,39,39,39,39,39,39,39,6,37,0,0,0,0,0,0
0,0,0,0,0,0,37,6,39,39,39,39,39,39,39,39,39,39,39,39,39,39,39,39,39,39,39,39,39,39,39,39,39,6,37,0,0,0,0,0,0
0,0,0,21,6,9,6,6,39,39,39,39,39,39,39,39,39,39,39,39,39,39,39,39,39,39,39,39,39,39,39,39,39,6,6,23,6,17,0,0,0
0,0,34,6,6,6,6,6,6,39,39,39,39,39,39,39,39,39,39,39,39,39,39,39,39,39,39,39,39,39,39,39,6,6,6,6,6,6,34,0,0
0,0,6,6,6,0,0,0,0,6,39,39,39,39,39,39,39,39,39,39,39,39,39,39,39,39,39,39,39,39,39,6,28,0,0,0,6,6,6,0,0
0,0,13,6,0,0,0,0,0,6,6,6,6,6,6,6,6,6,6,6,6,6,6,6,6,6,6,6,6,6,6,6,0,0,0,0,0,6,13,0,0
0,0,21,6,0,0,14,36,36,6,6,37,37,37,6,6,6,37,37,37,33,37,37,37,6,6,6,37,37,37,6,6,36,36,14,0,0,6,17,0,0
0,0,12,6,0,0,15,11,11,6,12,0,0,0,30,30,30,0,0,0,30,0,0,0,30,30,30,0,0,0,12,6,11,11,15,0,0,6,12,0,0
0,0,6,6,6,0,15,11,6,6,6,0,0,0,0,0,0,0,0,0,0,0,0,0,0,0,0,0,0,0,6,6,6,11,15,0,6,6,6,0,0
0,0,35,6,6,6,6,6,6,6,35,0,0,0,0,0,0,0,0,0,0,0,0,0,0,0,0,0,0,0,35,6,6,6,6,6,6,6,35,0,0
0,0,0,21,6,9,35,23,6,17,0,0,0,0,0,0,0,0,0,0,0,0,0,0,0,0,0,0,0,0,0,21,6,9,35,23,6,17,0,0,0
0,0,0,0,0,0,0,0,0,0,0,0,0,0,0,0,0,0,0,0,0,0,0,0,0,0,0,0,0,0,0,0,0,0,0,0,0,0,0,0,0
0,0,0,0,0,0,0,0,0,0,0,0,0,0,0,0,0,0,0,0,0,0,0,0,0,0,0,0,0,0,0,0,0,0,0,0,0,0,0,0,0
0,0,0,0,0,0,0,0,0,0,0,0,0,0,0,0,0,0,0,0,0,0,0,0,0,0,0,0,0,0,0,0,0,0,0,0,0,0,0,0,0
0,0,0,0,0,0,0,0,0,0,0,0,0,0,0,0,0,0,0,0,0,0,0,0,0,0,0,0,0,0,0,0,0,0,0,0,0,0,0,0,0
0,0,0,0,0,0,0,0,0,0,0,0,0,0,0,0,0,0,0,0,0,0,0,0,0,0,0,0,0,0,0,0,0,0,0,0,0,0,0,0,0
0,0,0,0,0,0,0,0,0,0,0,0,0,0,0,0,0,0,0,0,0,0,0,0,0,0,0,0,0,0,0,0,0,0,0,0,0,0,0,0,0
0,0,0,0,0,0,0,0,0,0,0,0,0,0,0,0,0,0,0,0,0,0,0,0,0,0,0,0,0,0,0,0,0,0,0,0,0,0,0,0,0
0,0,0,0,0,0,0,0,0,0,0,0,0,0,0,0,0,0,0,0,0,0,0,0,0,0,0,0,0,0,0,0,0,0,0,0,0,0,0,0,0
0,0,0,0,0,0,0,0,0,0,0,0,0,0,0,0,0,0,0,0,0,0,0,0,0,0,0,0,0,0,0,0,0,0,0,0,0,0,0,0,0
0,0,0,0,0,0,0,0,0,0,0,0,0,0,0,0,0,0,0,0,0,0,0,0,0,0,0,0,0,0,0,0,0,0,0,0,0,0,0,0,0
:endlayer
layer: 22
0,0,0,0,0,0,0,0,0,0,0,0,0,0,0,0,0,0,0,0,0,0,0,0,0,0,0,0,0,0,0,0,0,0,0,0,0,0,0,0,0
0,0,0,0,0,0,0,0,0,0,0,0,0,0,0,0,0,0,0,0,0,0,0,0,0,0,0,0,0,0,0,0,0,0,0,0,0,0,0,0,0
0,0,0,23,6,34,0,34,6,9,0,0,0,0,0,0,0,0,0,0,0,0,0,0,0,0,0,0,0,0,0,23,6,34,0,34,6,9,0,0,0
0,0,12,6,6,6,49,6,6,6,12,0,0,0,0,0,0,0,0,0,0,0,0,0,0,0,0,0,0,0,12,6,6,6,49,6,6,6,12,0,0
0,0,6,6,6,0,0,0,6,6,6,27,0,0,0,0,0,0,0,0,0,0,0,0,0,0,0,0,0,29,6,6,6,0,0,0,6,6,6,0,0
0,0,21,6,0,0,0,0,28,6,17,0,0,0,0,0,0,0,0,0,26,0,0,0,0,0,0,0,0,0,21,6,28,0,0,0,0,6,17,0,0
0,0,0,49,0,0,14,36,36,6,6,21,50,17,23,34,9,21,50,17,33,21,50,17,23,34,9,21,50,17,6,6,36,36,14,0,0,49,0,0,0
0,0,21,6,0,0,15,11,11,6,6,6,6,6,6,6,6,6,6,6,6,6,6,6,6,6,6,6,6,6,6,6,11,11,15,0,0,6,17,0,0
0,0,6,6,6,0,15,11,11,68,0,0,0,0,0,39,72,0,0,72,39,72,0,0,72,39,0,0,0,0,0,68,11,11,15,0,6,6,6,0,0
0,0,13,6,6,6,6,6,68,68,0,0,0,0,0,39,73,0,0,73,39,73,0,0,73,39,0,0,0,0,0,68,68,6,6,6,6,6,13,0,0
0,0,0,23,6,35,6,6,0,0,0,0,0,0,0,39,0,0,0,0,39,0,0,0,0,39,0,0,0,0,0,0,0,6,6,35,6,9,0,0,0
0,0,0,0,28,0,34,6,0,0,0,0,0,0,0,39,0,0,0,0,39,0,0,0,0,39,0,0,0,0,0,0,0,6,34,0,28,0,0,0,0
0,0,0,0,0,0,50,6,0,0,0,0,0,0,0,39,0,0,0,0,39,0,0,0,0,39,0,0,0,0,0,0,0,6,50,0,0,0,0,0,0
0,0,0,0,0,0,35,6,0,0,0,0,0,0,0,39,0,0,0,0,39,0,0,0,0,39,0,0,0,0,0,0,0,6,35,0,0,0,0,0,0
0,0,0,0,0,0,12,6,0,0,0,0,6,6,6,6,6,48,6,6,6,39,39,48,39,39,39,39,48,39,39,39,39,6,12,0,0,0,0,0,0
0,0,0,0,0,0,21,6,0,0,0,0,6,39,0,0,0,0,0,39,6,0,0,0,0,0,0,0,0,0,0,0,0,6,17,0,0,0,0,0,0
0,0,0,0,0,0,13,6,0,0,0,0,6,0,0,0,0,0,0,0,6,0,0,0,0,0,0,0,0,0,0,0,0,6,13,0,0,0,0,0,0
0,0,0,0,0,0,34,6,0,0,0,0,48,0,0,0,0,0,0,0,6,0,0,0,0,0,0,0,0,0,0,0,0,6,34,0,0,0,0,0,0
0,0,0,0,0,0,50,6,0,0,0,0,77,0,0,0,0,0,0,0,6,0,0,0,0,0,0,0,0,0,0,0,0,6,50,0,0,0,0,0,0
0,0,0,0,0,0,35,6,0,0,0,0,6,0,0,0,0,0,0,0,6,0,0,0,0,0,0,0,0,0,0,0,0,6,35,0,0,0,0,0,0
0,0,0,0,0,29,33,6,0,0,0,0,6,39,0,0,0,0,0,0,77,0,0,0,0,0,0,71,0,0,0,0,70,6,33,27,0,0,0,0,0
0,0,0,0,0,0,34,6,0,0,0,0,6,39,0,0,0,0,0,0,48,0,0,0,0,0,0,0,0,0,0,0,0,6,34,0,0,0,0,0,0
0,0,0,0,0,0,50,6,0,0,0,0,6,39,0,0,0,0,0,0,6,0,0,0,0,0,0,0,0,0,0,0,0,6,50,0,0,0,0,0,0
0,0,0,0,0,0,35,6,0,0,0,0,6,39,0,0,0,0,0,0,6,0,0,0,0,0,0,0,0,0,0,0,0,6,35,0,0,0,0,0,0
0,0,0,0,0,0,12,6,0,0,0,0,6,41,0,0,0,0,0,0,6,0,0,0,0,0,0,0,0,0,0,0,0,6,12,0,0,0,0,0,0
0,0,0,0,0,0,21,6,0,0,0,0,6,0,0,0,0,0,0,39,6,0,0,0,0,0,0,0,0,0,0,0,0,6,17,0,0,0,0,0,0
0,0,0,0,0,0,13,6,0,0,0,0,6,6,6,48,6,6,6,6,6,39,39,48,39,39,0,0,0,0,0,0,0,6,13,0,0,0,0,0,0
0,0,0,0,0,0,34,6,0,0,0,0,0,0,39,0,0,0,0,0,39,0,0,0,0,39,0,0,0,0,0,0,0,6,34,0,0,0,0,0,0
0,0,0,0,0,0,50,6,0,0,0,0,0,0,39,0,0,0,0,0,39,0,0,0,0,39,0,0,0,0,0,0,0,6,50,0,0,0,0,0,0
0,0,0,0,26,0,35,6,0,0,0,0,0,0,39,0,0,0,0,0,39,0,0,0,0,39,0,0,0,0,0,0,0,6,35,0,0,0,0,0,0
0,0,0,23,6,34,6,6,0,0,0,0,0,0,39,0,0,0,0,0,39,0,0,0,0,39,0,0,0,0,0,0,0,6,6,34,6,9,0,0,0
0,0,12,6,6,6,6,6,68,68,0,0,0,0,39,75,0,75,0,75,39,75,0,0,0,39,0,0,0,0,0,68,68,6,6,6,6,6,12,0,0
0,0,6,6,6,27,36,11,11,68,0,0,0,0,39,76,0,76,0,76,39,76,0,0,74,39,0,0,0,0,0,68,11,11,36,0,6,6,6,0,0
0,0,21,6,0,0,36,11,11,6,6,6,6,6,6,6,6,6,6,6,6,6,6,6,6,6,6,6,6,6,6,6,11,11,36,0,0,6,17,0,0
0,0,0,49,0,0,14,15,15,6,6,21,50,17,23,35,9,21,50,17,33,21,50,17,23,35,9,21,50,17,6,6,15,15,14,0,0,49,0,0,0
0,0,21,6,0,0,0,0,0,6,17,0,0,0,0,0,0,0,0,0,28,0,0,0,0,0,0,0,0,0,21,6,0,0,0,0,0,6,17,0,0
0,0,6,6,6,0,0,0,6,6,6,27,0,0,0,0,0,0,0,0,0,0,0,0,0,0,0,0,0,29,6,6,6,0,0,0,6,6,6,0,0
0,0,13,6,6,6,49,6,6,6,13,0,0,0,0,0,0,0,0,0,0,0,0,0,0,0,0,0,0,0,13,6,6,6,49,6,6,6,13,0,0
0,0,0,23,6,35,51,35,6,9,0,0,0,0,0,0,0,0,0,0,0,0,0,0,0,0,0,0,0,0,0,23,6,35,51,35,6,9,0,0,0
0,0,0,0,0,0,0,0,0,0,0,0,0,0,0,0,0,0,0,0,0,0,0,0,0,0,0,0,0,0,0,0,0,0,0,0,0,0,0,0,0
0,0,0,0,0,0,0,0,0,0,0,0,0,0,0,0,0,0,0,0,0,0,0,0,0,0,0,0,0,0,0,0,0,0,0,0,0,0,0,0,0
0,0,0,0,0,0,0,0,0,0,0,0,0,0,0,0,0,0,0,0,0,0,0,0,0,0,0,0,0,0,0,0,0,0,0,0,0,0,0,0,0
0,0,0,0,0,0,0,0,0,0,0,0,0,0,0,0,0,0,0,0,0,0,0,0,0,0,0,0,0,0,0,0,0,0,0,0,0,0,0,0,0
0,0,0,0,0,0,0,0,0,0,0,0,0,0,0,0,0,0,0,0,0,0,0,0,0,0,0,0,0,0,0,0,0,0,0,0,0,0,0,0,0
0,0,0,0,0,0,0,0,0,0,0,0,0,0,0,0,0,0,0,0,0,0,0,0,0,0,0,0,0,0,0,0,0,0,0,0,0,0,0,0,0
0,0,0,0,0,0,0,0,0,0,0,0,0,0,0,0,0,0,0,0,0,0,0,0,0,0,0,0,0,0,0,0,0,0,0,0,0,0,0,0,0
0,0,0,0,0,0,0,0,0,0,0,0,0,0,0,0,0,0,0,0,0,0,0,0,0,0,0,0,0,0,0,0,0,0,0,0,0,0,0,0,0
