# Ancient Warfare Structure Template File
# Auto-generated structure template file. created on: 2/23/2017 at: 3:24:9
# Lines beginning with # denote comments

header:
version=2.1
name=ReignThaumCouncil
size=41,43,49
offset=18,1,48
:endheader

#### VALIDATION ####
validation:
type=ground
survival=true
worldGenEnabled=false
unique=false
preserveBlocks=false
selectionWeight=100
clusterValue=100
minDuplicateDistance=100
dimensionWhiteList=false
dimensionList=
biomeWhiteList=true
biomeList=grove,shield,steppe,tundra,shrubland,prairie
leveling=10
fill=10
border=0
validTargetBlocks=minecraft:stained_hardened_clay,minecraft:dirt,minecraft:coal_ore,minecraft:diamond_ore,minecraft:lapis_ore,minecraft:gravel,minecraft:stone,minecraft:clay,minecraft:sand,minecraft:gold_ore,minecraft:redstone_ore,minecraft:grass,minecraft:log2,minecraft:iron_ore,minecraft:sapling
blockSwap=false
data:
:enddata
:endvalidation

#### LAYERS ####
layer: 0
2,2,2,2,2,2,2,2,2,2,2,2,2,2,2,2,2,2,2,2,2,2,2,2,2,2,2,2,2,2,2,2,2,2,2,2,2,2,2,2,2
2,2,2,2,3,2,3,2,3,2,2,2,2,2,2,2,2,2,2,2,2,2,2,2,2,2,2,2,2,2,2,2,3,2,3,2,3,2,2,2,2
2,2,2,3,3,3,3,3,3,3,2,2,2,2,2,2,2,2,2,2,2,2,2,2,2,2,2,2,2,2,2,3,3,3,3,3,3,3,2,2,2
2,2,3,3,4,4,4,4,4,4,4,4,4,4,4,4,4,4,4,4,4,4,4,4,4,4,4,4,4,4,4,4,4,4,4,4,4,4,3,2,2
2,3,3,3,4,4,4,4,4,4,4,4,4,4,4,4,4,4,4,4,4,4,4,4,4,4,4,4,4,4,4,4,4,4,4,4,4,4,3,3,2
2,2,3,3,4,4,4,4,4,4,4,4,4,4,4,4,4,4,4,4,4,4,4,4,4,4,4,4,4,4,4,4,4,4,4,4,4,4,3,2,2
2,3,3,3,4,4,4,4,4,4,4,4,4,4,4,4,4,4,4,4,4,4,4,4,4,4,4,4,4,4,4,4,4,4,4,4,4,4,3,3,2
2,2,3,3,4,4,4,4,4,4,4,4,4,4,4,4,4,4,4,4,4,4,4,4,4,4,4,4,4,4,4,4,4,4,4,4,4,4,3,2,2
2,3,3,3,4,4,4,4,4,4,4,4,4,4,4,4,4,4,4,4,4,4,4,4,4,4,4,4,4,4,4,4,4,4,4,4,4,4,3,3,2
2,2,3,3,4,4,4,4,4,4,4,4,4,4,4,4,4,4,4,4,4,4,4,4,4,4,4,4,4,4,4,4,4,4,4,4,4,4,3,2,2
2,2,2,3,4,4,4,4,4,4,5,4,4,4,4,4,5,4,4,4,4,4,4,4,5,4,4,4,4,4,5,4,4,4,4,4,4,4,2,2,2
2,2,2,2,4,4,4,4,4,4,4,4,4,4,4,4,4,4,4,4,4,4,4,4,4,4,4,4,4,4,4,4,4,4,4,4,4,4,2,2,2
2,2,2,2,4,4,4,4,4,4,4,4,4,4,4,4,4,4,4,4,4,4,4,4,4,4,4,4,4,4,4,4,4,4,4,4,4,4,2,2,2
2,2,2,2,4,4,4,4,4,4,4,4,4,4,4,4,4,4,4,4,4,4,4,4,4,4,4,4,4,4,4,4,4,4,4,4,4,4,2,2,2
2,2,2,2,4,4,4,4,4,4,4,4,4,4,4,4,4,4,4,4,4,4,4,4,4,4,4,4,4,4,4,4,4,4,4,4,4,4,2,2,2
2,2,2,2,4,4,4,4,4,4,4,4,4,4,4,4,4,4,4,4,4,4,4,4,4,4,4,4,4,4,4,4,4,4,4,4,4,4,2,2,2
2,2,2,2,4,4,4,4,4,4,5,4,4,4,4,4,4,4,4,4,5,4,4,4,4,4,4,4,4,4,5,4,4,4,4,4,4,4,2,2,2
2,2,2,2,4,4,4,4,4,4,4,4,4,4,4,4,4,4,4,4,4,4,4,4,4,4,4,4,4,4,4,4,4,4,4,4,4,4,2,2,2
2,2,2,2,4,4,4,4,4,4,4,4,4,4,4,4,4,4,4,4,4,4,4,4,4,4,4,4,4,4,4,4,4,4,4,4,4,4,2,2,2
2,2,2,2,4,4,4,4,4,4,4,4,4,4,4,4,4,4,4,4,4,4,4,4,4,4,4,4,4,4,4,4,4,4,4,4,4,4,2,2,2
2,2,2,2,4,4,4,4,4,4,4,4,4,4,4,4,4,4,4,4,4,4,4,4,4,4,4,4,4,4,4,4,4,4,4,4,4,4,2,2,2
2,2,2,2,4,4,4,4,4,4,4,4,4,4,4,4,4,4,4,4,4,4,4,4,4,4,4,4,4,4,4,4,4,4,4,4,4,4,2,2,2
2,2,2,2,4,4,4,4,4,4,4,4,4,4,4,4,4,4,4,4,4,4,4,4,4,4,4,4,4,4,4,4,4,4,4,4,4,4,2,2,2
2,2,2,2,4,4,4,4,4,4,4,4,4,4,4,4,4,4,4,4,4,4,4,4,4,4,4,4,4,4,4,4,4,4,4,4,4,4,2,2,2
2,2,2,2,4,4,4,4,4,4,5,4,4,4,4,4,4,4,4,4,5,4,4,4,4,4,4,4,4,4,5,4,4,4,4,4,4,4,2,2,2
2,2,2,2,4,4,4,4,4,4,4,4,4,4,4,4,4,4,4,4,4,4,4,4,4,4,4,4,4,4,4,4,4,4,4,4,4,4,2,2,2
2,2,2,2,4,4,4,4,4,4,4,4,4,4,4,4,4,4,4,4,4,4,4,4,4,4,4,4,4,4,4,4,4,4,4,4,4,4,2,2,2
2,2,2,2,4,4,4,4,4,4,4,4,4,4,4,4,4,4,4,4,4,4,4,4,4,4,4,4,4,4,4,4,4,4,4,4,4,4,2,2,2
2,2,2,2,4,4,4,4,4,4,4,4,4,4,4,4,4,4,4,4,4,4,4,4,4,4,4,4,4,4,4,4,4,4,4,4,4,4,2,2,2
2,2,2,2,4,4,4,4,4,4,4,4,4,4,4,4,4,4,4,4,4,4,4,4,4,4,4,4,4,4,4,4,4,4,4,4,4,4,2,2,2
2,2,2,3,4,4,4,4,4,4,5,4,4,4,4,4,5,4,4,4,4,4,4,4,5,4,4,4,4,4,5,4,4,4,4,4,4,4,2,2,2
2,2,3,3,4,4,4,4,4,4,4,4,4,4,4,4,4,4,4,4,4,4,4,4,4,4,4,4,4,4,4,4,4,4,4,4,4,4,3,2,2
2,3,3,3,4,4,4,4,4,4,4,4,4,4,4,4,4,4,4,4,4,4,4,4,4,4,4,4,4,4,4,4,4,4,4,4,4,4,3,3,2
2,2,3,3,4,4,4,4,4,4,4,4,4,4,4,4,4,4,4,4,4,4,4,4,4,4,4,4,4,4,4,4,4,4,4,4,4,4,3,2,2
2,3,3,3,4,4,4,4,4,4,4,4,4,4,4,4,4,4,4,4,4,4,4,4,4,4,4,4,4,4,4,4,4,4,4,4,4,4,3,3,2
2,2,3,3,4,4,4,4,4,4,4,4,4,4,4,4,4,4,4,4,4,4,4,4,4,4,4,4,4,4,4,4,4,4,4,4,4,4,3,2,2
2,3,3,3,4,4,4,4,4,4,4,4,4,4,4,4,4,4,4,4,4,4,4,4,4,4,4,4,4,4,4,4,4,4,4,4,4,4,3,3,2
1,1,3,3,3,3,3,3,3,3,3,1,1,1,1,1,1,2,6,2,2,2,3,2,1,1,1,1,1,1,3,3,3,3,3,3,3,3,3,1,1
1,1,1,3,3,3,3,3,3,3,1,1,1,1,1,1,1,3,3,6,2,6,3,6,1,1,1,1,1,1,1,3,3,3,3,3,3,3,1,1,1
1,1,1,1,3,2,3,2,3,1,1,1,1,1,1,1,1,2,3,2,2,2,3,2,1,1,1,1,1,1,1,1,3,2,3,2,3,1,1,1,1
1,1,1,1,1,1,1,1,1,1,1,1,1,1,1,1,1,1,1,1,1,1,1,1,1,1,1,1,1,1,1,1,1,1,1,1,1,1,1,1,1
1,1,1,1,1,1,1,1,1,1,1,1,1,1,1,1,1,1,1,1,1,1,1,1,1,1,1,1,1,1,1,1,1,1,1,1,1,1,1,1,1
1,1,1,1,1,1,1,1,1,1,1,1,1,1,1,1,1,1,1,1,1,1,1,1,1,1,1,1,1,1,1,1,1,1,1,1,1,1,1,1,1
1,1,1,1,1,1,1,1,1,1,1,1,1,1,1,1,1,1,1,1,1,1,1,1,1,1,1,1,1,1,1,1,1,1,1,1,1,1,1,1,1
1,1,1,1,1,1,1,1,1,1,1,1,1,1,1,1,1,1,1,1,1,1,1,1,1,1,1,1,1,1,1,1,1,1,1,1,1,1,1,1,1
1,1,1,1,1,1,1,1,1,1,1,1,1,1,1,1,1,1,1,1,1,1,1,1,1,1,1,1,1,1,1,1,1,1,1,1,1,1,1,1,1
1,1,1,1,1,1,1,1,1,1,1,1,1,1,1,1,1,1,1,1,1,1,1,1,1,1,1,1,1,1,1,1,1,1,1,1,1,1,1,1,1
1,1,1,1,1,1,1,1,1,1,1,1,1,1,1,1,1,1,1,1,1,1,1,1,1,1,1,1,1,1,1,1,1,1,1,1,1,1,1,1,1
1,1,1,1,1,1,1,1,1,1,1,1,1,1,1,1,1,1,1,1,1,1,1,1,1,1,1,1,1,1,1,1,1,1,1,1,1,1,1,1,1
:endlayer
layer: 1
0,0,0,0,0,0,0,0,0,0,0,0,0,0,0,0,0,0,0,0,0,0,0,0,0,0,0,0,0,0,0,0,0,0,0,0,0,0,0,0,0
0,0,0,0,6,13,6,13,6,0,0,0,0,0,0,0,0,0,0,0,0,0,0,0,0,0,0,0,0,0,0,0,6,13,6,13,6,0,0,0,0
0,0,0,6,6,6,6,6,6,6,0,0,0,0,0,0,0,0,0,0,0,0,0,0,0,0,0,0,0,0,0,6,6,6,6,6,6,6,0,0,0
0,0,6,6,6,6,6,6,6,6,6,0,0,0,0,0,0,0,0,0,0,0,0,0,0,0,0,0,0,0,6,6,6,6,6,6,6,6,6,0,0
0,6,6,6,6,10,10,10,6,6,6,6,0,0,0,0,0,0,0,0,0,0,0,0,0,0,0,0,0,6,6,6,6,10,10,10,6,6,6,6,0
0,9,6,6,0,0,10,10,10,6,6,0,6,13,6,13,6,13,6,13,6,13,6,13,6,13,6,13,6,0,6,6,10,10,0,0,0,6,6,22,0
0,6,6,6,0,0,14,12,12,6,6,6,6,6,6,6,6,6,6,6,6,6,6,6,6,6,6,6,6,6,6,6,12,12,14,0,0,6,6,6,0
0,9,6,6,0,0,0,0,0,6,6,6,6,6,6,6,6,6,6,6,6,6,6,6,6,6,6,6,6,6,6,6,0,0,0,0,0,6,6,22,0
0,6,6,6,6,0,0,0,0,0,0,0,0,0,0,0,0,0,0,0,0,0,0,0,0,0,0,0,0,0,0,0,0,0,0,0,6,6,6,6,0
0,0,6,6,6,6,6,6,0,0,0,0,0,0,0,0,0,0,0,0,0,0,0,0,0,0,0,0,0,0,0,0,0,6,6,6,6,6,6,0,0
0,0,0,6,6,6,6,6,0,0,0,0,0,0,0,0,0,0,0,0,0,0,0,0,0,0,0,0,0,0,0,0,0,6,6,6,6,6,0,0,0
0,0,0,0,6,0,6,6,0,0,0,0,0,0,0,0,0,0,0,0,0,0,0,0,0,0,0,0,0,0,0,0,0,6,6,0,6,0,0,0,0
0,0,0,0,0,6,6,6,0,0,0,0,0,0,0,0,0,0,0,0,0,0,0,0,0,0,0,0,0,0,0,0,0,6,6,6,0,0,0,0,0
0,0,0,0,0,9,6,6,0,0,0,0,0,0,0,0,0,0,0,0,0,0,0,0,0,0,0,0,0,0,0,0,0,6,6,22,0,0,0,0,0
0,0,0,0,0,6,6,6,0,0,0,0,0,0,0,0,0,0,0,0,0,0,0,0,0,0,0,0,0,0,0,0,0,6,6,6,0,0,0,0,0
0,0,0,0,0,9,6,6,0,0,0,0,0,0,0,0,0,0,0,0,0,0,0,0,0,0,0,0,0,0,0,0,0,6,6,22,0,0,0,0,0
0,0,0,0,0,6,6,6,0,0,0,0,0,0,0,0,0,0,0,0,0,0,0,0,0,0,0,0,0,0,0,0,0,6,6,6,0,0,0,0,0
0,0,0,0,0,9,6,6,0,0,0,0,0,0,0,0,0,0,0,0,0,0,0,0,0,0,0,0,0,0,0,0,0,6,6,22,0,0,0,0,0
0,0,0,0,0,6,6,6,0,0,0,0,0,0,0,0,0,0,0,0,0,0,0,0,0,0,0,0,0,0,0,0,0,6,6,6,0,0,0,0,0
0,0,0,0,0,9,6,6,0,0,0,0,0,0,0,0,0,0,0,0,0,0,0,0,0,0,0,0,0,0,0,0,0,6,6,22,0,0,0,0,0
0,0,0,0,0,6,6,6,0,0,0,0,0,0,0,0,0,0,0,0,19,0,0,0,0,0,0,0,0,0,0,0,0,6,6,6,0,0,0,0,0
0,0,0,0,0,9,6,6,0,0,0,0,0,0,0,0,0,0,0,0,0,0,0,0,0,0,0,0,0,0,0,0,0,6,6,22,0,0,0,0,0
0,0,0,0,0,6,6,6,0,0,0,0,0,0,0,0,0,0,0,0,0,0,0,0,0,0,0,0,0,0,0,0,0,6,6,6,0,0,0,0,0
0,0,0,0,0,9,6,6,0,0,0,0,0,0,0,0,0,0,0,0,0,0,0,0,0,0,0,0,0,0,0,0,0,6,6,22,0,0,0,0,0
0,0,0,0,0,6,6,6,0,0,0,0,0,0,0,0,0,0,0,0,0,0,0,0,0,0,0,0,0,0,0,0,0,6,6,6,0,0,0,0,0
0,0,0,0,0,9,6,6,0,0,0,0,0,0,0,0,0,0,0,0,0,0,0,0,0,0,0,0,0,0,0,0,0,6,6,22,0,0,0,0,0
0,0,0,0,0,6,6,6,0,0,0,0,0,0,0,0,0,0,0,0,0,0,0,0,0,0,0,0,0,0,0,0,0,6,6,6,0,0,0,0,0
0,0,0,0,0,9,6,6,0,0,0,0,0,0,0,0,0,0,0,0,0,0,0,0,0,0,0,0,0,0,0,0,0,6,6,22,0,0,0,0,0
0,0,0,0,0,6,6,6,0,0,0,0,0,0,0,0,0,0,0,0,0,0,0,0,0,0,0,0,0,0,0,0,0,6,6,6,0,0,0,0,0
0,0,0,0,6,0,6,6,0,0,0,0,0,0,0,0,0,0,0,0,0,0,0,0,0,0,0,0,0,0,0,0,0,6,6,0,6,0,0,0,0
0,0,0,6,6,6,6,6,0,0,0,0,0,0,0,0,0,0,0,0,0,0,0,0,0,0,0,0,0,0,0,0,0,6,6,6,6,6,0,0,0
0,0,6,6,6,6,6,6,0,0,0,0,0,0,0,0,0,0,0,0,0,0,0,0,0,0,0,0,0,0,0,0,0,6,6,6,6,6,6,0,0
0,6,6,6,6,12,12,0,0,0,0,0,0,0,0,0,0,0,0,0,0,0,0,0,0,0,0,0,0,0,0,0,0,0,12,10,6,6,6,6,0
0,9,6,6,10,10,12,0,0,6,6,6,6,6,6,6,6,6,6,6,6,6,6,6,6,6,6,6,6,6,6,6,0,0,12,10,0,6,6,22,0
0,6,6,6,10,10,14,0,0,6,6,6,6,6,6,6,6,6,6,6,6,6,6,6,6,6,6,6,6,6,6,6,0,0,14,0,10,6,6,6,0
0,9,6,6,10,10,0,0,0,6,6,0,6,11,6,11,6,0,16,0,0,0,20,0,6,11,6,11,6,0,6,6,0,0,0,0,0,6,6,22,0
0,6,6,6,6,10,0,0,6,6,6,6,0,0,0,0,0,6,6,0,0,0,6,6,0,0,0,0,0,6,6,6,6,0,0,0,6,6,6,6,0
7,7,6,6,6,6,6,6,6,6,6,0,0,0,0,0,0,0,16,0,0,0,20,0,0,0,0,0,0,0,6,6,6,6,6,6,6,6,6,7,7
7,0,0,6,6,6,6,6,6,6,0,0,0,0,0,0,0,6,6,0,0,0,6,6,0,0,0,0,0,0,0,6,6,6,6,6,6,6,0,0,7
7,0,0,0,6,11,6,11,6,0,0,0,0,0,0,0,0,0,16,0,0,0,20,0,0,0,0,0,0,0,0,0,6,11,6,11,6,0,0,0,7
7,0,0,0,0,0,0,0,0,0,0,0,0,0,0,0,0,6,6,0,0,0,6,6,0,0,0,0,0,0,0,0,0,0,0,0,0,0,0,0,7
7,0,0,0,0,0,0,0,0,0,0,0,0,0,0,0,0,0,16,0,0,0,20,0,0,0,0,0,0,0,0,0,0,0,0,0,0,0,0,0,7
7,0,0,0,0,0,0,0,0,0,0,0,0,0,0,0,0,6,6,18,18,18,6,6,0,0,0,0,0,0,0,0,0,0,0,0,0,0,0,0,7
7,0,0,0,0,0,0,0,0,0,0,0,0,0,0,0,0,0,6,17,17,17,6,0,0,0,0,0,0,0,0,0,0,0,0,0,0,0,0,0,7
7,8,0,0,0,0,0,0,0,0,0,0,15,0,0,0,0,0,0,0,0,0,0,0,0,0,0,0,0,21,0,0,0,0,0,0,0,0,0,23,7
7,0,0,0,0,0,0,0,0,0,0,0,0,0,0,0,0,0,0,0,0,0,0,0,0,0,0,0,0,0,0,0,0,0,0,0,0,0,0,0,7
7,0,0,0,0,0,0,0,0,0,0,0,0,0,0,0,0,0,0,0,0,0,0,0,0,0,0,0,0,0,0,0,0,0,0,0,0,0,0,0,7
7,0,0,0,0,0,0,0,0,0,0,0,0,0,0,0,0,0,0,0,0,0,0,0,0,0,0,0,0,0,0,0,0,0,0,0,0,0,0,0,7
7,7,7,7,7,7,7,7,7,7,7,7,7,7,7,7,7,7,6,0,0,0,6,7,7,7,7,7,7,7,7,7,7,7,7,7,7,7,7,7,7
:endlayer
layer: 2
0,0,0,0,0,0,0,0,0,0,0,0,0,0,0,0,0,0,0,0,0,0,0,0,0,0,0,0,0,0,0,0,0,0,0,0,0,0,0,0,0
0,0,0,0,6,0,6,0,6,0,0,0,0,0,0,0,0,0,0,0,0,0,0,0,0,0,0,0,0,0,0,0,6,0,6,0,6,0,0,0,0
0,0,0,6,6,6,6,6,6,6,0,0,0,0,0,0,0,0,0,0,0,0,0,0,0,0,0,0,0,0,0,6,6,6,6,6,6,6,0,0,0
0,0,6,6,6,6,6,6,6,6,6,0,0,0,0,0,0,0,0,0,0,0,0,0,0,0,0,0,0,0,6,6,6,6,6,6,6,6,6,0,0
0,6,6,6,6,10,12,0,6,6,6,6,0,0,0,0,0,0,0,0,0,0,0,0,0,0,0,0,0,6,6,6,6,0,12,10,6,6,6,6,0
0,0,6,6,10,10,12,0,0,6,6,0,6,0,6,0,6,0,6,0,6,0,6,0,6,0,6,0,6,0,6,6,0,0,12,10,10,6,6,0,0
0,6,6,6,0,0,14,0,0,6,6,6,6,6,6,6,6,6,6,6,6,6,6,6,6,6,6,6,6,6,6,6,0,0,14,0,0,6,6,6,0
0,0,6,6,0,0,0,0,0,6,6,6,6,6,6,6,6,6,6,6,6,6,6,6,6,6,6,6,6,6,6,6,0,0,0,0,0,6,6,0,0
0,6,6,6,6,0,0,0,0,0,0,0,0,0,0,0,0,0,0,0,0,0,0,0,0,0,0,0,0,0,0,0,0,0,0,0,6,6,6,6,0
0,0,6,6,6,6,6,6,0,0,0,0,0,0,0,0,0,0,0,0,0,0,0,0,0,0,0,0,0,0,0,0,0,6,6,6,6,6,6,0,0
0,0,0,6,6,6,6,6,0,0,0,0,0,0,0,0,0,0,0,0,0,0,0,0,0,0,0,0,0,0,0,0,0,6,6,6,6,6,0,0,0
0,0,0,0,6,0,6,6,0,0,0,0,0,0,0,0,0,0,0,0,0,0,0,0,0,0,0,0,0,0,0,0,0,6,6,0,6,0,0,0,0
0,0,0,0,0,6,6,6,0,0,0,0,0,0,0,0,0,0,0,0,0,0,0,0,0,0,0,0,0,0,0,0,0,6,6,6,0,0,0,0,0
0,0,0,0,0,0,6,6,0,0,0,0,0,0,0,0,0,0,0,0,0,0,0,0,0,0,0,0,0,0,0,0,0,6,6,0,0,0,0,0,0
0,0,0,0,0,6,6,6,0,0,0,0,0,0,0,0,0,0,0,0,0,0,0,0,0,0,0,0,0,0,0,0,0,6,6,6,0,0,0,0,0
0,0,0,0,0,0,6,6,0,0,0,0,0,0,0,0,0,0,0,0,0,0,0,0,0,0,0,0,0,0,0,0,0,6,6,0,0,0,0,0,0
0,0,0,0,0,6,6,6,0,0,0,0,0,0,0,0,0,0,0,0,0,0,0,0,0,0,0,0,0,0,0,0,0,6,6,6,0,0,0,0,0
0,0,0,0,0,0,6,6,0,0,0,0,0,0,0,0,0,0,0,0,0,0,0,0,0,0,0,0,0,0,0,0,0,6,6,0,0,0,0,0,0
0,0,0,0,0,6,6,6,0,0,0,0,0,0,0,0,0,0,0,0,0,0,0,0,0,0,0,0,0,0,0,0,0,6,6,6,0,0,0,0,0
0,0,0,0,0,0,6,6,0,0,0,0,0,0,0,0,0,0,0,0,0,0,0,0,0,0,0,0,0,0,0,0,0,6,6,0,0,0,0,0,0
0,0,0,0,0,6,6,6,0,0,0,0,0,0,0,0,0,0,0,0,0,0,0,0,0,0,0,0,0,0,0,0,0,6,6,6,0,0,0,0,0
0,0,0,0,0,0,6,6,0,0,0,0,0,0,0,0,0,0,0,0,0,0,0,0,0,0,0,0,0,0,0,0,0,6,6,0,0,0,0,0,0
0,0,0,0,0,6,6,6,0,0,0,0,0,0,0,0,0,0,0,0,0,0,0,0,0,0,0,0,0,0,0,0,0,6,6,6,0,0,0,0,0
0,0,0,0,0,0,6,6,0,0,0,0,0,0,0,0,0,0,0,0,0,0,0,0,0,0,0,0,0,0,0,0,0,6,6,0,0,0,0,0,0
0,0,0,0,0,6,6,6,0,0,0,0,0,0,0,0,0,0,0,0,0,0,0,0,0,0,0,0,0,0,0,0,0,6,6,6,0,0,0,0,0
0,0,0,0,0,0,6,6,0,0,0,0,0,0,0,0,0,0,0,0,0,0,0,0,0,0,0,0,0,0,0,0,0,6,6,0,0,0,0,0,0
0,0,0,0,0,6,6,6,0,0,0,0,0,0,0,0,0,0,0,0,0,0,0,0,0,0,0,0,0,0,0,0,0,6,6,6,0,0,0,0,0
0,0,0,0,0,0,6,6,0,0,0,0,0,0,0,0,0,0,0,0,0,0,0,0,0,0,0,0,0,0,0,0,0,6,6,0,0,0,0,0,0
0,0,0,0,0,6,6,6,0,0,0,0,0,0,0,0,0,0,0,0,0,0,0,0,0,0,0,0,0,0,0,0,0,6,6,6,0,0,0,0,0
0,0,0,0,6,0,6,6,0,0,0,0,0,0,0,0,0,0,0,0,0,0,0,0,0,0,0,0,0,0,0,0,0,6,6,0,6,0,0,0,0
0,0,0,6,6,6,6,6,0,0,0,0,0,0,0,0,0,0,0,0,0,0,0,0,0,0,0,0,0,0,0,0,0,6,6,6,6,6,0,0,0
0,0,6,6,6,6,6,6,0,0,0,0,0,0,0,0,0,0,0,0,0,0,0,0,0,0,0,0,0,0,0,0,0,6,6,6,6,6,6,0,0
0,6,6,6,6,0,0,0,0,0,0,0,0,0,0,0,0,0,0,0,0,0,0,0,0,0,0,0,0,0,0,0,0,0,0,0,6,6,6,6,0
0,0,6,6,0,0,0,0,0,6,6,6,6,6,6,6,6,6,6,6,6,6,6,6,6,6,6,6,6,6,6,6,0,0,0,0,12,6,6,0,0
0,6,6,6,12,12,14,0,0,6,6,6,6,6,6,6,6,6,6,6,6,6,6,6,6,6,6,6,6,6,6,6,0,0,14,12,12,6,6,6,0
0,0,6,6,10,10,10,0,0,6,6,0,6,0,6,0,6,0,9,0,0,0,22,0,6,0,6,0,6,0,6,6,0,0,0,10,10,6,6,0,0
0,6,6,6,6,10,10,10,6,6,6,6,0,0,0,0,0,6,6,0,0,0,6,6,0,0,0,0,0,6,6,6,6,0,0,10,6,6,6,6,0
0,0,6,6,6,6,6,6,6,6,6,0,0,0,0,0,0,0,9,0,0,0,22,0,0,0,0,0,0,0,6,6,6,6,6,6,6,6,6,0,0
0,0,0,6,6,6,6,6,6,6,0,0,0,0,0,0,0,6,6,0,0,0,6,6,0,0,0,0,0,0,0,6,6,6,6,6,6,6,0,0,0
0,0,0,0,6,0,6,0,6,0,0,0,0,0,0,0,0,0,9,0,0,0,22,0,0,0,0,0,0,0,0,0,6,0,6,0,6,0,0,0,0
0,0,0,0,0,0,0,0,0,0,0,0,0,0,0,0,0,6,6,0,0,0,6,6,0,0,0,0,0,0,0,0,0,0,0,0,0,0,0,0,0
0,0,0,0,0,0,0,0,0,0,0,0,0,0,0,0,0,0,6,18,18,18,6,0,0,0,0,0,0,0,0,0,0,0,0,0,0,0,0,0,0
0,0,0,0,0,0,0,0,0,0,0,0,0,0,0,0,0,9,6,17,17,17,6,22,0,0,0,0,0,0,0,0,0,0,0,0,0,0,0,0,0
0,0,0,0,0,0,0,0,0,0,0,0,0,0,0,0,0,0,6,0,0,0,6,0,0,0,0,0,0,0,0,0,0,0,0,0,0,0,0,0,0
0,0,0,0,0,0,0,0,0,0,0,0,0,0,0,0,0,0,0,0,0,0,0,0,0,0,0,0,0,0,0,0,0,0,0,0,0,0,0,0,0
0,0,0,0,0,0,0,0,0,0,0,0,0,0,0,0,0,0,0,0,0,0,0,0,0,0,0,0,0,0,0,0,0,0,0,0,0,0,0,0,0
0,0,0,0,0,0,0,0,0,0,0,0,0,0,0,0,0,0,0,0,0,0,0,0,0,0,0,0,0,0,0,0,0,0,0,0,0,0,0,0,0
0,0,0,0,0,0,0,0,0,0,0,0,0,0,0,0,0,0,25,0,0,0,25,0,0,0,0,0,0,0,0,0,0,0,0,0,0,0,0,0,0
24,0,0,0,0,0,24,0,0,0,0,0,0,0,0,0,0,0,6,0,0,0,6,0,0,0,0,0,0,0,0,0,0,0,24,0,0,0,0,0,24
:endlayer
layer: 3
0,0,0,0,25,0,25,0,25,0,0,0,0,0,0,0,0,0,0,0,0,0,0,0,0,0,0,0,0,0,0,0,25,0,25,0,25,0,0,0,0
0,0,0,0,6,0,6,0,6,0,0,0,0,0,0,0,0,0,0,0,0,0,0,0,0,0,0,0,0,0,0,0,6,0,6,0,6,0,0,0,0
0,0,26,6,6,6,6,6,6,6,0,0,0,0,0,0,0,0,0,0,0,0,0,0,0,0,0,0,0,0,0,6,6,6,6,6,6,6,0,0,0
0,26,6,6,6,6,6,6,6,6,6,0,0,0,0,0,0,0,0,0,0,0,0,0,0,0,0,0,0,0,6,6,6,6,6,6,6,6,6,0,0
26,6,6,6,6,0,0,0,6,6,6,6,28,0,0,0,0,0,0,0,0,0,0,0,0,0,0,0,26,6,6,6,6,0,0,0,6,6,6,6,28
0,0,6,6,0,0,0,0,0,6,6,0,6,25,6,25,6,25,6,25,6,25,6,25,6,25,6,25,6,0,6,6,0,0,0,0,0,6,6,0,0
26,6,6,6,12,12,5,0,0,6,6,6,6,6,6,6,6,6,6,6,6,6,6,6,6,6,6,6,6,6,6,6,0,0,5,12,12,6,6,6,28
0,0,6,6,10,10,0,0,0,6,6,6,6,6,6,6,6,6,6,6,6,6,6,6,6,6,6,6,6,6,6,6,0,0,0,10,10,6,6,0,0
26,6,6,6,6,10,0,0,0,0,0,0,0,0,0,0,0,0,0,0,0,0,0,0,0,0,0,0,0,0,0,0,0,0,0,10,6,6,6,6,28
0,27,6,6,6,6,6,6,0,0,0,0,0,0,0,0,0,0,0,0,0,0,0,0,0,0,0,0,0,0,0,0,0,6,6,6,6,6,6,0,0
0,0,27,6,6,6,6,6,0,0,0,0,0,0,0,0,0,0,0,0,0,0,0,0,0,0,0,0,0,0,0,0,0,6,6,6,6,6,0,0,0
0,0,0,27,6,0,6,6,0,0,0,0,0,0,0,0,0,0,0,0,0,0,0,0,0,0,0,0,0,0,0,0,0,6,6,0,6,28,0,0,0
0,0,0,0,27,6,6,6,0,0,0,0,0,0,0,0,0,0,0,0,0,0,0,0,0,0,0,0,0,0,0,0,0,6,6,6,0,0,0,0,0
0,0,0,0,0,26,6,6,0,0,0,0,0,0,0,0,0,0,0,0,0,0,0,0,0,0,0,0,0,0,0,0,0,6,6,28,0,0,0,0,0
0,0,0,0,0,6,6,6,0,0,0,0,0,0,0,0,0,0,0,0,0,0,0,0,0,0,0,0,0,0,0,0,0,6,6,6,0,0,0,0,0
0,0,0,0,0,26,6,6,0,0,0,0,0,0,0,0,0,0,0,0,0,0,0,0,0,0,0,0,0,0,0,0,0,6,6,28,0,0,0,0,0
0,0,0,0,0,6,6,6,0,0,0,0,0,0,0,0,0,0,0,0,0,0,0,0,0,0,0,0,0,0,0,0,0,6,6,6,0,0,0,0,0
0,0,0,0,0,26,6,6,0,0,0,0,0,0,0,0,0,0,0,0,0,0,0,0,0,0,0,0,0,0,0,0,0,6,6,28,0,0,0,0,0
0,0,0,0,0,6,6,6,0,0,0,0,0,0,0,0,0,0,0,0,0,0,0,0,0,0,0,0,0,0,0,0,0,6,6,6,0,0,0,0,0
0,0,0,0,0,26,6,6,0,0,0,0,0,0,0,0,0,0,0,0,0,0,0,0,0,0,0,0,0,0,0,0,0,6,6,28,0,0,0,0,0
0,0,0,0,0,6,6,6,0,0,0,0,0,0,0,0,0,0,0,0,0,0,0,0,0,0,0,0,0,0,0,0,0,6,6,6,0,0,0,0,0
0,0,0,0,0,26,6,6,0,0,0,0,0,0,0,0,0,0,0,0,0,0,0,0,0,0,0,0,0,0,0,0,0,6,6,28,0,0,0,0,0
0,0,0,0,0,6,6,6,0,0,0,0,0,0,0,0,0,0,0,0,0,0,0,0,0,0,0,0,0,0,0,0,0,6,6,6,0,0,0,0,0
0,0,0,0,0,26,6,6,0,0,0,0,0,0,0,0,0,0,0,0,0,0,0,0,0,0,0,0,0,0,0,0,0,6,6,28,0,0,0,0,0
0,0,0,0,0,6,6,6,0,0,0,0,0,0,0,0,0,0,0,0,0,0,0,0,0,0,0,0,0,0,0,0,0,6,6,6,0,0,0,0,0
0,0,0,0,0,26,6,6,0,0,0,0,0,0,0,0,0,0,0,0,0,0,0,0,0,0,0,0,0,0,0,0,0,6,6,28,0,0,0,0,0
0,0,0,0,0,6,6,6,0,0,0,0,0,0,0,0,0,0,0,0,0,0,0,0,0,0,0,0,0,0,0,0,0,6,6,6,0,0,0,0,0
0,0,0,0,0,26,6,6,0,0,0,0,0,0,0,0,0,0,0,0,0,0,0,0,0,0,0,0,0,0,0,0,0,6,6,28,0,0,0,0,0
0,0,0,0,25,6,6,6,0,0,0,0,0,0,0,0,0,0,0,0,0,0,0,0,0,0,0,0,0,0,0,0,0,6,6,6,0,0,0,0,0
0,0,0,25,6,0,6,6,0,0,0,0,0,0,0,0,0,0,0,0,0,0,0,0,0,0,0,0,0,0,0,0,0,6,6,0,6,0,0,0,0
0,0,25,6,6,6,6,6,0,0,0,0,0,0,0,0,0,0,0,0,0,0,0,0,0,0,0,0,0,0,0,0,0,6,6,6,6,6,28,0,0
0,25,6,6,6,6,6,6,0,0,0,0,0,0,0,0,0,0,0,0,0,0,0,0,0,0,0,0,0,0,0,0,0,6,6,6,6,6,6,0,0
26,6,6,6,6,0,0,0,0,0,0,0,0,0,0,0,0,0,0,0,0,0,0,0,0,0,0,0,0,0,0,0,0,0,0,0,6,6,6,6,28
0,0,6,6,0,0,0,0,0,6,6,6,6,6,6,6,6,6,6,6,6,6,6,6,6,6,6,6,6,6,6,6,0,0,0,0,0,6,6,0,0
26,6,6,6,0,0,5,0,0,6,6,6,6,6,6,6,6,6,6,6,6,6,6,6,6,6,6,6,6,6,6,6,0,0,5,0,0,6,6,6,28
0,0,6,6,0,0,12,10,10,6,6,0,6,27,6,27,6,0,16,0,0,0,20,0,6,27,6,27,6,0,6,6,10,10,12,0,0,6,6,0,0
26,6,6,6,6,0,12,10,6,6,6,6,0,0,0,0,26,6,6,0,0,0,6,6,28,0,0,0,0,6,6,6,6,10,12,0,6,6,6,6,28
0,26,6,6,6,6,6,6,6,6,6,0,0,0,0,0,0,0,16,0,0,0,20,0,0,0,0,0,0,0,6,6,6,6,6,6,6,6,6,0,0
0,0,26,6,6,6,6,6,6,6,27,0,0,0,0,0,26,6,6,0,0,0,6,6,28,0,0,0,0,0,0,6,6,6,6,6,6,6,0,0,0
0,0,0,0,6,27,6,27,6,0,0,0,0,0,0,0,0,0,16,0,0,0,20,0,0,0,0,0,0,0,0,0,6,0,6,0,6,0,0,0,0
0,0,0,0,0,0,0,0,0,0,0,0,0,0,0,0,0,6,6,18,18,18,6,6,0,0,0,0,0,0,0,0,27,0,27,0,27,0,0,0,0
0,0,0,0,0,0,0,0,0,0,0,0,0,0,0,0,0,27,6,17,17,17,6,27,0,0,0,0,0,0,0,0,0,0,0,0,0,0,0,0,0
0,0,0,0,0,0,0,0,0,0,0,0,0,0,0,0,0,0,6,0,0,0,6,0,0,0,0,0,0,0,0,0,0,0,0,0,0,0,0,0,0
0,0,0,0,0,0,0,0,0,0,0,0,0,0,0,0,0,0,11,0,0,0,11,0,0,0,0,0,0,0,0,0,0,0,0,0,0,0,0,0,0
0,0,0,0,0,0,0,0,0,0,0,0,0,0,0,0,0,0,0,0,0,0,0,0,0,0,0,0,0,30,0,0,0,0,0,0,0,0,0,0,0
0,0,0,0,0,0,0,0,0,0,0,0,0,0,0,0,0,0,0,0,0,0,0,0,0,0,0,0,0,0,0,0,0,0,0,0,0,0,0,0,0
0,0,0,0,0,0,0,0,0,0,0,0,0,0,0,0,0,0,0,0,0,0,0,0,0,0,0,0,0,0,0,0,0,0,0,0,0,0,0,0,0
0,0,0,0,0,0,0,0,0,0,0,0,0,0,0,0,0,0,0,0,0,0,0,0,0,0,0,0,0,0,0,0,0,0,0,0,0,0,0,0,0
0,0,0,0,0,0,0,0,0,0,0,0,0,0,0,0,0,0,29,0,0,0,29,0,0,0,0,0,0,0,0,0,0,0,0,0,0,0,0,0,0
:endlayer
layer: 4
0,0,0,0,0,0,0,0,0,0,0,0,0,0,0,0,0,0,0,0,0,0,0,0,0,0,0,0,0,0,0,0,0,0,0,0,0,0,0,0,0
0,0,0,0,13,0,13,0,13,0,0,0,0,0,0,0,0,0,0,0,0,0,0,0,0,0,0,0,0,0,0,0,13,0,13,0,13,0,0,0,0
0,0,0,9,6,6,6,6,6,22,0,0,0,0,0,0,0,0,0,0,0,0,0,0,0,0,0,0,0,0,0,9,6,6,6,6,6,22,0,0,0
0,0,13,6,6,6,6,6,6,6,13,0,0,0,0,0,0,0,0,0,0,0,0,0,0,0,0,0,0,0,13,6,6,6,6,6,6,6,13,0,0
0,9,6,6,6,0,0,0,6,6,6,22,0,0,0,0,0,0,0,0,0,0,0,0,0,0,0,0,0,9,6,6,6,0,0,0,6,6,6,22,0
0,0,6,6,0,0,0,0,0,6,6,0,13,0,13,0,13,0,13,0,13,0,13,0,13,0,13,0,13,0,6,6,0,0,0,0,0,6,6,0,0
0,9,6,6,0,0,14,0,0,6,6,6,6,6,6,6,6,6,6,6,6,6,6,6,6,6,6,6,6,6,6,6,0,0,14,0,0,6,6,22,0
0,0,6,6,0,0,12,10,10,6,6,6,6,6,6,6,6,6,6,6,6,6,6,6,6,6,6,6,6,6,6,6,10,10,12,0,0,6,6,0,0
0,9,6,6,6,0,12,10,10,6,0,0,0,0,0,0,0,0,0,0,0,0,0,0,0,0,0,0,0,0,0,6,10,10,12,0,6,6,6,22,0
0,0,11,6,6,6,6,6,6,0,0,0,0,0,0,0,0,0,0,0,0,0,0,0,0,0,0,0,0,0,0,0,6,6,6,6,6,6,11,0,0
0,0,0,9,6,6,6,6,0,0,0,0,0,0,0,0,0,0,0,0,0,0,0,0,0,0,0,0,0,0,0,0,0,6,6,6,6,22,0,0,0
0,0,0,0,11,0,6,6,0,0,0,0,0,0,0,0,0,0,0,0,0,0,0,0,0,0,0,0,0,0,0,0,0,6,6,0,11,0,0,0,0
0,0,0,0,0,9,6,6,0,0,0,0,0,0,0,0,0,0,0,0,0,0,0,0,0,0,0,0,0,0,0,0,0,6,6,22,0,0,0,0,0
0,0,0,0,0,0,6,6,0,0,0,0,0,0,0,0,0,0,0,0,0,0,0,0,0,0,0,0,0,0,0,0,0,6,6,0,0,0,0,0,0
0,0,0,0,0,9,6,6,0,0,0,0,0,0,0,0,0,0,0,0,0,0,0,0,0,0,0,0,0,0,0,0,0,6,6,22,0,0,0,0,0
0,0,0,0,0,0,6,6,0,0,0,0,0,0,0,0,0,0,0,0,0,0,0,0,0,0,0,0,0,0,0,0,0,6,6,0,0,0,0,0,0
0,0,0,0,0,9,6,6,0,0,0,0,0,0,0,0,0,0,0,0,0,0,0,0,0,0,0,0,0,0,0,0,0,6,6,22,0,0,0,0,0
0,0,0,0,0,0,6,6,0,0,0,0,0,0,0,0,0,0,0,0,0,0,0,0,0,0,0,0,0,0,0,0,0,6,6,0,0,0,0,0,0
0,0,0,0,0,9,6,6,0,0,0,0,0,0,0,0,0,0,0,0,0,0,0,0,0,0,0,0,0,0,0,0,0,6,6,22,0,0,0,0,0
0,0,0,0,0,0,6,6,0,0,0,0,0,0,0,0,0,0,0,0,0,0,0,0,0,0,0,0,0,0,0,0,0,6,6,0,0,0,0,0,0
0,0,0,0,0,9,6,6,0,0,0,0,0,0,0,0,0,0,0,0,0,0,0,0,0,0,0,0,0,0,0,0,0,6,6,22,0,0,0,0,0
0,0,0,0,0,0,6,6,0,0,0,0,0,0,0,0,0,0,0,0,0,0,0,0,0,0,0,0,0,0,0,0,0,6,6,0,0,0,0,0,0
0,0,0,0,0,9,6,6,0,0,0,0,0,0,0,0,0,0,0,0,0,0,0,0,0,0,0,0,0,0,0,0,0,6,6,22,0,0,0,0,0
0,0,0,0,0,0,6,6,0,0,0,0,0,0,0,0,0,0,0,0,0,0,0,0,0,0,0,0,0,0,0,0,0,6,6,0,0,0,0,0,0
0,0,0,0,0,9,6,6,0,0,0,0,0,0,0,0,0,0,0,0,0,0,0,0,0,0,0,0,0,0,0,0,0,6,6,22,0,0,0,0,0
0,0,0,0,0,0,6,6,0,0,0,0,0,0,0,0,0,0,0,0,0,0,0,0,0,0,0,0,0,0,0,0,0,6,6,0,0,0,0,0,0
0,0,0,0,0,9,6,6,0,0,0,0,0,0,0,0,0,0,0,0,0,0,0,0,0,0,0,0,0,0,0,0,0,6,6,22,0,0,0,0,0
0,0,0,0,0,0,6,6,0,0,0,0,0,0,0,0,0,0,0,0,0,0,0,0,0,0,0,0,0,0,0,0,0,6,6,0,0,0,0,0,0
0,0,0,0,0,9,6,6,0,0,0,0,0,0,0,0,0,0,0,0,0,0,0,0,0,0,0,0,0,0,0,0,0,6,6,22,0,0,0,0,0
0,0,0,0,13,0,6,6,0,0,0,0,0,0,0,0,0,0,0,0,0,0,0,0,0,0,0,0,0,0,0,0,0,6,6,0,13,0,0,0,0
0,0,0,9,6,6,6,6,0,0,0,0,0,0,0,0,0,0,0,0,0,0,0,0,0,0,0,0,0,0,0,0,0,6,6,6,6,22,0,0,0
0,0,13,6,6,6,6,6,6,0,0,0,0,0,0,0,0,0,0,0,0,0,0,0,0,0,0,0,0,0,0,0,6,6,6,6,6,6,13,0,0
0,9,6,6,6,0,0,10,10,6,0,0,0,0,0,0,0,0,0,0,0,0,0,0,0,0,0,0,0,0,0,6,12,10,0,0,6,6,6,22,0
0,0,6,6,0,0,0,10,10,6,6,6,6,6,6,6,6,6,6,6,6,6,6,6,6,6,6,6,6,6,6,6,12,10,0,0,0,6,6,0,0
0,9,6,6,0,0,14,12,12,6,6,6,6,6,6,6,6,6,6,6,6,6,6,6,6,6,6,6,6,6,6,6,12,12,14,0,0,6,6,22,0
0,0,6,6,0,0,0,0,0,6,6,0,11,0,11,0,11,0,9,0,0,0,22,0,11,0,11,0,11,0,6,6,0,0,0,0,0,6,6,0,0
0,9,6,6,6,0,0,0,6,6,6,22,0,0,0,0,0,9,6,0,0,0,6,22,0,0,0,0,0,9,6,6,6,0,0,0,6,6,6,22,0
0,0,11,6,6,6,6,6,6,6,11,0,0,0,0,0,0,0,9,0,0,0,22,0,0,0,0,0,0,0,11,6,6,6,6,6,6,6,11,0,0
0,0,0,9,6,6,6,6,6,22,0,0,0,0,0,0,0,9,6,0,0,0,6,22,0,0,0,0,0,0,0,9,6,6,6,6,6,22,0,0,0
0,0,0,0,11,0,11,0,11,0,0,0,0,0,0,0,0,0,9,18,18,18,22,0,0,0,0,0,0,0,0,0,11,0,11,0,11,0,0,0,0
0,0,0,0,0,0,0,0,0,0,0,0,0,0,0,0,0,9,6,17,17,17,6,22,0,0,0,0,0,0,0,0,0,0,0,0,0,0,0,0,0
0,0,0,0,0,0,0,0,0,0,0,0,0,0,0,0,0,0,6,0,0,0,6,0,0,0,0,0,0,0,0,0,0,0,0,0,0,0,0,0,0
0,0,0,0,0,0,0,0,0,0,0,0,0,0,0,0,0,0,11,0,0,0,11,0,0,0,0,0,0,0,0,0,0,0,0,0,0,0,0,0,0
0,0,0,0,0,0,0,0,0,0,0,0,0,0,0,0,0,0,0,0,0,0,0,0,0,0,0,0,0,0,0,0,0,0,0,0,0,0,0,0,0
0,0,0,0,0,0,0,0,0,0,0,0,0,0,0,0,0,0,0,0,0,0,0,0,0,0,0,0,0,31,0,0,0,0,0,0,0,0,0,0,0
0,0,0,0,0,0,0,0,0,0,0,0,0,0,0,0,0,0,0,0,0,0,0,0,0,0,0,0,0,0,0,0,0,0,0,0,0,0,0,0,0
0,0,0,0,0,0,0,0,0,0,0,0,0,0,0,0,0,0,0,0,0,0,0,0,0,0,0,0,0,0,0,0,0,0,0,0,0,0,0,0,0
0,0,0,0,0,0,0,0,0,0,0,0,0,0,0,0,0,0,0,0,0,0,0,0,0,0,0,0,0,0,0,0,0,0,0,0,0,0,0,0,0
0,0,0,0,0,0,0,0,0,0,0,0,0,0,0,0,0,0,0,0,0,0,0,0,0,0,0,0,0,0,0,0,0,0,0,0,0,0,0,0,0
:endlayer
layer: 5
0,0,0,0,0,0,0,0,0,0,0,0,0,0,0,0,0,0,0,0,0,0,0,0,0,0,0,0,0,0,0,0,0,0,0,0,0,0,0,0,0
0,0,0,0,32,32,32,32,32,0,0,0,0,0,0,0,0,0,0,0,0,0,0,0,0,0,0,0,0,0,0,0,32,32,32,32,32,0,0,0,0
0,0,0,32,6,6,6,6,6,32,0,0,0,0,0,0,0,0,0,0,0,0,0,0,0,0,0,0,0,0,0,32,6,6,6,6,6,32,0,0,0
0,0,32,6,6,6,6,6,6,6,32,0,0,0,0,0,0,0,0,0,0,0,0,0,0,0,0,0,0,0,32,6,6,6,6,6,6,6,32,0,0
0,32,6,6,6,0,0,10,6,6,6,32,0,0,0,0,0,0,0,0,0,0,0,0,0,0,0,0,0,32,6,6,6,10,0,0,6,6,6,32,0
0,32,6,6,0,0,0,10,10,6,6,32,32,32,0,0,0,32,32,32,0,32,32,32,0,0,0,32,32,32,6,6,10,10,0,0,0,6,6,32,0
0,32,6,6,0,0,14,12,12,6,6,6,6,6,6,6,6,6,6,6,6,6,6,6,6,6,6,6,6,6,6,6,12,12,14,0,0,6,6,32,0
0,32,6,6,0,0,0,0,0,6,6,6,6,6,6,6,6,6,6,6,6,6,6,6,6,6,6,6,6,6,6,6,0,0,0,0,0,6,6,32,0
0,32,6,6,6,0,0,0,0,6,0,0,0,0,0,0,0,0,0,0,0,0,0,0,0,0,0,0,0,0,0,6,0,0,0,0,6,6,6,32,0
0,0,32,6,6,6,6,6,6,0,0,0,0,0,0,0,0,0,0,0,0,0,0,0,0,0,0,0,0,0,0,0,6,6,6,6,6,6,32,0,0
0,0,0,32,6,6,6,6,0,0,0,0,0,0,0,0,0,0,0,0,0,0,0,0,0,0,0,0,0,0,0,0,0,6,6,6,6,32,0,0,0
0,0,0,0,32,32,6,6,0,0,0,0,0,0,0,0,0,0,0,0,0,0,0,0,0,0,0,0,0,0,0,0,0,6,6,32,32,0,0,0,0
0,0,0,0,0,32,6,6,0,0,0,0,0,0,0,0,0,0,0,0,0,0,0,0,0,0,0,0,0,0,0,0,0,6,6,32,0,0,0,0,0
0,0,0,0,0,32,6,6,0,0,0,0,0,0,0,0,0,0,0,0,0,0,0,0,0,0,0,0,0,0,0,0,0,6,6,32,0,0,0,0,0
0,0,0,0,0,0,6,6,0,0,0,0,0,0,0,0,0,0,0,0,0,0,0,0,0,0,0,0,0,0,0,0,0,6,6,0,0,0,0,0,0
0,0,0,0,0,0,6,6,0,0,0,0,0,0,0,0,0,0,0,0,0,0,0,0,0,0,0,0,0,0,0,0,0,6,6,0,0,0,0,0,0
0,0,0,0,0,0,6,6,0,0,0,0,0,0,0,0,0,0,0,0,0,0,0,0,0,0,0,0,0,0,0,0,0,6,6,0,0,0,0,0,0
0,0,0,0,0,32,6,6,0,0,0,0,0,0,0,0,0,0,0,0,0,0,0,0,0,0,0,0,0,0,0,0,0,6,6,32,0,0,0,0,0
0,0,0,0,0,32,6,6,0,0,0,0,0,0,0,0,0,0,0,0,0,0,0,0,0,0,0,0,0,0,0,0,0,6,6,32,0,0,0,0,0
0,0,0,0,0,32,6,6,0,0,0,0,0,0,0,0,0,0,0,0,0,0,0,0,0,0,0,0,0,0,0,0,0,6,6,32,0,0,0,0,0
0,0,0,0,0,0,6,6,0,0,0,0,0,0,0,0,0,0,0,0,0,0,0,0,0,0,0,0,0,0,0,0,0,6,6,0,0,0,0,0,0
0,0,0,0,0,32,6,6,0,0,0,0,0,0,0,0,0,0,0,0,0,0,0,0,0,0,0,0,0,0,0,0,0,6,6,32,0,0,0,0,0
0,0,0,0,0,32,6,6,0,0,0,0,0,0,0,0,0,0,0,0,0,0,0,0,0,0,0,0,0,0,0,0,0,6,6,32,0,0,0,0,0
0,0,0,0,0,32,6,6,0,0,0,0,0,0,0,0,0,0,0,0,0,0,0,0,0,0,0,0,0,0,0,0,0,6,6,32,0,0,0,0,0
0,0,0,0,0,0,6,6,0,0,0,0,0,0,0,0,0,0,0,0,0,0,0,0,0,0,0,0,0,0,0,0,0,6,6,0,0,0,0,0,0
0,0,0,0,0,0,6,6,0,0,0,0,0,0,0,0,0,0,0,0,0,0,0,0,0,0,0,0,0,0,0,0,0,6,6,0,0,0,0,0,0
0,0,0,0,0,0,6,6,0,0,0,0,0,0,0,0,0,0,0,0,0,0,0,0,0,0,0,0,0,0,0,0,0,6,6,0,0,0,0,0,0
0,0,0,0,0,32,6,6,0,0,0,0,0,0,0,0,0,0,0,0,0,0,0,0,0,0,0,0,0,0,0,0,0,6,6,32,0,0,0,0,0
0,0,0,0,0,32,6,6,0,0,0,0,0,0,0,0,0,0,0,0,0,0,0,0,0,0,0,0,0,0,0,0,0,6,6,32,0,0,0,0,0
0,0,0,0,32,32,6,6,0,0,0,0,0,0,0,0,0,0,0,0,0,0,0,0,0,0,0,0,0,0,0,0,0,6,6,32,32,0,0,0,0
0,0,0,32,6,6,6,6,0,0,0,0,0,0,0,0,0,0,0,0,0,0,0,0,0,0,0,0,0,0,0,0,0,6,6,6,6,32,0,0,0
0,0,32,6,6,6,6,6,6,0,0,0,0,0,0,0,0,0,0,0,0,0,0,0,0,0,0,0,0,0,0,0,6,6,6,6,6,6,32,0,0
0,32,6,6,6,10,12,0,0,6,0,0,0,0,0,0,0,0,0,0,0,0,0,0,0,0,0,0,0,0,0,6,0,0,12,10,6,6,6,32,0
0,32,6,6,10,10,12,0,0,6,6,6,6,6,6,6,6,6,6,6,6,6,6,6,6,6,6,6,6,6,6,6,0,0,12,10,10,6,6,32,0
0,32,6,6,0,0,14,0,0,6,6,6,6,6,6,6,6,6,6,6,6,6,6,6,6,6,6,6,6,6,6,6,0,0,14,0,0,6,33,32,0
0,32,6,6,0,0,0,0,0,6,6,32,32,32,0,0,0,0,6,0,0,0,6,0,0,0,0,32,32,32,6,6,0,0,0,0,0,6,6,32,0
0,32,6,6,6,0,0,0,6,6,6,32,0,0,0,0,0,0,16,0,0,0,20,0,0,0,0,0,0,32,6,6,6,0,0,0,6,6,6,32,0
0,0,32,6,6,6,6,6,6,6,32,0,0,0,0,0,0,0,6,0,0,0,6,0,0,0,0,0,0,0,32,6,6,6,6,6,6,6,32,0,0
0,0,0,32,6,6,6,6,6,32,0,0,0,0,0,0,0,0,16,18,18,18,20,0,0,0,0,0,0,0,0,32,6,6,33,6,6,32,0,0,0
0,0,0,0,32,32,32,32,32,0,0,0,0,0,0,0,0,0,6,17,17,17,6,0,0,0,0,0,0,0,0,0,32,32,32,32,32,0,0,0,0
0,0,0,0,0,0,0,0,0,0,0,0,0,0,0,0,0,0,6,0,0,0,6,0,0,0,0,0,0,0,0,0,0,0,0,0,0,0,0,0,0
0,0,0,0,0,0,0,0,0,0,0,0,0,0,0,0,0,0,11,0,0,0,11,0,0,0,0,0,0,0,0,0,0,0,0,0,0,0,0,0,0
0,0,0,0,0,0,0,0,0,0,0,0,0,0,0,0,0,0,0,0,0,0,0,0,0,0,0,0,0,0,0,0,0,0,0,0,0,0,0,0,0
0,0,0,0,0,0,0,0,0,0,0,0,0,0,0,0,0,0,0,0,0,0,0,0,0,0,0,0,0,0,0,0,0,0,0,0,0,0,0,0,0
0,0,0,0,0,0,0,0,0,0,0,0,0,0,0,0,0,0,0,0,0,0,0,0,0,0,0,0,0,0,0,0,0,0,0,0,0,0,0,0,0
0,0,0,0,0,0,0,0,0,0,0,0,0,0,0,0,0,0,0,0,0,0,0,0,0,0,0,0,0,0,0,0,0,0,0,0,0,0,0,0,0
0,0,0,0,0,0,0,0,0,0,0,0,0,0,0,0,0,0,0,0,0,0,0,0,0,0,0,0,0,0,0,0,0,0,0,0,0,0,0,0,0
0,0,0,0,0,0,0,0,0,0,0,0,0,0,0,0,0,0,0,0,0,0,0,0,0,0,0,0,0,0,0,0,0,0,0,0,0,0,0,0,0
0,0,0,0,0,0,0,0,0,0,0,0,0,0,0,0,0,0,0,0,0,0,0,0,0,0,0,0,0,0,0,0,0,0,0,0,0,0,0,0,0
:endlayer
layer: 6
0,0,0,0,0,0,0,0,0,0,0,0,0,0,0,0,0,0,0,0,0,0,0,0,0,0,0,0,0,0,0,0,0,0,0,0,0,0,0,0,0
0,0,0,0,32,32,32,32,32,0,0,0,0,0,0,0,0,0,0,0,0,0,0,0,0,0,0,0,0,0,0,0,32,32,32,32,32,0,0,0,0
0,0,0,32,6,6,33,6,6,32,0,0,0,0,0,0,0,0,0,0,0,0,0,0,0,0,0,0,0,0,0,32,6,6,33,6,6,32,0,0,0
0,0,32,6,6,6,6,6,6,6,32,0,0,0,0,0,0,0,0,0,0,0,0,0,0,0,0,0,0,0,32,6,6,6,6,6,6,6,32,0,0
0,32,6,6,6,10,12,0,6,6,6,32,0,0,0,0,0,0,0,0,0,0,0,0,0,0,0,0,0,32,6,6,6,0,12,10,6,6,6,32,0
0,32,6,6,10,10,12,0,0,6,6,32,32,32,29,29,29,32,32,32,29,32,32,32,29,29,29,32,32,32,6,6,0,0,12,10,10,6,6,32,0
0,32,33,6,10,10,14,0,0,6,6,6,6,6,6,6,6,6,6,6,6,6,6,6,6,6,6,6,6,6,6,6,0,0,5,0,0,6,33,32,0
0,32,6,6,10,0,0,0,0,6,6,6,6,6,6,6,6,6,6,6,6,6,6,6,6,6,6,6,6,6,6,6,0,0,0,0,0,6,6,32,0
0,32,6,6,6,0,0,0,0,6,10,10,10,10,10,10,10,10,10,10,10,10,10,10,10,10,10,10,10,10,10,6,0,0,0,0,6,6,6,32,0
0,0,32,6,6,6,6,6,6,10,10,10,10,10,10,10,10,10,10,10,10,10,10,10,10,10,10,10,10,10,10,10,6,6,6,6,6,6,32,0,0
0,0,0,32,6,6,6,6,10,10,10,10,10,5,10,10,10,10,10,10,10,10,10,10,10,10,10,5,10,10,10,10,10,6,6,6,6,32,0,0,0
0,0,0,0,32,32,6,6,10,10,10,10,10,10,10,10,10,10,10,10,10,10,10,10,10,10,10,10,10,10,10,10,10,6,6,32,32,0,0,0,0
0,0,0,0,0,32,6,6,10,10,10,10,10,10,10,10,10,10,10,10,10,10,10,10,10,10,10,10,10,10,10,10,10,6,6,32,0,0,0,0,0
0,0,0,0,0,32,6,6,10,10,10,10,10,10,10,10,10,10,10,10,10,10,10,10,10,10,10,10,10,10,10,10,10,6,6,32,0,0,0,0,0
0,0,0,0,0,29,6,6,10,10,10,10,10,10,10,10,10,10,10,10,5,10,10,10,10,10,10,10,10,10,10,10,10,6,6,29,0,0,0,0,0
0,0,0,0,0,29,6,6,10,10,10,10,10,10,10,10,10,10,10,10,10,10,10,10,10,10,10,10,10,10,10,10,10,6,6,29,0,0,0,0,0
0,0,0,0,0,29,6,6,10,10,10,10,10,10,10,10,10,10,10,10,10,10,10,10,10,10,10,10,10,10,10,10,10,6,6,29,0,0,0,0,0
0,0,0,0,0,32,6,6,10,10,10,10,10,10,10,10,10,10,10,10,10,10,10,10,10,10,10,10,10,10,10,10,10,6,6,32,0,0,0,0,0
0,0,0,0,0,32,6,6,10,10,10,10,10,10,10,10,10,10,10,10,10,10,10,10,10,10,10,10,10,10,10,10,10,6,6,32,0,0,0,0,0
0,0,0,0,0,32,6,6,10,10,10,10,10,10,10,10,10,10,10,10,10,10,10,10,10,10,10,10,10,10,10,10,10,6,6,32,0,0,0,0,0
0,0,0,0,0,29,6,6,10,10,10,10,10,10,10,5,10,10,10,10,10,10,10,10,10,5,10,10,10,10,10,10,10,6,6,29,0,0,0,0,0
0,0,0,0,0,32,6,6,10,10,10,10,10,10,10,10,10,10,10,10,10,10,10,10,10,10,10,10,10,10,10,10,10,6,6,32,0,0,0,0,0
0,0,0,0,0,32,6,6,10,10,10,10,10,10,10,10,10,10,10,10,10,10,10,10,10,10,10,10,10,10,10,10,10,6,6,32,0,0,0,0,0
0,0,0,0,0,32,6,6,10,10,10,10,10,10,10,10,10,10,10,10,10,10,10,10,10,10,10,10,10,10,10,10,10,6,6,32,0,0,0,0,0
0,0,0,0,0,29,6,6,10,10,10,10,10,10,10,10,10,10,10,10,5,10,10,10,10,10,10,10,10,10,10,10,10,6,6,29,0,0,0,0,0
0,0,0,0,0,29,6,6,10,10,10,10,10,10,10,10,10,10,10,10,10,10,10,10,10,10,10,10,10,10,10,10,10,6,6,29,0,0,0,0,0
0,0,0,0,0,29,6,6,10,10,10,10,10,10,10,10,10,10,10,10,10,10,10,10,10,10,10,10,10,10,10,10,10,6,6,29,0,0,0,0,0
0,0,0,0,0,32,6,6,10,10,10,10,10,10,10,10,10,10,10,10,10,10,10,10,10,10,10,10,10,10,10,10,10,6,6,32,0,0,0,0,0
0,0,0,0,0,32,6,6,10,10,10,10,10,10,10,10,10,10,10,10,10,10,10,10,10,10,10,10,10,10,10,10,10,6,6,32,0,0,0,0,0
0,0,0,0,32,32,6,6,10,10,10,10,10,10,10,10,10,10,10,10,10,10,10,10,10,10,10,10,10,10,10,10,10,6,6,32,32,0,0,0,0
0,0,0,32,6,6,6,6,10,10,10,10,10,10,5,10,10,10,10,10,10,10,10,10,10,10,5,10,10,10,10,10,10,6,6,6,6,32,0,0,0
0,0,32,6,6,6,6,6,6,10,10,10,10,10,10,10,10,10,10,10,10,10,10,10,10,10,10,10,10,10,10,10,6,6,6,6,6,6,32,0,0
0,32,6,6,6,0,0,0,0,6,10,10,10,10,10,10,10,10,10,10,10,10,10,10,10,10,10,10,10,10,10,6,0,0,0,0,6,6,6,32,0
0,32,6,6,0,0,0,0,0,6,6,6,6,6,6,6,6,6,6,10,10,10,6,6,6,6,6,6,6,6,6,6,0,0,0,0,0,6,6,32,0
0,32,33,6,12,12,14,0,0,6,6,6,6,6,6,6,6,6,6,10,10,10,6,6,6,6,6,6,6,6,6,6,0,0,14,12,12,6,33,32,0
0,32,6,6,10,10,10,0,0,6,6,32,32,32,29,29,29,29,6,10,10,10,6,29,29,29,29,32,32,32,6,6,0,0,10,10,10,6,6,32,0
0,32,6,6,6,10,10,10,6,6,6,32,0,0,0,0,0,32,6,10,10,10,6,32,0,0,0,0,0,32,6,6,6,10,10,10,6,6,6,32,0
0,0,32,6,6,6,6,6,6,6,32,0,0,0,0,0,0,29,6,10,10,10,6,29,0,0,0,0,0,0,32,6,6,6,6,6,6,6,32,0,0
0,0,0,32,6,6,33,6,6,32,0,0,0,0,0,0,0,29,6,17,17,17,6,29,0,0,0,0,0,0,0,32,6,6,33,6,6,32,0,0,0
0,0,0,0,32,32,32,32,32,0,0,0,0,0,0,0,0,29,6,0,0,0,6,29,0,0,0,0,0,0,0,0,32,32,32,32,32,0,0,0,0
0,0,0,0,0,0,0,0,0,0,0,0,0,0,0,0,0,0,11,0,0,0,11,0,0,0,0,0,0,0,0,0,0,0,0,0,0,0,0,0,0
0,0,0,0,0,0,0,0,0,0,0,0,0,0,0,0,0,0,0,0,0,0,0,0,0,0,0,0,0,0,0,0,0,0,0,0,0,0,0,0,0
0,0,0,0,0,0,0,0,0,0,0,0,0,0,0,0,0,0,0,0,0,0,0,0,0,0,0,0,0,0,0,0,0,0,0,0,0,0,0,0,0
0,0,0,0,0,0,0,0,0,0,0,0,0,0,0,0,0,0,0,0,0,0,0,0,0,0,0,0,0,0,0,0,0,0,0,0,0,0,0,0,0
0,0,0,0,0,0,0,0,0,0,0,0,0,0,0,0,0,0,0,0,0,0,0,0,0,0,0,0,0,0,0,0,0,0,0,0,0,0,0,0,0
0,0,0,0,0,0,0,0,0,0,0,0,0,0,0,0,0,0,0,0,0,0,0,0,0,0,0,0,0,0,0,0,0,0,0,0,0,0,0,0,0
0,0,0,0,0,0,0,0,0,0,0,0,0,0,0,0,0,0,0,0,0,0,0,0,0,0,0,0,0,0,0,0,0,0,0,0,0,0,0,0,0
0,0,0,0,0,0,0,0,0,0,0,0,0,0,0,0,0,0,0,0,0,0,0,0,0,0,0,0,0,0,0,0,0,0,0,0,0,0,0,0,0
0,0,0,0,0,0,0,0,0,0,0,0,0,0,0,0,0,0,0,0,0,0,0,0,0,0,0,0,0,0,0,0,0,0,0,0,0,0,0,0,0
:endlayer
layer: 7
0,0,0,0,0,0,0,0,0,0,0,0,0,0,0,0,0,0,0,0,0,0,0,0,0,0,0,0,0,0,0,0,0,0,0,0,0,0,0,0,0
0,0,0,0,0,0,0,0,0,0,0,0,0,0,0,0,0,0,0,0,0,0,0,0,0,0,0,0,0,0,0,0,0,0,0,0,0,0,0,0,0
0,0,0,16,6,22,35,9,6,20,0,0,0,0,0,0,0,0,0,0,0,0,0,0,0,0,0,0,0,0,0,16,6,22,35,9,6,20,0,0,0
0,0,35,6,6,6,6,6,6,6,35,0,0,0,0,0,0,0,0,0,0,0,0,0,0,0,0,0,0,0,35,6,6,6,6,6,6,6,35,0,0
0,0,6,6,6,0,0,0,6,6,6,0,0,0,0,0,0,0,0,0,0,0,0,0,0,0,0,0,0,0,6,6,6,0,0,0,6,6,6,0,0
0,0,11,6,0,0,0,0,0,6,11,0,0,0,29,29,29,0,0,0,29,0,0,0,29,29,29,0,0,0,11,6,0,0,0,0,0,6,11,0,0
0,0,16,6,12,12,5,0,0,6,6,36,36,36,6,6,6,36,36,36,33,36,36,36,6,6,6,36,36,36,6,6,0,0,14,12,12,6,20,0,0
0,0,13,6,10,10,37,0,0,6,6,6,6,6,6,6,6,6,6,6,6,6,6,6,6,6,6,6,6,6,6,6,0,0,0,10,10,6,13,0,0
0,0,6,6,6,10,37,0,0,6,6,12,0,0,0,38,44,39,39,39,39,39,39,39,43,38,0,0,0,0,12,6,37,0,37,10,6,6,6,0,0
0,0,34,6,6,6,6,6,6,38,12,0,0,0,0,0,44,39,39,39,39,39,39,39,43,0,0,0,0,0,0,38,6,6,6,6,6,6,34,0,0
0,0,0,16,6,22,6,6,6,12,0,0,0,0,0,0,44,39,39,39,39,39,39,39,43,0,0,0,0,0,0,0,12,6,6,9,6,20,0,0,0
0,0,0,0,0,0,36,6,12,0,0,0,0,0,0,0,44,39,39,39,49,39,39,39,43,0,0,0,0,0,0,0,0,6,36,0,0,0,0,0,0
0,0,0,0,0,0,36,6,0,0,0,0,0,41,0,0,6,40,40,40,40,40,40,40,6,0,0,41,0,0,0,0,0,6,36,0,0,0,0,0,0
0,0,0,0,0,0,36,6,0,0,0,0,39,39,39,0,0,42,42,42,42,42,42,42,0,0,39,39,39,0,0,0,0,6,36,0,0,0,0,0,0
0,0,0,0,0,29,6,6,0,0,0,0,39,39,39,39,43,42,45,45,45,45,45,42,44,39,39,39,39,0,0,0,0,6,6,29,0,0,0,0,0
0,0,0,0,0,29,6,6,38,0,0,0,39,39,39,39,43,42,45,46,46,46,45,42,44,39,39,39,39,0,0,0,38,6,6,29,0,0,0,0,0
0,0,0,0,0,29,6,6,0,0,0,0,39,39,39,39,43,42,45,46,46,46,45,42,44,39,39,39,39,0,0,0,0,6,6,29,0,0,0,0,0
0,0,0,0,0,0,36,6,0,0,0,0,39,39,39,39,43,42,45,46,46,46,45,42,44,39,39,39,39,0,0,0,0,6,36,0,0,0,0,0,0
0,0,0,0,0,0,36,6,0,0,0,0,39,39,39,5,43,42,45,46,48,46,45,42,44,5,39,39,39,0,0,0,0,6,36,0,0,0,0,0,0
0,0,0,0,0,0,36,6,0,0,0,0,39,39,39,39,43,42,45,46,46,46,45,42,44,39,39,39,39,0,0,0,0,6,36,0,0,0,0,0,0
0,0,0,0,0,29,33,6,38,0,0,0,39,39,39,39,43,42,45,46,46,46,45,42,44,39,39,39,39,0,0,0,38,6,33,29,0,0,0,0,0
0,0,0,0,0,0,36,6,0,0,0,0,39,39,39,39,43,42,45,46,46,46,45,42,44,39,39,39,39,0,0,0,0,6,36,0,0,0,0,0,0
0,0,0,0,0,0,36,6,0,0,0,0,39,39,39,39,43,42,45,45,45,45,45,42,44,39,39,39,39,0,0,0,0,6,36,0,0,0,0,0,0
0,0,0,0,0,0,36,6,0,0,0,0,39,39,39,39,43,42,42,42,42,42,42,42,44,39,39,39,39,0,0,0,0,6,36,0,0,0,0,0,0
0,0,0,0,0,29,6,6,0,0,0,0,39,39,39,40,39,42,42,42,42,42,42,42,39,40,39,39,39,0,0,0,0,6,6,29,0,0,0,0,0
0,0,0,0,0,29,6,6,38,0,0,0,0,40,42,42,42,42,42,42,42,42,42,42,42,42,42,40,0,0,0,0,38,6,6,29,0,0,0,0,0
0,0,0,0,0,29,6,6,6,0,0,0,6,0,6,6,6,6,6,42,42,42,6,6,6,6,6,0,6,0,0,0,6,6,6,29,0,0,0,0,0
0,0,0,0,0,0,36,6,0,0,0,0,0,0,0,0,0,0,33,42,42,42,33,0,0,0,0,0,0,0,0,0,0,6,36,0,0,0,0,0,0
0,0,0,0,0,0,36,6,0,0,0,0,0,0,0,0,0,0,0,0,0,0,0,0,0,0,0,0,0,0,0,0,0,6,36,0,0,0,0,0,0
0,0,0,0,0,0,36,6,0,0,0,0,0,0,0,0,0,0,0,0,0,0,0,0,0,0,0,0,0,0,0,0,0,6,36,0,0,0,0,0,0
0,0,0,16,6,22,6,6,12,0,0,0,0,0,0,0,0,0,0,0,0,0,0,0,0,0,0,0,0,0,0,0,12,6,6,9,6,20,0,0,0
0,0,35,6,6,6,6,6,6,12,0,0,0,0,0,0,0,0,0,0,0,0,0,0,0,0,0,0,0,0,0,12,6,6,6,6,6,6,35,0,0
0,0,6,6,6,0,0,0,37,6,12,0,0,0,0,0,0,0,0,6,47,6,0,0,0,0,0,0,0,0,12,6,37,0,0,0,6,6,6,0,0
0,0,11,6,0,0,0,0,0,6,6,6,6,6,6,6,6,6,6,0,0,0,6,6,6,6,6,6,6,6,6,6,0,0,0,0,0,6,11,0,0
0,0,16,6,0,0,5,37,37,6,6,36,36,36,6,6,6,36,6,0,0,0,6,36,6,6,6,36,36,36,6,6,37,37,5,0,0,6,20,0,0
0,0,13,6,0,0,12,10,10,6,13,0,0,0,29,29,29,29,6,0,0,0,6,29,29,29,29,0,0,0,13,6,10,10,12,0,0,6,13,0,0
0,0,6,6,6,0,12,10,6,6,6,0,0,0,0,0,0,32,6,0,0,0,6,32,0,0,0,0,0,0,6,6,6,10,12,0,6,6,6,0,0
0,0,34,6,6,6,6,6,6,6,34,0,0,0,0,0,0,29,6,0,0,0,6,29,0,0,0,0,0,0,34,6,6,6,6,6,6,6,34,0,0
0,0,0,16,6,22,34,9,6,20,0,0,0,0,0,0,0,29,6,0,0,0,6,29,0,0,0,0,0,0,0,16,6,22,34,9,6,20,0,0,0
0,0,0,0,0,0,0,0,0,0,0,0,0,0,0,0,0,0,11,0,0,0,11,0,0,0,0,0,0,0,0,0,0,0,0,0,0,0,0,0,0
0,0,0,0,0,0,0,0,0,0,0,0,0,0,0,0,0,0,0,0,0,0,0,0,0,0,0,0,0,0,0,0,0,0,0,0,0,0,0,0,0
0,0,0,0,0,0,0,0,0,0,0,0,0,0,0,0,0,0,0,0,0,0,0,0,0,0,0,0,0,0,0,0,0,0,0,0,0,0,0,0,0
0,0,0,0,0,0,0,0,0,0,0,0,0,0,0,0,0,0,0,0,0,0,0,0,0,0,0,0,0,0,0,0,0,0,0,0,0,0,0,0,0
0,0,0,0,0,0,0,0,0,0,0,0,0,0,0,0,0,0,0,0,0,0,0,0,0,0,0,0,0,0,0,0,0,0,0,0,0,0,0,0,0
0,0,0,0,0,0,0,0,0,0,0,0,0,0,0,0,0,0,0,0,0,0,0,0,0,0,0,0,0,0,0,0,0,0,0,0,0,0,0,0,0
0,0,0,0,0,0,0,0,0,0,0,0,0,0,0,0,0,0,0,0,0,0,0,0,0,0,0,0,0,0,0,0,0,0,0,0,0,0,0,0,0
0,0,0,0,0,0,0,0,0,0,0,0,0,0,0,0,0,0,0,0,0,0,0,0,0,0,0,0,0,0,0,0,0,0,0,0,0,0,0,0,0
0,0,0,0,0,0,0,0,0,0,0,0,0,0,0,0,0,0,0,0,0,0,0,0,0,0,0,0,0,0,0,0,0,0,0,0,0,0,0,0,0
0,0,0,0,0,0,0,0,0,0,0,0,0,0,0,0,0,0,0,0,0,0,0,0,0,0,0,0,0,0,0,0,0,0,0,0,0,0,0,0,0
:endlayer
layer: 8
0,0,0,0,0,0,0,0,0,0,0,0,0,0,0,0,0,0,0,0,0,0,0,0,0,0,0,0,0,0,0,0,0,0,0,0,0,0,0,0,0
0,0,0,0,0,0,0,0,0,0,0,0,0,0,0,0,0,0,0,0,0,0,0,0,0,0,0,0,0,0,0,0,0,0,0,0,0,0,0,0,0
0,0,0,9,6,35,0,35,6,22,0,0,0,0,0,0,0,0,0,0,0,0,0,0,0,0,0,0,0,0,0,9,6,35,0,35,6,22,0,0,0
0,0,13,6,6,6,50,6,6,6,13,0,0,0,0,0,0,0,0,0,0,0,0,0,0,0,0,0,0,0,13,6,6,6,50,6,6,6,13,0,0
0,0,6,6,6,0,0,26,6,6,6,28,0,0,0,0,0,0,0,0,0,0,0,0,0,0,0,0,0,26,6,6,6,28,0,0,6,6,6,0,0
0,0,16,6,0,0,0,0,0,6,20,0,0,0,0,0,0,0,0,0,25,0,0,0,0,0,0,0,0,0,16,6,0,0,0,0,0,6,20,0,0
0,0,0,50,0,0,14,37,37,6,6,16,52,20,9,35,22,16,52,20,33,16,52,20,9,35,22,35,52,20,6,6,37,37,14,0,0,50,0,0,0
0,0,16,6,0,0,12,10,10,6,6,6,6,6,6,6,6,6,6,6,6,6,6,6,6,6,6,6,6,6,6,6,10,10,12,0,0,6,20,0,0
0,0,6,6,6,0,12,10,10,12,0,0,0,0,0,38,0,53,0,0,57,0,0,53,0,38,0,0,0,0,0,0,12,10,12,0,6,6,6,0,0
0,0,11,6,6,6,6,6,12,38,0,0,0,0,0,0,0,45,45,0,56,0,45,45,0,0,0,0,0,0,0,38,0,6,6,6,6,6,11,0,0
0,0,0,9,6,34,6,6,0,0,0,0,0,0,0,0,0,45,45,0,0,0,45,45,0,0,0,0,0,0,0,0,0,6,6,34,6,22,0,0,0
0,0,0,0,27,0,35,6,0,0,0,0,0,0,0,0,0,45,45,54,54,54,45,45,0,0,0,0,0,0,0,0,0,6,35,0,27,0,0,0,0
0,0,0,0,0,0,52,6,0,0,0,0,0,0,0,0,53,0,0,0,0,0,0,0,53,0,0,0,0,0,0,0,0,6,52,0,0,0,0,0,0
0,0,0,0,0,0,16,6,0,0,0,0,39,41,39,0,0,0,0,0,0,0,0,0,0,0,39,41,39,0,0,0,0,6,34,0,0,0,0,0,0
0,0,0,0,0,0,13,6,0,0,0,0,39,39,43,42,0,0,0,0,0,0,0,0,0,42,44,39,39,0,0,0,0,6,13,0,0,0,0,0,0
0,0,0,0,0,0,16,6,5,0,0,0,39,39,43,42,0,0,0,0,0,0,0,0,0,42,44,39,39,0,0,0,5,6,20,0,0,0,0,0,0
0,0,0,0,0,0,11,6,0,0,0,0,39,39,43,42,0,0,0,0,0,0,0,0,0,42,44,39,39,0,0,0,0,6,11,0,0,0,0,0,0
0,0,0,0,0,0,35,6,0,0,0,0,39,39,43,42,0,0,0,0,0,0,0,0,0,42,44,39,39,0,0,0,0,6,35,0,0,0,0,0,0
0,0,0,0,0,0,52,6,0,0,0,0,39,39,43,0,0,0,0,0,0,0,0,0,0,0,44,39,39,0,0,0,0,6,52,0,0,0,0,0,0
0,0,0,0,0,0,34,6,0,0,0,0,39,39,43,42,0,0,0,0,0,0,0,0,0,42,44,39,39,0,0,0,0,6,34,0,0,0,0,0,0
0,0,0,0,0,26,33,6,5,0,0,0,39,39,43,42,0,0,0,0,0,0,0,0,0,42,44,39,39,0,0,0,5,6,33,28,0,0,0,0,0
0,0,0,0,0,0,35,6,0,0,0,0,39,39,43,42,0,0,0,0,0,0,0,0,0,42,44,39,39,0,0,0,0,6,35,0,0,0,0,0,0
0,0,0,0,0,0,52,6,0,0,0,0,39,39,43,42,0,0,0,0,0,0,0,0,0,42,44,39,39,0,0,0,0,6,52,0,0,0,0,0,0
0,0,0,0,0,0,34,6,0,0,0,0,39,39,43,42,0,0,0,0,0,0,0,0,0,42,44,39,39,0,0,0,0,6,34,0,0,0,0,0,0
0,0,0,0,0,0,13,6,0,0,0,0,39,40,39,0,53,0,0,0,0,0,0,0,53,0,39,40,39,0,0,0,0,6,13,0,0,0,0,0,0
0,0,0,0,0,0,16,6,5,0,0,0,0,0,0,0,0,0,0,0,0,0,0,0,0,0,0,0,0,0,0,0,5,6,20,0,0,0,0,0,0
0,0,0,0,0,0,11,6,6,0,0,0,6,0,6,6,6,6,6,0,0,0,6,6,6,6,6,0,6,0,0,0,6,6,11,0,0,0,0,0,0
0,0,0,0,0,0,35,6,0,0,0,0,0,0,0,0,0,0,33,0,0,0,33,0,0,0,0,0,0,0,0,0,0,6,20,0,0,0,0,0,0
0,0,0,0,0,0,52,6,0,0,0,0,0,0,0,0,0,0,0,0,0,0,0,0,0,0,0,0,0,0,0,0,0,6,52,0,0,0,0,0,0
0,0,0,0,25,0,34,6,0,0,0,0,0,0,0,0,0,0,0,0,0,0,0,0,0,0,0,0,0,0,0,0,0,6,34,0,0,0,0,0,0
0,0,0,9,6,35,6,6,0,0,0,0,0,0,0,0,0,0,0,0,0,0,0,0,0,0,0,0,0,0,0,0,0,6,6,35,6,22,0,0,0
0,0,13,6,6,6,6,6,0,0,0,0,0,0,0,0,0,0,0,0,0,0,0,0,0,0,0,0,0,0,0,0,0,6,6,6,6,6,13,0,0
0,0,6,6,6,0,37,10,12,0,0,0,0,0,0,0,0,0,0,6,55,6,0,0,0,0,0,0,0,0,0,0,12,10,37,0,6,6,6,0,0
0,0,16,6,27,0,37,10,10,6,6,6,6,6,6,6,6,6,6,27,0,27,6,6,6,6,6,6,6,6,6,6,10,10,37,0,0,6,20,0,0
0,0,0,50,0,0,14,12,12,6,6,16,52,34,9,34,22,16,13,0,0,0,13,20,9,34,22,16,52,20,6,6,12,12,14,0,0,50,0,0,0
0,0,16,6,0,0,0,0,0,6,20,0,0,0,0,0,0,0,13,0,0,0,13,0,0,0,0,0,0,0,16,6,0,0,0,0,0,6,20,0,0
0,0,6,6,6,0,0,0,6,6,6,0,0,0,0,0,0,0,13,0,0,0,13,0,0,0,0,0,0,0,6,6,6,0,0,0,6,6,6,0,0
0,0,11,6,6,6,50,6,6,6,11,0,0,0,0,0,0,0,13,0,0,0,13,0,0,0,0,0,0,0,11,6,6,6,50,6,6,6,11,0,0
0,0,0,9,6,34,51,34,6,22,0,0,0,0,0,0,0,0,11,0,0,0,11,0,0,0,0,0,0,0,0,9,6,34,51,34,6,22,0,0,0
0,0,0,0,0,0,0,0,0,0,0,0,0,0,0,0,0,0,0,0,0,0,0,0,0,0,0,0,0,0,0,0,0,0,0,0,0,0,0,0,0
0,0,0,0,0,0,0,0,0,0,0,0,0,0,0,0,0,0,0,0,0,0,0,0,0,0,0,0,0,0,0,0,0,0,0,0,0,0,0,0,0
0,0,0,0,0,0,0,0,0,0,0,0,0,0,0,0,0,0,0,0,0,0,0,0,0,0,0,0,0,0,0,0,0,0,0,0,0,0,0,0,0
0,0,0,0,0,0,0,0,0,0,0,0,0,0,0,0,0,0,0,0,0,0,0,0,0,0,0,0,0,0,0,0,0,0,0,0,0,0,0,0,0
0,0,0,0,0,0,0,0,0,0,0,0,0,0,0,0,0,0,0,0,0,0,0,0,0,0,0,0,0,0,0,0,0,0,0,0,0,0,0,0,0
0,0,0,0,0,0,0,0,0,0,0,0,0,0,0,0,0,0,0,0,0,0,0,0,0,0,0,0,0,0,0,0,0,0,0,0,0,0,0,0,0
0,0,0,0,0,0,0,0,0,0,0,0,0,0,0,0,0,0,0,0,0,0,0,0,0,0,0,0,0,0,0,0,0,0,0,0,0,0,0,0,0
0,0,0,0,0,0,0,0,0,0,0,0,0,0,0,0,0,0,0,0,0,0,0,0,0,0,0,0,0,0,0,0,0,0,0,0,0,0,0,0,0
0,0,0,0,0,0,0,0,0,0,0,0,0,0,0,0,0,0,0,0,0,0,0,0,0,0,0,0,0,0,0,0,0,0,0,0,0,0,0,0,0
0,0,0,0,0,0,0,0,0,0,0,0,0,0,0,0,0,0,0,0,0,0,0,0,0,0,0,0,0,0,0,0,0,0,0,0,0,0,0,0,0
:endlayer
layer: 9
0,0,0,0,0,0,0,0,0,0,0,0,0,0,0,0,0,0,0,0,0,0,0,0,0,0,0,0,0,0,0,0,0,0,0,0,0,0,0,0,0
0,0,0,0,0,0,0,0,0,0,0,0,0,0,0,0,0,0,0,0,0,0,0,0,0,0,0,0,0,0,0,0,0,0,0,0,0,0,0,0,0
0,0,0,0,6,58,0,58,6,0,0,0,0,0,0,0,0,0,0,0,0,0,0,0,0,0,0,0,0,0,0,0,6,58,0,58,6,0,0,0,0
0,0,0,6,6,6,50,6,6,6,0,0,0,0,0,0,0,0,0,0,0,0,0,0,0,0,0,0,0,0,0,6,6,6,50,6,6,6,0,0,0
0,0,6,6,6,0,37,10,6,6,6,0,0,0,0,0,0,0,0,0,0,0,0,0,0,0,0,0,0,0,6,6,6,10,37,0,6,6,6,0,0
0,0,58,6,0,0,37,10,10,6,58,0,0,0,0,0,0,0,0,0,0,0,0,0,0,0,0,0,0,0,58,6,10,10,37,0,0,6,58,0,0
0,0,0,50,0,0,14,12,12,6,6,58,0,58,0,13,0,58,0,58,33,58,0,58,0,13,0,58,0,58,6,6,12,12,14,0,0,50,0,0,0
0,0,58,6,0,0,0,0,0,6,6,6,50,6,6,6,6,6,50,6,6,6,50,6,6,6,6,6,50,6,6,6,0,0,0,0,0,6,58,0,0
0,0,6,6,6,0,0,0,0,0,0,0,0,0,0,38,0,51,0,0,57,0,0,51,0,38,0,0,0,0,0,0,0,0,0,0,6,6,6,0,0
0,0,0,6,6,6,6,6,0,5,0,0,0,0,0,59,0,0,0,0,0,0,0,0,0,62,0,0,0,0,0,5,0,6,6,6,6,6,0,0,0
0,0,0,0,6,58,6,6,0,0,0,0,0,0,0,0,0,0,0,0,0,0,0,0,0,0,0,0,0,0,0,0,0,6,6,58,6,0,0,0,0
0,0,0,0,0,0,58,6,0,0,0,0,0,0,0,0,0,0,0,60,60,60,0,0,0,0,0,0,0,0,0,0,0,6,58,0,0,0,0,0,0
0,0,0,0,0,0,0,50,0,0,0,0,0,0,0,0,24,0,0,0,0,0,0,0,24,0,0,0,0,0,0,0,0,50,0,0,0,0,0,0,0
0,0,0,0,0,0,58,6,0,0,0,26,39,0,53,0,0,0,0,0,0,0,0,0,0,0,53,0,39,28,0,0,0,6,58,0,0,0,0,0,0
0,0,0,0,0,0,0,6,0,0,0,0,43,42,0,0,0,0,0,0,0,0,0,0,0,0,0,42,44,0,0,0,0,6,0,0,0,0,0,0,0
0,0,0,0,0,0,9,6,38,0,0,26,43,42,0,0,0,0,0,0,0,0,0,0,0,0,0,42,44,28,0,0,38,6,22,0,0,0,0,0,0
0,0,0,0,0,0,0,6,0,0,0,0,43,42,0,0,0,0,0,0,0,0,0,0,0,0,0,42,44,0,0,0,0,6,0,0,0,0,0,0,0
0,0,0,0,0,0,58,6,0,0,0,0,43,42,0,0,0,0,0,0,0,0,0,0,0,0,0,42,44,0,0,0,0,6,58,0,0,0,0,0,0
0,0,0,0,0,0,0,50,0,0,0,0,43,42,0,0,0,0,0,0,61,0,0,0,0,0,0,42,44,0,0,0,0,50,0,0,0,0,0,0,0
0,0,0,0,0,0,58,6,0,0,0,0,43,42,0,0,0,0,0,0,0,0,0,0,0,0,0,42,44,0,0,0,0,6,58,0,0,0,0,0,0
0,0,0,0,0,0,33,6,38,0,0,26,43,42,0,0,0,0,0,0,0,0,0,0,0,0,0,42,44,28,0,0,38,6,33,0,0,0,0,0,0
0,0,0,0,0,0,58,6,0,0,0,0,43,42,0,0,0,0,0,0,0,0,0,0,0,0,0,42,44,0,0,0,0,6,58,0,0,0,0,0,0
0,0,0,0,0,0,0,50,0,0,0,0,43,42,0,0,0,0,0,0,0,0,0,0,0,0,0,42,44,0,0,0,0,50,0,0,0,0,0,0,0
0,0,0,0,0,0,58,6,0,0,0,0,43,42,0,0,0,0,0,0,0,0,0,0,0,0,0,42,44,0,0,0,0,6,58,0,0,0,0,0,0
0,0,0,0,0,0,0,6,0,0,0,26,39,0,53,0,24,0,0,0,0,0,0,0,24,0,53,0,39,28,0,0,0,6,0,0,0,0,0,0,0
0,0,0,0,0,0,9,6,38,0,0,0,0,0,0,0,0,0,0,0,0,0,0,0,0,0,0,0,0,0,0,0,38,6,22,0,0,0,0,0,0
0,0,0,0,0,0,0,6,6,0,0,0,6,0,6,6,6,6,6,0,0,0,6,6,6,6,6,0,6,0,0,0,6,6,0,0,0,0,0,0,0
0,0,0,0,0,0,58,6,0,0,0,0,0,0,0,0,0,0,33,0,0,0,33,0,0,0,0,0,0,0,0,0,0,6,58,0,0,0,0,0,0
0,0,0,0,0,0,0,50,0,0,0,0,0,0,0,0,0,0,0,0,0,0,0,0,0,0,0,0,0,0,0,0,0,50,0,0,0,0,0,0,0
0,0,0,0,0,0,58,6,0,0,0,0,0,0,0,0,0,0,0,0,0,0,0,0,0,0,0,0,0,0,0,0,0,6,58,0,0,0,0,0,0
0,0,0,0,6,58,6,6,0,0,0,0,0,0,0,0,0,0,0,0,0,0,0,0,0,0,0,0,0,0,0,0,0,6,6,58,6,0,0,0,0
0,0,0,6,6,6,6,6,0,0,0,0,0,0,0,0,0,0,0,25,0,25,0,0,0,0,0,0,0,0,0,0,0,6,6,6,6,6,0,0,0
0,0,6,6,6,10,12,0,0,0,0,0,0,0,0,0,0,0,0,6,34,6,0,0,0,0,0,0,0,0,0,0,0,0,12,10,6,6,6,0,0
0,0,58,6,10,10,12,0,0,6,6,6,50,6,6,6,6,6,6,0,0,0,6,6,6,6,6,6,50,6,6,6,0,0,12,10,10,6,58,0,0
0,0,0,50,37,37,14,0,0,6,6,58,0,58,0,11,0,58,27,0,0,0,27,58,0,11,0,58,0,58,6,6,0,0,14,37,37,50,0,0,0
0,0,58,6,0,0,0,0,0,6,58,0,0,0,0,0,0,0,0,0,0,0,0,0,0,0,0,0,0,0,58,6,0,0,0,0,0,6,58,0,0
0,0,6,6,6,0,0,0,6,6,6,28,0,0,0,0,0,0,0,0,0,0,0,0,0,0,0,0,0,26,6,6,6,0,0,0,6,6,6,0,0
0,0,0,6,6,6,50,6,6,6,0,0,0,0,0,0,0,0,0,0,0,0,0,0,0,0,0,0,0,0,0,6,6,6,50,6,6,6,0,0,0
0,0,0,0,6,58,0,58,6,0,0,0,0,0,0,0,0,0,0,0,0,0,0,0,0,0,0,0,0,0,0,0,6,58,0,58,6,0,0,0,0
0,0,0,0,0,0,0,0,0,0,0,0,0,0,0,0,0,0,0,0,0,0,0,0,0,0,0,0,0,0,0,0,0,0,0,0,0,0,0,0,0
0,0,0,0,0,0,0,0,0,0,0,0,0,0,0,0,0,0,0,0,0,0,0,0,0,0,0,0,0,0,0,0,0,0,0,0,0,0,0,0,0
0,0,0,0,0,0,0,0,0,0,0,0,0,0,0,0,0,0,0,0,0,0,0,0,0,0,0,0,0,0,0,0,0,0,0,0,0,0,0,0,0
0,0,0,0,0,0,0,0,0,0,0,0,0,0,0,0,0,0,0,0,0,0,0,0,0,0,0,0,0,0,0,0,0,0,0,0,0,0,0,0,0
0,0,0,0,0,0,0,0,0,0,0,0,0,0,0,0,0,0,0,0,0,0,0,0,0,0,0,0,0,0,0,0,0,0,0,0,0,0,0,0,0
0,0,0,0,0,0,0,0,0,0,0,0,0,0,0,0,0,0,0,0,0,0,0,0,0,0,0,0,0,0,0,0,0,0,0,0,0,0,0,0,0
0,0,0,0,0,0,0,0,0,0,0,0,0,0,0,0,0,0,0,0,0,0,0,0,0,0,0,0,0,0,0,0,0,0,0,0,0,0,0,0,0
0,0,0,0,0,0,0,0,0,0,0,0,0,0,0,0,0,0,0,0,0,0,0,0,0,0,0,0,0,0,0,0,0,0,0,0,0,0,0,0,0
0,0,0,0,0,0,0,0,0,0,0,0,0,0,0,0,0,0,0,0,0,0,0,0,0,0,0,0,0,0,0,0,0,0,0,0,0,0,0,0,0
0,0,0,0,0,0,0,0,0,0,0,0,0,0,0,0,0,0,0,0,0,0,0,0,0,0,0,0,0,0,0,0,0,0,0,0,0,0,0,0,0
:endlayer
layer: 10
0,0,0,0,0,0,0,0,0,0,0,0,0,0,0,0,0,0,0,0,0,0,0,0,0,0,0,0,0,0,0,0,0,0,0,0,0,0,0,0,0
0,0,0,0,25,0,0,0,25,0,0,0,0,0,0,0,0,0,0,0,0,0,0,0,0,0,0,0,0,0,0,0,25,0,0,0,25,0,0,0,0
0,0,0,16,6,13,0,13,6,20,0,0,0,0,0,0,0,0,0,0,0,0,0,0,0,0,0,0,0,0,0,16,6,13,0,13,6,20,0,0,0
0,0,35,6,6,6,50,6,6,6,35,0,0,0,0,0,0,0,0,0,0,0,0,0,0,0,0,0,0,0,35,6,6,6,50,6,6,6,35,0,0
0,26,6,6,6,10,12,0,6,6,6,0,0,0,0,0,0,0,0,0,0,0,0,0,0,0,0,0,0,0,6,6,6,0,12,10,6,6,6,28,0
0,0,9,6,10,10,12,0,0,6,22,0,0,0,0,0,0,0,0,0,0,0,0,0,0,0,0,0,0,0,9,6,0,0,12,10,10,6,22,0,0
0,0,0,50,37,37,14,0,0,6,6,58,0,58,0,58,0,58,0,58,33,58,0,58,0,58,0,58,0,58,6,6,0,0,14,37,37,50,0,0,0
0,0,9,6,0,0,0,0,0,6,6,6,50,6,6,6,6,6,50,6,6,6,50,6,6,6,6,6,50,6,6,6,0,0,0,0,26,6,22,0,0
0,26,6,6,6,28,0,0,0,0,0,0,0,0,0,38,0,0,0,0,57,0,0,0,0,38,0,0,0,0,0,0,0,0,0,0,6,6,6,28,0
0,0,34,6,6,6,6,6,0,38,0,0,0,0,0,0,0,0,0,0,0,0,0,0,0,0,0,0,0,0,0,38,0,6,6,6,6,6,34,0,0
0,0,0,16,6,11,6,6,0,0,0,0,0,0,0,0,0,0,0,0,0,0,0,0,0,0,0,0,0,0,0,0,0,6,6,11,6,20,0,0,0
0,0,0,0,0,0,58,6,0,0,0,0,0,0,0,0,0,0,0,0,0,0,0,0,0,0,0,0,0,0,0,0,0,6,58,0,0,0,0,0,0
0,0,0,0,0,0,0,50,0,0,0,0,0,0,0,0,0,0,0,0,0,0,0,0,0,0,0,0,0,0,0,0,0,50,0,0,0,0,0,0,0
0,0,0,0,0,0,58,6,0,0,0,0,53,0,51,0,0,0,0,0,0,0,0,0,0,0,51,0,53,0,0,0,0,6,58,0,0,0,0,0,0
0,0,0,0,0,0,0,6,0,0,0,0,0,0,0,0,0,0,0,0,0,0,0,0,0,0,0,0,0,0,0,0,0,6,0,0,0,0,0,0,0
0,0,0,0,0,0,58,6,38,0,0,0,0,0,0,0,0,0,0,0,0,0,0,0,0,0,0,0,0,0,0,0,38,6,58,0,0,0,0,0,0
0,0,0,0,0,0,0,6,0,0,0,0,0,0,0,0,0,0,0,0,0,0,0,0,0,0,0,0,0,0,0,0,0,6,0,0,0,0,0,0,0
0,0,0,0,0,0,58,6,0,0,0,0,0,0,0,0,0,0,0,0,0,0,0,0,0,0,0,0,0,0,0,0,0,6,58,0,0,0,0,0,0
0,0,0,0,0,0,0,50,0,0,0,0,0,0,0,0,0,0,0,0,63,0,0,0,0,0,0,0,0,0,0,0,0,50,0,0,0,0,0,0,0
0,0,0,0,0,0,58,6,0,0,0,0,0,0,0,0,0,0,0,0,0,0,0,0,0,0,0,0,0,0,0,0,0,6,58,0,0,0,0,0,0
0,0,0,0,0,0,33,6,38,0,0,0,0,0,0,0,0,0,0,0,0,0,0,0,0,0,0,0,0,0,0,0,38,6,33,0,0,0,0,0,0
0,0,0,0,0,0,58,6,0,0,0,0,0,0,0,0,0,0,0,0,0,0,0,0,0,0,0,0,0,0,0,0,0,6,58,0,0,0,0,0,0
0,0,0,0,0,0,0,50,0,0,0,0,0,0,0,0,0,0,0,0,0,0,0,0,0,0,0,0,0,0,0,0,0,50,0,0,0,0,0,0,0
0,0,0,0,0,0,58,6,0,0,0,0,0,0,0,0,0,0,0,0,0,0,0,0,0,0,0,0,0,0,0,0,0,6,58,0,0,0,0,0,0
0,0,0,0,0,0,0,6,0,0,0,0,53,0,51,0,0,0,0,0,0,0,0,0,0,0,51,0,53,0,0,0,0,6,0,0,0,0,0,0,0
0,0,0,0,0,0,58,6,38,0,0,0,25,0,0,0,0,0,25,0,0,0,25,0,0,0,0,0,25,0,0,0,38,6,58,0,0,0,0,0,0
0,0,0,0,0,0,0,6,6,20,0,16,6,0,6,6,6,6,6,20,0,16,6,6,6,6,6,0,6,20,0,16,6,6,0,0,0,0,0,0,0
0,0,0,0,0,0,58,6,27,0,0,0,27,0,27,0,0,0,33,0,0,0,33,0,0,0,27,0,27,0,0,0,27,6,58,0,0,0,0,0,0
0,0,0,0,0,0,0,50,0,0,0,0,0,0,0,0,0,0,0,0,0,0,0,0,0,0,0,0,0,0,0,0,0,50,0,0,0,0,0,0,0
0,0,0,0,0,0,58,6,0,0,0,0,0,0,0,0,0,0,0,0,0,0,0,0,0,0,0,0,0,0,0,0,0,6,58,0,0,0,0,0,0
0,0,0,16,6,13,6,6,0,0,0,0,0,0,0,0,0,0,0,0,0,0,0,0,0,0,0,0,0,0,0,0,0,6,6,13,6,20,0,0,0
0,0,35,6,6,6,6,6,0,0,0,0,0,0,0,0,0,0,0,0,0,0,0,0,0,0,0,0,0,0,0,0,0,6,6,6,6,6,35,0,0
0,26,6,6,6,0,0,0,0,0,0,0,0,0,0,0,0,0,0,9,13,22,0,0,0,0,0,0,0,0,0,0,0,0,0,0,6,6,6,28,0
0,0,9,6,0,0,0,0,0,6,6,6,50,6,6,6,6,6,6,20,27,16,6,6,6,6,6,6,50,6,6,6,0,0,0,0,0,6,22,0,0
0,0,0,50,12,12,14,0,0,6,6,58,0,58,0,58,0,58,0,0,0,0,0,58,0,58,0,58,0,58,6,6,0,0,14,12,12,50,0,0,0
0,0,9,6,10,10,37,0,25,6,22,0,0,0,0,0,0,0,0,0,0,0,0,0,0,0,0,0,0,0,9,6,25,0,37,10,10,6,22,0,0
0,26,6,6,6,10,37,0,6,6,6,0,0,0,0,0,0,0,0,0,0,0,0,0,0,0,0,0,0,0,6,6,6,0,37,10,6,6,6,28,0
0,0,34,6,6,6,50,6,6,6,34,0,0,0,0,0,0,0,0,0,0,0,0,0,0,0,0,0,0,0,34,6,6,6,50,6,6,6,34,0,0
0,0,0,16,6,11,0,11,6,20,0,0,0,0,0,0,0,0,0,0,0,0,0,0,0,0,0,0,0,0,0,16,6,11,0,11,6,20,0,0,0
0,0,0,0,0,0,0,0,0,0,0,0,0,0,0,0,0,0,0,0,0,0,0,0,0,0,0,0,0,0,0,0,0,0,0,0,0,0,0,0,0
0,0,0,0,0,0,0,0,0,0,0,0,0,0,0,0,0,0,0,0,0,0,0,0,0,0,0,0,0,0,0,0,0,0,0,0,0,0,0,0,0
0,0,0,0,0,0,0,0,0,0,0,0,0,0,0,0,0,0,0,0,0,0,0,0,0,0,0,0,0,0,0,0,0,0,0,0,0,0,0,0,0
0,0,0,0,0,0,0,0,0,0,0,0,0,0,0,0,0,0,0,0,0,0,0,0,0,0,0,0,0,0,0,0,0,0,0,0,0,0,0,0,0
0,0,0,0,0,0,0,0,0,0,0,0,0,0,0,0,0,0,0,0,0,0,0,0,0,0,0,0,0,0,0,0,0,0,0,0,0,0,0,0,0
0,0,0,0,0,0,0,0,0,0,0,0,0,0,0,0,0,0,0,0,0,0,0,0,0,0,0,0,0,0,0,0,0,0,0,0,0,0,0,0,0
0,0,0,0,0,0,0,0,0,0,0,0,0,0,0,0,0,0,0,0,0,0,0,0,0,0,0,0,0,0,0,0,0,0,0,0,0,0,0,0,0
0,0,0,0,0,0,0,0,0,0,0,0,0,0,0,0,0,0,0,0,0,0,0,0,0,0,0,0,0,0,0,0,0,0,0,0,0,0,0,0,0
0,0,0,0,0,0,0,0,0,0,0,0,0,0,0,0,0,0,0,0,0,0,0,0,0,0,0,0,0,0,0,0,0,0,0,0,0,0,0,0,0
0,0,0,0,0,0,0,0,0,0,0,0,0,0,0,0,0,0,0,0,0,0,0,0,0,0,0,0,0,0,0,0,0,0,0,0,0,0,0,0,0
:endlayer
layer: 11
0,0,0,0,0,0,0,0,0,0,0,0,0,0,0,0,0,0,0,0,0,0,0,0,0,0,0,0,0,0,0,0,0,0,0,0,0,0,0,0,0
0,0,0,0,0,0,0,0,0,0,0,0,0,0,0,0,0,0,0,0,0,0,0,0,0,0,0,0,0,0,0,0,0,0,0,0,0,0,0,0,0
0,0,0,9,6,20,13,16,6,22,0,0,0,0,0,0,0,0,0,0,0,0,0,0,0,0,0,0,0,0,0,9,6,20,13,16,6,22,0,0,0
0,0,13,6,6,6,6,6,6,6,13,0,0,0,0,0,0,0,0,0,0,0,0,0,0,0,0,0,0,0,13,6,6,6,6,6,6,6,13,0,0
0,0,6,6,6,0,0,0,6,6,6,0,0,0,0,0,0,0,0,0,0,0,0,0,0,0,0,0,0,0,6,6,6,0,0,0,6,6,6,0,0
0,0,34,6,0,0,0,0,0,6,34,0,0,0,0,0,0,0,0,0,0,0,0,0,0,0,0,0,0,0,34,6,0,0,0,0,0,6,34,0,0
0,0,9,6,12,12,14,0,0,6,6,9,52,22,0,35,0,9,52,22,33,9,52,22,0,35,0,9,52,22,6,6,0,0,14,12,12,6,22,0,0
0,0,35,6,10,10,37,0,0,6,6,6,6,6,6,6,6,6,6,6,6,6,6,6,6,6,6,6,6,6,6,6,0,0,37,10,10,6,35,0,0
0,0,6,6,6,10,37,0,0,6,6,28,27,0,0,38,0,0,27,0,57,0,27,0,0,38,0,0,27,26,6,6,0,0,37,10,6,6,6,0,0
0,0,11,6,6,6,6,6,6,38,27,0,0,0,0,0,0,0,0,0,0,0,0,0,0,0,0,0,0,0,27,38,6,6,6,6,6,6,11,0,0
0,0,0,9,6,20,6,6,6,28,0,0,0,0,0,0,0,0,0,0,0,0,0,0,0,0,0,0,0,0,0,26,6,6,6,16,6,22,0,0,0
0,0,0,0,0,0,13,6,27,0,0,0,0,0,0,0,0,0,0,0,0,0,0,0,0,0,0,0,0,0,0,0,27,6,13,0,0,0,0,0,0
0,0,0,0,0,0,52,6,28,0,0,0,0,0,0,0,0,0,0,0,0,0,0,0,0,0,0,0,0,0,0,0,26,6,52,0,0,0,0,0,0
0,0,0,0,0,0,11,6,0,0,0,0,51,0,0,0,0,0,0,0,0,0,0,0,0,0,0,0,51,0,0,0,0,6,11,0,0,0,0,0,0
0,0,0,0,0,0,0,6,0,0,0,0,0,0,0,0,0,0,0,0,0,0,0,0,0,0,0,0,0,0,0,0,0,6,0,0,0,0,0,0,0
0,0,0,0,0,0,16,6,38,0,0,0,0,0,0,0,0,0,0,0,0,0,0,0,0,0,0,0,0,0,0,0,38,6,20,0,0,0,0,0,0
0,0,0,0,0,0,0,6,0,0,0,0,0,0,0,0,0,0,0,0,0,0,0,0,0,0,0,0,0,0,0,0,0,6,0,0,0,0,0,0,0
0,0,0,0,0,0,13,6,0,0,0,0,0,0,0,0,0,0,0,0,0,0,0,0,0,0,0,0,0,0,0,0,0,6,13,0,0,0,0,0,0
0,0,0,0,0,0,52,6,28,0,0,0,0,0,0,0,0,0,0,0,64,0,0,0,0,0,0,0,0,0,0,0,26,6,52,0,0,0,0,0,0
0,0,0,0,0,0,11,6,0,0,0,0,0,0,0,0,0,0,0,0,0,0,0,0,0,0,0,0,0,0,0,0,0,6,11,0,0,0,0,0,0
0,0,0,0,0,0,33,6,38,0,0,0,0,0,0,0,0,0,0,0,0,0,0,0,0,0,0,0,0,0,0,0,38,6,33,0,0,0,0,0,0
0,0,0,0,0,0,13,6,0,0,0,0,0,0,0,0,0,0,0,0,0,0,0,0,0,0,0,0,0,0,0,0,0,6,13,0,0,0,0,0,0
0,0,0,0,0,0,52,6,28,0,0,0,0,0,0,0,0,0,0,0,0,0,0,0,0,0,0,0,0,0,0,0,26,6,52,0,0,0,0,0,0
0,0,0,0,0,0,11,6,0,0,0,0,0,0,0,0,0,0,0,0,0,0,0,0,0,0,0,0,0,0,0,0,0,6,11,0,0,0,0,0,0
0,0,0,0,0,0,0,6,0,0,0,0,51,0,0,0,0,0,0,0,0,0,0,0,0,0,0,0,51,0,0,0,0,6,0,0,0,0,0,0,0
0,0,0,0,0,0,16,6,38,0,0,0,0,0,0,0,0,0,0,0,0,0,0,0,0,0,0,0,0,0,0,0,38,6,20,0,0,0,0,0,0
0,0,0,0,0,0,0,6,6,6,6,6,6,6,6,6,6,6,6,6,6,6,6,6,6,6,6,6,6,6,6,6,6,6,0,0,0,0,0,0,0
0,0,0,0,0,0,13,6,0,0,0,0,0,0,0,0,0,0,33,0,27,0,33,0,0,0,0,0,0,0,0,0,0,6,13,0,0,0,0,0,0
0,0,0,0,0,0,52,6,28,0,0,0,0,0,0,0,0,0,0,0,0,0,0,0,0,0,0,0,0,0,0,0,26,6,52,0,0,0,0,0,0
0,0,0,0,0,0,11,6,25,0,0,0,0,0,0,0,0,0,0,0,0,0,0,0,0,0,0,0,0,0,0,0,25,6,11,0,0,0,0,0,0
0,0,0,9,6,20,6,6,6,28,0,0,0,0,0,0,0,0,0,0,0,0,0,0,0,0,0,0,0,0,0,26,6,6,6,16,6,22,0,0,0
0,0,13,6,6,6,6,6,6,0,25,0,0,0,0,0,0,0,0,0,0,0,0,0,0,0,0,0,0,0,25,0,6,6,6,6,6,6,13,0,0
0,0,6,6,6,0,0,0,0,6,6,28,25,0,0,0,0,0,0,0,0,0,0,0,0,0,0,0,25,26,6,6,0,0,0,0,6,6,6,0,0
0,0,34,6,0,0,0,0,0,6,6,6,6,6,6,6,6,6,6,6,6,6,6,6,6,6,6,6,6,6,6,6,0,0,0,0,0,6,34,0,0
0,0,9,6,0,0,14,37,37,6,6,9,52,22,0,34,0,9,0,0,0,0,0,22,0,34,0,9,52,22,6,6,37,37,5,0,0,6,22,0,0
0,0,35,6,0,0,12,10,10,6,35,0,0,0,0,0,0,0,0,0,0,0,0,0,0,0,0,0,0,0,35,6,10,10,12,0,0,6,35,0,0
0,0,6,6,6,0,12,10,6,6,6,0,0,0,0,0,0,0,0,0,0,0,0,0,0,0,0,0,0,0,6,6,6,10,12,0,6,6,6,0,0
0,0,11,6,6,6,6,6,6,6,11,0,0,0,0,0,0,0,0,0,0,0,0,0,0,0,0,0,0,0,11,6,6,6,6,6,6,6,11,0,0
0,0,0,9,6,20,11,16,6,22,0,0,0,0,0,0,0,0,0,0,0,0,0,0,0,0,0,0,0,0,0,9,6,20,11,16,6,22,0,0,0
0,0,0,0,0,0,0,0,0,0,0,0,0,0,0,0,0,0,0,0,0,0,0,0,0,0,0,0,0,0,0,0,0,0,0,0,0,0,0,0,0
0,0,0,0,0,0,0,0,0,0,0,0,0,0,0,0,0,0,0,0,0,0,0,0,0,0,0,0,0,0,0,0,0,0,0,0,0,0,0,0,0
0,0,0,0,0,0,0,0,0,0,0,0,0,0,0,0,0,0,0,0,0,0,0,0,0,0,0,0,0,0,0,0,0,0,0,0,0,0,0,0,0
0,0,0,0,0,0,0,0,0,0,0,0,0,0,0,0,0,0,0,0,0,0,0,0,0,0,0,0,0,0,0,0,0,0,0,0,0,0,0,0,0
0,0,0,0,0,0,0,0,0,0,0,0,0,0,0,0,0,0,0,0,0,0,0,0,0,0,0,0,0,0,0,0,0,0,0,0,0,0,0,0,0
0,0,0,0,0,0,0,0,0,0,0,0,0,0,0,0,0,0,0,0,0,0,0,0,0,0,0,0,0,0,0,0,0,0,0,0,0,0,0,0,0
0,0,0,0,0,0,0,0,0,0,0,0,0,0,0,0,0,0,0,0,0,0,0,0,0,0,0,0,0,0,0,0,0,0,0,0,0,0,0,0,0
0,0,0,0,0,0,0,0,0,0,0,0,0,0,0,0,0,0,0,0,0,0,0,0,0,0,0,0,0,0,0,0,0,0,0,0,0,0,0,0,0
0,0,0,0,0,0,0,0,0,0,0,0,0,0,0,0,0,0,0,0,0,0,0,0,0,0,0,0,0,0,0,0,0,0,0,0,0,0,0,0,0
0,0,0,0,0,0,0,0,0,0,0,0,0,0,0,0,0,0,0,0,0,0,0,0,0,0,0,0,0,0,0,0,0,0,0,0,0,0,0,0,0
:endlayer
layer: 12
0,0,0,0,0,0,0,0,0,0,0,0,0,0,0,0,0,0,0,0,0,0,0,0,0,0,0,0,0,0,0,0,0,0,0,0,0,0,0,0,0
0,0,0,0,32,32,32,32,32,0,0,0,0,0,0,0,0,0,0,0,0,0,0,0,0,0,0,0,0,0,0,0,32,32,32,32,32,0,0,0,0
0,0,0,32,6,6,33,6,6,32,0,0,0,0,0,0,0,0,0,0,0,0,0,0,0,0,0,0,0,0,0,32,6,6,33,6,6,32,0,0,0
0,0,32,6,6,6,6,6,6,6,32,0,0,0,0,0,0,0,0,0,0,0,0,0,0,0,0,0,0,0,32,6,6,6,6,6,6,6,32,0,0
0,32,6,6,6,0,0,0,6,6,6,32,0,0,0,0,0,0,0,0,0,0,0,0,0,0,0,0,0,32,6,6,6,0,0,0,6,6,6,32,0
0,32,6,6,0,0,0,0,27,6,6,32,32,32,0,0,0,32,32,32,0,32,32,32,0,0,0,32,32,32,6,6,27,0,0,0,0,6,6,32,0
0,32,33,6,0,0,14,37,37,6,6,6,6,6,16,13,20,6,6,6,33,6,6,6,16,13,20,6,6,6,6,6,37,37,14,0,0,6,33,32,0
0,32,6,6,0,0,12,10,10,6,6,6,6,6,6,6,6,6,6,6,6,6,6,6,6,6,6,6,6,6,6,6,10,10,12,0,0,6,6,32,0
0,32,6,6,6,0,12,10,10,6,66,66,66,66,66,66,66,66,66,66,66,66,66,66,66,66,66,66,66,66,66,6,10,10,12,0,6,6,6,32,0
0,0,32,6,6,6,6,6,6,38,0,0,0,0,0,27,0,0,0,0,27,0,0,0,0,27,0,0,0,0,0,38,6,6,6,6,6,6,32,0,0
0,0,0,32,6,6,6,6,65,0,0,0,0,0,0,0,0,0,0,0,0,0,0,0,0,0,0,0,0,0,0,0,65,6,6,6,6,32,0,0,0
0,0,0,0,32,32,6,6,65,0,0,0,0,0,0,0,0,0,0,0,0,0,0,0,0,0,0,0,0,0,0,0,65,6,6,32,32,0,0,0,0
0,0,0,0,0,32,6,6,65,0,0,0,0,0,0,0,0,0,0,0,0,0,0,0,0,0,0,0,0,0,0,0,65,6,6,32,0,0,0,0,0
0,0,0,0,0,32,6,6,65,0,0,0,0,0,0,0,0,0,0,0,0,0,0,0,0,0,0,0,0,0,0,0,65,6,6,32,0,0,0,0,0
0,0,0,0,0,0,35,6,65,0,0,0,0,0,0,0,0,0,0,0,0,0,0,0,0,0,0,0,0,0,0,0,65,6,35,0,0,0,0,0,0
0,0,0,0,0,0,9,6,65,28,0,0,0,0,0,0,0,0,0,0,0,0,0,0,0,0,0,0,0,0,0,26,65,6,22,0,0,0,0,0,0
0,0,0,0,0,0,34,6,65,0,0,0,0,0,0,0,0,0,0,0,0,0,0,0,0,0,0,0,0,0,0,0,65,6,34,0,0,0,0,0,0
0,0,0,0,0,32,6,6,65,0,0,0,0,0,0,0,0,0,0,0,0,0,0,0,0,0,0,0,0,0,0,0,65,6,6,32,0,0,0,0,0
0,0,0,0,0,32,6,6,65,0,0,0,0,0,0,0,0,0,0,0,67,0,0,0,0,0,0,0,0,0,0,0,65,6,6,32,0,0,0,0,0
0,0,0,0,0,32,6,6,65,0,0,0,0,0,0,0,0,0,0,0,0,0,0,0,0,0,0,0,0,0,0,0,65,6,6,32,0,0,0,0,0
0,0,0,0,0,0,33,6,65,28,0,0,0,0,0,0,0,0,0,0,0,0,0,0,0,0,0,0,0,0,0,26,65,6,33,0,0,0,0,0,0
0,0,0,0,0,32,6,6,65,0,0,0,0,0,0,0,0,0,0,0,0,0,0,0,0,0,0,0,0,0,0,0,65,6,6,32,0,0,0,0,0
0,0,0,0,0,32,6,6,65,0,0,0,0,0,0,0,0,0,0,0,0,0,0,0,0,0,0,0,0,0,0,0,65,6,6,32,0,0,0,0,0
0,0,0,0,0,32,6,6,65,0,0,0,0,0,0,0,0,0,0,0,0,0,0,0,0,0,0,0,0,0,0,0,65,6,6,32,0,0,0,0,0
0,0,0,0,0,0,35,6,65,0,0,0,0,0,0,0,0,0,0,0,0,0,0,0,0,0,0,0,0,0,0,0,65,6,35,0,0,0,0,0,0
0,0,0,0,0,0,9,6,65,28,0,0,0,0,0,0,0,0,0,0,0,0,0,0,0,0,0,0,0,0,0,26,65,6,22,0,0,0,0,0,0
0,0,0,0,0,0,34,6,6,6,6,6,6,6,6,6,6,6,6,6,6,6,6,6,6,6,6,6,6,6,6,6,6,6,34,0,0,0,0,0,0
0,0,0,0,0,32,6,6,0,0,0,0,0,0,0,0,0,0,33,0,0,0,33,0,0,0,0,0,0,0,0,0,0,6,6,32,0,0,0,0,0
0,0,0,0,0,32,6,6,0,0,0,0,0,0,0,0,0,0,0,0,0,0,0,0,0,0,0,0,0,0,0,0,0,6,6,32,0,0,0,0,0
0,0,0,0,32,32,6,6,0,0,0,0,0,0,0,0,0,0,0,0,0,0,0,0,0,0,0,0,0,0,0,0,0,6,6,32,32,0,0,0,0
0,0,0,32,6,6,6,6,5,0,0,0,0,0,0,0,0,0,0,0,0,0,0,0,0,0,0,0,0,0,0,0,0,6,6,6,6,32,0,0,0
0,0,32,6,6,6,6,6,6,0,0,0,0,0,0,0,0,0,0,0,0,0,0,0,0,0,0,0,0,0,0,0,6,6,6,6,6,6,32,0,0
0,32,6,6,6,28,37,10,39,6,5,0,0,0,0,0,0,0,0,0,0,0,0,0,0,0,0,0,0,0,0,6,39,10,37,26,6,6,6,32,0
0,32,6,6,0,0,37,10,10,6,6,6,6,6,6,6,6,6,6,6,6,6,6,6,6,6,6,6,6,6,6,6,10,10,37,0,0,6,6,32,0
0,32,33,6,0,0,14,12,12,6,6,6,6,6,16,11,20,6,6,6,33,6,6,6,16,11,20,6,6,6,6,6,12,12,14,0,0,6,33,32,0
0,32,6,6,0,0,0,0,0,6,6,32,32,32,0,0,0,32,32,32,0,32,32,32,0,0,0,32,32,32,6,6,0,0,0,0,0,6,6,32,0
0,32,6,6,6,0,0,0,6,6,6,32,0,0,0,0,0,0,0,0,0,0,0,0,0,0,0,0,0,32,6,6,6,0,0,0,6,6,6,32,0
0,0,32,6,6,6,6,6,6,6,32,0,0,0,0,0,0,0,0,0,0,0,0,0,0,0,0,0,0,0,32,6,6,6,6,6,6,6,32,0,0
0,0,0,32,6,6,33,6,6,32,0,0,0,0,0,0,0,0,0,0,0,0,0,0,0,0,0,0,0,0,0,32,6,6,33,6,6,32,0,0,0
0,0,0,0,32,32,32,32,32,0,0,0,0,0,0,0,0,0,0,0,0,0,0,0,0,0,0,0,0,0,0,0,32,32,32,32,32,0,0,0,0
0,0,0,0,0,0,0,0,0,0,0,0,0,0,0,0,0,0,0,0,0,0,0,0,0,0,0,0,0,0,0,0,0,0,0,0,0,0,0,0,0
0,0,0,0,0,0,0,0,0,0,0,0,0,0,0,0,0,0,0,0,0,0,0,0,0,0,0,0,0,0,0,0,0,0,0,0,0,0,0,0,0
0,0,0,0,0,0,0,0,0,0,0,0,0,0,0,0,0,0,0,0,0,0,0,0,0,0,0,0,0,0,0,0,0,0,0,0,0,0,0,0,0
0,0,0,0,0,0,0,0,0,0,0,0,0,0,0,0,0,0,0,0,0,0,0,0,0,0,0,0,0,0,0,0,0,0,0,0,0,0,0,0,0
0,0,0,0,0,0,0,0,0,0,0,0,0,0,0,0,0,0,0,0,0,0,0,0,0,0,0,0,0,0,0,0,0,0,0,0,0,0,0,0,0
0,0,0,0,0,0,0,0,0,0,0,0,0,0,0,0,0,0,0,0,0,0,0,0,0,0,0,0,0,0,0,0,0,0,0,0,0,0,0,0,0
0,0,0,0,0,0,0,0,0,0,0,0,0,0,0,0,0,0,0,0,0,0,0,0,0,0,0,0,0,0,0,0,0,0,0,0,0,0,0,0,0
0,0,0,0,0,0,0,0,0,0,0,0,0,0,0,0,0,0,0,0,0,0,0,0,0,0,0,0,0,0,0,0,0,0,0,0,0,0,0,0,0
0,0,0,0,0,0,0,0,0,0,0,0,0,0,0,0,0,0,0,0,0,0,0,0,0,0,0,0,0,0,0,0,0,0,0,0,0,0,0,0,0
:endlayer
layer: 13
0,0,0,0,0,0,0,0,0,0,0,0,0,0,0,0,0,0,0,0,0,0,0,0,0,0,0,0,0,0,0,0,0,0,0,0,0,0,0,0,0
0,0,0,0,0,0,0,0,0,0,0,0,0,0,0,0,0,0,0,0,0,0,0,0,0,0,0,0,0,0,0,0,0,0,0,0,0,0,0,0,0
0,0,0,16,6,22,35,9,6,20,0,0,0,0,0,0,0,0,0,0,0,0,0,0,0,0,0,0,0,0,0,16,6,22,35,9,6,20,0,0,0
0,0,35,6,6,6,6,6,6,6,35,0,0,0,0,0,0,0,0,0,0,0,0,0,0,0,0,0,0,0,35,6,6,6,6,6,6,6,35,0,0
0,0,6,6,6,0,37,10,6,6,6,0,0,0,0,0,0,0,0,0,0,0,0,0,0,0,0,0,0,0,6,6,6,10,37,0,6,6,6,0,0
0,0,11,6,0,0,37,10,10,6,11,0,0,0,29,29,29,0,0,0,29,0,0,0,29,29,29,0,0,0,11,6,10,10,37,0,0,6,11,0,0
0,0,16,6,0,0,14,12,12,6,6,36,36,36,6,6,6,36,36,36,33,36,36,36,6,6,6,36,36,36,6,6,12,12,14,0,0,6,20,0,0
0,0,13,6,0,0,0,0,0,6,6,6,6,6,6,6,6,6,6,6,6,6,6,6,6,6,6,6,6,6,6,6,0,0,0,0,0,6,13,0,0
0,0,6,6,6,0,0,0,0,6,0,0,0,0,0,38,0,0,0,0,38,0,0,0,0,38,0,0,0,0,0,6,0,0,0,0,6,6,6,0,0
0,0,34,6,6,6,6,6,6,38,0,0,0,0,0,0,0,0,0,0,0,0,0,0,0,0,0,0,0,0,0,38,6,6,6,6,6,6,34,0,0
0,0,0,16,6,22,6,6,0,0,0,0,0,0,0,0,0,0,0,0,0,0,0,0,0,0,0,0,0,0,0,0,0,6,6,9,6,20,0,0,0
0,0,0,0,0,0,36,6,0,0,0,0,0,0,0,0,0,0,0,0,0,0,0,0,0,0,0,0,0,0,0,0,0,6,36,0,0,0,0,0,0
0,0,0,0,0,0,36,6,0,0,0,0,0,0,0,0,0,0,0,0,0,0,0,0,0,0,0,0,0,0,0,0,0,6,36,0,0,0,0,0,0
0,0,0,0,0,0,36,6,0,0,0,0,0,0,0,0,0,0,0,0,0,0,0,0,0,0,0,0,0,0,0,0,0,6,36,0,0,0,0,0,0
0,0,0,0,0,29,6,6,0,0,0,0,0,0,0,0,0,0,0,0,0,0,0,0,0,0,0,0,0,0,0,0,0,6,6,29,0,0,0,0,0
0,0,0,0,0,29,6,6,38,0,0,0,0,0,0,0,0,0,0,0,0,0,0,0,0,0,0,0,0,0,0,0,38,6,6,29,0,0,0,0,0
0,0,0,0,0,29,6,6,0,0,0,0,0,0,0,0,0,0,0,0,0,0,0,0,0,0,0,0,0,0,0,0,0,6,6,29,0,0,0,0,0
0,0,0,0,0,0,36,6,0,0,0,0,0,0,0,0,0,0,0,0,0,0,0,0,0,0,0,0,0,0,0,0,0,6,36,0,0,0,0,0,0
0,0,0,0,0,0,36,6,0,0,0,0,0,0,0,0,0,0,0,0,69,0,0,0,0,0,0,0,0,0,0,0,0,6,36,0,0,0,0,0,0
0,0,0,0,0,0,36,6,0,0,0,0,0,0,0,0,0,0,0,0,0,0,0,0,0,0,0,0,0,0,0,0,0,6,36,0,0,0,0,0,0
0,0,0,0,0,29,33,6,38,0,0,0,0,0,0,0,0,0,0,0,0,0,0,0,0,0,0,0,0,0,0,0,38,6,33,29,0,0,0,0,0
0,0,0,0,0,0,36,6,0,0,0,0,0,0,0,0,0,0,0,0,0,0,0,0,0,0,0,0,0,0,0,0,0,6,36,0,0,0,0,0,0
0,0,0,0,0,0,36,6,0,0,0,0,0,0,0,0,0,0,0,0,0,0,0,0,0,0,0,0,0,0,0,0,0,6,36,0,0,0,0,0,0
0,0,0,0,0,0,36,6,0,0,0,0,0,0,0,0,0,0,0,0,0,0,0,0,0,0,0,0,0,0,0,0,0,6,36,0,0,0,0,0,0
0,0,0,0,0,29,6,6,0,0,0,0,0,0,0,0,0,0,0,0,0,0,0,0,0,0,0,0,0,0,0,0,0,6,6,29,0,0,0,0,0
0,0,0,0,0,29,6,6,38,0,0,0,0,0,0,0,0,0,0,0,0,0,0,0,0,0,0,0,0,0,0,0,38,6,6,29,0,0,0,0,0
0,0,0,0,0,29,6,6,41,41,41,41,41,41,41,41,41,41,41,41,41,41,41,41,41,41,41,41,41,41,41,41,41,6,6,29,0,0,0,0,0
0,0,0,0,0,0,36,6,39,39,39,39,39,39,39,39,39,39,39,39,39,39,39,39,39,39,39,39,39,39,39,39,39,6,36,0,0,0,0,0,0
0,0,0,0,0,0,36,6,39,39,39,39,39,39,39,39,39,39,39,39,39,39,39,39,39,39,39,39,39,39,39,39,39,6,36,0,0,0,0,0,0
0,0,0,0,0,0,36,6,39,39,39,39,39,39,39,39,39,39,39,39,39,39,39,39,39,39,39,39,39,39,39,39,39,6,36,0,0,0,0,0,0
0,0,0,16,6,22,6,6,39,39,39,39,39,39,39,39,39,39,39,39,39,39,39,39,39,39,39,39,39,39,39,39,39,6,6,9,6,20,0,0,0
0,0,35,6,6,6,6,6,39,39,39,39,39,39,39,39,39,39,39,39,39,39,39,39,39,39,39,39,39,39,39,39,39,6,6,6,6,6,35,0,0
0,0,6,6,6,10,12,0,68,39,39,39,39,39,39,39,39,39,39,39,39,39,39,39,39,39,39,39,39,39,39,39,68,0,12,10,6,6,6,0,0
0,0,11,6,10,10,12,0,0,6,6,6,6,6,6,6,6,6,6,6,6,6,6,6,6,6,6,6,6,6,6,6,0,0,12,10,10,6,11,0,0
0,0,16,6,37,37,14,0,0,6,6,36,36,36,6,6,6,36,36,36,33,36,36,36,6,6,6,36,36,36,6,6,0,0,14,37,37,6,20,0,0
0,0,13,6,0,0,0,0,0,6,13,0,0,0,29,29,29,0,0,0,29,0,0,0,29,29,29,0,0,0,13,6,0,0,0,0,0,6,13,0,0
0,0,6,6,6,0,0,0,6,6,6,0,0,0,0,0,0,0,0,0,0,0,0,0,0,0,0,0,0,0,6,6,6,0,0,0,6,6,6,0,0
0,0,34,6,6,6,6,6,6,6,34,0,0,0,0,0,0,0,0,0,0,0,0,0,0,0,0,0,0,0,34,6,6,6,6,6,6,6,34,0,0
0,0,0,16,6,22,34,9,6,20,0,0,0,0,0,0,0,0,0,0,0,0,0,0,0,0,0,0,0,0,0,16,6,22,34,9,6,20,0,0,0
0,0,0,0,0,0,0,0,0,0,0,0,0,0,0,0,0,0,0,0,0,0,0,0,0,0,0,0,0,0,0,0,0,0,0,0,0,0,0,0,0
0,0,0,0,0,0,0,0,0,0,0,0,0,0,0,0,0,0,0,0,0,0,0,0,0,0,0,0,0,0,0,0,0,0,0,0,0,0,0,0,0
0,0,0,0,0,0,0,0,0,0,0,0,0,0,0,0,0,0,0,0,0,0,0,0,0,0,0,0,0,0,0,0,0,0,0,0,0,0,0,0,0
0,0,0,0,0,0,0,0,0,0,0,0,0,0,0,0,0,0,0,0,0,0,0,0,0,0,0,0,0,0,0,0,0,0,0,0,0,0,0,0,0
0,0,0,0,0,0,0,0,0,0,0,0,0,0,0,0,0,0,0,0,0,0,0,0,0,0,0,0,0,0,0,0,0,0,0,0,0,0,0,0,0
0,0,0,0,0,0,0,0,0,0,0,0,0,0,0,0,0,0,0,0,0,0,0,0,0,0,0,0,0,0,0,0,0,0,0,0,0,0,0,0,0
0,0,0,0,0,0,0,0,0,0,0,0,0,0,0,0,0,0,0,0,0,0,0,0,0,0,0,0,0,0,0,0,0,0,0,0,0,0,0,0,0
0,0,0,0,0,0,0,0,0,0,0,0,0,0,0,0,0,0,0,0,0,0,0,0,0,0,0,0,0,0,0,0,0,0,0,0,0,0,0,0,0
0,0,0,0,0,0,0,0,0,0,0,0,0,0,0,0,0,0,0,0,0,0,0,0,0,0,0,0,0,0,0,0,0,0,0,0,0,0,0,0,0
0,0,0,0,0,0,0,0,0,0,0,0,0,0,0,0,0,0,0,0,0,0,0,0,0,0,0,0,0,0,0,0,0,0,0,0,0,0,0,0,0
:endlayer
layer: 14
0,0,0,0,0,0,0,0,0,0,0,0,0,0,0,0,0,0,0,0,0,0,0,0,0,0,0,0,0,0,0,0,0,0,0,0,0,0,0,0,0
0,0,0,0,0,0,0,0,0,0,0,0,0,0,0,0,0,0,0,0,0,0,0,0,0,0,0,0,0,0,0,0,0,0,0,0,0,0,0,0,0
0,0,0,9,6,35,0,35,6,22,0,0,0,0,0,0,0,0,0,0,0,0,0,0,0,0,0,0,0,0,0,9,6,35,0,35,6,22,0,0,0
0,0,13,6,6,6,50,6,6,6,13,0,0,0,0,0,0,0,0,0,0,0,0,0,0,0,0,0,0,0,13,6,6,6,50,6,6,6,13,0,0
0,0,6,6,6,10,12,0,6,6,6,28,0,0,0,0,0,0,0,0,0,0,0,0,0,0,0,0,0,26,6,6,6,0,12,10,6,6,6,0,0
0,0,16,6,10,10,12,0,0,6,20,0,0,0,0,0,0,0,0,0,25,0,0,0,0,0,0,0,0,0,16,6,0,0,12,10,10,6,20,0,0
0,0,0,50,37,37,14,0,0,6,6,16,52,20,9,35,22,16,52,20,33,16,52,20,9,35,22,16,52,20,6,6,0,0,14,37,37,50,0,0,0
0,0,16,6,25,0,0,0,0,6,6,6,6,6,6,6,6,6,6,6,6,6,6,6,6,6,6,6,6,6,6,6,0,0,0,0,25,6,20,0,0
0,0,6,6,6,0,0,0,0,6,0,0,0,0,0,38,0,0,0,0,38,0,0,0,0,38,0,0,0,0,0,6,0,0,0,0,6,6,6,0,0
0,0,11,6,6,6,6,6,6,38,0,0,0,0,0,0,0,0,0,0,0,0,0,0,0,0,0,0,0,0,0,38,6,6,6,6,6,6,11,0,0
0,0,0,9,6,34,6,6,0,0,0,0,0,0,0,0,0,0,0,0,0,0,0,0,0,0,0,0,0,0,0,0,0,6,6,34,6,22,0,0,0
0,0,0,0,27,0,35,6,0,0,0,0,0,0,0,0,0,0,0,0,0,0,0,0,0,0,0,0,0,0,0,0,0,6,35,0,27,0,0,0,0
0,0,0,0,0,0,52,6,0,0,0,0,0,0,0,0,0,0,0,0,0,0,0,0,0,0,0,0,0,0,0,0,0,6,52,0,0,0,0,0,0
0,0,0,0,0,0,34,6,0,0,0,0,0,0,0,0,0,0,0,0,0,0,0,0,0,0,0,0,0,0,0,0,0,6,34,0,0,0,0,0,0
0,0,0,0,0,0,13,6,0,0,0,0,0,0,0,0,0,0,0,0,0,0,0,0,0,0,0,0,0,0,0,0,0,6,13,0,0,0,0,0,0
0,0,0,0,0,0,16,6,38,0,0,0,0,0,0,0,0,0,0,0,0,0,0,0,0,0,0,0,0,0,0,0,38,6,20,0,0,0,0,0,0
0,0,0,0,0,0,11,6,0,0,0,0,0,0,0,0,0,0,0,0,0,0,0,0,0,0,0,0,0,0,0,0,0,6,11,0,0,0,0,0,0
0,0,0,0,0,0,35,6,0,0,0,0,0,0,0,0,0,0,0,0,0,0,0,0,0,0,0,0,0,0,0,0,0,6,35,0,0,0,0,0,0
0,0,0,0,0,0,52,6,0,0,0,0,0,0,0,0,0,0,0,0,0,0,0,0,0,0,0,0,0,0,0,0,0,6,52,0,0,0,0,0,0
0,0,0,0,0,0,34,6,0,0,0,0,0,0,0,0,0,0,0,0,0,0,0,0,0,0,0,0,0,0,0,0,0,6,34,0,0,0,0,0,0
0,0,0,0,0,26,33,6,38,0,0,0,0,0,0,0,0,0,0,0,0,0,0,0,0,0,0,0,0,0,0,0,38,6,33,28,0,0,0,0,0
0,0,0,0,0,0,35,6,0,0,0,0,0,0,0,0,0,0,0,0,0,0,0,0,0,0,0,0,0,0,0,0,0,6,35,0,0,0,0,0,0
0,0,0,0,0,0,52,6,0,0,0,0,0,0,0,0,0,0,0,0,0,0,0,0,0,0,0,0,0,0,0,0,0,6,52,0,0,0,0,0,0
0,0,0,0,0,0,34,6,0,0,0,0,0,0,0,0,0,0,0,0,0,0,0,0,0,0,0,0,0,0,0,0,0,6,34,0,0,0,0,0,0
0,0,0,0,0,0,13,6,0,0,0,0,0,0,0,0,0,0,0,0,0,0,0,0,0,0,0,0,0,0,0,0,0,6,13,0,0,0,0,0,0
0,0,0,0,0,0,16,6,38,0,0,0,0,0,0,0,0,0,0,0,0,0,0,0,0,0,0,0,0,0,0,0,38,6,20,0,0,0,0,0,0
0,0,0,0,0,0,11,6,0,0,0,0,0,0,0,0,0,0,0,0,0,0,0,0,0,0,0,0,0,0,0,0,0,6,11,0,0,0,0,0,0
0,0,0,0,0,0,35,6,53,53,53,53,38,53,53,53,53,53,38,53,53,53,38,53,53,53,53,53,38,53,53,53,53,6,35,0,0,0,0,0,0
0,0,0,0,0,0,52,6,0,0,0,0,0,0,0,0,0,0,0,0,0,0,0,0,0,0,0,0,0,0,0,0,0,6,52,0,0,0,0,0,0
0,0,0,0,25,0,34,6,0,0,0,0,0,0,0,0,0,0,0,0,0,0,0,0,0,0,0,0,0,0,0,0,0,6,34,0,0,0,0,0,0
0,0,0,9,6,35,6,6,0,0,0,0,0,0,0,0,0,0,0,0,0,0,0,0,0,0,0,0,0,0,0,0,0,6,6,35,6,22,0,0,0
0,0,13,6,6,6,6,6,0,38,0,0,0,0,0,0,0,0,0,0,0,0,0,0,0,0,0,0,0,0,0,38,0,6,6,6,6,6,13,0,0
0,0,6,6,6,0,0,0,0,0,0,0,0,0,0,38,0,0,0,0,38,0,0,0,0,38,0,0,0,0,0,0,0,0,0,0,6,6,6,0,0
0,0,16,6,0,0,0,0,0,6,6,6,6,6,6,6,6,6,6,6,6,6,6,6,6,6,6,6,6,6,6,6,0,0,0,0,0,6,20,0,0
0,0,0,50,12,12,14,0,0,6,6,16,52,20,9,34,22,16,52,20,33,16,52,20,9,34,22,16,52,20,6,6,0,0,14,12,12,50,0,0,0
0,0,16,6,10,10,37,0,0,6,20,0,0,0,0,0,0,0,0,0,27,0,0,0,0,0,0,0,0,0,16,6,0,0,37,10,10,6,20,0,0
0,0,6,6,6,10,37,26,6,6,6,0,0,0,0,0,0,0,0,0,0,0,0,0,0,0,0,0,0,26,6,6,6,28,37,10,6,6,6,0,0
0,0,11,6,6,6,50,6,6,6,11,0,0,0,0,0,0,0,0,0,0,0,0,0,0,0,0,0,0,0,11,6,6,6,50,6,6,6,11,0,0
0,0,0,9,6,34,51,34,6,22,0,0,0,0,0,0,0,0,0,0,0,0,0,0,0,0,0,0,0,0,0,9,6,34,51,34,6,22,0,0,0
0,0,0,0,0,0,0,0,0,0,0,0,0,0,0,0,0,0,0,0,0,0,0,0,0,0,0,0,0,0,0,0,0,0,0,0,0,0,0,0,0
0,0,0,0,0,0,0,0,0,0,0,0,0,0,0,0,0,0,0,0,0,0,0,0,0,0,0,0,0,0,0,0,0,0,0,0,0,0,0,0,0
0,0,0,0,0,0,0,0,0,0,0,0,0,0,0,0,0,0,0,0,0,0,0,0,0,0,0,0,0,0,0,0,0,0,0,0,0,0,0,0,0
0,0,0,0,0,0,0,0,0,0,0,0,0,0,0,0,0,0,0,0,0,0,0,0,0,0,0,0,0,0,0,0,0,0,0,0,0,0,0,0,0
0,0,0,0,0,0,0,0,0,0,0,0,0,0,0,0,0,0,0,0,0,0,0,0,0,0,0,0,0,0,0,0,0,0,0,0,0,0,0,0,0
0,0,0,0,0,0,0,0,0,0,0,0,0,0,0,0,0,0,0,0,0,0,0,0,0,0,0,0,0,0,0,0,0,0,0,0,0,0,0,0,0
0,0,0,0,0,0,0,0,0,0,0,0,0,0,0,0,0,0,0,0,0,0,0,0,0,0,0,0,0,0,0,0,0,0,0,0,0,0,0,0,0
0,0,0,0,0,0,0,0,0,0,0,0,0,0,0,0,0,0,0,0,0,0,0,0,0,0,0,0,0,0,0,0,0,0,0,0,0,0,0,0,0
0,0,0,0,0,0,0,0,0,0,0,0,0,0,0,0,0,0,0,0,0,0,0,0,0,0,0,0,0,0,0,0,0,0,0,0,0,0,0,0,0
0,0,0,0,0,0,0,0,0,0,0,0,0,0,0,0,0,0,0,0,0,0,0,0,0,0,0,0,0,0,0,0,0,0,0,0,0,0,0,0,0
:endlayer
layer: 15
0,0,0,0,0,0,0,0,0,0,0,0,0,0,0,0,0,0,0,0,0,0,0,0,0,0,0,0,0,0,0,0,0,0,0,0,0,0,0,0,0
0,0,0,0,0,0,0,0,0,0,0,0,0,0,0,0,0,0,0,0,0,0,0,0,0,0,0,0,0,0,0,0,0,0,0,0,0,0,0,0,0
0,0,0,0,6,58,0,58,6,0,0,0,0,0,0,0,0,0,0,0,0,0,0,0,0,0,0,0,0,0,0,0,6,58,0,58,6,0,0,0,0
0,0,0,6,6,6,50,6,6,6,0,0,0,0,0,0,0,0,0,0,0,0,0,0,0,0,0,0,0,0,0,6,6,6,50,6,6,6,0,0,0
0,0,6,6,6,0,0,0,6,6,6,0,0,0,0,0,0,0,0,0,0,0,0,0,0,0,0,0,0,0,6,6,6,0,0,0,6,6,6,0,0
0,0,58,6,0,0,0,0,0,6,58,0,0,0,0,0,0,0,0,0,0,0,0,0,0,0,0,0,0,0,58,6,0,0,0,0,0,6,58,0,0
0,0,0,50,12,12,14,0,0,6,6,58,0,58,0,13,0,58,0,58,33,58,0,58,0,13,0,58,0,58,6,6,0,0,5,12,12,50,0,0,0
0,0,58,6,10,10,37,0,0,6,6,6,50,6,6,6,6,6,50,6,6,6,50,6,6,6,6,6,50,6,6,6,0,0,37,10,10,6,58,0,0
0,0,6,6,6,10,37,0,0,6,0,0,0,0,0,38,0,0,0,0,38,0,0,0,0,38,0,0,0,0,0,6,0,0,37,10,6,6,6,0,0
0,0,0,6,6,6,6,6,6,38,0,0,0,0,0,0,0,0,0,0,0,0,0,0,0,0,0,0,0,0,0,38,6,6,6,6,6,6,0,0,0
0,0,0,0,6,58,6,6,0,0,0,0,0,0,0,0,0,0,0,0,0,0,0,0,0,0,0,0,0,0,0,0,0,6,6,58,6,0,0,0,0
0,0,0,0,0,0,58,6,0,0,0,0,0,0,0,0,0,0,0,0,0,0,0,0,0,0,0,0,0,0,0,0,0,6,58,0,0,0,0,0,0
0,0,0,0,0,0,0,50,0,0,0,0,0,0,0,0,0,0,0,0,0,0,0,0,0,0,0,0,0,0,0,0,0,50,0,0,0,0,0,0,0
0,0,0,0,0,0,58,6,0,0,0,0,0,0,0,0,0,0,0,0,0,0,0,0,0,0,0,0,0,0,0,0,0,6,58,0,0,0,0,0,0
0,0,0,0,0,0,0,6,0,0,0,0,0,0,0,0,0,0,0,0,0,0,0,0,0,0,0,0,0,0,0,0,0,6,0,0,0,0,0,0,0
0,0,0,0,0,0,9,6,38,0,0,0,0,0,0,0,0,0,0,0,0,0,0,0,0,0,0,0,0,0,0,0,38,6,22,0,0,0,0,0,0
0,0,0,0,0,0,0,6,0,0,0,0,0,0,0,0,0,0,0,0,0,0,0,0,0,0,0,0,0,0,0,0,0,6,0,0,0,0,0,0,0
0,0,0,0,0,0,58,6,0,0,0,0,0,0,0,0,0,0,0,0,0,0,0,0,0,0,0,0,0,0,0,0,0,6,58,0,0,0,0,0,0
0,0,0,0,0,0,0,50,0,0,0,0,0,0,0,0,0,0,0,0,0,0,0,0,0,0,0,0,0,0,0,0,0,50,0,0,0,0,0,0,0
0,0,0,0,0,0,58,6,0,0,0,0,0,0,0,0,0,0,0,0,0,0,0,0,0,0,0,0,0,0,0,0,0,6,58,0,0,0,0,0,0
0,0,0,0,0,0,33,6,38,0,0,0,0,0,0,0,0,0,0,0,0,0,0,0,0,0,0,0,0,0,0,0,38,6,33,0,0,0,0,0,0
0,0,0,0,0,0,58,6,0,0,0,0,0,0,0,0,0,0,0,0,0,0,0,0,0,0,0,0,0,0,0,0,0,6,58,0,0,0,0,0,0
0,0,0,0,0,0,0,50,0,0,0,0,0,0,0,0,0,0,0,0,0,0,0,0,0,0,0,0,0,0,0,0,0,50,0,0,0,0,0,0,0
0,0,0,0,0,0,58,6,0,0,0,0,0,0,0,0,0,0,0,0,0,0,0,0,0,0,0,0,0,0,0,0,0,6,58,0,0,0,0,0,0
0,0,0,0,0,0,0,6,0,0,0,0,0,0,0,0,0,0,0,0,0,0,0,0,0,0,0,0,0,0,0,0,0,6,0,0,0,0,0,0,0
0,0,0,0,0,0,9,6,38,0,0,0,0,0,0,0,0,0,0,0,0,0,0,0,0,0,0,0,0,0,0,0,38,6,22,0,0,0,0,0,0
0,0,0,0,0,0,0,6,0,0,0,0,0,0,0,0,0,0,0,0,0,0,0,0,0,0,0,0,0,0,0,0,0,6,0,0,0,0,0,0,0
0,0,0,0,0,0,58,6,0,0,0,0,38,0,0,0,0,0,38,0,0,0,38,0,0,0,0,0,38,0,0,0,0,6,58,0,0,0,0,0,0
0,0,0,0,0,0,0,50,0,0,0,0,0,0,0,0,0,0,0,0,0,0,0,0,0,0,0,0,0,0,0,0,0,50,0,0,0,0,0,0,0
0,0,0,0,0,0,58,6,0,0,0,0,0,0,0,0,0,0,0,0,0,0,0,0,0,0,0,0,0,0,0,0,0,6,58,0,0,0,0,0,0
0,0,0,0,6,58,6,6,0,0,0,0,0,0,0,0,0,0,0,0,0,0,0,0,0,0,0,0,0,0,0,0,0,6,6,58,6,0,0,0,0
0,0,0,6,6,6,6,6,0,38,0,0,0,0,0,25,0,0,0,0,25,0,0,0,0,25,0,0,0,0,0,38,0,6,6,6,6,6,0,0,0
0,0,6,6,6,0,0,0,0,0,0,0,0,0,0,38,0,0,0,0,38,0,0,0,0,38,0,0,0,0,0,0,0,0,0,0,6,6,6,0,0
0,0,58,6,0,0,0,0,0,6,6,6,50,6,6,6,6,6,50,6,6,6,50,6,6,6,6,6,50,6,6,6,0,0,0,0,0,6,58,0,0
0,0,0,50,0,0,14,37,37,6,6,58,0,58,0,11,0,58,0,58,33,58,0,58,0,11,0,58,0,58,6,6,37,37,14,0,0,50,0,0,0
0,0,58,6,0,0,12,10,10,6,58,0,0,0,0,0,0,0,0,0,0,0,0,0,0,0,0,0,0,0,58,6,10,10,12,0,0,6,58,0,0
0,0,6,6,6,0,12,10,6,6,6,28,0,0,0,0,0,0,0,0,0,0,0,0,0,0,0,0,0,0,6,6,6,10,12,0,6,6,6,0,0
0,0,0,6,6,6,50,6,6,6,0,0,0,0,0,0,0,0,0,0,0,0,0,0,0,0,0,0,0,0,0,6,6,6,50,6,6,6,0,0,0
0,0,0,0,6,58,0,58,6,0,0,0,0,0,0,0,0,0,0,0,0,0,0,0,0,0,0,0,0,0,0,0,6,58,0,58,6,0,0,0,0
0,0,0,0,0,0,0,0,0,0,0,0,0,0,0,0,0,0,0,0,0,0,0,0,0,0,0,0,0,0,0,0,0,0,0,0,0,0,0,0,0
0,0,0,0,0,0,0,0,0,0,0,0,0,0,0,0,0,0,0,0,0,0,0,0,0,0,0,0,0,0,0,0,0,0,0,0,0,0,0,0,0
0,0,0,0,0,0,0,0,0,0,0,0,0,0,0,0,0,0,0,0,0,0,0,0,0,0,0,0,0,0,0,0,0,0,0,0,0,0,0,0,0
0,0,0,0,0,0,0,0,0,0,0,0,0,0,0,0,0,0,0,0,0,0,0,0,0,0,0,0,0,0,0,0,0,0,0,0,0,0,0,0,0
0,0,0,0,0,0,0,0,0,0,0,0,0,0,0,0,0,0,0,0,0,0,0,0,0,0,0,0,0,0,0,0,0,0,0,0,0,0,0,0,0
0,0,0,0,0,0,0,0,0,0,0,0,0,0,0,0,0,0,0,0,0,0,0,0,0,0,0,0,0,0,0,0,0,0,0,0,0,0,0,0,0
0,0,0,0,0,0,0,0,0,0,0,0,0,0,0,0,0,0,0,0,0,0,0,0,0,0,0,0,0,0,0,0,0,0,0,0,0,0,0,0,0
0,0,0,0,0,0,0,0,0,0,0,0,0,0,0,0,0,0,0,0,0,0,0,0,0,0,0,0,0,0,0,0,0,0,0,0,0,0,0,0,0
0,0,0,0,0,0,0,0,0,0,0,0,0,0,0,0,0,0,0,0,0,0,0,0,0,0,0,0,0,0,0,0,0,0,0,0,0,0,0,0,0
0,0,0,0,0,0,0,0,0,0,0,0,0,0,0,0,0,0,0,0,0,0,0,0,0,0,0,0,0,0,0,0,0,0,0,0,0,0,0,0,0
:endlayer
layer: 16
0,0,0,0,0,0,0,0,0,0,0,0,0,0,0,0,0,0,0,0,0,0,0,0,0,0,0,0,0,0,0,0,0,0,0,0,0,0,0,0,0
0,0,0,0,25,0,0,0,25,0,0,0,0,0,0,0,0,0,0,0,0,0,0,0,0,0,0,0,0,0,0,0,25,0,0,0,25,0,0,0,0
0,0,0,16,6,13,0,13,6,20,0,0,0,0,0,0,0,0,0,0,0,0,0,0,0,0,0,0,0,0,0,16,6,13,0,13,6,20,0,0,0
0,0,35,6,6,6,50,6,6,6,35,0,0,0,0,0,0,0,0,0,0,0,0,0,0,0,0,0,0,0,35,6,6,6,50,6,6,6,35,0,0
0,26,6,6,6,0,0,0,6,6,6,0,0,0,0,0,0,0,0,0,0,0,0,0,0,0,0,0,0,0,6,6,6,0,0,0,6,6,6,28,0
0,0,9,6,0,0,0,0,27,6,22,0,0,0,0,0,0,0,0,0,0,0,0,0,0,0,0,0,0,0,9,6,27,0,0,0,0,6,22,0,0
0,0,0,50,0,0,14,37,37,6,6,58,0,58,0,58,0,58,0,58,33,58,0,58,0,58,0,58,0,58,6,6,37,37,14,0,0,50,0,0,0
0,0,9,6,0,0,12,10,10,6,6,6,50,6,6,6,6,6,50,6,6,6,50,6,6,6,6,6,50,6,6,6,10,10,12,0,0,6,22,0,0
0,26,6,6,6,0,12,10,10,6,0,0,0,0,0,38,0,0,0,0,38,0,0,0,0,38,0,0,0,0,0,6,10,10,12,0,6,6,6,28,0
0,0,34,6,6,6,6,6,6,38,0,0,0,0,0,0,0,0,0,0,0,0,0,0,0,0,0,0,0,0,0,38,6,6,6,6,6,6,34,0,0
0,0,0,16,6,11,6,6,0,0,0,0,0,0,0,0,0,0,0,0,0,0,0,0,0,0,0,0,0,0,0,0,0,6,6,11,6,20,0,0,0
0,0,0,0,0,0,58,6,0,0,0,0,0,0,0,0,0,0,0,0,0,0,0,0,0,0,0,0,0,0,0,0,0,6,58,0,0,0,0,0,0
0,0,0,0,0,0,0,50,0,0,0,0,0,0,0,0,0,0,0,0,0,0,0,0,0,0,0,0,0,0,0,0,0,50,0,0,0,0,0,0,0
0,0,0,0,0,0,58,6,0,0,0,0,0,0,0,0,0,0,0,0,0,0,0,0,0,0,0,0,0,0,0,0,0,6,58,0,0,0,0,0,0
0,0,0,0,0,0,0,6,0,0,0,0,0,0,0,0,0,0,0,0,0,0,0,0,0,0,0,0,0,0,0,0,0,6,0,0,0,0,0,0,0
0,0,0,0,0,0,58,6,38,0,0,0,0,0,0,0,0,0,0,0,0,0,0,0,0,0,0,0,0,0,0,0,38,6,58,0,0,0,0,0,0
0,0,0,0,0,0,0,6,0,0,0,0,0,0,0,0,0,0,0,0,0,0,0,0,0,0,0,0,0,0,0,0,0,6,0,0,0,0,0,0,0
0,0,0,0,0,0,58,6,0,0,0,0,0,0,0,0,0,0,0,0,0,0,0,0,0,0,0,0,0,0,0,0,0,6,58,0,0,0,0,0,0
0,0,0,0,0,0,0,50,0,0,0,0,0,0,0,0,0,0,0,0,0,0,0,0,0,0,0,0,0,0,0,0,0,50,0,0,0,0,0,0,0
0,0,0,0,0,0,58,6,0,0,0,0,0,0,0,0,0,0,0,0,0,0,0,0,0,0,0,0,0,0,0,0,0,6,58,0,0,0,0,0,0
0,0,0,0,0,0,33,6,38,0,0,0,0,0,0,0,0,0,0,0,0,0,0,0,0,0,0,0,0,0,0,0,38,6,33,0,0,0,0,0,0
0,0,0,0,0,0,58,6,0,0,0,0,0,0,0,0,0,0,0,0,0,0,0,0,0,0,0,0,0,0,0,0,0,6,58,0,0,0,0,0,0
0,0,0,0,0,0,0,50,0,0,0,0,0,0,0,0,0,0,0,0,0,0,0,0,0,0,0,0,0,0,0,0,0,50,0,0,0,0,0,0,0
0,0,0,0,0,0,58,6,0,0,0,0,0,0,0,0,0,0,0,0,0,0,0,0,0,0,0,0,0,0,0,0,0,6,58,0,0,0,0,0,0
0,0,0,0,0,0,0,6,0,0,0,0,0,0,0,0,0,0,0,0,0,0,0,0,0,0,0,0,0,0,0,0,0,6,0,0,0,0,0,0,0
0,0,0,0,0,0,58,6,38,0,0,0,0,0,0,0,0,0,0,0,0,0,0,0,0,0,0,0,0,0,0,0,38,6,58,0,0,0,0,0,0
0,0,0,0,0,0,0,6,0,0,0,0,0,0,0,0,0,0,0,0,0,0,0,0,0,0,0,0,0,0,0,0,0,6,0,0,0,0,0,0,0
0,0,0,0,0,0,58,6,0,0,0,0,38,0,0,0,0,0,38,0,0,0,38,0,0,0,0,0,38,0,0,0,0,6,58,0,0,0,0,0,0
0,0,0,0,0,0,0,50,0,0,0,0,0,0,0,0,0,0,0,0,0,0,0,0,0,0,0,0,0,0,0,0,0,50,0,0,0,0,0,0,0
0,0,0,0,0,0,58,6,0,0,0,0,0,0,0,0,0,0,0,0,0,0,0,0,0,0,0,0,0,0,0,0,0,6,58,0,0,0,0,0,0
0,0,0,16,6,13,6,6,0,0,0,0,0,0,0,0,0,0,0,0,0,0,0,0,0,0,0,0,0,0,0,0,0,6,6,13,6,20,0,0,0
0,0,35,6,6,6,6,6,0,38,0,0,0,0,0,0,0,0,0,0,0,0,0,0,0,0,0,0,0,0,0,38,0,6,6,6,6,6,35,0,0
0,26,6,6,6,28,37,10,10,0,0,0,0,0,0,38,0,0,0,0,38,0,0,0,0,38,0,0,0,0,0,0,10,10,37,26,6,6,6,28,0
0,0,9,6,0,0,37,10,10,6,6,6,50,6,6,6,6,6,50,6,6,6,50,6,6,6,6,6,50,6,6,6,10,10,37,0,0,6,22,0,0
0,0,0,50,0,0,14,12,12,6,6,58,0,58,0,58,0,58,0,58,33,58,0,58,0,58,0,58,0,58,6,6,12,12,14,0,0,50,0,0,0
0,0,9,6,0,0,0,0,0,6,22,0,0,0,0,0,0,0,0,0,0,0,0,0,0,0,0,0,0,0,9,6,0,0,0,0,0,6,22,0,0
0,26,6,6,6,0,0,0,6,6,6,0,0,0,0,0,0,0,0,0,0,0,0,0,0,0,0,0,0,0,6,6,6,0,0,0,6,6,6,28,0
0,0,34,6,6,6,50,6,6,6,34,0,0,0,0,0,0,0,0,0,0,0,0,0,0,0,0,0,0,0,34,6,6,6,50,6,6,6,34,0,0
0,0,0,16,6,11,0,11,6,20,0,0,0,0,0,0,0,0,0,0,0,0,0,0,0,0,0,0,0,0,0,16,6,11,0,11,6,20,0,0,0
0,0,0,0,0,0,0,0,0,0,0,0,0,0,0,0,0,0,0,0,0,0,0,0,0,0,0,0,0,0,0,0,0,0,0,0,0,0,0,0,0
0,0,0,0,0,0,0,0,0,0,0,0,0,0,0,0,0,0,0,0,0,0,0,0,0,0,0,0,0,0,0,0,0,0,0,0,0,0,0,0,0
0,0,0,0,0,0,0,0,0,0,0,0,0,0,0,0,0,0,0,0,0,0,0,0,0,0,0,0,0,0,0,0,0,0,0,0,0,0,0,0,0
0,0,0,0,0,0,0,0,0,0,0,0,0,0,0,0,0,0,0,0,0,0,0,0,0,0,0,0,0,0,0,0,0,0,0,0,0,0,0,0,0
0,0,0,0,0,0,0,0,0,0,0,0,0,0,0,0,0,0,0,0,0,0,0,0,0,0,0,0,0,0,0,0,0,0,0,0,0,0,0,0,0
0,0,0,0,0,0,0,0,0,0,0,0,0,0,0,0,0,0,0,0,0,0,0,0,0,0,0,0,0,0,0,0,0,0,0,0,0,0,0,0,0
0,0,0,0,0,0,0,0,0,0,0,0,0,0,0,0,0,0,0,0,0,0,0,0,0,0,0,0,0,0,0,0,0,0,0,0,0,0,0,0,0
0,0,0,0,0,0,0,0,0,0,0,0,0,0,0,0,0,0,0,0,0,0,0,0,0,0,0,0,0,0,0,0,0,0,0,0,0,0,0,0,0
0,0,0,0,0,0,0,0,0,0,0,0,0,0,0,0,0,0,0,0,0,0,0,0,0,0,0,0,0,0,0,0,0,0,0,0,0,0,0,0,0
0,0,0,0,0,0,0,0,0,0,0,0,0,0,0,0,0,0,0,0,0,0,0,0,0,0,0,0,0,0,0,0,0,0,0,0,0,0,0,0,0
:endlayer
layer: 17
0,0,0,0,0,0,0,0,0,0,0,0,0,0,0,0,0,0,0,0,0,0,0,0,0,0,0,0,0,0,0,0,0,0,0,0,0,0,0,0,0
0,0,0,0,0,0,0,0,0,0,0,0,0,0,0,0,0,0,0,0,0,0,0,0,0,0,0,0,0,0,0,0,0,0,0,0,0,0,0,0,0
0,0,0,9,6,20,13,16,6,22,0,0,0,0,0,0,0,0,0,0,0,0,0,0,0,0,0,0,0,0,0,9,6,20,13,16,6,22,0,0,0
0,0,13,6,6,6,6,6,6,6,13,0,0,0,0,0,0,0,0,0,0,0,0,0,0,0,0,0,0,0,13,6,6,6,6,6,6,6,13,0,0
0,0,6,6,6,0,37,10,6,6,6,0,0,0,0,0,0,0,0,0,0,0,0,0,0,0,0,0,0,0,6,6,6,10,37,0,6,6,6,0,0
0,0,34,6,0,0,37,10,10,6,34,0,0,0,0,0,0,0,0,0,0,0,0,0,0,0,0,0,0,0,34,6,10,10,37,0,0,6,34,0,0
0,0,9,6,0,0,14,12,12,6,6,9,52,22,0,35,0,9,52,22,33,9,52,22,0,35,0,9,52,22,6,6,12,12,14,0,0,6,22,0,0
0,0,35,6,0,0,0,0,0,6,6,6,6,6,6,6,6,6,6,6,6,6,6,6,6,6,6,6,6,6,6,6,0,0,0,0,0,6,35,0,0
0,0,6,6,6,0,0,0,0,6,0,0,27,0,0,38,0,0,27,0,38,0,27,0,0,38,0,0,27,0,0,6,0,0,0,0,6,6,6,0,0
0,0,11,6,6,6,6,6,6,38,0,0,0,0,0,0,0,0,0,0,0,0,0,0,0,0,0,0,0,0,0,38,6,6,6,6,6,6,11,0,0
0,0,0,9,6,20,6,6,0,0,0,0,0,0,0,0,0,0,0,0,0,0,0,0,0,0,0,0,0,0,0,0,0,6,6,16,6,22,0,0,0
0,0,0,0,0,0,13,6,0,0,0,0,0,0,0,0,0,0,0,0,0,0,0,0,0,0,0,0,0,0,0,0,0,6,13,0,0,0,0,0,0
0,0,0,0,0,0,52,6,28,0,0,0,0,0,0,0,0,0,0,0,0,0,0,0,0,0,0,0,0,0,0,0,26,6,52,0,0,0,0,0,0
0,0,0,0,0,0,11,6,0,0,0,0,0,0,0,0,0,0,0,0,0,0,0,0,0,0,0,0,0,0,0,0,0,6,11,0,0,0,0,0,0
0,0,0,0,0,0,0,6,0,0,0,0,0,0,0,0,0,0,0,0,0,0,0,0,0,0,0,0,0,0,0,0,0,6,0,0,0,0,0,0,0
0,0,0,0,0,0,16,6,38,0,0,0,0,0,0,0,0,0,0,0,0,0,0,0,0,0,0,0,0,0,0,0,38,6,20,0,0,0,0,0,0
0,0,0,0,0,0,0,6,0,0,0,0,0,0,0,0,0,0,0,0,0,0,0,0,0,0,0,0,0,0,0,0,0,6,0,0,0,0,0,0,0
0,0,0,0,0,0,13,6,0,0,0,0,0,0,0,0,0,0,0,0,0,0,0,0,0,0,0,0,0,0,0,0,0,6,13,0,0,0,0,0,0
0,0,0,0,0,0,52,6,28,0,0,0,0,0,0,0,0,0,0,0,0,0,0,0,0,0,0,0,0,0,0,0,26,6,52,0,0,0,0,0,0
0,0,0,0,0,0,11,6,0,0,0,0,0,0,0,0,0,0,0,0,0,0,0,0,0,0,0,0,0,0,0,0,0,6,11,0,0,0,0,0,0
0,0,0,0,0,0,33,6,38,0,0,0,0,0,0,0,0,0,0,0,0,0,0,0,0,0,0,0,0,0,0,0,38,6,33,0,0,0,0,0,0
0,0,0,0,0,0,13,6,0,0,0,0,0,0,0,0,0,0,0,0,0,0,0,0,0,0,0,0,0,0,0,0,0,6,13,0,0,0,0,0,0
0,0,0,0,0,0,52,6,28,0,0,0,0,0,0,0,0,0,0,0,0,0,0,0,0,0,0,0,0,0,0,0,26,6,52,0,0,0,0,0,0
0,0,0,0,0,0,11,6,0,0,0,0,0,0,0,0,0,0,0,0,0,0,0,0,0,0,0,0,0,0,0,0,0,6,11,0,0,0,0,0,0
0,0,0,0,0,0,0,6,0,0,0,0,0,0,0,0,0,0,0,0,0,0,0,0,0,0,0,0,0,0,0,0,0,6,0,0,0,0,0,0,0
0,0,0,0,0,0,16,6,38,0,0,0,0,0,0,0,0,0,0,0,0,0,0,0,0,0,0,0,0,0,0,0,38,6,20,0,0,0,0,0,0
0,0,0,0,0,0,0,6,0,0,0,0,25,0,0,0,0,0,25,0,0,0,25,0,0,0,0,0,25,0,0,0,0,6,0,0,0,0,0,0,0
0,0,0,0,0,0,13,6,0,0,0,0,38,0,0,0,0,0,38,0,0,0,38,0,0,0,0,0,38,0,0,0,0,6,13,0,0,0,0,0,0
0,0,0,0,0,0,52,6,28,0,0,0,27,0,0,0,0,0,27,0,0,0,27,0,0,0,0,0,27,0,0,0,26,6,52,0,0,0,0,0,0
0,0,0,0,0,0,11,6,25,0,0,0,0,0,0,0,0,0,0,0,0,0,0,0,0,0,0,0,0,0,0,0,25,6,11,0,0,0,0,0,0
0,0,0,9,6,20,6,6,6,28,0,0,0,0,0,0,0,0,0,0,0,0,0,0,0,0,0,0,0,0,0,26,6,6,6,16,6,22,0,0,0
0,0,13,6,6,6,6,6,6,38,25,0,0,0,0,25,0,0,0,0,25,0,0,0,0,25,0,0,0,0,25,38,6,6,6,6,6,6,13,0,0
0,0,6,6,6,10,12,0,0,6,6,28,25,0,0,38,0,0,25,0,38,0,25,0,0,38,0,0,25,26,6,6,0,0,12,10,6,6,6,0,0
0,0,34,6,10,10,12,0,0,6,6,6,6,6,6,6,6,6,6,6,6,6,6,6,6,6,6,6,6,6,6,6,0,0,12,10,10,6,34,0,0
0,0,9,6,37,37,14,0,0,6,6,9,52,22,0,34,0,9,52,22,33,9,52,22,0,34,0,9,52,22,6,6,0,0,14,37,37,6,22,0,0
0,0,35,6,25,0,0,0,0,6,35,0,0,0,0,0,0,0,0,0,0,0,0,0,0,0,0,0,0,0,35,6,0,0,0,0,0,6,35,0,0
0,0,6,6,6,0,0,0,6,6,6,0,0,0,0,0,0,0,0,0,0,0,0,0,0,0,0,0,0,0,6,6,6,0,0,0,6,6,6,0,0
0,0,11,6,6,6,6,6,6,6,11,0,0,0,0,0,0,0,0,0,0,0,0,0,0,0,0,0,0,0,11,6,6,6,6,6,6,6,11,0,0
0,0,0,9,6,20,11,16,6,22,0,0,0,0,0,0,0,0,0,0,0,0,0,0,0,0,0,0,0,0,0,9,6,20,11,16,6,22,0,0,0
0,0,0,0,0,0,0,0,0,0,0,0,0,0,0,0,0,0,0,0,0,0,0,0,0,0,0,0,0,0,0,0,0,0,0,0,0,0,0,0,0
0,0,0,0,0,0,0,0,0,0,0,0,0,0,0,0,0,0,0,0,0,0,0,0,0,0,0,0,0,0,0,0,0,0,0,0,0,0,0,0,0
0,0,0,0,0,0,0,0,0,0,0,0,0,0,0,0,0,0,0,0,0,0,0,0,0,0,0,0,0,0,0,0,0,0,0,0,0,0,0,0,0
0,0,0,0,0,0,0,0,0,0,0,0,0,0,0,0,0,0,0,0,0,0,0,0,0,0,0,0,0,0,0,0,0,0,0,0,0,0,0,0,0
0,0,0,0,0,0,0,0,0,0,0,0,0,0,0,0,0,0,0,0,0,0,0,0,0,0,0,0,0,0,0,0,0,0,0,0,0,0,0,0,0
0,0,0,0,0,0,0,0,0,0,0,0,0,0,0,0,0,0,0,0,0,0,0,0,0,0,0,0,0,0,0,0,0,0,0,0,0,0,0,0,0
0,0,0,0,0,0,0,0,0,0,0,0,0,0,0,0,0,0,0,0,0,0,0,0,0,0,0,0,0,0,0,0,0,0,0,0,0,0,0,0,0
0,0,0,0,0,0,0,0,0,0,0,0,0,0,0,0,0,0,0,0,0,0,0,0,0,0,0,0,0,0,0,0,0,0,0,0,0,0,0,0,0
0,0,0,0,0,0,0,0,0,0,0,0,0,0,0,0,0,0,0,0,0,0,0,0,0,0,0,0,0,0,0,0,0,0,0,0,0,0,0,0,0
0,0,0,0,0,0,0,0,0,0,0,0,0,0,0,0,0,0,0,0,0,0,0,0,0,0,0,0,0,0,0,0,0,0,0,0,0,0,0,0,0
:endlayer
layer: 18
0,0,0,0,0,0,0,0,0,0,0,0,0,0,0,0,0,0,0,0,0,0,0,0,0,0,0,0,0,0,0,0,0,0,0,0,0,0,0,0,0
0,0,0,0,32,32,32,32,32,0,0,0,0,0,0,0,0,0,0,0,0,0,0,0,0,0,0,0,0,0,0,0,32,32,32,32,32,0,0,0,0
0,0,0,32,6,6,33,6,6,32,0,0,0,0,0,0,0,0,0,0,0,0,0,0,0,0,0,0,0,0,0,32,6,6,33,6,6,32,0,0,0
0,0,32,6,6,6,6,6,6,6,32,0,0,0,0,0,0,0,0,0,0,0,0,0,0,0,0,0,0,0,32,6,6,6,6,6,6,6,32,0,0
0,32,6,6,6,10,12,0,6,6,6,32,0,0,0,0,0,0,0,0,0,0,0,0,0,0,0,0,0,32,6,6,6,0,12,10,6,6,6,32,0
0,32,6,6,10,10,12,0,0,6,6,32,32,32,0,0,0,32,32,32,0,32,32,32,0,0,0,32,32,32,6,6,0,0,12,10,10,6,6,32,0
0,32,33,6,37,37,14,0,0,6,6,6,6,6,16,13,20,6,6,6,33,6,6,6,16,13,20,6,6,6,6,6,0,0,14,37,37,6,33,32,0
0,32,6,6,25,0,0,0,0,6,6,6,6,6,6,6,6,6,6,6,6,6,6,6,6,6,6,6,6,6,6,6,0,0,0,0,25,6,6,32,0
0,32,6,6,6,0,0,0,0,6,66,66,65,66,66,66,66,66,65,66,66,66,65,66,66,66,66,66,65,66,66,6,0,0,0,0,6,6,6,32,0
0,0,32,6,6,6,6,6,6,38,0,0,65,0,0,0,0,0,65,0,0,0,65,0,0,0,0,0,65,0,0,38,6,6,6,6,6,6,32,0,0
0,0,0,32,6,6,6,6,65,0,0,0,65,0,0,0,0,0,65,0,0,0,65,0,0,0,0,0,65,0,0,0,65,6,6,6,6,32,0,0,0
0,0,0,0,32,32,6,6,65,0,0,0,65,0,0,0,0,0,65,0,0,0,65,0,0,0,0,0,65,0,0,0,65,6,6,32,32,0,0,0,0
0,0,0,0,0,32,6,6,65,66,66,66,65,66,66,66,66,66,65,66,66,66,65,66,66,66,66,66,65,66,66,66,65,6,6,32,0,0,0,0,0
0,0,0,0,0,32,6,6,65,0,0,0,65,0,0,0,0,0,65,0,0,0,65,0,0,0,0,0,65,0,0,0,65,6,6,32,0,0,0,0,0
0,0,0,0,0,0,35,6,65,0,0,0,65,0,0,0,0,0,65,0,0,0,65,0,0,0,0,0,65,0,0,0,65,6,35,0,0,0,0,0,0
0,0,0,0,0,0,9,6,65,0,0,0,65,0,0,0,0,0,65,0,0,0,65,0,0,0,0,0,65,0,0,0,65,6,22,0,0,0,0,0,0
0,0,0,0,0,0,34,6,65,0,0,0,65,0,0,0,0,0,65,0,0,0,65,0,0,0,0,0,65,0,0,0,65,6,34,0,0,0,0,0,0
0,0,0,0,0,32,6,6,65,0,0,0,65,0,0,0,0,0,65,0,0,0,65,0,0,0,0,0,65,0,0,0,65,6,6,32,0,0,0,0,0
0,0,0,0,0,32,6,6,65,66,66,66,65,66,66,66,66,66,65,66,66,66,65,66,66,66,66,66,65,66,66,66,65,6,6,32,0,0,0,0,0
0,0,0,0,0,32,6,6,65,0,0,0,65,0,0,0,0,0,65,0,0,0,65,0,0,0,0,0,65,0,0,0,65,6,6,32,0,0,0,0,0
0,0,0,0,0,0,33,6,65,0,0,0,65,0,0,0,0,0,65,0,0,0,65,0,0,0,0,0,65,0,0,0,65,6,33,0,0,0,0,0,0
0,0,0,0,0,32,6,6,65,0,0,0,65,0,0,0,0,0,65,0,0,0,65,0,0,0,0,0,65,0,0,0,65,6,6,32,0,0,0,0,0
0,0,0,0,0,32,6,6,65,66,66,66,65,66,66,66,66,66,65,66,66,66,65,66,66,66,66,66,65,66,66,66,65,6,6,32,0,0,0,0,0
0,0,0,0,0,32,6,6,65,0,0,0,65,0,0,0,0,0,65,0,0,0,65,0,0,0,0,0,65,0,0,0,65,6,6,32,0,0,0,0,0
0,0,0,0,0,0,35,6,65,0,0,0,65,0,0,0,0,0,65,0,0,0,65,0,0,0,0,0,65,0,0,0,65,6,35,0,0,0,0,0,0
0,0,0,0,0,0,9,6,65,0,0,0,65,0,0,0,0,0,65,0,0,0,65,0,0,0,0,0,65,0,0,0,65,6,22,0,0,0,0,0,0
0,0,0,0,0,0,34,6,65,0,0,0,65,0,0,0,0,0,65,0,0,0,65,0,0,0,0,0,65,0,0,0,65,6,34,0,0,0,0,0,0
0,0,0,0,0,32,6,6,66,66,66,66,65,66,66,66,66,66,65,66,66,66,65,66,66,66,66,66,65,66,66,66,66,6,6,32,0,0,0,0,0
0,0,0,0,0,32,6,6,65,0,0,0,65,0,0,0,0,0,65,0,0,0,65,0,0,0,0,0,65,0,0,0,65,6,6,32,0,0,0,0,0
0,0,0,0,32,32,6,6,65,0,0,0,65,0,0,0,0,0,65,0,0,0,65,0,0,0,0,0,65,0,0,0,65,6,6,32,32,0,0,0,0
0,0,0,32,6,6,6,6,65,0,0,0,65,0,0,0,0,0,65,0,0,0,65,0,0,0,0,0,65,0,0,0,65,6,6,6,6,32,0,0,0
0,0,32,6,6,6,6,6,6,38,0,0,65,0,0,0,0,0,65,0,0,0,65,0,0,0,0,0,65,0,0,38,6,6,6,6,6,6,32,0,0
0,32,6,6,6,0,0,0,0,6,66,66,65,66,66,66,66,66,65,66,66,66,65,66,66,66,66,66,65,66,66,6,0,0,0,0,6,6,6,32,0
0,32,6,6,0,0,0,0,0,6,6,6,6,6,6,6,6,6,6,6,6,6,6,6,6,6,6,6,6,6,6,6,0,0,0,0,0,6,6,32,0
0,32,33,6,12,12,14,0,0,6,6,6,6,6,16,11,20,6,6,6,33,6,6,6,16,11,20,6,6,6,6,6,0,0,14,12,12,6,33,32,0
0,32,6,6,10,10,37,0,25,6,6,32,32,32,0,0,0,32,32,32,0,32,32,32,0,0,0,32,32,32,6,6,0,0,37,10,10,6,6,32,0
0,32,6,6,6,10,37,0,6,6,6,32,0,0,0,0,0,0,0,0,0,0,0,0,0,0,0,0,0,32,6,6,6,28,37,10,6,6,6,32,0
0,0,32,6,6,6,6,6,6,6,32,0,0,0,0,0,0,0,0,0,0,0,0,0,0,0,0,0,0,0,32,6,6,6,6,6,6,6,32,0,0
0,0,0,32,6,6,33,6,6,32,0,0,0,0,0,0,0,0,0,0,0,0,0,0,0,0,0,0,0,0,0,32,6,6,33,6,6,32,0,0,0
0,0,0,0,32,32,32,32,32,0,0,0,0,0,0,0,0,0,0,0,0,0,0,0,0,0,0,0,0,0,0,0,32,32,32,32,32,0,0,0,0
0,0,0,0,0,0,0,0,0,0,0,0,0,0,0,0,0,0,0,0,0,0,0,0,0,0,0,0,0,0,0,0,0,0,0,0,0,0,0,0,0
0,0,0,0,0,0,0,0,0,0,0,0,0,0,0,0,0,0,0,0,0,0,0,0,0,0,0,0,0,0,0,0,0,0,0,0,0,0,0,0,0
0,0,0,0,0,0,0,0,0,0,0,0,0,0,0,0,0,0,0,0,0,0,0,0,0,0,0,0,0,0,0,0,0,0,0,0,0,0,0,0,0
0,0,0,0,0,0,0,0,0,0,0,0,0,0,0,0,0,0,0,0,0,0,0,0,0,0,0,0,0,0,0,0,0,0,0,0,0,0,0,0,0
0,0,0,0,0,0,0,0,0,0,0,0,0,0,0,0,0,0,0,0,0,0,0,0,0,0,0,0,0,0,0,0,0,0,0,0,0,0,0,0,0
0,0,0,0,0,0,0,0,0,0,0,0,0,0,0,0,0,0,0,0,0,0,0,0,0,0,0,0,0,0,0,0,0,0,0,0,0,0,0,0,0
0,0,0,0,0,0,0,0,0,0,0,0,0,0,0,0,0,0,0,0,0,0,0,0,0,0,0,0,0,0,0,0,0,0,0,0,0,0,0,0,0
0,0,0,0,0,0,0,0,0,0,0,0,0,0,0,0,0,0,0,0,0,0,0,0,0,0,0,0,0,0,0,0,0,0,0,0,0,0,0,0,0
0,0,0,0,0,0,0,0,0,0,0,0,0,0,0,0,0,0,0,0,0,0,0,0,0,0,0,0,0,0,0,0,0,0,0,0,0,0,0,0,0
:endlayer
layer: 19
0,0,0,0,0,0,0,0,0,0,0,0,0,0,0,0,0,0,0,0,0,0,0,0,0,0,0,0,0,0,0,0,0,0,0,0,0,0,0,0,0
0,0,0,0,0,0,0,0,0,0,0,0,0,0,0,0,0,0,0,0,0,0,0,0,0,0,0,0,0,0,0,0,0,0,0,0,0,0,0,0,0
0,0,0,16,6,22,35,9,6,20,0,0,0,0,0,0,0,0,0,0,0,0,0,0,0,0,0,0,0,0,0,16,6,22,35,9,6,20,0,0,0
0,0,35,6,6,6,6,6,6,6,35,0,0,0,0,0,0,0,0,0,0,0,0,0,0,0,0,0,0,0,35,6,6,6,6,6,6,6,35,0,0
0,0,6,6,6,0,0,0,6,6,6,0,0,0,0,0,0,0,0,0,0,0,0,0,0,0,0,0,0,0,6,6,6,0,0,0,6,6,6,0,0
0,0,11,6,0,0,0,0,0,6,11,0,0,0,29,29,29,0,0,0,29,0,0,0,29,29,29,0,0,0,11,6,0,0,0,0,0,6,11,0,0
0,0,16,6,12,12,14,0,0,6,6,36,36,36,6,6,6,36,36,36,33,36,36,36,6,6,6,36,36,36,6,6,0,0,14,12,12,6,20,0,0
0,0,13,6,10,10,37,0,0,6,6,6,6,6,6,6,6,6,6,6,6,6,6,6,6,6,6,6,6,6,6,6,0,0,37,10,10,6,13,0,0
0,0,6,6,6,10,37,0,0,6,39,39,39,39,39,39,39,39,39,39,39,39,39,39,39,39,39,39,39,39,39,6,0,0,37,10,6,6,6,0,0
0,0,34,6,6,6,6,6,6,39,39,39,39,39,39,39,39,39,39,39,39,39,39,39,39,39,39,39,39,39,39,39,6,6,6,6,6,6,34,0,0
0,0,0,16,6,22,6,6,39,39,39,39,39,39,39,39,39,39,39,39,39,39,39,39,39,39,39,39,39,39,39,39,39,6,6,9,6,20,0,0,0
0,0,0,0,0,0,36,6,39,39,39,39,39,39,39,39,39,39,39,39,39,39,39,39,39,39,39,39,39,39,39,39,39,6,36,0,0,0,0,0,0
0,0,0,0,0,0,36,6,39,39,39,39,39,39,39,39,39,39,39,39,39,39,39,39,39,39,39,39,39,39,39,39,39,6,36,0,0,0,0,0,0
0,0,0,0,0,0,36,6,39,39,39,39,39,39,39,39,39,39,39,39,39,39,39,39,39,39,39,39,39,39,39,39,39,6,36,0,0,0,0,0,0
0,0,0,0,0,29,6,6,39,39,39,39,39,39,39,39,39,39,39,39,39,39,39,39,39,39,39,39,39,39,39,39,39,6,6,29,0,0,0,0,0
0,0,0,0,0,29,6,6,39,39,39,39,39,39,39,39,39,39,39,39,39,39,39,39,39,39,39,39,39,39,39,39,39,6,6,29,0,0,0,0,0
0,0,0,0,0,29,6,6,39,39,39,39,39,39,39,39,39,39,39,39,39,39,39,39,39,39,39,39,39,39,39,39,39,6,6,29,0,0,0,0,0
0,0,0,0,0,0,36,6,39,39,39,39,39,39,39,39,39,39,39,39,39,39,39,39,39,39,39,39,39,39,39,39,39,6,36,0,0,0,0,0,0
0,0,0,0,0,0,36,6,39,39,39,39,39,39,39,39,39,39,39,39,39,39,39,39,39,39,39,39,39,39,39,39,39,6,36,0,0,0,0,0,0
0,0,0,0,0,0,36,6,39,39,39,39,39,39,39,39,39,39,39,39,39,39,39,39,39,39,39,39,39,39,39,39,39,6,36,0,0,0,0,0,0
0,0,0,0,0,29,33,6,39,39,39,39,39,5,39,39,39,39,39,39,39,39,39,39,39,39,39,5,39,39,39,39,39,6,33,29,0,0,0,0,0
0,0,0,0,0,0,36,6,39,39,39,39,39,39,39,39,39,39,39,39,39,39,39,39,39,39,39,39,39,39,39,39,39,6,36,0,0,0,0,0,0
0,0,0,0,0,0,36,6,39,39,39,39,39,39,39,39,39,39,39,39,39,39,39,39,39,39,39,39,39,39,39,39,39,6,36,0,0,0,0,0,0
0,0,0,0,0,0,36,6,39,39,39,39,39,39,39,39,39,39,39,39,39,39,39,39,39,39,39,39,39,39,39,39,39,6,36,0,0,0,0,0,0
0,0,0,0,0,29,6,6,39,39,39,39,39,39,39,39,39,39,39,39,39,39,39,39,39,39,39,39,39,39,39,39,39,6,6,29,0,0,0,0,0
0,0,0,0,0,29,6,6,39,39,39,39,39,39,39,39,39,39,39,39,39,39,39,39,39,39,39,39,39,39,39,39,39,6,6,29,0,0,0,0,0
0,0,0,0,0,29,6,6,39,39,39,39,39,39,39,39,39,39,39,39,39,39,39,39,39,39,39,39,39,39,39,39,39,6,6,29,0,0,0,0,0
0,0,0,0,0,0,36,6,39,39,39,39,39,39,39,39,39,39,39,39,39,39,39,39,39,39,39,39,39,5,39,39,39,6,36,0,0,0,0,0,0
0,0,0,0,0,0,36,6,39,39,39,39,39,39,39,39,39,39,39,39,39,39,39,39,39,39,39,39,39,39,39,39,39,6,36,0,0,0,0,0,0
0,0,0,0,0,0,36,6,39,39,39,39,39,39,39,39,39,39,39,39,39,39,39,39,39,39,39,39,39,39,39,39,39,6,36,0,0,0,0,0,0
0,0,0,16,6,22,6,6,39,39,39,39,39,39,39,39,39,39,39,39,39,39,39,39,39,39,39,39,39,39,39,39,39,6,6,9,6,20,0,0,0
0,0,35,6,6,6,6,6,6,39,39,39,39,39,39,39,39,39,39,39,39,39,39,39,39,39,39,39,39,39,39,39,6,6,6,6,6,6,35,0,0
0,0,6,6,6,0,0,0,0,6,39,39,39,39,39,39,39,39,39,39,39,39,39,39,39,39,39,39,39,39,39,6,27,0,0,0,6,6,6,0,0
0,0,11,6,0,0,0,0,0,6,6,6,6,6,6,6,6,6,6,6,6,6,6,6,6,6,6,6,6,6,6,6,0,0,0,0,0,6,11,0,0
0,0,16,6,0,0,14,37,37,6,6,36,36,36,6,6,6,36,36,36,33,36,36,36,6,6,6,36,36,36,6,6,37,37,14,0,0,6,20,0,0
0,0,13,6,0,0,12,10,10,6,13,0,0,0,29,29,29,0,0,0,29,0,0,0,29,29,29,0,0,0,13,6,10,10,12,0,0,6,13,0,0
0,0,6,6,6,0,12,10,6,6,6,0,0,0,0,0,0,0,0,0,0,0,0,0,0,0,0,0,0,0,6,6,6,10,12,0,6,6,6,0,0
0,0,34,6,6,6,6,6,6,6,34,0,0,0,0,0,0,0,0,0,0,0,0,0,0,0,0,0,0,0,34,6,6,6,6,6,6,6,34,0,0
0,0,0,16,6,22,34,9,6,20,0,0,0,0,0,0,0,0,0,0,0,0,0,0,0,0,0,0,0,0,0,16,6,22,34,9,6,20,0,0,0
0,0,0,0,0,0,0,0,0,0,0,0,0,0,0,0,0,0,0,0,0,0,0,0,0,0,0,0,0,0,0,0,0,0,0,0,0,0,0,0,0
0,0,0,0,0,0,0,0,0,0,0,0,0,0,0,0,0,0,0,0,0,0,0,0,0,0,0,0,0,0,0,0,0,0,0,0,0,0,0,0,0
0,0,0,0,0,0,0,0,0,0,0,0,0,0,0,0,0,0,0,0,0,0,0,0,0,0,0,0,0,0,0,0,0,0,0,0,0,0,0,0,0
0,0,0,0,0,0,0,0,0,0,0,0,0,0,0,0,0,0,0,0,0,0,0,0,0,0,0,0,0,0,0,0,0,0,0,0,0,0,0,0,0
0,0,0,0,0,0,0,0,0,0,0,0,0,0,0,0,0,0,0,0,0,0,0,0,0,0,0,0,0,0,0,0,0,0,0,0,0,0,0,0,0
0,0,0,0,0,0,0,0,0,0,0,0,0,0,0,0,0,0,0,0,0,0,0,0,0,0,0,0,0,0,0,0,0,0,0,0,0,0,0,0,0
0,0,0,0,0,0,0,0,0,0,0,0,0,0,0,0,0,0,0,0,0,0,0,0,0,0,0,0,0,0,0,0,0,0,0,0,0,0,0,0,0
0,0,0,0,0,0,0,0,0,0,0,0,0,0,0,0,0,0,0,0,0,0,0,0,0,0,0,0,0,0,0,0,0,0,0,0,0,0,0,0,0
0,0,0,0,0,0,0,0,0,0,0,0,0,0,0,0,0,0,0,0,0,0,0,0,0,0,0,0,0,0,0,0,0,0,0,0,0,0,0,0,0
0,0,0,0,0,0,0,0,0,0,0,0,0,0,0,0,0,0,0,0,0,0,0,0,0,0,0,0,0,0,0,0,0,0,0,0,0,0,0,0,0
:endlayer
layer: 20
0,0,0,0,0,0,0,0,0,0,0,0,0,0,0,0,0,0,0,0,0,0,0,0,0,0,0,0,0,0,0,0,0,0,0,0,0,0,0,0,0
0,0,0,0,0,0,0,0,0,0,0,0,0,0,0,0,0,0,0,0,0,0,0,0,0,0,0,0,0,0,0,0,0,0,0,0,0,0,0,0,0
0,0,0,9,6,35,0,35,6,22,0,0,0,0,0,0,0,0,0,0,0,0,0,0,0,0,0,0,0,0,0,9,6,35,0,35,6,22,0,0,0
0,0,13,6,6,6,50,6,6,6,13,0,0,0,0,0,0,0,0,0,0,0,0,0,0,0,0,0,0,0,13,6,6,6,50,6,6,6,13,0,0
0,0,6,6,6,0,0,0,6,6,6,28,0,0,0,0,0,0,0,0,0,0,0,0,0,0,0,0,0,26,6,6,6,0,0,0,6,6,6,0,0
0,0,16,6,0,0,0,0,27,6,20,0,0,0,0,0,0,0,0,0,25,0,0,0,0,0,0,0,0,0,16,6,27,0,0,0,0,6,20,0,0
0,0,0,50,0,0,14,37,37,6,6,16,52,20,9,35,22,16,52,20,33,16,52,20,9,35,22,16,52,20,6,6,37,37,14,0,0,50,0,0,0
0,0,16,6,0,0,12,10,10,6,6,6,6,6,6,6,6,6,6,6,6,6,6,6,6,6,6,6,6,6,6,6,10,10,12,0,0,6,20,0,0
0,0,6,6,6,0,12,10,10,68,0,0,0,0,0,39,0,0,0,0,39,0,0,0,0,39,0,0,0,0,0,68,10,10,12,0,6,6,6,0,0
0,0,11,6,6,6,6,6,68,68,0,0,0,0,0,39,0,0,0,0,39,0,0,0,0,39,0,0,0,0,0,68,68,6,6,6,6,6,11,0,0
0,0,0,9,6,34,6,6,0,0,0,0,0,0,0,39,0,0,0,0,39,0,0,0,0,39,0,0,0,0,0,0,0,6,6,34,6,22,0,0,0
0,0,0,0,27,0,35,6,0,0,0,0,0,0,0,39,0,0,0,0,39,0,0,0,0,39,0,0,0,0,0,0,0,6,35,0,27,0,0,0,0
0,0,0,0,0,0,52,6,0,0,0,0,0,0,0,39,0,0,0,0,39,0,0,0,0,39,0,0,0,0,0,0,0,6,52,0,0,0,0,0,0
0,0,0,0,0,0,34,6,0,0,0,0,0,0,0,39,0,0,0,0,39,0,0,0,0,39,0,0,0,0,0,0,0,6,34,0,0,0,0,0,0
0,0,0,0,0,0,13,6,0,0,0,0,6,6,6,6,6,47,6,6,6,39,39,47,39,39,39,39,47,39,39,39,39,6,13,0,0,0,0,0,0
0,0,0,0,0,0,16,6,0,0,0,0,6,39,0,0,0,0,0,39,6,0,0,0,0,0,0,0,0,0,0,0,0,6,20,0,0,0,0,0,0
0,0,0,0,0,0,11,6,0,0,0,0,6,0,0,0,0,0,0,0,6,0,0,0,0,0,0,0,0,0,0,0,0,6,11,0,0,0,0,0,0
0,0,0,0,0,0,35,6,0,0,0,0,47,0,0,0,0,0,0,0,6,0,0,0,0,0,0,0,0,0,0,0,0,6,35,0,0,0,0,0,0
0,0,0,0,0,0,52,6,0,0,0,0,70,0,0,0,0,0,0,0,6,0,0,0,0,0,0,0,0,0,0,0,0,6,52,0,0,0,0,0,0
0,0,0,0,0,0,34,6,0,0,0,0,6,0,0,0,0,0,0,0,6,0,0,0,0,0,0,0,0,0,0,0,0,6,34,0,0,0,0,0,0
0,0,0,0,0,26,33,6,0,0,0,0,6,39,0,0,0,0,0,0,47,0,0,0,0,0,0,72,0,0,0,0,0,6,33,28,0,0,0,0,0
0,0,0,0,0,0,35,6,0,0,0,0,6,39,0,0,0,0,0,0,70,0,0,0,0,0,0,0,0,0,0,0,0,6,35,0,0,0,0,0,0
0,0,0,0,0,0,52,6,0,0,0,0,6,39,0,0,0,0,0,0,6,0,0,0,0,0,0,0,0,0,0,0,0,6,52,0,0,0,0,0,0
0,0,0,0,0,0,34,6,0,0,0,0,6,39,0,0,0,0,0,0,6,0,0,0,0,0,0,0,0,0,0,0,0,6,34,0,0,0,0,0,0
0,0,0,0,0,0,13,6,0,0,0,0,6,40,0,0,0,0,0,0,6,0,0,0,0,0,0,0,0,0,0,0,0,6,13,0,0,0,0,0,0
0,0,0,0,0,0,16,6,0,0,0,0,6,0,0,0,0,0,0,39,6,0,0,0,0,0,0,0,0,0,0,0,0,6,20,0,0,0,0,0,0
0,0,0,0,0,0,11,6,0,0,0,0,6,6,6,47,6,6,6,6,6,39,39,47,39,39,0,0,0,0,0,0,0,6,11,0,0,0,0,0,0
0,0,0,0,0,0,35,6,0,0,0,0,0,0,39,0,0,0,0,0,39,0,0,0,0,39,0,0,0,0,0,0,0,6,35,0,0,0,0,0,0
0,0,0,0,0,0,52,6,0,0,0,0,0,0,39,0,0,0,0,0,39,0,0,0,0,39,0,0,0,0,0,0,0,6,52,0,0,0,0,0,0
0,0,0,0,25,0,34,6,0,0,0,0,0,0,39,0,0,0,0,0,39,0,0,0,0,39,0,0,0,0,0,0,0,6,34,0,0,0,0,0,0
0,0,0,9,6,35,6,6,0,0,0,0,0,0,39,0,0,0,0,0,39,0,0,0,0,39,0,0,0,0,0,0,0,6,6,35,6,22,0,0,0
0,0,13,6,6,6,6,6,68,68,0,0,0,0,39,0,0,0,0,0,39,0,0,0,0,39,0,0,0,0,0,68,68,6,6,6,6,6,13,0,0
0,0,6,6,6,28,37,10,10,68,0,0,0,0,39,0,0,0,0,0,39,0,0,0,71,39,0,0,0,0,0,68,10,10,37,0,6,6,6,0,0
0,0,16,6,0,0,37,10,10,6,6,6,6,6,6,6,6,6,6,6,6,6,6,6,6,6,6,6,6,6,6,6,10,10,37,0,0,6,20,0,0
0,0,0,50,0,0,14,12,12,6,6,16,52,20,9,34,22,16,52,20,33,16,52,20,9,34,22,16,52,20,6,6,12,12,14,0,0,50,0,0,0
0,0,16,6,0,0,0,0,0,6,20,0,0,0,0,0,0,0,0,0,27,0,0,0,0,0,0,0,0,0,16,6,0,0,0,0,0,6,20,0,0
0,0,6,6,6,0,0,0,6,6,6,28,0,0,0,0,0,0,0,0,0,0,0,0,0,0,0,0,0,26,6,6,6,0,0,0,6,6,6,0,0
0,0,11,6,6,6,50,6,6,6,11,0,0,0,0,0,0,0,0,0,0,0,0,0,0,0,0,0,0,0,11,6,6,6,50,6,6,6,11,0,0
0,0,0,9,6,34,51,34,6,22,0,0,0,0,0,0,0,0,0,0,0,0,0,0,0,0,0,0,0,0,0,9,6,34,51,34,6,22,0,0,0
0,0,0,0,0,0,0,0,0,0,0,0,0,0,0,0,0,0,0,0,0,0,0,0,0,0,0,0,0,0,0,0,0,0,0,0,0,0,0,0,0
0,0,0,0,0,0,0,0,0,0,0,0,0,0,0,0,0,0,0,0,0,0,0,0,0,0,0,0,0,0,0,0,0,0,0,0,0,0,0,0,0
0,0,0,0,0,0,0,0,0,0,0,0,0,0,0,0,0,0,0,0,0,0,0,0,0,0,0,0,0,0,0,0,0,0,0,0,0,0,0,0,0
0,0,0,0,0,0,0,0,0,0,0,0,0,0,0,0,0,0,0,0,0,0,0,0,0,0,0,0,0,0,0,0,0,0,0,0,0,0,0,0,0
0,0,0,0,0,0,0,0,0,0,0,0,0,0,0,0,0,0,0,0,0,0,0,0,0,0,0,0,0,0,0,0,0,0,0,0,0,0,0,0,0
0,0,0,0,0,0,0,0,0,0,0,0,0,0,0,0,0,0,0,0,0,0,0,0,0,0,0,0,0,0,0,0,0,0,0,0,0,0,0,0,0
0,0,0,0,0,0,0,0,0,0,0,0,0,0,0,0,0,0,0,0,0,0,0,0,0,0,0,0,0,0,0,0,0,0,0,0,0,0,0,0,0
0,0,0,0,0,0,0,0,0,0,0,0,0,0,0,0,0,0,0,0,0,0,0,0,0,0,0,0,0,0,0,0,0,0,0,0,0,0,0,0,0
0,0,0,0,0,0,0,0,0,0,0,0,0,0,0,0,0,0,0,0,0,0,0,0,0,0,0,0,0,0,0,0,0,0,0,0,0,0,0,0,0
0,0,0,0,0,0,0,0,0,0,0,0,0,0,0,0,0,0,0,0,0,0,0,0,0,0,0,0,0,0,0,0,0,0,0,0,0,0,0,0,0
:endlayer
layer: 21
0,0,0,0,0,0,0,0,0,0,0,0,0,0,0,0,0,0,0,0,0,0,0,0,0,0,0,0,0,0,0,0,0,0,0,0,0,0,0,0,0
0,0,0,0,0,0,0,0,0,0,0,0,0,0,0,0,0,0,0,0,0,0,0,0,0,0,0,0,0,0,0,0,0,0,0,0,0,0,0,0,0
0,0,0,0,6,58,0,58,6,0,0,0,0,0,0,0,0,0,0,0,0,0,0,0,0,0,0,0,0,0,0,0,6,58,0,58,6,0,0,0,0
0,0,0,6,6,6,50,6,6,6,0,0,0,0,0,0,0,0,0,0,0,0,0,0,0,0,0,0,0,0,0,6,6,6,50,6,6,6,0,0,0
0,0,6,6,6,0,37,10,6,6,6,0,0,0,0,0,0,0,0,0,0,0,0,0,0,0,0,0,0,0,6,6,6,10,37,0,6,6,6,0,0
0,0,58,6,0,0,37,10,10,6,58,0,0,0,0,0,0,0,0,0,0,0,0,0,0,0,0,0,0,0,58,6,10,10,37,0,0,6,58,0,0
0,0,0,50,0,0,14,12,12,6,6,58,0,58,0,13,0,58,0,58,33,58,0,58,0,13,0,58,0,58,6,6,12,12,14,0,0,50,0,0,0
0,0,58,6,0,0,0,0,0,6,6,6,50,6,6,6,6,6,50,6,6,6,50,6,6,6,6,6,50,6,6,6,0,0,0,0,0,6,58,0,0
0,0,6,6,6,0,0,0,0,0,0,0,0,0,0,39,0,0,0,0,39,0,0,0,0,39,0,0,0,0,0,0,0,0,0,0,6,6,6,0,0
0,0,0,6,6,6,6,6,0,0,0,0,0,0,0,39,0,0,0,0,39,0,0,0,0,39,0,0,0,0,0,0,0,6,6,6,6,6,0,0,0
0,0,0,0,6,58,6,6,0,0,0,0,0,0,0,39,0,0,0,0,39,0,0,0,0,39,0,0,0,0,0,0,0,6,6,58,6,0,0,0,0
0,0,0,0,0,0,58,6,0,0,0,0,0,0,0,39,0,0,0,0,39,0,0,0,0,39,0,0,0,0,0,0,0,6,58,0,0,0,0,0,0
0,0,0,0,0,0,0,50,0,0,0,0,0,0,0,39,0,0,0,0,39,0,0,0,0,39,0,0,0,0,0,0,0,50,0,0,0,0,0,0,0
0,0,0,0,0,0,58,6,0,0,0,0,0,0,0,39,0,0,0,0,39,0,0,0,0,39,0,0,0,0,0,0,0,6,58,0,0,0,0,0,0
0,0,0,0,0,0,0,6,0,0,0,0,6,6,6,6,6,76,6,6,6,39,39,80,39,39,39,39,81,39,39,39,39,6,0,0,0,0,0,0,0
0,0,0,0,0,0,9,6,0,0,0,0,6,39,0,0,0,0,0,39,6,0,0,0,0,0,0,0,0,0,0,0,0,6,22,0,0,0,0,0,0
0,0,0,0,0,0,0,6,0,0,0,0,6,0,0,0,0,0,0,0,6,0,0,0,0,0,0,0,0,0,0,0,0,6,0,0,0,0,0,0,0
0,0,0,0,0,0,58,6,0,0,0,0,74,0,0,0,0,0,0,0,6,0,0,0,0,0,0,0,0,0,0,0,0,6,58,0,0,0,0,0,0
0,0,0,0,0,0,0,50,0,0,0,0,73,0,0,0,0,0,0,0,6,0,0,0,0,0,0,0,0,0,0,0,0,50,0,0,0,0,0,0,0
0,0,0,0,0,0,58,6,0,0,0,0,6,0,0,0,0,0,0,0,6,0,0,0,0,0,0,0,0,0,0,0,0,6,58,0,0,0,0,0,0
0,0,0,0,0,0,33,6,0,0,0,0,6,39,0,0,0,0,0,0,78,0,0,0,0,0,0,0,0,0,0,0,0,6,33,0,0,0,0,0,0
0,0,0,0,0,0,58,6,0,0,0,0,6,39,0,0,0,0,0,0,77,0,0,0,0,0,0,0,0,0,0,0,0,6,58,0,0,0,0,0,0
0,0,0,0,0,0,0,50,0,0,0,0,6,39,0,0,0,0,0,0,6,0,0,0,0,0,0,0,0,0,0,0,0,50,0,0,0,0,0,0,0
0,0,0,0,0,0,58,6,0,0,0,0,6,40,0,0,0,0,0,0,6,0,0,0,0,0,0,0,0,0,0,0,0,6,58,0,0,0,0,0,0
0,0,0,0,0,0,0,6,0,0,0,0,6,0,0,0,0,0,0,0,6,0,0,0,0,0,0,0,0,0,0,0,0,6,0,0,0,0,0,0,0
0,0,0,0,0,0,9,6,0,0,0,0,6,0,0,0,0,0,0,39,6,0,0,0,0,0,0,0,0,0,0,0,0,6,22,0,0,0,0,0,0
0,0,0,0,0,0,0,6,0,0,0,0,6,6,6,75,6,6,6,6,6,39,39,79,39,39,0,0,0,0,0,0,0,6,0,0,0,0,0,0,0
0,0,0,0,0,0,58,6,0,0,0,0,0,0,39,0,0,0,0,0,39,0,0,0,0,39,0,0,0,0,0,0,0,6,58,0,0,0,0,0,0
0,0,0,0,0,0,0,50,0,0,0,0,0,0,39,0,0,0,0,0,39,0,0,0,0,39,0,0,0,0,0,0,0,50,0,0,0,0,0,0,0
0,0,0,0,0,0,58,6,0,0,0,0,0,0,39,0,0,0,0,0,39,0,0,0,0,39,0,0,0,0,0,0,0,6,58,0,0,0,0,0,0
0,0,0,0,6,58,6,6,0,0,0,0,0,0,39,0,0,0,0,0,39,0,0,0,0,39,0,0,0,0,0,0,0,6,6,58,6,0,0,0,0
0,0,0,6,6,6,6,6,0,0,0,0,0,0,39,0,0,0,0,0,39,0,0,0,0,39,0,0,0,0,0,0,0,6,6,6,6,6,0,0,0
0,0,6,6,6,10,12,0,0,0,0,0,0,0,39,0,0,0,0,0,39,0,0,0,0,39,0,0,0,0,0,0,0,0,12,10,6,6,6,0,0
0,0,58,6,10,10,12,0,0,6,6,6,50,6,6,6,6,6,50,6,6,6,50,6,6,6,6,6,50,6,6,6,0,0,12,10,10,6,58,0,0
0,0,0,50,37,37,14,0,0,6,6,58,0,58,0,11,0,58,0,58,33,58,0,58,0,11,0,58,0,58,6,6,0,0,14,37,37,50,0,0,0
0,0,58,6,0,0,0,0,0,6,58,0,0,0,0,0,0,0,0,0,0,0,0,0,0,0,0,0,0,0,58,6,0,0,0,0,0,6,58,0,0
0,0,6,6,6,0,0,0,6,6,6,0,0,0,0,0,0,0,0,0,0,0,0,0,0,0,0,0,0,0,6,6,6,0,0,0,6,6,6,0,0
0,0,0,6,6,6,50,6,6,6,0,0,0,0,0,0,0,0,0,0,0,0,0,0,0,0,0,0,0,0,0,6,6,6,50,6,6,6,0,0,0
0,0,0,0,6,58,0,58,6,0,0,0,0,0,0,0,0,0,0,0,0,0,0,0,0,0,0,0,0,0,0,0,6,58,0,58,6,0,0,0,0
0,0,0,0,0,0,0,0,0,0,0,0,0,0,0,0,0,0,0,0,0,0,0,0,0,0,0,0,0,0,0,0,0,0,0,0,0,0,0,0,0
0,0,0,0,0,0,0,0,0,0,0,0,0,0,0,0,0,0,0,0,0,0,0,0,0,0,0,0,0,0,0,0,0,0,0,0,0,0,0,0,0
0,0,0,0,0,0,0,0,0,0,0,0,0,0,0,0,0,0,0,0,0,0,0,0,0,0,0,0,0,0,0,0,0,0,0,0,0,0,0,0,0
0,0,0,0,0,0,0,0,0,0,0,0,0,0,0,0,0,0,0,0,0,0,0,0,0,0,0,0,0,0,0,0,0,0,0,0,0,0,0,0,0
0,0,0,0,0,0,0,0,0,0,0,0,0,0,0,0,0,0,0,0,0,0,0,0,0,0,0,0,0,0,0,0,0,0,0,0,0,0,0,0,0
0,0,0,0,0,0,0,0,0,0,0,0,0,0,0,0,0,0,0,0,0,0,0,0,0,0,0,0,0,0,0,0,0,0,0,0,0,0,0,0,0
0,0,0,0,0,0,0,0,0,0,0,0,0,0,0,0,0,0,0,0,0,0,0,0,0,0,0,0,0,0,0,0,0,0,0,0,0,0,0,0,0
0,0,0,0,0,0,0,0,0,0,0,0,0,0,0,0,0,0,0,0,0,0,0,0,0,0,0,0,0,0,0,0,0,0,0,0,0,0,0,0,0
0,0,0,0,0,0,0,0,0,0,0,0,0,0,0,0,0,0,0,0,0,0,0,0,0,0,0,0,0,0,0,0,0,0,0,0,0,0,0,0,0
0,0,0,0,0,0,0,0,0,0,0,0,0,0,0,0,0,0,0,0,0,0,0,0,0,0,0,0,0,0,0,0,0,0,0,0,0,0,0,0,0
:endlayer
layer: 22
0,0,0,0,0,0,0,0,0,0,0,0,0,0,0,0,0,0,0,0,0,0,0,0,0,0,0,0,0,0,0,0,0,0,0,0,0,0,0,0,0
0,0,0,0,25,0,0,0,25,0,0,0,0,0,0,0,0,0,0,0,0,0,0,0,0,0,0,0,0,0,0,0,25,0,0,0,25,0,0,0,0
0,0,0,16,6,13,0,13,6,20,0,0,0,0,0,0,0,0,0,0,0,0,0,0,0,0,0,0,0,0,0,16,6,13,0,13,6,20,0,0,0
0,0,35,6,6,6,50,6,6,6,35,0,0,0,0,0,0,0,0,0,0,0,0,0,0,0,0,0,0,0,35,6,6,6,50,6,6,6,35,0,0
0,26,6,6,6,10,12,0,6,6,6,0,0,0,0,0,0,0,0,0,0,0,0,0,0,0,0,0,0,0,6,6,6,0,12,10,6,6,6,28,0
0,0,9,6,10,10,12,0,0,6,22,0,0,0,0,0,0,0,0,0,0,0,0,0,0,0,0,0,0,0,9,6,0,0,12,10,10,6,22,0,0
0,0,0,50,37,37,14,0,0,6,6,58,0,58,0,58,0,58,0,58,33,58,0,58,0,58,0,58,0,58,6,6,0,0,14,37,37,50,0,0,0
0,0,9,6,25,0,0,0,0,6,6,6,50,6,6,6,6,6,50,6,6,6,50,6,6,6,6,6,50,6,6,6,0,0,0,0,25,6,22,0,0
0,26,6,6,6,0,0,0,0,0,0,0,0,0,0,39,0,0,0,0,39,0,0,0,0,39,0,0,0,0,0,0,0,0,0,0,6,6,6,28,0
0,0,34,6,6,6,6,6,0,0,0,0,0,0,0,39,0,0,0,0,39,0,0,0,0,39,0,0,0,0,0,0,0,6,6,6,6,6,34,0,0
0,0,0,16,6,11,6,6,0,0,0,0,0,0,0,39,0,0,0,0,39,0,0,0,0,39,0,0,0,0,0,0,0,6,6,11,6,20,0,0,0
0,0,0,0,0,0,58,6,0,0,0,0,0,0,0,39,0,0,0,0,39,0,0,0,0,39,0,0,0,0,0,0,0,6,58,0,0,0,0,0,0
0,0,0,0,0,0,0,50,0,0,0,0,0,0,0,39,0,0,0,0,39,0,0,0,0,39,0,0,0,0,0,0,0,50,0,0,0,0,0,0,0
0,0,0,0,0,0,58,6,0,0,0,0,0,0,0,39,0,25,0,0,39,0,25,0,0,39,0,0,0,25,0,0,0,6,58,0,0,0,0,0,0
0,0,0,0,0,0,0,6,0,0,0,0,6,6,6,6,6,6,6,6,6,39,39,39,39,39,39,39,39,39,39,39,39,6,0,0,0,0,0,0,0
0,0,0,0,0,0,58,6,0,0,0,0,6,39,0,0,0,0,0,39,6,0,0,0,0,0,0,0,0,0,0,0,0,6,58,0,0,0,0,0,0
0,0,0,0,0,0,0,6,0,0,0,0,6,0,0,0,0,0,0,0,6,0,0,0,0,0,0,0,0,0,0,0,0,6,0,0,0,0,0,0,0
0,0,0,0,0,0,58,6,0,0,0,26,6,0,0,0,0,0,0,0,6,0,0,0,0,0,0,0,0,0,0,0,0,6,58,0,0,0,0,0,0
0,0,0,0,0,0,0,50,0,0,0,26,6,0,0,0,0,0,0,0,6,0,0,0,0,0,0,0,0,0,0,0,0,50,0,0,0,0,0,0,0
0,0,0,0,0,0,58,6,0,0,0,0,6,0,0,0,0,0,0,0,6,28,0,0,0,0,0,0,0,0,0,0,0,6,58,0,0,0,0,0,0
0,0,0,0,0,0,33,6,0,0,0,0,6,39,0,0,0,0,0,0,6,0,0,0,0,0,0,0,0,0,0,0,0,6,33,0,0,0,0,0,0
0,0,0,0,0,0,58,6,0,0,0,0,6,39,0,0,0,0,0,0,6,0,0,0,0,0,0,0,0,0,0,0,0,6,58,0,0,0,0,0,0
0,0,0,0,0,0,0,50,0,0,0,0,6,40,0,0,0,0,0,0,6,0,0,0,0,0,0,0,0,0,0,0,0,50,0,0,0,0,0,0,0
0,0,0,0,0,0,58,6,0,0,0,0,6,0,0,0,0,0,0,0,6,0,0,0,0,0,0,0,0,0,0,0,0,6,58,0,0,0,0,0,0
0,0,0,0,0,0,0,6,0,0,0,0,6,0,0,0,0,0,0,0,6,0,0,0,0,0,0,0,0,0,0,0,0,6,0,0,0,0,0,0,0
0,0,0,0,0,0,58,6,0,0,0,0,6,0,0,0,0,0,0,39,6,0,0,0,0,0,0,0,0,0,0,0,0,6,58,0,0,0,0,0,0
0,0,0,0,0,0,0,6,0,0,0,0,6,6,6,6,6,6,6,6,6,39,39,39,39,39,0,0,0,0,0,0,0,6,0,0,0,0,0,0,0
0,0,0,0,0,0,58,6,0,0,0,0,0,0,39,0,82,0,0,0,39,0,0,27,0,39,0,0,0,0,0,0,0,6,58,0,0,0,0,0,0
0,0,0,0,0,0,0,50,0,0,0,0,0,0,39,0,0,0,0,0,39,0,0,0,0,39,0,0,0,0,0,0,0,50,0,0,0,0,0,0,0
0,0,0,0,0,0,58,6,0,0,0,0,0,0,39,0,0,0,0,0,39,0,0,0,0,39,0,0,0,0,0,0,0,6,58,0,0,0,0,0,0
0,0,0,16,6,13,6,6,0,0,0,0,0,0,39,0,0,0,0,0,39,0,0,0,0,39,0,0,0,0,0,0,0,6,6,13,6,20,0,0,0
0,0,35,6,6,6,6,6,0,0,0,0,0,0,39,0,0,0,0,0,39,0,0,0,0,39,0,0,0,0,0,0,0,6,6,6,6,6,35,0,0
0,26,6,6,6,0,0,0,0,0,0,0,0,0,39,0,0,0,0,0,39,0,0,0,0,39,0,0,0,0,0,0,0,0,0,0,6,6,6,28,0
0,0,9,6,0,0,0,0,0,6,6,6,50,6,6,6,6,6,50,6,6,6,50,6,6,6,6,6,50,6,6,6,0,0,0,0,0,6,22,0,0
0,0,0,50,12,12,14,0,0,6,6,58,0,58,0,58,0,58,0,58,33,58,0,58,0,58,0,58,0,58,6,6,0,0,14,12,12,50,0,0,0
0,0,9,6,10,10,37,0,0,6,22,0,0,0,0,0,0,0,0,0,0,0,0,0,0,0,0,0,0,0,9,6,0,0,37,10,10,6,22,0,0
0,26,6,6,6,10,37,26,6,6,6,0,0,0,0,0,0,0,0,0,0,0,0,0,0,0,0,0,0,0,6,6,6,28,37,10,6,6,6,28,0
0,0,34,6,6,6,50,6,6,6,34,0,0,0,0,0,0,0,0,0,0,0,0,0,0,0,0,0,0,0,34,6,6,6,50,6,6,6,34,0,0
