# Ancient Warfare Structure Template File
# Auto-generated structure template file. created on: 4/4/2017 at: 4:34:53
# Lines beginning with # denote comments

header:
version=2.1
name=ReignDungeonChurch
size=31,52,22
offset=15,8,19
:endheader

#### VALIDATION ####
validation:
type=ground
survival=false
worldGenEnabled=false
unique=false
preserveBlocks=false
selectionWeight=0
clusterValue=0
minDuplicateDistance=0
dimensionWhiteList=false
dimensionList=
biomeWhiteList=false
biomeList=
leveling=0
fill=0
border=0
validTargetBlocks=
blockSwap=false
data:
:enddata
:endvalidation

#### LAYERS ####
layer: 0
1,2,2,2,2,2,2,2,2,2,2,2,2,2,2,2,2,2,2,2,2,2,2,2,2,2,2,2,2,3,1
1,2,2,2,2,2,2,2,2,2,2,2,2,2,2,2,2,2,2,2,2,2,2,2,2,2,2,2,2,3,3
1,2,2,2,2,2,2,2,2,2,2,2,2,2,2,2,2,2,2,2,2,2,2,2,2,2,2,2,2,3,3
1,2,2,2,2,2,2,2,2,2,2,2,2,2,2,2,2,2,2,2,2,2,2,2,2,2,2,2,2,3,3
1,2,2,2,2,2,2,2,2,2,2,2,2,2,2,2,2,2,2,2,2,2,2,2,2,2,2,2,2,3,3
1,2,2,2,2,2,2,2,2,2,2,2,2,2,2,2,2,2,2,2,2,2,2,2,2,2,2,2,2,7,3
1,2,2,2,2,2,2,2,2,2,2,2,2,2,2,2,2,2,2,2,2,2,2,2,2,2,2,2,2,7,3
1,2,2,2,2,2,2,2,2,2,2,2,2,2,2,2,2,2,2,2,2,2,2,2,2,2,2,2,2,3,3
1,2,2,2,2,2,2,2,2,2,2,2,2,2,2,2,2,2,2,2,2,2,2,2,2,2,2,2,2,3,3
1,2,2,2,2,2,2,2,2,2,2,2,2,2,2,2,2,2,2,2,2,2,2,2,2,2,2,2,2,3,3
1,2,2,2,2,2,2,2,2,2,2,2,2,2,2,2,2,2,2,2,2,2,2,2,2,2,2,2,2,3,3
1,2,2,2,2,2,2,2,2,2,2,2,2,2,2,2,2,2,2,2,2,2,2,4,5,2,2,2,2,3,3
1,2,2,2,2,2,2,2,2,2,2,2,2,2,2,2,2,2,2,2,2,2,2,2,2,2,2,2,2,3,3
1,2,2,2,2,2,2,2,2,2,2,2,2,2,2,2,2,2,2,2,2,2,2,2,2,2,2,2,2,3,3
1,2,2,2,2,2,2,2,2,2,2,2,2,2,2,2,2,2,2,2,2,2,2,2,2,2,2,2,2,3,3
1,2,2,2,2,2,2,2,2,2,2,2,2,2,2,2,2,2,2,2,2,2,2,2,2,2,2,2,2,3,3
1,2,2,2,2,2,2,2,2,2,2,2,2,2,2,2,2,2,2,2,2,2,2,2,2,2,2,2,2,3,3
1,2,2,2,2,2,2,2,2,2,2,2,2,2,2,2,2,2,2,2,2,2,2,2,2,2,2,2,2,3,6
1,2,2,2,2,2,2,2,2,2,2,2,2,2,2,2,2,2,2,2,2,2,2,2,2,2,2,2,2,6,6
1,2,2,2,2,2,2,2,2,2,2,2,2,2,2,2,2,2,2,2,2,2,2,2,2,2,2,2,2,6,6
1,2,2,2,2,2,2,2,2,2,2,2,2,2,2,2,2,2,2,2,2,2,2,2,2,2,2,2,2,6,6
1,1,1,1,1,1,1,1,1,1,1,1,1,1,1,1,1,1,1,1,3,3,3,3,3,3,3,6,6,6,6
:endlayer
layer: 1
2,2,2,2,2,2,2,2,2,2,2,2,2,2,2,2,2,2,2,2,2,2,2,2,2,2,2,2,2,2,7
2,2,2,0,0,0,0,0,0,0,0,0,0,0,22,22,2,0,28,0,2,0,0,33,2,0,0,0,2,2,7
2,0,0,0,0,0,0,0,0,16,0,0,0,0,21,24,2,0,0,0,2,0,0,0,2,0,0,0,2,2,7
2,0,0,2,2,2,2,2,0,0,0,0,2,2,2,2,2,2,0,2,2,2,0,2,2,2,0,2,2,2,7
2,0,0,2,8,2,15,2,2,2,2,2,19,0,0,0,0,0,0,0,0,0,0,0,0,0,0,0,29,2,7
2,0,0,0,8,0,0,0,0,2,2,2,19,0,0,0,0,0,0,0,0,0,0,0,0,0,0,0,29,2,7
2,0,0,2,2,2,2,2,0,2,2,2,2,2,2,2,2,0,0,2,2,2,2,2,2,2,2,2,2,2,7
2,0,0,0,14,2,0,0,0,2,17,17,17,17,17,17,2,0,0,2,29,29,2,29,2,0,31,0,39,2,7
2,0,0,2,2,2,2,2,0,0,0,0,0,0,0,0,0,0,0,0,0,0,0,0,0,0,2,2,2,2,7
2,0,0,0,13,2,0,0,0,2,0,0,0,0,0,0,0,0,0,0,0,0,0,0,0,0,31,0,0,2,7
2,0,0,2,2,2,2,2,0,0,0,0,0,0,0,23,2,19,23,2,19,0,0,0,0,0,2,2,2,2,7
2,0,0,0,12,2,0,0,0,2,0,18,0,0,0,0,17,0,0,17,0,0,0,32,0,0,31,0,38,2,7
2,0,0,2,2,2,2,2,0,0,0,0,0,0,0,0,25,0,27,25,0,0,0,0,0,0,2,2,2,2,7
2,0,0,0,11,2,0,0,0,2,0,0,0,0,0,23,2,19,23,2,19,0,0,0,0,0,31,0,37,2,7
2,0,0,2,2,2,2,2,0,0,0,0,0,0,0,0,0,0,0,0,0,0,0,0,0,0,2,2,2,2,7
2,0,0,0,10,2,0,0,0,2,0,0,0,0,0,0,0,0,0,0,0,0,0,0,0,0,31,0,36,2,7
2,0,0,2,2,2,2,2,0,0,8,2,2,2,2,0,2,0,0,2,2,0,0,2,2,2,2,2,2,2,7
2,0,0,0,9,2,0,0,0,2,0,0,0,20,0,0,0,0,0,0,0,0,0,2,0,0,0,0,0,2,7
2,0,0,2,2,2,2,2,0,0,0,0,0,0,0,0,2,0,26,0,0,0,30,31,0,0,0,35,2,2,7
2,2,0,0,8,0,0,0,0,2,0,0,0,0,0,0,2,0,0,2,0,0,0,2,0,0,34,2,2,2,7
2,2,2,8,0,0,0,0,0,0,0,0,0,0,0,0,2,0,0,2,0,0,0,2,0,0,2,2,2,2,7
2,2,2,2,2,2,2,2,2,2,2,2,2,2,2,2,2,2,2,2,2,2,2,2,2,2,2,2,2,2,7
:endlayer
layer: 2
2,2,2,2,2,2,2,2,2,2,2,2,2,2,2,2,2,2,2,2,2,2,2,2,2,2,2,2,2,2,7
2,2,2,0,0,0,0,0,0,0,0,0,0,0,0,0,2,0,44,0,42,0,0,0,42,0,0,0,0,2,7
2,0,0,0,0,0,0,0,0,0,0,0,0,0,0,0,2,0,0,0,42,0,0,0,42,0,0,0,52,2,7
2,0,0,2,2,2,2,2,0,0,0,0,2,2,2,2,2,2,0,2,2,2,0,2,2,2,0,2,2,2,7
2,0,0,2,0,2,0,2,42,2,2,19,0,0,0,0,0,0,0,0,0,0,0,0,0,0,0,0,8,2,7
2,0,0,0,8,0,0,0,0,2,2,19,0,0,0,8,0,0,0,0,0,0,0,0,0,0,0,0,0,2,7
2,0,0,2,40,2,41,2,0,2,2,2,2,2,2,2,2,0,0,2,2,2,2,2,2,2,2,2,2,2,7
2,0,0,0,0,2,0,0,0,2,29,29,29,29,29,29,2,0,0,2,0,0,2,0,2,0,51,0,0,2,7
2,0,0,2,40,2,41,2,0,0,0,0,0,0,0,0,0,0,0,0,0,0,0,0,0,0,2,23,23,2,7
2,0,0,0,0,2,0,0,0,2,0,0,0,0,0,0,0,0,0,0,0,0,0,0,0,0,50,0,0,2,7
2,0,0,2,40,2,41,2,0,0,0,0,0,0,0,0,2,0,0,2,0,0,0,0,0,0,2,23,23,2,7
2,0,0,0,0,2,0,0,0,2,0,44,0,0,0,0,0,0,0,0,0,0,0,44,0,0,49,0,0,2,7
2,0,0,2,40,2,41,2,0,0,0,0,0,0,0,0,0,0,44,0,0,0,0,0,0,0,2,23,23,2,7
2,0,0,0,0,2,0,0,0,2,0,0,0,0,0,0,2,0,0,2,0,0,0,0,0,0,48,0,0,2,7
2,0,0,2,40,2,41,2,0,0,0,0,0,0,0,0,0,0,0,0,0,0,0,0,0,0,2,23,23,2,7
2,0,0,0,0,2,0,0,0,2,0,0,0,0,0,0,0,0,0,0,0,0,0,0,0,0,47,0,0,2,7
2,0,0,2,40,2,41,2,0,0,8,2,2,2,2,0,2,0,0,2,2,0,0,2,2,2,2,2,2,2,7
2,0,0,0,0,2,0,0,0,2,0,0,0,44,0,0,0,0,0,0,0,0,0,2,0,0,0,0,0,2,7
2,0,0,2,2,2,41,2,0,0,0,0,0,0,0,0,2,0,44,0,0,0,0,46,0,0,0,0,2,2,7
2,2,0,0,0,0,0,0,0,2,0,0,0,0,0,0,2,0,0,2,0,0,0,2,0,0,0,2,2,2,7
2,2,2,0,0,0,0,0,0,0,0,0,0,0,0,0,2,0,0,2,0,0,0,45,0,0,2,2,2,2,7
2,2,2,2,0,2,2,2,2,43,2,2,2,2,2,2,2,2,2,2,2,2,2,2,2,2,2,2,2,2,7
:endlayer
layer: 3
2,2,2,2,2,2,2,2,2,2,2,2,2,2,2,2,2,2,2,2,2,2,2,2,2,2,2,2,2,2,7
2,2,2,0,0,0,0,0,0,0,0,0,0,0,0,0,2,0,44,0,42,0,0,0,42,0,0,0,2,2,7
2,0,0,0,0,0,0,0,0,0,0,0,0,0,0,0,2,0,0,0,57,0,0,0,57,0,0,0,2,2,7
2,0,0,2,2,2,2,2,2,2,2,2,2,2,2,2,2,2,0,2,2,2,0,2,2,2,0,2,2,2,7
2,2,2,2,0,2,0,2,8,2,19,0,0,0,0,0,0,0,0,0,0,0,0,0,0,0,0,0,29,2,7
2,0,0,29,8,0,0,29,0,2,19,0,0,0,0,8,0,0,0,0,0,0,0,0,0,0,0,0,29,2,7
2,0,0,2,2,2,2,2,0,2,2,2,2,2,2,2,2,0,0,2,2,2,2,2,2,2,2,2,2,2,7
2,0,0,29,0,2,0,29,0,2,0,53,0,0,0,54,2,0,0,2,56,56,17,56,17,0,2,0,0,2,7
2,0,0,2,2,2,2,2,0,0,0,0,0,0,0,0,0,0,0,0,0,0,0,0,0,0,2,2,2,2,7
2,0,0,29,0,2,0,29,0,2,0,0,0,0,0,0,0,0,0,0,0,0,0,0,0,0,2,0,0,2,7
2,0,0,2,2,2,2,2,0,0,0,0,0,0,0,0,2,0,0,2,0,0,0,0,0,0,2,2,2,2,7
2,0,0,29,0,2,0,29,0,2,0,44,0,0,0,0,0,0,0,0,0,0,0,44,0,0,2,0,0,2,7
2,0,0,2,2,2,2,2,0,0,0,0,0,0,0,0,0,0,44,0,0,0,0,0,0,0,2,2,2,2,7
2,0,0,29,0,2,0,29,0,2,0,0,0,0,0,0,2,0,0,2,0,0,0,0,0,0,2,0,0,2,7
2,0,0,2,2,2,2,2,0,0,0,0,0,0,0,0,0,0,0,0,0,0,0,0,0,0,2,2,2,2,7
2,0,0,29,0,2,0,29,0,2,0,0,0,0,0,0,0,0,0,0,0,0,0,0,0,0,2,0,0,2,7
2,0,0,2,2,2,2,2,0,0,8,2,2,2,2,0,2,0,0,2,2,0,0,2,45,2,2,2,2,2,7
2,0,0,29,0,2,0,29,0,2,0,0,0,44,0,0,0,0,0,0,0,0,0,2,0,0,0,0,0,2,7
2,0,0,2,2,2,2,2,0,0,0,0,0,0,0,0,2,0,44,0,0,0,0,2,58,0,0,0,2,2,7
2,2,0,0,0,0,0,0,0,2,0,0,0,0,0,0,2,0,0,2,0,0,0,2,0,0,0,2,2,2,7
2,2,2,0,0,0,0,0,0,0,0,0,0,0,0,0,55,0,0,45,0,0,0,45,0,0,2,2,2,2,7
2,2,2,2,0,2,2,2,2,2,2,2,2,2,2,2,2,2,2,2,2,2,2,2,2,2,2,2,2,2,7
:endlayer
layer: 4
2,2,2,2,2,2,2,2,2,2,2,2,2,2,2,2,2,2,2,2,2,2,2,2,2,2,2,2,2,2,7
2,2,2,0,0,0,0,0,0,0,0,0,0,0,0,0,2,0,0,0,42,0,0,0,42,0,0,0,61,2,7
2,0,0,0,0,0,0,0,0,0,0,0,0,0,0,0,2,0,0,0,42,0,0,0,42,0,0,0,0,2,7
2,0,0,2,2,2,2,2,2,2,2,2,2,2,2,2,2,41,2,40,2,40,2,40,2,41,2,40,2,2,7
2,2,2,2,0,2,0,2,42,19,0,0,0,0,2,0,0,0,0,0,0,0,0,0,0,0,0,0,0,2,7
2,0,0,42,8,0,0,29,29,19,0,0,0,0,2,8,0,0,0,0,0,0,0,0,0,0,0,0,60,2,7
2,0,0,2,40,2,2,2,29,2,2,2,2,2,2,2,2,0,0,2,2,45,2,45,2,2,2,2,2,2,7
2,0,0,42,0,2,0,29,29,2,41,29,29,29,29,40,2,0,0,2,41,0,0,0,0,0,2,0,0,2,7
2,0,0,2,40,2,41,2,0,2,0,0,0,0,0,8,2,0,0,42,0,0,0,0,0,40,2,40,40,2,7
2,0,0,42,0,2,0,29,0,2,41,29,29,29,29,29,2,0,0,57,0,0,0,0,0,0,2,0,0,2,7
2,0,0,2,40,2,41,2,0,2,8,0,0,0,0,40,2,0,0,2,41,0,0,0,0,40,2,40,40,2,7
2,0,0,42,0,2,0,29,0,2,41,29,29,29,29,29,2,0,0,42,0,0,0,0,0,59,2,0,0,2,7
2,0,0,2,40,2,41,2,0,2,0,0,0,0,0,0,2,0,0,57,0,0,0,0,0,40,2,40,40,2,7
2,0,0,42,0,2,0,29,0,2,41,29,29,29,29,40,2,0,0,2,41,0,0,0,0,0,2,0,0,2,7
2,0,0,2,40,2,41,2,0,2,8,0,0,0,0,8,2,0,0,42,0,0,0,0,0,40,2,40,40,2,7
2,0,0,57,0,2,0,29,0,2,41,29,29,29,29,29,2,0,0,57,0,0,0,0,0,0,2,0,0,2,7
2,0,0,2,40,2,41,2,0,2,0,2,2,2,2,40,2,0,0,2,2,41,40,2,2,2,2,2,2,2,7
2,0,0,57,0,2,0,29,0,2,41,29,29,29,29,29,2,0,0,42,0,0,0,2,0,0,0,0,0,2,7
2,8,0,2,0,2,41,2,0,2,0,0,0,0,0,40,2,0,0,57,0,0,0,2,0,0,0,0,2,2,7
2,2,8,0,0,0,0,29,0,2,41,29,29,29,29,29,2,0,0,2,0,0,0,2,0,0,0,2,2,2,7
2,2,2,0,0,0,0,29,8,2,0,0,0,0,0,40,2,0,0,2,0,0,0,2,0,0,2,2,2,2,7
2,2,2,2,2,2,2,2,2,2,2,2,2,2,2,2,2,2,2,2,2,2,2,2,2,2,2,2,2,2,7
:endlayer
layer: 5
7,7,7,7,7,7,7,7,7,7,7,7,7,7,7,7,7,7,7,7,7,7,7,7,7,7,7,7,7,7,7
7,7,7,2,2,2,2,2,2,2,2,2,2,2,2,2,7,2,2,2,7,2,2,2,7,2,2,2,2,7,7
7,2,2,2,2,2,2,2,2,2,2,2,2,2,2,2,7,2,2,2,7,2,2,2,7,2,2,2,2,7,7
7,2,2,7,7,7,2,7,2,2,2,2,2,2,7,7,7,7,7,7,7,7,7,7,7,7,7,7,7,7,7
7,2,2,7,2,7,2,7,19,0,0,0,0,0,2,2,2,2,2,2,2,2,2,2,2,2,2,2,2,7,7
7,2,2,7,2,2,2,7,19,0,0,0,0,0,2,2,2,2,2,2,2,2,2,2,2,2,2,2,2,7,7
7,2,2,7,7,7,2,7,2,2,2,2,2,2,2,7,7,62,62,7,2,2,2,2,2,2,7,7,7,7,7
7,2,2,7,2,7,2,2,2,7,7,7,7,7,7,7,7,62,62,2,2,2,2,2,2,2,2,2,2,7,7
7,2,2,7,7,7,7,7,2,7,2,2,2,2,2,2,7,62,62,2,2,2,2,2,2,2,7,7,7,7,7
7,2,2,7,2,7,2,2,2,7,7,7,7,7,7,7,7,62,62,2,2,2,2,2,2,2,2,2,2,7,7
7,2,2,7,7,7,7,7,2,7,2,2,2,2,2,7,7,62,62,7,2,2,2,2,2,7,7,7,7,7,7
7,2,2,7,7,7,2,2,2,7,7,7,7,7,7,7,7,62,62,7,2,2,2,2,2,2,2,2,2,7,7
7,2,2,7,7,7,7,7,2,7,2,2,2,2,2,2,7,62,62,7,2,2,2,2,2,7,7,7,7,7,7
7,2,2,7,2,7,2,2,2,7,7,7,7,7,7,7,7,62,62,7,2,2,2,2,2,2,2,2,2,7,7
7,2,2,7,7,7,7,7,2,7,2,2,2,2,2,2,7,62,62,7,2,2,2,2,2,2,7,7,7,7,7
7,2,2,7,2,7,2,2,2,7,7,7,7,7,7,7,7,62,62,7,2,2,2,2,2,2,2,2,2,7,7
7,2,2,7,7,7,7,7,2,7,2,2,2,2,2,7,7,62,62,7,2,2,2,2,2,2,2,2,2,7,7
2,2,2,7,2,7,2,2,2,7,7,7,7,7,7,7,7,62,62,2,2,2,2,7,2,2,2,2,2,2,7
7,2,2,7,2,7,7,7,2,7,2,2,2,2,2,7,7,62,62,2,2,2,2,7,2,2,2,2,2,7,7
7,7,2,2,2,2,2,2,2,7,7,7,7,7,7,7,7,62,62,2,2,2,2,7,2,2,2,7,7,7,7
7,7,7,2,2,2,2,2,2,7,2,2,2,2,2,7,7,62,62,7,2,2,2,7,2,2,7,7,7,7,7
7,7,7,7,7,7,7,7,7,7,7,7,7,7,7,7,7,7,7,7,7,7,7,7,7,7,7,7,7,7,7
:endlayer
layer: 6
7,7,7,7,7,7,7,7,7,7,7,7,7,7,7,7,7,7,7,7,7,7,7,7,7,7,7,7,7,7,7
7,7,7,7,7,7,7,7,7,7,7,7,7,7,7,7,7,7,7,7,7,7,7,7,7,7,7,7,7,7,7
7,7,7,7,7,7,7,7,7,7,7,7,7,7,7,7,7,7,7,7,7,7,7,7,7,7,7,7,7,7,7
7,7,7,7,7,7,7,2,2,2,2,2,7,7,7,7,7,7,7,7,7,7,7,7,7,7,7,7,7,7,7
7,7,7,7,7,7,7,19,0,0,0,0,2,2,7,7,7,7,7,7,7,7,7,7,7,7,7,7,7,7,7
7,7,7,7,7,7,7,19,0,0,0,0,2,2,7,7,7,7,7,7,7,7,7,7,7,7,7,7,7,7,7
7,7,7,7,7,7,7,2,2,2,2,2,7,7,7,7,7,7,7,7,7,7,7,7,7,7,7,7,7,7,7
7,7,7,7,7,7,7,7,7,7,7,7,7,7,7,7,7,7,7,7,7,7,7,7,7,7,7,7,7,7,7
7,7,7,7,7,7,7,7,7,7,7,7,7,7,7,7,7,7,7,7,7,7,7,7,7,7,7,7,7,7,7
7,7,7,7,7,7,7,7,7,7,7,7,7,7,7,7,7,7,7,7,7,7,7,7,7,7,7,7,7,7,7
7,7,7,7,7,7,7,7,7,7,7,7,7,7,7,7,7,7,7,7,7,7,7,7,7,7,7,7,7,7,7
7,7,7,7,7,7,7,7,7,7,7,7,7,7,7,7,7,7,7,7,7,7,7,7,7,7,7,7,7,7,7
7,7,7,7,7,7,7,7,7,7,7,7,7,7,7,7,7,7,7,7,7,7,7,7,7,7,7,7,7,7,7
7,7,7,7,7,7,7,7,7,7,7,7,7,7,7,7,7,7,7,7,7,7,7,7,7,7,7,7,7,7,7
7,7,7,7,7,7,7,7,7,7,7,7,7,7,7,7,7,7,7,7,7,7,7,7,7,7,7,7,7,7,7
7,7,7,7,7,7,7,7,7,7,7,7,7,7,7,7,7,7,7,7,7,7,7,7,7,7,7,7,7,7,7
7,7,7,7,7,7,7,7,7,7,7,7,7,7,7,7,7,7,7,7,7,7,7,7,7,7,7,7,7,7,7
7,7,7,7,7,7,7,7,7,7,7,7,7,7,7,7,7,7,7,7,7,7,7,7,7,7,7,7,7,7,7
7,7,7,7,7,7,7,7,7,7,7,7,7,7,7,7,7,7,7,7,7,7,7,7,7,7,7,7,7,7,7
7,7,7,7,7,7,7,7,7,7,7,7,7,7,7,7,7,7,7,7,7,7,7,7,7,7,7,7,7,7,7
7,7,7,7,7,7,7,7,7,7,7,7,7,7,7,7,7,7,7,7,7,7,7,7,7,7,7,7,7,7,7
7,7,7,7,7,7,7,7,7,7,7,7,7,7,7,7,7,7,7,7,7,7,7,7,7,7,7,7,7,7,7
:endlayer
layer: 7
63,63,63,63,63,63,63,63,63,63,63,63,63,63,63,63,63,63,63,63,63,63,63,63,63,63,63,63,63,63,63
63,63,63,63,63,63,63,63,63,63,63,63,63,7,63,63,63,63,63,7,63,63,63,63,63,7,63,63,63,63,63
63,63,7,63,63,63,63,63,7,63,63,63,63,7,63,63,63,63,63,7,63,63,63,63,63,7,63,63,63,63,63
63,63,63,63,63,7,2,2,2,2,2,65,65,65,65,65,65,65,65,65,65,65,65,65,65,65,65,65,63,63,63
63,63,64,64,63,2,19,0,0,0,0,2,65,65,65,65,65,65,65,65,65,65,65,65,65,65,65,65,63,63,63
63,7,64,63,64,2,19,0,0,0,0,2,65,65,65,65,65,65,65,65,65,65,65,65,65,65,65,65,7,7,63
63,63,63,64,63,7,2,2,2,2,2,65,65,65,65,65,65,65,65,65,65,65,65,65,65,65,65,2,2,63,63
63,63,64,63,63,7,66,66,66,66,66,65,65,65,65,65,65,65,65,65,65,65,65,65,65,65,65,2,2,63,63
63,63,63,64,63,65,66,66,0,66,65,65,65,65,65,65,65,65,65,65,65,65,65,65,65,65,65,2,2,63,63
63,63,64,63,63,65,66,66,66,2,65,65,65,65,67,65,67,65,67,65,65,65,65,65,65,65,65,2,2,63,63
63,63,64,63,63,65,66,66,66,66,65,65,65,65,65,65,65,65,65,65,65,65,65,65,65,65,65,2,2,63,63
63,63,64,64,63,63,66,66,66,66,66,65,65,65,65,65,65,65,65,65,65,65,65,65,65,65,65,2,2,63,63
63,63,7,64,63,63,63,65,65,65,63,65,65,65,65,65,65,65,65,65,65,65,65,65,65,65,65,2,2,63,63
63,63,64,64,63,63,63,63,63,63,63,65,65,65,65,65,65,65,65,65,65,65,65,65,65,65,65,65,7,7,63
63,63,64,63,63,63,63,63,63,63,63,65,65,65,65,65,65,65,65,65,65,65,65,65,65,65,65,65,63,63,63
63,63,64,64,63,63,63,63,63,63,63,65,65,65,65,65,65,65,65,65,65,65,65,65,65,65,65,65,63,63,63
63,63,63,64,63,63,63,63,63,63,63,63,65,65,65,65,65,65,65,65,63,63,63,63,63,7,63,63,63,63,63
63,63,63,64,63,63,63,63,63,63,63,63,65,65,65,65,65,65,65,65,63,63,63,63,63,7,63,63,63,63,63
63,63,63,64,64,64,64,64,64,63,63,63,65,65,65,65,65,65,65,65,63,63,63,63,63,63,63,63,63,63,63
63,63,63,63,63,64,64,64,64,64,64,63,65,65,65,65,65,65,65,65,63,63,63,63,63,63,63,63,63,63,63
63,63,7,63,63,63,63,63,63,63,64,63,63,63,7,66,66,7,63,63,63,63,63,63,63,63,63,63,63,63,63
63,63,63,63,63,63,63,63,63,63,64,63,63,63,63,66,66,63,63,63,63,63,63,63,63,63,63,63,63,63,63
:endlayer
layer: 8
68,68,68,68,68,68,68,68,68,69,69,69,0,0,69,69,69,69,69,0,69,69,69,0,0,0,69,69,0,69,0
68,69,0,69,69,0,0,0,68,0,0,0,0,2,69,69,69,69,69,2,0,0,69,69,69,2,0,0,69,69,69
68,0,71,69,69,69,74,69,2,0,0,0,0,2,0,0,0,69,0,2,0,69,0,69,69,2,0,0,0,69,69
68,69,69,69,0,2,2,2,2,2,2,2,2,2,2,83,83,83,2,2,2,83,83,83,2,2,2,2,69,69,69
68,69,0,0,23,2,0,0,0,0,0,2,73,73,73,73,73,73,73,73,73,73,73,73,73,73,73,2,0,69,69
68,71,0,69,72,31,0,0,0,0,0,2,73,0,0,0,0,0,0,0,0,0,0,0,0,0,73,2,2,2,0
68,69,0,0,23,2,2,2,2,2,2,2,73,0,81,0,81,0,81,0,0,0,0,0,0,0,73,2,92,0,0
68,0,0,69,0,2,2,73,73,73,73,73,73,0,81,0,81,0,81,0,0,0,0,0,0,0,73,2,91,0,0
68,70,0,0,0,2,73,66,76,0,0,0,73,0,81,0,81,0,81,0,0,0,0,0,0,0,73,2,90,0,0
68,0,0,0,0,2,73,66,66,0,0,78,31,80,0,0,0,0,0,0,0,0,84,0,85,0,73,2,89,69,69
68,0,0,0,69,2,73,66,66,66,73,73,73,0,81,0,81,0,81,0,0,0,0,0,0,0,73,2,88,0,69
68,0,0,0,69,69,2,73,73,73,2,66,73,0,81,0,81,0,81,0,0,0,0,0,0,0,73,2,87,0,69
68,0,71,0,69,69,0,2,2,2,77,2,73,0,81,0,81,0,81,0,0,0,0,0,0,0,73,2,86,69,0
68,69,0,0,0,0,0,0,0,0,0,2,73,0,0,0,0,0,0,0,0,0,0,0,0,0,73,2,2,2,0
68,69,0,0,69,0,0,0,0,0,0,2,73,73,0,0,0,0,73,73,73,73,73,73,73,73,73,2,0,68,0
68,69,0,0,0,0,0,0,0,0,0,2,66,73,0,0,0,0,73,66,2,83,83,83,2,66,2,2,69,68,69
68,69,0,0,0,0,0,0,0,0,0,0,2,73,0,0,0,0,73,2,0,0,0,0,0,2,0,0,69,68,69
68,0,69,0,0,70,0,75,0,70,0,0,2,73,0,0,0,0,73,2,0,0,0,0,0,2,69,69,0,68,0
68,69,0,0,0,0,0,0,0,0,0,0,2,73,73,0,0,73,73,2,0,69,0,0,69,0,0,0,69,68,0
68,0,0,0,0,0,0,0,0,0,0,0,2,2,66,82,2,66,2,2,0,0,0,69,69,69,0,69,69,68,0
68,69,71,69,69,69,69,0,0,0,0,68,79,0,79,0,2,79,0,79,68,69,0,69,69,69,0,0,0,68,69
68,68,68,68,68,68,68,68,68,68,0,68,0,0,0,0,0,0,69,0,68,0,68,68,68,68,68,68,68,68,0
:endlayer
layer: 9
93,0,0,0,0,0,0,0,93,0,0,0,0,0,0,0,0,0,0,0,0,0,0,0,0,0,0,0,0,0,0
0,0,0,0,0,0,0,0,0,0,0,0,0,2,0,0,0,0,0,2,0,0,0,0,0,2,0,0,0,0,0
0,0,71,0,0,0,0,0,2,0,0,0,0,2,0,0,0,0,0,2,0,0,0,0,0,2,0,0,0,0,0
0,0,0,0,0,2,2,2,2,2,2,2,2,2,2,99,99,99,2,2,2,99,99,99,2,2,2,2,0,0,0
0,0,0,0,0,2,0,0,0,0,0,2,73,73,73,0,0,0,73,73,73,0,0,0,73,73,73,2,0,0,0
0,71,0,0,0,94,0,0,0,0,0,2,73,0,0,0,0,0,101,0,0,0,0,0,0,0,73,2,2,2,0
0,0,0,0,0,2,2,2,2,2,2,2,73,0,0,0,0,0,0,0,0,0,0,0,0,0,73,2,96,0,0
0,0,0,0,0,2,2,73,73,73,73,73,73,0,0,0,0,0,0,0,0,0,0,0,0,0,0,83,0,0,0
0,0,0,0,0,2,73,0,0,0,0,0,73,0,0,0,0,0,0,0,0,0,0,0,0,0,0,83,0,0,0
0,0,0,0,0,2,73,95,66,96,0,0,97,0,0,0,0,0,0,0,0,0,0,0,0,0,0,83,0,0,0
0,0,0,0,0,2,73,66,66,66,73,73,73,0,0,0,0,0,0,0,0,0,0,0,0,0,0,83,0,0,0
93,0,0,0,0,0,2,73,73,73,2,66,73,0,0,0,0,0,0,0,0,0,0,0,0,0,0,83,0,0,0
0,0,71,0,0,0,0,2,2,2,0,2,73,0,0,0,0,0,0,0,0,0,0,0,0,0,73,2,96,0,0
0,0,0,0,0,0,0,0,0,0,0,2,73,0,0,0,0,0,100,0,0,0,0,0,0,0,73,2,2,2,0
0,0,0,0,0,0,0,0,0,0,0,2,73,73,0,0,0,0,73,73,73,0,0,0,73,73,73,2,0,0,0
0,0,0,0,0,0,0,0,0,0,0,2,2,73,0,0,0,0,73,66,2,99,99,99,2,66,2,2,0,0,0
0,0,0,0,0,0,0,0,0,0,0,0,2,73,0,0,0,0,73,2,0,0,0,0,0,2,0,0,0,0,0
0,0,0,0,0,0,0,0,0,0,0,0,2,73,0,0,0,0,73,2,0,0,0,0,0,2,0,0,0,0,0
0,0,0,0,0,0,0,0,0,0,0,0,2,73,73,0,0,73,73,2,0,0,0,0,0,0,0,0,0,0,0
0,0,0,0,0,0,0,0,0,0,0,0,2,2,66,98,99,66,2,2,96,0,0,0,0,0,0,0,0,0,0
0,0,71,0,0,0,0,0,0,0,0,0,79,22,79,0,99,79,22,79,0,0,0,0,0,0,0,0,0,0,0
0,0,0,0,0,0,0,0,0,93,0,0,0,0,0,0,0,0,0,0,0,0,0,0,0,0,0,0,0,0,0
:endlayer
layer: 10
102,102,102,102,0,0,0,0,0,0,0,0,0,100,0,0,0,0,0,100,0,0,0,0,0,100,0,0,0,0,0
102,102,102,102,0,0,0,0,0,0,0,0,0,2,0,0,0,0,0,2,0,0,0,0,0,2,0,0,0,0,0
102,102,71,102,102,0,0,0,2,0,0,0,0,2,0,0,0,0,0,2,0,0,0,0,0,2,0,100,0,0,0
102,102,102,0,0,2,2,2,2,2,2,2,2,2,2,99,105,99,2,2,2,99,105,99,2,2,2,2,96,0,0
102,102,0,0,0,2,2,2,0,0,0,2,73,73,73,0,0,0,73,73,73,0,0,0,73,73,73,2,0,0,0
0,71,0,0,0,2,2,2,0,0,0,2,73,0,101,0,0,0,0,101,0,0,0,0,0,0,73,2,2,2,96
0,0,0,0,0,2,2,2,2,2,2,2,73,0,0,0,0,0,0,0,0,0,0,0,0,103,73,2,0,0,0
0,0,0,0,0,2,2,73,73,73,73,73,73,0,0,0,0,0,0,0,0,0,0,0,0,0,0,99,0,0,0
0,0,0,0,103,2,73,0,0,0,0,0,73,0,0,0,0,0,0,0,0,0,0,0,0,0,0,99,0,0,0
0,0,0,0,0,2,73,0,66,0,0,0,73,0,0,0,0,0,0,0,0,0,106,0,0,0,0,107,0,0,0
0,0,0,0,103,2,73,0,104,66,73,73,73,0,0,0,0,0,0,0,0,0,0,0,0,0,0,99,0,0,0
0,0,0,0,0,103,2,73,73,73,2,66,73,96,0,0,0,0,0,0,0,0,0,0,0,0,0,99,0,0,0
0,0,71,0,0,0,101,2,2,2,0,2,73,0,0,0,0,0,0,0,0,0,0,0,0,103,73,2,0,0,0
0,0,0,0,0,0,0,101,0,101,0,2,73,0,0,0,0,0,0,100,0,0,0,0,0,0,73,2,2,2,96
0,0,0,0,0,0,0,0,0,0,0,2,73,73,0,0,0,0,73,73,73,0,0,0,73,73,73,2,0,0,0
0,0,0,0,0,0,0,0,0,0,103,2,2,73,0,0,0,0,73,66,2,99,105,99,2,66,2,2,96,0,0
0,0,0,0,0,0,0,0,0,0,0,101,2,73,0,0,0,103,73,2,0,0,0,0,0,2,0,101,0,0,0
0,0,0,0,0,0,0,0,0,0,0,0,2,73,0,0,0,0,73,2,0,0,0,0,0,2,0,0,0,0,0
0,0,0,0,0,0,0,0,0,0,0,0,2,73,73,0,0,73,73,2,0,0,0,0,0,101,0,0,0,0,0
0,0,0,0,0,0,0,0,0,0,0,0,2,2,2,2,2,2,2,2,0,0,0,0,0,0,0,0,0,0,0
0,0,71,0,0,0,0,0,0,0,0,0,79,22,79,2,2,79,22,79,0,0,0,0,0,0,0,0,0,0,0
0,0,0,0,0,0,0,0,0,0,0,0,0,0,0,0,0,0,0,0,0,0,0,0,0,0,0,0,0,0,0
:endlayer
layer: 11
0,102,102,102,0,0,0,0,0,0,0,0,0,0,0,0,0,0,0,0,0,0,0,0,0,0,0,0,0,0,0
102,102,102,102,102,0,0,0,0,0,0,0,0,2,0,0,0,0,0,2,0,0,0,0,0,2,0,0,0,0,0
102,102,71,102,102,0,0,0,25,0,0,0,0,2,0,0,0,0,0,2,0,0,0,0,0,2,0,0,0,0,0
102,102,102,102,102,23,2,2,2,2,2,2,2,2,2,99,105,99,2,2,2,99,105,99,2,2,2,2,0,0,0
102,102,102,102,0,23,2,2,2,2,2,2,73,73,73,0,0,0,73,73,73,0,0,0,73,73,73,2,0,0,0
102,71,102,102,0,23,2,2,2,2,2,2,73,0,0,0,0,0,0,0,0,0,0,0,0,0,73,2,2,2,0
102,102,102,102,0,23,2,2,2,2,2,2,73,0,0,0,0,0,0,0,0,0,0,0,0,0,73,2,0,0,0
102,102,102,102,0,23,2,73,73,73,2,73,73,0,0,0,0,0,0,0,0,0,0,0,0,0,0,105,0,0,0
0,0,0,0,0,2,73,0,0,66,73,73,73,0,0,0,0,0,0,0,0,0,0,0,0,0,0,99,0,0,0
0,0,0,0,0,2,73,0,66,108,73,73,73,0,0,0,0,0,0,0,0,0,112,0,0,0,0,107,0,0,0
0,102,102,102,102,2,73,0,0,0,73,73,73,0,0,0,0,0,0,0,0,0,0,0,0,0,0,99,0,0,0
102,102,102,102,102,0,2,73,73,73,2,66,73,0,0,0,0,0,0,0,0,0,0,0,0,0,0,105,0,0,0
102,102,71,102,102,0,0,2,2,2,0,2,73,0,0,0,0,0,0,0,0,0,0,0,0,0,73,2,0,0,0
102,102,102,102,102,0,0,0,0,0,0,2,73,0,0,0,0,0,0,0,0,0,0,0,0,0,73,2,2,2,0
0,102,102,102,0,0,0,0,0,0,0,66,73,73,0,0,0,0,73,73,73,0,0,0,73,73,73,2,0,0,0
0,0,0,0,0,0,0,0,0,0,0,2,2,73,0,0,0,0,73,66,2,99,105,99,2,66,2,2,0,0,0
0,0,0,0,0,0,0,0,0,0,0,109,66,73,0,0,0,0,73,66,111,0,0,0,0,2,0,0,0,0,0
0,0,0,0,0,0,0,0,0,0,0,109,66,73,0,0,0,0,73,66,111,0,0,0,0,2,0,0,0,0,0
0,0,0,0,0,0,0,0,0,0,0,109,66,73,73,0,0,73,73,66,111,0,0,0,0,0,0,0,0,0,0
0,0,0,0,0,0,0,0,0,0,0,109,2,2,66,2,2,66,2,2,111,0,0,0,0,0,0,0,0,0,0
0,0,71,0,0,0,0,0,0,0,0,109,79,110,0,101,101,0,110,79,111,0,0,0,0,0,0,0,0,0,0
0,0,0,0,0,0,0,0,0,0,0,109,0,0,0,0,0,0,0,0,111,0,0,0,0,0,0,0,0,0,0
:endlayer
layer: 12
0,0,0,0,0,0,0,0,0,0,0,0,0,0,0,0,0,0,0,0,0,0,0,0,0,0,0,0,0,0,0
0,0,102,0,0,0,0,0,0,0,0,0,0,2,0,0,0,0,0,2,0,0,0,0,0,2,0,0,0,0,0
0,102,71,102,0,0,0,0,0,0,0,0,0,2,0,0,0,0,0,2,0,0,0,0,0,2,0,0,0,0,0
102,102,102,102,0,0,23,2,55,2,19,2,2,2,2,99,105,99,2,2,2,99,105,99,2,2,2,2,0,0,0
102,102,102,102,0,0,23,2,0,2,19,2,73,73,73,0,0,0,73,73,73,0,0,0,73,73,73,2,0,0,0
102,71,102,102,0,0,23,2,0,2,19,2,73,0,0,0,0,0,0,0,0,0,0,0,0,0,73,2,2,2,0
102,102,102,102,0,0,23,2,2,2,2,2,73,0,0,0,0,0,0,0,0,0,0,0,0,0,73,2,0,0,0
102,102,102,0,0,0,2,73,73,73,2,66,73,0,0,0,0,0,0,0,0,0,0,0,0,0,0,99,0,0,0
0,0,0,0,0,2,73,66,76,0,73,66,73,0,0,0,0,0,0,0,0,0,0,0,0,0,0,105,0,0,0
0,0,0,0,0,2,73,0,66,0,73,66,73,0,0,0,0,0,0,0,0,0,114,0,0,0,0,107,0,0,0
102,102,102,102,0,2,73,0,0,0,73,66,73,0,0,0,0,0,0,0,0,0,0,0,0,0,0,105,0,0,0
102,102,102,102,102,0,2,73,73,73,2,66,73,0,0,0,0,0,0,0,0,0,0,0,0,0,0,99,0,0,0
102,102,71,102,102,0,0,2,2,2,0,2,73,0,0,0,0,0,0,0,0,0,0,0,0,0,73,2,0,0,0
102,102,102,102,102,0,0,0,0,0,0,2,73,0,0,0,0,0,0,0,0,0,0,0,0,0,73,2,2,2,0
102,102,102,102,0,0,0,0,0,0,0,2,73,73,0,0,0,0,73,73,73,0,0,0,73,73,73,2,0,0,0
0,0,0,0,0,0,0,0,0,0,0,2,2,73,0,0,0,0,73,2,2,99,105,99,2,66,2,2,0,0,0
0,0,0,0,0,0,0,0,0,0,0,0,109,73,0,0,0,0,73,111,0,0,0,0,0,2,0,0,0,0,0
0,0,0,0,0,0,0,0,0,0,0,0,109,73,0,0,0,0,73,111,0,0,0,0,0,2,0,0,0,0,0
0,102,102,102,0,0,0,0,0,0,0,0,109,73,73,73,73,73,73,111,0,0,0,0,0,0,0,0,0,0,0
102,102,102,102,102,0,0,0,0,0,0,0,109,66,66,66,66,66,66,111,0,0,0,0,0,0,0,0,0,0,0
102,102,71,102,102,0,0,0,0,0,0,0,109,79,79,113,113,79,79,111,0,0,0,0,0,0,0,0,0,0,0
102,102,102,102,102,0,0,0,0,0,0,0,109,0,0,0,0,0,0,111,0,0,0,0,0,0,0,0,0,0,0
:endlayer
layer: 13
0,0,0,0,0,0,0,0,0,0,0,0,0,0,0,0,0,0,0,0,0,0,0,0,0,0,0,0,0,0,0
0,0,102,0,0,0,0,0,0,0,0,0,0,2,0,0,0,0,0,2,0,0,0,0,0,2,0,0,0,0,0
0,102,102,102,0,0,0,0,0,0,0,0,0,2,0,0,0,0,0,2,0,0,0,0,0,2,0,0,0,0,0
0,0,102,0,0,0,0,23,2,19,0,2,2,2,2,99,105,99,2,2,2,99,105,99,2,2,2,2,0,0,0
0,102,0,0,0,0,0,23,2,19,0,2,73,73,73,0,0,0,73,73,73,0,0,0,73,73,73,2,0,0,0
102,71,102,0,0,0,0,23,2,19,0,2,73,0,0,0,0,0,0,0,0,0,0,0,0,0,73,2,2,2,0
102,102,102,0,0,0,0,2,2,2,2,2,73,0,0,0,0,0,0,0,0,0,0,0,0,0,73,2,0,0,0
0,0,0,0,0,0,2,73,73,73,2,66,73,0,0,0,0,0,0,0,0,0,0,0,0,0,0,99,0,0,0
0,0,0,0,0,2,73,0,0,0,73,66,73,0,0,0,0,0,0,0,0,0,0,0,0,0,0,99,0,0,0
0,0,0,0,0,2,73,95,66,0,73,66,73,0,0,0,0,0,0,0,0,0,115,0,0,0,0,107,0,0,0
0,0,0,0,0,2,73,66,0,0,73,66,73,0,0,0,0,0,0,0,0,0,0,0,0,0,0,99,0,0,0
0,0,102,102,0,0,2,73,73,73,2,66,73,0,0,0,0,0,0,0,0,0,0,0,0,0,0,99,0,0,0
0,102,71,102,0,0,0,2,2,2,0,2,73,0,0,0,0,0,0,0,0,0,0,0,0,0,73,2,0,0,0
0,102,102,0,0,0,0,0,0,0,0,2,73,0,0,0,0,0,0,0,0,0,0,0,0,0,73,2,2,2,0
0,0,0,0,0,0,0,0,0,0,0,2,73,73,73,73,73,73,73,73,73,0,0,0,73,73,73,2,0,0,0
0,0,0,0,0,0,0,0,0,0,0,2,2,2,73,73,73,73,2,2,2,99,105,99,2,66,2,2,0,0,0
0,0,0,0,0,0,0,0,0,0,0,0,0,109,73,73,73,73,111,0,0,0,0,0,0,2,0,0,0,0,0
0,0,0,0,0,0,0,0,0,0,0,0,0,109,73,73,73,73,111,0,0,0,0,0,0,2,0,0,0,0,0
102,102,102,102,102,0,0,0,0,0,0,0,0,109,73,73,73,73,111,0,0,0,0,0,0,0,0,0,0,0,0
102,102,102,102,102,0,0,0,0,0,0,0,0,109,2,2,2,2,111,0,0,0,0,0,0,0,0,0,0,0,0
102,102,71,102,102,0,0,0,0,0,0,0,0,109,83,83,83,83,111,0,0,0,0,0,0,0,0,0,0,0,0
102,102,102,102,102,0,0,0,0,0,0,0,0,109,0,0,0,0,111,0,0,0,0,0,0,0,0,0,0,0,0
:endlayer
layer: 14
0,0,0,0,0,0,0,0,0,0,0,0,0,0,0,0,0,0,0,0,0,0,0,0,0,0,0,0,0,0,0
0,0,0,0,0,0,0,0,0,0,0,0,0,25,0,0,0,0,0,25,0,0,0,0,0,25,0,0,0,0,0
0,0,0,0,0,0,0,0,0,0,0,0,0,2,0,0,0,0,0,2,0,0,0,0,0,2,0,0,0,0,0
0,0,0,0,0,0,0,0,56,0,0,2,2,2,2,105,105,105,2,2,66,105,105,105,2,2,2,2,0,0,0
0,102,0,0,0,0,0,0,56,0,0,2,73,73,73,0,0,0,73,73,73,0,0,0,73,73,73,2,0,0,0
102,102,102,0,0,0,0,0,56,0,0,2,73,0,0,0,0,0,0,0,0,0,0,0,0,0,73,2,2,19,0
0,102,0,0,0,0,0,79,79,79,0,2,73,0,0,0,0,0,0,0,0,0,0,0,0,0,73,2,0,0,0
0,0,0,0,0,0,79,73,73,73,79,66,73,0,0,0,0,0,0,0,0,0,0,0,0,0,0,99,0,0,0
0,0,0,0,0,79,73,0,0,0,73,66,73,0,0,0,0,0,0,0,0,0,0,0,0,0,0,99,0,0,0
0,0,0,0,0,79,73,0,66,0,73,66,73,0,0,0,0,0,0,0,0,0,116,0,0,0,0,107,0,0,0
0,0,0,0,0,79,73,0,104,66,73,66,73,0,0,0,0,0,0,0,0,0,0,0,0,0,0,99,0,0,0
0,0,102,0,0,0,79,73,73,73,79,66,73,0,0,0,0,0,0,0,0,0,0,0,0,0,0,99,0,0,0
0,102,102,102,0,0,0,79,79,79,0,2,73,0,0,0,0,0,0,0,0,0,0,0,0,0,73,2,0,0,0
0,0,102,0,0,0,0,0,0,0,0,2,73,0,0,0,0,0,0,0,0,0,0,0,0,0,73,2,2,19,0
0,0,0,0,0,0,0,0,0,0,0,2,73,73,73,73,73,73,73,73,73,0,0,0,73,73,73,2,0,0,0
0,0,0,0,0,0,0,0,0,0,0,2,2,2,2,66,66,2,2,2,2,105,105,105,2,66,2,2,0,0,0
0,0,0,0,0,0,0,0,0,0,0,0,0,0,109,65,65,111,0,0,0,0,0,0,0,2,0,0,0,0,0
0,0,0,0,0,0,0,0,0,0,0,0,0,0,109,65,65,111,0,0,0,0,0,0,0,17,0,0,0,0,0
0,0,0,0,0,0,0,0,0,0,0,0,0,0,109,65,65,111,0,0,0,0,0,0,0,0,0,0,0,0,0
0,0,102,0,0,0,0,0,0,0,0,0,0,0,109,79,79,111,0,0,0,0,0,0,0,0,0,0,0,0,0
0,102,71,102,0,0,0,0,0,0,0,0,0,0,109,79,79,111,0,0,0,0,0,0,0,0,0,0,0,0,0
0,102,102,0,0,0,0,0,0,0,0,0,0,0,109,0,0,111,0,0,0,0,0,0,0,0,0,0,0,0,0
:endlayer
layer: 15
0,0,0,0,0,0,0,0,0,0,0,0,0,0,0,0,0,0,0,0,0,0,0,0,0,0,0,0,0,0,0
0,0,0,0,0,0,0,0,0,0,0,0,0,0,0,0,0,0,0,0,0,0,0,0,0,0,0,0,0,0,0
0,0,0,0,0,0,0,0,0,0,0,0,0,2,0,0,0,0,0,2,0,0,0,0,0,2,0,0,0,0,0
0,0,0,0,0,0,0,0,0,0,0,2,2,2,2,99,105,99,2,2,2,99,105,99,2,2,2,2,0,0,0
0,0,0,0,0,0,0,0,0,0,0,2,66,73,73,0,0,0,73,73,73,0,0,0,73,73,73,2,0,0,0
0,0,0,0,0,0,0,0,0,0,0,2,73,0,0,0,0,0,0,0,0,0,0,0,0,0,73,2,2,0,0
0,0,0,0,0,0,0,2,2,2,0,2,73,0,0,0,0,0,0,0,0,0,0,0,0,0,73,2,0,0,0
0,0,0,0,0,0,2,73,73,73,2,66,73,0,0,0,0,0,0,0,0,0,0,0,0,0,0,99,0,0,0
0,0,0,0,0,2,73,0,0,66,73,66,73,0,0,0,0,0,0,0,0,0,0,0,0,0,0,105,0,0,0
0,0,0,0,0,2,73,0,66,108,73,66,73,0,0,0,0,0,0,0,0,0,0,0,0,0,0,107,0,0,0
0,0,0,0,0,2,73,0,0,0,73,66,73,0,0,0,0,0,0,0,0,0,0,0,0,0,0,105,0,0,0
0,0,0,0,0,0,2,73,73,73,2,66,73,0,0,0,0,0,0,0,0,0,0,0,0,0,0,99,0,0,0
0,0,0,0,0,0,0,2,2,2,0,2,73,0,0,0,0,0,0,0,0,0,0,0,0,0,73,2,0,0,0
0,0,0,0,0,0,0,0,0,0,0,2,73,0,0,0,0,0,0,0,0,0,0,0,0,0,73,2,2,0,0
0,0,0,0,0,0,0,0,0,0,0,2,73,73,73,73,73,73,73,73,73,0,0,0,73,73,73,2,0,0,0
0,0,0,0,0,0,0,0,0,0,0,2,2,2,2,2,2,2,2,2,2,99,105,99,2,66,2,2,0,0,0
0,0,0,0,0,0,0,0,0,0,0,0,0,0,0,109,111,0,0,0,0,0,0,0,0,2,0,0,0,0,0
0,0,0,0,0,0,0,0,0,0,0,0,0,0,0,109,111,0,0,0,0,0,0,0,0,0,0,0,0,0,0
0,0,0,0,0,0,0,0,0,0,0,0,0,0,0,109,111,0,0,0,0,0,0,0,0,0,0,0,0,0,0
0,0,102,0,0,0,0,0,0,0,0,0,0,0,0,109,111,0,0,0,0,0,0,0,0,0,0,0,0,0,0
0,102,102,102,0,0,0,0,0,0,0,0,0,0,0,109,111,0,0,0,0,0,0,0,0,0,0,0,0,0,0
0,0,102,0,0,0,0,0,0,0,0,0,0,0,0,109,111,0,0,0,0,0,0,0,0,0,0,0,0,0,0
:endlayer
layer: 16
0,0,0,0,0,0,0,0,0,0,0,0,0,0,0,0,0,0,0,0,0,0,0,0,0,0,0,0,0,0,0
0,0,0,0,0,0,0,0,0,0,0,0,0,0,0,0,0,0,0,0,0,0,0,0,0,0,0,0,0,0,0
0,0,0,0,0,0,0,0,0,0,0,0,0,25,0,0,0,0,0,25,0,0,0,0,0,25,0,0,0,0,0
0,0,0,0,0,0,0,0,0,0,0,2,2,2,2,2,2,2,2,2,2,2,2,2,2,2,2,2,0,0,0
0,0,0,0,0,0,0,0,0,0,0,2,73,73,73,73,117,73,73,73,73,73,119,73,73,73,73,2,0,0,0
0,0,0,0,0,0,0,0,0,0,0,2,73,0,0,0,0,0,0,0,0,0,0,0,0,0,73,2,19,0,0
0,0,0,0,0,0,0,2,2,2,0,2,73,0,0,0,0,0,0,0,0,0,0,0,0,0,73,2,0,0,0
0,0,0,0,0,0,2,73,73,73,2,66,73,0,0,0,0,0,0,0,0,0,0,0,0,0,0,107,0,0,0
0,0,0,0,0,2,73,66,76,0,73,66,73,0,0,0,0,0,0,0,0,0,0,0,0,0,0,107,0,0,0
0,0,0,0,0,2,73,0,66,0,73,66,73,0,0,0,0,0,0,0,0,0,0,0,0,0,0,107,0,0,0
0,0,0,0,0,2,73,0,0,0,73,66,73,0,0,0,0,0,0,0,0,0,0,0,0,0,0,107,0,0,0
0,0,0,0,0,0,2,73,73,73,2,66,73,0,0,0,0,0,0,0,0,0,0,0,0,0,0,107,0,0,0
0,0,0,0,0,0,0,2,2,2,0,2,73,0,0,0,0,0,0,0,0,0,0,0,0,0,73,2,0,0,0
0,0,0,0,0,0,0,0,0,0,0,2,73,0,0,0,0,0,0,0,0,0,0,0,0,0,73,2,19,0,0
0,0,0,0,0,0,0,0,0,0,0,2,73,73,73,73,73,73,73,73,73,73,118,73,73,73,73,2,0,0,0
0,0,0,0,0,0,0,0,0,0,0,2,2,2,2,2,2,2,2,2,2,2,2,2,2,66,2,2,0,0,0
0,0,0,0,0,0,0,0,0,0,0,0,0,0,0,0,0,0,0,0,0,0,0,0,0,17,0,0,0,0,0
0,0,0,0,0,0,0,0,0,0,0,0,0,0,0,0,0,0,0,0,0,0,0,0,0,0,0,0,0,0,0
0,0,0,0,0,0,0,0,0,0,0,0,0,0,0,0,0,0,0,0,0,0,0,0,0,0,0,0,0,0,0
0,0,0,0,0,0,0,0,0,0,0,0,0,0,0,0,0,0,0,0,0,0,0,0,0,0,0,0,0,0,0
0,0,0,0,0,0,0,0,0,0,0,0,0,0,0,0,0,0,0,0,0,0,0,0,0,0,0,0,0,0,0
0,0,0,0,0,0,0,0,0,0,0,0,0,0,0,0,0,0,0,0,0,0,0,0,0,0,0,0,0,0,0
:endlayer
layer: 17
0,0,0,0,0,0,0,0,0,0,0,0,0,0,0,0,0,0,0,0,0,0,0,0,0,0,0,0,0,0,0
0,0,0,0,0,0,0,0,0,0,0,0,0,0,0,0,0,0,0,0,0,0,0,0,0,0,0,0,0,0,0
0,0,0,0,0,0,0,0,0,0,0,25,121,121,121,121,121,121,121,121,121,121,121,121,121,121,121,25,0,0,0
0,0,0,0,0,0,0,0,0,0,0,2,2,66,66,66,2,66,66,66,66,66,2,66,66,66,2,2,0,0,0
0,0,0,0,0,0,0,0,0,0,0,2,73,73,73,73,73,73,73,73,73,73,73,73,73,73,73,2,0,0,0
0,0,0,0,0,0,0,0,0,0,0,2,73,0,0,0,0,0,0,0,0,0,0,0,0,0,73,2,0,0,0
0,0,0,0,0,0,0,2,2,2,0,2,73,0,0,0,0,0,0,0,0,0,0,0,0,0,73,2,0,0,0
0,0,0,0,0,0,2,73,73,73,2,66,73,0,0,0,0,0,0,0,0,0,0,0,0,0,0,99,0,0,0
0,0,0,0,0,2,73,0,0,0,73,66,73,0,0,0,0,0,0,0,0,0,0,0,0,0,0,105,0,0,0
0,0,0,0,0,2,73,95,66,0,73,66,73,0,0,0,0,0,0,0,0,0,0,0,0,0,0,107,0,0,0
0,0,0,0,0,2,73,66,0,0,73,66,73,0,0,0,0,0,0,0,0,0,0,0,0,0,0,105,0,0,0
0,0,0,0,0,0,2,73,73,73,2,66,73,0,0,0,0,0,0,0,0,0,0,0,0,0,0,99,0,0,0
0,0,0,0,0,0,0,2,2,2,0,2,73,0,0,0,0,0,0,0,0,0,0,0,0,0,73,2,0,0,0
0,0,0,0,0,0,0,0,0,0,0,2,73,0,0,0,0,0,0,0,0,0,0,0,0,0,73,2,0,0,0
0,0,0,0,0,0,0,0,0,0,0,2,73,73,73,73,73,73,73,73,73,73,73,73,73,73,73,2,0,0,0
0,0,0,0,0,0,0,0,0,0,0,2,2,66,66,66,66,66,66,66,66,66,2,66,66,66,2,2,0,0,0
0,0,0,0,0,0,0,0,0,0,0,17,120,120,120,120,120,120,120,120,120,120,120,120,120,120,120,17,0,0,0
0,0,0,0,0,0,0,0,0,0,0,0,0,0,0,0,0,0,0,0,0,0,0,0,0,0,0,0,0,0,0
0,0,0,0,0,0,0,0,0,0,0,0,0,0,0,0,0,0,0,0,0,0,0,0,0,0,0,0,0,0,0
0,0,0,0,0,0,0,0,0,0,0,0,0,0,0,0,0,0,0,0,0,0,0,0,0,0,0,0,0,0,0
0,0,0,0,0,0,0,0,0,0,0,0,0,0,0,0,0,0,0,0,0,0,0,0,0,0,0,0,0,0,0
0,0,0,0,0,0,0,0,0,0,0,0,0,0,0,0,0,0,0,0,0,0,0,0,0,0,0,0,0,0,0
:endlayer
layer: 18
0,0,0,0,0,0,0,0,0,0,0,0,0,0,0,0,0,0,0,0,0,0,0,0,0,0,0,0,0,0,0
0,0,0,0,0,0,0,0,0,0,0,0,0,0,0,0,0,0,0,0,0,0,0,0,0,0,0,0,0,0,0
0,0,0,0,0,0,0,0,0,0,0,0,0,0,0,0,0,0,0,0,0,0,0,0,0,0,0,0,0,0,0
0,0,0,0,0,0,0,0,0,0,0,2,121,121,121,121,121,121,121,121,121,121,121,121,121,121,121,2,0,0,0
0,0,0,0,0,0,0,0,0,0,0,2,73,73,73,73,73,73,73,73,73,73,73,73,73,73,73,2,0,0,0
0,0,0,0,0,0,0,0,0,0,0,2,73,0,0,0,0,0,0,0,0,0,0,0,0,0,73,2,0,0,0
0,0,0,0,0,0,0,2,2,2,0,2,73,0,0,0,0,0,0,0,0,0,0,0,0,0,73,2,0,0,0
0,0,0,0,0,0,2,73,73,73,2,66,73,0,0,0,0,0,0,0,0,0,0,0,0,0,0,99,0,0,0
0,0,0,0,0,2,73,0,0,0,73,66,73,0,0,0,0,0,0,0,0,0,0,0,0,0,0,99,0,0,0
0,0,0,0,0,2,73,0,66,0,73,66,73,0,0,0,0,0,0,0,0,0,0,0,0,0,0,107,0,0,0
0,0,0,0,0,2,73,0,104,66,73,66,73,0,0,0,0,0,0,0,0,0,0,0,0,0,0,99,0,0,0
0,0,0,0,0,0,2,73,73,73,2,66,73,0,0,0,0,0,0,0,0,0,0,0,0,0,0,99,0,0,0
0,0,0,0,0,0,0,2,2,2,0,2,73,0,0,0,0,0,0,0,0,0,0,0,0,0,73,2,0,0,0
0,0,0,0,0,0,0,0,0,0,0,2,73,0,0,0,0,0,0,0,0,0,0,0,0,0,73,2,0,0,0
0,0,0,0,0,0,0,0,0,0,0,2,73,73,73,73,73,73,73,73,73,73,73,73,73,73,73,2,0,0,0
0,0,0,0,0,0,0,0,0,0,0,2,120,120,120,120,120,120,120,120,120,120,120,120,120,120,120,2,0,0,0
0,0,0,0,0,0,0,0,0,0,0,0,0,0,0,0,0,0,0,0,0,0,0,0,0,0,0,0,0,0,0
0,0,0,0,0,0,0,0,0,0,0,0,0,0,0,0,0,0,0,0,0,0,0,0,0,0,0,0,0,0,0
0,0,0,0,0,0,0,0,0,0,0,0,0,0,0,0,0,0,0,0,0,0,0,0,0,0,0,0,0,0,0
0,0,0,0,0,0,0,0,0,0,0,0,0,0,0,0,0,0,0,0,0,0,0,0,0,0,0,0,0,0,0
0,0,0,0,0,0,0,0,0,0,0,0,0,0,0,0,0,0,0,0,0,0,0,0,0,0,0,0,0,0,0
0,0,0,0,0,0,0,0,0,0,0,0,0,0,0,0,0,0,0,0,0,0,0,0,0,0,0,0,0,0,0
:endlayer
layer: 19
0,0,0,0,0,0,0,0,0,0,0,0,0,0,0,0,0,0,0,0,0,0,0,0,0,0,0,0,0,0,0
0,0,0,0,0,0,0,0,0,0,0,0,0,0,0,0,0,0,0,0,0,0,0,0,0,0,0,0,0,0,0
0,0,0,0,0,0,0,0,0,0,0,0,0,0,0,0,0,0,0,0,0,0,0,0,0,0,0,0,0,0,0
0,0,0,0,0,0,0,0,0,0,0,0,0,0,0,0,0,0,0,0,0,0,0,0,0,0,0,0,0,0,0
0,0,0,0,0,0,0,0,0,0,0,2,121,121,121,121,121,121,121,121,121,121,121,121,121,121,121,2,0,0,0
0,0,0,0,0,0,0,0,0,0,0,2,73,0,0,0,65,0,0,0,0,0,65,0,0,0,73,2,0,0,0
0,0,0,0,0,0,0,2,2,2,0,2,73,0,0,0,65,0,0,0,0,0,65,0,0,0,73,2,0,0,0
0,0,0,0,0,0,2,73,73,73,2,66,73,0,0,0,65,0,0,0,0,0,65,0,0,0,73,2,0,0,0
0,0,0,0,0,2,73,0,0,66,73,66,73,0,0,0,65,0,0,0,0,0,65,0,0,0,0,105,0,0,0
0,0,0,0,0,2,73,0,66,108,73,66,73,0,0,0,65,0,0,0,0,0,65,0,0,0,0,107,0,0,0
0,0,0,0,0,2,73,0,0,0,73,66,73,0,0,0,65,0,0,0,0,0,65,0,0,0,0,105,0,0,0
0,0,0,0,0,0,2,73,73,73,2,66,73,0,0,0,65,0,0,0,0,0,65,0,0,0,73,2,0,0,0
0,0,0,0,0,0,0,2,2,2,0,2,73,0,0,0,65,0,0,0,0,0,65,0,0,0,73,2,0,0,0
0,0,0,0,0,0,0,0,0,0,0,2,73,0,0,0,65,0,0,0,0,0,65,0,0,0,73,2,0,0,0
0,0,0,0,0,0,0,0,0,0,0,2,120,120,120,120,120,120,120,120,120,120,120,120,120,120,120,2,0,0,0
0,0,0,0,0,0,0,0,0,0,0,0,0,0,0,0,0,0,0,0,0,0,0,0,0,0,0,0,0,0,0
0,0,0,0,0,0,0,0,0,0,0,0,0,0,0,0,0,0,0,0,0,0,0,0,0,0,0,0,0,0,0
0,0,0,0,0,0,0,0,0,0,0,0,0,0,0,0,0,0,0,0,0,0,0,0,0,0,0,0,0,0,0
0,0,0,0,0,0,0,0,0,0,0,0,0,0,0,0,0,0,0,0,0,0,0,0,0,0,0,0,0,0,0
0,0,0,0,0,0,0,0,0,0,0,0,0,0,0,0,0,0,0,0,0,0,0,0,0,0,0,0,0,0,0
0,0,0,0,0,0,0,0,0,0,0,0,0,0,0,0,0,0,0,0,0,0,0,0,0,0,0,0,0,0,0
0,0,0,0,0,0,0,0,0,0,0,0,0,0,0,0,0,0,0,0,0,0,0,0,0,0,0,0,0,0,0
:endlayer
layer: 20
0,0,0,0,0,0,0,0,0,0,0,0,0,0,0,0,0,0,0,0,0,0,0,0,0,0,0,0,0,0,0
0,0,0,0,0,0,0,0,0,0,0,0,0,0,0,0,0,0,0,0,0,0,0,0,0,0,0,0,0,0,0
0,0,0,0,0,0,0,0,0,0,0,0,0,0,0,0,0,0,0,0,0,0,0,0,0,0,0,0,0,0,0
0,0,0,0,0,0,0,0,0,0,0,0,0,0,0,0,0,0,0,0,0,0,0,0,0,0,0,0,0,0,0
0,0,0,0,0,0,0,0,0,0,0,0,0,0,0,0,0,0,0,0,0,0,0,0,0,0,0,0,0,0,0
0,0,0,0,0,0,0,0,0,0,0,2,121,121,121,121,121,121,121,121,121,121,121,121,121,121,121,2,0,0,0
0,0,0,0,0,0,0,2,2,2,0,2,73,0,0,0,0,0,0,0,0,0,0,0,0,0,73,2,0,0,0
0,0,0,0,0,0,2,73,73,73,2,66,73,0,0,0,0,0,0,0,0,0,0,0,0,0,73,2,0,0,0
0,0,0,0,0,2,73,66,76,0,73,66,73,0,0,0,0,0,0,0,0,0,0,0,0,0,73,2,0,0,0
0,0,0,0,0,2,73,0,66,0,73,66,73,0,0,0,122,0,0,0,0,0,123,0,0,0,124,2,0,0,0
0,0,0,0,0,2,73,0,0,0,73,66,73,0,0,0,0,0,0,0,0,0,0,0,0,0,73,2,0,0,0
0,0,0,0,0,0,2,73,73,73,2,66,73,0,0,0,0,0,0,0,0,0,0,0,0,0,73,2,0,0,0
0,0,0,0,0,0,0,2,2,2,0,2,73,0,0,0,0,0,0,0,0,0,0,0,0,0,73,2,0,0,0
0,0,0,0,0,0,0,0,0,0,0,2,120,120,120,120,120,120,120,120,120,120,120,120,120,120,120,2,0,0,0
0,0,0,0,0,0,0,0,0,0,0,0,0,0,0,0,0,0,0,0,0,0,0,0,0,0,0,0,0,0,0
0,0,0,0,0,0,0,0,0,0,0,0,0,0,0,0,0,0,0,0,0,0,0,0,0,0,0,0,0,0,0
0,0,0,0,0,0,0,0,0,0,0,0,0,0,0,0,0,0,0,0,0,0,0,0,0,0,0,0,0,0,0
0,0,0,0,0,0,0,0,0,0,0,0,0,0,0,0,0,0,0,0,0,0,0,0,0,0,0,0,0,0,0
0,0,0,0,0,0,0,0,0,0,0,0,0,0,0,0,0,0,0,0,0,0,0,0,0,0,0,0,0,0,0
0,0,0,0,0,0,0,0,0,0,0,0,0,0,0,0,0,0,0,0,0,0,0,0,0,0,0,0,0,0,0
0,0,0,0,0,0,0,0,0,0,0,0,0,0,0,0,0,0,0,0,0,0,0,0,0,0,0,0,0,0,0
0,0,0,0,0,0,0,0,0,0,0,0,0,0,0,0,0,0,0,0,0,0,0,0,0,0,0,0,0,0,0
:endlayer
layer: 21
0,0,0,0,0,0,0,0,0,0,0,0,0,0,0,0,0,0,0,0,0,0,0,0,0,0,0,0,0,0,0
0,0,0,0,0,0,0,0,0,0,0,0,0,0,0,0,0,0,0,0,0,0,0,0,0,0,0,0,0,0,0
0,0,0,0,0,0,0,0,0,0,0,0,0,0,0,0,0,0,0,0,0,0,0,0,0,0,0,0,0,0,0
0,0,0,0,0,0,0,0,0,0,0,0,0,0,0,0,0,0,0,0,0,0,0,0,0,0,0,0,0,0,0
0,0,0,0,0,0,0,0,0,0,0,0,0,0,0,0,0,0,0,0,0,0,0,0,0,0,0,0,0,0,0
0,0,0,0,0,0,0,0,0,0,0,0,0,0,0,0,0,0,0,0,0,0,0,0,0,0,0,0,0,0,0
0,0,0,0,0,0,0,2,2,2,0,2,121,121,121,121,121,121,121,121,121,121,121,121,121,121,121,2,0,0,0
0,0,0,0,0,0,2,73,73,73,2,66,73,0,0,0,0,0,0,0,0,0,0,0,0,0,73,2,0,0,0
0,0,0,0,0,2,73,0,0,0,73,66,73,0,0,0,0,0,0,0,0,0,0,0,0,0,73,2,0,0,0
0,0,0,0,0,2,73,95,66,0,73,66,73,0,0,0,0,0,0,0,0,0,0,0,0,0,73,2,0,0,0
0,0,0,0,0,2,73,66,0,0,73,66,73,0,0,0,0,0,0,0,0,0,0,0,0,0,73,2,0,0,0
0,0,0,0,0,0,2,73,73,73,2,66,73,0,0,0,0,0,0,0,0,0,0,0,0,0,73,2,0,0,0
0,0,0,0,0,0,0,2,2,2,0,2,120,120,120,120,120,120,120,120,120,120,120,120,120,120,120,2,0,0,0
0,0,0,0,0,0,0,0,0,0,0,0,0,0,0,0,0,0,0,0,0,0,0,0,0,0,0,0,0,0,0
0,0,0,0,0,0,0,0,0,0,0,0,0,0,0,0,0,0,0,0,0,0,0,0,0,0,0,0,0,0,0
0,0,0,0,0,0,0,0,0,0,0,0,0,0,0,0,0,0,0,0,0,0,0,0,0,0,0,0,0,0,0
0,0,0,0,0,0,0,0,0,0,0,0,0,0,0,0,0,0,0,0,0,0,0,0,0,0,0,0,0,0,0
0,0,0,0,0,0,0,0,0,0,0,0,0,0,0,0,0,0,0,0,0,0,0,0,0,0,0,0,0,0,0
0,0,0,0,0,0,0,0,0,0,0,0,0,0,0,0,0,0,0,0,0,0,0,0,0,0,0,0,0,0,0
0,0,0,0,0,0,0,0,0,0,0,0,0,0,0,0,0,0,0,0,0,0,0,0,0,0,0,0,0,0,0
0,0,0,0,0,0,0,0,0,0,0,0,0,0,0,0,0,0,0,0,0,0,0,0,0,0,0,0,0,0,0
0,0,0,0,0,0,0,0,0,0,0,0,0,0,0,0,0,0,0,0,0,0,0,0,0,0,0,0,0,0,0
:endlayer
layer: 22
0,0,0,0,0,0,0,0,0,0,0,0,0,0,0,0,0,0,0,0,0,0,0,0,0,0,0,0,0,0,0
0,0,0,0,0,0,0,0,0,0,0,0,0,0,0,0,0,0,0,0,0,0,0,0,0,0,0,0,0,0,0
0,0,0,0,0,0,0,0,0,0,0,0,0,0,0,0,0,0,0,0,0,0,0,0,0,0,0,0,0,0,0
0,0,0,0,0,0,0,0,0,0,0,0,0,0,0,0,0,0,0,0,0,0,0,0,0,0,0,0,0,0,0
0,0,0,0,0,0,0,0,0,0,0,0,0,0,0,0,0,0,0,0,0,0,0,0,0,0,0,0,0,0,0
0,0,0,0,0,0,0,0,0,0,0,0,0,0,0,0,0,0,0,0,0,0,0,0,0,0,0,0,0,0,0
0,0,0,0,0,0,0,79,79,79,0,0,0,0,0,0,0,0,0,0,0,0,0,0,0,0,0,0,0,0,0
0,0,0,0,0,0,79,73,73,73,79,2,121,121,121,121,121,121,121,121,121,121,121,121,121,121,121,2,0,0,0
0,0,0,0,0,79,73,0,0,0,73,2,73,0,0,0,0,0,0,0,0,0,0,0,0,0,73,2,0,0,0
0,0,0,0,0,79,73,0,66,0,73,2,73,0,0,0,0,0,0,0,0,0,0,0,0,0,73,2,0,0,0
0,0,0,0,0,79,73,0,104,66,73,2,73,0,0,0,0,0,0,0,0,0,0,0,0,0,73,2,0,0,0
0,0,0,0,0,0,79,73,73,73,79,2,120,120,120,120,120,120,120,120,120,120,120,120,120,120,120,2,0,0,0
0,0,0,0,0,0,0,79,79,79,0,0,0,0,0,0,0,0,0,0,0,0,0,0,0,0,0,0,0,0,0
0,0,0,0,0,0,0,0,0,0,0,0,0,0,0,0,0,0,0,0,0,0,0,0,0,0,0,0,0,0,0
0,0,0,0,0,0,0,0,0,0,0,0,0,0,0,0,0,0,0,0,0,0,0,0,0,0,0,0,0,0,0
0,0,0,0,0,0,0,0,0,0,0,0,0,0,0,0,0,0,0,0,0,0,0,0,0,0,0,0,0,0,0
0,0,0,0,0,0,0,0,0,0,0,0,0,0,0,0,0,0,0,0,0,0,0,0,0,0,0,0,0,0,0
0,0,0,0,0,0,0,0,0,0,0,0,0,0,0,0,0,0,0,0,0,0,0,0,0,0,0,0,0,0,0
0,0,0,0,0,0,0,0,0,0,0,0,0,0,0,0,0,0,0,0,0,0,0,0,0,0,0,0,0,0,0
0,0,0,0,0,0,0,0,0,0,0,0,0,0,0,0,0,0,0,0,0,0,0,0,0,0,0,0,0,0,0
0,0,0,0,0,0,0,0,0,0,0,0,0,0,0,0,0,0,0,0,0,0,0,0,0,0,0,0,0,0,0
0,0,0,0,0,0,0,0,0,0,0,0,0,0,0,0,0,0,0,0,0,0,0,0,0,0,0,0,0,0,0
:endlayer
layer: 23
0,0,0,0,0,0,0,0,0,0,0,0,0,0,0,0,0,0,0,0,0,0,0,0,0,0,0,0,0,0,0
0,0,0,0,0,0,0,0,0,0,0,0,0,0,0,0,0,0,0,0,0,0,0,0,0,0,0,0,0,0,0
0,0,0,0,0,0,0,0,0,0,0,0,0,0,0,0,0,0,0,0,0,0,0,0,0,0,0,0,0,0,0
0,0,0,0,0,0,0,0,0,0,0,0,0,0,0,0,0,0,0,0,0,0,0,0,0,0,0,0,0,0,0
0,0,0,0,0,0,0,0,0,0,0,0,0,0,0,0,0,0,0,0,0,0,0,0,0,0,0,0,0,0,0
0,0,0,0,0,0,0,0,0,0,0,0,0,0,0,0,0,0,0,0,0,0,0,0,0,0,0,0,0,0,0
0,0,0,0,0,0,0,2,2,2,0,0,0,0,0,0,0,0,0,0,0,0,0,0,0,0,0,0,0,0,0
0,0,0,0,0,0,2,73,73,73,2,0,0,0,0,0,0,0,0,0,0,0,0,0,0,0,0,0,0,0,0
0,0,0,0,0,2,73,0,0,66,73,2,121,121,121,121,121,121,121,121,121,121,121,121,121,121,121,2,0,0,0
0,0,0,0,0,2,73,0,66,108,73,2,65,65,65,65,65,65,65,65,65,65,65,65,65,65,65,2,0,0,0
0,0,0,0,0,2,73,0,0,0,73,2,120,120,120,120,120,120,120,120,120,120,120,120,120,120,120,2,0,0,0
0,0,0,0,0,0,2,73,73,73,2,0,0,0,0,0,0,0,0,0,0,0,0,0,0,0,0,0,0,0,0
0,0,0,0,0,0,0,2,2,2,0,0,0,0,0,0,0,0,0,0,0,0,0,0,0,0,0,0,0,0,0
0,0,0,0,0,0,0,0,0,0,0,0,0,0,0,0,0,0,0,0,0,0,0,0,0,0,0,0,0,0,0
0,0,0,0,0,0,0,0,0,0,0,0,0,0,0,0,0,0,0,0,0,0,0,0,0,0,0,0,0,0,0
0,0,0,0,0,0,0,0,0,0,0,0,0,0,0,0,0,0,0,0,0,0,0,0,0,0,0,0,0,0,0
0,0,0,0,0,0,0,0,0,0,0,0,0,0,0,0,0,0,0,0,0,0,0,0,0,0,0,0,0,0,0
0,0,0,0,0,0,0,0,0,0,0,0,0,0,0,0,0,0,0,0,0,0,0,0,0,0,0,0,0,0,0
0,0,0,0,0,0,0,0,0,0,0,0,0,0,0,0,0,0,0,0,0,0,0,0,0,0,0,0,0,0,0
0,0,0,0,0,0,0,0,0,0,0,0,0,0,0,0,0,0,0,0,0,0,0,0,0,0,0,0,0,0,0
0,0,0,0,0,0,0,0,0,0,0,0,0,0,0,0,0,0,0,0,0,0,0,0,0,0,0,0,0,0,0
0,0,0,0,0,0,0,0,0,0,0,0,0,0,0,0,0,0,0,0,0,0,0,0,0,0,0,0,0,0,0
:endlayer
layer: 24
0,0,0,0,0,0,0,0,0,0,0,0,0,0,0,0,0,0,0,0,0,0,0,0,0,0,0,0,0,0,0
0,0,0,0,0,0,0,0,0,0,0,0,0,0,0,0,0,0,0,0,0,0,0,0,0,0,0,0,0,0,0
0,0,0,0,0,0,0,0,0,0,0,0,0,0,0,0,0,0,0,0,0,0,0,0,0,0,0,0,0,0,0
0,0,0,0,0,0,0,0,0,0,0,0,0,0,0,0,0,0,0,0,0,0,0,0,0,0,0,0,0,0,0
0,0,0,0,0,0,0,0,0,0,0,0,0,0,0,0,0,0,0,0,0,0,0,0,0,0,0,0,0,0,0
0,0,0,0,0,0,0,0,0,0,0,0,0,0,0,0,0,0,0,0,0,0,0,0,0,0,0,0,0,0,0
0,0,0,0,0,0,0,2,2,2,0,0,0,0,0,0,0,0,0,0,0,0,0,0,0,0,0,0,0,0,0
0,0,0,0,0,0,2,65,65,65,2,0,0,0,0,0,0,0,0,0,0,0,0,0,0,0,0,0,0,0,0
0,0,0,0,0,2,65,65,76,0,65,2,0,0,0,0,0,0,0,0,0,0,0,0,0,0,0,0,0,0,0
0,0,0,0,0,2,65,0,65,0,65,2,93,0,0,0,0,0,0,93,0,0,0,0,0,0,93,2,0,0,0
0,0,0,0,0,2,65,0,0,0,65,2,0,0,0,0,0,0,0,0,0,0,0,0,0,0,0,0,0,0,0
0,0,0,0,0,0,2,65,65,65,2,0,0,0,0,0,0,0,0,0,0,0,0,0,0,0,0,0,0,0,0
0,0,0,0,0,0,0,2,2,2,0,0,0,0,0,0,0,0,0,0,0,0,0,0,0,0,0,0,0,0,0
0,0,0,0,0,0,0,0,0,0,0,0,0,0,0,0,0,0,0,0,0,0,0,0,0,0,0,0,0,0,0
0,0,0,0,0,0,0,0,0,0,0,0,0,0,0,0,0,0,0,0,0,0,0,0,0,0,0,0,0,0,0
0,0,0,0,0,0,0,0,0,0,0,0,0,0,0,0,0,0,0,0,0,0,0,0,0,0,0,0,0,0,0
0,0,0,0,0,0,0,0,0,0,0,0,0,0,0,0,0,0,0,0,0,0,0,0,0,0,0,0,0,0,0
0,0,0,0,0,0,0,0,0,0,0,0,0,0,0,0,0,0,0,0,0,0,0,0,0,0,0,0,0,0,0
0,0,0,0,0,0,0,0,0,0,0,0,0,0,0,0,0,0,0,0,0,0,0,0,0,0,0,0,0,0,0
0,0,0,0,0,0,0,0,0,0,0,0,0,0,0,0,0,0,0,0,0,0,0,0,0,0,0,0,0,0,0
0,0,0,0,0,0,0,0,0,0,0,0,0,0,0,0,0,0,0,0,0,0,0,0,0,0,0,0,0,0,0
0,0,0,0,0,0,0,0,0,0,0,0,0,0,0,0,0,0,0,0,0,0,0,0,0,0,0,0,0,0,0
:endlayer
layer: 25
0,0,0,0,0,0,0,0,0,0,0,0,0,0,0,0,0,0,0,0,0,0,0,0,0,0,0,0,0,0,0
0,0,0,0,0,0,0,0,0,0,0,0,0,0,0,0,0,0,0,0,0,0,0,0,0,0,0,0,0,0,0
0,0,0,0,0,0,0,0,0,0,0,0,0,0,0,0,0,0,0,0,0,0,0,0,0,0,0,0,0,0,0
0,0,0,0,0,0,0,0,0,0,0,0,0,0,0,0,0,0,0,0,0,0,0,0,0,0,0,0,0,0,0
0,0,0,0,0,0,0,0,0,0,0,0,0,0,0,0,0,0,0,0,0,0,0,0,0,0,0,0,0,0,0
0,0,0,0,0,0,0,0,0,0,0,0,0,0,0,0,0,0,0,0,0,0,0,0,0,0,0,0,0,0,0
0,0,0,0,0,0,0,2,125,2,0,0,0,0,0,0,0,0,0,0,0,0,0,0,0,0,0,0,0,0,0
0,0,0,0,0,0,2,0,0,0,2,0,0,0,0,0,0,0,0,0,0,0,0,0,0,0,0,0,0,0,0
0,0,0,0,0,2,0,0,0,0,0,2,0,0,0,0,0,0,0,0,0,0,0,0,0,0,0,0,0,0,0
0,0,0,0,0,125,0,0,0,0,0,125,0,0,0,0,0,0,0,0,0,0,0,0,0,0,0,0,0,0,0
0,0,0,0,0,2,0,0,0,0,0,2,0,0,0,0,0,0,0,0,0,0,0,0,0,0,0,0,0,0,0
0,0,0,0,0,0,2,0,0,0,2,0,0,0,0,0,0,0,0,0,0,0,0,0,0,0,0,0,0,0,0
0,0,0,0,0,0,0,2,125,2,0,0,0,0,0,0,0,0,0,0,0,0,0,0,0,0,0,0,0,0,0
0,0,0,0,0,0,0,0,0,0,0,0,0,0,0,0,0,0,0,0,0,0,0,0,0,0,0,0,0,0,0
0,0,0,0,0,0,0,0,0,0,0,0,0,0,0,0,0,0,0,0,0,0,0,0,0,0,0,0,0,0,0
0,0,0,0,0,0,0,0,0,0,0,0,0,0,0,0,0,0,0,0,0,0,0,0,0,0,0,0,0,0,0
0,0,0,0,0,0,0,0,0,0,0,0,0,0,0,0,0,0,0,0,0,0,0,0,0,0,0,0,0,0,0
0,0,0,0,0,0,0,0,0,0,0,0,0,0,0,0,0,0,0,0,0,0,0,0,0,0,0,0,0,0,0
0,0,0,0,0,0,0,0,0,0,0,0,0,0,0,0,0,0,0,0,0,0,0,0,0,0,0,0,0,0,0
0,0,0,0,0,0,0,0,0,0,0,0,0,0,0,0,0,0,0,0,0,0,0,0,0,0,0,0,0,0,0
0,0,0,0,0,0,0,0,0,0,0,0,0,0,0,0,0,0,0,0,0,0,0,0,0,0,0,0,0,0,0
0,0,0,0,0,0,0,0,0,0,0,0,0,0,0,0,0,0,0,0,0,0,0,0,0,0,0,0,0,0,0
:endlayer
layer: 26
0,0,0,0,0,0,0,0,0,0,0,0,0,0,0,0,0,0,0,0,0,0,0,0,0,0,0,0,0,0,0
0,0,0,0,0,0,0,0,0,0,0,0,0,0,0,0,0,0,0,0,0,0,0,0,0,0,0,0,0,0,0
0,0,0,0,0,0,0,0,0,0,0,0,0,0,0,0,0,0,0,0,0,0,0,0,0,0,0,0,0,0,0
0,0,0,0,0,0,0,0,0,0,0,0,0,0,0,0,0,0,0,0,0,0,0,0,0,0,0,0,0,0,0
0,0,0,0,0,0,0,0,0,0,0,0,0,0,0,0,0,0,0,0,0,0,0,0,0,0,0,0,0,0,0
0,0,0,0,0,0,0,0,0,0,0,0,0,0,0,0,0,0,0,0,0,0,0,0,0,0,0,0,0,0,0
0,0,0,0,0,0,0,2,0,2,0,0,0,0,0,0,0,0,0,0,0,0,0,0,0,0,0,0,0,0,0
0,0,0,0,0,0,2,0,0,0,2,0,0,0,0,0,0,0,0,0,0,0,0,0,0,0,0,0,0,0,0
0,0,0,0,0,2,0,0,0,0,0,2,0,0,0,0,0,0,0,0,0,0,0,0,0,0,0,0,0,0,0
0,0,0,0,0,0,0,0,0,0,0,0,0,0,0,0,0,0,0,0,0,0,0,0,0,0,0,0,0,0,0
0,0,0,0,0,2,0,0,0,0,0,2,0,0,0,0,0,0,0,0,0,0,0,0,0,0,0,0,0,0,0
0,0,0,0,0,0,2,0,0,0,2,0,0,0,0,0,0,0,0,0,0,0,0,0,0,0,0,0,0,0,0
0,0,0,0,0,0,0,2,0,2,0,0,0,0,0,0,0,0,0,0,0,0,0,0,0,0,0,0,0,0,0
0,0,0,0,0,0,0,0,0,0,0,0,0,0,0,0,0,0,0,0,0,0,0,0,0,0,0,0,0,0,0
0,0,0,0,0,0,0,0,0,0,0,0,0,0,0,0,0,0,0,0,0,0,0,0,0,0,0,0,0,0,0
0,0,0,0,0,0,0,0,0,0,0,0,0,0,0,0,0,0,0,0,0,0,0,0,0,0,0,0,0,0,0
0,0,0,0,0,0,0,0,0,0,0,0,0,0,0,0,0,0,0,0,0,0,0,0,0,0,0,0,0,0,0
0,0,0,0,0,0,0,0,0,0,0,0,0,0,0,0,0,0,0,0,0,0,0,0,0,0,0,0,0,0,0
0,0,0,0,0,0,0,0,0,0,0,0,0,0,0,0,0,0,0,0,0,0,0,0,0,0,0,0,0,0,0
0,0,0,0,0,0,0,0,0,0,0,0,0,0,0,0,0,0,0,0,0,0,0,0,0,0,0,0,0,0,0
0,0,0,0,0,0,0,0,0,0,0,0,0,0,0,0,0,0,0,0,0,0,0,0,0,0,0,0,0,0,0
0,0,0,0,0,0,0,0,0,0,0,0,0,0,0,0,0,0,0,0,0,0,0,0,0,0,0,0,0,0,0
:endlayer
layer: 27
0,0,0,0,0,0,0,0,0,0,0,0,0,0,0,0,0,0,0,0,0,0,0,0,0,0,0,0,0,0,0
0,0,0,0,0,0,0,0,0,0,0,0,0,0,0,0,0,0,0,0,0,0,0,0,0,0,0,0,0,0,0
0,0,0,0,0,0,0,0,0,0,0,0,0,0,0,0,0,0,0,0,0,0,0,0,0,0,0,0,0,0,0
0,0,0,0,0,0,0,0,0,0,0,0,0,0,0,0,0,0,0,0,0,0,0,0,0,0,0,0,0,0,0
0,0,0,0,0,0,0,0,0,0,0,0,0,0,0,0,0,0,0,0,0,0,0,0,0,0,0,0,0,0,0
0,0,0,0,0,0,0,0,0,0,0,0,0,0,0,0,0,0,0,0,0,0,0,0,0,0,0,0,0,0,0
0,0,0,0,0,0,0,2,0,2,0,0,0,0,0,0,0,0,0,0,0,0,0,0,0,0,0,0,0,0,0
0,0,0,0,0,0,2,0,0,0,2,0,0,0,0,0,0,0,0,0,0,0,0,0,0,0,0,0,0,0,0
0,0,0,0,0,2,0,0,0,0,0,2,0,0,0,0,0,0,0,0,0,0,0,0,0,0,0,0,0,0,0
0,0,0,0,0,0,0,0,0,0,0,0,0,0,0,0,0,0,0,0,0,0,0,0,0,0,0,0,0,0,0
0,0,0,0,0,2,0,0,0,0,0,2,0,0,0,0,0,0,0,0,0,0,0,0,0,0,0,0,0,0,0
0,0,0,0,0,0,2,0,0,0,2,0,0,0,0,0,0,0,0,0,0,0,0,0,0,0,0,0,0,0,0
0,0,0,0,0,0,0,2,0,2,0,0,0,0,0,0,0,0,0,0,0,0,0,0,0,0,0,0,0,0,0
0,0,0,0,0,0,0,0,0,0,0,0,0,0,0,0,0,0,0,0,0,0,0,0,0,0,0,0,0,0,0
0,0,0,0,0,0,0,0,0,0,0,0,0,0,0,0,0,0,0,0,0,0,0,0,0,0,0,0,0,0,0
0,0,0,0,0,0,0,0,0,0,0,0,0,0,0,0,0,0,0,0,0,0,0,0,0,0,0,0,0,0,0
0,0,0,0,0,0,0,0,0,0,0,0,0,0,0,0,0,0,0,0,0,0,0,0,0,0,0,0,0,0,0
0,0,0,0,0,0,0,0,0,0,0,0,0,0,0,0,0,0,0,0,0,0,0,0,0,0,0,0,0,0,0
0,0,0,0,0,0,0,0,0,0,0,0,0,0,0,0,0,0,0,0,0,0,0,0,0,0,0,0,0,0,0
0,0,0,0,0,0,0,0,0,0,0,0,0,0,0,0,0,0,0,0,0,0,0,0,0,0,0,0,0,0,0
0,0,0,0,0,0,0,0,0,0,0,0,0,0,0,0,0,0,0,0,0,0,0,0,0,0,0,0,0,0,0
0,0,0,0,0,0,0,0,0,0,0,0,0,0,0,0,0,0,0,0,0,0,0,0,0,0,0,0,0,0,0
:endlayer
layer: 28
0,0,0,0,0,0,0,0,0,0,0,0,0,0,0,0,0,0,0,0,0,0,0,0,0,0,0,0,0,0,0
0,0,0,0,0,0,0,0,0,0,0,0,0,0,0,0,0,0,0,0,0,0,0,0,0,0,0,0,0,0,0
0,0,0,0,0,0,0,0,0,0,0,0,0,0,0,0,0,0,0,0,0,0,0,0,0,0,0,0,0,0,0
0,0,0,0,0,0,0,0,0,0,0,0,0,0,0,0,0,0,0,0,0,0,0,0,0,0,0,0,0,0,0
0,0,0,0,0,0,0,0,0,0,0,0,0,0,0,0,0,0,0,0,0,0,0,0,0,0,0,0,0,0,0
0,0,0,0,0,0,0,0,57,0,0,0,0,0,0,0,0,0,0,0,0,0,0,0,0,0,0,0,0,0,0
0,0,0,0,0,0,0,2,2,2,0,0,0,0,0,0,0,0,0,0,0,0,0,0,0,0,0,0,0,0,0
0,0,0,0,0,0,2,0,0,0,2,0,0,0,0,0,0,0,0,0,0,0,0,0,0,0,0,0,0,0,0
0,0,0,0,0,2,0,0,0,0,0,2,0,0,0,0,0,0,0,0,0,0,0,0,0,0,0,0,0,0,0
0,0,0,0,40,2,0,0,0,0,0,2,41,0,0,0,0,0,0,0,0,0,0,0,0,0,0,0,0,0,0
0,0,0,0,0,2,0,0,0,0,0,2,0,0,0,0,0,0,0,0,0,0,0,0,0,0,0,0,0,0,0
0,0,0,0,0,0,2,0,0,0,2,0,0,0,0,0,0,0,0,0,0,0,0,0,0,0,0,0,0,0,0
0,0,0,0,0,0,0,2,2,2,0,0,0,0,0,0,0,0,0,0,0,0,0,0,0,0,0,0,0,0,0
0,0,0,0,0,0,0,0,42,0,0,0,0,0,0,0,0,0,0,0,0,0,0,0,0,0,0,0,0,0,0
0,0,0,0,0,0,0,0,0,0,0,0,0,0,0,0,0,0,0,0,0,0,0,0,0,0,0,0,0,0,0
0,0,0,0,0,0,0,0,0,0,0,0,0,0,0,0,0,0,0,0,0,0,0,0,0,0,0,0,0,0,0
0,0,0,0,0,0,0,0,0,0,0,0,0,0,0,0,0,0,0,0,0,0,0,0,0,0,0,0,0,0,0
0,0,0,0,0,0,0,0,0,0,0,0,0,0,0,0,0,0,0,0,0,0,0,0,0,0,0,0,0,0,0
0,0,0,0,0,0,0,0,0,0,0,0,0,0,0,0,0,0,0,0,0,0,0,0,0,0,0,0,0,0,0
0,0,0,0,0,0,0,0,0,0,0,0,0,0,0,0,0,0,0,0,0,0,0,0,0,0,0,0,0,0,0
0,0,0,0,0,0,0,0,0,0,0,0,0,0,0,0,0,0,0,0,0,0,0,0,0,0,0,0,0,0,0
0,0,0,0,0,0,0,0,0,0,0,0,0,0,0,0,0,0,0,0,0,0,0,0,0,0,0,0,0,0,0
:endlayer
layer: 29
0,0,0,0,0,0,0,0,0,0,0,0,0,0,0,0,0,0,0,0,0,0,0,0,0,0,0,0,0,0,0
0,0,0,0,0,0,0,0,0,0,0,0,0,0,0,0,0,0,0,0,0,0,0,0,0,0,0,0,0,0,0
0,0,0,0,0,0,0,0,0,0,0,0,0,0,0,0,0,0,0,0,0,0,0,0,0,0,0,0,0,0,0
0,0,0,0,0,0,0,0,0,0,0,0,0,0,0,0,0,0,0,0,0,0,0,0,0,0,0,0,0,0,0
0,0,0,0,0,0,0,0,0,0,0,0,0,0,0,0,0,0,0,0,0,0,0,0,0,0,0,0,0,0,0
0,0,0,0,0,0,0,0,126,0,0,0,0,0,0,0,0,0,0,0,0,0,0,0,0,0,0,0,0,0,0
0,0,0,0,0,0,126,2,2,2,126,0,0,0,0,0,0,0,0,0,0,0,0,0,0,0,0,0,0,0,0
0,0,0,0,0,126,66,0,101,0,66,126,0,0,0,0,0,0,0,0,0,0,0,0,0,0,0,0,0,0,0
0,0,0,0,0,2,0,0,0,0,0,2,0,0,0,0,0,0,0,0,0,0,0,0,0,0,0,0,0,0,0
0,0,0,0,126,2,0,0,0,0,0,2,126,0,0,0,0,0,0,0,0,0,0,0,0,0,0,0,0,0,0
0,0,0,0,0,2,0,0,0,0,0,2,0,0,0,0,0,0,0,0,0,0,0,0,0,0,0,0,0,0,0
0,0,0,0,0,126,66,0,100,0,66,126,0,0,0,0,0,0,0,0,0,0,0,0,0,0,0,0,0,0,0
0,0,0,0,0,0,126,2,2,2,126,0,0,0,0,0,0,0,0,0,0,0,0,0,0,0,0,0,0,0,0
0,0,0,0,0,0,0,0,126,0,0,0,0,0,0,0,0,0,0,0,0,0,0,0,0,0,0,0,0,0,0
0,0,0,0,0,0,0,0,0,0,0,0,0,0,0,0,0,0,0,0,0,0,0,0,0,0,0,0,0,0,0
0,0,0,0,0,0,0,0,0,0,0,0,0,0,0,0,0,0,0,0,0,0,0,0,0,0,0,0,0,0,0
0,0,0,0,0,0,0,0,0,0,0,0,0,0,0,0,0,0,0,0,0,0,0,0,0,0,0,0,0,0,0
0,0,0,0,0,0,0,0,0,0,0,0,0,0,0,0,0,0,0,0,0,0,0,0,0,0,0,0,0,0,0
0,0,0,0,0,0,0,0,0,0,0,0,0,0,0,0,0,0,0,0,0,0,0,0,0,0,0,0,0,0,0
0,0,0,0,0,0,0,0,0,0,0,0,0,0,0,0,0,0,0,0,0,0,0,0,0,0,0,0,0,0,0
0,0,0,0,0,0,0,0,0,0,0,0,0,0,0,0,0,0,0,0,0,0,0,0,0,0,0,0,0,0,0
0,0,0,0,0,0,0,0,0,0,0,0,0,0,0,0,0,0,0,0,0,0,0,0,0,0,0,0,0,0,0
:endlayer
layer: 30
0,0,0,0,0,0,0,0,0,0,0,0,0,0,0,0,0,0,0,0,0,0,0,0,0,0,0,0,0,0,0
0,0,0,0,0,0,0,0,0,0,0,0,0,0,0,0,0,0,0,0,0,0,0,0,0,0,0,0,0,0,0
0,0,0,0,0,0,0,0,0,0,0,0,0,0,0,0,0,0,0,0,0,0,0,0,0,0,0,0,0,0,0
0,0,0,0,0,0,0,0,0,0,0,0,0,0,0,0,0,0,0,0,0,0,0,0,0,0,0,0,0,0,0
0,0,0,0,0,0,0,0,0,0,0,0,0,0,0,0,0,0,0,0,0,0,0,0,0,0,0,0,0,0,0
0,0,0,0,121,121,121,121,121,121,121,121,111,0,0,0,0,0,0,0,0,0,0,0,0,0,0,0,0,0,0
0,0,0,0,109,65,66,66,66,66,66,65,111,0,0,0,0,0,0,0,0,0,0,0,0,0,0,0,0,0,0
0,0,0,0,109,66,66,0,65,0,66,66,111,0,0,0,0,0,0,0,0,0,0,0,0,0,0,0,0,0,0
0,0,0,0,109,66,0,0,65,0,0,66,111,0,0,0,0,0,0,0,0,0,0,0,0,0,0,0,0,0,0
0,0,0,0,109,66,0,0,65,0,0,66,111,0,0,0,0,0,0,0,0,0,0,0,0,0,0,0,0,0,0
0,0,0,0,109,66,0,0,65,0,0,66,111,0,0,0,0,0,0,0,0,0,0,0,0,0,0,0,0,0,0
0,0,0,0,109,66,66,0,65,0,66,66,111,0,0,0,0,0,0,0,0,0,0,0,0,0,0,0,0,0,0
0,0,0,0,109,65,66,66,66,66,66,65,111,0,0,0,0,0,0,0,0,0,0,0,0,0,0,0,0,0,0
0,0,0,0,120,120,120,120,120,120,120,120,120,0,0,0,0,0,0,0,0,0,0,0,0,0,0,0,0,0,0
0,0,0,0,0,0,0,0,0,0,0,0,0,0,0,0,0,0,0,0,0,0,0,0,0,0,0,0,0,0,0
0,0,0,0,0,0,0,0,0,0,0,0,0,0,0,0,0,0,0,0,0,0,0,0,0,0,0,0,0,0,0
0,0,0,0,0,0,0,0,0,0,0,0,0,0,0,0,0,0,0,0,0,0,0,0,0,0,0,0,0,0,0
0,0,0,0,0,0,0,0,0,0,0,0,0,0,0,0,0,0,0,0,0,0,0,0,0,0,0,0,0,0,0
0,0,0,0,0,0,0,0,0,0,0,0,0,0,0,0,0,0,0,0,0,0,0,0,0,0,0,0,0,0,0
0,0,0,0,0,0,0,0,0,0,0,0,0,0,0,0,0,0,0,0,0,0,0,0,0,0,0,0,0,0,0
0,0,0,0,0,0,0,0,0,0,0,0,0,0,0,0,0,0,0,0,0,0,0,0,0,0,0,0,0,0,0
0,0,0,0,0,0,0,0,0,0,0,0,0,0,0,0,0,0,0,0,0,0,0,0,0,0,0,0,0,0,0
:endlayer
layer: 31
0,0,0,0,0,0,0,0,0,0,0,0,0,0,0,0,0,0,0,0,0,0,0,0,0,0,0,0,0,0,0
0,0,0,0,0,0,0,0,0,0,0,0,0,0,0,0,0,0,0,0,0,0,0,0,0,0,0,0,0,0,0
0,0,0,0,0,0,0,0,0,0,0,0,0,0,0,0,0,0,0,0,0,0,0,0,0,0,0,0,0,0,0
0,0,0,0,0,0,0,0,0,0,0,0,0,0,0,0,0,0,0,0,0,0,0,0,0,0,0,0,0,0,0
0,0,0,0,0,0,0,0,0,0,0,0,0,0,0,0,0,0,0,0,0,0,0,0,0,0,0,0,0,0,0
0,0,0,0,0,0,0,0,0,0,0,0,0,0,0,0,0,0,0,0,0,0,0,0,0,0,0,0,0,0,0
0,0,0,0,0,109,121,121,121,121,121,111,0,0,0,0,0,0,0,0,0,0,0,0,0,0,0,0,0,0,0
0,0,0,0,0,109,66,0,0,0,66,111,0,0,0,0,0,0,0,0,0,0,0,0,0,0,0,0,0,0,0
0,0,0,0,0,109,0,0,129,0,0,111,0,0,0,0,0,0,0,0,0,0,0,0,0,0,0,0,0,0,0
0,0,0,0,0,109,0,0,128,0,0,111,0,0,0,0,0,0,0,0,0,0,0,0,0,0,0,0,0,0,0
0,0,0,0,0,109,0,0,127,0,0,111,0,0,0,0,0,0,0,0,0,0,0,0,0,0,0,0,0,0,0
0,0,0,0,0,109,66,0,0,0,66,111,0,0,0,0,0,0,0,0,0,0,0,0,0,0,0,0,0,0,0
0,0,0,0,0,120,120,120,120,120,120,120,0,0,0,0,0,0,0,0,0,0,0,0,0,0,0,0,0,0,0
0,0,0,0,0,0,0,0,0,0,0,0,0,0,0,0,0,0,0,0,0,0,0,0,0,0,0,0,0,0,0
0,0,0,0,0,0,0,0,0,0,0,0,0,0,0,0,0,0,0,0,0,0,0,0,0,0,0,0,0,0,0
0,0,0,0,0,0,0,0,0,0,0,0,0,0,0,0,0,0,0,0,0,0,0,0,0,0,0,0,0,0,0
0,0,0,0,0,0,0,0,0,0,0,0,0,0,0,0,0,0,0,0,0,0,0,0,0,0,0,0,0,0,0
0,0,0,0,0,0,0,0,0,0,0,0,0,0,0,0,0,0,0,0,0,0,0,0,0,0,0,0,0,0,0
0,0,0,0,0,0,0,0,0,0,0,0,0,0,0,0,0,0,0,0,0,0,0,0,0,0,0,0,0,0,0
0,0,0,0,0,0,0,0,0,0,0,0,0,0,0,0,0,0,0,0,0,0,0,0,0,0,0,0,0,0,0
0,0,0,0,0,0,0,0,0,0,0,0,0,0,0,0,0,0,0,0,0,0,0,0,0,0,0,0,0,0,0
0,0,0,0,0,0,0,0,0,0,0,0,0,0,0,0,0,0,0,0,0,0,0,0,0,0,0,0,0,0,0
:endlayer
layer: 32
0,0,0,0,0,0,0,0,0,0,0,0,0,0,0,0,0,0,0,0,0,0,0,0,0,0,0,0,0,0,0
0,0,0,0,0,0,0,0,0,0,0,0,0,0,0,0,0,0,0,0,0,0,0,0,0,0,0,0,0,0,0
0,0,0,0,0,0,0,0,0,0,0,0,0,0,0,0,0,0,0,0,0,0,0,0,0,0,0,0,0,0,0
0,0,0,0,0,0,0,0,0,0,0,0,0,0,0,0,0,0,0,0,0,0,0,0,0,0,0,0,0,0,0
0,0,0,0,0,0,0,0,0,0,0,0,0,0,0,0,0,0,0,0,0,0,0,0,0,0,0,0,0,0,0
0,0,0,0,0,0,0,0,0,0,0,0,0,0,0,0,0,0,0,0,0,0,0,0,0,0,0,0,0,0,0
0,0,0,0,0,0,0,0,0,0,0,0,0,0,0,0,0,0,0,0,0,0,0,0,0,0,0,0,0,0,0
0,0,0,0,0,0,109,121,121,121,111,0,0,0,0,0,0,0,0,0,0,0,0,0,0,0,0,0,0,0,0
0,0,0,0,0,0,109,65,0,65,111,0,0,0,0,0,0,0,0,0,0,0,0,0,0,0,0,0,0,0,0
0,0,0,0,0,0,109,0,0,0,111,0,0,0,0,0,0,0,0,0,0,0,0,0,0,0,0,0,0,0,0
0,0,0,0,0,0,109,65,0,65,111,0,0,0,0,0,0,0,0,0,0,0,0,0,0,0,0,0,0,0,0
0,0,0,0,0,0,120,120,120,120,111,0,0,0,0,0,0,0,0,0,0,0,0,0,0,0,0,0,0,0,0
0,0,0,0,0,0,0,0,0,0,0,0,0,0,0,0,0,0,0,0,0,0,0,0,0,0,0,0,0,0,0
0,0,0,0,0,0,0,0,0,0,0,0,0,0,0,0,0,0,0,0,0,0,0,0,0,0,0,0,0,0,0
0,0,0,0,0,0,0,0,0,0,0,0,0,0,0,0,0,0,0,0,0,0,0,0,0,0,0,0,0,0,0
0,0,0,0,0,0,0,0,0,0,0,0,0,0,0,0,0,0,0,0,0,0,0,0,0,0,0,0,0,0,0
0,0,0,0,0,0,0,0,0,0,0,0,0,0,0,0,0,0,0,0,0,0,0,0,0,0,0,0,0,0,0
0,0,0,0,0,0,0,0,0,0,0,0,0,0,0,0,0,0,0,0,0,0,0,0,0,0,0,0,0,0,0
0,0,0,0,0,0,0,0,0,0,0,0,0,0,0,0,0,0,0,0,0,0,0,0,0,0,0,0,0,0,0
0,0,0,0,0,0,0,0,0,0,0,0,0,0,0,0,0,0,0,0,0,0,0,0,0,0,0,0,0,0,0
0,0,0,0,0,0,0,0,0,0,0,0,0,0,0,0,0,0,0,0,0,0,0,0,0,0,0,0,0,0,0
0,0,0,0,0,0,0,0,0,0,0,0,0,0,0,0,0,0,0,0,0,0,0,0,0,0,0,0,0,0,0
:endlayer
layer: 33
0,0,0,0,0,0,0,0,0,0,0,0,0,0,0,0,0,0,0,0,0,0,0,0,0,0,0,0,0,0,0
0,0,0,0,0,0,0,0,0,0,0,0,0,0,0,0,0,0,0,0,0,0,0,0,0,0,0,0,0,0,0
0,0,0,0,0,0,0,0,0,0,0,0,0,0,0,0,0,0,0,0,0,0,0,0,0,0,0,0,0,0,0
0,0,0,0,0,0,0,0,0,0,0,0,0,0,0,0,0,0,0,0,0,0,0,0,0,0,0,0,0,0,0
0,0,0,0,0,0,0,0,0,0,0,0,0,0,0,0,0,0,0,0,0,0,0,0,0,0,0,0,0,0,0
0,0,0,0,0,0,0,0,0,0,0,0,0,0,0,0,0,0,0,0,0,0,0,0,0,0,0,0,0,0,0
0,0,0,0,0,0,0,0,0,0,0,0,0,0,0,0,0,0,0,0,0,0,0,0,0,0,0,0,0,0,0
0,0,0,0,0,0,0,0,0,0,0,0,0,0,0,0,0,0,0,0,0,0,0,0,0,0,0,0,0,0,0
0,0,0,0,0,0,0,65,0,65,0,0,0,0,0,0,0,0,0,0,0,0,0,0,0,0,0,0,0,0,0
0,0,0,0,0,0,0,0,0,0,0,0,0,0,0,0,0,0,0,0,0,0,0,0,0,0,0,0,0,0,0
0,0,0,0,0,0,0,65,0,65,0,0,0,0,0,0,0,0,0,0,0,0,0,0,0,0,0,0,0,0,0
0,0,0,0,0,0,0,0,0,0,0,0,0,0,0,0,0,0,0,0,0,0,0,0,0,0,0,0,0,0,0
0,0,0,0,0,0,0,0,0,0,0,0,0,0,0,0,0,0,0,0,0,0,0,0,0,0,0,0,0,0,0
0,0,0,0,0,0,0,0,0,0,0,0,0,0,0,0,0,0,0,0,0,0,0,0,0,0,0,0,0,0,0
0,0,0,0,0,0,0,0,0,0,0,0,0,0,0,0,0,0,0,0,0,0,0,0,0,0,0,0,0,0,0
0,0,0,0,0,0,0,0,0,0,0,0,0,0,0,0,0,0,0,0,0,0,0,0,0,0,0,0,0,0,0
0,0,0,0,0,0,0,0,0,0,0,0,0,0,0,0,0,0,0,0,0,0,0,0,0,0,0,0,0,0,0
0,0,0,0,0,0,0,0,0,0,0,0,0,0,0,0,0,0,0,0,0,0,0,0,0,0,0,0,0,0,0
0,0,0,0,0,0,0,0,0,0,0,0,0,0,0,0,0,0,0,0,0,0,0,0,0,0,0,0,0,0,0
0,0,0,0,0,0,0,0,0,0,0,0,0,0,0,0,0,0,0,0,0,0,0,0,0,0,0,0,0,0,0
0,0,0,0,0,0,0,0,0,0,0,0,0,0,0,0,0,0,0,0,0,0,0,0,0,0,0,0,0,0,0
0,0,0,0,0,0,0,0,0,0,0,0,0,0,0,0,0,0,0,0,0,0,0,0,0,0,0,0,0,0,0
:endlayer
layer: 34
0,0,0,0,0,0,0,0,0,0,0,0,0,0,0,0,0,0,0,0,0,0,0,0,0,0,0,0,0,0,0
0,0,0,0,0,0,0,0,0,0,0,0,0,0,0,0,0,0,0,0,0,0,0,0,0,0,0,0,0,0,0
0,0,0,0,0,0,0,0,0,0,0,0,0,0,0,0,0,0,0,0,0,0,0,0,0,0,0,0,0,0,0
0,0,0,0,0,0,0,0,0,0,0,0,0,0,0,0,0,0,0,0,0,0,0,0,0,0,0,0,0,0,0
0,0,0,0,0,0,0,0,0,0,0,0,0,0,0,0,0,0,0,0,0,0,0,0,0,0,0,0,0,0,0
0,0,0,0,0,0,0,0,0,0,0,0,0,0,0,0,0,0,0,0,0,0,0,0,0,0,0,0,0,0,0
0,0,0,0,0,0,0,0,0,0,0,0,0,0,0,0,0,0,0,0,0,0,0,0,0,0,0,0,0,0,0
0,0,0,0,0,0,0,0,0,0,0,0,0,0,0,0,0,0,0,0,0,0,0,0,0,0,0,0,0,0,0
0,0,0,0,0,0,0,65,0,65,0,0,0,0,0,0,0,0,0,0,0,0,0,0,0,0,0,0,0,0,0
0,0,0,0,0,0,0,0,130,0,0,0,0,0,0,0,0,0,0,0,0,0,0,0,0,0,0,0,0,0,0
0,0,0,0,0,0,0,65,0,65,0,0,0,0,0,0,0,0,0,0,0,0,0,0,0,0,0,0,0,0,0
0,0,0,0,0,0,0,0,0,0,0,0,0,0,0,0,0,0,0,0,0,0,0,0,0,0,0,0,0,0,0
0,0,0,0,0,0,0,0,0,0,0,0,0,0,0,0,0,0,0,0,0,0,0,0,0,0,0,0,0,0,0
0,0,0,0,0,0,0,0,0,0,0,0,0,0,0,0,0,0,0,0,0,0,0,0,0,0,0,0,0,0,0
0,0,0,0,0,0,0,0,0,0,0,0,0,0,0,0,0,0,0,0,0,0,0,0,0,0,0,0,0,0,0
0,0,0,0,0,0,0,0,0,0,0,0,0,0,0,0,0,0,0,0,0,0,0,0,0,0,0,0,0,0,0
0,0,0,0,0,0,0,0,0,0,0,0,0,0,0,0,0,0,0,0,0,0,0,0,0,0,0,0,0,0,0
0,0,0,0,0,0,0,0,0,0,0,0,0,0,0,0,0,0,0,0,0,0,0,0,0,0,0,0,0,0,0
0,0,0,0,0,0,0,0,0,0,0,0,0,0,0,0,0,0,0,0,0,0,0,0,0,0,0,0,0,0,0
0,0,0,0,0,0,0,0,0,0,0,0,0,0,0,0,0,0,0,0,0,0,0,0,0,0,0,0,0,0,0
0,0,0,0,0,0,0,0,0,0,0,0,0,0,0,0,0,0,0,0,0,0,0,0,0,0,0,0,0,0,0
0,0,0,0,0,0,0,0,0,0,0,0,0,0,0,0,0,0,0,0,0,0,0,0,0,0,0,0,0,0,0
:endlayer
layer: 35
0,0,0,0,0,0,0,0,0,0,0,0,0,0,0,0,0,0,0,0,0,0,0,0,0,0,0,0,0,0,0
0,0,0,0,0,0,0,0,0,0,0,0,0,0,0,0,0,0,0,0,0,0,0,0,0,0,0,0,0,0,0
0,0,0,0,0,0,0,0,0,0,0,0,0,0,0,0,0,0,0,0,0,0,0,0,0,0,0,0,0,0,0
0,0,0,0,0,0,0,0,0,0,0,0,0,0,0,0,0,0,0,0,0,0,0,0,0,0,0,0,0,0,0
0,0,0,0,0,0,0,0,0,0,0,0,0,0,0,0,0,0,0,0,0,0,0,0,0,0,0,0,0,0,0
0,0,0,0,0,0,0,0,0,0,0,0,0,0,0,0,0,0,0,0,0,0,0,0,0,0,0,0,0,0,0
0,0,0,0,0,0,0,0,0,0,0,0,0,0,0,0,0,0,0,0,0,0,0,0,0,0,0,0,0,0,0
0,0,0,0,0,0,0,0,0,0,0,0,0,0,0,0,0,0,0,0,0,0,0,0,0,0,0,0,0,0,0
0,0,0,0,0,0,0,65,0,65,0,0,0,0,0,0,0,0,0,0,0,0,0,0,0,0,0,0,0,0,0
0,0,0,0,0,0,0,0,130,0,0,0,0,0,0,0,0,0,0,0,0,0,0,0,0,0,0,0,0,0,0
0,0,0,0,0,0,0,65,0,65,0,0,0,0,0,0,0,0,0,0,0,0,0,0,0,0,0,0,0,0,0
0,0,0,0,0,0,0,0,0,0,0,0,0,0,0,0,0,0,0,0,0,0,0,0,0,0,0,0,0,0,0
0,0,0,0,0,0,0,0,0,0,0,0,0,0,0,0,0,0,0,0,0,0,0,0,0,0,0,0,0,0,0
0,0,0,0,0,0,0,0,0,0,0,0,0,0,0,0,0,0,0,0,0,0,0,0,0,0,0,0,0,0,0
0,0,0,0,0,0,0,0,0,0,0,0,0,0,0,0,0,0,0,0,0,0,0,0,0,0,0,0,0,0,0
0,0,0,0,0,0,0,0,0,0,0,0,0,0,0,0,0,0,0,0,0,0,0,0,0,0,0,0,0,0,0
0,0,0,0,0,0,0,0,0,0,0,0,0,0,0,0,0,0,0,0,0,0,0,0,0,0,0,0,0,0,0
0,0,0,0,0,0,0,0,0,0,0,0,0,0,0,0,0,0,0,0,0,0,0,0,0,0,0,0,0,0,0
0,0,0,0,0,0,0,0,0,0,0,0,0,0,0,0,0,0,0,0,0,0,0,0,0,0,0,0,0,0,0
0,0,0,0,0,0,0,0,0,0,0,0,0,0,0,0,0,0,0,0,0,0,0,0,0,0,0,0,0,0,0
0,0,0,0,0,0,0,0,0,0,0,0,0,0,0,0,0,0,0,0,0,0,0,0,0,0,0,0,0,0,0
0,0,0,0,0,0,0,0,0,0,0,0,0,0,0,0,0,0,0,0,0,0,0,0,0,0,0,0,0,0,0
:endlayer
layer: 36
0,0,0,0,0,0,0,0,0,0,0,0,0,0,0,0,0,0,0,0,0,0,0,0,0,0,0,0,0,0,0
0,0,0,0,0,0,0,0,0,0,0,0,0,0,0,0,0,0,0,0,0,0,0,0,0,0,0,0,0,0,0
0,0,0,0,0,0,0,0,0,0,0,0,0,0,0,0,0,0,0,0,0,0,0,0,0,0,0,0,0,0,0
0,0,0,0,0,0,0,0,0,0,0,0,0,0,0,0,0,0,0,0,0,0,0,0,0,0,0,0,0,0,0
0,0,0,0,0,0,0,0,0,0,0,0,0,0,0,0,0,0,0,0,0,0,0,0,0,0,0,0,0,0,0
0,0,0,0,0,0,0,0,0,0,0,0,0,0,0,0,0,0,0,0,0,0,0,0,0,0,0,0,0,0,0
0,0,0,0,0,0,0,0,0,0,0,0,0,0,0,0,0,0,0,0,0,0,0,0,0,0,0,0,0,0,0
0,0,0,0,0,0,121,121,121,121,0,0,0,0,0,0,0,0,0,0,0,0,0,0,0,0,0,0,0,0,0
0,0,0,0,0,0,109,65,65,65,111,0,0,0,0,0,0,0,0,0,0,0,0,0,0,0,0,0,0,0,0
0,0,0,0,0,0,109,65,103,65,111,0,0,0,0,0,0,0,0,0,0,0,0,0,0,0,0,0,0,0,0
0,0,0,0,0,0,109,65,65,65,111,0,0,0,0,0,0,0,0,0,0,0,0,0,0,0,0,0,0,0,0
0,0,0,0,0,0,120,120,120,120,120,0,0,0,0,0,0,0,0,0,0,0,0,0,0,0,0,0,0,0,0
0,0,0,0,0,0,0,0,0,0,0,0,0,0,0,0,0,0,0,0,0,0,0,0,0,0,0,0,0,0,0
0,0,0,0,0,0,0,0,0,0,0,0,0,0,0,0,0,0,0,0,0,0,0,0,0,0,0,0,0,0,0
0,0,0,0,0,0,0,0,0,0,0,0,0,0,0,0,0,0,0,0,0,0,0,0,0,0,0,0,0,0,0
0,0,0,0,0,0,0,0,0,0,0,0,0,0,0,0,0,0,0,0,0,0,0,0,0,0,0,0,0,0,0
0,0,0,0,0,0,0,0,0,0,0,0,0,0,0,0,0,0,0,0,0,0,0,0,0,0,0,0,0,0,0
0,0,0,0,0,0,0,0,0,0,0,0,0,0,0,0,0,0,0,0,0,0,0,0,0,0,0,0,0,0,0
0,0,0,0,0,0,0,0,0,0,0,0,0,0,0,0,0,0,0,0,0,0,0,0,0,0,0,0,0,0,0
0,0,0,0,0,0,0,0,0,0,0,0,0,0,0,0,0,0,0,0,0,0,0,0,0,0,0,0,0,0,0
0,0,0,0,0,0,0,0,0,0,0,0,0,0,0,0,0,0,0,0,0,0,0,0,0,0,0,0,0,0,0
0,0,0,0,0,0,0,0,0,0,0,0,0,0,0,0,0,0,0,0,0,0,0,0,0,0,0,0,0,0,0
:endlayer
layer: 37
0,0,0,0,0,0,0,0,0,0,0,0,0,0,0,0,0,0,0,0,0,0,0,0,0,0,0,0,0,0,0
0,0,0,0,0,0,0,0,0,0,0,0,0,0,0,0,0,0,0,0,0,0,0,0,0,0,0,0,0,0,0
0,0,0,0,0,0,0,0,0,0,0,0,0,0,0,0,0,0,0,0,0,0,0,0,0,0,0,0,0,0,0
0,0,0,0,0,0,0,0,0,0,0,0,0,0,0,0,0,0,0,0,0,0,0,0,0,0,0,0,0,0,0
0,0,0,0,0,0,0,0,0,0,0,0,0,0,0,0,0,0,0,0,0,0,0,0,0,0,0,0,0,0,0
0,0,0,0,0,0,0,0,0,0,0,0,0,0,0,0,0,0,0,0,0,0,0,0,0,0,0,0,0,0,0
0,0,0,0,0,0,0,0,0,0,0,0,0,0,0,0,0,0,0,0,0,0,0,0,0,0,0,0,0,0,0
0,0,0,0,0,0,0,0,0,0,0,0,0,0,0,0,0,0,0,0,0,0,0,0,0,0,0,0,0,0,0
0,0,0,0,0,0,0,121,121,111,0,0,0,0,0,0,0,0,0,0,0,0,0,0,0,0,0,0,0,0,0
0,0,0,0,0,0,0,109,65,111,0,0,0,0,0,0,0,0,0,0,0,0,0,0,0,0,0,0,0,0,0
0,0,0,0,0,0,0,120,120,111,0,0,0,0,0,0,0,0,0,0,0,0,0,0,0,0,0,0,0,0,0
0,0,0,0,0,0,0,0,0,0,0,0,0,0,0,0,0,0,0,0,0,0,0,0,0,0,0,0,0,0,0
0,0,0,0,0,0,0,0,0,0,0,0,0,0,0,0,0,0,0,0,0,0,0,0,0,0,0,0,0,0,0
0,0,0,0,0,0,0,0,0,0,0,0,0,0,0,0,0,0,0,0,0,0,0,0,0,0,0,0,0,0,0
0,0,0,0,0,0,0,0,0,0,0,0,0,0,0,0,0,0,0,0,0,0,0,0,0,0,0,0,0,0,0
0,0,0,0,0,0,0,0,0,0,0,0,0,0,0,0,0,0,0,0,0,0,0,0,0,0,0,0,0,0,0
0,0,0,0,0,0,0,0,0,0,0,0,0,0,0,0,0,0,0,0,0,0,0,0,0,0,0,0,0,0,0
0,0,0,0,0,0,0,0,0,0,0,0,0,0,0,0,0,0,0,0,0,0,0,0,0,0,0,0,0,0,0
0,0,0,0,0,0,0,0,0,0,0,0,0,0,0,0,0,0,0,0,0,0,0,0,0,0,0,0,0,0,0
0,0,0,0,0,0,0,0,0,0,0,0,0,0,0,0,0,0,0,0,0,0,0,0,0,0,0,0,0,0,0
0,0,0,0,0,0,0,0,0,0,0,0,0,0,0,0,0,0,0,0,0,0,0,0,0,0,0,0,0,0,0
0,0,0,0,0,0,0,0,0,0,0,0,0,0,0,0,0,0,0,0,0,0,0,0,0,0,0,0,0,0,0
:endlayer
layer: 38
0,0,0,0,0,0,0,0,0,0,0,0,0,0,0,0,0,0,0,0,0,0,0,0,0,0,0,0,0,0,0
0,0,0,0,0,0,0,0,0,0,0,0,0,0,0,0,0,0,0,0,0,0,0,0,0,0,0,0,0,0,0
0,0,0,0,0,0,0,0,0,0,0,0,0,0,0,0,0,0,0,0,0,0,0,0,0,0,0,0,0,0,0
0,0,0,0,0,0,0,0,0,0,0,0,0,0,0,0,0,0,0,0,0,0,0,0,0,0,0,0,0,0,0
0,0,0,0,0,0,0,0,0,0,0,0,0,0,0,0,0,0,0,0,0,0,0,0,0,0,0,0,0,0,0
0,0,0,0,0,0,0,0,0,0,0,0,0,0,0,0,0,0,0,0,0,0,0,0,0,0,0,0,0,0,0
0,0,0,0,0,0,0,0,0,0,0,0,0,0,0,0,0,0,0,0,0,0,0,0,0,0,0,0,0,0,0
0,0,0,0,0,0,0,0,0,0,0,0,0,0,0,0,0,0,0,0,0,0,0,0,0,0,0,0,0,0,0
0,0,0,0,0,0,0,0,0,0,0,0,0,0,0,0,0,0,0,0,0,0,0,0,0,0,0,0,0,0,0
0,0,0,0,0,0,0,0,65,0,0,0,0,0,0,0,0,0,0,0,0,0,0,0,0,0,0,0,0,0,0
0,0,0,0,0,0,0,0,0,0,0,0,0,0,0,0,0,0,0,0,0,0,0,0,0,0,0,0,0,0,0
0,0,0,0,0,0,0,0,0,0,0,0,0,0,0,0,0,0,0,0,0,0,0,0,0,0,0,0,0,0,0
0,0,0,0,0,0,0,0,0,0,0,0,0,0,0,0,0,0,0,0,0,0,0,0,0,0,0,0,0,0,0
0,0,0,0,0,0,0,0,0,0,0,0,0,0,0,0,0,0,0,0,0,0,0,0,0,0,0,0,0,0,0
0,0,0,0,0,0,0,0,0,0,0,0,0,0,0,0,0,0,0,0,0,0,0,0,0,0,0,0,0,0,0
0,0,0,0,0,0,0,0,0,0,0,0,0,0,0,0,0,0,0,0,0,0,0,0,0,0,0,0,0,0,0
0,0,0,0,0,0,0,0,0,0,0,0,0,0,0,0,0,0,0,0,0,0,0,0,0,0,0,0,0,0,0
0,0,0,0,0,0,0,0,0,0,0,0,0,0,0,0,0,0,0,0,0,0,0,0,0,0,0,0,0,0,0
0,0,0,0,0,0,0,0,0,0,0,0,0,0,0,0,0,0,0,0,0,0,0,0,0,0,0,0,0,0,0
0,0,0,0,0,0,0,0,0,0,0,0,0,0,0,0,0,0,0,0,0,0,0,0,0,0,0,0,0,0,0
0,0,0,0,0,0,0,0,0,0,0,0,0,0,0,0,0,0,0,0,0,0,0,0,0,0,0,0,0,0,0
0,0,0,0,0,0,0,0,0,0,0,0,0,0,0,0,0,0,0,0,0,0,0,0,0,0,0,0,0,0,0
:endlayer
layer: 39
0,0,0,0,0,0,0,0,0,0,0,0,0,0,0,0,0,0,0,0,0,0,0,0,0,0,0,0,0,0,0
0,0,0,0,0,0,0,0,0,0,0,0,0,0,0,0,0,0,0,0,0,0,0,0,0,0,0,0,0,0,0
0,0,0,0,0,0,0,0,0,0,0,0,0,0,0,0,0,0,0,0,0,0,0,0,0,0,0,0,0,0,0
0,0,0,0,0,0,0,0,0,0,0,0,0,0,0,0,0,0,0,0,0,0,0,0,0,0,0,0,0,0,0
0,0,0,0,0,0,0,0,0,0,0,0,0,0,0,0,0,0,0,0,0,0,0,0,0,0,0,0,0,0,0
0,0,0,0,0,0,0,0,0,0,0,0,0,0,0,0,0,0,0,0,0,0,0,0,0,0,0,0,0,0,0
0,0,0,0,0,0,0,0,0,0,0,0,0,0,0,0,0,0,0,0,0,0,0,0,0,0,0,0,0,0,0
0,0,0,0,0,0,0,0,0,0,0,0,0,0,0,0,0,0,0,0,0,0,0,0,0,0,0,0,0,0,0
0,0,0,0,0,0,0,0,0,0,0,0,0,0,0,0,0,0,0,0,0,0,0,0,0,0,0,0,0,0,0
0,0,0,0,0,0,0,0,131,0,0,0,0,0,0,0,0,0,0,0,0,0,0,0,0,0,0,0,0,0,0
0,0,0,0,0,0,0,0,0,0,0,0,0,0,0,0,0,0,0,0,0,0,0,0,0,0,0,0,0,0,0
0,0,0,0,0,0,0,0,0,0,0,0,0,0,0,0,0,0,0,0,0,0,0,0,0,0,0,0,0,0,0
0,0,0,0,0,0,0,0,0,0,0,0,0,0,0,0,0,0,0,0,0,0,0,0,0,0,0,0,0,0,0
0,0,0,0,0,0,0,0,0,0,0,0,0,0,0,0,0,0,0,0,0,0,0,0,0,0,0,0,0,0,0
0,0,0,0,0,0,0,0,0,0,0,0,0,0,0,0,0,0,0,0,0,0,0,0,0,0,0,0,0,0,0
0,0,0,0,0,0,0,0,0,0,0,0,0,0,0,0,0,0,0,0,0,0,0,0,0,0,0,0,0,0,0
0,0,0,0,0,0,0,0,0,0,0,0,0,0,0,0,0,0,0,0,0,0,0,0,0,0,0,0,0,0,0
0,0,0,0,0,0,0,0,0,0,0,0,0,0,0,0,0,0,0,0,0,0,0,0,0,0,0,0,0,0,0
0,0,0,0,0,0,0,0,0,0,0,0,0,0,0,0,0,0,0,0,0,0,0,0,0,0,0,0,0,0,0
0,0,0,0,0,0,0,0,0,0,0,0,0,0,0,0,0,0,0,0,0,0,0,0,0,0,0,0,0,0,0
0,0,0,0,0,0,0,0,0,0,0,0,0,0,0,0,0,0,0,0,0,0,0,0,0,0,0,0,0,0,0
0,0,0,0,0,0,0,0,0,0,0,0,0,0,0,0,0,0,0,0,0,0,0,0,0,0,0,0,0,0,0
:endlayer
layer: 40
0,0,0,0,0,0,0,0,0,0,0,0,0,0,0,0,0,0,0,0,0,0,0,0,0,0,0,0,0,0,0
0,0,0,0,0,0,0,0,0,0,0,0,0,0,0,0,0,0,0,0,0,0,0,0,0,0,0,0,0,0,0
0,0,0,0,0,0,0,0,0,0,0,0,0,0,0,0,0,0,0,0,0,0,0,0,0,0,0,0,0,0,0
0,0,0,0,0,0,0,0,0,0,0,0,0,0,0,0,0,0,0,0,0,0,0,0,0,0,0,0,0,0,0
0,0,0,0,0,0,0,0,0,0,0,0,0,0,0,0,0,0,0,0,0,0,0,0,0,0,0,0,0,0,0
0,0,0,0,0,0,0,0,0,0,0,0,0,0,0,0,0,0,0,0,0,0,0,0,0,0,0,0,0,0,0
0,0,0,0,0,0,0,0,0,0,0,0,0,0,0,0,0,0,0,0,0,0,0,0,0,0,0,0,0,0,0
0,0,0,0,0,0,0,0,0,0,0,0,0,0,0,0,0,0,0,0,0,0,0,0,0,0,0,0,0,0,0
0,0,0,0,0,0,0,0,131,0,0,0,0,0,0,0,0,0,0,0,0,0,0,0,0,0,0,0,0,0,0
0,0,0,0,0,0,0,131,131,131,0,0,0,0,0,0,0,0,0,0,0,0,0,0,0,0,0,0,0,0,0
0,0,0,0,0,0,0,0,131,0,0,0,0,0,0,0,0,0,0,0,0,0,0,0,0,0,0,0,0,0,0
0,0,0,0,0,0,0,0,0,0,0,0,0,0,0,0,0,0,0,0,0,0,0,0,0,0,0,0,0,0,0
0,0,0,0,0,0,0,0,0,0,0,0,0,0,0,0,0,0,0,0,0,0,0,0,0,0,0,0,0,0,0
0,0,0,0,0,0,0,0,0,0,0,0,0,0,0,0,0,0,0,0,0,0,0,0,0,0,0,0,0,0,0
0,0,0,0,0,0,0,0,0,0,0,0,0,0,0,0,0,0,0,0,0,0,0,0,0,0,0,0,0,0,0
0,0,0,0,0,0,0,0,0,0,0,0,0,0,0,0,0,0,0,0,0,0,0,0,0,0,0,0,0,0,0
0,0,0,0,0,0,0,0,0,0,0,0,0,0,0,0,0,0,0,0,0,0,0,0,0,0,0,0,0,0,0
0,0,0,0,0,0,0,0,0,0,0,0,0,0,0,0,0,0,0,0,0,0,0,0,0,0,0,0,0,0,0
0,0,0,0,0,0,0,0,0,0,0,0,0,0,0,0,0,0,0,0,0,0,0,0,0,0,0,0,0,0,0
0,0,0,0,0,0,0,0,0,0,0,0,0,0,0,0,0,0,0,0,0,0,0,0,0,0,0,0,0,0,0
0,0,0,0,0,0,0,0,0,0,0,0,0,0,0,0,0,0,0,0,0,0,0,0,0,0,0,0,0,0,0
0,0,0,0,0,0,0,0,0,0,0,0,0,0,0,0,0,0,0,0,0,0,0,0,0,0,0,0,0,0,0
:endlayer
layer: 41
0,0,0,0,0,0,0,0,0,0,0,0,0,0,0,0,0,0,0,0,0,0,0,0,0,0,0,0,0,0,0
0,0,0,0,0,0,0,0,0,0,0,0,0,0,0,0,0,0,0,0,0,0,0,0,0,0,0,0,0,0,0
0,0,0,0,0,0,0,0,0,0,0,0,0,0,0,0,0,0,0,0,0,0,0,0,0,0,0,0,0,0,0
0,0,0,0,0,0,0,0,0,0,0,0,0,0,0,0,0,0,0,0,0,0,0,0,0,0,0,0,0,0,0
0,0,0,0,0,0,0,0,0,0,0,0,0,0,0,0,0,0,0,0,0,0,0,0,0,0,0,0,0,0,0
0,0,0,0,0,0,0,0,0,0,0,0,0,0,0,0,0,0,0,0,0,0,0,0,0,0,0,0,0,0,0
0,0,0,0,0,0,0,0,0,0,0,0,0,0,0,0,0,0,0,0,0,0,0,0,0,0,0,0,0,0,0
0,0,0,0,0,0,0,0,0,0,0,0,0,0,0,0,0,0,0,0,0,0,0,0,0,0,0,0,0,0,0
0,0,0,0,0,0,0,0,93,0,0,0,0,0,0,0,0,0,0,0,0,0,0,0,0,0,0,0,0,0,0
0,0,0,0,0,0,0,93,131,93,0,0,0,0,0,0,0,0,0,0,0,0,0,0,0,0,0,0,0,0,0
0,0,0,0,0,0,0,0,93,0,0,0,0,0,0,0,0,0,0,0,0,0,0,0,0,0,0,0,0,0,0
0,0,0,0,0,0,0,0,0,0,0,0,0,0,0,0,0,0,0,0,0,0,0,0,0,0,0,0,0,0,0
0,0,0,0,0,0,0,0,0,0,0,0,0,0,0,0,0,0,0,0,0,0,0,0,0,0,0,0,0,0,0
0,0,0,0,0,0,0,0,0,0,0,0,0,0,0,0,0,0,0,0,0,0,0,0,0,0,0,0,0,0,0
0,0,0,0,0,0,0,0,0,0,0,0,0,0,0,0,0,0,0,0,0,0,0,0,0,0,0,0,0,0,0
0,0,0,0,0,0,0,0,0,0,0,0,0,0,0,0,0,0,0,0,0,0,0,0,0,0,0,0,0,0,0
0,0,0,0,0,0,0,0,0,0,0,0,0,0,0,0,0,0,0,0,0,0,0,0,0,0,0,0,0,0,0
0,0,0,0,0,0,0,0,0,0,0,0,0,0,0,0,0,0,0,0,0,0,0,0,0,0,0,0,0,0,0
0,0,0,0,0,0,0,0,0,0,0,0,0,0,0,0,0,0,0,0,0,0,0,0,0,0,0,0,0,0,0
0,0,0,0,0,0,0,0,0,0,0,0,0,0,0,0,0,0,0,0,0,0,0,0,0,0,0,0,0,0,0
0,0,0,0,0,0,0,0,0,0,0,0,0,0,0,0,0,0,0,0,0,0,0,0,0,0,0,0,0,0,0
0,0,0,0,0,0,0,0,0,0,0,0,0,0,0,0,0,0,0,0,0,0,0,0,0,0,0,0,0,0,0
:endlayer
layer: 42
0,0,0,0,0,0,0,0,0,0,0,0,0,0,0,0,0,0,0,0,0,0,0,0,0,0,0,0,0,0,0
0,0,0,0,0,0,0,0,0,0,0,0,0,0,0,0,0,0,0,0,0,0,0,0,0,0,0,0,0,0,0
0,0,0,0,0,0,0,0,0,0,0,0,0,0,0,0,0,0,0,0,0,0,0,0,0,0,0,0,0,0,0
0,0,0,0,0,0,0,0,0,0,0,0,0,0,0,0,0,0,0,0,0,0,0,0,0,0,0,0,0,0,0
0,0,0,0,0,0,0,0,0,0,0,0,0,0,0,0,0,0,0,0,0,0,0,0,0,0,0,0,0,0,0
0,0,0,0,0,0,0,0,0,0,0,0,0,0,0,0,0,0,0,0,0,0,0,0,0,0,0,0,0,0,0
0,0,0,0,0,0,0,0,0,0,0,0,0,0,0,0,0,0,0,0,0,0,0,0,0,0,0,0,0,0,0
0,0,0,0,0,0,0,0,0,0,0,0,0,0,0,0,0,0,0,0,0,0,0,0,0,0,0,0,0,0,0
0,0,0,0,0,0,0,0,0,0,0,0,0,0,0,0,0,0,0,0,0,0,0,0,0,0,0,0,0,0,0
0,0,0,0,0,0,0,0,131,0,0,0,0,0,0,0,0,0,0,0,0,0,0,0,0,0,0,0,0,0,0
0,0,0,0,0,0,0,0,0,0,0,0,0,0,0,0,0,0,0,0,0,0,0,0,0,0,0,0,0,0,0
0,0,0,0,0,0,0,0,0,0,0,0,0,0,0,0,0,0,0,0,0,0,0,0,0,0,0,0,0,0,0
0,0,0,0,0,0,0,0,0,0,0,0,0,0,0,0,0,0,0,0,0,0,0,0,0,0,0,0,0,0,0
0,0,0,0,0,0,0,0,0,0,0,0,0,0,0,0,0,0,0,0,0,0,0,0,0,0,0,0,0,0,0
0,0,0,0,0,0,0,0,0,0,0,0,0,0,0,0,0,0,0,0,0,0,0,0,0,0,0,0,0,0,0
0,0,0,0,0,0,0,0,0,0,0,0,0,0,0,0,0,0,0,0,0,0,0,0,0,0,0,0,0,0,0
0,0,0,0,0,0,0,0,0,0,0,0,0,0,0,0,0,0,0,0,0,0,0,0,0,0,0,0,0,0,0
0,0,0,0,0,0,0,0,0,0,0,0,0,0,0,0,0,0,0,0,0,0,0,0,0,0,0,0,0,0,0
0,0,0,0,0,0,0,0,0,0,0,0,0,0,0,0,0,0,0,0,0,0,0,0,0,0,0,0,0,0,0
0,0,0,0,0,0,0,0,0,0,0,0,0,0,0,0,0,0,0,0,0,0,0,0,0,0,0,0,0,0,0
0,0,0,0,0,0,0,0,0,0,0,0,0,0,0,0,0,0,0,0,0,0,0,0,0,0,0,0,0,0,0
0,0,0,0,0,0,0,0,0,0,0,0,0,0,0,0,0,0,0,0,0,0,0,0,0,0,0,0,0,0,0
:endlayer
layer: 43
0,0,0,0,0,0,0,0,0,0,0,0,0,0,0,0,0,0,0,0,0,0,0,0,0,0,0,0,0,0,0
0,0,0,0,0,0,0,0,0,0,0,0,0,0,0,0,0,0,0,0,0,0,0,0,0,0,0,0,0,0,0
0,0,0,0,0,0,0,0,0,0,0,0,0,0,0,0,0,0,0,0,0,0,0,0,0,0,0,0,0,0,0
0,0,0,0,0,0,0,0,0,0,0,0,0,0,0,0,0,0,0,0,0,0,0,0,0,0,0,0,0,0,0
0,0,0,0,0,0,0,0,0,0,0,0,0,0,0,0,0,0,0,0,0,0,0,0,0,0,0,0,0,0,0
0,0,0,0,0,0,0,0,0,0,0,0,0,0,0,0,0,0,0,0,0,0,0,0,0,0,0,0,0,0,0
0,0,0,0,0,0,0,0,0,0,0,0,0,0,0,0,0,0,0,0,0,0,0,0,0,0,0,0,0,0,0
0,0,0,0,0,0,0,0,0,0,0,0,0,0,0,0,0,0,0,0,0,0,0,0,0,0,0,0,0,0,0
0,0,0,0,0,0,0,0,0,0,0,0,0,0,0,0,0,0,0,0,0,0,0,0,0,0,0,0,0,0,0
0,0,0,0,0,0,0,0,93,0,0,0,0,0,0,0,0,0,0,0,0,0,0,0,0,0,0,0,0,0,0
0,0,0,0,0,0,0,0,0,0,0,0,0,0,0,0,0,0,0,0,0,0,0,0,0,0,0,0,0,0,0
0,0,0,0,0,0,0,0,0,0,0,0,0,0,0,0,0,0,0,0,0,0,0,0,0,0,0,0,0,0,0
0,0,0,0,0,0,0,0,0,0,0,0,0,0,0,0,0,0,0,0,0,0,0,0,0,0,0,0,0,0,0
0,0,0,0,0,0,0,0,0,0,0,0,0,0,0,0,0,0,0,0,0,0,0,0,0,0,0,0,0,0,0
0,0,0,0,0,0,0,0,0,0,0,0,0,0,0,0,0,0,0,0,0,0,0,0,0,0,0,0,0,0,0
0,0,0,0,0,0,0,0,0,0,0,0,0,0,0,0,0,0,0,0,0,0,0,0,0,0,0,0,0,0,0
0,0,0,0,0,0,0,0,0,0,0,0,0,0,0,0,0,0,0,0,0,0,0,0,0,0,0,0,0,0,0
0,0,0,0,0,0,0,0,0,0,0,0,0,0,0,0,0,0,0,0,0,0,0,0,0,0,0,0,0,0,0
0,0,0,0,0,0,0,0,0,0,0,0,0,0,0,0,0,0,0,0,0,0,0,0,0,0,0,0,0,0,0
0,0,0,0,0,0,0,0,0,0,0,0,0,0,0,0,0,0,0,0,0,0,0,0,0,0,0,0,0,0,0
0,0,0,0,0,0,0,0,0,0,0,0,0,0,0,0,0,0,0,0,0,0,0,0,0,0,0,0,0,0,0
0,0,0,0,0,0,0,0,0,0,0,0,0,0,0,0,0,0,0,0,0,0,0,0,0,0,0,0,0,0,0
:endlayer
layer: 44
0,0,0,0,0,0,0,0,0,0,0,0,0,0,0,0,0,0,0,0,0,0,0,0,0,0,0,0,0,0,0
0,0,0,0,0,0,0,0,0,0,0,0,0,0,0,0,0,0,0,0,0,0,0,0,0,0,0,0,0,0,0
0,0,0,0,0,0,0,0,0,0,0,0,0,0,0,0,0,0,0,0,0,0,0,0,0,0,0,0,0,0,0
0,0,0,0,0,0,0,0,0,0,0,0,0,0,0,0,0,0,0,0,0,0,0,0,0,0,0,0,0,0,0
0,0,0,0,0,0,0,0,0,0,0,0,0,0,0,0,0,0,0,0,0,0,0,0,0,0,0,0,0,0,0
0,0,0,0,0,0,0,0,0,0,0,0,0,0,0,0,0,0,0,0,0,0,0,0,0,0,0,0,0,0,0
0,0,0,0,0,0,0,0,0,0,0,0,0,0,0,0,0,0,0,0,0,0,0,0,0,0,0,0,0,0,0
0,0,0,0,0,0,0,0,0,0,0,0,0,0,0,0,0,0,0,0,0,0,0,0,0,0,0,0,0,0,0
0,0,0,0,0,0,0,0,0,0,0,0,0,0,0,0,0,0,0,0,0,0,0,0,0,0,0,0,0,0,0
0,0,0,0,0,0,0,0,0,0,0,0,0,0,0,0,0,0,0,0,0,0,0,0,0,0,0,0,0,0,0
0,0,0,0,0,0,0,0,0,0,0,0,0,0,0,0,0,0,0,0,0,0,0,0,0,0,0,0,0,0,0
0,0,0,0,0,0,0,0,0,0,0,0,0,0,0,0,0,0,0,0,0,0,0,0,0,0,0,0,0,0,0
0,0,0,0,0,0,0,0,0,0,0,0,0,0,0,0,0,0,0,0,0,0,0,0,0,0,0,0,0,0,0
0,0,0,0,0,0,0,0,0,0,0,0,0,0,0,0,0,0,0,0,0,0,0,0,0,0,0,0,0,0,0
0,0,0,0,0,0,0,0,0,0,0,0,0,0,0,0,0,0,0,0,0,0,0,0,0,0,0,0,0,0,0
0,0,0,0,0,0,0,0,0,0,0,0,0,0,0,0,0,0,0,0,0,0,0,0,0,0,0,0,0,0,0
0,0,0,0,0,0,0,0,0,0,0,0,0,0,0,0,0,0,0,0,0,0,0,0,0,0,0,0,0,0,0
0,0,0,0,0,0,0,0,0,0,0,0,0,0,0,0,0,0,0,0,0,0,0,0,0,0,0,0,0,0,0
0,0,0,0,0,0,0,0,0,0,0,0,0,0,0,0,0,0,0,0,0,0,0,0,0,0,0,0,0,0,0
0,0,0,0,0,0,0,0,0,0,0,0,0,0,0,0,0,0,0,0,0,0,0,0,0,0,0,0,0,0,0
0,0,0,0,0,0,0,0,0,0,0,0,0,0,0,0,0,0,0,0,0,0,0,0,0,0,0,0,0,0,0
0,0,0,0,0,0,0,0,0,0,0,0,0,0,0,0,0,0,0,0,0,0,0,0,0,0,0,0,0,0,0
:endlayer
layer: 45
0,0,0,0,0,0,0,0,0,0,0,0,0,0,0,0,0,0,0,0,0,0,0,0,0,0,0,0,0,0,0
0,0,0,0,0,0,0,0,0,0,0,0,0,0,0,0,0,0,0,0,0,0,0,0,0,0,0,0,0,0,0
0,0,0,0,0,0,0,0,0,0,0,0,0,0,0,0,0,0,0,0,0,0,0,0,0,0,0,0,0,0,0
0,0,0,0,0,0,0,0,0,0,0,0,0,0,0,0,0,0,0,0,0,0,0,0,0,0,0,0,0,0,0
0,0,0,0,0,0,0,0,0,0,0,0,0,0,0,0,0,0,0,0,0,0,0,0,0,0,0,0,0,0,0
0,0,0,0,0,0,0,0,0,0,0,0,0,0,0,0,0,0,0,0,0,0,0,0,0,0,0,0,0,0,0
0,0,0,0,0,0,0,0,0,0,0,0,0,0,0,0,0,0,0,0,0,0,0,0,0,0,0,0,0,0,0
0,0,0,0,0,0,0,0,0,0,0,0,0,0,0,0,0,0,0,0,0,0,0,0,0,0,0,0,0,0,0
0,0,0,0,0,0,0,0,0,0,0,0,0,0,0,0,0,0,0,0,0,0,0,0,0,0,0,0,0,0,0
0,0,0,0,0,0,0,0,0,0,0,0,0,0,0,0,0,0,0,0,0,0,0,0,0,0,0,0,0,0,0
0,0,0,0,0,0,0,0,0,0,0,0,0,0,0,0,0,0,0,0,0,0,0,0,0,0,0,0,0,0,0
0,0,0,0,0,0,0,0,0,0,0,0,0,0,0,0,0,0,0,0,0,0,0,0,0,0,0,0,0,0,0
0,0,0,0,0,0,0,0,0,0,0,0,0,0,0,0,0,0,0,0,0,0,0,0,0,0,0,0,0,0,0
0,0,0,0,0,0,0,0,0,0,0,0,0,0,0,0,0,0,0,0,0,0,0,0,0,0,0,0,0,0,0
0,0,0,0,0,0,0,0,0,0,0,0,0,0,0,0,0,0,0,0,0,0,0,0,0,0,0,0,0,0,0
0,0,0,0,0,0,0,0,0,0,0,0,0,0,0,0,0,0,0,0,0,0,0,0,0,0,0,0,0,0,0
0,0,0,0,0,0,0,0,0,0,0,0,0,0,0,0,0,0,0,0,0,0,0,0,0,0,0,0,0,0,0
0,0,0,0,0,0,0,0,0,0,0,0,0,0,0,0,0,0,0,0,0,0,0,0,0,0,0,0,0,0,0
0,0,0,0,0,0,0,0,0,0,0,0,0,0,0,0,0,0,0,0,0,0,0,0,0,0,0,0,0,0,0
0,0,0,0,0,0,0,0,0,0,0,0,0,0,0,0,0,0,0,0,0,0,0,0,0,0,0,0,0,0,0
0,0,0,0,0,0,0,0,0,0,0,0,0,0,0,0,0,0,0,0,0,0,0,0,0,0,0,0,0,0,0
0,0,0,0,0,0,0,0,0,0,0,0,0,0,0,0,0,0,0,0,0,0,0,0,0,0,0,0,0,0,0
:endlayer
layer: 46
0,0,0,0,0,0,0,0,0,0,0,0,0,0,0,0,0,0,0,0,0,0,0,0,0,0,0,0,0,0,0
0,0,0,0,0,0,0,0,0,0,0,0,0,0,0,0,0,0,0,0,0,0,0,0,0,0,0,0,0,0,0
0,0,0,0,0,0,0,0,0,0,0,0,0,0,0,0,0,0,0,0,0,0,0,0,0,0,0,0,0,0,0
0,0,0,0,0,0,0,0,0,0,0,0,0,0,0,0,0,0,0,0,0,0,0,0,0,0,0,0,0,0,0
0,0,0,0,0,0,0,0,0,0,0,0,0,0,0,0,0,0,0,0,0,0,0,0,0,0,0,0,0,0,0
0,0,0,0,0,0,0,0,0,0,0,0,0,0,0,0,0,0,0,0,0,0,0,0,0,0,0,0,0,0,0
0,0,0,0,0,0,0,0,0,0,0,0,0,0,0,0,0,0,0,0,0,0,0,0,0,0,0,0,0,0,0
0,0,0,0,0,0,0,0,0,0,0,0,0,0,0,0,0,0,0,0,0,0,0,0,0,0,0,0,0,0,0
0,0,0,0,0,0,0,0,0,0,0,0,0,0,0,0,0,0,0,0,0,0,0,0,0,0,0,0,0,0,0
0,0,0,0,0,0,0,0,0,0,0,0,0,0,0,0,0,0,0,0,0,0,0,0,0,0,0,0,0,0,0
0,0,0,0,0,0,0,0,0,0,0,0,0,0,0,0,0,0,0,0,0,0,0,0,0,0,0,0,0,0,0
0,0,0,0,0,0,0,0,0,0,0,0,0,0,0,0,0,0,0,0,0,0,0,0,0,0,0,0,0,0,0
0,0,0,0,0,0,0,0,0,0,0,0,0,0,0,0,0,0,0,0,0,0,0,0,0,0,0,0,0,0,0
0,0,0,0,0,0,0,0,0,0,0,0,0,0,0,0,0,0,0,0,0,0,0,0,0,0,0,0,0,0,0
0,0,0,0,0,0,0,0,0,0,0,0,0,0,0,0,0,0,0,0,0,0,0,0,0,0,0,0,0,0,0
0,0,0,0,0,0,0,0,0,0,0,0,0,0,0,0,0,0,0,0,0,0,0,0,0,0,0,0,0,0,0
0,0,0,0,0,0,0,0,0,0,0,0,0,0,0,0,0,0,0,0,0,0,0,0,0,0,0,0,0,0,0
0,0,0,0,0,0,0,0,0,0,0,0,0,0,0,0,0,0,0,0,0,0,0,0,0,0,0,0,0,0,0
0,0,0,0,0,0,0,0,0,0,0,0,0,0,0,0,0,0,0,0,0,0,0,0,0,0,0,0,0,0,0
0,0,0,0,0,0,0,0,0,0,0,0,0,0,0,0,0,0,0,0,0,0,0,0,0,0,0,0,0,0,0
0,0,0,0,0,0,0,0,0,0,0,0,0,0,0,0,0,0,0,0,0,0,0,0,0,0,0,0,0,0,0
0,0,0,0,0,0,0,0,0,0,0,0,0,0,0,0,0,0,0,0,0,0,0,0,0,0,0,0,0,0,0
:endlayer
layer: 47
0,0,0,0,0,0,0,0,0,0,0,0,0,0,0,0,0,0,0,0,0,0,0,0,0,0,0,0,0,0,0
0,0,0,0,0,0,0,0,0,0,0,0,0,0,0,0,0,0,0,0,0,0,0,0,0,0,0,0,0,0,0
0,0,0,0,0,0,0,0,0,0,0,0,0,0,0,0,0,0,0,0,0,0,0,0,0,0,0,0,0,0,0
0,0,0,0,0,0,0,0,0,0,0,0,0,0,0,0,0,0,0,0,0,0,0,0,0,0,0,0,0,0,0
0,0,0,0,0,0,0,0,0,0,0,0,0,0,0,0,0,0,0,0,0,0,0,0,0,0,0,0,0,0,0
0,0,0,0,0,0,0,0,0,0,0,0,0,0,0,0,0,0,0,0,0,0,0,0,0,0,0,0,0,0,0
0,0,0,0,0,0,0,0,0,0,0,0,0,0,0,0,0,0,0,0,0,0,0,0,0,0,0,0,0,0,0
0,0,0,0,0,0,0,0,0,0,0,0,0,0,0,0,0,0,0,0,0,0,0,0,0,0,0,0,0,0,0
0,0,0,0,0,0,0,0,0,0,0,0,0,0,0,0,0,0,0,0,0,0,0,0,0,0,0,0,0,0,0
0,0,0,0,0,0,0,0,0,0,0,0,0,0,0,0,0,0,0,0,0,0,0,0,0,0,0,0,0,0,0
0,0,0,0,0,0,0,0,0,0,0,0,0,0,0,0,0,0,0,0,0,0,0,0,0,0,0,0,0,0,0
0,0,0,0,0,0,0,0,0,0,0,0,0,0,0,0,0,0,0,0,0,0,0,0,0,0,0,0,0,0,0
0,0,0,0,0,0,0,0,0,0,0,0,0,0,0,0,0,0,0,0,0,0,0,0,0,0,0,0,0,0,0
0,0,0,0,0,0,0,0,0,0,0,0,0,0,0,0,0,0,0,0,0,0,0,0,0,0,0,0,0,0,0
0,0,0,0,0,0,0,0,0,0,0,0,0,0,0,0,0,0,0,0,0,0,0,0,0,0,0,0,0,0,0
0,0,0,0,0,0,0,0,0,0,0,0,0,0,0,0,0,0,0,0,0,0,0,0,0,0,0,0,0,0,0
0,0,0,0,0,0,0,0,0,0,0,0,0,0,0,0,0,0,0,0,0,0,0,0,0,0,0,0,0,0,0
0,0,0,0,0,0,0,0,0,0,0,0,0,0,0,0,0,0,0,0,0,0,0,0,0,0,0,0,0,0,0
0,0,0,0,0,0,0,0,0,0,0,0,0,0,0,0,0,0,0,0,0,0,0,0,0,0,0,0,0,0,0
0,0,0,0,0,0,0,0,0,0,0,0,0,0,0,0,0,0,0,0,0,0,0,0,0,0,0,0,0,0,0
0,0,0,0,0,0,0,0,0,0,0,0,0,0,0,0,0,0,0,0,0,0,0,0,0,0,0,0,0,0,0
0,0,0,0,0,0,0,0,0,0,0,0,0,0,0,0,0,0,0,0,0,0,0,0,0,0,0,0,0,0,0
:endlayer
layer: 48
0,0,0,0,0,0,0,0,0,0,0,0,0,0,0,0,0,0,0,0,0,0,0,0,0,0,0,0,0,0,0
0,0,0,0,0,0,0,0,0,0,0,0,0,0,0,0,0,0,0,0,0,0,0,0,0,0,0,0,0,0,0
0,0,0,0,0,0,0,0,0,0,0,0,0,0,0,0,0,0,0,0,0,0,0,0,0,0,0,0,0,0,0
0,0,0,0,0,0,0,0,0,0,0,0,0,0,0,0,0,0,0,0,0,0,0,0,0,0,0,0,0,0,0
0,0,0,0,0,0,0,0,0,0,0,0,0,0,0,0,0,0,0,0,0,0,0,0,0,0,0,0,0,0,0
0,0,0,0,0,0,0,0,0,0,0,0,0,0,0,0,0,0,0,0,0,0,0,0,0,0,0,0,0,0,0
0,0,0,0,0,0,0,0,0,0,0,0,0,0,0,0,0,0,0,0,0,0,0,0,0,0,0,0,0,0,0
0,0,0,0,0,0,0,0,0,0,0,0,0,0,0,0,0,0,0,0,0,0,0,0,0,0,0,0,0,0,0
0,0,0,0,0,0,0,0,0,0,0,0,0,0,0,0,0,0,0,0,0,0,0,0,0,0,0,0,0,0,0
0,0,0,0,0,0,0,0,0,0,0,0,0,0,0,0,0,0,0,0,0,0,0,0,0,0,0,0,0,0,0
0,0,0,0,0,0,0,0,0,0,0,0,0,0,0,0,0,0,0,0,0,0,0,0,0,0,0,0,0,0,0
0,0,0,0,0,0,0,0,0,0,0,0,0,0,0,0,0,0,0,0,0,0,0,0,0,0,0,0,0,0,0
0,0,0,0,0,0,0,0,0,0,0,0,0,0,0,0,0,0,0,0,0,0,0,0,0,0,0,0,0,0,0
0,0,0,0,0,0,0,0,0,0,0,0,0,0,0,0,0,0,0,0,0,0,0,0,0,0,0,0,0,0,0
0,0,0,0,0,0,0,0,0,0,0,0,0,0,0,0,0,0,0,0,0,0,0,0,0,0,0,0,0,0,0
0,0,0,0,0,0,0,0,0,0,0,0,0,0,0,0,0,0,0,0,0,0,0,0,0,0,0,0,0,0,0
0,0,0,0,0,0,0,0,0,0,0,0,0,0,0,0,0,0,0,0,0,0,0,0,0,0,0,0,0,0,0
0,0,0,0,0,0,0,0,0,0,0,0,0,0,0,0,0,0,0,0,0,0,0,0,0,0,0,0,0,0,0
0,0,0,0,0,0,0,0,0,0,0,0,0,0,0,0,0,0,0,0,0,0,0,0,0,0,0,0,0,0,0
0,0,0,0,0,0,0,0,0,0,0,0,0,0,0,0,0,0,0,0,0,0,0,0,0,0,0,0,0,0,0
0,0,0,0,0,0,0,0,0,0,0,0,0,0,0,0,0,0,0,0,0,0,0,0,0,0,0,0,0,0,0
0,0,0,0,0,0,0,0,0,0,0,0,0,0,0,0,0,0,0,0,0,0,0,0,0,0,0,0,0,0,0
:endlayer
layer: 49
0,0,0,0,0,0,0,0,0,0,0,0,0,0,0,0,0,0,0,0,0,0,0,0,0,0,0,0,0,0,0
0,0,0,0,0,0,0,0,0,0,0,0,0,0,0,0,0,0,0,0,0,0,0,0,0,0,0,0,0,0,0
0,0,0,0,0,0,0,0,0,0,0,0,0,0,0,0,0,0,0,0,0,0,0,0,0,0,0,0,0,0,0
0,0,0,0,0,0,0,0,0,0,0,0,0,0,0,0,0,0,0,0,0,0,0,0,0,0,0,0,0,0,0
0,0,0,0,0,0,0,0,0,0,0,0,0,0,0,0,0,0,0,0,0,0,0,0,0,0,0,0,0,0,0
0,0,0,0,0,0,0,0,0,0,0,0,0,0,0,0,0,0,0,0,0,0,0,0,0,0,0,0,0,0,0
0,0,0,0,0,0,0,0,0,0,0,0,0,0,0,0,0,0,0,0,0,0,0,0,0,0,0,0,0,0,0
0,0,0,0,0,0,0,0,0,0,0,0,0,0,0,0,0,0,0,0,0,0,0,0,0,0,0,0,0,0,0
0,0,0,0,0,0,0,0,0,0,0,0,0,0,0,0,0,0,0,0,0,0,0,0,0,0,0,0,0,0,0
0,0,0,0,0,0,0,0,0,0,0,0,0,0,0,0,0,0,0,0,0,0,0,0,0,0,0,0,0,0,0
0,0,0,0,0,0,0,0,0,0,0,0,0,0,0,0,0,0,0,0,0,0,0,0,0,0,0,0,0,0,0
0,0,0,0,0,0,0,0,0,0,0,0,0,0,0,0,0,0,0,0,0,0,0,0,0,0,0,0,0,0,0
0,0,0,0,0,0,0,0,0,0,0,0,0,0,0,0,0,0,0,0,0,0,0,0,0,0,0,0,0,0,0
0,0,0,0,0,0,0,0,0,0,0,0,0,0,0,0,0,0,0,0,0,0,0,0,0,0,0,0,0,0,0
0,0,0,0,0,0,0,0,0,0,0,0,0,0,0,0,0,0,0,0,0,0,0,0,0,0,0,0,0,0,0
0,0,0,0,0,0,0,0,0,0,0,0,0,0,0,0,0,0,0,0,0,0,0,0,0,0,0,0,0,0,0
0,0,0,0,0,0,0,0,0,0,0,0,0,0,0,0,0,0,0,0,0,0,0,0,0,0,0,0,0,0,0
0,0,0,0,0,0,0,0,0,0,0,0,0,0,0,0,0,0,0,0,0,0,0,0,0,0,0,0,0,0,0
0,0,0,0,0,0,0,0,0,0,0,0,0,0,0,0,0,0,0,0,0,0,0,0,0,0,0,0,0,0,0
0,0,0,0,0,0,0,0,0,0,0,0,0,0,0,0,0,0,0,0,0,0,0,0,0,0,0,0,0,0,0
0,0,0,0,0,0,0,0,0,0,0,0,0,0,0,0,0,0,0,0,0,0,0,0,0,0,0,0,0,0,0
0,0,0,0,0,0,0,0,0,0,0,0,0,0,0,0,0,0,0,0,0,0,0,0,0,0,0,0,0,0,0
:endlayer
layer: 50
0,0,0,0,0,0,0,0,0,0,0,0,0,0,0,0,0,0,0,0,0,0,0,0,0,0,0,0,0,0,0
0,0,0,0,0,0,0,0,0,0,0,0,0,0,0,0,0,0,0,0,0,0,0,0,0,0,0,0,0,0,0
0,0,0,0,0,0,0,0,0,0,0,0,0,0,0,0,0,0,0,0,0,0,0,0,0,0,0,0,0,0,0
0,0,0,0,0,0,0,0,0,0,0,0,0,0,0,0,0,0,0,0,0,0,0,0,0,0,0,0,0,0,0
0,0,0,0,0,0,0,0,0,0,0,0,0,0,0,0,0,0,0,0,0,0,0,0,0,0,0,0,0,0,0
0,0,0,0,0,0,0,0,0,0,0,0,0,0,0,0,0,0,0,0,0,0,0,0,0,0,0,0,0,0,0
0,0,0,0,0,0,0,0,0,0,0,0,0,0,0,0,0,0,0,0,0,0,0,0,0,0,0,0,0,0,0
0,0,0,0,0,0,0,0,0,0,0,0,0,0,0,0,0,0,0,0,0,0,0,0,0,0,0,0,0,0,0
0,0,0,0,0,0,0,0,0,0,0,0,0,0,0,0,0,0,0,0,0,0,0,0,0,0,0,0,0,0,0
0,0,0,0,0,0,0,0,0,0,0,0,0,0,0,0,0,0,0,0,0,0,0,0,0,0,0,0,0,0,0
0,0,0,0,0,0,0,0,0,0,0,0,0,0,0,0,0,0,0,0,0,0,0,0,0,0,0,0,0,0,0
0,0,0,0,0,0,0,0,0,0,0,0,0,0,0,0,0,0,0,0,0,0,0,0,0,0,0,0,0,0,0
0,0,0,0,0,0,0,0,0,0,0,0,0,0,0,0,0,0,0,0,0,0,0,0,0,0,0,0,0,0,0
0,0,0,0,0,0,0,0,0,0,0,0,0,0,0,0,0,0,0,0,0,0,0,0,0,0,0,0,0,0,0
0,0,0,0,0,0,0,0,0,0,0,0,0,0,0,0,0,0,0,0,0,0,0,0,0,0,0,0,0,0,0
0,0,0,0,0,0,0,0,0,0,0,0,0,0,0,0,0,0,0,0,0,0,0,0,0,0,0,0,0,0,0
0,0,0,0,0,0,0,0,0,0,0,0,0,0,0,0,0,0,0,0,0,0,0,0,0,0,0,0,0,0,0
0,0,0,0,0,0,0,0,0,0,0,0,0,0,0,0,0,0,0,0,0,0,0,0,0,0,0,0,0,0,0
0,0,0,0,0,0,0,0,0,0,0,0,0,0,0,0,0,0,0,0,0,0,0,0,0,0,0,0,0,0,0
0,0,0,0,0,0,0,0,0,0,0,0,0,0,0,0,0,0,0,0,0,0,0,0,0,0,0,0,0,0,0
0,0,0,0,0,0,0,0,0,0,0,0,0,0,0,0,0,0,0,0,0,0,0,0,0,0,0,0,0,0,0
0,0,0,0,0,0,0,0,0,0,0,0,0,0,0,0,0,0,0,0,0,0,0,0,0,0,0,0,0,0,0
:endlayer
layer: 51
0,0,0,0,0,0,0,0,0,0,0,0,0,0,0,0,0,0,0,0,0,0,0,0,0,0,0,0,0,0,0
0,0,0,0,0,0,0,0,0,0,0,0,0,0,0,0,0,0,0,0,0,0,0,0,0,0,0,0,0,0,0
0,0,0,0,0,0,0,0,0,0,0,0,0,0,0,0,0,0,0,0,0,0,0,0,0,0,0,0,0,0,0
0,0,0,0,0,0,0,0,0,0,0,0,0,0,0,0,0,0,0,0,0,0,0,0,0,0,0,0,0,0,0
0,0,0,0,0,0,0,0,0,0,0,0,0,0,0,0,0,0,0,0,0,0,0,0,0,0,0,0,0,0,0
0,0,0,0,0,0,0,0,0,0,0,0,0,0,0,0,0,0,0,0,0,0,0,0,0,0,0,0,0,0,0
0,0,0,0,0,0,0,0,0,0,0,0,0,0,0,0,0,0,0,0,0,0,0,0,0,0,0,0,0,0,0
0,0,0,0,0,0,0,0,0,0,0,0,0,0,0,0,0,0,0,0,0,0,0,0,0,0,0,0,0,0,0
0,0,0,0,0,0,0,0,0,0,0,0,0,0,0,0,0,0,0,0,0,0,0,0,0,0,0,0,0,0,0
0,0,0,0,0,0,0,0,0,0,0,0,0,0,0,0,0,0,0,0,0,0,0,0,0,0,0,0,0,0,0
0,0,0,0,0,0,0,0,0,0,0,0,0,0,0,0,0,0,0,0,0,0,0,0,0,0,0,0,0,0,0
0,0,0,0,0,0,0,0,0,0,0,0,0,0,0,0,0,0,0,0,0,0,0,0,0,0,0,0,0,0,0
0,0,0,0,0,0,0,0,0,0,0,0,0,0,0,0,0,0,0,0,0,0,0,0,0,0,0,0,0,0,0
0,0,0,0,0,0,0,0,0,0,0,0,0,0,0,0,0,0,0,0,0,0,0,0,0,0,0,0,0,0,0
0,0,0,0,0,0,0,0,0,0,0,0,0,0,0,0,0,0,0,0,0,0,0,0,0,0,0,0,0,0,0
0,0,0,0,0,0,0,0,0,0,0,0,0,0,0,0,0,0,0,0,0,0,0,0,0,0,0,0,0,0,0
0,0,0,0,0,0,0,0,0,0,0,0,0,0,0,0,0,0,0,0,0,0,0,0,0,0,0,0,0,0,0
0,0,0,0,0,0,0,0,0,0,0,0,0,0,0,0,0,0,0,0,0,0,0,0,0,0,0,0,0,0,0
0,0,0,0,0,0,0,0,0,0,0,0,0,0,0,0,0,0,0,0,0,0,0,0,0,0,0,0,0,0,0
0,0,0,0,0,0,0,0,0,0,0,0,0,0,0,0,0,0,0,0,0,0,0,0,0,0,0,0,0,0,0
0,0,0,0,0,0,0,0,0,0,0,0,0,0,0,0,0,0,0,0,0,0,0,0,0,0,0,0,0,0,0
0,0,0,0,0,0,0,0,0,0,0,0,0,0,0,0,0,0,0,0,0,0,0,0,0,0,0,0,0,0,0
:endlayer

#### RULES ####
rule:
plugin=modBlockDefault
number=1
data:
JSON:{{"val":{"blockName":{"val":"UndergroundBiomes:metamorphicStone","id":"ss"},"meta":{"val":"1","id":"pi"}},"id":"ct"}}
:enddata
:endrule

rule:
plugin=vanillaBlocks
number=2
data:
JSON:{{"val":{"buildPass":{"val":"0","id":"pi"},"blockName":{"val":"minecraft:stonebrick","id":"ss"},"meta":{"val":"0","id":"pi"}},"id":"ct"}}
:enddata
:endrule

rule:
plugin=vanillaBlocks
number=3
data:
JSON:{{"val":{"buildPass":{"val":"0","id":"pi"},"blockName":{"val":"minecraft:sandstone","id":"ss"},"meta":{"val":"0","id":"pi"}},"id":"ct"}}
:enddata
:endrule

rule:
plugin=vanillaInventory
number=4
data:
JSON:{{"val":{"buildPass":{"val":"0","id":"pi"},"blockName":{"val":"minecraft:chest","id":"ss"},"meta":{"val":"2","id":"pi"},"lootLevel":{"val":"0","id":"pi"},"teData":{"val":{"x":{"val":"221","id":"pi"},"y":{"val":"63","id":"pi"},"z":{"val":"442","id":"pi"},"id":{"val":"Chest","id":"ss"}},"id":"ct"},"inventoryData":{"val":{"length":{"val":"27","id":"pi"},"inventoryContents":{"val":[{"val":{"damage":{"val":"0","id":"pi"},"item":{"val":"AncientWarfareNpc:npc_spawner","id":"ss"},"quantity":{"val":"1","id":"pi"},"stackTag":{"val":{"npcSubtype":{"val":"","id":"ss"},"npcType":{"val":"worker","id":"ss"}},"id":"ct"},"slot":{"val":"3","id":"pi"}},"id":"ct"},{"val":{"damage":{"val":"0","id":"pi"},"item":{"val":"AncientWarfareNpc:npc_spawner","id":"ss"},"quantity":{"val":"1","id":"pi"},"stackTag":{"val":{"npcSubtype":{"val":"","id":"ss"},"npcType":{"val":"worker","id":"ss"}},"id":"ct"},"slot":{"val":"6","id":"pi"}},"id":"ct"}],"id":"ls"}},"id":"ct"}},"id":"ct"}}
:enddata
:endrule

rule:
plugin=vanillaInventory
number=5
data:
JSON:{{"val":{"buildPass":{"val":"0","id":"pi"},"blockName":{"val":"minecraft:chest","id":"ss"},"meta":{"val":"2","id":"pi"},"lootLevel":{"val":"0","id":"pi"},"teData":{"val":{"x":{"val":"221","id":"pi"},"y":{"val":"63","id":"pi"},"z":{"val":"443","id":"pi"},"id":{"val":"Chest","id":"ss"}},"id":"ct"},"inventoryData":{"val":{"length":{"val":"27","id":"pi"},"inventoryContents":{"val":[{"val":{"damage":{"val":"0","id":"pi"},"item":{"val":"GraveStone:Corpse","id":"ss"},"quantity":{"val":"1","id":"pi"},"stackTag":{"val":{"VillagerType":{"val":"6156","id":"pi"}},"id":"ct"},"slot":{"val":"0","id":"pi"}},"id":"ct"},{"val":{"damage":{"val":"0","id":"pi"},"item":{"val":"GraveStone:Corpse","id":"ss"},"quantity":{"val":"1","id":"pi"},"stackTag":{"val":{"VillagerType":{"val":"385","id":"pi"}},"id":"ct"},"slot":{"val":"1","id":"pi"}},"id":"ct"},{"val":{"damage":{"val":"0","id":"pi"},"item":{"val":"GraveStone:Corpse","id":"ss"},"quantity":{"val":"1","id":"pi"},"stackTag":{"val":{"VillagerType":{"val":"2","id":"pi"}},"id":"ct"},"slot":{"val":"2","id":"pi"}},"id":"ct"},{"val":{"damage":{"val":"0","id":"pi"},"item":{"val":"GraveStone:Corpse","id":"ss"},"quantity":{"val":"1","id":"pi"},"stackTag":{"val":{"VillagerType":{"val":"1","id":"pi"}},"id":"ct"},"slot":{"val":"3","id":"pi"}},"id":"ct"},{"val":{"damage":{"val":"0","id":"pi"},"item":{"val":"GraveStone:Corpse","id":"ss"},"quantity":{"val":"1","id":"pi"},"stackTag":{"val":{"VillagerType":{"val":"0","id":"pi"}},"id":"ct"},"slot":{"val":"4","id":"pi"}},"id":"ct"}],"id":"ls"}},"id":"ct"}},"id":"ct"}}
:enddata
:endrule

rule:
plugin=vanillaBlocks
number=6
data:
JSON:{{"val":{"buildPass":{"val":"0","id":"pi"},"blockName":{"val":"minecraft:sand","id":"ss"},"meta":{"val":"0","id":"pi"}},"id":"ct"}}
:enddata
:endrule

rule:
plugin=vanillaBlocks
number=7
data:
JSON:{{"val":{"buildPass":{"val":"0","id":"pi"},"blockName":{"val":"minecraft:dirt","id":"ss"},"meta":{"val":"0","id":"pi"}},"id":"ct"}}
:enddata
:endrule

rule:
plugin=vanillaBlocks
number=8
data:
JSON:{{"val":{"buildPass":{"val":"0","id":"pi"},"blockName":{"val":"minecraft:web","id":"ss"},"meta":{"val":"0","id":"pi"}},"id":"ct"}}
:enddata
:endrule

rule:
plugin=vanillaInventory
number=9
data:
JSON:{{"val":{"buildPass":{"val":"0","id":"pi"},"blockName":{"val":"minecraft:chest","id":"ss"},"meta":{"val":"4","id":"pi"},"lootLevel":{"val":"0","id":"pi"},"teData":{"val":{"x":{"val":"215","id":"pi"},"y":{"val":"64","id":"pi"},"z":{"val":"423","id":"pi"},"id":{"val":"Chest","id":"ss"}},"id":"ct"},"inventoryData":{"val":{"length":{"val":"27","id":"pi"},"inventoryContents":{"val":[{"val":{"damage":{"val":"6","id":"pi"},"item":{"val":"EnderIO:itemAlloy","id":"ss"},"quantity":{"val":"3","id":"pi"},"slot":{"val":"0","id":"pi"}},"id":"ct"},{"val":{"damage":{"val":"0","id":"pi"},"item":{"val":"minecraft:ender_pearl","id":"ss"},"quantity":{"val":"1","id":"pi"},"slot":{"val":"1","id":"pi"}},"id":"ct"},{"val":{"damage":{"val":"0","id":"pi"},"item":{"val":"rftools:unknownDimlet","id":"ss"},"quantity":{"val":"2","id":"pi"},"slot":{"val":"4","id":"pi"}},"id":"ct"},{"val":{"damage":{"val":"0","id":"pi"},"item":{"val":"harvestcraft:beefwellingtonItem","id":"ss"},"quantity":{"val":"2","id":"pi"},"slot":{"val":"6","id":"pi"}},"id":"ct"},{"val":{"damage":{"val":"0","id":"pi"},"item":{"val":"minecraft:wheat","id":"ss"},"quantity":{"val":"4","id":"pi"},"slot":{"val":"9","id":"pi"}},"id":"ct"},{"val":{"damage":{"val":"0","id":"pi"},"item":{"val":"minecraft:name_tag","id":"ss"},"quantity":{"val":"1","id":"pi"},"slot":{"val":"12","id":"pi"}},"id":"ct"},{"val":{"damage":{"val":"0","id":"pi"},"item":{"val":"minecraft:name_tag","id":"ss"},"quantity":{"val":"1","id":"pi"},"slot":{"val":"15","id":"pi"}},"id":"ct"},{"val":{"damage":{"val":"10","id":"pi"},"item":{"val":"RotaryCraft:rotarycraft_item_shaftcraft","id":"ss"},"quantity":{"val":"1","id":"pi"},"slot":{"val":"17","id":"pi"}},"id":"ct"}],"id":"ls"}},"id":"ct"}},"id":"ct"}}
:enddata
:endrule

rule:
plugin=vanillaInventory
number=10
data:
JSON:{{"val":{"buildPass":{"val":"0","id":"pi"},"blockName":{"val":"minecraft:chest","id":"ss"},"meta":{"val":"4","id":"pi"},"lootLevel":{"val":"0","id":"pi"},"teData":{"val":{"x":{"val":"217","id":"pi"},"y":{"val":"64","id":"pi"},"z":{"val":"423","id":"pi"},"id":{"val":"Chest","id":"ss"}},"id":"ct"},"inventoryData":{"val":{"length":{"val":"27","id":"pi"},"inventoryContents":{"val":[{"val":{"damage":{"val":"0","id":"pi"},"item":{"val":"minecraft:record_cat","id":"ss"},"quantity":{"val":"1","id":"pi"},"slot":{"val":"3","id":"pi"}},"id":"ct"},{"val":{"damage":{"val":"1","id":"pi"},"item":{"val":"Thaumcraft:ItemLootBag","id":"ss"},"quantity":{"val":"2","id":"pi"},"slot":{"val":"9","id":"pi"}},"id":"ct"},{"val":{"damage":{"val":"0","id":"pi"},"item":{"val":"rftools:unknownDimlet","id":"ss"},"quantity":{"val":"2","id":"pi"},"slot":{"val":"13","id":"pi"}},"id":"ct"},{"val":{"damage":{"val":"0","id":"pi"},"item":{"val":"minecraft:record_cat","id":"ss"},"quantity":{"val":"1","id":"pi"},"slot":{"val":"22","id":"pi"}},"id":"ct"},{"val":{"damage":{"val":"0","id":"pi"},"item":{"val":"harvestcraft:ploughmanslunchItem","id":"ss"},"quantity":{"val":"2","id":"pi"},"slot":{"val":"23","id":"pi"}},"id":"ct"}],"id":"ls"}},"id":"ct"}},"id":"ct"}}
:enddata
:endrule

rule:
plugin=vanillaLogic
number=11
data:
JSON:{{"val":{"buildPass":{"val":"0","id":"pi"},"blockName":{"val":"GraveStone:GSHauntedChest","id":"ss"},"meta":{"val":"5","id":"pi"},"teData":{"val":{"id":{"val":"GSHauntedChest","id":"ss"},"ChestType":{"val":"0","id":"pb"}},"id":"ct"}},"id":"ct"}}
:enddata
:endrule

rule:
plugin=vanillaLogic
number=12
data:
JSON:{{"val":{"buildPass":{"val":"0","id":"pi"},"blockName":{"val":"GraveStone:GSHauntedChest","id":"ss"},"meta":{"val":"5","id":"pi"},"teData":{"val":{"id":{"val":"GSHauntedChest","id":"ss"},"ChestType":{"val":"1","id":"pb"}},"id":"ct"}},"id":"ct"}}
:enddata
:endrule

rule:
plugin=vanillaLogic
number=13
data:
JSON:{{"val":{"buildPass":{"val":"0","id":"pi"},"blockName":{"val":"yegamolchattels:loot_chest","id":"ss"},"meta":{"val":"0","id":"pi"},"teData":{"val":{"lockFall":{"val":"5.0E-4","id":"pf"},"lockFrame":{"val":"0.0","id":"pf"},"chestFrame":{"val":"0.0","id":"pf"},"closed":{"val":"1","id":"pb"},"opened":{"val":"0","id":"pb"},"id":{"val":"ygcLootChest","id":"ss"},"items":{"val":[{"val":{"id":{"val":"322","id":"ps"},"Count":{"val":"1","id":"pb"},"Damage":{"val":"1","id":"ps"}},"id":"ct"}],"id":"ls"},"lockAccel":{"val":"1.0","id":"pf"},"direction":{"val":"0","id":"pi"}},"id":"ct"}},"id":"ct"}}
:enddata
:endrule

rule:
plugin=vanillaLogic
number=14
data:
JSON:{{"val":{"buildPass":{"val":"0","id":"pi"},"blockName":{"val":"reccomplex:spawn_script","id":"ss"},"meta":{"val":"0","id":"pi"},"teData":{"val":{"id":{"val":"RCSpawnScript","id":"ss"},"script":{"val":{"scripts":{"val":[{"val":{"id":{"val":"command","id":"ss"},"script":{"val":{"commands":{"val":[{"val":{"weight":{"val":"1.0","id":"pd"},"command":{"val":"/setblock ~ ~ ~ mob_spawner 0 replace {EntityId:Bat}","id":"ss"}},"id":"ct"}],"id":"ls"}},"id":"ct"}},"id":"ct"}],"id":"ls"}},"id":"ct"}},"id":"ct"}},"id":"ct"}}
:enddata
:endrule

rule:
plugin=vanillaLogic
number=15
data:
JSON:{{"val":{"buildPass":{"val":"0","id":"pi"},"blockName":{"val":"GraveStone:GSPileOfBones","id":"ss"},"meta":{"val":"1","id":"pi"},"teData":{"val":{"id":{"val":"GSPileOfBones","id":"ss"},"Direction":{"val":"3","id":"pb"}},"id":"ct"}},"id":"ct"}}
:enddata
:endrule

rule:
plugin=vanillaLogic
number=16
data:
JSON:{{"val":{"buildPass":{"val":"0","id":"pi"},"blockName":{"val":"GraveStone:GSSpawner","id":"ss"},"meta":{"val":"2","id":"pi"},"teData":{"val":{"id":{"val":"GSSpawner","id":"ss"}},"id":"ct"}},"id":"ct"}}
:enddata
:endrule

rule:
plugin=vanillaBlocks
number=17
data:
JSON:{{"val":{"buildPass":{"val":"0","id":"pi"},"blockName":{"val":"minecraft:stone_brick_stairs","id":"ss"},"meta":{"val":"3","id":"pi"}},"id":"ct"}}
:enddata
:endrule

rule:
plugin=vanillaLogic
number=18
data:
JSON:{{"val":{"buildPass":{"val":"0","id":"pi"},"blockName":{"val":"GraveStone:GSMemorial","id":"ss"},"meta":{"val":"0","id":"pi"},"teData":{"val":{"isLocalized":{"val":"0","id":"pb"},"HangedMob":{"val":"0","id":"pb"},"DeathText":{"val":"","id":"ss"},"Enchanted":{"val":"0","id":"pb"},"HangedVillagerProfession":{"val":"0","id":"pi"},"id":{"val":"GSMemorial","id":"ss"},"GraveType":{"val":"116","id":"pb"}},"id":"ct"}},"id":"ct"}}
:enddata
:endrule

rule:
plugin=vanillaBlocks
number=19
data:
JSON:{{"val":{"buildPass":{"val":"0","id":"pi"},"blockName":{"val":"minecraft:stone_brick_stairs","id":"ss"},"meta":{"val":"1","id":"pi"}},"id":"ct"}}
:enddata
:endrule

rule:
plugin=vanillaLogic
number=20
data:
JSON:{{"val":{"buildPass":{"val":"0","id":"pi"},"blockName":{"val":"GraveStone:GSMemorial","id":"ss"},"meta":{"val":"3","id":"pi"},"teData":{"val":{"isLocalized":{"val":"0","id":"pb"},"HangedMob":{"val":"1","id":"pb"},"DeathText":{"val":"","id":"ss"},"Enchanted":{"val":"0","id":"pb"},"HangedVillagerProfession":{"val":"0","id":"pi"},"id":{"val":"GSMemorial","id":"ss"},"GraveType":{"val":"116","id":"pb"}},"id":"ct"}},"id":"ct"}}
:enddata
:endrule

rule:
plugin=vanillaLogic
number=21
data:
JSON:{{"val":{"buildPass":{"val":"0","id":"pi"},"blockName":{"val":"GraveStone:GSAltar","id":"ss"},"meta":{"val":"0","id":"pi"},"teData":{"val":{"id":{"val":"GSAltarTE","id":"ss"}},"id":"ct"}},"id":"ct"}}
:enddata
:endrule

rule:
plugin=vanillaBlocks
number=22
data:
JSON:{{"val":{"buildPass":{"val":"0","id":"pi"},"blockName":{"val":"minecraft:stone_slab","id":"ss"},"meta":{"val":"0","id":"pi"}},"id":"ct"}}
:enddata
:endrule

rule:
plugin=vanillaBlocks
number=23
data:
JSON:{{"val":{"buildPass":{"val":"0","id":"pi"},"blockName":{"val":"minecraft:stone_brick_stairs","id":"ss"},"meta":{"val":"0","id":"pi"}},"id":"ct"}}
:enddata
:endrule

rule:
plugin=vanillaInventory
number=24
data:
JSON:{{"val":{"buildPass":{"val":"0","id":"pi"},"blockName":{"val":"minecraft:chest","id":"ss"},"meta":{"val":"4","id":"pi"},"lootLevel":{"val":"0","id":"pi"},"teData":{"val":{"x":{"val":"230","id":"pi"},"y":{"val":"64","id":"pi"},"z":{"val":"434","id":"pi"},"id":{"val":"Chest","id":"ss"}},"id":"ct"},"inventoryData":{"val":{"length":{"val":"27","id":"pi"},"inventoryContents":{"val":[{"val":{"damage":{"val":"0","id":"pi"},"item":{"val":"rftools:unknownDimlet","id":"ss"},"quantity":{"val":"2","id":"pi"},"slot":{"val":"2","id":"pi"}},"id":"ct"},{"val":{"damage":{"val":"0","id":"pi"},"item":{"val":"minecraft:iron_ingot","id":"ss"},"quantity":{"val":"3","id":"pi"},"slot":{"val":"6","id":"pi"}},"id":"ct"},{"val":{"damage":{"val":"0","id":"pi"},"item":{"val":"minecraft:iron_ingot","id":"ss"},"quantity":{"val":"2","id":"pi"},"slot":{"val":"7","id":"pi"}},"id":"ct"},{"val":{"damage":{"val":"0","id":"pi"},"item":{"val":"minecraft:bucket","id":"ss"},"quantity":{"val":"1","id":"pi"},"slot":{"val":"8","id":"pi"}},"id":"ct"},{"val":{"damage":{"val":"2","id":"pi"},"item":{"val":"Thaumcraft:ItemBaubleBlanks","id":"ss"},"quantity":{"val":"1","id":"pi"},"slot":{"val":"9","id":"pi"}},"id":"ct"},{"val":{"damage":{"val":"0","id":"pi"},"item":{"val":"rftools:unknownDimlet","id":"ss"},"quantity":{"val":"1","id":"pi"},"slot":{"val":"10","id":"pi"}},"id":"ct"},{"val":{"damage":{"val":"0","id":"pi"},"item":{"val":"minecraft:record_cat","id":"ss"},"quantity":{"val":"1","id":"pi"},"slot":{"val":"11","id":"pi"}},"id":"ct"},{"val":{"damage":{"val":"0","id":"pi"},"item":{"val":"minecraft:wheat","id":"ss"},"quantity":{"val":"3","id":"pi"},"slot":{"val":"16","id":"pi"}},"id":"ct"},{"val":{"damage":{"val":"0","id":"pi"},"item":{"val":"minecraft:redstone","id":"ss"},"quantity":{"val":"4","id":"pi"},"slot":{"val":"17","id":"pi"}},"id":"ct"},{"val":{"damage":{"val":"0","id":"pi"},"item":{"val":"minecraft:gunpowder","id":"ss"},"quantity":{"val":"3","id":"pi"},"slot":{"val":"19","id":"pi"}},"id":"ct"},{"val":{"damage":{"val":"0","id":"pi"},"item":{"val":"rftools:unknownDimlet","id":"ss"},"quantity":{"val":"1","id":"pi"},"slot":{"val":"21","id":"pi"}},"id":"ct"},{"val":{"damage":{"val":"0","id":"pi"},"item":{"val":"minecraft:ender_pearl","id":"ss"},"quantity":{"val":"1","id":"pi"},"slot":{"val":"24","id":"pi"}},"id":"ct"},{"val":{"damage":{"val":"0","id":"pi"},"item":{"val":"EnderIO:item.darkSteel_sword","id":"ss"},"quantity":{"val":"1","id":"pi"},"slot":{"val":"26","id":"pi"}},"id":"ct"}],"id":"ls"}},"id":"ct"}},"id":"ct"}}
:enddata
:endrule

rule:
plugin=vanillaBlocks
number=25
data:
JSON:{{"val":{"buildPass":{"val":"0","id":"pi"},"blockName":{"val":"minecraft:stone_brick_stairs","id":"ss"},"meta":{"val":"2","id":"pi"}},"id":"ct"}}
:enddata
:endrule

rule:
plugin=vanillaLogic
number=26
data:
JSON:{{"val":{"buildPass":{"val":"0","id":"pi"},"blockName":{"val":"GraveStone:GSMemorial","id":"ss"},"meta":{"val":"2","id":"pi"},"teData":{"val":{"isLocalized":{"val":"0","id":"pb"},"HangedMob":{"val":"6","id":"pb"},"DeathText":{"val":"","id":"ss"},"Enchanted":{"val":"0","id":"pb"},"HangedVillagerProfession":{"val":"0","id":"pi"},"id":{"val":"GSMemorial","id":"ss"},"GraveType":{"val":"117","id":"pb"}},"id":"ct"}},"id":"ct"}}
:enddata
:endrule

rule:
plugin=vanillaLogic
number=27
data:
JSON:{{"val":{"buildPass":{"val":"0","id":"pi"},"blockName":{"val":"GraveStone:GSMemorial","id":"ss"},"meta":{"val":"1","id":"pi"},"teData":{"val":{"isLocalized":{"val":"0","id":"pb"},"HangedMob":{"val":"6","id":"pb"},"DeathText":{"val":"","id":"ss"},"Enchanted":{"val":"0","id":"pb"},"HangedVillagerProfession":{"val":"0","id":"pi"},"id":{"val":"GSMemorial","id":"ss"},"GraveType":{"val":"118","id":"pb"}},"id":"ct"}},"id":"ct"}}
:enddata
:endrule

rule:
plugin=vanillaLogic
number=28
data:
JSON:{{"val":{"buildPass":{"val":"0","id":"pi"},"blockName":{"val":"GraveStone:GSMemorial","id":"ss"},"meta":{"val":"3","id":"pi"},"teData":{"val":{"isLocalized":{"val":"0","id":"pb"},"HangedMob":{"val":"6","id":"pb"},"DeathText":{"val":"","id":"ss"},"Enchanted":{"val":"0","id":"pb"},"HangedVillagerProfession":{"val":"0","id":"pi"},"id":{"val":"GSMemorial","id":"ss"},"GraveType":{"val":"116","id":"pb"}},"id":"ct"}},"id":"ct"}}
:enddata
:endrule

rule:
plugin=vanillaBlocks
number=29
data:
JSON:{{"val":{"buildPass":{"val":"0","id":"pi"},"blockName":{"val":"minecraft:stone_slab","id":"ss"},"meta":{"val":"13","id":"pi"}},"id":"ct"}}
:enddata
:endrule

rule:
plugin=vanillaLogic
number=30
data:
JSON:{{"val":{"buildPass":{"val":"0","id":"pi"},"blockName":{"val":"EnderIO:blockDarkSteelPressurePlate","id":"ss"},"meta":{"val":"0","id":"pi"},"teData":{"val":{"silent":{"val":"0","id":"pb"},"sourceBlockMeta":{"val":"0","id":"pi"},"id":{"val":"blockDarkSteelPressurePlateTileEntity","id":"ss"}},"id":"ct"}},"id":"ct"}}
:enddata
:endrule

rule:
plugin=vanillaDoors
number=31
data:
JSON:{{"val":{"buildPass":{"val":"2","id":"pi"},"blockName":{"val":"minecraft:iron_door","id":"ss"},"meta":{"val":"0","id":"pi"},"sideFlag":{"val":"8","id":"pb"}},"id":"ct"}}
:enddata
:endrule

rule:
plugin=vanillaLogic
number=32
data:
JSON:{{"val":{"buildPass":{"val":"0","id":"pi"},"blockName":{"val":"GraveStone:GSMemorial","id":"ss"},"meta":{"val":"2","id":"pi"},"teData":{"val":{"isLocalized":{"val":"0","id":"pb"},"HangedMob":{"val":"6","id":"pb"},"DeathText":{"val":"","id":"ss"},"Enchanted":{"val":"0","id":"pb"},"HangedVillagerProfession":{"val":"0","id":"pi"},"id":{"val":"GSMemorial","id":"ss"},"GraveType":{"val":"117","id":"pb"}},"id":"ct"}},"id":"ct"}}
:enddata
:endrule

rule:
plugin=vanillaLogic
number=33
data:
JSON:{{"val":{"buildPass":{"val":"0","id":"pi"},"blockName":{"val":"GraveStone:GSSkullCandle","id":"ss"},"meta":{"val":"0","id":"pi"},"teData":{"val":{"id":{"val":"GSSkullCandle","id":"ss"},"Rotation":{"val":"4","id":"pb"}},"id":"ct"}},"id":"ct"}}
:enddata
:endrule

rule:
plugin=vanillaLogic
number=34
data:
JSON:{{"val":{"buildPass":{"val":"0","id":"pi"},"blockName":{"val":"cfm:plate","id":"ss"},"meta":{"val":"1","id":"pi"},"teData":{"val":{"Items":{"val":[{"val":{"id":{"val":"260","id":"ps"},"Count":{"val":"1","id":"pb"},"Damage":{"val":"0","id":"ps"}},"id":"ct"}],"id":"ls"},"id":{"val":"cfmPlate","id":"ss"},"Rotation":{"val":"1","id":"pi"}},"id":"ct"}},"id":"ct"}}
:enddata
:endrule

rule:
plugin=vanillaLogic
number=35
data:
JSON:{{"val":{"buildPass":{"val":"0","id":"pi"},"blockName":{"val":"cfm:plate","id":"ss"},"meta":{"val":"0","id":"pi"},"teData":{"val":{"Items":{"val":[{"val":{"id":{"val":"260","id":"ps"},"Count":{"val":"1","id":"pb"},"Damage":{"val":"0","id":"ps"}},"id":"ct"}],"id":"ls"},"id":{"val":"cfmPlate","id":"ss"},"Rotation":{"val":"0","id":"pi"}},"id":"ct"}},"id":"ct"}}
:enddata
:endrule

rule:
plugin=vanillaInventory
number=36
data:
JSON:{{"val":{"buildPass":{"val":"0","id":"pi"},"blockName":{"val":"minecraft:chest","id":"ss"},"meta":{"val":"4","id":"pi"},"lootLevel":{"val":"0","id":"pi"},"teData":{"val":{"x":{"val":"217","id":"pi"},"y":{"val":"64","id":"pi"},"z":{"val":"447","id":"pi"},"id":{"val":"Chest","id":"ss"}},"id":"ct"},"inventoryData":{"val":{"length":{"val":"27","id":"pi"},"inventoryContents":{"val":[{"val":{"damage":{"val":"0","id":"pi"},"item":{"val":"harvestcraft:hamsweetpicklesandwichItem","id":"ss"},"quantity":{"val":"2","id":"pi"},"slot":{"val":"0","id":"pi"}},"id":"ct"},{"val":{"damage":{"val":"0","id":"pi"},"item":{"val":"minecraft:ender_pearl","id":"ss"},"quantity":{"val":"1","id":"pi"},"slot":{"val":"1","id":"pi"}},"id":"ct"},{"val":{"damage":{"val":"10","id":"pi"},"item":{"val":"RotaryCraft:rotarycraft_item_shaftcraft","id":"ss"},"quantity":{"val":"1","id":"pi"},"slot":{"val":"3","id":"pi"}},"id":"ct"},{"val":{"damage":{"val":"0","id":"pi"},"item":{"val":"minecraft:bucket","id":"ss"},"quantity":{"val":"1","id":"pi"},"slot":{"val":"4","id":"pi"}},"id":"ct"},{"val":{"damage":{"val":"0","id":"pi"},"item":{"val":"harvestcraft:sundayroastItem","id":"ss"},"quantity":{"val":"1","id":"pi"},"slot":{"val":"6","id":"pi"}},"id":"ct"},{"val":{"damage":{"val":"0","id":"pi"},"item":{"val":"harvestcraft:hamsweetpicklesandwichItem","id":"ss"},"quantity":{"val":"2","id":"pi"},"slot":{"val":"8","id":"pi"}},"id":"ct"},{"val":{"damage":{"val":"0","id":"pi"},"item":{"val":"harvestcraft:cottagepieItem","id":"ss"},"quantity":{"val":"1","id":"pi"},"slot":{"val":"9","id":"pi"}},"id":"ct"},{"val":{"damage":{"val":"0","id":"pi"},"item":{"val":"EnderIO:itemConduitProbe","id":"ss"},"quantity":{"val":"1","id":"pi"},"slot":{"val":"13","id":"pi"}},"id":"ct"},{"val":{"damage":{"val":"0","id":"pi"},"item":{"val":"rftools:unknownDimlet","id":"ss"},"quantity":{"val":"2","id":"pi"},"slot":{"val":"14","id":"pi"}},"id":"ct"},{"val":{"damage":{"val":"0","id":"pi"},"item":{"val":"harvestcraft:sausageinbreadItem","id":"ss"},"quantity":{"val":"2","id":"pi"},"slot":{"val":"15","id":"pi"}},"id":"ct"},{"val":{"damage":{"val":"0","id":"pi"},"item":{"val":"openmodularturrets:disposeItemTurret","id":"ss"},"quantity":{"val":"2","id":"pi"},"slot":{"val":"18","id":"pi"}},"id":"ct"},{"val":{"damage":{"val":"0","id":"pi"},"item":{"val":"EnderIO:itemConduitProbe","id":"ss"},"quantity":{"val":"1","id":"pi"},"slot":{"val":"19","id":"pi"}},"id":"ct"},{"val":{"damage":{"val":"9","id":"pi"},"item":{"val":"Thaumcraft:ItemResource","id":"ss"},"quantity":{"val":"1","id":"pi"},"slot":{"val":"20","id":"pi"}},"id":"ct"},{"val":{"damage":{"val":"0","id":"pi"},"item":{"val":"Thaumcraft:ItemThaumonomicon","id":"ss"},"quantity":{"val":"1","id":"pi"},"slot":{"val":"23","id":"pi"}},"id":"ct"},{"val":{"damage":{"val":"6","id":"pi"},"item":{"val":"EnderIO:itemAlloy","id":"ss"},"quantity":{"val":"1","id":"pi"},"slot":{"val":"25","id":"pi"}},"id":"ct"}],"id":"ls"}},"id":"ct"}},"id":"ct"}}
:enddata
:endrule

rule:
plugin=vanillaLogic
number=37
data:
JSON:{{"val":{"buildPass":{"val":"0","id":"pi"},"blockName":{"val":"GraveStone:GSHauntedChest","id":"ss"},"meta":{"val":"5","id":"pi"},"teData":{"val":{"id":{"val":"GSHauntedChest","id":"ss"},"ChestType":{"val":"0","id":"pb"}},"id":"ct"}},"id":"ct"}}
:enddata
:endrule

rule:
plugin=vanillaInventory
number=38
data:
