# Ancient Warfare Structure Template File
# Auto-generated structure template file. created on: 12/18/2016 at: 12:57:0
# Lines beginning with # denote comments

header:
version=2.1
name=ReignTradeBazaar2
size=35,20,36
offset=17,2,32
:endheader

#### VALIDATION ####
validation:
type=ground
survival=true
worldGenEnabled=true
unique=false
preserveBlocks=false
selectionWeight=100
clusterValue=100
minDuplicateDistance=100
dimensionWhiteList=true
dimensionList=
biomeWhiteList=true
biomeList=chaparral,tundra,canyon,grove,mesa,savanna,shrubland,eucalyptus forest,heathland,scrubland,outback,steppe
leveling=6
fill=6
border=0
validTargetBlocks=minecraft:stained_hardened_clay,minecraft:dirt,BiomesOPlenty:driedDirt,minecraft:coal_ore,minecraft:diamond_ore,minecraft:lapis_ore,minecraft:gravel,minecraft:stone,minecraft:sand,minecraft:clay,minecraft:gold_ore,minecraft:redstone_ore,BiomesOPlenty:hardSand,minecraft:grass,BiomesOPlenty:hardDirt,minecraft:iron_ore
blockSwap=false
data:
:enddata
:endvalidation

#### LAYERS ####
layer: 0
1,1,1,1,1,1,1,1,1,1,1,1,1,1,1,1,1,1,1,1,1,1,1,1,1,1,1,1,1,1,1,1,1,1,1
1,1,1,1,1,1,1,1,1,1,1,1,1,1,1,1,1,1,1,1,1,1,1,1,1,1,1,1,1,1,1,1,1,1,1
1,1,1,1,1,1,1,1,1,1,1,1,1,1,1,1,1,1,1,1,1,1,1,1,1,1,1,1,1,1,1,1,1,1,1
1,1,1,1,1,1,1,1,1,1,1,1,1,1,1,1,1,1,1,1,1,1,1,1,1,1,1,1,1,1,1,1,1,1,1
1,1,1,1,1,1,1,1,1,1,1,1,1,1,1,1,1,1,1,1,1,1,1,1,1,1,1,1,1,1,1,1,1,1,1
1,1,1,1,1,1,1,1,1,1,1,1,1,1,1,1,1,1,1,1,1,1,1,1,1,1,1,1,1,1,1,1,1,1,1
1,1,1,1,1,1,1,1,1,1,1,1,1,1,1,1,1,1,1,1,1,1,1,1,1,1,1,1,1,1,1,1,1,1,1
1,1,1,1,1,1,1,1,1,1,1,1,1,1,1,1,1,1,1,1,1,1,1,1,1,1,1,1,1,1,1,1,1,1,1
1,1,1,1,1,1,1,1,1,1,1,1,1,1,1,1,1,1,1,1,1,1,1,1,1,1,1,1,1,1,1,1,1,1,1
1,1,1,1,1,1,1,1,1,1,1,1,1,1,1,1,1,1,1,1,1,1,1,1,1,1,1,1,1,1,1,1,1,1,1
1,1,1,1,1,1,1,1,1,1,1,1,1,1,1,1,1,1,1,1,1,1,1,1,1,1,1,1,1,1,1,1,1,1,1
1,1,1,1,1,1,1,1,1,1,1,1,1,1,1,1,1,1,1,1,1,1,1,1,1,1,1,1,1,1,1,1,1,1,1
1,1,1,1,1,1,1,1,1,1,1,1,1,1,1,1,1,1,1,1,1,1,1,1,1,1,1,1,1,1,1,1,1,1,1
1,1,1,1,1,1,1,1,1,1,1,1,1,1,1,1,1,1,1,1,1,1,1,1,1,1,1,1,1,1,1,1,1,1,1
1,1,1,1,1,1,1,1,1,1,1,1,1,1,1,1,1,1,1,1,1,1,1,1,1,1,1,1,1,1,1,1,1,1,1
1,1,1,1,1,1,1,1,1,1,1,1,1,1,1,1,1,1,1,1,1,1,1,1,1,1,1,1,1,1,1,1,1,1,1
1,1,1,1,1,1,1,1,1,1,1,1,1,1,1,1,1,1,1,1,1,1,1,1,1,1,1,1,1,1,1,1,1,1,1
1,1,1,1,1,1,1,1,1,1,1,1,1,1,1,1,1,1,1,1,1,1,1,1,1,1,1,1,1,1,1,1,1,1,1
1,1,1,1,1,1,1,1,1,1,1,1,1,1,1,1,1,1,1,1,1,1,1,1,1,1,1,1,1,1,1,1,1,1,1
1,1,1,1,1,1,1,1,1,1,1,1,1,1,1,1,1,1,1,1,1,1,1,1,1,1,1,1,1,1,1,1,1,1,1
1,1,1,1,1,1,1,1,1,1,1,1,1,1,1,1,1,1,1,1,1,1,1,1,1,1,1,1,1,1,1,1,1,1,1
1,1,1,1,1,1,1,1,1,1,1,1,1,1,1,1,1,1,1,1,1,1,1,1,1,1,1,1,1,1,1,1,1,1,1
1,1,1,1,1,1,1,1,1,1,1,1,1,1,1,1,1,1,1,1,1,1,1,1,1,1,1,1,1,1,1,1,1,1,1
1,1,1,1,1,1,1,1,1,1,1,1,1,1,1,1,1,1,1,1,1,1,1,1,1,1,1,1,1,1,1,1,1,1,1
1,1,1,1,1,1,1,1,1,1,1,1,1,1,1,1,1,1,1,1,1,1,1,1,1,1,1,1,1,1,1,1,1,1,1
1,1,1,1,1,1,1,1,1,1,1,1,1,1,1,1,1,1,1,1,1,1,1,1,1,1,1,1,1,1,1,1,1,1,1
1,1,1,1,1,1,1,1,1,1,1,1,1,1,1,1,1,1,1,1,1,1,1,1,1,1,1,1,1,1,1,1,1,1,1
1,1,1,1,1,1,1,1,1,1,1,1,1,1,1,1,1,1,1,1,1,1,1,1,1,1,1,1,1,1,1,1,1,1,1
1,1,1,1,1,1,1,1,1,1,1,1,1,1,1,1,1,1,1,1,1,1,1,1,1,1,1,1,1,1,1,1,1,1,1
1,1,1,1,1,1,1,1,1,1,1,1,1,1,1,1,1,1,1,1,1,1,1,1,1,1,1,1,1,1,1,1,1,1,1
1,1,1,1,1,1,1,1,1,1,1,1,1,1,1,1,1,1,1,1,1,1,1,1,1,1,1,1,1,1,1,1,1,1,1
1,1,1,1,1,1,1,1,1,1,1,1,1,1,1,1,1,1,1,1,1,1,1,1,1,1,1,1,1,1,1,1,1,1,1
1,1,1,1,1,1,1,1,1,1,1,1,1,1,1,1,1,1,1,1,1,1,1,1,1,1,1,1,1,1,1,1,1,1,1
1,1,1,1,1,1,1,1,1,1,1,1,1,1,1,1,1,1,1,1,1,1,1,1,1,1,1,1,1,1,1,1,1,1,1
1,1,1,1,1,1,1,1,1,1,1,1,1,1,1,1,1,1,1,1,1,1,1,1,1,1,1,1,1,1,1,1,1,1,1
1,1,1,1,1,1,1,1,1,1,1,1,1,1,1,1,1,1,1,1,1,1,1,1,1,1,1,1,1,1,1,1,1,1,1
:endlayer
layer: 1
2,2,2,2,2,2,2,2,2,2,2,2,2,2,2,2,2,2,2,2,2,2,2,2,2,2,2,2,2,2,2,2,2,2,2
2,2,2,2,2,2,2,2,2,2,2,2,2,2,2,2,2,2,2,2,2,2,2,2,2,2,2,2,2,2,2,2,2,2,2
2,2,2,2,2,2,2,2,2,2,2,2,2,2,2,2,2,2,2,2,2,2,2,2,2,2,2,2,2,2,2,2,2,2,2
2,2,2,2,2,2,2,1,1,1,1,1,1,1,1,1,1,1,1,1,1,1,1,1,1,1,1,2,2,2,2,2,2,2,2
2,2,2,2,2,1,1,1,1,1,1,1,1,1,1,1,1,1,1,1,1,1,1,1,1,1,1,1,1,2,2,2,2,2,2
2,2,2,2,1,1,1,1,1,2,2,2,2,2,2,2,2,2,2,2,2,2,2,3,2,1,1,1,1,1,2,2,2,2,2
2,2,2,1,1,1,1,2,2,2,2,2,2,2,2,2,2,2,2,2,2,2,2,3,3,2,2,1,1,1,1,2,2,2,2
2,2,2,1,1,1,2,2,2,2,2,2,2,1,1,1,1,1,1,1,2,2,2,3,3,2,1,1,1,1,1,2,2,2,2
2,2,1,1,1,2,2,2,2,2,2,2,2,1,1,1,1,1,1,1,2,2,2,3,3,2,2,2,1,1,1,1,2,2,2
2,2,1,1,2,2,2,2,2,2,2,2,2,1,1,1,1,1,1,1,2,2,2,3,3,2,2,2,2,2,1,1,2,2,2
2,2,1,1,2,2,2,2,2,2,2,2,2,1,1,1,1,1,1,1,2,2,2,3,3,2,2,2,2,2,1,1,2,2,2
2,2,1,1,2,1,1,1,1,2,2,2,2,1,1,1,1,1,1,1,2,2,2,3,3,1,1,1,1,2,1,1,2,2,2
2,2,1,1,2,1,2,2,1,2,2,2,2,1,1,1,1,1,1,1,2,2,2,3,3,1,2,2,2,2,1,1,2,2,2
2,2,1,1,2,1,2,2,1,2,2,2,2,1,1,1,1,1,1,4,2,2,2,3,3,1,2,2,1,2,1,1,2,2,2
2,2,1,1,2,2,2,2,1,2,2,2,2,2,2,3,1,3,2,2,2,2,2,3,3,1,2,2,1,2,1,1,2,2,2
2,2,1,1,2,1,1,1,1,2,2,2,2,2,2,3,3,3,2,2,2,2,2,3,3,1,1,1,1,2,1,1,2,2,2
2,2,1,1,2,2,2,2,2,2,2,2,2,2,2,2,3,3,3,3,3,3,5,3,3,3,3,3,3,2,1,1,2,2,2
2,2,1,1,2,2,2,2,2,2,2,2,2,2,2,2,3,3,3,3,3,3,3,3,3,3,3,3,3,2,1,1,2,2,2
2,2,1,1,2,2,2,2,2,2,2,2,2,2,2,2,3,3,2,2,2,1,3,2,2,2,2,2,2,2,1,1,2,2,2
2,2,1,1,2,3,3,3,2,2,1,3,3,3,3,2,3,3,2,2,2,3,3,2,2,2,2,2,2,2,1,1,2,2,2
2,2,1,1,2,3,3,3,2,2,2,3,3,3,3,2,3,3,2,2,2,3,3,2,2,2,1,2,2,2,1,1,2,2,2
2,2,1,1,2,3,3,3,2,2,2,3,3,3,3,2,3,3,2,2,2,3,3,2,2,1,2,2,2,2,1,1,2,2,2
2,2,1,1,2,3,3,3,2,2,2,3,3,3,3,2,3,3,2,2,2,3,3,2,2,2,2,2,2,2,1,1,2,2,2
2,2,1,1,2,3,3,3,2,2,1,3,3,3,3,2,3,3,2,2,2,3,3,2,2,2,2,2,2,2,1,1,2,2,2
2,2,1,1,2,3,3,3,2,2,2,2,2,2,2,2,3,3,2,2,2,3,3,2,2,1,1,2,2,2,1,1,2,2,2
2,2,1,1,2,1,1,1,2,2,2,2,2,2,2,2,3,3,2,2,2,1,3,3,3,3,3,1,2,2,1,1,2,2,2
2,2,1,1,2,1,2,2,2,2,2,2,2,2,2,2,3,3,2,2,2,1,3,3,3,3,3,1,1,2,1,1,2,2,2
2,2,1,1,1,1,2,1,2,3,3,3,3,3,2,2,3,3,2,2,2,1,3,3,3,3,3,1,2,1,1,1,2,2,2
2,2,2,1,1,1,1,1,3,3,3,3,3,3,2,2,3,3,2,2,2,1,3,3,3,3,3,1,2,1,1,2,2,2,2
2,2,2,1,1,1,1,1,3,3,3,1,1,1,2,1,3,3,2,2,2,2,2,2,2,2,2,2,1,1,1,2,2,2,2
2,2,2,2,1,1,1,1,3,3,3,2,2,2,2,2,3,3,2,2,2,2,2,2,2,2,1,3,6,1,2,2,2,2,2
2,2,2,2,2,1,1,1,1,1,1,1,1,1,1,5,5,5,5,1,1,1,1,1,1,1,1,1,1,2,2,2,2,2,2
2,2,2,2,2,2,2,1,1,1,1,1,1,1,1,5,5,5,5,1,1,1,1,1,1,1,1,2,2,2,2,2,2,2,2
2,2,2,2,2,2,2,2,2,2,2,2,2,2,2,2,3,3,2,2,2,2,2,2,2,2,2,2,2,2,2,2,2,2,2
2,2,2,2,2,2,2,2,2,2,2,2,2,2,2,2,3,3,2,2,2,2,2,2,2,2,2,2,1,2,2,2,2,2,2
2,2,2,2,2,2,2,2,2,2,2,2,2,2,2,2,3,3,2,2,2,2,2,2,2,2,2,2,2,2,2,2,2,2,2
:endlayer
layer: 2
0,0,0,0,0,0,0,0,0,0,0,0,0,0,0,0,0,0,0,0,0,0,0,0,0,0,0,0,0,0,0,0,0,0,0
0,0,7,0,0,7,7,0,7,7,0,0,7,7,7,0,0,0,0,7,0,0,0,0,7,7,7,0,7,0,0,0,0,0,0
0,0,0,7,7,7,7,7,7,7,0,7,7,7,7,0,0,0,7,7,7,7,0,0,7,7,7,7,0,0,0,0,0,0,0
0,7,7,7,7,7,8,9,9,9,9,9,9,9,9,9,9,9,9,9,9,9,9,9,9,9,9,8,0,0,7,7,7,0,0
0,7,7,7,8,9,9,6,6,6,6,6,6,6,6,6,6,6,6,6,6,6,6,6,6,6,6,9,9,8,7,7,7,7,0
7,0,7,8,9,6,6,6,6,10,0,8,0,0,0,0,0,0,0,0,0,8,0,0,11,6,6,6,6,9,8,7,7,7,0
7,7,7,9,6,6,12,0,0,0,0,0,0,0,0,0,0,0,0,0,0,0,0,0,0,0,0,13,6,6,9,7,7,7,0
0,7,8,9,6,12,0,0,0,0,0,0,0,14,14,14,14,14,14,14,0,0,0,0,0,0,13,13,15,6,9,8,0,7,0
7,7,9,6,6,0,0,0,0,0,0,0,0,14,14,14,14,14,14,14,0,0,0,0,0,0,0,0,13,6,6,9,0,0,0
7,7,9,6,0,0,0,0,0,0,0,0,0,14,14,14,14,14,14,14,0,0,0,0,0,0,0,0,0,0,6,9,0,0,0
0,0,9,6,0,0,0,0,0,0,0,0,0,14,14,14,14,14,14,14,0,0,0,0,0,0,0,0,0,0,6,9,0,0,0
0,0,9,6,0,6,6,6,6,16,0,0,0,14,14,14,14,14,14,14,0,0,0,0,17,6,6,6,6,0,6,9,0,7,0
0,7,9,6,0,6,0,0,6,0,0,0,0,14,14,14,14,14,14,14,0,0,0,0,0,6,0,0,18,0,6,9,19,20,0
7,0,9,6,0,6,0,0,6,0,0,0,0,14,14,14,14,14,14,14,0,0,0,0,0,6,0,0,6,0,6,9,7,7,0
7,7,9,6,21,18,0,0,6,0,0,0,0,0,0,22,14,23,0,0,0,0,0,0,0,6,0,0,6,21,6,9,0,7,0
7,7,9,6,0,6,6,6,6,0,0,8,0,0,0,22,24,23,0,0,0,8,0,0,0,6,6,6,6,0,6,9,0,0,0
19,0,9,6,0,0,0,0,0,0,0,0,0,0,0,0,0,0,0,0,0,0,0,0,0,0,0,0,0,0,6,9,0,0,0
0,0,9,6,10,0,0,0,0,0,0,0,0,0,0,0,0,0,0,0,0,0,0,0,0,0,0,0,0,11,6,9,0,0,0
0,0,9,6,0,0,0,0,0,0,0,0,0,0,0,0,0,0,0,0,17,6,6,8,8,8,8,8,8,0,6,9,0,0,0
7,7,9,6,0,6,25,25,0,0,6,26,25,25,6,16,0,0,0,0,0,27,28,29,0,0,0,0,8,0,6,9,0,0,0
7,7,9,6,0,6,0,30,0,0,27,0,0,21,30,0,0,0,0,0,0,27,0,8,0,0,0,0,8,0,6,9,7,0,0
0,7,9,6,21,6,0,30,0,21,27,0,8,0,30,0,0,0,0,0,0,27,0,8,0,0,0,0,8,0,6,9,7,7,0
0,7,9,6,0,6,0,18,0,0,27,0,0,31,30,0,0,0,0,0,0,27,0,8,0,0,0,0,8,0,6,9,7,7,0
0,0,9,6,0,6,32,32,0,0,6,32,32,32,6,16,0,0,0,0,0,27,0,8,0,0,0,0,8,0,6,9,0,7,0
0,0,9,6,0,0,0,0,0,0,0,0,0,0,0,0,0,0,0,0,0,18,0,8,0,0,0,0,8,0,6,9,0,7,0
7,7,9,6,0,6,6,6,0,0,0,0,0,0,0,0,0,0,0,0,0,6,6,6,6,6,6,6,8,0,6,9,0,0,0
7,7,9,6,0,6,0,18,0,33,0,0,0,0,0,0,0,0,0,0,0,6,0,0,0,0,0,34,0,0,6,9,0,0,0
0,7,9,6,6,6,0,6,0,6,26,25,25,30,0,0,0,0,0,0,0,6,0,0,0,0,0,34,0,6,6,9,0,0,0
0,19,8,9,6,6,6,6,35,6,0,0,0,30,0,0,0,0,0,0,17,6,36,6,6,6,6,6,0,6,9,8,0,7,0
0,0,0,9,6,6,6,6,6,6,6,6,6,6,0,0,0,0,0,0,0,0,0,0,21,0,0,0,6,6,9,7,0,0,0
7,7,7,8,9,6,6,6,6,6,10,0,0,0,0,0,0,0,0,0,0,0,0,0,0,11,6,6,6,9,8,7,7,7,0
0,7,7,0,8,9,9,6,6,6,6,6,6,6,6,9,0,0,9,6,6,6,6,6,6,6,6,9,9,8,0,7,7,7,0
0,0,7,7,7,7,8,9,9,9,9,9,9,9,9,0,0,0,0,9,9,9,9,9,9,9,9,8,7,7,20,0,7,7,0
7,7,7,0,37,7,7,0,7,7,7,7,0,0,8,0,0,0,0,8,7,38,0,0,7,0,0,0,7,7,7,7,0,0,0
0,7,0,7,7,7,7,7,0,7,39,7,7,0,0,0,0,0,0,0,7,19,0,7,0,0,0,7,7,20,7,7,0,0,0
7,0,7,7,0,7,7,0,0,0,7,7,7,0,0,0,0,0,0,0,7,7,7,0,0,0,0,7,7,7,0,0,0,0,0
:endlayer
layer: 3
0,0,0,0,0,0,0,0,0,0,0,0,0,0,0,0,0,0,0,0,0,0,0,0,0,0,0,0,0,0,0,0,0,0,0
0,0,0,0,0,0,0,0,0,0,0,0,0,0,0,0,0,0,0,0,0,0,0,0,0,0,0,0,0,0,0,0,0,0,0
0,0,0,0,0,0,0,0,0,0,0,0,0,0,0,0,0,0,0,0,0,0,0,0,0,0,0,0,0,0,0,0,0,0,0
0,0,0,0,0,0,8,9,9,9,9,9,9,9,9,9,9,9,9,9,9,9,9,9,9,9,9,8,0,0,0,0,0,0,0
0,0,0,0,8,9,9,6,6,6,6,6,6,6,6,6,6,6,6,6,6,6,6,6,6,6,6,9,9,8,0,0,0,0,0
0,0,0,8,9,6,6,6,10,0,0,8,0,0,0,0,0,0,0,0,0,8,0,0,0,11,6,6,6,9,8,0,0,0,0
0,0,0,9,6,6,0,0,0,0,0,0,0,0,0,0,0,0,0,0,0,0,0,0,0,0,0,0,6,6,9,0,0,0,0
0,0,8,9,6,0,0,0,0,0,0,0,0,6,6,6,6,6,6,6,0,0,0,0,0,0,0,13,15,6,9,8,0,0,0
0,0,9,6,6,0,0,0,0,0,0,0,0,6,40,41,42,43,44,6,0,0,0,0,0,0,0,0,0,6,6,9,0,0,0
0,0,9,6,0,0,0,0,0,0,0,0,0,6,0,0,0,0,0,6,0,0,0,0,0,0,0,0,0,0,6,9,0,0,0
0,0,9,6,0,0,0,0,0,0,0,0,0,6,36,45,46,47,48,6,0,0,0,0,0,0,0,0,0,0,6,9,0,0,0
0,0,9,6,0,8,8,8,8,0,0,0,0,6,0,49,50,51,52,6,0,0,0,0,0,8,8,8,8,0,6,9,0,0,0
0,0,9,6,0,8,0,0,53,0,0,0,0,6,0,0,0,0,0,6,0,0,0,0,0,0,0,0,0,0,6,9,0,0,0
0,0,9,6,0,8,0,0,0,0,0,0,0,6,6,6,54,6,6,6,0,0,0,0,0,0,0,0,8,0,6,9,0,0,0
0,0,9,6,0,0,0,0,0,0,0,0,0,0,0,0,0,0,0,0,0,0,0,0,0,0,0,0,8,0,6,9,0,0,0
0,0,9,6,0,8,0,0,8,0,0,8,0,0,0,0,0,0,0,0,0,8,0,0,0,8,8,8,8,0,6,9,0,0,0
0,0,9,55,0,0,0,0,0,0,0,0,0,0,0,0,0,0,0,0,0,0,0,0,0,0,0,0,0,0,55,9,0,0,0
0,0,9,0,0,0,0,0,0,0,0,0,0,0,0,0,0,0,0,0,0,0,0,0,0,0,0,0,0,0,0,9,0,0,0
0,0,9,35,0,0,0,0,0,0,0,0,0,0,0,0,0,0,0,0,0,8,0,8,0,0,0,0,21,0,35,9,0,0,0
0,0,9,6,0,8,0,8,0,0,8,0,0,0,8,0,0,0,0,0,0,0,0,0,0,0,0,0,0,0,6,9,0,0,0
0,0,9,6,0,8,0,0,0,0,0,0,0,0,0,0,0,0,0,0,0,8,0,0,0,0,0,0,0,0,6,9,0,0,0
0,0,9,6,0,6,0,0,0,0,0,0,8,0,0,0,0,0,0,0,0,0,0,0,0,0,0,0,0,0,6,9,0,0,0
0,0,9,6,0,8,0,0,0,0,0,0,0,0,0,0,0,0,0,0,0,0,0,0,0,0,0,0,0,0,6,9,0,0,0
0,0,9,6,0,8,0,8,0,0,8,0,0,0,8,0,0,0,0,0,0,8,0,0,0,0,0,0,21,0,6,9,0,0,0
0,0,9,6,16,0,0,0,0,0,0,0,0,0,0,0,0,0,0,0,0,0,0,21,0,0,0,0,0,0,6,9,0,0,0
0,0,9,6,0,8,0,8,0,0,0,0,0,0,0,0,0,0,0,0,0,8,0,8,0,0,0,8,0,0,6,9,0,0,0
0,0,9,6,0,0,0,0,0,0,0,0,0,0,0,0,0,0,0,0,0,0,0,0,0,0,0,34,0,0,6,9,0,0,0
0,0,9,6,6,8,0,0,0,8,0,0,0,8,0,0,0,0,0,0,0,0,0,0,0,0,0,34,0,6,6,9,0,0,0
0,0,8,9,6,8,8,8,0,0,0,0,0,0,0,0,0,0,0,0,0,8,0,0,0,0,0,8,0,6,9,8,0,0,0
0,0,0,9,6,6,6,6,35,8,8,8,8,8,0,0,0,0,0,0,0,0,0,0,0,0,0,0,6,6,9,0,0,0,0
0,0,0,8,9,6,6,6,6,10,0,0,0,0,0,33,0,0,33,0,0,0,0,0,0,0,11,6,6,9,8,0,0,0,0
0,0,0,0,8,9,9,6,6,6,6,6,6,6,6,9,0,0,9,6,6,6,6,6,6,6,6,9,9,8,0,0,0,0,0
0,0,0,0,0,0,8,9,9,9,9,9,9,9,9,0,0,0,0,9,9,9,9,9,9,9,9,8,0,0,0,0,0,0,0
0,0,0,0,0,0,0,0,0,0,0,0,0,0,8,0,0,0,0,8,0,0,0,0,0,0,0,0,0,0,0,0,0,0,0
0,0,0,0,0,0,0,0,0,0,0,0,0,0,0,0,0,0,0,0,0,0,0,0,0,0,0,0,0,0,0,0,0,0,0
0,0,0,0,0,0,0,0,0,0,0,0,0,0,0,0,0,0,0,0,0,0,0,0,0,0,0,0,0,0,0,0,0,0,0
:endlayer
layer: 4
0,0,0,0,0,0,0,0,0,0,0,0,0,0,0,0,0,0,0,0,0,0,0,0,0,0,0,0,0,0,0,0,0,0,0
0,0,0,0,0,0,0,0,0,0,0,0,0,0,0,0,0,0,0,0,0,0,0,0,0,0,0,0,0,0,0,0,0,0,0
0,0,0,0,0,0,0,0,0,0,0,0,0,0,0,0,0,0,0,0,0,0,0,0,0,0,0,0,0,0,0,0,0,0,0
0,0,0,0,0,0,8,8,9,9,8,8,9,9,8,8,9,9,8,8,9,9,8,8,9,9,8,8,0,0,0,0,0,0,0
0,0,0,0,8,9,9,0,0,56,0,0,0,56,0,0,0,0,0,0,56,0,0,0,0,0,0,9,9,8,0,0,0,0,0
0,0,0,8,8,0,56,0,0,0,0,8,0,0,0,0,0,0,0,0,0,8,0,0,0,0,0,56,0,8,8,0,0,0,0
0,0,0,9,0,0,0,0,0,0,0,0,0,33,0,0,0,0,0,33,0,0,0,0,0,0,0,0,0,0,9,0,0,0,0
0,0,8,9,16,0,0,0,0,0,0,0,17,6,6,57,6,57,6,6,16,0,0,0,0,0,0,0,0,17,9,8,0,0,0
0,0,8,0,0,0,0,0,0,0,0,0,0,6,0,0,58,59,0,6,0,0,0,0,0,0,0,0,0,0,0,8,0,0,0
0,0,9,0,0,0,0,0,0,0,0,0,0,57,0,0,0,0,0,6,0,0,0,0,0,0,0,0,0,0,0,9,0,0,0
0,0,9,0,0,0,0,0,0,0,0,0,0,6,0,0,0,60,0,6,0,0,0,0,0,0,0,0,0,0,0,9,0,0,0
0,0,8,0,0,61,61,61,61,0,0,0,0,57,0,0,0,0,0,57,0,0,0,0,0,62,62,62,62,0,0,8,0,0,0
0,0,8,0,0,61,61,61,61,0,0,0,0,6,0,0,0,0,0,6,0,0,0,0,0,62,62,62,62,0,0,8,0,0,0
0,0,9,0,0,61,61,61,61,0,0,0,17,6,57,6,63,6,57,6,16,0,0,0,0,62,62,62,62,0,0,9,0,0,0
0,0,9,0,0,61,61,61,61,0,0,0,0,56,0,0,0,0,0,56,0,0,0,0,0,62,62,62,62,0,0,9,0,0,0
0,0,8,0,0,61,61,61,61,0,0,8,0,0,0,0,0,0,0,0,0,8,0,0,0,62,62,62,62,0,0,8,0,0,0
0,0,8,0,0,0,0,0,0,0,0,0,0,0,0,0,0,0,0,0,0,0,0,0,0,0,0,0,0,0,0,8,0,0,0
0,0,9,0,0,0,0,0,0,0,0,0,0,0,0,0,0,0,0,0,0,0,0,0,0,0,0,0,0,0,0,9,0,0,0
0,0,9,0,0,0,0,0,0,0,0,0,0,0,0,0,0,0,0,0,0,64,64,8,0,0,0,0,0,0,0,9,0,0,0
0,0,8,0,0,62,62,62,0,0,65,65,65,65,65,0,0,0,0,0,0,8,0,0,0,0,0,0,0,0,0,8,0,0,0
0,0,8,0,0,62,0,62,0,0,65,0,0,0,65,0,0,0,0,0,0,8,0,0,0,0,0,0,0,0,0,8,0,0,0
0,0,9,0,0,6,0,62,0,0,65,0,8,0,65,0,0,0,0,0,0,8,0,0,0,0,0,0,0,0,17,9,0,0,0
0,0,9,0,0,62,0,62,0,0,65,0,0,0,65,0,0,0,0,0,0,8,0,0,0,0,0,0,0,0,0,9,0,0,0
0,0,8,0,0,62,62,62,0,0,65,65,65,65,65,0,0,0,0,0,0,8,0,0,0,0,0,0,0,0,0,8,0,0,0
0,0,8,0,0,0,0,0,0,0,0,0,0,0,0,0,0,0,0,0,0,8,0,0,0,0,0,0,0,0,0,8,0,0,0
0,0,9,0,0,8,8,8,0,0,0,0,0,0,0,0,0,0,0,0,0,64,64,8,8,8,8,61,0,0,0,9,0,0,0
0,0,9,0,0,8,0,8,0,0,0,0,0,0,0,0,0,0,0,0,0,61,61,0,0,0,0,34,0,0,0,9,0,0,0
0,0,8,0,0,8,0,8,0,66,8,8,8,66,0,0,0,0,0,0,0,61,61,0,0,0,0,34,0,0,0,8,0,0,0
0,0,8,9,0,8,8,8,0,66,0,0,0,66,0,0,0,0,0,0,0,61,61,8,8,8,61,61,0,17,9,8,0,0,0
0,0,0,9,0,0,0,0,0,66,8,8,8,66,0,0,0,0,0,0,0,0,0,0,0,0,0,0,0,0,9,0,0,0,0
0,0,0,8,8,0,0,0,0,0,0,0,0,0,0,0,0,0,0,0,0,0,0,0,0,0,0,33,0,8,8,0,0,0,0
0,0,0,0,8,9,9,0,0,0,0,0,0,0,11,9,0,0,9,10,0,0,0,0,0,0,0,9,9,8,0,0,0,0,0
0,0,0,0,0,0,8,8,9,9,8,8,8,9,9,0,0,0,0,9,9,8,8,8,9,9,8,8,0,0,0,0,0,0,0
0,0,0,0,0,0,0,0,0,0,0,0,0,0,8,0,0,0,0,8,0,0,0,0,0,0,0,0,0,0,0,0,0,0,0
0,0,0,0,0,0,0,0,0,0,0,0,0,0,0,0,0,0,0,0,0,0,0,0,0,0,0,0,0,0,0,0,0,0,0
0,0,0,0,0,0,0,0,0,0,0,0,0,0,0,0,0,0,0,0,0,0,0,0,0,0,0,0,0,0,0,0,0,0,0
:endlayer
layer: 5
0,0,0,0,0,0,0,0,0,0,0,0,0,0,0,0,0,0,0,0,0,0,0,0,0,0,0,0,0,0,0,0,0,0,0
0,0,0,0,0,0,0,0,0,0,0,0,0,0,0,0,0,0,0,0,0,0,0,0,0,0,0,0,0,0,0,0,0,0,0
0,0,0,0,0,0,0,0,0,0,0,0,33,0,0,0,33,0,0,0,33,0,0,0,0,33,0,0,0,0,0,0,0,0,0
0,0,0,0,0,33,0,0,9,9,0,0,9,9,0,0,9,9,0,0,9,9,0,0,9,9,0,0,33,0,0,0,0,0,0
0,0,0,0,0,9,9,0,0,0,0,0,0,0,0,0,0,0,0,0,0,0,0,0,0,0,0,9,9,0,0,0,0,0,0
0,0,0,0,0,0,0,0,0,0,0,6,67,67,67,67,67,67,67,67,67,6,0,0,0,0,0,0,0,0,0,0,0,0,0
0,0,17,9,0,0,0,0,0,0,0,67,30,32,32,32,32,32,32,32,27,67,0,0,0,0,0,0,0,0,9,16,0,0,0
0,0,0,9,0,0,0,0,0,0,0,67,30,6,6,6,6,6,6,6,27,67,0,0,0,0,0,0,0,0,9,0,0,0,0
0,0,0,0,0,0,0,0,0,0,0,67,30,6,0,67,67,0,0,6,27,67,0,0,0,0,0,0,0,0,0,0,0,0,0
0,0,9,0,0,0,0,0,0,0,0,67,30,6,0,0,0,0,67,6,27,67,0,0,0,0,0,0,0,0,0,9,0,0,0
0,17,9,0,0,0,0,0,0,0,0,67,30,6,67,68,69,70,67,6,27,67,0,0,0,0,0,0,0,0,0,9,16,0,0
0,0,0,0,0,0,0,0,0,0,0,67,30,6,67,0,0,0,0,6,27,67,0,0,0,0,0,0,0,0,0,0,0,0,0
0,0,0,0,0,0,0,21,0,0,0,67,30,6,0,0,33,0,0,6,27,67,0,0,0,0,62,62,0,0,0,0,0,0,0
0,0,9,0,0,0,0,0,0,0,0,67,30,6,6,6,6,6,6,6,27,67,0,0,0,0,62,62,0,0,0,9,0,0,0
0,17,9,16,0,0,0,21,0,0,0,67,30,25,25,25,25,25,25,25,25,67,0,0,0,0,62,62,0,0,17,9,16,0,0
0,0,0,0,0,0,0,0,0,0,0,6,67,67,67,67,67,67,67,67,67,6,0,0,0,0,0,0,0,0,0,0,0,0,0
0,0,0,0,0,0,0,0,0,0,0,0,0,0,0,0,0,0,0,0,0,0,0,0,0,0,0,0,0,0,0,0,0,0,0
0,0,9,0,0,0,0,0,0,0,0,0,0,0,0,0,0,0,0,0,0,0,0,0,0,0,0,0,0,0,0,9,16,0,0
0,17,9,0,0,0,0,0,0,0,0,0,0,0,0,0,0,0,0,0,0,64,64,64,0,0,0,0,0,0,0,9,0,0,0
0,0,0,0,0,0,0,0,0,0,0,0,0,0,0,0,0,0,0,0,0,64,64,64,0,0,0,0,0,0,0,0,0,0,0
0,0,0,0,0,0,62,0,0,0,0,65,65,65,0,0,0,0,0,0,0,64,64,64,0,0,0,0,0,0,0,0,0,0,0
0,0,9,16,0,62,62,0,0,0,0,65,65,65,0,0,0,0,0,0,0,64,64,64,0,0,0,0,0,0,0,9,16,0,0
0,17,9,0,0,0,62,0,0,0,0,65,65,65,0,0,0,0,0,0,0,64,64,64,0,0,0,0,0,0,0,9,0,0,0
0,0,0,0,0,0,0,0,0,0,0,0,0,0,0,0,0,0,0,0,0,64,64,64,0,0,0,0,0,0,0,0,0,0,0
0,0,0,0,0,0,0,0,0,0,0,0,0,0,0,0,0,0,0,0,0,64,64,64,0,0,0,0,0,0,0,0,0,0,0
0,0,9,0,0,71,71,71,0,0,0,0,0,0,0,0,0,0,0,0,0,64,64,64,61,61,61,61,0,0,0,9,16,0,0
0,17,9,0,0,71,71,71,0,0,0,0,0,0,0,0,0,0,0,0,0,61,61,61,61,61,61,61,0,0,0,9,0,0,0
0,0,0,0,0,71,71,71,0,0,66,66,66,0,0,0,0,0,0,0,0,61,61,61,61,61,61,61,0,0,0,0,0,0,0
0,0,0,9,0,71,71,71,0,0,66,66,66,0,0,0,0,0,0,0,0,61,61,61,61,61,61,61,0,0,9,0,0,0,0
0,0,17,9,0,0,0,0,0,0,66,66,66,0,0,0,0,0,0,0,0,0,0,0,0,0,0,0,0,0,9,16,0,0,0
0,0,0,0,0,0,0,0,0,0,0,0,0,0,0,0,0,0,0,0,0,0,0,0,0,0,0,0,0,0,0,0,0,0,0
0,0,0,0,0,9,9,0,0,0,0,0,0,0,0,11,6,6,10,0,0,0,0,0,0,0,0,9,9,0,0,0,0,0,0
0,0,0,0,0,56,0,0,9,9,0,0,8,9,9,72,72,72,72,9,9,8,0,0,9,9,0,0,56,0,0,0,0,0,0
0,0,0,0,0,0,0,0,56,0,0,0,0,56,8,8,8,8,8,8,56,0,0,0,0,56,0,0,0,0,0,0,0,0,0
0,0,0,0,0,0,0,0,0,0,0,0,0,0,0,0,0,0,0,0,0,0,0,0,0,0,0,0,0,0,0,0,0,0,0
0,0,0,0,0,0,0,0,0,0,0,0,0,0,0,0,0,0,0,0,0,0,0,0,0,0,0,0,0,0,0,0,0,0,0
:endlayer
layer: 6
0,0,0,0,0,0,0,0,0,0,0,0,0,0,0,0,0,0,0,0,0,0,0,0,0,0,0,0,0,0,0,0,0,0,0
0,0,0,0,0,0,0,0,0,0,0,0,0,0,0,0,0,0,0,0,0,0,0,0,0,0,0,0,0,0,0,0,0,0,0
0,0,0,0,0,0,0,0,0,0,0,0,0,0,0,0,0,0,0,0,0,0,0,0,0,0,0,0,0,0,0,0,0,0,0
0,0,0,0,0,0,0,0,0,0,0,0,0,0,0,0,0,0,0,0,0,0,0,0,0,0,0,0,0,0,0,0,0,0,0
0,0,0,0,0,0,0,0,0,0,0,0,0,0,0,0,0,0,0,0,0,0,0,0,0,0,0,0,0,0,0,0,0,0,0
0,0,0,0,0,0,0,0,0,0,0,21,0,0,0,0,0,0,0,0,0,21,0,0,0,0,0,0,0,0,0,0,0,0,0
0,0,0,0,0,0,0,0,0,0,0,0,11,35,35,35,35,35,35,35,10,0,0,0,0,0,0,0,0,0,0,0,0,0,0
0,0,0,0,0,0,0,0,0,0,0,0,11,6,6,6,6,6,6,6,10,0,0,0,0,0,0,0,0,0,0,0,0,0,0
0,0,0,0,0,0,0,0,0,0,0,0,11,6,0,73,74,0,0,6,10,0,0,0,0,0,0,0,0,0,0,0,0,0,0
0,0,0,0,0,0,0,0,0,0,0,0,11,6,0,0,0,0,75,6,10,0,0,0,0,0,0,0,0,0,0,0,0,0,0
0,0,0,0,0,0,0,0,0,0,0,0,11,6,76,0,0,0,77,6,10,0,0,0,0,0,0,0,0,0,0,0,0,0,0
0,0,0,0,0,0,0,0,0,0,0,0,11,6,78,0,0,0,0,6,10,0,0,0,0,0,0,0,0,0,0,0,0,0,0
0,0,0,0,0,0,0,0,0,0,0,0,11,6,0,0,0,0,79,6,10,0,0,0,0,0,0,0,0,0,0,0,0,0,0
0,0,0,0,0,0,0,0,0,0,0,0,11,6,6,6,6,6,6,6,10,0,0,0,0,0,21,0,0,0,0,0,0,0,0
0,0,0,0,0,0,0,0,0,0,0,0,11,55,55,55,55,55,55,55,55,0,0,0,0,0,0,0,0,0,0,0,0,0,0
0,0,0,0,0,0,0,0,0,0,0,21,0,0,0,0,0,0,0,0,0,21,0,0,0,0,0,0,0,0,0,0,0,0,0
0,0,0,0,0,0,0,0,0,0,0,0,0,0,0,0,0,0,0,0,0,0,0,0,0,0,0,0,0,0,0,0,0,0,0
0,0,0,0,0,0,0,0,0,0,0,0,0,0,0,0,0,0,0,0,0,0,0,0,0,0,0,0,0,0,0,0,0,0,0
0,0,0,0,0,0,0,0,0,0,0,0,0,0,0,0,0,0,0,0,0,0,0,0,0,0,0,0,0,0,0,0,0,0,0
0,0,0,0,0,0,0,0,0,0,0,0,0,0,0,0,0,0,0,0,0,0,0,0,0,0,0,0,0,0,0,0,0,0,0
0,0,0,0,0,0,0,0,0,0,0,0,0,0,0,0,0,0,0,0,0,0,21,0,0,0,0,0,0,0,0,0,0,0,0
0,0,0,0,0,0,21,0,0,0,0,0,21,0,0,0,0,0,0,0,0,0,0,0,0,0,0,0,0,0,0,0,0,0,0
0,0,0,0,0,0,0,0,0,0,0,0,0,0,0,0,0,0,0,0,0,0,0,0,0,0,0,0,0,0,0,0,0,0,0
0,0,0,0,0,0,0,0,0,0,0,0,0,0,0,0,0,0,0,0,0,0,21,0,0,0,0,0,0,0,0,0,0,0,0
0,0,0,0,0,0,0,0,0,0,0,0,0,0,0,0,0,0,0,0,0,0,0,0,0,0,0,0,0,0,0,0,0,0,0
0,0,0,0,0,0,0,0,0,0,0,0,0,0,0,0,0,0,0,0,0,0,0,0,0,0,0,0,0,0,0,0,0,0,0
0,0,0,0,0,0,21,0,0,0,0,0,0,0,0,0,0,0,0,0,0,0,0,0,0,0,0,0,0,0,0,0,0,0,0
0,0,0,0,0,0,21,0,0,0,0,0,0,0,0,0,0,0,0,0,0,0,0,0,21,0,0,0,0,0,0,0,0,0,0
0,0,0,0,0,0,0,0,0,0,0,21,0,0,0,0,0,0,0,0,0,0,0,0,0,0,0,0,0,0,0,0,0,0,0
0,0,0,0,0,0,0,0,0,0,0,0,0,0,0,0,0,0,0,0,0,0,0,0,0,0,0,0,0,0,0,0,0,0,0
0,0,0,0,0,0,0,0,0,0,0,0,0,0,0,0,0,0,0,0,0,0,0,0,0,0,0,0,0,0,0,0,0,0,0
0,0,0,0,0,0,0,0,0,0,0,0,0,0,0,0,0,0,0,0,0,0,0,0,0,0,0,0,0,0,0,0,0,0,0
0,0,0,0,0,0,0,0,0,0,0,0,8,8,8,0,0,0,0,8,8,8,0,0,0,0,0,0,0,0,0,0,0,0,0
0,0,0,0,0,0,0,0,0,0,0,0,0,0,0,0,0,0,0,0,0,0,0,0,0,0,0,0,0,0,0,0,0,0,0
0,0,0,0,0,0,0,0,0,0,0,0,0,0,0,0,0,0,0,0,0,0,0,0,0,0,0,0,0,0,0,0,0,0,0
0,0,0,0,0,0,0,0,0,0,0,0,0,0,0,0,0,0,0,0,0,0,0,0,0,0,0,0,0,0,0,0,0,0,0
:endlayer
layer: 7
0,0,0,0,0,0,0,0,0,0,0,0,0,0,0,0,0,0,0,0,0,0,0,80,0,0,0,0,0,0,0,0,0,0,0
0,0,0,0,0,0,0,0,0,0,0,0,0,0,0,0,0,0,0,0,0,0,0,0,0,0,0,0,0,0,0,0,0,0,0
0,0,0,0,0,0,0,0,0,0,0,0,0,0,0,0,0,0,0,0,0,0,0,0,0,0,0,0,0,0,0,0,0,0,0
0,0,0,0,0,0,0,0,0,0,0,0,0,0,0,0,0,0,0,0,0,0,0,0,0,0,0,0,0,0,0,0,0,0,0
0,0,0,0,0,0,0,0,0,0,0,0,0,0,0,0,0,0,0,0,0,0,0,0,0,0,0,0,0,0,0,0,0,0,0
0,0,0,0,0,0,0,0,0,0,0,0,0,0,0,0,0,0,0,0,0,0,0,0,0,0,0,0,0,0,0,0,0,0,0
0,0,0,0,0,0,0,0,0,0,0,0,0,0,0,0,0,0,0,0,0,0,0,0,0,0,0,0,0,0,0,0,0,0,0
0,0,0,0,0,0,0,0,0,0,0,0,0,11,35,35,35,35,35,35,0,0,0,0,0,0,0,0,0,0,0,0,0,0,0
0,0,0,0,0,0,0,0,0,0,0,0,0,11,6,16,0,17,6,10,0,0,0,0,0,0,0,0,0,0,0,0,0,0,0
0,0,0,0,0,0,0,0,0,0,0,0,0,11,56,0,0,0,56,10,0,0,0,0,0,0,0,0,0,0,0,0,0,0,0
0,0,0,0,0,0,0,0,0,0,0,0,0,11,81,0,0,0,0,10,0,0,0,0,0,0,0,0,0,0,0,0,0,0,0
0,0,0,0,0,0,0,0,0,0,0,0,0,11,33,0,0,0,33,10,0,0,0,0,0,0,0,0,0,0,0,0,0,0,0
0,0,0,0,0,0,0,0,0,0,0,0,0,11,6,16,0,17,6,10,0,0,0,0,0,0,0,0,0,0,0,0,0,0,0
0,0,0,0,0,0,0,0,0,0,0,0,0,11,55,55,55,55,55,10,0,0,0,0,0,0,0,0,0,0,0,0,0,0,0
0,0,0,0,0,0,0,0,0,0,0,0,0,0,0,0,0,0,0,0,0,0,0,0,0,0,0,0,0,0,0,0,0,0,0
0,0,0,0,0,0,0,0,0,0,0,0,0,0,0,0,0,0,0,0,0,0,0,0,0,0,0,0,0,0,0,0,0,0,0
0,0,0,0,0,0,0,0,0,0,0,0,0,0,0,0,0,0,0,0,0,0,0,0,0,0,0,0,0,0,0,0,0,0,0
0,0,0,0,0,0,0,0,0,0,0,0,0,0,0,0,0,0,0,0,0,0,0,0,0,0,0,0,0,0,0,0,0,0,0
0,0,0,0,0,0,0,0,0,0,0,0,0,0,0,0,0,0,0,0,0,0,0,0,0,0,0,0,0,0,0,0,0,0,0
0,0,0,0,0,0,0,0,0,0,0,0,0,0,0,0,0,0,0,0,0,0,0,0,0,0,0,0,0,0,0,0,0,0,0
0,0,0,0,0,0,0,0,0,0,0,0,0,0,0,0,0,0,0,0,0,0,0,0,0,0,0,0,0,0,0,0,0,0,0
0,0,0,0,0,0,0,0,0,0,0,0,0,0,0,0,0,0,0,0,0,0,0,0,0,0,0,0,0,0,0,0,0,0,0
0,0,0,0,0,0,0,0,0,0,0,0,0,0,0,0,0,0,0,0,0,0,0,0,0,0,0,0,0,0,0,0,0,0,0
0,0,0,0,0,0,0,0,0,0,0,0,0,0,0,0,0,0,0,0,0,0,0,0,0,0,0,0,0,0,0,0,0,0,0
0,0,0,0,0,0,0,0,0,0,0,0,0,0,0,0,0,0,0,0,0,0,0,0,0,0,0,0,0,0,0,0,0,0,0
0,0,0,0,0,0,0,0,0,0,0,0,0,0,0,0,0,0,0,0,0,0,0,0,0,0,0,0,0,0,0,0,0,0,0
0,0,0,0,0,0,0,0,0,0,0,0,0,0,0,0,0,0,0,0,0,0,0,0,0,0,0,0,0,0,0,0,0,0,0
0,0,0,0,0,0,0,0,0,0,0,0,0,0,0,0,0,0,0,0,0,0,0,0,0,0,0,0,0,0,0,0,0,0,0
0,0,0,0,0,0,0,0,0,0,0,0,0,0,0,0,0,0,0,0,0,0,0,0,0,0,0,0,0,0,0,0,0,0,0
0,0,0,0,0,0,0,0,0,0,0,0,0,0,0,0,0,0,0,0,0,0,0,0,0,0,0,0,0,0,0,0,0,0,0
0,0,0,0,0,0,0,0,0,0,0,0,0,0,0,0,0,0,0,0,0,0,0,0,0,0,0,0,0,0,0,0,0,0,0
0,0,0,0,0,0,0,0,0,0,0,0,0,0,0,0,0,0,0,0,0,0,0,0,0,0,0,0,0,0,0,0,0,0,0
0,0,0,0,0,0,0,0,0,0,0,0,0,21,8,0,0,0,0,8,21,0,0,0,0,0,0,0,0,0,0,0,0,0,0
0,0,0,0,0,0,0,0,0,0,0,0,0,0,0,0,0,0,0,0,0,0,0,0,0,0,0,0,0,0,0,0,0,0,0
0,0,0,0,0,0,0,0,0,0,0,0,0,0,0,0,0,0,0,0,0,0,0,0,0,0,0,0,0,0,0,0,0,0,0
0,0,0,0,0,0,0,0,0,0,0,0,0,0,0,0,0,0,0,0,0,0,0,0,0,0,0,0,0,0,0,0,0,0,0
:endlayer
layer: 8
0,0,0,0,0,0,0,0,0,0,0,0,0,0,0,0,0,0,0,0,0,0,0,0,0,0,0,0,0,0,0,0,0,0,0
0,0,0,0,0,0,0,0,0,0,0,0,0,0,0,0,0,0,0,0,0,0,0,0,0,0,0,0,0,0,0,0,0,0,0
0,0,0,0,0,0,0,0,0,0,0,0,0,0,0,0,0,0,0,0,0,0,0,0,0,0,0,0,0,0,0,0,0,0,0
0,0,0,0,0,0,0,0,0,0,0,0,0,0,0,0,0,0,0,0,0,0,0,0,0,0,0,0,0,0,0,0,0,0,0
0,0,0,0,0,0,0,0,0,0,0,0,0,0,0,0,0,0,0,0,0,0,0,0,0,0,0,0,0,0,0,0,0,0,0
0,0,0,0,0,0,0,0,0,0,0,0,0,0,0,0,0,0,0,0,0,0,0,0,0,0,0,0,0,0,0,0,0,0,0
0,0,0,0,0,0,0,0,0,0,0,0,0,0,0,0,0,0,0,0,0,0,0,0,0,0,0,0,0,0,0,0,0,0,0
0,0,0,0,0,0,0,0,0,0,0,0,0,0,0,0,0,0,0,0,0,0,0,0,0,0,0,0,0,0,0,0,0,0,0
0,0,0,0,0,0,0,0,0,0,0,0,0,0,11,35,35,35,10,0,0,0,0,0,0,0,0,0,0,0,0,0,0,0,0
0,0,0,0,0,0,0,0,0,0,0,0,0,0,11,6,25,6,10,0,0,0,0,0,0,0,0,0,0,0,0,0,0,0,0
0,0,0,0,0,0,0,0,0,0,0,0,0,0,11,27,0,30,10,0,0,0,0,0,0,0,0,0,0,0,0,0,0,0,0
0,0,0,0,0,0,0,0,0,0,0,0,0,0,11,6,32,6,10,0,0,0,0,0,0,0,0,0,0,0,0,0,0,0,0
0,0,0,0,0,0,0,0,0,0,0,0,0,0,11,55,55,55,55,0,0,0,0,0,0,0,0,0,0,0,0,0,0,0,0
0,0,0,0,0,0,0,0,0,0,0,0,0,0,0,0,0,0,0,0,0,0,0,0,0,0,0,0,0,0,0,0,0,0,0
0,0,0,0,0,0,0,0,0,0,0,0,0,0,0,0,0,0,0,0,0,0,0,0,0,0,0,0,0,0,0,0,0,0,0
0,0,0,0,0,0,0,0,0,0,0,0,0,0,0,0,0,0,0,0,0,0,0,0,0,0,0,0,0,0,0,0,0,0,0
0,0,0,0,0,0,0,0,0,0,0,0,0,0,0,0,0,0,0,0,0,0,0,0,0,0,0,0,0,0,0,0,0,0,0
0,0,0,0,0,0,0,0,0,0,0,0,0,0,0,0,0,0,0,0,0,0,0,0,0,0,0,0,0,0,0,0,0,0,0
0,0,0,0,0,0,0,0,0,0,0,0,0,0,0,0,0,0,0,0,0,0,0,0,0,0,0,0,0,0,0,0,0,0,0
0,0,0,0,0,0,0,0,0,0,0,0,0,0,0,0,0,0,0,0,0,0,0,0,0,0,0,0,0,0,0,0,0,0,0
0,0,0,0,0,0,0,0,0,0,0,0,0,0,0,0,0,0,0,0,0,0,0,0,0,0,0,0,0,0,0,0,0,0,0
0,0,0,0,0,0,0,0,0,0,0,0,0,0,0,0,0,0,0,0,0,0,0,0,0,0,0,0,0,0,0,0,0,0,0
0,0,0,0,0,0,0,0,0,0,0,0,0,0,0,0,0,0,0,0,0,0,0,0,0,0,0,0,0,0,0,0,0,0,0
0,0,0,0,0,0,0,0,0,0,0,0,0,0,0,0,0,0,0,0,0,0,0,0,0,0,0,0,0,0,0,0,0,0,0
0,0,0,0,0,0,0,0,0,0,0,0,0,0,0,0,0,0,0,0,0,0,0,0,0,0,0,0,0,0,0,0,0,0,0
0,0,0,0,0,0,0,0,0,0,0,0,0,0,0,0,0,0,0,0,0,0,0,0,0,0,0,0,0,0,0,0,0,0,0
0,0,0,0,0,0,0,0,0,0,0,0,0,0,0,0,0,0,0,0,0,0,0,0,0,0,0,0,0,0,0,0,0,0,0
0,0,0,0,0,0,0,0,0,0,0,0,0,0,0,0,0,0,0,0,0,0,0,0,0,0,0,0,0,0,0,0,0,0,0
0,0,0,0,0,0,0,0,0,0,0,0,0,0,0,0,0,0,0,0,0,0,0,0,0,0,0,0,0,0,0,0,0,0,0
0,0,0,0,0,0,0,0,0,0,0,0,0,0,0,0,0,0,0,0,0,0,0,0,0,0,0,0,0,0,0,0,0,0,0
0,0,0,0,0,0,0,0,0,0,0,0,0,0,0,0,0,0,0,0,0,0,0,0,0,0,0,0,0,0,0,0,0,0,0
0,0,0,0,0,0,0,0,0,0,0,0,0,0,0,0,0,0,0,0,0,0,0,0,0,0,0,0,0,0,0,0,0,0,0
0,0,0,0,0,0,0,0,0,0,0,0,0,0,8,0,0,0,0,8,0,0,0,0,0,0,0,0,0,0,0,0,0,0,0
0,0,0,0,0,0,0,0,0,0,0,0,0,0,8,8,8,8,8,8,0,0,0,0,0,0,0,0,0,0,0,0,0,0,0
0,0,0,0,0,0,0,0,0,0,0,0,0,0,0,0,0,0,0,0,0,0,0,0,0,0,0,0,0,0,0,0,0,0,0
0,0,0,0,0,0,0,0,0,0,0,0,0,0,0,0,0,0,0,0,0,0,0,0,0,0,0,0,0,0,0,0,0,0,0
:endlayer
layer: 9
0,0,0,0,0,0,0,0,0,0,0,0,0,0,0,0,0,0,0,0,0,0,0,0,0,0,0,0,0,0,0,0,0,0,0
0,0,0,0,0,0,0,0,0,0,0,0,0,0,0,0,0,0,0,0,0,0,0,0,0,0,0,0,0,0,0,0,0,0,0
0,0,0,0,0,0,0,0,0,0,0,0,0,0,0,0,0,0,0,0,0,0,0,0,0,0,0,0,0,0,0,0,0,0,0
0,0,0,0,0,0,0,0,0,0,0,0,0,0,0,0,0,0,0,0,0,0,0,0,0,0,0,0,0,0,0,0,0,0,0
0,0,0,0,0,0,0,0,0,0,0,0,0,0,0,0,0,0,0,0,0,0,0,0,0,0,0,0,0,0,0,0,0,0,0
0,0,0,0,0,0,0,0,0,0,0,0,0,0,0,0,0,0,0,0,0,0,0,0,0,0,0,0,0,0,0,0,0,0,0
0,0,0,0,0,0,0,0,0,0,0,0,0,0,0,0,0,0,0,0,0,0,0,0,0,0,0,0,0,0,0,0,0,0,0
0,0,0,0,0,0,0,0,0,0,0,0,0,0,0,0,0,0,0,0,0,0,0,0,0,0,0,0,0,0,0,0,0,0,0
0,0,0,0,0,0,0,0,0,0,0,0,0,0,0,0,0,0,0,0,0,0,0,0,0,0,0,0,0,0,0,0,0,0,0
0,0,0,0,0,0,0,0,0,0,0,0,0,0,0,35,35,35,0,0,0,0,0,0,0,0,0,0,0,0,0,0,0,0,0
0,0,0,0,0,0,0,0,0,0,0,0,0,0,0,11,6,10,0,0,0,0,0,0,0,0,0,0,0,0,0,0,0,0,0
0,0,0,0,0,0,0,0,0,0,0,0,0,0,0,11,55,55,0,0,0,0,0,0,0,0,0,0,0,0,0,0,0,0,0
0,0,0,0,0,0,0,0,0,0,0,0,0,0,0,0,0,0,0,0,0,0,0,0,0,0,0,0,0,0,0,0,0,0,0
0,0,0,0,0,0,0,0,0,0,0,0,0,0,0,0,0,0,0,0,0,0,0,0,0,0,0,0,0,0,0,0,0,0,0
0,0,0,0,0,0,0,0,0,0,0,0,0,0,0,0,0,0,0,0,0,0,0,0,0,0,0,0,0,0,0,0,0,0,0
0,0,0,0,0,0,0,0,0,0,0,0,0,0,0,0,0,0,0,0,0,0,0,0,0,0,0,0,0,0,0,0,0,0,0
0,0,0,0,0,0,0,0,0,0,0,0,0,0,0,0,0,0,0,0,0,0,0,0,0,0,0,0,0,0,0,0,0,0,0
0,0,0,0,0,0,0,0,0,0,0,0,0,0,0,0,0,0,0,0,0,0,0,0,0,0,0,0,0,0,0,0,0,0,0
0,0,0,0,0,0,0,0,0,0,0,0,0,0,0,0,0,0,0,0,0,0,0,0,0,0,0,0,0,0,0,0,0,0,0
0,0,0,0,0,0,0,0,0,0,0,0,0,0,0,0,0,0,0,0,0,0,0,0,0,0,0,0,0,0,0,0,0,0,0
0,0,0,0,0,0,0,0,0,0,0,0,0,0,0,0,0,0,0,0,0,0,0,0,0,0,0,0,0,0,0,0,0,0,0
0,0,0,0,0,0,0,0,0,0,0,0,0,0,0,0,0,0,0,0,0,0,0,0,0,0,0,0,0,0,0,0,0,0,0
0,0,0,0,0,0,0,0,0,0,0,0,0,0,0,0,0,0,0,0,0,0,0,0,0,0,0,0,0,0,0,0,0,0,0
0,0,0,0,0,0,0,0,0,0,0,0,0,0,0,0,0,0,0,0,0,0,0,0,0,0,0,0,0,0,0,0,0,0,0
0,0,0,0,0,0,0,0,0,0,0,0,0,0,0,0,0,0,0,0,0,0,0,0,0,0,0,0,0,0,0,0,0,0,0
0,0,0,0,0,0,0,0,0,0,0,0,0,0,0,0,0,0,0,0,0,0,0,0,0,0,0,0,0,0,0,0,0,0,0
0,0,0,0,0,0,0,0,0,0,0,0,0,0,0,0,0,0,0,0,0,0,0,0,0,0,0,0,0,0,0,0,0,0,0
0,0,0,0,0,0,0,0,0,0,0,0,0,0,0,0,0,0,0,0,0,0,0,0,0,0,0,0,0,0,0,0,0,0,0
0,0,0,0,0,0,0,0,0,0,0,0,0,0,0,0,0,0,0,0,0,0,0,0,0,0,0,0,0,0,0,0,0,0,0
0,0,0,0,0,0,0,0,0,0,0,0,0,0,0,0,0,0,0,0,0,0,0,0,0,0,0,0,0,0,0,0,0,0,0
0,0,0,0,0,0,0,0,0,0,0,0,0,0,0,0,0,0,0,0,0,0,0,0,0,0,0,0,0,0,0,0,0,0,0
0,0,0,0,0,0,0,0,0,0,0,0,0,0,0,0,0,0,0,0,0,0,0,0,0,0,0,0,0,0,0,0,0,0,0
0,0,0,0,0,0,0,0,0,0,0,0,0,0,0,0,0,0,0,0,0,0,0,0,0,0,0,0,0,0,0,0,0,0,0
0,0,0,0,0,0,0,0,0,0,0,0,0,0,0,0,0,0,0,0,0,0,0,0,0,0,0,0,0,0,0,0,0,0,0
0,0,0,0,0,0,0,0,0,0,0,0,0,0,0,0,0,0,0,0,0,0,0,0,0,0,0,0,0,0,0,0,0,0,0
0,0,0,0,0,0,0,0,0,0,0,0,0,0,0,0,0,0,0,0,0,0,0,0,0,0,0,0,0,0,0,0,0,0,0
:endlayer
layer: 10
0,0,0,0,0,0,0,0,0,0,0,0,0,0,0,0,0,0,0,0,0,0,0,0,0,0,0,0,0,0,0,0,0,0,0
0,0,0,0,0,0,0,0,0,0,0,0,0,0,0,0,0,0,0,0,0,0,0,0,0,0,0,0,0,0,0,0,0,0,0
0,0,0,0,0,0,0,0,0,0,0,0,0,0,0,0,0,0,0,0,0,0,0,0,0,0,0,0,0,0,0,0,0,0,0
0,0,0,0,0,0,0,0,0,0,0,0,0,0,0,0,0,0,0,0,0,0,0,0,0,0,0,0,0,0,0,0,0,0,0
0,0,0,0,0,0,0,0,0,0,0,0,0,0,0,0,0,0,0,0,0,0,0,0,0,0,0,0,0,0,0,0,0,0,0
0,0,0,0,0,0,0,0,0,0,0,0,0,0,0,0,0,0,0,0,0,0,0,0,0,0,0,0,0,0,0,0,0,0,0
0,0,0,0,0,0,0,0,0,0,0,0,0,0,0,0,0,0,0,0,0,0,0,0,0,0,0,0,0,0,0,0,0,0,0
0,0,0,0,0,0,0,0,0,0,0,0,0,0,0,0,0,0,0,0,0,0,0,0,0,0,0,0,0,0,0,0,0,0,0
0,0,0,0,0,0,0,0,0,0,0,0,0,0,0,0,0,0,0,0,0,0,0,0,0,0,0,0,0,0,0,0,0,0,0
0,0,0,0,0,0,0,0,0,0,0,0,0,0,0,0,0,0,0,0,0,0,0,0,0,0,0,0,0,0,0,0,0,0,0
0,0,0,0,0,0,0,0,0,0,0,0,0,0,0,0,21,0,0,0,0,0,0,0,0,0,0,0,0,0,0,0,0,0,0
0,0,0,0,0,0,0,0,0,0,0,0,0,0,0,0,0,0,0,0,0,0,0,0,0,0,0,0,0,0,0,0,0,0,0
0,0,0,0,0,0,0,0,0,0,0,0,0,0,0,0,0,0,0,0,0,0,0,0,0,0,0,0,0,0,0,0,0,0,0
0,0,0,0,0,0,0,0,0,0,0,0,0,0,0,0,0,0,0,0,0,0,0,0,0,0,0,0,0,0,0,0,0,0,0
0,0,0,0,0,0,0,0,0,0,0,0,0,0,0,0,0,0,0,0,0,0,0,0,0,0,0,0,0,0,0,0,0,0,0
0,0,0,0,0,0,0,0,0,0,0,0,0,0,0,0,0,0,0,0,0,0,0,0,0,0,0,0,0,0,0,0,0,0,0
0,0,0,0,0,0,0,0,0,0,0,0,0,0,0,0,0,0,0,0,0,0,0,0,0,0,0,0,0,0,0,0,0,0,0
0,0,0,0,0,0,0,0,0,0,0,0,0,0,0,0,0,0,0,0,0,0,0,0,0,0,0,0,0,0,0,0,0,0,0
0,0,0,0,0,0,0,0,0,0,0,0,0,0,0,0,0,0,0,0,0,0,0,0,0,0,0,0,0,0,0,0,0,0,0
0,0,0,0,0,0,0,0,0,0,0,0,0,0,0,0,0,0,0,0,0,0,0,0,0,0,0,0,0,0,0,0,0,0,0
0,0,0,0,0,0,0,0,0,0,0,0,0,0,0,0,0,0,0,0,0,0,0,0,0,0,0,0,0,0,0,0,0,0,0
0,0,0,0,0,0,0,0,0,0,0,0,0,0,0,0,0,0,0,0,0,0,0,0,0,0,0,0,0,0,0,0,0,0,0
0,0,0,0,0,0,0,0,0,0,0,0,0,0,0,0,0,0,0,0,0,0,0,0,0,0,0,0,0,0,0,0,0,0,0
0,0,0,0,0,0,0,0,0,0,0,0,0,0,0,0,0,0,0,0,0,0,0,0,0,0,0,0,0,0,0,0,0,0,0
0,0,0,0,0,0,0,0,0,0,0,0,0,0,0,0,0,0,0,0,0,0,0,0,0,0,0,0,0,0,0,0,0,0,0
0,0,0,0,0,0,0,0,0,0,0,0,0,0,0,0,0,0,0,0,0,0,0,0,0,0,0,0,0,0,0,0,0,0,0
0,0,0,0,0,0,0,0,0,0,0,0,0,0,0,0,0,0,0,0,0,0,0,0,0,0,0,0,0,0,0,0,0,0,0
0,0,0,0,0,0,0,0,0,0,0,0,0,0,0,0,0,0,0,0,0,0,0,0,0,0,0,0,0,0,0,0,0,0,0
0,0,0,0,0,0,0,0,0,0,0,0,0,0,0,0,0,0,0,0,0,0,0,0,0,0,0,0,0,0,0,0,0,0,0
0,0,0,0,0,0,0,0,0,0,0,0,0,0,0,0,0,0,0,0,0,0,0,0,0,0,0,0,0,0,0,0,0,0,0
0,0,0,0,0,0,0,0,0,0,0,0,0,0,0,0,0,0,0,0,0,0,0,0,0,0,0,0,0,0,0,0,0,0,0
0,0,0,0,0,0,0,0,0,0,0,0,0,0,0,0,0,0,0,0,0,0,0,0,0,0,0,0,0,0,0,0,0,0,0
0,0,0,0,0,0,0,0,0,0,0,0,0,0,0,0,0,0,0,0,0,0,0,0,0,0,0,0,0,0,0,0,0,0,0
0,0,0,0,0,0,0,0,0,0,0,0,0,0,0,0,0,0,0,0,0,0,0,0,0,0,0,0,0,0,0,0,0,0,0
0,0,0,0,0,0,0,0,0,0,0,0,0,0,0,0,0,0,0,0,0,0,0,0,0,0,0,0,0,0,0,0,0,0,0
0,0,0,0,0,0,0,0,0,0,0,0,0,0,0,0,0,0,0,0,0,0,0,0,0,0,0,0,0,0,0,0,0,0,0
:endlayer
layer: 11
0,0,0,0,0,0,0,0,0,0,0,0,0,0,0,0,0,0,0,0,0,0,0,0,0,0,0,0,0,0,0,0,0,0,0
0,0,0,0,0,0,0,0,0,0,0,0,0,0,0,0,0,0,0,0,0,0,0,0,0,0,0,0,0,0,0,0,0,0,0
0,0,0,0,0,0,0,0,0,0,0,0,0,0,0,0,0,0,0,0,0,0,0,0,0,0,0,0,0,0,0,0,0,0,0
0,0,0,0,0,0,0,0,0,0,0,0,0,0,0,0,0,0,0,0,0,0,0,0,0,0,0,0,0,0,0,0,0,0,0
0,0,0,0,0,0,0,0,0,0,0,0,0,0,0,0,0,0,0,0,0,0,0,0,0,0,0,0,0,0,0,0,0,0,0
0,0,0,0,0,0,0,0,0,0,0,0,0,0,0,0,0,0,0,0,0,0,0,0,0,0,0,0,0,0,0,0,0,0,0
0,0,0,0,0,0,0,0,0,0,0,0,0,0,0,0,0,0,0,0,0,0,0,0,0,0,0,0,0,0,0,0,0,0,0
0,0,0,0,0,0,0,0,0,0,0,0,0,0,0,0,0,0,0,0,0,0,0,0,0,0,0,0,0,0,0,0,0,0,0
0,0,0,0,0,0,0,0,0,0,0,0,0,0,0,0,0,0,0,0,0,0,0,0,0,0,0,0,0,0,0,0,0,0,0
0,0,0,0,0,0,0,0,0,0,0,0,0,0,0,0,0,0,0,0,0,0,0,0,0,0,0,0,0,0,0,0,0,0,0
0,0,0,0,0,0,0,0,0,0,0,0,0,0,0,0,0,0,0,0,0,0,0,0,0,0,0,0,0,0,0,0,0,0,0
0,0,0,0,0,0,0,0,0,0,0,0,0,0,0,0,0,0,0,0,0,0,0,0,0,0,0,0,0,0,0,0,0,0,0
0,0,0,0,0,0,0,0,0,0,0,0,0,0,0,0,0,0,0,0,0,0,0,0,0,0,0,0,0,0,0,0,0,0,0
0,0,0,0,0,0,0,0,0,0,0,0,0,0,0,0,0,0,0,0,0,0,0,0,0,0,0,0,0,0,0,0,0,0,0
0,0,0,0,0,0,0,0,0,0,0,0,0,0,0,0,0,0,0,0,0,0,0,0,0,0,0,0,0,0,0,0,0,0,0
0,0,0,0,0,0,0,0,0,0,0,0,0,0,0,0,0,0,0,0,0,0,0,0,0,0,0,0,0,0,0,0,0,0,0
0,0,0,0,0,0,0,0,0,0,0,0,0,0,0,0,0,0,0,0,0,0,0,0,0,0,0,0,0,0,0,0,0,0,0
0,0,0,0,0,0,0,0,0,0,0,0,0,0,0,0,0,0,0,0,0,0,0,0,0,0,0,0,0,0,0,0,0,0,0
0,0,0,0,0,0,0,0,0,0,0,0,0,0,0,0,0,0,0,0,0,0,0,0,0,0,0,0,0,0,0,0,0,0,0
0,0,0,0,0,0,0,0,0,0,0,0,0,0,0,0,0,0,0,0,0,0,0,0,0,0,0,0,0,0,0,0,0,0,0
0,0,0,0,0,0,0,0,0,0,0,0,0,0,0,0,0,0,0,0,0,0,0,0,0,0,0,0,0,0,0,0,0,0,0
0,0,0,0,0,0,0,0,0,0,0,0,0,0,0,0,0,0,0,0,0,0,0,0,0,0,0,0,0,0,0,0,0,0,0
0,0,0,0,0,0,0,0,0,0,0,0,0,0,0,0,0,0,0,0,0,0,0,0,0,0,0,0,0,0,0,0,0,0,0
0,0,0,0,0,0,0,0,0,0,0,0,0,0,0,0,0,0,0,0,0,0,0,0,0,0,0,0,0,0,0,0,0,0,0
0,0,0,0,0,0,0,0,0,0,0,0,0,0,0,0,0,0,0,0,0,0,0,0,0,0,0,0,0,0,0,0,0,0,0
0,0,0,0,0,0,0,0,0,0,0,0,0,0,0,0,0,0,0,0,0,0,0,0,0,0,0,0,0,0,0,0,0,0,0
0,0,0,0,0,0,0,0,0,0,0,0,0,0,0,0,0,0,0,0,0,0,0,0,0,0,0,0,0,0,0,0,0,0,0
0,0,0,0,0,0,0,0,0,0,0,0,0,0,0,0,0,0,0,0,0,0,0,0,0,0,0,0,0,0,0,0,0,0,0
0,0,0,0,0,0,0,0,0,0,0,0,0,0,0,0,0,0,0,0,0,0,0,0,0,0,0,0,0,0,0,0,0,0,0
0,0,0,0,0,0,0,0,0,0,0,0,0,0,0,0,0,0,0,0,0,0,0,0,0,0,0,0,0,0,0,0,0,0,0
0,0,0,0,0,0,0,0,0,0,0,0,0,0,0,0,0,0,0,0,0,0,0,0,0,0,0,0,0,0,0,0,0,0,0
0,0,0,0,0,0,0,0,0,0,0,0,0,0,0,0,0,0,0,0,0,0,0,0,0,0,0,0,0,0,0,0,0,0,0
0,0,0,0,0,0,0,0,0,0,0,0,0,0,0,0,0,0,0,0,0,0,0,0,0,0,0,0,0,0,0,0,0,0,0
0,0,0,0,0,0,0,0,0,0,0,0,0,0,0,0,0,0,0,0,0,0,0,0,0,0,0,0,0,0,0,0,0,0,0
0,0,0,0,0,0,0,0,0,0,0,0,0,0,0,0,0,0,0,0,0,0,0,0,0,0,0,0,0,0,0,0,0,0,0
0,0,0,0,0,0,0,0,0,0,0,0,0,0,0,0,0,0,0,0,0,0,0,0,0,0,0,0,0,0,0,0,0,0,0
:endlayer
layer: 12
0,0,0,0,0,0,0,0,0,0,0,0,0,0,0,0,0,0,0,0,0,0,0,0,0,0,0,0,0,0,0,0,0,0,0
0,0,0,0,0,0,0,0,0,0,0,0,0,0,0,0,0,0,0,0,0,0,0,0,0,0,0,0,0,0,0,0,0,0,0
0,0,0,0,0,0,0,0,0,0,0,0,0,0,0,0,0,0,0,0,0,0,0,0,0,0,0,0,0,0,0,0,0,0,0
0,0,0,0,0,0,0,0,0,0,0,0,0,0,0,0,0,0,0,0,0,0,0,0,0,0,0,0,0,0,0,0,0,0,0
0,0,0,0,0,0,0,0,0,0,0,0,0,0,0,0,0,0,0,0,0,0,0,0,0,0,0,0,0,0,0,0,0,0,0
0,0,0,0,0,0,0,0,0,0,0,0,0,0,0,0,0,0,0,0,0,0,0,0,0,0,0,0,0,0,0,0,0,0,0
0,0,0,0,0,0,0,0,0,0,0,0,0,0,0,0,0,0,0,0,0,0,0,0,0,0,0,0,0,0,0,0,0,0,0
0,0,0,0,0,0,0,0,0,0,0,0,0,0,0,0,0,0,0,0,0,0,0,0,0,0,0,0,0,0,0,0,0,0,0
0,0,0,0,0,0,0,0,0,0,0,0,0,0,0,0,0,0,0,0,0,0,0,0,0,0,0,0,0,0,0,0,0,0,0
0,0,0,0,0,0,0,0,0,0,0,0,0,0,0,0,0,0,0,0,0,0,0,0,0,0,0,0,0,0,0,0,0,0,0
0,0,0,0,0,0,0,0,0,0,0,0,0,0,0,0,0,0,0,0,0,0,0,0,0,0,0,0,0,0,0,0,0,0,0
0,0,0,0,0,0,0,0,0,0,0,0,0,0,0,0,0,0,0,0,0,0,0,0,0,0,0,0,0,0,0,0,0,0,0
0,0,0,0,0,0,0,0,0,0,0,0,0,0,0,0,0,0,0,0,0,0,0,0,0,0,0,0,0,0,0,0,0,0,0
0,0,0,0,0,0,0,0,0,0,0,0,0,0,0,0,0,0,0,0,0,0,0,0,0,0,0,0,0,0,0,0,0,0,0
0,0,0,0,0,0,0,0,0,0,0,0,0,0,0,0,0,0,0,0,0,0,0,0,0,0,0,0,0,0,0,0,0,0,0
0,0,0,0,0,0,0,0,0,0,0,0,0,0,0,0,0,0,0,0,0,0,0,0,0,0,0,0,0,0,0,0,0,0,0
0,0,0,0,0,0,0,0,0,0,0,0,0,0,0,0,0,0,0,0,0,0,0,0,0,0,0,0,0,0,0,0,0,0,0
0,0,0,0,0,0,0,0,0,0,0,0,0,0,0,0,0,0,0,0,0,0,0,0,0,0,0,0,0,0,0,0,0,0,0
0,0,0,0,0,0,0,0,0,0,0,0,0,0,0,0,0,0,0,0,0,0,0,0,0,0,0,0,0,0,0,0,0,0,0
0,0,0,0,0,0,0,0,0,0,0,0,0,0,0,0,0,0,0,0,0,0,0,0,0,0,0,0,0,0,0,0,0,0,0
0,0,0,0,0,0,0,0,0,0,0,0,0,0,0,0,0,0,0,0,0,0,0,0,0,0,0,0,0,0,0,0,0,0,0
0,0,0,0,0,0,0,0,0,0,0,0,0,0,0,0,0,0,0,0,0,0,0,0,0,0,0,0,0,0,0,0,0,0,0
0,0,0,0,0,0,0,0,0,0,0,0,0,0,0,0,0,0,0,0,0,0,0,0,0,0,0,0,0,0,0,0,0,0,0
0,0,0,0,0,0,0,0,0,0,0,0,0,0,0,0,0,0,0,0,0,0,0,0,0,0,0,0,0,0,0,0,0,0,0
0,0,0,0,0,0,0,0,0,0,0,0,0,0,0,0,0,0,0,0,0,0,0,0,0,0,0,0,0,0,0,0,0,0,0
0,0,0,0,0,0,0,0,0,0,0,0,0,0,0,0,0,0,0,0,0,0,0,0,0,0,0,0,0,0,0,0,0,0,0
0,0,0,0,0,0,0,0,0,0,0,0,0,0,0,0,0,0,0,0,0,0,0,0,0,0,0,0,0,0,0,0,0,0,0
0,0,0,0,0,0,0,0,0,0,0,0,0,0,0,0,0,0,0,0,0,0,0,0,0,0,0,0,0,0,0,0,0,0,0
0,0,0,0,0,0,0,0,0,0,0,0,0,0,0,0,0,0,0,0,0,0,0,0,0,0,0,0,0,0,0,0,0,0,0
0,0,0,0,0,0,0,0,0,0,0,0,0,0,0,0,0,0,0,0,0,0,0,0,0,0,0,0,0,0,0,0,0,0,0
0,0,0,0,0,0,0,0,0,0,0,0,0,0,0,0,0,0,0,0,0,0,0,0,0,0,0,0,0,0,0,0,0,0,0
0,0,0,0,0,0,0,0,0,0,0,0,0,0,0,0,0,0,0,0,0,0,0,0,0,0,0,0,0,0,0,0,0,0,0
0,0,0,0,0,0,0,0,0,0,0,0,0,0,0,0,0,0,0,0,0,0,0,0,0,0,0,0,0,0,0,0,0,0,0
0,0,0,0,0,0,0,0,0,0,0,0,0,0,0,0,0,0,0,0,0,0,0,0,0,0,0,0,0,0,0,0,0,0,0
0,0,0,0,0,0,0,0,0,0,0,0,0,0,0,0,0,0,0,0,0,0,0,0,0,0,0,0,0,0,0,0,0,0,0
0,0,0,0,0,0,0,0,0,0,0,0,0,0,0,0,0,0,0,0,0,0,0,0,0,0,0,0,0,0,0,0,0,0,0
:endlayer
layer: 13
0,0,0,0,0,0,0,0,0,0,0,0,0,0,0,0,0,0,0,0,0,0,0,0,0,0,0,0,0,0,0,0,0,0,0
0,0,0,0,0,0,0,0,0,0,0,0,0,0,0,0,0,0,0,0,0,0,0,0,0,0,0,0,0,0,0,0,0,0,0
0,0,0,0,0,0,0,0,0,0,0,0,0,0,0,0,0,0,0,0,0,0,0,0,0,0,0,0,0,0,0,0,0,0,0
0,0,0,0,0,0,0,0,0,0,0,0,0,0,0,0,0,0,0,0,0,0,0,0,0,0,0,0,0,0,0,0,0,0,0
0,0,0,0,0,0,0,0,0,0,0,0,0,0,0,0,0,0,0,0,0,0,0,0,0,0,0,0,0,0,0,0,0,0,0
0,0,0,0,0,0,0,0,0,0,0,0,0,0,0,0,0,0,0,0,0,0,0,0,0,0,0,0,0,0,0,0,0,0,0
0,0,0,0,0,0,0,0,0,0,0,0,0,0,0,0,0,0,0,0,0,0,0,0,0,0,0,0,0,0,0,0,0,0,0
0,0,0,0,0,0,0,0,0,0,0,0,0,0,0,0,0,0,0,0,0,0,0,0,0,0,0,0,0,0,0,0,0,0,0
0,0,0,0,0,0,0,0,0,0,0,0,0,0,0,0,0,0,0,0,0,0,0,0,0,0,0,0,0,0,0,0,0,0,0
0,0,0,0,0,0,0,0,0,0,0,0,0,0,0,0,0,0,0,0,0,0,0,0,0,0,0,0,0,0,0,0,0,0,0
0,0,0,0,0,0,0,0,0,0,0,0,0,0,0,0,0,0,0,0,0,0,0,0,0,0,0,0,0,0,0,0,0,0,0
0,0,0,0,0,0,0,0,0,0,0,0,0,0,0,0,0,0,0,0,0,0,0,0,0,0,0,0,0,0,0,0,0,0,0
0,0,0,0,0,0,0,0,0,0,0,0,0,0,0,0,0,0,0,0,0,0,0,0,0,0,0,0,0,0,0,0,0,0,0
0,0,0,0,0,0,0,0,0,0,0,0,0,0,0,0,0,0,0,0,0,0,0,0,0,0,0,0,0,0,0,0,0,0,0
0,0,0,0,0,0,0,0,0,0,0,0,0,0,0,0,0,0,0,0,0,0,0,0,0,0,0,0,0,0,0,0,0,0,0
0,0,0,0,0,0,0,0,0,0,0,0,0,0,0,0,0,0,0,0,0,0,0,0,0,0,0,0,0,0,0,0,0,0,0
0,0,0,0,0,0,0,0,0,0,0,0,0,0,0,0,0,0,0,0,0,0,0,0,0,0,0,0,0,0,0,0,0,0,0
0,0,0,0,0,0,0,0,0,0,0,0,0,0,0,0,0,0,0,0,0,0,0,0,0,0,0,0,0,0,0,0,0,0,0
0,0,0,0,0,0,0,0,0,0,0,0,0,0,0,0,0,0,0,0,0,0,0,0,0,0,0,0,0,0,0,0,0,0,0
0,0,0,0,0,0,0,0,0,0,0,0,0,0,0,0,0,0,0,0,0,0,0,0,0,0,0,0,0,0,0,0,0,0,0
0,0,0,0,0,0,0,0,0,0,0,0,0,0,0,0,0,0,0,0,0,0,0,0,0,0,0,0,0,0,0,0,0,0,0
0,0,0,0,0,0,0,0,0,0,0,0,0,0,0,0,0,0,0,0,0,0,0,0,0,0,0,0,0,0,0,0,0,0,0
0,0,0,0,0,0,0,0,0,0,0,0,0,0,0,0,0,0,0,0,0,0,0,0,0,0,0,0,0,0,0,0,0,0,0
0,0,0,0,0,0,0,0,0,0,0,0,0,0,0,0,0,0,0,0,0,0,0,0,0,0,0,0,0,0,0,0,0,0,0
0,0,0,0,0,0,0,0,0,0,0,0,0,0,0,0,0,0,0,0,0,0,0,0,0,0,0,0,0,0,0,0,0,0,0
0,0,0,0,0,0,0,0,0,0,0,0,0,0,0,0,0,0,0,0,0,0,0,0,0,0,0,0,0,0,0,0,0,0,0
0,0,0,0,0,0,0,0,0,0,0,0,0,0,0,0,0,0,0,0,0,0,0,0,0,0,0,0,0,0,0,0,0,0,0
0,0,0,0,0,0,0,0,0,0,0,0,0,0,0,0,0,0,0,0,0,0,0,0,0,0,0,0,0,0,0,0,0,0,0
0,0,0,0,0,0,0,0,0,0,0,0,0,0,0,0,0,0,0,0,0,0,0,0,0,0,0,0,0,0,0,0,0,0,0
0,0,0,0,0,0,0,0,0,0,0,0,0,0,0,0,0,0,0,0,0,0,0,0,0,0,0,0,0,0,0,0,0,0,0
0,0,0,0,0,0,0,0,0,0,0,0,0,0,0,0,0,0,0,0,0,0,0,0,0,0,0,0,0,0,0,0,0,0,0
0,0,0,0,0,0,0,0,0,0,0,0,0,0,0,0,0,0,0,0,0,0,0,0,0,0,0,0,0,0,0,0,0,0,0
0,0,0,0,0,0,0,0,0,0,0,0,0,0,0,0,0,0,0,0,0,0,0,0,0,0,0,0,0,0,0,0,0,0,0
0,0,0,0,0,0,0,0,0,0,0,0,0,0,0,0,0,0,0,0,0,0,0,0,0,0,0,0,0,0,0,0,0,0,0
0,0,0,0,0,0,0,0,0,0,0,0,0,0,0,0,0,0,0,0,0,0,0,0,0,0,0,0,0,0,0,0,0,0,0
0,0,0,0,0,0,0,0,0,0,0,0,0,0,0,0,0,0,0,0,0,0,0,0,0,0,0,0,0,0,0,0,0,0,0
:endlayer
layer: 14
0,0,0,0,0,0,0,0,0,0,0,0,0,0,0,0,0,0,0,0,0,0,0,0,0,0,0,0,0,0,0,0,0,0,0
0,0,0,0,0,0,0,0,0,0,0,0,0,0,0,0,0,0,0,0,0,0,0,0,0,0,0,0,0,0,0,0,0,0,0
0,0,0,0,0,0,0,0,0,0,0,0,0,0,0,0,0,0,0,0,0,0,0,0,0,0,0,0,0,0,0,0,0,0,0
0,0,0,0,0,0,0,0,0,0,0,0,0,0,0,0,0,0,0,0,0,0,0,0,0,0,0,0,0,0,0,0,0,0,0
0,0,0,0,0,0,0,0,0,0,0,0,0,0,0,0,0,0,0,0,0,0,0,0,0,0,0,0,0,0,0,0,0,0,0
0,0,0,0,0,0,0,0,0,0,0,0,0,0,0,0,0,0,0,0,0,0,0,0,0,0,0,0,0,0,0,0,0,0,0
0,0,0,0,0,0,0,0,0,0,0,0,0,0,0,0,0,0,0,0,0,0,0,0,0,0,0,0,0,0,0,0,0,0,0
0,0,0,0,0,0,0,0,0,0,0,0,0,0,0,0,0,0,0,0,0,0,0,0,0,0,0,0,0,0,0,0,0,0,0
0,0,0,0,0,0,0,0,0,0,0,0,0,0,0,0,0,0,0,0,0,0,0,0,0,0,0,0,0,0,0,0,0,0,0
0,0,0,0,0,0,0,0,0,0,0,0,0,0,0,0,0,0,0,0,0,0,0,0,0,0,0,0,0,0,0,0,0,0,0
0,0,0,0,0,0,0,0,0,0,0,0,0,0,0,0,0,0,0,0,0,0,0,0,0,0,0,0,0,0,0,0,0,0,0
0,0,0,0,0,0,0,0,0,0,0,0,0,0,0,0,0,0,0,0,0,0,0,0,0,0,0,0,0,0,0,0,0,0,0
0,0,0,0,0,0,0,0,0,0,0,0,0,0,0,0,0,0,0,0,0,0,0,0,0,0,0,0,0,0,0,0,0,0,0
0,0,0,0,0,0,0,0,0,0,0,0,0,0,0,0,0,0,0,0,0,0,0,0,0,0,0,0,0,0,0,0,0,0,0
0,0,0,0,0,0,0,0,0,0,0,0,0,0,0,0,0,0,0,0,0,0,0,0,0,0,0,0,0,0,0,0,0,0,0
0,0,0,0,0,0,0,0,0,0,0,0,0,0,0,0,0,0,0,0,0,0,0,0,0,0,0,0,0,0,0,0,0,0,0
0,0,0,0,0,0,0,0,0,0,0,0,0,0,0,0,0,0,0,0,0,0,0,0,0,0,0,0,0,0,0,0,0,0,0
0,0,0,0,0,0,0,0,0,0,0,0,0,0,0,0,0,0,0,0,0,0,0,0,0,0,0,0,0,0,0,0,0,0,0
0,0,0,0,0,0,0,0,0,0,0,0,0,0,0,0,0,0,0,0,0,0,0,0,0,0,0,0,0,0,0,0,0,0,0
0,0,0,0,0,0,0,0,0,0,0,0,0,0,0,0,0,0,0,0,0,0,0,0,0,0,0,0,0,0,0,0,0,0,0
0,0,0,0,0,0,0,0,0,0,0,0,0,0,0,0,0,0,0,0,0,0,0,0,0,0,0,0,0,0,0,0,0,0,0
0,0,0,0,0,0,0,0,0,0,0,0,0,0,0,0,0,0,0,0,0,0,0,0,0,0,0,0,0,0,0,0,0,0,0
0,0,0,0,0,0,0,0,0,0,0,0,0,0,0,0,0,0,0,0,0,0,0,0,0,0,0,0,0,0,0,0,0,0,0
0,0,0,0,0,0,0,0,0,0,0,0,0,0,0,0,0,0,0,0,0,0,0,0,0,0,0,0,0,0,0,0,0,0,0
0,0,0,0,0,0,0,0,0,0,0,0,0,0,0,0,0,0,0,0,0,0,0,0,0,0,0,0,0,0,0,0,0,0,0
0,0,0,0,0,0,0,0,0,0,0,0,0,0,0,0,0,0,0,0,0,0,0,0,0,0,0,0,0,0,0,0,0,0,0
0,0,0,0,0,0,0,0,0,0,0,0,0,0,0,0,0,0,0,0,0,0,0,0,0,0,0,0,0,0,0,0,0,0,0
0,0,0,0,0,0,0,0,0,0,0,0,0,0,0,0,0,0,0,0,0,0,0,0,0,0,0,0,0,0,0,0,0,0,0
0,0,0,0,0,0,0,0,0,0,0,0,0,0,0,0,0,0,0,0,0,0,0,0,0,0,0,0,0,0,0,0,0,0,0
0,0,0,0,0,0,0,0,0,0,0,0,0,0,0,0,0,0,0,0,0,0,0,0,0,0,0,0,0,0,0,0,0,0,0
0,0,0,0,0,0,0,0,0,0,0,0,0,0,0,0,0,0,0,0,0,0,0,0,0,0,0,0,0,0,0,0,0,0,0
0,0,0,0,0,0,0,0,0,0,0,0,0,0,0,0,0,0,0,0,0,0,0,0,0,0,0,0,0,0,0,0,0,0,0
0,0,0,0,0,0,0,0,0,0,0,0,0,0,0,0,0,0,0,0,0,0,0,0,0,0,0,0,0,0,0,0,0,0,0
0,0,0,0,0,0,0,0,0,0,0,0,0,0,0,0,0,0,0,0,0,0,0,0,0,0,0,0,0,0,0,0,0,0,0
0,0,0,0,0,0,0,0,0,0,0,0,0,0,0,0,0,0,0,0,0,0,0,0,0,0,0,0,0,0,0,0,0,0,0
0,0,0,0,0,0,0,0,0,0,0,0,0,0,0,0,0,0,0,0,0,0,0,0,0,0,0,0,0,0,0,0,0,0,0
:endlayer
layer: 15
0,0,0,0,0,0,0,0,0,0,0,0,0,0,0,0,0,0,0,0,0,0,0,0,0,0,0,0,0,0,0,0,0,0,0
0,0,0,0,0,0,0,0,0,0,0,0,0,0,0,0,0,0,0,0,0,0,0,0,0,0,0,0,0,0,0,0,0,0,0
0,0,0,0,0,0,0,0,0,0,0,0,0,0,0,0,0,0,0,0,0,0,0,0,0,0,0,0,0,0,0,0,0,0,0
0,0,0,0,0,0,0,0,0,0,0,0,0,0,0,0,0,0,0,0,0,0,0,0,0,0,0,0,0,0,0,0,0,0,0
0,0,0,0,0,0,0,0,0,0,0,0,0,0,0,0,0,0,0,0,0,0,0,0,0,0,0,0,0,0,0,0,0,0,0
0,0,0,0,0,0,0,0,0,0,0,0,0,0,0,0,0,0,0,0,0,0,0,0,0,0,0,0,0,0,0,0,0,0,0
0,0,0,0,0,0,0,0,0,0,0,0,0,0,0,0,0,0,0,0,0,0,0,0,0,0,0,0,0,0,0,0,0,0,0
0,0,0,0,0,0,0,0,0,0,0,0,0,0,0,0,0,0,0,0,0,0,0,0,0,0,0,0,0,0,0,0,0,0,0
0,0,0,0,0,0,0,0,0,0,0,0,0,0,0,0,0,0,0,0,0,0,0,0,0,0,0,0,0,0,0,0,0,0,0
0,0,0,0,0,0,0,0,0,0,0,0,0,0,0,0,0,0,0,0,0,0,0,0,0,0,0,0,0,0,0,0,0,0,0
0,0,0,0,0,0,0,0,0,0,0,0,0,0,0,0,0,0,0,0,0,0,0,0,0,0,0,0,0,0,0,0,0,0,0
0,0,0,0,0,0,0,0,0,0,0,0,0,0,0,0,0,0,0,0,0,0,0,0,0,0,0,0,0,0,0,0,0,0,0
0,0,0,0,0,0,0,0,0,0,0,0,0,0,0,0,0,0,0,0,0,0,0,0,0,0,0,0,0,0,0,0,0,0,0
0,0,0,0,0,0,0,0,0,0,0,0,0,0,0,0,0,0,0,0,0,0,0,0,0,0,0,0,0,0,0,0,0,0,0
0,0,0,0,0,0,0,0,0,0,0,0,0,0,0,0,0,0,0,0,0,0,0,0,0,0,0,0,0,0,0,0,0,0,0
0,0,0,0,0,0,0,0,0,0,0,0,0,0,0,0,0,0,0,0,0,0,0,0,0,0,0,0,0,0,0,0,0,0,0
0,0,0,0,0,0,0,0,0,0,0,0,0,0,0,0,0,0,0,0,0,0,0,0,0,0,0,0,0,0,0,0,0,0,0
0,0,0,0,0,0,0,0,0,0,0,0,0,0,0,0,0,0,0,0,0,0,0,0,0,0,0,0,0,0,0,0,0,0,0
0,0,0,0,0,0,0,0,0,0,0,0,0,0,0,0,0,0,0,0,0,0,0,0,0,0,0,0,0,0,0,0,0,0,0
0,0,0,0,0,0,0,0,0,0,0,0,0,0,0,0,0,0,0,0,0,0,0,0,0,0,0,0,0,0,0,0,0,0,0
0,0,0,0,0,0,0,0,0,0,0,0,0,0,0,0,0,0,0,0,0,0,0,0,0,0,0,0,0,0,0,0,0,0,0
0,0,0,0,0,0,0,0,0,0,0,0,0,0,0,0,0,0,0,0,0,0,0,0,0,0,0,0,0,0,0,0,0,0,0
0,0,0,0,0,0,0,0,0,0,0,0,0,0,0,0,0,0,0,0,0,0,0,0,0,0,0,0,0,0,0,0,0,0,0
0,0,0,0,0,0,0,0,0,0,0,0,0,0,0,0,0,0,0,0,0,0,0,0,0,0,0,0,0,0,0,0,0,0,0
0,0,0,0,0,0,0,0,0,0,0,0,0,0,0,0,0,0,0,0,0,0,0,0,0,0,0,0,0,0,0,0,0,0,0
0,0,0,0,0,0,0,0,0,0,0,0,0,0,0,0,0,0,0,0,0,0,0,0,0,0,0,0,0,0,0,0,0,0,0
0,0,0,0,0,0,0,0,0,0,0,0,0,0,0,0,0,0,0,0,0,0,0,0,0,0,0,0,0,0,0,0,0,0,0
0,0,0,0,0,0,0,0,0,0,0,0,0,0,0,0,0,0,0,0,0,0,0,0,0,0,0,0,0,0,0,0,0,0,0
0,0,0,0,0,0,0,0,0,0,0,0,0,0,0,0,0,0,0,0,0,0,0,0,0,0,0,0,0,0,0,0,0,0,0
0,0,0,0,0,0,0,0,0,0,0,0,0,0,0,0,0,0,0,0,0,0,0,0,0,0,0,0,0,0,0,0,0,0,0
0,0,0,0,0,0,0,0,0,0,0,0,0,0,0,0,0,0,0,0,0,0,0,0,0,0,0,0,0,0,0,0,0,0,0
0,0,0,0,0,0,0,0,0,0,0,0,0,0,0,0,0,0,0,0,0,0,0,0,0,0,0,0,0,0,0,0,0,0,0
0,0,0,0,0,0,0,0,0,0,0,0,0,0,0,0,0,0,0,0,0,0,0,0,0,0,0,0,0,0,0,0,0,0,0
0,0,0,0,0,0,0,0,0,0,0,0,0,0,0,0,0,0,0,0,0,0,0,0,0,0,0,0,0,0,0,0,0,0,0
0,0,0,0,0,0,0,0,0,0,0,0,0,0,0,0,0,0,0,0,0,0,0,0,0,0,0,0,0,0,0,0,0,0,0
0,0,0,0,0,0,0,0,0,0,0,0,0,0,0,0,0,0,0,0,0,0,0,0,0,0,0,0,0,0,0,0,0,0,0
:endlayer
layer: 16
0,0,0,0,0,0,0,0,0,0,0,0,0,0,0,0,0,0,0,0,0,0,0,0,0,0,0,0,0,0,0,0,0,0,0
0,0,0,0,0,0,0,0,0,0,0,0,0,0,0,0,0,0,0,0,0,0,0,0,0,0,0,0,0,0,0,0,0,0,0
0,0,0,0,0,0,0,0,0,0,0,0,0,0,0,0,0,0,0,0,0,0,0,0,0,0,0,0,0,0,0,0,0,0,0
0,0,0,0,0,0,0,0,0,0,0,0,0,0,0,0,0,0,0,0,0,0,0,0,0,0,0,0,0,0,0,0,0,0,0
0,0,0,0,0,0,0,0,0,0,0,0,0,0,0,0,0,0,0,0,0,0,0,0,0,0,0,0,0,0,0,0,0,0,0
0,0,0,0,0,0,0,0,0,0,0,0,0,0,0,0,0,0,0,0,0,0,0,0,0,0,0,0,0,0,0,0,0,0,0
0,0,0,0,0,0,0,0,0,0,0,0,0,0,0,0,0,0,0,0,0,0,0,0,0,0,0,0,0,0,0,0,0,0,0
0,0,0,0,0,0,0,0,0,0,0,0,0,0,0,0,0,0,0,0,0,0,0,0,0,0,0,0,0,0,0,0,0,0,0
0,0,0,0,0,0,0,0,0,0,0,0,0,0,0,0,0,0,0,0,0,0,0,0,0,0,0,0,0,0,0,0,0,0,0
0,0,0,0,0,0,0,0,0,0,0,0,0,0,0,0,0,0,0,0,0,0,0,0,0,0,0,0,0,0,0,0,0,0,0
0,0,0,0,0,0,0,0,0,0,0,0,0,0,0,0,0,0,0,0,0,0,0,0,0,0,0,0,0,0,0,0,0,0,0
0,0,0,0,0,0,0,0,0,0,0,0,0,0,0,0,0,0,0,0,0,0,0,0,0,0,0,0,0,0,0,0,0,0,0
0,0,0,0,0,0,0,0,0,0,0,0,0,0,0,0,0,0,0,0,0,0,0,0,0,0,0,0,0,0,0,0,0,0,0
0,0,0,0,0,0,0,0,0,0,0,0,0,0,0,0,0,0,0,0,0,0,0,0,0,0,0,0,0,0,0,0,0,0,0
0,0,0,0,0,0,0,0,0,0,0,0,0,0,0,0,0,0,0,0,0,0,0,0,0,0,0,0,0,0,0,0,0,0,0
0,0,0,0,0,0,0,0,0,0,0,0,0,0,0,0,0,0,0,0,0,0,0,0,0,0,0,0,0,0,0,0,0,0,0
0,0,0,0,0,0,0,0,0,0,0,0,0,0,0,0,0,0,0,0,0,0,0,0,0,0,0,0,0,0,0,0,0,0,0
0,0,0,0,0,0,0,0,0,0,0,0,0,0,0,0,0,0,0,0,0,0,0,0,0,0,0,0,0,0,0,0,0,0,0
0,0,0,0,0,0,0,0,0,0,0,0,0,0,0,0,0,0,0,0,0,0,0,0,0,0,0,0,0,0,0,0,0,0,0
0,0,0,0,0,0,0,0,0,0,0,0,0,0,0,0,0,0,0,0,0,0,0,0,0,0,0,0,0,0,0,0,0,0,0
0,0,0,0,0,0,0,0,0,0,0,0,0,0,0,0,0,0,0,0,0,0,0,0,0,0,0,0,0,0,0,0,0,0,0
0,0,0,0,0,0,0,0,0,0,0,0,0,0,0,0,0,0,0,0,0,0,0,0,0,0,0,0,0,0,0,0,0,0,0
0,0,0,0,0,0,0,0,0,0,0,0,0,0,0,0,0,0,0,0,0,0,0,0,0,0,0,0,0,0,0,0,0,0,0
0,0,0,0,0,0,0,0,0,0,0,0,0,0,0,0,0,0,0,0,0,0,0,0,0,0,0,0,0,0,0,0,0,0,0
0,0,0,0,0,0,0,0,0,0,0,0,0,0,0,0,0,0,0,0,0,0,0,0,0,0,0,0,0,0,0,0,0,0,0
0,0,0,0,0,0,0,0,0,0,0,0,0,0,0,0,0,0,0,0,0,0,0,0,0,0,0,0,0,0,0,0,0,0,0
0,0,0,0,0,0,0,0,0,0,0,0,0,0,0,0,0,0,0,0,0,0,0,0,0,0,0,0,0,0,0,0,0,0,0
0,0,0,0,0,0,0,0,0,0,0,0,0,0,0,0,0,0,0,0,0,0,0,0,0,0,0,0,0,0,0,0,0,0,0
0,0,0,0,0,0,0,0,0,0,0,0,0,0,0,0,0,0,0,0,0,0,0,0,0,0,0,0,0,0,0,0,0,0,0
0,0,0,0,0,0,0,0,0,0,0,0,0,0,0,0,0,0,0,0,0,0,0,0,0,0,0,0,0,0,0,0,0,0,0
0,0,0,0,0,0,0,0,0,0,0,0,0,0,0,0,0,0,0,0,0,0,0,0,0,0,0,0,0,0,0,0,0,0,0
0,0,0,0,0,0,0,0,0,0,0,0,0,0,0,0,0,0,0,0,0,0,0,0,0,0,0,0,0,0,0,0,0,0,0
0,0,0,0,0,0,0,0,0,0,0,0,0,0,0,0,0,0,0,0,0,0,0,0,0,0,0,0,0,0,0,0,0,0,0
0,0,0,0,0,0,0,0,0,0,0,0,0,0,0,0,0,0,0,0,0,0,0,0,0,0,0,0,0,0,0,0,0,0,0
0,0,0,0,0,0,0,0,0,0,0,0,0,0,0,0,0,0,0,0,0,0,0,0,0,0,0,0,0,0,0,0,0,0,0
0,0,0,0,0,0,0,0,0,0,0,0,0,0,0,0,0,0,0,0,0,0,0,0,0,0,0,0,0,0,0,0,0,0,0
:endlayer
layer: 17
0,0,0,0,0,0,0,0,0,0,0,0,0,0,0,0,0,0,0,0,0,0,0,0,0,0,0,0,0,0,0,0,0,0,0
0,0,0,0,0,0,0,0,0,0,0,0,0,0,0,0,0,0,0,0,0,0,0,0,0,0,0,0,0,0,0,0,0,0,0
0,0,0,0,0,0,0,0,0,0,0,0,0,0,0,0,0,0,0,0,0,0,0,0,0,0,0,0,0,0,0,0,0,0,0
0,0,0,0,0,0,0,0,0,0,0,0,0,0,0,0,0,0,0,0,0,0,0,0,0,0,0,0,0,0,0,0,0,0,0
0,0,0,0,0,0,0,0,0,0,0,0,0,0,0,0,0,0,0,0,0,0,0,0,0,0,0,0,0,0,0,0,0,0,0
0,0,0,0,0,0,0,0,0,0,0,0,0,0,0,0,0,0,0,0,0,0,0,0,0,0,0,0,0,0,0,0,0,0,0
0,0,0,0,0,0,0,0,0,0,0,0,0,0,0,0,0,0,0,0,0,0,0,0,0,0,0,0,0,0,0,0,0,0,0
0,0,0,0,0,0,0,0,0,0,0,0,0,0,0,0,0,0,0,0,0,0,0,0,0,0,0,0,0,0,0,0,0,0,0
0,0,0,0,0,0,0,0,0,0,0,0,0,0,0,0,0,0,0,0,0,0,0,0,0,0,0,0,0,0,0,0,0,0,0
0,0,0,0,0,0,0,0,0,0,0,0,0,0,0,0,0,0,0,0,0,0,0,0,0,0,0,0,0,0,0,0,0,0,0
0,0,0,0,0,0,0,0,0,0,0,0,0,0,0,0,0,0,0,0,0,0,0,0,0,0,0,0,0,0,0,0,0,0,0
0,0,0,0,0,0,0,0,0,0,0,0,0,0,0,0,0,0,0,0,0,0,0,0,0,0,0,0,0,0,0,0,0,0,0
0,0,0,0,0,0,0,0,0,0,0,0,0,0,0,0,0,0,0,0,0,0,0,0,0,0,0,0,0,0,0,0,0,0,0
0,0,0,0,0,0,0,0,0,0,0,0,0,0,0,0,0,0,0,0,0,0,0,0,0,0,0,0,0,0,0,0,0,0,0
0,0,0,0,0,0,0,0,0,0,0,0,0,0,0,0,0,0,0,0,0,0,0,0,0,0,0,0,0,0,0,0,0,0,0
0,0,0,0,0,0,0,0,0,0,0,0,0,0,0,0,0,0,0,0,0,0,0,0,0,0,0,0,0,0,0,0,0,0,0
0,0,0,0,0,0,0,0,0,0,0,0,0,0,0,0,0,0,0,0,0,0,0,0,0,0,0,0,0,0,0,0,0,0,0
0,0,0,0,0,0,0,0,0,0,0,0,0,0,0,0,0,0,0,0,0,0,0,0,0,0,0,0,0,0,0,0,0,0,0
0,0,0,0,0,0,0,0,0,0,0,0,0,0,0,0,0,0,0,0,0,0,0,0,0,0,0,0,0,0,0,0,0,0,0
0,0,0,0,0,0,0,0,0,0,0,0,0,0,0,0,0,0,0,0,0,0,0,0,0,0,0,0,0,0,0,0,0,0,0
0,0,0,0,0,0,0,0,0,0,0,0,0,0,0,0,0,0,0,0,0,0,0,0,0,0,0,0,0,0,0,0,0,0,0
0,0,0,0,0,0,0,0,0,0,0,0,0,0,0,0,0,0,0,0,0,0,0,0,0,0,0,0,0,0,0,0,0,0,0
0,0,0,0,0,0,0,0,0,0,0,0,0,0,0,0,0,0,0,0,0,0,0,0,0,0,0,0,0,0,0,0,0,0,0
0,0,0,0,0,0,0,0,0,0,0,0,0,0,0,0,0,0,0,0,0,0,0,0,0,0,0,0,0,0,0,0,0,0,0
0,0,0,0,0,0,0,0,0,0,0,0,0,0,0,0,0,0,0,0,0,0,0,0,0,0,0,0,0,0,0,0,0,0,0
0,0,0,0,0,0,0,0,0,0,0,0,0,0,0,0,0,0,0,0,0,0,0,0,0,0,0,0,0,0,0,0,0,0,0
0,0,0,0,0,0,0,0,0,0,0,0,0,0,0,0,0,0,0,0,0,0,0,0,0,0,0,0,0,0,0,0,0,0,0
0,0,0,0,0,0,0,0,0,0,0,0,0,0,0,0,0,0,0,0,0,0,0,0,0,0,0,0,0,0,0,0,0,0,0
0,0,0,0,0,0,0,0,0,0,0,0,0,0,0,0,0,0,0,0,0,0,0,0,0,0,0,0,0,0,0,0,0,0,0
0,0,0,0,0,0,0,0,0,0,0,0,0,0,0,0,0,0,0,0,0,0,0,0,0,0,0,0,0,0,0,0,0,0,0
0,0,0,0,0,0,0,0,0,0,0,0,0,0,0,0,0,0,0,0,0,0,0,0,0,0,0,0,0,0,0,0,0,0,0
0,0,0,0,0,0,0,0,0,0,0,0,0,0,0,0,0,0,0,0,0,0,0,0,0,0,0,0,0,0,0,0,0,0,0
0,0,0,0,0,0,0,0,0,0,0,0,0,0,0,0,0,0,0,0,0,0,0,0,0,0,0,0,0,0,0,0,0,0,0
0,0,0,0,0,0,0,0,0,0,0,0,0,0,0,0,0,0,0,0,0,0,0,0,0,0,0,0,0,0,0,0,0,0,0
0,0,0,0,0,0,0,0,0,0,0,0,0,0,0,0,0,0,0,0,0,0,0,0,0,0,0,0,0,0,0,0,0,0,0
0,0,0,0,0,0,0,0,0,0,0,0,0,0,0,0,0,0,0,0,0,0,0,0,0,0,0,0,0,0,0,0,0,0,0
:endlayer
layer: 18
0,0,0,0,0,0,0,0,0,0,0,0,0,0,0,0,0,0,0,0,0,0,0,0,0,0,0,0,0,0,0,0,0,0,0
0,0,0,0,0,0,0,0,0,0,0,0,0,0,0,0,0,0,0,0,0,0,0,0,0,0,0,0,0,0,0,0,0,0,0
0,0,0,0,0,0,0,0,0,0,0,0,0,0,0,0,0,0,0,0,0,0,0,0,0,0,0,0,0,0,0,0,0,0,0
0,0,0,0,0,0,0,0,0,0,0,0,0,0,0,0,0,0,0,0,0,0,0,0,0,0,0,0,0,0,0,0,0,0,0
0,0,0,0,0,0,0,0,0,0,0,0,0,0,0,0,0,0,0,0,0,0,0,0,0,0,0,0,0,0,0,0,0,0,0
0,0,0,0,0,0,0,0,0,0,0,0,0,0,0,0,0,0,0,0,0,0,0,0,0,0,0,0,0,0,0,0,0,0,0
0,0,0,0,0,0,0,0,0,0,0,0,0,0,0,0,0,0,0,0,0,0,0,0,0,0,0,0,0,0,0,0,0,0,0
0,0,0,0,0,0,0,0,0,0,0,0,0,0,0,0,0,0,0,0,0,0,0,0,0,0,0,0,0,0,0,0,0,0,0
0,0,0,0,0,0,0,0,0,0,0,0,0,0,0,0,0,0,0,0,0,0,0,0,0,0,0,0,0,0,0,0,0,0,0
0,0,0,0,0,0,0,0,0,0,0,0,0,0,0,0,0,0,0,0,0,0,0,0,0,0,0,0,0,0,0,0,0,0,0
0,0,0,0,0,0,0,0,0,0,0,0,0,0,0,0,0,0,0,0,0,0,0,0,0,0,0,0,0,0,0,0,0,0,0
0,0,0,0,0,0,0,0,0,0,0,0,0,0,0,0,0,0,0,0,0,0,0,0,0,0,0,0,0,0,0,0,0,0,0
0,0,0,0,0,0,0,0,0,0,0,0,0,0,0,0,0,0,0,0,0,0,0,0,0,0,0,0,0,0,0,0,0,0,0
0,0,0,0,0,0,0,0,0,0,0,0,0,0,0,0,0,0,0,0,0,0,0,0,0,0,0,0,0,0,0,0,0,0,0
0,0,0,0,0,0,0,0,0,0,0,0,0,0,0,0,0,0,0,0,0,0,0,0,0,0,0,0,0,0,0,0,0,0,0
0,0,0,0,0,0,0,0,0,0,0,0,0,0,0,0,0,0,0,0,0,0,0,0,0,0,0,0,0,0,0,0,0,0,0
0,0,0,0,0,0,0,0,0,0,0,0,0,0,0,0,0,0,0,0,0,0,0,0,0,0,0,0,0,0,0,0,0,0,0
0,0,0,0,0,0,0,0,0,0,0,0,0,0,0,0,0,0,0,0,0,0,0,0,0,0,0,0,0,0,0,0,0,0,0
0,0,0,0,0,0,0,0,0,0,0,0,0,0,0,0,0,0,0,0,0,0,0,0,0,0,0,0,0,0,0,0,0,0,0
0,0,0,0,0,0,0,0,0,0,0,0,0,0,0,0,0,0,0,0,0,0,0,0,0,0,0,0,0,0,0,0,0,0,0
0,0,0,0,0,0,0,0,0,0,0,0,0,0,0,0,0,0,0,0,0,0,0,0,0,0,0,0,0,0,0,0,0,0,0
0,0,0,0,0,0,0,0,0,0,0,0,0,0,0,0,0,0,0,0,0,0,0,0,0,0,0,0,0,0,0,0,0,0,0
0,0,0,0,0,0,0,0,0,0,0,0,0,0,0,0,0,0,0,0,0,0,0,0,0,0,0,0,0,0,0,0,0,0,0
0,0,0,0,0,0,0,0,0,0,0,0,0,0,0,0,0,0,0,0,0,0,0,0,0,0,0,0,0,0,0,0,0,0,0
0,0,0,0,0,0,0,0,0,0,0,0,0,0,0,0,0,0,0,0,0,0,0,0,0,0,0,0,0,0,0,0,0,0,0
0,0,0,0,0,0,0,0,0,0,0,0,0,0,0,0,0,0,0,0,0,0,0,0,0,0,0,0,0,0,0,0,0,0,0
0,0,0,0,0,0,0,0,0,0,0,0,0,0,0,0,0,0,0,0,0,0,0,0,0,0,0,0,0,0,0,0,0,0,0
0,0,0,0,0,0,0,0,0,0,0,0,0,0,0,0,0,0,0,0,0,0,0,0,0,0,0,0,0,0,0,0,0,0,0
0,0,0,0,0,0,0,0,0,0,0,0,0,0,0,0,0,0,0,0,0,0,0,0,0,0,0,0,0,0,0,0,0,0,0
0,0,0,0,0,0,0,0,0,0,0,0,0,0,0,0,0,0,0,0,0,0,0,0,0,0,0,0,0,0,0,0,0,0,0
0,0,0,0,0,0,0,0,0,0,0,0,0,0,0,0,0,0,0,0,0,0,0,0,0,0,0,0,0,0,0,0,0,0,0
0,0,0,0,0,0,0,0,0,0,0,0,0,0,0,0,0,0,0,0,0,0,0,0,0,0,0,0,0,0,0,0,0,0,0
0,0,0,0,0,0,0,0,0,0,0,0,0,0,0,0,0,0,0,0,0,0,0,0,0,0,0,0,0,0,0,0,0,0,0
0,0,0,0,0,0,0,0,0,0,0,0,0,0,0,0,0,0,0,0,0,0,0,0,0,0,0,0,0,0,0,0,0,0,0
0,0,0,0,0,0,0,0,0,0,0,0,0,0,0,0,0,0,0,0,0,0,0,0,0,0,0,0,0,0,0,0,0,0,0
0,0,0,0,0,0,0,0,0,0,0,0,0,0,0,0,0,0,0,0,0,0,0,0,0,0,0,0,0,0,0,0,0,0,0
:endlayer
layer: 19
0,0,0,0,0,0,0,0,0,0,0,0,0,0,0,0,0,0,0,0,0,0,0,0,0,0,0,0,0,0,0,0,0,0,0
0,0,0,0,0,0,0,0,0,0,0,0,0,0,0,0,0,0,0,0,0,0,0,0,0,0,0,0,0,0,0,0,0,0,0
0,0,0,0,0,0,0,0,0,0,0,0,0,0,0,0,0,0,0,0,0,0,0,0,0,0,0,0,0,0,0,0,0,0,0
0,0,0,0,0,0,0,0,0,0,0,0,0,0,0,0,0,0,0,0,0,0,0,0,0,0,0,0,0,0,0,0,0,0,0
0,0,0,0,0,0,0,0,0,0,0,0,0,0,0,0,0,0,0,0,0,0,0,0,0,0,0,0,0,0,0,0,0,0,0
0,0,0,0,0,0,0,0,0,0,0,0,0,0,0,0,0,0,0,0,0,0,0,0,0,0,0,0,0,0,0,0,0,0,0
0,0,0,0,0,0,0,0,0,0,0,0,0,0,0,0,0,0,0,0,0,0,0,0,0,0,0,0,0,0,0,0,0,0,0
0,0,0,0,0,0,0,0,0,0,0,0,0,0,0,0,0,0,0,0,0,0,0,0,0,0,0,0,0,0,0,0,0,0,0
0,0,0,0,0,0,0,0,0,0,0,0,0,0,0,0,0,0,0,0,0,0,0,0,0,0,0,0,0,0,0,0,0,0,0
0,0,0,0,0,0,0,0,0,0,0,0,0,0,0,0,0,0,0,0,0,0,0,0,0,0,0,0,0,0,0,0,0,0,0
0,0,0,0,0,0,0,0,0,0,0,0,0,0,0,0,0,0,0,0,0,0,0,0,0,0,0,0,0,0,0,0,0,0,0
0,0,0,0,0,0,0,0,0,0,0,0,0,0,0,0,0,0,0,0,0,0,0,0,0,0,0,0,0,0,0,0,0,0,0
0,0,0,0,0,0,0,0,0,0,0,0,0,0,0,0,0,0,0,0,0,0,0,0,0,0,0,0,0,0,0,0,0,0,0
0,0,0,0,0,0,0,0,0,0,0,0,0,0,0,0,0,0,0,0,0,0,0,0,0,0,0,0,0,0,0,0,0,0,0
0,0,0,0,0,0,0,0,0,0,0,0,0,0,0,0,0,0,0,0,0,0,0,0,0,0,0,0,0,0,0,0,0,0,0
0,0,0,0,0,0,0,0,0,0,0,0,0,0,0,0,0,0,0,0,0,0,0,0,0,0,0,0,0,0,0,0,0,0,0
0,0,0,0,0,0,0,0,0,0,0,0,0,0,0,0,0,0,0,0,0,0,0,0,0,0,0,0,0,0,0,0,0,0,0
0,0,0,0,0,0,0,0,0,0,0,0,0,0,0,0,0,0,0,0,0,0,0,0,0,0,0,0,0,0,0,0,0,0,0
0,0,0,0,0,0,0,0,0,0,0,0,0,0,0,0,0,0,0,0,0,0,0,0,0,0,0,0,0,0,0,0,0,0,0
0,0,0,0,0,0,0,0,0,0,0,0,0,0,0,0,0,0,0,0,0,0,0,0,0,0,0,0,0,0,0,0,0,0,0
0,0,0,0,0,0,0,0,0,0,0,0,0,0,0,0,0,0,0,0,0,0,0,0,0,0,0,0,0,0,0,0,0,0,0
0,0,0,0,0,0,0,0,0,0,0,0,0,0,0,0,0,0,0,0,0,0,0,0,0,0,0,0,0,0,0,0,0,0,0
0,0,0,0,0,0,0,0,0,0,0,0,0,0,0,0,0,0,0,0,0,0,0,0,0,0,0,0,0,0,0,0,0,0,0
0,0,0,0,0,0,0,0,0,0,0,0,0,0,0,0,0,0,0,0,0,0,0,0,0,0,0,0,0,0,0,0,0,0,0
0,0,0,0,0,0,0,0,0,0,0,0,0,0,0,0,0,0,0,0,0,0,0,0,0,0,0,0,0,0,0,0,0,0,0
0,0,0,0,0,0,0,0,0,0,0,0,0,0,0,0,0,0,0,0,0,0,0,0,0,0,0,0,0,0,0,0,0,0,0
0,0,0,0,0,0,0,0,0,0,0,0,0,0,0,0,0,0,0,0,0,0,0,0,0,0,0,0,0,0,0,0,0,0,0
0,0,0,0,0,0,0,0,0,0,0,0,0,0,0,0,0,0,0,0,0,0,0,0,0,0,0,0,0,0,0,0,0,0,0
0,0,0,0,0,0,0,0,0,0,0,0,0,0,0,0,0,0,0,0,0,0,0,0,0,0,0,0,0,0,0,0,0,0,0
0,0,0,0,0,0,0,0,0,0,0,0,0,0,0,0,0,0,0,0,0,0,0,0,0,0,0,0,0,0,0,0,0,0,0
0,0,0,0,0,0,0,0,0,0,0,0,0,0,0,0,0,0,0,0,0,0,0,0,0,0,0,0,0,0,0,0,0,0,0
0,0,0,0,0,0,0,0,0,0,0,0,0,0,0,0,0,0,0,0,0,0,0,0,0,0,0,0,0,0,0,0,0,0,0
0,0,0,0,0,0,0,0,0,0,0,0,0,0,0,0,0,0,0,0,0,0,0,0,0,0,0,0,0,0,0,0,0,0,0
0,0,0,0,0,0,0,0,0,0,0,0,0,0,0,0,0,0,0,0,0,0,0,0,0,0,0,0,0,0,0,0,0,0,0
0,0,0,0,0,0,0,0,0,0,0,0,0,0,0,0,0,0,0,0,0,0,0,0,0,0,0,0,0,0,0,0,0,0,0
0,0,0,0,0,0,0,0,0,0,0,0,0,0,0,0,0,0,0,0,0,0,0,0,0,0,0,0,0,0,0,0,0,0,0
:endlayer

#### RULES ####
rule:
plugin=vanillaBlocks
number=1
data:
JSON:{{"val":{"buildPass":{"val":"0","id":"pi"},"blockName":{"val":"minecraft:dirt","id":"ss"},"meta":{"val":"0","id":"pi"}},"id":"ct"}}
:enddata
:endrule

rule:
plugin=vanillaBlocks
number=2
data:
JSON:{{"val":{"buildPass":{"val":"0","id":"pi"},"blockName":{"val":"minecraft:grass","id":"ss"},"meta":{"val":"0","id":"pi"}},"id":"ct"}}
:enddata
:endrule

rule:
plugin=vanillaBlocks
number=3
data:
JSON:{{"val":{"buildPass":{"val":"0","id":"pi"},"blockName":{"val":"minecraft:gravel","id":"ss"},"meta":{"val":"0","id":"pi"}},"id":"ct"}}
:enddata
:endrule

rule:
plugin=vanillaBlocks
number=4
data:
JSON:{{"val":{"buildPass":{"val":"0","id":"pi"},"blockName":{"val":"minecraft:stone","id":"ss"},"meta":{"val":"0","id":"pi"}},"id":"ct"}}
:enddata
:endrule

rule:
plugin=vanillaBlocks
number=5
data:
JSON:{{"val":{"buildPass":{"val":"0","id":"pi"},"blockName":{"val":"minecraft:cobblestone","id":"ss"},"meta":{"val":"0","id":"pi"}},"id":"ct"}}
:enddata
:endrule

rule:
plugin=vanillaBlocks
number=6
data:
JSON:{{"val":{"buildPass":{"val":"0","id":"pi"},"blockName":{"val":"minecraft:planks","id":"ss"},"meta":{"val":"0","id":"pi"}},"id":"ct"}}
:enddata
:endrule

rule:
plugin=vanillaBlocks
number=7
data:
JSON:{{"val":{"buildPass":{"val":"2","id":"pi"},"blockName":{"val":"minecraft:tallgrass","id":"ss"},"meta":{"val":"1","id":"pi"}},"id":"ct"}}
:enddata
:endrule

rule:
plugin=vanillaBlocks
number=8
data:
JSON:{{"val":{"buildPass":{"val":"0","id":"pi"},"blockName":{"val":"minecraft:fence","id":"ss"},"meta":{"val":"0","id":"pi"}},"id":"ct"}}
:enddata
:endrule

rule:
plugin=vanillaBlocks
number=9
data:
JSON:{{"val":{"buildPass":{"val":"0","id":"pi"},"blockName":{"val":"minecraft:log","id":"ss"},"meta":{"val":"0","id":"pi"}},"id":"ct"}}
:enddata
:endrule

rule:
plugin=vanillaBlocks
number=10
data:
JSON:{{"val":{"buildPass":{"val":"0","id":"pi"},"blockName":{"val":"minecraft:oak_stairs","id":"ss"},"meta":{"val":"1","id":"pi"}},"id":"ct"}}
:enddata
:endrule

rule:
plugin=vanillaBlocks
number=11
data:
JSON:{{"val":{"buildPass":{"val":"0","id":"pi"},"blockName":{"val":"minecraft:oak_stairs","id":"ss"},"meta":{"val":"0","id":"pi"}},"id":"ct"}}
:enddata
:endrule

rule:
plugin=vanillaBlocks
number=12
data:
JSON:{{"val":{"buildPass":{"val":"0","id":"pi"},"blockName":{"val":"minecraft:hay_block","id":"ss"},"meta":{"val":"0","id":"pi"}},"id":"ct"}}
:enddata
:endrule

rule:
plugin=vanillaBlocks
number=13
data:
JSON:{{"val":{"buildPass":{"val":"0","id":"pi"},"blockName":{"val":"minecraft:hay_block","id":"ss"},"meta":{"val":"4","id":"pi"}},"id":"ct"}}
:enddata
:endrule

rule:
plugin=vanillaBlocks
number=14
data:
JSON:{{"val":{"buildPass":{"val":"0","id":"pi"},"blockName":{"val":"minecraft:stonebrick","id":"ss"},"meta":{"val":"0","id":"pi"}},"id":"ct"}}
:enddata
:endrule

rule:
plugin=vanillaBlocks
number=15
data:
JSON:{{"val":{"buildPass":{"val":"0","id":"pi"},"blockName":{"val":"minecraft:hay_block","id":"ss"},"meta":{"val":"8","id":"pi"}},"id":"ct"}}
:enddata
:endrule

rule:
plugin=vanillaBlocks
number=16
data:
JSON:{{"val":{"buildPass":{"val":"2","id":"pi"},"blockName":{"val":"minecraft:torch","id":"ss"},"meta":{"val":"1","id":"pi"}},"id":"ct"}}
:enddata
:endrule

rule:
plugin=vanillaBlocks
number=17
data:
JSON:{{"val":{"buildPass":{"val":"2","id":"pi"},"blockName":{"val":"minecraft:torch","id":"ss"},"meta":{"val":"2","id":"pi"}},"id":"ct"}}
:enddata
:endrule

rule:
plugin=vanillaBlocks
number=18
data:
JSON:{{"val":{"buildPass":{"val":"2","id":"pi"},"blockName":{"val":"minecraft:trapdoor","id":"ss"},"meta":{"val":"8","id":"pi"}},"id":"ct"}}
:enddata
:endrule

rule:
plugin=vanillaBlocks
number=19
data:
JSON:{{"val":{"buildPass":{"val":"2","id":"pi"},"blockName":{"val":"minecraft:yellow_flower","id":"ss"},"meta":{"val":"0","id":"pi"}},"id":"ct"}}
:enddata
:endrule

rule:
plugin=vanillaBlocks
number=20
data:
JSON:{{"val":{"buildPass":{"val":"2","id":"pi"},"blockName":{"val":"minecraft:red_flower","id":"ss"},"meta":{"val":"8","id":"pi"}},"id":"ct"}}
:enddata
:endrule

rule:
plugin=vanillaBlocks
number=21
data:
JSON:{{"val":{"buildPass":{"val":"2","id":"pi"},"blockName":{"val":"minecraft:torch","id":"ss"},"meta":{"val":"5","id":"pi"}},"id":"ct"}}
:enddata
:endrule

rule:
plugin=vanillaBlocks
number=22
data:
JSON:{{"val":{"buildPass":{"val":"0","id":"pi"},"blockName":{"val":"minecraft:stone_brick_stairs","id":"ss"},"meta":{"val":"0","id":"pi"}},"id":"ct"}}
:enddata
:endrule

rule:
plugin=vanillaBlocks
number=23
data:
JSON:{{"val":{"buildPass":{"val":"0","id":"pi"},"blockName":{"val":"minecraft:stone_brick_stairs","id":"ss"},"meta":{"val":"1","id":"pi"}},"id":"ct"}}
:enddata
:endrule

rule:
plugin=vanillaBlocks
number=24
data:
JSON:{{"val":{"buildPass":{"val":"0","id":"pi"},"blockName":{"val":"minecraft:stone_brick_stairs","id":"ss"},"meta":{"val":"3","id":"pi"}},"id":"ct"}}
:enddata
:endrule

rule:
plugin=vanillaBlocks
number=25
data:
JSON:{{"val":{"buildPass":{"val":"0","id":"pi"},"blockName":{"val":"minecraft:oak_stairs","id":"ss"},"meta":{"val":"7","id":"pi"}},"id":"ct"}}
:enddata
:endrule

rule:
plugin=vanillaBlocks
number=26
data:
JSON:{{"val":{"buildPass":{"val":"2","id":"pi"},"blockName":{"val":"minecraft:trapdoor","id":"ss"},"meta":{"val":"10","id":"pi"}},"id":"ct"}}
:enddata
:endrule

rule:
plugin=vanillaBlocks
number=27
data:
JSON:{{"val":{"buildPass":{"val":"0","id":"pi"},"blockName":{"val":"minecraft:oak_stairs","id":"ss"},"meta":{"val":"5","id":"pi"}},"id":"ct"}}
:enddata
:endrule

rule:
plugin=vanillaInventory
number=28
data:
JSON:{{"val":{"buildPass":{"val":"0","id":"pi"},"blockName":{"val":"minecraft:chest","id":"ss"},"meta":{"val":"3","id":"pi"},"lootLevel":{"val":"0","id":"pi"},"teData":{"val":{"x":{"val":"-1825","id":"pi"},"y":{"val":"4","id":"pi"},"z":{"val":"-1097","id":"pi"},"id":{"val":"Chest","id":"ss"}},"id":"ct"},"inventoryData":{"val":{"length":{"val":"27","id":"pi"},"inventoryContents":{"val":[],"id":"ls"}},"id":"ct"}},"id":"ct"}}
:enddata
:endrule

rule:
plugin=vanillaBlocks
number=29
data:
JSON:{{"val":{"buildPass":{"val":"0","id":"pi"},"blockName":{"val":"minecraft:fence_gate","id":"ss"},"meta":{"val":"1","id":"pi"}},"id":"ct"}}
:enddata
:endrule

rule:
plugin=vanillaBlocks
number=30
data:
JSON:{{"val":{"buildPass":{"val":"0","id":"pi"},"blockName":{"val":"minecraft:oak_stairs","id":"ss"},"meta":{"val":"4","id":"pi"}},"id":"ct"}}
:enddata
:endrule

rule:
plugin=vanillaInventory
number=31
data:
JSON:{{"val":{"buildPass":{"val":"0","id":"pi"},"blockName":{"val":"minecraft:chest","id":"ss"},"meta":{"val":"2","id":"pi"},"lootLevel":{"val":"0","id":"pi"},"teData":{"val":{"x":{"val":"-1834","id":"pi"},"y":{"val":"4","id":"pi"},"z":{"val":"-1094","id":"pi"},"id":{"val":"Chest","id":"ss"}},"id":"ct"},"inventoryData":{"val":{"length":{"val":"27","id":"pi"},"inventoryContents":{"val":[],"id":"ls"}},"id":"ct"}},"id":"ct"}}
:enddata
:endrule

rule:
plugin=vanillaBlocks
number=32
data:
JSON:{{"val":{"buildPass":{"val":"0","id":"pi"},"blockName":{"val":"minecraft:oak_stairs","id":"ss"},"meta":{"val":"6","id":"pi"}},"id":"ct"}}
:enddata
:endrule

rule:
plugin=vanillaBlocks
number=33
data:
JSON:{{"val":{"buildPass":{"val":"2","id":"pi"},"blockName":{"val":"minecraft:torch","id":"ss"},"meta":{"val":"4","id":"pi"}},"id":"ct"}}
:enddata
:endrule

rule:
plugin=vanillaBlocks
number=34
data:
JSON:{{"val":{"buildPass":{"val":"0","id":"pi"},"blockName":{"val":"minecraft:bookshelf","id":"ss"},"meta":{"val":"0","id":"pi"}},"id":"ct"}}
:enddata
:endrule

rule:
plugin=vanillaBlocks
number=35
data:
JSON:{{"val":{"buildPass":{"val":"0","id":"pi"},"blockName":{"val":"minecraft:oak_stairs","id":"ss"},"meta":{"val":"2","id":"pi"}},"id":"ct"}}
:enddata
:endrule

rule:
plugin=vanillaBlocks
number=36
data:
JSON:{{"val":{"buildPass":{"val":"2","id":"pi"},"blockName":{"val":"minecraft:trapdoor","id":"ss"},"meta":{"val":"11","id":"pi"}},"id":"ct"}}
:enddata
:endrule

rule:
plugin=vanillaBlocks
number=37
data:
JSON:{{"val":{"buildPass":{"val":"2","id":"pi"},"blockName":{"val":"minecraft:red_flower","id":"ss"},"meta":{"val":"6","id":"pi"}},"id":"ct"}}
:enddata
:endrule

rule:
plugin=vanillaBlocks
number=38
data:
JSON:{{"val":{"buildPass":{"val":"2","id":"pi"},"blockName":{"val":"minecraft:red_flower","id":"ss"},"meta":{"val":"0","id":"pi"}},"id":"ct"}}
:enddata
:endrule

rule:
plugin=vanillaBlocks
number=39
data:
JSON:{{"val":{"buildPass":{"val":"2","id":"pi"},"blockName":{"val":"minecraft:red_flower","id":"ss"},"meta":{"val":"3","id":"pi"}},"id":"ct"}}
:enddata
:endrule

rule:
plugin=vanillaLogic
number=40
data:
JSON:{{"val":{"buildPass":{"val":"0","id":"pi"},"blockName":{"val":"props:blockProps","id":"ss"},"meta":{"val":"0","id":"pi"},"teData":{"val":{"slaves":{"val":[],"id":"ls"},"BlockType":{"val":"89","id":"pi"},"isRunning":{"val":"0","id":"pb"},"Items":{"val":[{"val":{"Slot":{"val":"0","id":"pb"},"id":{"val":"6643","id":"ps"},"Count":{"val":"1","id":"pb"},"Damage":{"val":"0","id":"ps"}},"id":"ct"},{"val":{"Slot":{"val":"1","id":"pb"},"id":{"val":"6643","id":"ps"},"Count":{"val":"1","id":"pb"},"Damage":{"val":"0","id":"ps"}},"id":"ct"},{"val":{"Slot":{"val":"2","id":"pb"},"id":{"val":"6643","id":"ps"},"Count":{"val":"1","id":"pb"},"Damage":{"val":"0","id":"ps"}},"id":"ct"},{"val":{"Slot":{"val":"3","id":"pb"},"id":{"val":"6643","id":"ps"},"Count":{"val":"1","id":"pb"},"Damage":{"val":"0","id":"ps"}},"id":"ct"},{"val":{"Slot":{"val":"4","id":"pb"},"id":{"val":"6643","id":"ps"},"Count":{"val":"1","id":"pb"},"Damage":{"val":"0","id":"ps"}},"id":"ct"},{"val":{"Slot":{"val":"5","id":"pb"},"id":{"val":"6643","id":"ps"},"Count":{"val":"1","id":"pb"},"Damage":{"val":"0","id":"ps"}},"id":"ct"},{"val":{"Slot":{"val":"6","id":"pb"},"id":{"val":"6643","id":"ps"},"Count":{"val":"1","id":"pb"},"Damage":{"val":"0","id":"ps"}},"id":"ct"},{"val":{"Slot":{"val":"7","id":"pb"},"id":{"val":"6643","id":"ps"},"Count":{"val":"1","id":"pb"},"Damage":{"val":"0","id":"ps"}},"id":"ct"},{"val":{"Slot":{"val":"8","id":"pb"},"id":{"val":"6643","id":"ps"},"Count":{"val":"1","id":"pb"},"Damage":{"val":"0","id":"ps"}},"id":"ct"},{"val":{"Slot":{"val":"9","id":"pb"},"id":{"val":"6643","id":"ps"},"Count":{"val":"1","id":"pb"},"Damage":{"val":"0","id":"ps"}},"id":"ct"},{"val":{"Slot":{"val":"10","id":"pb"},"id":{"val":"6643","id":"ps"},"Count":{"val":"1","id":"pb"},"Damage":{"val":"0","id":"ps"}},"id":"ct"},{"val":{"Slot":{"val":"11","id":"pb"},"id":{"val":"6643","id":"ps"},"Count":{"val":"1","id":"pb"},"Damage":{"val":"0","id":"ps"}},"id":"ct"},{"val":{"Slot":{"val":"12","id":"pb"},"id":{"val":"6643","id":"ps"},"Count":{"val":"1","id":"pb"},"Damage":{"val":"0","id":"ps"}},"id":"ct"},{"val":{"Slot":{"val":"13","id":"pb"},"id":{"val":"6643","id":"ps"},"Count":{"val":"1","id":"pb"},"Damage":{"val":"0","id":"ps"}},"id":"ct"},{"val":{"Slot":{"val":"14","id":"pb"},"id":{"val":"6643","id":"ps"},"Count":{"val":"1","id":"pb"},"Damage":{"val":"0","id":"ps"}},"id":"ct"}],"id":"ls"},"id":{"val":"com.mia.props.common.entities.TileContainer","id":"ss"},"BlockRotation":{"val":"8","id":"pi"}},"id":"ct"}},"id":"ct"}}
:enddata
:endrule

rule:
plugin=vanillaBlocks
number=41
data:
JSON:{{"val":{"buildPass":{"val":"0","id":"pi"},"blockName":{"val":"minecraft:crafting_table","id":"ss"},"meta":{"val":"0","id":"pi"}},"id":"ct"}}
:enddata
:endrule

rule:
plugin=vanillaLogic
number=42
data:
JSON:{{"val":{"buildPass":{"val":"0","id":"pi"},"blockName":{"val":"minecraft:furnace","id":"ss"},"meta":{"val":"3","id":"pi"},"teData":{"val":{"CookTime":{"val":"0","id":"ps"},"BurnTime":{"val":"0","id":"ps"},"Items":{"val":[],"id":"ls"},"id":{"val":"Furnace","id":"ss"}},"id":"ct"}},"id":"ct"}}
:enddata
:endrule

rule:
plugin=vanillaLogic
number=43
data:
JSON:{{"val":{"buildPass":{"val":"0","id":"pi"},"blockName":{"val":"props:blockProps","id":"ss"},"meta":{"val":"0","id":"pi"},"teData":{"val":{"slaves":{"val":[{"val":["-1830","6","-1108"],"id":"ai"}],"id":"ls"},"BlockType":{"val":"317","id":"pi"},"isRunning":{"val":"0","id":"pb"},"Items":{"val":[{"val":{"Slot":{"val":"0","id":"pb"},"id":{"val":"260","id":"ps"},"Count":{"val":"1","id":"pb"},"Damage":{"val":"0","id":"ps"}},"id":"ct"},{"val":{"Slot":{"val":"1","id":"pb"},"id":{"val":"260","id":"ps"},"Count":{"val":"1","id":"pb"},"Damage":{"val":"0","id":"ps"}},"id":"ct"},{"val":{"Slot":{"val":"2","id":"pb"},"id":{"val":"260","id":"ps"},"Count":{"val":"1","id":"pb"},"Damage":{"val":"0","id":"ps"}},"id":"ct"},{"val":{"Slot":{"val":"3","id":"pb"},"id":{"val":"260","id":"ps"},"Count":{"val":"1","id":"pb"},"Damage":{"val":"0","id":"ps"}},"id":"ct"},{"val":{"Slot":{"val":"4","id":"pb"},"id":{"val":"260","id":"ps"},"Count":{"val":"1","id":"pb"},"Damage":{"val":"0","id":"ps"}},"id":"ct"},{"val":{"Slot":{"val":"5","id":"pb"},"id":{"val":"260","id":"ps"},"Count":{"val":"1","id":"pb"},"Damage":{"val":"0","id":"ps"}},"id":"ct"},{"val":{"Slot":{"val":"6","id":"pb"},"id":{"val":"260","id":"ps"},"Count":{"val":"1","id":"pb"},"Damage":{"val":"0","id":"ps"}},"id":"ct"},{"val":{"Slot":{"val":"7","id":"pb"},"id":{"val":"260","id":"ps"},"Count":{"val":"1","id":"pb"},"Damage":{"val":"0","id":"ps"}},"id":"ct"},{"val":{"Slot":{"val":"8","id":"pb"},"id":{"val":"260","id":"ps"},"Count":{"val":"1","id":"pb"},"Damage":{"val":"0","id":"ps"}},"id":"ct"},{"val":{"Slot":{"val":"9","id":"pb"},"id":{"val":"260","id":"ps"},"Count":{"val":"1","id":"pb"},"Damage":{"val":"0","id":"ps"}},"id":"ct"},{"val":{"Slot":{"val":"10","id":"pb"},"id":{"val":"260","id":"ps"},"Count":{"val":"1","id":"pb"},"Damage":{"val":"0","id":"ps"}},"id":"ct"},{"val":{"Slot":{"val":"11","id":"pb"},"id":{"val":"260","id":"ps"},"Count":{"val":"1","id":"pb"},"Damage":{"val":"0","id":"ps"}},"id":"ct"},{"val":{"Slot":{"val":"12","id":"pb"},"id":{"val":"260","id":"ps"},"Count":{"val":"1","id":"pb"},"Damage":{"val":"0","id":"ps"}},"id":"ct"},{"val":{"Slot":{"val":"13","id":"pb"},"id":{"val":"260","id":"ps"},"Count":{"val":"1","id":"pb"},"Damage":{"val":"0","id":"ps"}},"id":"ct"},{"val":{"Slot":{"val":"14","id":"pb"},"id":{"val":"260","id":"ps"},"Count":{"val":"1","id":"pb"},"Damage":{"val":"0","id":"ps"}},"id":"ct"}],"id":"ls"},"id":{"val":"com.mia.props.common.entities.TileContainer","id":"ss"},"BlockRotation":{"val":"8","id":"pi"}},"id":"ct"}},"id":"ct"}}
:enddata
:endrule

rule:
plugin=vanillaLogic
number=44
data:
JSON:{{"val":{"buildPass":{"val":"0","id":"pi"},"blockName":{"val":"props:blockProps","id":"ss"},"meta":{"val":"0","id":"pi"},"teData":{"val":{"slaves":{"val":[],"id":"ls"},"BlockType":{"val":"590","id":"pi"},"isRunning":{"val":"0","id":"pb"},"Items":{"val":[{"val":{"Slot":{"val":"0","id":"pb"},"id":{"val":"297","id":"ps"},"Count":{"val":"1","id":"pb"},"Damage":{"val":"0","id":"ps"}},"id":"ct"},{"val":{"Slot":{"val":"1","id":"pb"},"id":{"val":"297","id":"ps"},"Count":{"val":"1","id":"pb"},"Damage":{"val":"0","id":"ps"}},"id":"ct"},{"val":{"Slot":{"val":"2","id":"pb"},"id":{"val":"297","id":"ps"},"Count":{"val":"1","id":"pb"},"Damage":{"val":"0","id":"ps"}},"id":"ct"},{"val":{"Slot":{"val":"3","id":"pb"},"id":{"val":"297","id":"ps"},"Count":{"val":"1","id":"pb"},"Damage":{"val":"0","id":"ps"}},"id":"ct"},{"val":{"Slot":{"val":"4","id":"pb"},"id":{"val":"297","id":"ps"},"Count":{"val":"1","id":"pb"},"Damage":{"val":"0","id":"ps"}},"id":"ct"},{"val":{"Slot":{"val":"5","id":"pb"},"id":{"val":"282","id":"ps"},"Count":{"val":"1","id":"pb"},"Damage":{"val":"0","id":"ps"}},"id":"ct"},{"val":{"Slot":{"val":"6","id":"pb"},"id":{"val":"282","id":"ps"},"Count":{"val":"1","id":"pb"},"Damage":{"val":"0","id":"ps"}},"id":"ct"},{"val":{"Slot":{"val":"7","id":"pb"},"id":{"val":"297","id":"ps"},"Count":{"val":"1","id":"pb"},"Damage":{"val":"0","id":"ps"}},"id":"ct"},{"val":{"Slot":{"val":"8","id":"pb"},"id":{"val":"297","id":"ps"},"Count":{"val":"1","id":"pb"},"Damage":{"val":"0","id":"ps"}},"id":"ct"},{"val":{"Slot":{"val":"9","id":"pb"},"id":{"val":"297","id":"ps"},"Count":{"val":"1","id":"pb"},"Damage":{"val":"0","id":"ps"}},"id":"ct"},{"val":{"Slot":{"val":"10","id":"pb"},"id":{"val":"6833","id":"ps"},"Count":{"val":"1","id":"pb"},"Damage":{"val":"0","id":"ps"}},"id":"ct"},{"val":{"Slot":{"val":"11","id":"pb"},"id":{"val":"6833","id":"ps"},"Count":{"val":"1","id":"pb"},"Damage":{"val":"0","id":"ps"}},"id":"ct"},{"val":{"Slot":{"val":"12","id":"pb"},"id":{"val":"6833","id":"ps"},"Count":{"val":"1","id":"pb"},"Damage":{"val":"0","id":"ps"}},"id":"ct"},{"val":{"Slot":{"val":"13","id":"pb"},"id":{"val":"6833","id":"ps"},"Count":{"val":"1","id":"pb"},"Damage":{"val":"0","id":"ps"}},"id":"ct"},{"val":{"Slot":{"val":"14","id":"pb"},"id":{"val":"6833","id":"ps"},"Count":{"val":"1","id":"pb"},"Damage":{"val":"0","id":"ps"}},"id":"ct"}],"id":"ls"},"id":{"val":"com.mia.props.common.entities.TileContainer","id":"ss"},"BlockRotation":{"val":"8","id":"pi"}},"id":"ct"}},"id":"ct"}}
:enddata
:endrule

rule:
plugin=vanillaLogic
number=45
data:
JSON:{{"val":{"buildPass":{"val":"0","id":"pi"},"blockName":{"val":"props:blockProps","id":"ss"},"meta":{"val":"0","id":"pi"},"teData":{"val":{"slaves":{"val":[],"id":"ls"},"BlockType":{"val":"591","id":"pi"},"isRunning":{"val":"0","id":"pb"},"id":{"val":"com.mia.props.common.TileProps","id":"ss"},"BlockRotation":{"val":"8","id":"pi"}},"id":"ct"}},"id":"ct"}}
:enddata
:endrule

rule:
plugin=vanillaLogic
number=46
data:
JSON:{{"val":{"buildPass":{"val":"0","id":"pi"},"blockName":{"val":"props:blockProps","id":"ss"},"meta":{"val":"0","id":"pi"},"teData":{"val":{"slaves":{"val":[],"id":"ls"},"BlockType":{"val":"591","id":"pi"},"isRunning":{"val":"0","id":"pb"},"id":{"val":"com.mia.props.common.TileProps","id":"ss"},"BlockRotation":{"val":"0","id":"pi"}},"id":"ct"}},"id":"ct"}}
:enddata
:endrule

rule:
plugin=vanillaLogic
number=47
data:
JSON:{{"val":{"buildPass":{"val":"0","id":"pi"},"blockName":{"val":"props:blockProps","id":"ss"},"meta":{"val":"0","id":"pi"},"teData":{"val":{"slaves":{"val":[],"id":"ls"},"BlockType":{"val":"591","id":"pi"},"isRunning":{"val":"0","id":"pb"},"id":{"val":"com.mia.props.common.TileProps","id":"ss"},"BlockRotation":{"val":"0","id":"pi"}},"id":"ct"}},"id":"ct"}}
:enddata
:endrule

rule:
plugin=vanillaLogic
number=48
data:
JSON:{{"val":{"buildPass":{"val":"0","id":"pi"},"blockName":{"val":"props:blockProps","id":"ss"},"meta":{"val":"0","id":"pi"},"teData":{"val":{"slaves":{"val":[],"id":"ls"},"BlockType":{"val":"568","id":"pi"},"isRunning":{"val":"0","id":"pb"},"Items":{"val":[],"id":"ls"},"id":{"val":"com.mia.props.common.entities.TileContainer","id":"ss"},"BlockRotation":{"val":"0","id":"pi"}},"id":"ct"}},"id":"ct"}}
:enddata
:endrule

rule:
plugin=vanillaLogic
number=49
data:
JSON:{{"val":{"buildPass":{"val":"0","id":"pi"},"blockName":{"val":"customnpcs:npcStool","id":"ss"},"meta":{"val":"5","id":"pi"},"teData":{"val":{"BannerColor":{"val":"14","id":"pi"},"BannerRotation":{"val":"2","id":"pi"},"id":{"val":"TileNPCStool","id":"ss"}},"id":"ct"}},"id":"ct"}}
:enddata
:endrule

rule:
plugin=vanillaLogic
number=50
data:
JSON:{{"val":{"buildPass":{"val":"0","id":"pi"},"blockName":{"val":"customnpcs:npcStool","id":"ss"},"meta":{"val":"5","id":"pi"},"teData":{"val":{"BannerColor":{"val":"14","id":"pi"},"BannerRotation":{"val":"2","id":"pi"},"id":{"val":"TileNPCStool","id":"ss"}},"id":"ct"}},"id":"ct"}}
:enddata
:endrule

rule:
plugin=vanillaLogic
number=51
data:
JSON:{{"val":{"buildPass":{"val":"0","id":"pi"},"blockName":{"val":"customnpcs:npcStool","id":"ss"},"meta":{"val":"5","id":"pi"},"teData":{"val":{"BannerColor":{"val":"14","id":"pi"},"BannerRotation":{"val":"2","id":"pi"},"id":{"val":"TileNPCStool","id":"ss"}},"id":"ct"}},"id":"ct"}}
:enddata
:endrule

rule:
plugin=vanillaLogic
number=52
data:
JSON:{{"val":{"buildPass":{"val":"0","id":"pi"},"blockName":{"val":"customnpcs:npcStool","id":"ss"},"meta":{"val":"5","id":"pi"},"teData":{"val":{"BannerColor":{"val":"14","id":"pi"},"BannerRotation":{"val":"2","id":"pi"},"id":{"val":"TileNPCStool","id":"ss"}},"id":"ct"}},"id":"ct"}}
:enddata
:endrule

rule:
plugin=vanillaFlowerPot
number=53
data:
JSON:{{"val":{"itemName":{"val":"minecraft:red_flower","id":"ss"},"buildPass":{"val":"0","id":"pi"},"itemMeta":{"val":"1","id":"pi"},"blockName":{"val":"minecraft:flower_pot","id":"ss"},"meta":{"val":"1","id":"pi"}},"id":"ct"}}
:enddata
:endrule

rule:
plugin=vanillaDoors
number=54
data:
JSON:{{"val":{"buildPass":{"val":"2","id":"pi"},"blockName":{"val":"minecraft:wooden_door","id":"ss"},"meta":{"val":"3","id":"pi"},"sideFlag":{"val":"8","id":"pb"}},"id":"ct"}}
:enddata
:endrule

rule:
plugin=vanillaBlocks
number=55
data:
JSON:{{"val":{"buildPass":{"val":"0","id":"pi"},"blockName":{"val":"minecraft:oak_stairs","id":"ss"},"meta":{"val":"3","id":"pi"}},"id":"ct"}}
:enddata
:endrule

rule:
plugin=vanillaBlocks
number=56
data:
JSON:{{"val":{"buildPass":{"val":"2","id":"pi"},"blockName":{"val":"minecraft:torch","id":"ss"},"meta":{"val":"3","id":"pi"}},"id":"ct"}}
:enddata
:endrule

rule:
plugin=vanillaBlocks
number=57
data:
JSON:{{"val":{"buildPass":{"val":"0","id":"pi"},"blockName":{"val":"minecraft:glass_pane","id":"ss"},"meta":{"val":"0","id":"pi"}},"id":"ct"}}
:enddata
:endrule

rule:
plugin=vanillaLogic
number=58
data:
JSON:{{"val":{"buildPass":{"val":"0","id":"pi"},"blockName":{"val":"props:blockProps","id":"ss"},"meta":{"val":"0","id":"pi"},"teData":{"val":{"slaves":{"val":[],"id":"ls"},"BlockType":{"val":"600","id":"pi"},"isRunning":{"val":"0","id":"pb"},"id":{"val":"com.mia.props.common.TileProps","id":"ss"},"BlockRotation":{"val":"8","id":"pi"}},"id":"ct"}},"id":"ct"}}
:enddata
:endrule

rule:
plugin=vanillaLogic
number=59
data:
JSON:{{"val":{"buildPass":{"val":"0","id":"pi"},"blockName":{"val":"props:blockFake","id":"ss"},"meta":{"val":"0","id":"pi"},"teData":{"val":{"id":{"val":"TileFake","id":"ss"},"master":{"val":["-1830","5","-1108"],"id":"ai"}},"id":"ct"}},"id":"ct"}}
:enddata
:endrule

rule:
plugin=vanillaLogic
number=60
data:
JSON:{{"val":{"buildPass":{"val":"0","id":"pi"},"blockName":{"val":"props:blockProps","id":"ss"},"meta":{"val":"0","id":"pi"},"teData":{"val":{"slaves":{"val":[],"id":"ls"},"BlockType":{"val":"525","id":"pi"},"isRunning":{"val":"0","id":"pb"},"id":{"val":"com.mia.props.common.TileProps","id":"ss"},"BlockRotation":{"val":"10","id":"pi"}},"id":"ct"}},"id":"ct"}}
:enddata
:endrule

rule:
plugin=vanillaBlocks
number=61
data:
JSON:{{"val":{"buildPass":{"val":"0","id":"pi"},"blockName":{"val":"minecraft:wool","id":"ss"},"meta":{"val":"0","id":"pi"}},"id":"ct"}}
:enddata
:endrule

rule:
plugin=vanillaBlocks
number=62
data:
JSON:{{"val":{"buildPass":{"val":"0","id":"pi"},"blockName":{"val":"minecraft:wool","id":"ss"},"meta":{"val":"8","id":"pi"}},"id":"ct"}}
:enddata
:endrule

rule:
plugin=vanillaDoors
number=63
data:
JSON:{{"val":{"buildPass":{"val":"2","id":"pi"},"blockName":{"val":"minecraft:wooden_door","id":"ss"},"meta":{"val":"8","id":"pi"},"sideFlag":{"val":"0","id":"pb"}},"id":"ct"}}
:enddata
:endrule

rule:
plugin=vanillaBlocks
number=64
data:
JSON:{{"val":{"buildPass":{"val":"0","id":"pi"},"blockName":{"val":"minecraft:wool","id":"ss"},"meta":{"val":"7","id":"pi"}},"id":"ct"}}
:enddata
:endrule

rule:
plugin=vanillaBlocks
number=65
data:
JSON:{{"val":{"buildPass":{"val":"0","id":"pi"},"blockName":{"val":"minecraft:wool","id":"ss"},"meta":{"val":"4","id":"pi"}},"id":"ct"}}
:enddata
:endrule

rule:
plugin=vanillaBlocks
number=66
data:
JSON:{{"val":{"buildPass":{"val":"0","id":"pi"},"blockName":{"val":"minecraft:wool","id":"ss"},"meta":{"val":"15","id":"pi"}},"id":"ct"}}
:enddata
:endrule

rule:
plugin=vanillaBlocks
number=67
data:
JSON:{{"val":{"buildPass":{"val":"0","id":"pi"},"blockName":{"val":"minecraft:wooden_slab","id":"ss"},"meta":{"val":"8","id":"pi"}},"id":"ct"}}
:enddata
:endrule

rule:
plugin=vanillaLogic
number=68
data:
JSON:{{"val":{"buildPass":{"val":"0","id":"pi"},"blockName":{"val":"props:blockProps","id":"ss"},"meta":{"val":"0","id":"pi"},"teData":{"val":{"slaves":{"val":[],"id":"ls"},"BlockType":{"val":"570","id":"pi"},"isRunning":{"val":"0","id":"pb"},"Items":{"val":[{"val":{"Slot":{"val":"0","id":"pb"},"id":{"val":"6828","id":"ps"},"Count":{"val":"1","id":"pb"},"Damage":{"val":"0","id":"ps"}},"id":"ct"},{"val":{"Slot":{"val":"1","id":"pb"},"id":{"val":"6828","id":"ps"},"Count":{"val":"1","id":"pb"},"Damage":{"val":"0","id":"ps"}},"id":"ct"},{"val":{"Slot":{"val":"2","id":"pb"},"id":{"val":"6828","id":"ps"},"Count":{"val":"1","id":"pb"},"Damage":{"val":"0","id":"ps"}},"id":"ct"},{"val":{"Slot":{"val":"3","id":"pb"},"id":{"val":"6828","id":"ps"},"Count":{"val":"1","id":"pb"},"Damage":{"val":"0","id":"ps"}},"id":"ct"},{"val":{"Slot":{"val":"4","id":"pb"},"id":{"val":"6828","id":"ps"},"Count":{"val":"1","id":"pb"},"Damage":{"val":"0","id":"ps"}},"id":"ct"},{"val":{"Slot":{"val":"5","id":"pb"},"id":{"val":"6828","id":"ps"},"Count":{"val":"1","id":"pb"},"Damage":{"val":"0","id":"ps"}},"id":"ct"},{"val":{"Slot":{"val":"6","id":"pb"},"id":{"val":"6828","id":"ps"},"Count":{"val":"1","id":"pb"},"Damage":{"val":"0","id":"ps"}},"id":"ct"},{"val":{"Slot":{"val":"7","id":"pb"},"id":{"val":"6828","id":"ps"},"Count":{"val":"1","id":"pb"},"Damage":{"val":"0","id":"ps"}},"id":"ct"},{"val":{"Slot":{"val":"8","id":"pb"},"id":{"val":"8308","id":"ps"},"Count":{"val":"1","id":"pb"},"Damage":{"val":"41","id":"ps"}},"id":"ct"},{"val":{"Slot":{"val":"9","id":"pb"},"id":{"val":"8308","id":"ps"},"Count":{"val":"1","id":"pb"},"Damage":{"val":"41","id":"ps"}},"id":"ct"},{"val":{"Slot":{"val":"10","id":"pb"},"id":{"val":"8308","id":"ps"},"Count":{"val":"1","id":"pb"},"Damage":{"val":"41","id":"ps"}},"id":"ct"},{"val":{"Slot":{"val":"11","id":"pb"},"id":{"val":"8308","id":"ps"},"Count":{"val":"1","id":"pb"},"Damage":{"val":"41","id":"ps"}},"id":"ct"},{"val":{"Slot":{"val":"12","id":"pb"},"id":{"val":"8310","id":"ps"},"Count":{"val":"1","id":"pb"},"Damage":{"val":"3","id":"ps"}},"id":"ct"},{"val":{"Slot":{"val":"13","id":"pb"},"id":{"val":"8310","id":"ps"},"Count":{"val":"1","id":"pb"},"Damage":{"val":"3","id":"ps"}},"id":"ct"},{"val":{"Slot":{"val":"14","id":"pb"},"id":{"val":"8310","id":"ps"},"Count":{"val":"1","id":"pb"},"Damage":{"val":"3","id":"ps"}},"id":"ct"},{"val":{"Slot":{"val":"15","id":"pb"},"id":{"val":"8310","id":"ps"},"Count":{"val":"1","id":"pb"},"Damage":{"val":"3","id":"ps"}},"id":"ct"}],"id":"ls"},"id":{"val":"com.mia.props.common.entities.TileContainer","id":"ss"},"BlockRotation":{"val":"0","id":"pi"}},"id":"ct"}},"id":"ct"}}
:enddata
:endrule

rule:
plugin=vanillaLogic
number=69
data:
JSON:{{"val":{"buildPass":{"val":"0","id":"pi"},"blockName":{"val":"props:blockProps","id":"ss"},"meta":{"val":"0","id":"pi"},"teData":{"val":{"slaves":{"val":[],"id":"ls"},"BlockType":{"val":"570","id":"pi"},"isRunning":{"val":"0","id":"pb"},"Items":{"val":[{"val":{"Slot":{"val":"0","id":"pb"},"id":{"val":"6711","id":"ps"},"Count":{"val":"1","id":"pb"},"Damage":{"val":"0","id":"ps"}},"id":"ct"},{"val":{"Slot":{"val":"1","id":"pb"},"id":{"val":"6711","id":"ps"},"Count":{"val":"1","id":"pb"},"Damage":{"val":"0","id":"ps"}},"id":"ct"},{"val":{"Slot":{"val":"2","id":"pb"},"id":{"val":"6711","id":"ps"},"Count":{"val":"1","id":"pb"},"Damage":{"val":"0","id":"ps"}},"id":"ct"},{"val":{"Slot":{"val":"3","id":"pb"},"id":{"val":"6711","id":"ps"},"Count":{"val":"1","id":"pb"},"Damage":{"val":"0","id":"ps"}},"id":"ct"},{"val":{"Slot":{"val":"4","id":"pb"},"id":{"val":"6674","id":"ps"},"Count":{"val":"1","id":"pb"},"Damage":{"val":"0","id":"ps"}},"id":"ct"},{"val":{"Slot":{"val":"5","id":"pb"},"id":{"val":"6674","id":"ps"},"Count":{"val":"1","id":"pb"},"Damage":{"val":"0","id":"ps"}},"id":"ct"},{"val":{"Slot":{"val":"6","id":"pb"},"id":{"val":"6674","id":"ps"},"Count":{"val":"1","id":"pb"},"Damage":{"val":"0","id":"ps"}},"id":"ct"},{"val":{"Slot":{"val":"7","id":"pb"},"id":{"val":"6674","id":"ps"},"Count":{"val":"1","id":"pb"},"Damage":{"val":"0","id":"ps"}},"id":"ct"},{"val":{"Slot":{"val":"8","id":"pb"},"id":{"val":"6698","id":"ps"},"Count":{"val":"1","id":"pb"},"Damage":{"val":"0","id":"ps"}},"id":"ct"},{"val":{"Slot":{"val":"9","id":"pb"},"id":{"val":"6698","id":"ps"},"Count":{"val":"1","id":"pb"},"Damage":{"val":"0","id":"ps"}},"id":"ct"},{"val":{"Slot":{"val":"10","id":"pb"},"id":{"val":"6698","id":"ps"},"Count":{"val":"1","id":"pb"},"Damage":{"val":"0","id":"ps"}},"id":"ct"},{"val":{"Slot":{"val":"11","id":"pb"},"id":{"val":"6698","id":"ps"},"Count":{"val":"1","id":"pb"},"Damage":{"val":"0","id":"ps"}},"id":"ct"},{"val":{"Slot":{"val":"12","id":"pb"},"id":{"val":"6713","id":"ps"},"Count":{"val":"1","id":"pb"},"Damage":{"val":"0","id":"ps"}},"id":"ct"},{"val":{"Slot":{"val":"13","id":"pb"},"id":{"val":"6713","id":"ps"},"Count":{"val":"1","id":"pb"},"Damage":{"val":"0","id":"ps"}},"id":"ct"},{"val":{"Slot":{"val":"14","id":"pb"},"id":{"val":"6713","id":"ps"},"Count":{"val":"1","id":"pb"},"Damage":{"val":"0","id":"ps"}},"id":"ct"},{"val":{"Slot":{"val":"15","id":"pb"},"id":{"val":"6713","id":"ps"},"Count":{"val":"1","id":"pb"},"Damage":{"val":"0","id":"ps"}},"id":"ct"}],"id":"ls"},"id":{"val":"com.mia.props.common.entities.TileContainer","id":"ss"},"BlockRotation":{"val":"0","id":"pi"}},"id":"ct"}},"id":"ct"}}
:enddata
:endrule

rule:
plugin=vanillaLogic
number=70
data:
JSON:{{"val":{"buildPass":{"val":"0","id":"pi"},"blockName":{"val":"props:blockProps","id":"ss"},"meta":{"val":"0","id":"pi"},"teData":{"val":{"slaves":{"val":[],"id":"ls"},"BlockType":{"val":"570","id":"pi"},"isRunning":{"val":"0","id":"pb"},"Items":{"val":[{"val":{"Slot":{"val":"0","id":"pb"},"id":{"val":"5896","id":"ps"},"Count":{"val":"1","id":"pb"},"Damage":{"val":"0","id":"ps"}},"id":"ct"},{"val":{"Slot":{"val":"1","id":"pb"},"id":{"val":"5896","id":"ps"},"Count":{"val":"1","id":"pb"},"Damage":{"val":"0","id":"ps"}},"id":"ct"},{"val":{"Slot":{"val":"2","id":"pb"},"id":{"val":"5896","id":"ps"},"Count":{"val":"1","id":"pb"},"Damage":{"val":"0","id":"ps"}},"id":"ct"},{"val":{"Slot":{"val":"3","id":"pb"},"id":{"val":"5896","id":"ps"},"Count":{"val":"1","id":"pb"},"Damage":{"val":"0","id":"ps"}},"id":"ct"},{"val":{"Slot":{"val":"4","id":"pb"},"id":{"val":"5482","id":"ps"},"Count":{"val":"1","id":"pb"},"Damage":{"val":"0","id":"ps"}},"id":"ct"},{"val":{"Slot":{"val":"5","id":"pb"},"id":{"val":"5482","id":"ps"},"Count":{"val":"1","id":"pb"},"Damage":{"val":"0","id":"ps"}},"id":"ct"},{"val":{"Slot":{"val":"6","id":"pb"},"id":{"val":"5482","id":"ps"},"Count":{"val":"1","id":"pb"},"Damage":{"val":"0","id":"ps"}},"id":"ct"},{"val":{"Slot":{"val":"7","id":"pb"},"id":{"val":"5482","id":"ps"},"Count":{"val":"1","id":"pb"},"Damage":{"val":"0","id":"ps"}},"id":"ct"},{"val":{"Slot":{"val":"8","id":"pb"},"id":{"val":"5482","id":"ps"},"Count":{"val":"1","id":"pb"},"Damage":{"val":"1","id":"ps"}},"id":"ct"},{"val":{"Slot":{"val":"9","id":"pb"},"id":{"val":"5482","id":"ps"},"Count":{"val":"1","id":"pb"},"Damage":{"val":"1","id":"ps"}},"id":"ct"},{"val":{"Slot":{"val":"10","id":"pb"},"id":{"val":"5482","id":"ps"},"Count":{"val":"1","id":"pb"},"Damage":{"val":"1","id":"ps"}},"id":"ct"},{"val":{"Slot":{"val":"11","id":"pb"},"id":{"val":"5482","id":"ps"},"Count":{"val":"1","id":"pb"},"Damage":{"val":"1","id":"ps"}},"id":"ct"},{"val":{"Slot":{"val":"12","id":"pb"},"id":{"val":"5482","id":"ps"},"Count":{"val":"1","id":"pb"},"Damage":{"val":"3","id":"ps"}},"id":"ct"},{"val":{"Slot":{"val":"13","id":"pb"},"id":{"val":"5482","id":"ps"},"Count":{"val":"1","id":"pb"},"Damage":{"val":"3","id":"ps"}},"id":"ct"},{"val":{"Slot":{"val":"14","id":"pb"},"id":{"val":"5482","id":"ps"},"Count":{"val":"1","id":"pb"},"Damage":{"val":"3","id":"ps"}},"id":"ct"},{"val":{"Slot":{"val":"15","id":"pb"},"id":{"val":"5482","id":"ps"},"Count":{"val":"1","id":"pb"},"Damage":{"val":"3","id":"ps"}},"id":"ct"}],"id":"ls"},"id":{"val":"com.mia.props.common.entities.TileContainer","id":"ss"},"BlockRotation":{"val":"0","id":"pi"}},"id":"ct"}},"id":"ct"}}
:enddata
:endrule

rule:
plugin=vanillaBlocks
number=71
data:
JSON:{{"val":{"buildPass":{"val":"0","id":"pi"},"blockName":{"val":"minecraft:wool","id":"ss"},"meta":{"val":"13","id":"pi"}},"id":"ct"}}
:enddata
:endrule

rule:
plugin=vanillaBlocks
number=72
data:
JSON:{{"val":{"buildPass":{"val":"0","id":"pi"},"blockName":{"val":"minecraft:log","id":"ss"},"meta":{"val":"4","id":"pi"}},"id":"ct"}}
:enddata
:endrule

rule:
plugin=vanillaLogic
number=73
data:
JSON:{{"val":{"buildPass":{"val":"0","id":"pi"},"blockName":{"val":"props:blockProps","id":"ss"},"meta":{"val":"0","id":"pi"},"teData":{"val":{"slaves":{"val":[],"id":"ls"},"BlockType":{"val":"101","id":"pi"},"isRunning":{"val":"0","id":"pb"},"Items":{"val":[{"val":{"Slot":{"val":"0","id":"pb"},"id":{"val":"6837","id":"ps"},"Count":{"val":"1","id":"pb"},"Damage":{"val":"0","id":"ps"}},"id":"ct"},{"val":{"Slot":{"val":"1","id":"pb"},"id":{"val":"6837","id":"ps"},"Count":{"val":"1","id":"pb"},"Damage":{"val":"0","id":"ps"}},"id":"ct"},{"val":{"Slot":{"val":"2","id":"pb"},"id":{"val":"6837","id":"ps"},"Count":{"val":"1","id":"pb"},"Damage":{"val":"0","id":"ps"}},"id":"ct"},{"val":{"Slot":{"val":"3","id":"pb"},"id":{"val":"6837","id":"ps"},"Count":{"val":"1","id":"pb"},"Damage":{"val":"0","id":"ps"}},"id":"ct"},{"val":{"Slot":{"val":"4","id":"pb"},"id":{"val":"6837","id":"ps"},"Count":{"val":"1","id":"pb"},"Damage":{"val":"0","id":"ps"}},"id":"ct"},{"val":{"Slot":{"val":"5","id":"pb"},"id":{"val":"6837","id":"ps"},"Count":{"val":"1","id":"pb"},"Damage":{"val":"0","id":"ps"}},"id":"ct"},{"val":{"Slot":{"val":"6","id":"pb"},"id":{"val":"6837","id":"ps"},"Count":{"val":"1","id":"pb"},"Damage":{"val":"0","id":"ps"}},"id":"ct"},{"val":{"Slot":{"val":"7","id":"pb"},"id":{"val":"6837","id":"ps"},"Count":{"val":"1","id":"pb"},"Damage":{"val":"0","id":"ps"}},"id":"ct"},{"val":{"Slot":{"val":"8","id":"pb"},"id":{"val":"6837","id":"ps"},"Count":{"val":"1","id":"pb"},"Damage":{"val":"0","id":"ps"}},"id":"ct"},{"val":{"Slot":{"val":"9","id":"pb"},"id":{"val":"6837","id":"ps"},"Count":{"val":"1","id":"pb"},"Damage":{"val":"0","id":"ps"}},"id":"ct"},{"val":{"Slot":{"val":"10","id":"pb"},"id":{"val":"6837","id":"ps"},"Count":{"val":"1","id":"pb"},"Damage":{"val":"0","id":"ps"}},"id":"ct"},{"val":{"Slot":{"val":"11","id":"pb"},"id":{"val":"6837","id":"ps"},"Count":{"val":"1","id":"pb"},"Damage":{"val":"0","id":"ps"}},"id":"ct"},{"val":{"Slot":{"val":"12","id":"pb"},"id":{"val":"6837","id":"ps"},"Count":{"val":"1","id":"pb"},"Damage":{"val":"0","id":"ps"}},"id":"ct"},{"val":{"Slot":{"val":"13","id":"pb"},"id":{"val":"6837","id":"ps"},"Count":{"val":"1","id":"pb"},"Damage":{"val":"0","id":"ps"}},"id":"ct"},{"val":{"Slot":{"val":"14","id":"pb"},"id":{"val":"6837","id":"ps"},"Count":{"val":"1","id":"pb"},"Damage":{"val":"0","id":"ps"}},"id":"ct"}],"id":"ls"},"id":{"val":"com.mia.props.common.entities.TileContainer","id":"ss"},"BlockRotation":{"val":"8","id":"pi"}},"id":"ct"}},"id":"ct"}}
:enddata
:endrule

rule:
plugin=vanillaLogic
number=74
data:
JSON:{{"val":{"buildPass":{"val":"0","id":"pi"},"blockName":{"val":"props:blockProps","id":"ss"},"meta":{"val":"0","id":"pi"},"teData":{"val":{"slaves":{"val":[],"id":"ls"},"BlockType":{"val":"101","id":"pi"},"isRunning":{"val":"0","id":"pb"},"Items":{"val":[],"id":"ls"},"id":{"val":"com.mia.props.common.entities.TileContainer","id":"ss"},"BlockRotation":{"val":"8","id":"pi"}},"id":"ct"}},"id":"ct"}}
:enddata
:endrule

rule:
plugin=vanillaLogic
number=75
data:
JSON:{{"val":{"buildPass":{"val":"0","id":"pi"},"blockName":{"val":"props:blockProps","id":"ss"},"meta":{"val":"0","id":"pi"},"teData":{"val":{"slaves":{"val":[],"id":"ls"},"BlockType":{"val":"101","id":"pi"},"isRunning":{"val":"0","id":"pb"},"Items":{"val":[],"id":"ls"},"id":{"val":"com.mia.props.common.entities.TileContainer","id":"ss"},"BlockRotation":{"val":"12","id":"pi"}},"id":"ct"}},"id":"ct"}}
:enddata
:endrule

rule:
plugin=vanillaLogic
number=76
data:
JSON:{{"val":{"buildPass":{"val":"0","id":"pi"},"blockName":{"val":"props:blockProps","id":"ss"},"meta":{"val":"0","id":"pi"},"teData":{"val":{"slaves":{"val":[{"val":["-267","68","422"],"id":"ai"}],"id":"ls"},"BlockType":{"val":"99","id":"pi"},"isRunning":{"val":"0","id":"pb"},"id":{"val":"com.mia.props.common.TileProps","id":"ss"},"BlockRotation":{"val":"4","id":"pi"}},"id":"ct"}},"id":"ct"}}
:enddata
:endrule

rule:
plugin=vanillaLogic
number=77
data:
JSON:{{"val":{"buildPass":{"val":"0","id":"pi"},"blockName":{"val":"props:blockProps","id":"ss"},"meta":{"val":"0","id":"pi"},"teData":{"val":{"slaves":{"val":[],"id":"ls"},"BlockType":{"val":"101","id":"pi"},"isRunning":{"val":"0","id":"pb"},"Items":{"val":[],"id":"ls"},"id":{"val":"com.mia.props.common.entities.TileContainer","id":"ss"},"BlockRotation":{"val":"12","id":"pi"}},"id":"ct"}},"id":"ct"}}
:enddata
:endrule

rule:
plugin=vanillaLogic
number=78
data:
JSON:{{"val":{"buildPass":{"val":"0","id":"pi"},"blockName":{"val":"props:blockProps","id":"ss"},"meta":{"val":"0","id":"pi"},"teData":{"val":{"slaves":{"val":[{"val":["-267","68","423"],"id":"ai"}],"id":"ls"},"BlockType":{"val":"99","id":"pi"},"isRunning":{"val":"0","id":"pb"},"id":{"val":"com.mia.props.common.TileProps","id":"ss"},"BlockRotation":{"val":"4","id":"pi"}},"id":"ct"}},"id":"ct"}}
:enddata
:endrule

rule:
plugin=vanillaLogic
number=79
data:
JSON:{{"val":{"buildPass":{"val":"0","id":"pi"},"blockName":{"val":"props:blockProps","id":"ss"},"meta":{"val":"0","id":"pi"},"teData":{"val":{"slaves":{"val":[],"id":"ls"},"BlockType":{"val":"570","id":"pi"},"isRunning":{"val":"0","id":"pb"},"Items":{"val":[{"val":{"Slot":{"val":"0","id":"pb"},"id":{"val":"5468","id":"ps"},"Count":{"val":"1","id":"pb"},"Damage":{"val":"2","id":"ps"}},"id":"ct"}],"id":"ls"},"id":{"val":"com.mia.props.common.entities.TileContainer","id":"ss"},"BlockRotation":{"val":"12","id":"pi"}},"id":"ct"}},"id":"ct"}}
:enddata
:endrule

rule:
plugin=vanillaLogic
number=80
data:
JSON:{{"val":{"buildPass":{"val":"0","id":"pi"},"blockName":{"val":"Thaumcraft:blockAiry","id":"ss"},"meta":{"val":"0","id":"pi"},"teData":{"val":{"lastActive":{"val":"1482029819831","id":"pl"},"modifier":{"val":"-1","id":"pb"},"Aspects":{"val":[{"val":{"amount":{"val":"13","id":"pi"},"key":{"val":"aer","id":"ss"}},"id":"ct"},{"val":{"amount":{"val":"11","id":"pi"},"key":{"val":"ignis","id":"ss"}},"id":"ct"},{"val":{"amount":{"val":"11","id":"pi"},"key":{"val":"ordo","id":"ss"}},"id":"ct"}],"id":"ls"},"AspectsBase":{"val":[{"val":{"amount":{"val":"13","id":"pi"},"key":{"val":"aer","id":"ss"}},"id":"ct"},{"val":{"amount":{"val":"11","id":"pi"},"key":{"val":"ignis","id":"ss"}},"id":"ct"},{"val":{"amount":{"val":"11","id":"pi"},"key":{"val":"ordo","id":"ss"}},"id":"ct"}],"id":"ls"},"id":{"val":"TileNode","id":"ss"},"type":{"val":"0","id":"pb"},"nodeId":{"val":"0:-1824:9:-1116","id":"ss"},"draincolor":{"val":"16777215","id":"pi"}},"id":"ct"}},"id":"ct"}}
:enddata
:endrule

rule:
plugin=vanillaLogic
number=81
data:
JSON:{{"val":{"buildPass":{"val":"0","id":"pi"},"blockName":{"val":"props:blockProps","id":"ss"},"meta":{"val":"0","id":"pi"},"teData":{"val":{"slaves":{"val":[],"id":"ls"},"BlockType":{"val":"570","id":"pi"},"isRunning":{"val":"0","id":"pb"},"Items":{"val":[{"val":{"Slot":{"val":"0","id":"pb"},"id":{"val":"5470","id":"ps"},"Count":{"val":"1","id":"pb"},"Damage":{"val":"2","id":"ps"}},"id":"ct"}],"id":"ls"},"id":{"val":"com.mia.props.common.entities.TileContainer","id":"ss"},"BlockRotation":{"val":"4","id":"pi"}},"id":"ct"}},"id":"ct"}}
:enddata
:endrule

#### ENTITIES ####
entity:
plugin=AWNpc
number=0
data:
position=6,2,20
