# Ancient Warfare Structure Template File
# Auto-generated structure template file. created on: 12/13/2016 at: 16:51:51
# Lines beginning with # denote comments

header:
version=2.1
name=ReignLiarBryChurch
size=20,42,62
offset=10,2,54
:endheader

#### VALIDATION ####
validation:
type=ground
survival=true
worldGenEnabled=true
unique=false
preserveBlocks=false
selectionWeight=100
clusterValue=130
minDuplicateDistance=50
dimensionWhiteList=true
dimensionList=0
biomeWhiteList=true
biomeList=forest,roofed forest,dead forest,taiga,arctic,dense forest,frost forest,ice plains,ominous woods
leveling=10
fill=8
border=6
validTargetBlocks=minecraft:stained_hardened_clay,minecraft:dirt,minecraft:coal_ore,minecraft:lapis_ore,minecraft:diamond_ore,minecraft:gravel,minecraft:stone,minecraft:sand,minecraft:clay,minecraft:gold_ore,minecraft:redstone_ore,minecraft:grass,minecraft:iron_ore
blockSwap=false
data:
:enddata
:endvalidation

#### LAYERS ####
layer: 0
1,1,1,1,1,1,1,1,1,1,1,1,1,1,1,1,1,1,1,1
1,1,1,1,1,1,1,1,1,1,1,1,1,1,1,1,1,1,1,1
1,1,1,1,1,1,1,1,1,1,1,1,1,1,1,1,1,1,1,1
1,1,1,1,1,1,1,1,1,1,1,1,1,1,1,1,1,1,1,1
1,1,1,1,1,1,1,1,1,1,1,1,1,1,1,1,1,1,1,1
1,1,1,1,1,1,1,1,1,1,1,1,1,1,1,1,1,1,1,1
1,1,1,1,1,1,1,1,1,1,1,1,1,1,1,1,1,1,1,1
1,1,1,1,1,1,1,1,1,1,1,1,1,1,1,1,1,1,1,1
1,1,1,1,1,1,1,1,1,1,1,1,1,1,1,1,1,1,1,1
1,1,1,1,1,1,1,1,1,1,1,1,1,1,1,1,1,1,1,1
1,1,1,1,1,1,1,1,1,1,1,1,1,1,1,1,1,1,1,1
1,1,1,1,1,1,1,1,1,1,1,1,1,1,1,1,1,1,1,1
1,1,1,1,1,1,1,1,1,1,1,1,1,1,1,1,1,1,1,1
1,1,1,1,1,1,1,1,1,1,1,1,1,1,1,1,1,1,1,1
1,1,1,1,1,1,1,1,1,1,1,1,1,1,1,1,1,1,1,1
1,1,1,1,1,1,1,1,1,1,1,1,1,1,1,1,1,1,1,1
1,1,1,1,1,1,1,1,1,1,1,1,1,1,1,1,1,1,1,1
1,1,1,1,1,1,1,1,1,1,1,1,1,1,1,1,1,1,1,1
1,1,1,1,1,1,1,1,1,1,1,1,1,1,1,1,1,1,1,1
1,1,1,1,1,1,1,1,1,1,1,1,1,1,1,1,1,1,1,1
1,1,1,1,1,1,1,1,1,1,1,1,1,1,1,1,1,1,1,1
1,1,1,1,1,1,1,1,1,1,1,1,1,1,1,1,1,1,1,1
1,1,1,1,1,1,1,1,1,1,1,1,1,1,1,1,1,1,1,1
1,1,1,1,1,1,1,1,1,1,1,1,1,1,1,1,1,1,1,1
1,1,1,1,1,1,1,1,1,1,1,1,1,1,1,1,1,1,1,1
1,1,1,1,1,1,1,1,1,1,1,1,1,1,1,1,1,1,1,1
1,1,1,1,1,1,1,1,1,1,1,1,1,1,1,1,1,1,1,1
1,1,1,1,1,1,1,1,1,1,1,1,1,1,1,1,1,1,1,1
1,1,1,1,1,1,1,1,1,1,1,1,1,1,1,1,1,1,1,1
1,1,1,1,1,1,1,1,1,1,1,1,1,1,1,1,1,1,1,1
1,1,1,1,1,1,1,1,1,1,1,1,1,1,1,1,1,1,1,1
1,1,1,1,1,1,1,1,1,1,1,1,1,1,1,1,1,1,1,1
1,1,1,1,1,1,1,1,1,1,1,1,1,1,1,1,1,1,1,1
1,1,1,1,1,1,1,1,1,1,1,1,1,1,1,1,1,1,1,1
1,1,1,1,1,1,1,1,1,1,1,1,1,1,1,1,1,1,1,1
1,1,1,1,1,1,1,1,1,1,1,1,1,1,1,1,1,1,1,1
1,1,1,1,1,1,1,1,1,1,1,1,1,1,1,1,1,1,1,1
1,1,1,1,1,1,1,1,1,1,1,1,1,1,1,1,1,1,1,1
1,1,1,1,1,1,1,1,1,1,1,1,1,1,1,1,1,1,1,1
1,1,1,1,1,1,1,1,1,1,1,1,1,1,1,1,1,1,1,1
1,1,1,1,1,1,1,1,1,1,1,1,1,1,1,1,1,1,1,1
1,1,1,1,1,1,1,1,1,1,1,1,1,1,1,1,1,1,1,1
1,1,1,1,1,1,1,1,1,1,1,1,1,1,1,1,1,1,1,1
1,1,1,1,1,1,1,1,1,1,1,1,1,1,1,1,1,1,1,1
1,1,1,1,1,1,1,1,1,1,1,1,1,1,1,1,1,1,1,1
1,1,1,1,1,1,1,1,1,1,1,1,1,1,1,1,1,1,1,1
1,1,1,1,1,1,1,1,1,1,1,1,1,1,1,1,1,1,1,1
1,1,1,1,1,1,1,1,1,1,1,1,1,1,1,1,1,1,1,1
1,1,1,1,1,1,1,1,1,1,1,1,1,1,1,1,1,1,1,1
1,1,1,1,1,1,1,1,1,1,1,1,1,1,1,1,1,1,1,1
1,1,1,1,1,1,1,1,1,1,1,1,1,1,1,1,1,1,1,1
1,1,1,1,1,1,1,1,1,1,1,1,1,1,1,1,1,1,1,1
1,1,1,1,1,1,1,1,1,1,1,1,1,1,1,1,1,1,1,1
1,1,1,1,1,1,1,1,1,1,1,1,1,1,1,1,1,1,1,1
1,1,1,1,1,1,1,1,1,1,1,1,1,1,1,1,1,1,1,1
1,1,1,1,1,1,1,1,1,1,1,1,1,1,1,1,1,1,1,1
1,1,1,1,1,1,1,1,1,1,1,1,1,1,1,1,1,1,1,1
1,1,1,1,1,1,1,1,1,1,1,1,1,1,1,1,1,1,1,1
1,1,1,1,1,1,1,1,1,1,1,1,1,1,1,1,1,1,1,1
1,1,1,1,1,1,1,1,1,1,1,1,1,1,1,1,1,1,1,1
1,1,1,1,1,1,1,1,1,1,1,1,1,1,1,1,1,1,1,1
1,1,1,1,1,1,1,1,1,1,1,1,1,1,1,1,1,1,1,1
:endlayer
layer: 1
2,2,2,2,2,2,2,2,2,2,2,2,2,2,2,2,2,2,2,2
2,2,3,4,4,4,4,4,9,4,4,4,4,4,4,4,4,4,3,2
2,2,4,1,0,0,0,3,0,0,3,0,0,3,0,3,3,4,4,2
2,2,4,1,4,4,4,4,4,4,4,4,4,4,4,4,4,4,4,2
2,2,4,1,4,4,4,4,4,4,4,4,4,4,4,4,4,1,4,2
2,2,3,3,3,3,3,3,3,3,3,3,3,3,3,3,3,3,3,2
2,2,3,3,3,4,4,4,4,4,4,4,4,4,4,4,3,3,3,2
2,2,4,1,3,4,3,3,3,3,3,3,3,3,3,4,3,1,4,2
2,2,4,1,3,4,3,1,3,3,3,3,3,1,3,4,3,4,4,2
2,2,4,1,3,4,3,3,3,4,4,4,3,3,3,4,3,4,4,2
2,2,1,3,3,4,3,3,4,3,4,3,4,3,3,4,3,3,3,2
2,2,1,3,3,4,3,3,4,3,4,3,4,3,3,4,3,3,3,2
2,2,4,1,3,4,3,3,3,4,4,4,3,3,3,4,3,1,4,2
2,2,4,1,3,4,3,1,3,3,3,3,3,1,3,4,3,1,4,2
2,2,4,1,3,4,3,3,3,4,4,4,3,3,3,4,3,1,4,2
2,2,3,3,3,4,3,3,4,3,4,3,4,3,3,4,3,3,3,2
2,2,3,3,3,4,3,3,4,3,4,3,4,3,3,4,3,3,3,2
2,2,4,1,3,4,3,3,3,4,4,4,3,3,3,4,3,1,4,2
2,2,4,1,3,4,3,1,3,3,3,3,3,1,3,4,3,1,4,2
2,2,4,1,3,4,3,3,3,4,4,4,3,3,3,4,3,4,4,2
2,2,1,3,3,4,3,3,4,3,4,3,4,3,3,4,3,3,3,2
2,2,1,3,3,4,3,3,4,3,4,3,4,3,3,4,3,3,3,2
2,2,4,1,3,4,3,3,3,4,4,4,3,3,3,4,3,1,4,2
2,2,4,1,3,4,3,1,3,3,3,3,3,1,3,4,3,1,4,2
2,2,4,1,3,4,3,3,3,4,4,4,3,3,3,4,3,1,4,2
2,2,1,3,3,4,3,3,4,3,4,3,4,3,3,4,3,3,1,2
2,2,1,3,3,4,3,3,4,3,4,3,4,3,3,4,3,3,1,2
2,2,4,1,3,4,3,3,3,4,4,4,3,3,3,4,3,1,4,2
2,2,4,1,3,4,3,1,3,3,3,3,3,1,3,4,3,1,4,2
2,2,4,1,3,4,3,3,3,4,4,4,3,3,3,4,3,1,4,2
2,2,1,3,3,4,3,3,4,3,4,3,4,3,3,4,3,3,1,2
2,2,1,3,3,4,3,3,4,3,4,3,4,3,3,4,3,3,1,2
2,2,4,1,3,4,3,3,3,4,4,4,3,3,3,4,3,1,4,2
2,2,4,1,3,4,3,1,3,3,3,3,3,1,3,4,3,1,4,2
2,2,4,1,3,4,3,3,4,4,8,4,4,3,3,4,3,1,4,2
2,2,1,3,3,4,3,3,4,4,1,4,4,3,3,4,3,3,1,2
2,2,1,3,3,4,3,3,4,4,1,4,4,3,3,4,3,3,1,2
2,2,4,1,3,4,3,3,4,4,4,4,4,3,3,4,3,1,4,2
2,2,4,1,3,4,3,1,3,3,3,3,3,1,3,4,3,1,4,2
2,2,4,1,3,4,3,3,3,3,3,3,3,3,3,4,3,1,4,2
2,2,1,3,3,4,4,4,4,4,4,4,4,4,4,4,3,3,1,2
2,2,1,3,3,3,3,3,3,3,3,3,3,3,3,3,3,3,1,2
2,2,4,1,4,4,4,4,4,4,4,4,4,4,4,4,4,1,4,2
2,2,4,1,4,4,4,4,4,4,4,4,4,4,4,4,4,1,4,2
2,2,4,4,4,4,4,3,5,5,5,5,5,3,4,4,4,1,4,2
2,2,1,1,1,1,1,1,4,4,4,4,4,4,4,4,1,1,1,2
2,2,4,2,1,1,4,10,4,4,4,4,4,4,4,4,1,2,4,2
2,2,4,2,1,1,1,4,4,4,4,1,1,1,1,1,1,2,4,2
2,2,4,2,1,1,1,1,1,4,4,4,1,1,1,1,1,2,4,2
2,2,4,1,1,1,1,1,1,4,4,4,1,1,1,1,1,2,4,2
2,2,4,1,1,1,1,1,1,4,4,4,2,1,1,1,1,2,4,2
2,2,4,1,1,1,1,1,1,4,4,4,2,1,2,2,1,2,4,2
2,2,4,1,1,1,1,1,1,6,6,6,1,1,1,1,1,2,4,2
2,2,4,1,1,1,1,1,6,7,7,7,6,1,1,1,1,2,4,2
2,2,4,1,1,1,1,1,6,7,6,7,6,2,2,2,2,1,4,2
2,2,4,4,4,4,4,4,4,4,4,4,4,4,4,4,4,4,4,2
2,2,2,2,2,2,2,2,2,4,3,4,2,2,2,2,2,2,2,2
2,2,2,2,2,2,2,2,2,4,3,4,2,2,2,2,2,2,2,2
2,2,2,2,2,2,2,2,2,4,3,4,2,2,2,2,2,2,2,2
2,2,2,2,2,2,2,2,2,4,3,4,2,2,2,2,2,2,2,2
2,2,2,2,2,2,2,2,2,4,3,4,2,2,2,2,2,2,2,2
2,2,2,2,2,2,2,2,2,2,2,2,2,2,2,2,2,2,2,2
:endlayer
layer: 2
0,11,11,0,0,0,0,0,0,0,0,0,0,0,0,0,0,0,0,0
0,11,3,3,13,0,14,3,13,14,3,13,14,3,13,0,14,3,3,0
0,11,0,4,3,3,3,15,3,3,26,3,3,15,3,3,3,4,0,0
0,11,0,4,12,12,12,0,12,12,0,12,12,0,12,12,12,4,0,0
0,11,0,4,12,0,0,0,0,0,0,0,0,0,0,0,12,4,0,0
0,11,3,12,49,0,0,0,0,0,0,0,0,0,0,0,0,12,3,0
0,11,3,12,50,0,0,0,0,0,0,0,0,0,0,0,0,12,3,0
0,51,0,4,12,0,0,12,12,0,27,0,12,12,0,0,12,4,0,0
0,0,0,4,12,0,0,18,12,0,28,0,12,18,0,0,12,4,0,0
0,52,0,4,12,0,0,12,12,0,29,0,12,12,0,0,12,4,0,0
0,0,3,12,0,0,0,0,0,0,0,0,0,0,0,0,0,12,3,0
0,0,3,12,0,0,0,0,0,0,0,0,0,0,0,0,0,12,3,0
0,11,0,4,12,0,0,12,12,0,30,0,12,12,0,0,12,4,0,0
0,11,0,4,12,0,0,18,12,0,31,0,12,18,0,0,12,4,0,0
0,11,0,4,12,0,0,12,12,0,32,0,12,12,0,0,12,4,0,0
0,11,3,12,0,0,0,0,0,0,0,0,0,0,0,0,0,12,3,0
0,11,3,12,0,0,0,0,0,0,0,0,0,0,0,0,0,12,3,0
0,0,0,4,12,0,0,12,12,0,33,0,12,12,0,0,12,4,0,0
0,0,0,4,12,0,0,18,12,0,34,0,21,18,0,0,12,4,0,0
0,0,0,4,12,0,0,12,12,0,35,0,12,12,0,0,12,4,0,0
0,0,3,12,0,0,0,0,0,0,0,0,0,0,0,0,0,12,3,0
0,0,3,12,0,0,0,0,0,0,0,0,0,0,0,0,0,12,3,0
0,11,0,4,12,0,0,12,12,0,36,0,12,12,0,0,12,4,0,0
0,0,0,4,12,0,0,18,12,0,37,0,12,18,0,0,12,4,0,0
0,0,0,4,12,0,0,12,12,0,38,0,12,12,0,0,12,4,0,0
0,0,3,12,0,0,0,0,0,0,0,0,0,0,0,0,0,12,3,0
0,11,3,12,0,0,0,0,0,0,0,0,0,0,0,0,0,12,3,0
0,11,0,4,12,0,0,12,12,0,39,0,12,12,0,0,12,4,0,0
0,11,0,4,12,0,0,18,12,0,40,0,12,18,0,0,12,4,0,0
0,11,0,4,12,0,0,12,12,0,41,0,12,12,0,0,12,4,0,0
0,0,3,12,0,0,0,0,0,0,0,0,0,0,0,0,0,12,3,0
0,0,3,12,0,0,0,0,0,0,0,0,0,0,0,0,0,12,3,0
0,0,0,4,12,0,0,0,0,0,0,0,0,0,0,0,12,4,0,0
0,0,0,4,12,0,0,3,0,0,0,0,0,3,0,0,12,4,0,0
0,0,0,4,12,0,0,0,0,44,0,0,0,0,0,0,12,4,0,0
0,11,3,12,0,0,0,0,0,45,3,0,0,0,0,0,0,12,3,0
0,0,3,12,0,0,0,0,0,0,3,0,0,0,0,0,0,12,3,0
0,11,0,4,12,0,0,0,0,0,0,0,0,0,0,0,12,4,0,0
0,11,0,4,12,0,0,3,0,0,0,0,0,3,0,0,12,4,0,0
0,11,0,4,12,0,0,0,0,0,0,0,0,0,0,0,12,4,0,0
0,11,3,12,0,0,0,0,46,0,0,0,22,0,0,0,0,12,3,0
0,0,3,12,0,0,0,0,47,0,0,0,23,0,0,0,0,12,3,0
0,0,0,4,12,0,0,0,0,0,0,0,0,0,0,0,12,4,0,0
0,11,0,4,12,12,12,0,48,0,0,0,0,19,12,12,12,4,0,0
0,0,0,4,15,15,15,15,5,25,25,25,5,15,15,15,15,4,0,0
0,0,3,3,13,3,14,3,13,14,0,13,14,3,13,3,14,3,3,0
0,11,0,14,3,4,6,0,17,3,0,3,17,17,17,6,3,13,0,0
0,11,0,14,3,4,3,4,4,3,0,3,4,4,4,4,3,13,0,0
0,11,0,14,3,3,15,3,3,3,0,3,3,3,15,3,3,13,0,0
0,0,0,14,4,4,4,4,4,3,42,3,4,4,4,4,4,13,0,0
0,0,0,14,3,3,3,6,24,0,0,0,24,6,3,3,3,13,0,0
0,11,0,14,3,0,0,20,24,0,0,0,24,20,0,0,3,13,0,0
0,11,0,14,3,0,0,0,3,4,15,4,3,4,4,4,3,13,0,0
0,0,0,14,3,3,4,4,3,0,0,0,3,4,4,3,3,13,0,0
0,0,0,4,16,16,16,16,3,0,43,0,3,16,16,16,16,4,0,0
0,0,0,0,0,0,0,0,0,0,0,0,0,0,0,0,0,0,0,0
0,11,11,0,0,0,0,0,0,0,0,0,11,0,11,0,11,11,0,0
0,11,11,11,0,0,0,0,0,0,0,0,0,0,11,0,11,11,11,0
0,0,11,0,0,11,0,11,0,0,0,0,0,11,0,11,0,11,11,0
0,11,11,11,0,11,11,11,0,0,0,0,0,11,0,0,11,11,0,0
0,0,0,0,0,11,11,11,11,0,0,0,0,11,0,0,11,0,0,0
0,11,11,0,0,0,0,11,0,0,11,0,0,0,0,0,0,0,0,0
:endlayer
layer: 3
0,0,0,0,0,0,0,0,0,0,0,0,0,0,0,0,0,0,0,0
0,0,3,3,9,0,53,3,9,53,3,9,53,3,9,0,53,3,3,0
0,0,0,4,3,3,3,15,3,3,26,3,3,15,3,3,3,4,0,0
0,0,0,4,12,12,12,0,12,12,0,12,12,0,12,12,12,4,0,0
0,0,0,4,12,0,0,0,0,0,0,0,0,0,0,0,12,4,0,0
0,0,3,12,0,0,0,0,0,0,0,0,0,0,0,0,0,12,3,0
0,0,3,12,0,0,0,0,0,0,0,0,0,0,0,0,0,12,3,0
0,0,0,4,12,0,0,12,12,0,0,0,12,12,0,0,12,4,0,0
0,0,0,4,12,0,0,15,12,0,0,0,12,15,0,0,12,4,0,0
0,0,0,4,12,0,0,12,12,0,0,0,12,12,0,0,12,4,0,0
0,0,3,12,0,0,0,0,0,0,0,0,0,0,0,0,0,12,3,0
0,0,3,12,0,0,0,0,0,0,0,0,0,0,0,0,0,12,3,0
0,0,0,4,12,0,0,12,12,0,0,0,12,12,0,0,12,4,0,0
0,0,0,4,12,0,0,15,12,0,0,0,12,15,0,0,12,4,0,0
0,0,0,4,12,0,0,12,12,0,0,0,12,12,0,0,12,4,0,0
0,0,3,12,0,0,0,0,0,0,0,0,0,0,0,0,0,12,3,0
0,0,3,12,0,0,0,0,0,0,0,0,0,0,0,0,0,12,3,0
0,0,0,4,12,0,0,12,12,0,0,0,12,12,0,0,12,4,0,0
0,0,0,4,12,0,0,15,12,0,0,0,12,15,0,0,12,4,0,0
0,0,0,4,12,0,0,12,12,0,0,0,12,12,0,0,12,4,0,0
0,0,3,12,0,0,0,0,0,0,0,0,0,0,0,0,0,12,3,0
0,0,3,12,0,0,0,0,0,0,0,0,0,0,0,0,0,12,3,0
0,0,0,4,12,0,0,12,12,0,0,0,12,12,0,0,12,4,0,0
0,0,0,4,12,0,0,15,12,0,0,0,12,15,0,0,12,4,0,0
0,0,0,4,12,0,0,12,12,0,0,0,12,12,0,0,12,4,0,0
0,0,3,12,0,0,0,0,0,0,0,0,0,0,0,0,0,12,3,0
0,0,3,12,0,0,0,0,0,0,0,0,0,0,0,0,0,12,3,0
0,0,0,4,12,0,0,12,12,0,0,0,12,12,0,0,12,4,0,0
0,0,0,4,12,0,0,15,12,0,0,0,12,15,0,0,12,4,0,0
0,0,0,4,12,0,0,12,12,0,0,0,12,12,0,0,12,4,0,0
0,0,3,12,0,0,0,0,0,0,0,0,0,0,0,0,0,12,3,0
0,0,3,12,0,0,0,0,0,0,0,0,0,0,0,0,0,12,3,0
0,0,0,4,12,0,0,0,0,0,0,0,0,0,0,0,12,4,0,0
0,0,0,4,12,0,0,3,0,0,0,0,0,3,0,0,12,4,0,0
0,0,0,4,12,0,0,0,0,0,0,0,0,0,0,0,12,4,0,0
0,0,3,12,0,0,0,0,0,0,3,0,0,0,0,0,0,12,3,0
0,0,3,12,0,0,0,0,0,44,3,0,0,0,0,0,0,12,3,0
0,0,0,4,12,0,0,0,0,45,0,0,0,0,0,0,12,4,0,0
0,0,0,4,12,0,0,3,0,0,0,0,0,3,0,0,12,4,0,0
0,0,0,4,12,0,0,0,0,0,0,0,0,0,0,0,12,4,0,0
0,0,3,12,0,0,0,0,0,0,0,0,0,0,0,0,0,12,3,0
0,0,3,12,0,0,0,0,0,0,0,0,0,0,0,0,0,12,3,0
0,0,0,4,12,0,0,0,0,0,0,0,0,0,0,0,12,4,0,0
0,0,0,4,12,12,12,0,0,0,0,0,0,0,12,12,12,4,0,0
0,0,0,4,15,15,15,15,5,25,25,25,5,15,15,15,15,4,0,0
0,0,3,3,9,3,53,3,9,53,0,9,53,3,9,3,53,3,3,0
0,0,0,0,4,3,6,17,17,3,0,3,17,17,54,6,3,0,0,0
0,0,0,0,4,0,3,4,4,3,0,3,4,4,3,4,3,0,0,0
0,0,0,0,3,3,55,3,3,3,0,3,3,3,55,3,3,0,0,0
0,0,0,0,4,4,4,4,4,3,56,3,4,4,4,4,4,0,0,0
0,0,0,0,24,6,24,0,0,0,0,0,0,0,24,6,24,0,0,0
0,0,0,0,24,6,24,0,0,0,0,0,0,0,24,6,24,0,0,0
0,0,0,0,24,6,4,4,3,4,15,4,3,4,4,6,24,0,0,0
0,0,0,0,24,6,4,4,3,0,0,0,3,4,4,6,24,0,0,0
0,0,0,0,0,0,0,0,3,0,0,0,3,0,0,0,0,0,0,0
0,0,0,0,0,0,0,0,0,0,0,0,0,0,0,0,0,0,0,0
0,0,0,0,0,0,0,0,0,0,0,0,0,0,0,0,0,0,0,0
0,0,0,0,0,0,0,0,0,0,0,0,0,0,0,0,0,0,0,0
0,0,0,0,0,0,0,0,0,0,0,0,0,0,0,0,0,0,0,0
0,0,0,0,0,0,0,0,0,0,0,0,0,0,0,0,0,0,0,0
0,0,0,0,0,0,0,0,0,0,0,0,0,0,0,0,0,0,0,0
0,0,0,0,0,0,0,0,0,0,0,0,0,0,0,0,0,0,0,0
:endlayer
layer: 4
0,0,0,0,0,0,0,0,0,0,0,0,0,0,0,0,0,0,0,0
0,0,3,3,13,0,14,3,13,14,3,13,14,3,13,0,14,3,3,0
0,0,3,4,3,3,3,15,3,3,26,3,3,15,3,3,3,4,0,0
0,0,0,4,12,12,12,0,12,12,0,12,12,0,12,12,12,4,0,0
0,0,3,4,12,0,0,0,0,0,0,0,0,0,0,0,12,4,0,0
0,0,3,12,0,0,0,0,0,0,0,0,0,0,0,0,0,12,3,0
0,0,3,12,0,0,0,0,0,0,0,0,0,0,0,0,0,12,3,0
0,0,0,4,12,0,0,12,12,0,0,0,12,12,0,0,12,4,0,0
0,0,0,4,12,0,64,3,12,0,0,0,12,3,57,0,12,4,0,0
0,0,3,4,12,0,0,12,12,0,0,0,12,12,0,0,12,4,0,0
0,0,3,12,0,0,0,0,0,0,0,0,0,0,0,0,0,12,3,0
0,0,3,12,0,0,0,0,0,0,0,0,0,0,0,0,0,12,3,0
0,0,0,4,12,0,0,12,12,0,0,0,12,12,0,0,12,4,0,0
0,0,0,4,12,0,64,3,12,0,0,0,12,3,57,0,12,4,0,0
0,0,0,4,12,0,0,12,12,0,0,0,12,12,0,0,12,4,0,0
0,0,3,12,0,0,0,0,0,0,0,0,0,0,0,0,0,12,3,0
0,0,3,12,0,0,0,0,0,0,0,0,0,0,0,0,0,12,3,0
0,0,0,4,12,0,0,12,12,0,0,0,12,12,0,0,12,4,0,0
0,0,0,4,12,0,64,3,12,0,0,0,12,3,57,0,12,4,0,0
0,0,0,4,12,0,0,12,12,0,0,0,12,12,0,0,12,4,0,0
0,0,3,12,0,0,0,0,0,0,0,0,0,0,0,0,0,12,3,0
0,0,3,12,0,0,0,0,0,0,0,0,0,0,0,0,0,12,3,0
0,0,0,4,12,0,0,12,12,0,0,0,12,12,0,0,12,4,0,0
0,0,0,4,12,0,64,3,12,0,0,0,12,3,57,0,12,4,0,0
0,0,0,4,12,0,0,12,12,0,0,0,12,12,0,0,12,4,0,0
0,0,3,12,0,0,0,0,0,0,0,0,0,0,0,0,0,12,3,0
0,0,3,12,0,0,0,0,0,0,0,0,0,0,0,0,0,12,3,0
0,0,0,4,12,0,0,12,12,0,0,0,12,12,0,0,12,4,0,0
0,0,0,4,12,0,64,3,12,0,0,0,12,3,57,0,12,4,0,0
0,0,0,4,12,0,0,12,12,0,0,0,12,12,0,0,12,4,0,0
0,0,3,12,0,0,0,0,0,0,0,0,0,0,0,0,0,12,3,0
0,0,3,12,0,0,0,0,0,0,0,0,0,0,0,0,0,12,3,0
0,0,0,4,12,0,0,0,0,0,0,0,0,0,0,0,12,4,0,0
0,0,0,4,12,0,64,3,0,0,0,0,0,3,57,0,12,4,0,0
0,0,0,4,12,0,0,0,0,0,0,0,0,0,0,0,12,4,0,0
0,0,3,12,0,0,0,0,0,0,3,0,0,0,0,0,0,12,3,0
0,0,3,12,0,0,0,0,0,0,3,0,0,0,0,0,0,12,3,0
0,0,0,4,12,0,0,0,0,0,44,45,0,0,0,0,12,4,0,0
0,0,0,4,12,0,64,3,0,0,0,0,0,3,57,0,12,4,0,0
0,0,0,4,12,0,0,58,0,0,0,0,0,58,0,0,12,4,0,0
0,0,3,12,0,0,0,0,0,0,0,0,0,0,0,0,0,12,3,0
0,0,3,12,0,0,0,0,0,0,0,0,0,0,0,0,0,12,3,0
0,0,0,4,12,0,0,0,0,0,0,0,0,0,0,0,12,4,0,0
0,0,0,4,12,12,12,0,0,0,0,0,0,0,12,12,12,4,0,0
0,0,0,4,15,15,15,15,5,25,25,25,5,15,15,15,15,4,0,0
0,0,3,3,13,3,14,3,13,63,60,59,14,3,13,3,14,3,3,0
0,0,0,0,4,3,6,54,17,3,0,3,17,17,17,6,4,0,0,0
0,0,0,0,4,4,4,4,3,3,0,3,4,4,4,4,4,0,0,0
0,0,0,0,3,0,55,0,3,3,61,3,3,0,55,0,3,0,0,0
0,0,0,0,0,0,0,0,0,3,3,3,0,0,0,0,0,0,0,0
0,0,0,0,0,0,0,0,0,0,62,0,0,0,0,0,0,0,0,0
0,0,0,0,0,0,0,0,0,0,0,0,0,0,0,0,0,0,0,0
0,0,0,0,0,0,24,6,3,4,15,4,3,6,24,0,0,0,0,0
0,0,0,0,0,0,24,6,3,9,0,53,3,6,24,0,0,0,0,0
0,0,0,0,0,0,0,0,3,0,0,0,3,0,0,0,0,0,0,0
0,0,0,0,0,0,0,0,0,0,0,0,0,0,0,0,0,0,0,0
0,0,0,0,0,0,0,0,0,0,0,0,0,0,0,0,0,0,0,0
0,0,0,0,0,0,0,0,0,0,0,0,0,0,0,0,0,0,0,0
0,0,0,0,0,0,0,0,0,0,0,0,0,0,0,0,0,0,0,0
0,0,0,0,0,0,0,0,0,0,0,0,0,0,0,0,0,0,0,0
0,0,0,0,0,0,0,0,0,0,0,0,0,0,0,0,0,0,0,0
0,0,0,0,0,0,0,0,0,0,0,0,0,0,0,0,0,0,0,0
:endlayer
layer: 5
0,0,0,0,0,0,0,0,0,0,0,0,0,0,0,0,0,0,0,0
0,0,3,3,9,0,53,3,9,53,3,9,53,3,9,0,53,3,3,0
0,0,3,4,3,3,3,15,3,3,26,3,3,15,3,3,3,4,0,0
0,0,3,4,65,65,65,67,0,0,0,0,0,67,65,65,65,4,0,0
0,0,3,4,65,65,65,67,0,0,0,0,0,67,65,65,65,4,0,0
0,0,3,65,65,65,65,67,0,0,0,0,0,67,65,65,65,65,3,0
0,0,3,65,65,65,65,67,0,0,0,0,0,67,65,65,65,65,3,0
0,0,3,4,65,65,65,67,72,0,0,0,68,67,65,65,65,4,0,0
0,0,3,4,26,66,66,3,72,0,0,0,68,3,66,66,26,4,0,0
0,0,3,4,65,65,65,67,72,0,0,0,68,67,65,65,65,4,0,0
0,0,3,65,65,65,65,67,0,0,0,0,0,67,65,65,65,65,3,0
0,0,3,65,65,65,65,67,0,0,0,0,0,67,65,65,65,65,3,0
0,0,0,4,65,65,65,67,72,0,0,0,68,67,65,65,65,4,0,0
0,0,0,4,26,66,66,3,72,0,0,0,68,3,66,66,26,4,0,0
0,0,0,4,65,65,65,67,72,0,0,0,68,67,65,65,65,4,0,0
0,0,3,65,65,65,65,67,0,0,0,0,0,67,65,65,65,65,3,0
0,0,3,65,65,65,65,67,0,0,0,0,0,67,65,65,65,65,3,0
0,0,0,4,65,65,65,67,72,0,0,0,68,67,65,65,65,4,0,0
0,0,0,4,26,66,66,3,72,0,0,0,68,3,66,66,26,4,0,0
0,0,0,4,65,65,65,67,72,0,0,0,68,67,65,65,65,4,0,0
0,0,3,65,65,65,65,67,0,0,0,0,0,67,65,65,65,65,3,0
0,0,3,65,65,65,65,67,0,0,0,0,0,67,65,65,65,65,3,0
0,0,0,4,65,65,65,67,72,0,0,0,68,67,65,65,65,4,0,0
0,0,0,4,26,66,66,3,72,0,0,0,68,3,66,66,66,4,0,0
0,0,0,4,65,65,65,67,72,0,0,0,68,67,65,65,65,4,0,0
0,0,3,65,65,65,65,67,0,0,0,0,0,67,65,65,65,65,3,0
0,0,3,65,65,65,65,67,0,0,0,0,0,67,65,65,65,65,3,0
0,0,0,4,65,65,65,67,72,0,0,0,68,67,65,65,65,4,0,0
0,0,0,4,26,66,66,3,72,0,0,0,68,3,66,66,66,4,0,0
0,0,0,4,65,65,65,67,72,0,0,0,68,67,65,65,65,4,0,0
0,0,3,65,65,65,65,67,0,0,0,0,0,67,65,65,65,65,3,0
0,0,3,65,65,65,65,67,0,0,0,0,0,67,65,65,65,65,3,0
0,0,0,4,65,65,65,67,0,0,0,0,0,67,65,65,65,4,0,0
0,0,0,4,66,66,66,3,66,66,66,66,66,3,66,66,26,4,0,0
0,0,0,4,65,65,65,67,65,0,0,0,65,67,65,65,65,4,0,0
0,0,3,65,65,65,65,67,65,0,3,45,65,67,65,65,65,65,3,0
0,0,3,65,65,65,65,67,65,0,3,44,65,67,65,65,65,65,3,0
0,0,0,4,65,65,65,67,65,0,0,0,65,67,65,65,65,4,0,0
0,0,0,4,66,66,66,3,66,66,66,66,66,3,66,66,26,4,0,0
0,0,0,4,65,65,65,67,65,65,65,65,65,67,65,65,65,4,0,0
0,0,3,65,65,65,65,67,65,65,65,65,65,67,65,65,65,65,3,0
0,0,3,65,65,65,65,67,65,65,65,65,65,67,65,65,65,65,3,0
0,0,0,4,65,65,65,67,65,65,65,65,65,67,65,65,65,4,0,0
0,0,0,4,65,65,65,67,65,65,65,65,65,67,65,65,65,4,0,0
0,0,0,4,3,3,3,67,5,5,5,5,5,67,3,3,3,4,0,0
0,0,3,3,9,3,53,3,9,53,3,9,53,3,9,3,53,3,3,0
0,0,0,0,4,3,6,17,17,3,3,3,17,17,17,6,4,0,0,0
0,0,0,0,4,4,4,4,3,3,3,3,4,4,4,4,4,0,0,0
0,0,0,0,3,0,55,0,3,3,3,3,3,0,55,0,3,0,0,0
0,0,0,0,0,0,0,0,0,3,3,3,0,0,0,0,0,0,0,0
0,0,0,0,0,0,0,0,0,69,69,69,0,0,0,0,0,0,0,0
0,0,0,0,0,0,0,0,0,20,20,20,0,0,0,0,0,0,0,0
0,0,0,0,0,0,0,0,24,6,6,6,24,0,0,0,0,0,0,0
0,0,0,0,0,0,0,0,24,6,6,6,24,0,0,0,0,0,0,0
0,0,0,0,0,0,0,0,3,71,45,70,3,0,0,0,0,0,0,0
0,0,0,0,0,0,0,0,0,0,0,0,0,0,0,0,0,0,0,0
0,0,0,0,0,0,0,0,0,0,0,0,0,0,0,0,0,0,0,0
0,0,0,0,0,0,0,0,0,0,0,0,0,0,0,0,0,0,0,0
0,0,0,0,0,0,0,0,0,0,0,0,0,0,0,0,0,0,0,0
0,0,0,0,0,0,0,0,0,0,0,0,0,0,0,0,0,0,0,0
0,0,0,0,0,0,0,0,0,0,0,0,0,0,0,0,0,0,0,0
0,0,0,0,0,0,0,0,0,0,0,0,0,0,0,0,0,0,0,0
:endlayer
layer: 6
0,0,0,0,0,0,0,0,0,0,0,0,0,0,0,0,0,0,0,0
0,0,3,3,13,0,14,3,13,14,3,13,14,3,13,0,14,3,3,0
0,0,69,3,3,3,3,15,3,3,26,3,3,15,3,3,3,3,69,0
0,0,0,18,12,12,12,110,0,0,103,0,0,73,12,12,12,18,0,0
0,0,60,3,12,0,0,111,0,0,0,0,0,74,0,0,12,3,60,0
0,0,3,15,0,0,0,112,0,0,0,0,0,75,0,0,0,15,3,0
0,0,3,15,0,0,0,113,0,0,0,0,0,76,0,0,0,15,3,0
0,0,69,3,12,0,0,114,0,0,0,0,0,77,0,0,12,3,69,0
0,0,0,18,12,0,0,3,0,0,0,0,0,3,0,0,12,18,0,0
0,0,60,3,12,0,0,115,0,0,0,0,0,78,0,0,12,3,60,0
0,0,3,15,0,0,0,116,0,0,0,0,0,79,0,0,0,15,3,0
0,0,3,15,0,0,0,117,0,0,0,0,0,80,0,0,0,15,3,0
0,0,69,3,12,0,0,118,0,0,0,0,0,81,0,0,12,3,69,0
0,0,0,18,12,0,0,3,0,0,0,0,0,3,0,0,12,18,0,0
0,0,60,3,12,0,0,119,0,0,0,0,0,82,0,0,12,3,60,0
0,0,3,15,0,0,0,120,0,0,0,0,0,83,0,0,0,15,3,0
0,0,3,15,0,0,0,121,0,0,0,0,0,84,0,0,0,15,3,0
0,0,69,3,12,0,0,122,0,0,0,0,0,85,0,0,12,3,69,0
0,0,0,18,12,0,0,3,0,0,0,0,0,3,0,0,12,18,0,0
0,0,60,3,12,0,0,123,0,0,0,0,0,86,0,0,12,3,60,0
0,0,3,15,0,0,0,124,0,0,0,0,0,87,0,0,0,15,3,0
0,0,3,15,0,0,0,125,0,0,0,0,0,88,0,0,0,15,3,0
0,0,69,3,12,0,0,126,0,0,0,0,0,89,0,0,12,3,69,0
0,0,0,18,12,0,0,3,0,0,0,0,0,3,0,0,12,18,0,0
0,0,60,3,12,0,0,127,0,0,0,0,0,90,0,0,12,3,60,0
0,0,3,15,0,0,0,128,0,0,0,0,0,91,0,0,0,15,3,0
0,0,3,15,0,0,0,129,0,0,0,0,0,92,0,0,0,15,3,0
0,0,69,3,12,0,0,130,0,0,0,0,0,93,0,0,12,3,69,0
0,0,0,18,12,0,0,3,0,0,0,0,0,3,0,0,12,18,0,0
0,0,60,3,12,0,0,131,0,0,0,0,0,94,0,0,12,3,60,0
0,0,3,15,0,0,0,132,0,0,0,0,0,95,0,0,0,15,3,0
0,0,3,15,0,0,0,133,0,0,0,0,0,96,0,0,0,15,3,0
0,0,69,3,12,0,0,134,0,0,0,0,0,97,0,0,12,3,69,0
0,0,0,18,12,0,0,3,108,106,104,101,99,3,0,0,12,18,0,0
0,0,60,3,12,0,0,135,0,0,45,44,0,0,0,0,12,3,60,0
0,0,3,15,0,0,0,136,0,0,3,0,0,0,0,0,0,15,3,0
0,0,3,15,0,0,0,137,0,0,3,0,0,0,0,0,0,15,3,0
0,0,69,3,12,0,0,138,0,0,0,0,0,0,0,0,12,3,69,0
0,0,0,18,12,0,0,3,109,107,105,102,100,3,0,0,12,18,0,0
0,0,60,3,12,0,0,0,0,0,0,0,0,0,0,0,12,3,60,0
0,0,3,15,0,0,0,0,0,0,0,0,0,0,0,0,0,15,3,0
0,0,3,15,0,0,0,0,12,12,12,12,12,0,0,0,0,15,3,0
0,0,69,3,12,0,0,0,0,0,0,0,0,0,0,0,12,3,69,0
0,0,0,18,12,12,12,0,12,12,12,12,12,0,12,12,12,18,0,0
0,0,60,3,3,3,3,139,3,3,4,3,3,98,3,3,3,3,60,0
0,0,3,3,13,3,14,3,13,14,3,13,14,3,13,3,53,3,3,0
0,0,0,0,4,3,6,54,54,3,3,3,54,54,54,6,4,0,0,0
0,0,0,0,4,4,4,4,3,3,3,3,4,4,4,4,4,0,0,0
0,0,0,0,3,0,55,0,3,3,3,3,3,0,55,0,3,0,0,0
0,0,0,0,0,0,0,0,58,3,3,3,58,0,0,0,0,0,0,0
0,0,0,0,0,0,0,0,0,6,6,6,0,0,0,0,0,0,0,0
0,0,0,0,0,0,0,0,0,24,24,24,0,0,0,0,0,0,0,0
0,0,0,0,0,0,0,0,0,0,0,0,0,0,0,0,0,0,0,0
0,0,0,0,0,0,0,0,0,0,0,0,0,0,0,0,0,0,0,0
0,0,0,0,0,0,0,0,0,3,3,3,0,0,0,0,0,0,0,0
0,0,0,0,0,0,0,0,0,0,0,0,0,0,0,0,0,0,0,0
0,0,0,0,0,0,0,0,0,0,0,0,0,0,0,0,0,0,0,0
0,0,0,0,0,0,0,0,0,0,0,0,0,0,0,0,0,0,0,0
0,0,0,0,0,0,0,0,0,0,0,0,0,0,0,0,0,0,0,0
0,0,0,0,0,0,0,0,0,0,0,0,0,0,0,0,0,0,0,0
0,0,0,0,0,0,0,0,0,0,0,0,0,0,0,0,0,0,0,0
0,0,0,0,0,0,0,0,0,0,0,0,0,0,0,0,0,0,0,0
:endlayer
layer: 7
0,0,0,0,0,0,0,0,0,0,0,0,0,0,0,0,0,0,0,0
0,0,140,3,9,0,53,3,9,53,3,9,53,3,9,0,53,3,140,0
0,0,3,15,3,3,3,15,3,3,26,3,3,15,3,3,3,15,3,0
0,0,3,15,12,12,12,0,147,146,144,143,142,0,12,12,12,15,3,0
0,0,3,15,12,0,0,0,0,0,0,0,0,0,0,0,12,15,3,0
0,0,16,15,0,0,0,0,0,0,0,0,0,0,0,0,0,15,16,0
0,0,140,15,0,0,0,0,0,0,0,0,0,0,0,0,0,15,140,0
0,0,3,15,12,0,0,0,0,0,0,0,0,0,0,0,12,15,3,0
0,0,3,15,12,0,64,3,57,0,0,0,64,3,57,0,12,15,3,0
0,0,3,15,12,0,0,0,0,0,0,0,0,0,0,0,12,15,3,0
0,0,16,15,0,0,0,0,0,0,0,0,0,0,0,0,0,15,16,0
0,0,140,15,0,0,0,0,0,0,0,0,0,0,0,0,0,15,140,0
0,0,3,15,12,0,0,0,0,0,0,0,0,0,0,0,12,15,3,0
0,0,3,15,12,0,64,3,57,0,0,0,64,3,57,0,12,15,3,0
0,0,3,15,12,0,0,0,0,0,0,0,0,0,0,0,12,15,3,0
0,0,16,15,0,0,0,0,0,0,0,0,0,0,0,0,0,15,16,0
0,0,140,15,0,0,0,0,0,0,0,0,0,0,0,0,0,15,140,0
0,0,3,15,12,0,0,0,0,0,0,0,0,0,0,0,12,15,3,0
0,0,3,15,12,0,64,3,57,0,0,0,64,3,57,0,12,15,3,0
0,0,3,15,12,0,0,0,0,0,0,0,0,0,0,0,12,15,3,0
0,0,16,15,0,0,0,0,0,0,0,0,0,0,0,0,0,15,16,0
0,0,140,15,0,0,0,0,0,0,0,0,0,0,0,0,0,15,140,0
0,0,3,15,12,0,0,0,0,0,0,0,0,0,0,0,12,15,3,0
0,0,3,15,12,0,64,3,57,0,0,0,64,3,57,0,12,15,3,0
0,0,3,15,12,0,0,0,0,0,0,0,0,0,0,0,12,15,3,0
0,0,16,15,0,0,0,0,0,0,0,0,0,0,0,0,0,15,16,0
0,0,140,15,0,0,0,0,0,0,0,0,0,0,0,0,0,15,140,0
0,0,3,15,12,0,0,0,0,0,0,0,0,0,0,0,12,15,3,0
0,0,3,15,12,0,64,3,57,0,0,0,64,3,57,0,12,15,3,0
0,0,3,15,12,0,0,0,0,0,0,0,0,0,0,0,12,15,3,0
0,0,16,15,0,0,0,0,0,0,0,0,0,0,0,0,0,15,16,0
0,0,140,15,0,0,0,0,0,0,0,0,0,0,0,0,0,15,140,0
0,0,3,15,12,0,0,0,0,0,0,0,0,0,0,0,12,15,3,0
0,0,3,15,12,0,64,3,0,0,0,0,0,3,0,0,12,15,3,0
0,0,3,15,12,0,0,0,0,44,0,0,0,0,0,0,12,15,3,0
0,0,16,15,0,0,0,0,0,45,3,0,0,0,0,0,0,15,16,0
0,0,140,15,0,0,0,0,0,0,3,0,0,0,0,0,0,15,140,0
0,0,3,15,12,0,0,0,0,0,0,0,0,0,0,0,12,15,3,0
0,0,3,15,12,0,0,3,0,0,0,0,0,3,0,0,12,15,3,0
0,0,3,15,12,0,0,0,0,0,0,0,0,0,0,0,12,15,3,0
0,0,16,15,0,0,0,0,0,0,0,0,0,0,0,0,0,15,16,0
0,0,140,15,0,0,0,0,12,12,12,12,12,0,0,0,0,15,140,0
0,0,3,15,12,0,0,0,0,0,0,0,0,0,0,0,12,15,3,0
0,0,3,15,12,12,12,0,12,12,12,12,12,0,12,12,12,15,3,0
0,0,3,15,3,3,3,0,3,3,4,3,3,0,3,3,3,15,3,0
0,0,16,3,9,3,4,3,9,53,3,9,53,3,9,3,53,3,16,0
0,0,0,0,4,6,6,54,54,3,3,3,4,4,3,6,4,0,0,0
0,0,0,0,4,4,7,4,6,6,6,6,4,4,7,4,4,0,0,0
0,0,0,0,3,9,141,53,3,6,6,6,3,9,141,53,3,0,0,0
0,0,0,0,0,0,0,0,0,24,24,24,0,0,0,0,0,0,0,0
0,0,0,0,0,0,0,0,0,0,0,0,0,0,0,0,0,0,0,0
0,0,0,0,0,0,0,0,0,0,0,0,0,0,0,0,0,0,0,0
0,0,0,0,0,0,0,0,0,0,0,0,0,0,0,0,0,0,0,0
0,0,0,0,0,0,0,0,0,0,0,0,0,0,0,0,0,0,0,0
0,0,0,0,0,0,0,0,0,0,145,0,0,0,0,0,0,0,0,0
0,0,0,0,0,0,0,0,0,0,0,0,0,0,0,0,0,0,0,0
0,0,0,0,0,0,0,0,0,0,0,0,0,0,0,0,0,0,0,0
0,0,0,0,0,0,0,0,0,0,0,0,0,0,0,0,0,0,0,0
0,0,0,0,0,0,0,0,0,0,0,0,0,0,0,0,0,0,0,0
0,0,0,0,0,0,0,0,0,0,0,0,0,0,0,0,0,0,0,0
0,0,0,0,0,0,0,0,0,0,0,0,0,0,0,0,0,0,0,0
0,0,0,0,0,0,0,0,0,0,0,0,0,0,0,0,0,0,0,0
:endlayer
layer: 8
0,0,0,0,0,0,0,0,0,0,0,0,0,0,0,0,0,0,0,0
0,0,140,3,13,0,14,3,13,14,3,13,14,3,13,0,14,3,140,0
0,0,140,3,3,3,3,15,3,3,26,3,3,15,3,3,3,3,140,0
0,0,3,15,12,12,12,0,0,150,149,148,0,0,12,12,12,15,3,0
0,0,16,15,12,0,0,0,0,0,0,0,0,0,0,0,12,15,16,0
0,0,0,15,0,0,0,0,0,0,0,0,0,0,0,0,0,15,0,0
0,0,0,15,0,0,0,0,0,0,0,0,0,0,0,0,0,15,0,0
0,0,140,15,12,0,0,0,0,0,0,0,0,0,0,0,12,15,140,0
0,0,3,15,12,0,0,3,0,0,0,0,0,3,0,0,12,15,3,0
0,0,16,15,12,0,0,0,0,0,0,0,0,0,0,0,12,15,16,0
0,0,0,15,0,0,0,0,0,0,0,0,0,0,0,0,0,15,0,0
0,0,0,15,0,0,0,0,0,0,0,0,0,0,0,0,0,15,0,0
0,0,140,15,12,0,0,0,0,0,0,0,0,0,0,0,12,15,140,0
0,0,3,15,12,0,0,3,0,0,0,0,0,3,0,0,12,15,3,0
0,0,16,15,12,0,0,0,0,0,0,0,0,0,0,0,12,15,16,0
0,0,0,15,0,0,0,0,0,0,0,0,0,0,0,0,0,15,0,0
0,0,0,15,0,0,0,0,0,0,0,0,0,0,0,0,0,15,0,0
0,0,140,15,12,0,0,0,0,0,0,0,0,0,0,0,12,15,140,0
0,0,3,15,12,0,0,3,0,0,0,0,0,3,0,0,12,15,3,0
0,0,16,15,12,0,0,0,0,0,0,0,0,0,0,0,12,15,16,0
0,0,0,15,0,0,0,0,0,0,0,0,0,0,0,0,0,15,0,0
0,0,0,15,0,0,0,0,0,0,0,0,0,0,0,0,0,15,0,0
0,0,140,15,12,0,0,0,0,0,0,0,0,0,0,0,12,15,140,0
0,0,3,15,12,0,0,3,0,0,0,0,0,3,0,0,12,15,3,0
0,0,16,15,12,0,0,0,0,0,0,0,0,0,0,0,12,15,16,0
0,0,0,15,0,0,0,0,0,0,0,0,0,0,0,0,0,15,0,0
0,0,0,15,0,0,0,0,0,0,0,0,0,0,0,0,0,15,0,0
0,0,140,15,12,0,0,0,0,0,0,0,0,0,0,0,12,15,140,0
0,0,3,15,12,0,0,3,0,0,0,0,0,3,0,0,12,15,3,0
0,0,16,15,12,0,0,0,0,0,0,0,0,0,0,0,12,15,16,0
0,0,0,15,0,0,0,0,0,0,0,0,0,0,0,0,0,15,0,0
0,0,0,15,0,0,0,0,0,0,0,0,0,0,0,0,0,15,0,0
0,0,140,15,12,0,0,0,0,0,0,0,0,0,0,0,12,15,140,0
0,0,3,15,12,0,0,3,0,0,0,0,0,3,0,0,12,15,3,0
0,0,16,15,12,0,0,0,0,0,0,0,0,0,0,0,12,15,16,0
0,0,0,15,0,0,0,0,0,0,3,0,0,0,0,0,0,15,0,0
0,0,0,15,0,0,0,0,0,44,3,0,0,0,0,0,0,15,0,0
0,0,140,15,12,0,0,0,0,45,0,0,0,0,0,0,12,15,140,0
0,0,3,15,12,0,0,3,0,0,0,0,0,3,0,0,12,15,3,0
0,0,16,15,12,0,0,0,0,0,0,0,0,0,0,0,12,15,16,0
0,0,0,15,0,0,0,0,0,0,0,0,0,0,0,0,0,15,0,0
0,0,0,15,0,0,0,0,12,12,12,12,12,0,0,0,0,15,0,0
0,0,140,15,12,0,0,0,0,0,0,0,0,0,0,0,12,15,140,0
0,0,3,15,12,12,12,0,12,12,12,12,12,0,12,12,12,15,3,0
0,0,16,3,3,3,3,0,3,3,4,3,3,0,3,3,3,3,16,0
0,0,16,3,13,3,4,3,13,14,3,13,14,3,13,3,14,3,16,0
0,0,0,0,4,6,6,4,4,4,4,4,4,4,4,6,4,0,0,0
0,0,0,0,6,6,6,6,24,0,0,0,24,6,6,6,6,0,0,0
0,0,0,0,6,6,6,6,24,0,0,0,24,6,6,6,6,0,0,0
0,0,0,0,0,0,0,0,0,0,0,0,0,0,0,0,0,0,0,0
0,0,0,0,0,0,0,0,0,0,0,0,0,0,0,0,0,0,0,0
0,0,0,0,0,0,0,0,0,0,0,0,0,0,0,0,0,0,0,0
0,0,0,0,0,0,0,0,0,0,0,0,0,0,0,0,0,0,0,0
0,0,0,0,0,0,0,0,0,0,0,0,0,0,0,0,0,0,0,0
0,0,0,0,0,0,0,0,0,0,0,0,0,0,0,0,0,0,0,0
0,0,0,0,0,0,0,0,0,0,0,0,0,0,0,0,0,0,0,0
0,0,0,0,0,0,0,0,0,0,0,0,0,0,0,0,0,0,0,0
0,0,0,0,0,0,0,0,0,0,0,0,0,0,0,0,0,0,0,0
0,0,0,0,0,0,0,0,0,0,0,0,0,0,0,0,0,0,0,0
0,0,0,0,0,0,0,0,0,0,0,0,0,0,0,0,0,0,0,0
0,0,0,0,0,0,0,0,0,0,0,0,0,0,0,0,0,0,0,0
0,0,0,0,0,0,0,0,0,0,0,0,0,0,0,0,0,0,0,0
:endlayer
layer: 9
0,0,0,0,0,0,0,0,0,0,0,0,0,0,0,0,0,0,0,0
0,0,4,3,3,3,3,3,3,3,3,3,3,3,3,3,3,3,4,0
0,0,4,26,26,26,26,26,26,26,26,26,26,26,26,26,26,26,4,0
0,0,4,26,3,4,3,3,3,3,4,4,3,3,3,4,3,26,4,0
0,0,4,26,3,4,3,3,4,3,4,3,4,3,3,4,3,26,4,0
0,0,4,26,3,4,3,3,4,4,18,4,4,3,3,4,3,26,4,0
0,0,4,26,3,4,3,3,4,18,18,18,4,3,3,4,3,26,4,0
0,0,4,26,3,4,3,3,3,4,18,4,3,3,3,4,3,26,4,0
0,0,4,26,3,4,3,65,3,4,3,4,3,65,3,4,3,26,4,0
0,0,4,26,3,4,3,3,4,3,3,3,4,3,3,4,3,26,4,0
0,0,4,26,3,4,3,3,4,3,3,3,4,3,3,4,3,26,4,0
0,0,4,26,3,4,3,3,4,3,3,3,4,3,3,4,3,26,4,0
0,0,4,26,3,4,3,3,3,4,3,4,3,3,3,4,3,26,4,0
0,0,4,26,3,4,3,65,4,4,3,4,4,65,3,4,3,26,4,0
0,0,4,26,3,4,3,3,3,4,3,4,3,3,3,4,3,26,4,0
0,0,4,26,3,4,3,3,4,3,3,3,4,3,3,4,3,26,4,0
0,0,4,26,3,4,3,3,4,3,3,3,4,3,3,4,3,26,4,0
0,0,4,26,3,4,3,3,3,4,3,4,3,3,3,4,3,26,4,0
0,0,4,26,3,4,3,65,4,4,3,4,4,65,3,4,3,26,4,0
0,0,4,26,3,4,3,3,3,4,3,4,3,3,3,4,3,26,4,0
0,0,4,26,3,4,3,3,4,3,3,3,4,3,3,4,3,26,4,0
0,0,4,26,3,4,3,3,4,3,3,3,4,3,3,4,3,26,4,0
0,0,4,26,3,4,3,3,3,4,3,4,3,3,3,4,3,26,4,0
0,0,4,26,3,4,3,65,4,4,3,4,4,65,3,4,3,26,4,0
0,0,4,26,3,4,3,3,3,4,3,4,3,3,3,4,3,26,4,0
0,0,4,26,3,4,3,3,4,3,3,3,4,3,3,4,3,26,4,0
0,0,4,26,3,4,3,3,4,3,3,3,4,3,3,4,3,26,4,0
0,0,4,26,3,4,3,3,3,4,3,4,3,3,3,4,3,26,4,0
0,0,4,26,3,4,3,65,4,4,3,4,4,65,3,4,3,26,4,0
0,0,4,26,3,4,3,3,3,4,3,4,3,3,3,4,3,26,4,0
0,0,4,26,3,4,3,3,4,3,3,3,4,3,3,4,3,26,4,0
0,0,4,26,3,4,3,3,4,3,3,3,4,3,3,4,3,26,4,0
0,0,4,26,3,4,3,3,3,4,3,4,3,3,3,4,3,26,4,0
0,0,4,26,3,4,3,65,4,4,3,4,4,65,3,4,3,26,4,0
0,0,4,26,3,4,3,3,4,0,0,0,4,3,3,4,3,26,4,0
0,0,4,26,3,4,3,3,4,0,3,0,4,3,3,4,3,26,4,0
0,0,4,26,3,4,3,3,4,0,3,0,4,3,3,4,3,26,4,0
0,0,4,26,3,4,3,3,4,0,44,45,4,3,3,4,3,26,4,0
0,0,4,26,3,4,3,65,4,4,3,4,4,3,3,4,3,26,4,0
0,0,4,26,3,4,3,3,3,4,3,4,3,3,3,4,3,26,4,0
0,0,4,26,3,4,3,3,4,3,3,3,4,3,3,4,3,26,4,0
0,0,4,26,3,4,3,3,3,4,3,4,3,3,3,4,3,26,4,0
0,0,4,26,3,4,3,3,3,4,3,4,3,3,3,4,3,26,4,0
0,0,4,26,3,4,3,3,3,4,3,4,3,3,3,4,3,26,4,0
0,0,4,26,4,4,4,26,26,26,26,26,26,26,4,4,4,26,4,0
0,0,4,3,3,3,3,3,3,3,3,3,3,3,3,3,3,3,4,0
0,0,0,0,24,24,24,3,3,3,3,3,3,3,24,24,24,0,0,0
0,0,0,0,0,0,0,0,0,0,0,0,0,0,0,0,0,0,0,0
0,0,0,0,0,0,0,0,0,0,0,0,0,0,0,0,0,0,0,0
0,0,0,0,0,0,0,0,0,0,0,0,0,0,0,0,0,0,0,0
0,0,0,0,0,0,0,0,0,0,0,0,0,0,0,0,0,0,0,0
0,0,0,0,0,0,0,0,0,0,0,0,0,0,0,0,0,0,0,0
0,0,0,0,0,0,0,0,0,0,0,0,0,0,0,0,0,0,0,0
0,0,0,0,0,0,0,0,0,0,0,0,0,0,0,0,0,0,0,0
0,0,0,0,0,0,0,0,0,0,0,0,0,0,0,0,0,0,0,0
0,0,0,0,0,0,0,0,0,0,0,0,0,0,0,0,0,0,0,0
0,0,0,0,0,0,0,0,0,0,0,0,0,0,0,0,0,0,0,0
0,0,0,0,0,0,0,0,0,0,0,0,0,0,0,0,0,0,0,0
0,0,0,0,0,0,0,0,0,0,0,0,0,0,0,0,0,0,0,0
0,0,0,0,0,0,0,0,0,0,0,0,0,0,0,0,0,0,0,0
0,0,0,0,0,0,0,0,0,0,0,0,0,0,0,0,0,0,0,0
0,0,0,0,0,0,0,0,0,0,0,0,0,0,0,0,0,0,0,0
:endlayer
layer: 10
0,0,0,0,0,0,0,0,0,0,0,0,0,0,0,0,0,0,0,0
0,0,4,151,151,140,140,151,140,140,140,140,140,151,140,140,151,151,4,0
0,0,63,3,3,3,3,3,3,3,3,3,3,3,3,3,3,3,59,0
0,0,63,3,188,0,0,68,154,154,65,154,154,72,0,0,0,3,59,0
0,0,14,4,0,26,0,68,67,67,67,67,67,72,0,26,0,4,13,0
0,0,14,4,0,0,0,68,67,67,67,67,67,72,0,153,0,4,13,0
0,0,14,4,0,0,0,68,67,67,67,67,67,72,0,0,0,4,13,0
0,0,14,4,0,0,0,68,67,67,67,67,67,72,0,0,0,4,13,0
0,0,63,3,0,0,0,3,155,155,155,155,155,3,0,0,0,3,59,0
0,0,14,4,0,0,0,0,0,0,0,0,0,0,0,0,0,4,13,0
0,0,14,4,0,0,0,0,0,0,0,0,0,0,0,0,0,4,13,0
0,0,14,4,0,0,0,0,0,0,0,0,0,0,0,0,0,4,13,0
0,0,14,4,0,0,0,0,0,0,0,0,0,0,0,0,0,4,13,0
0,0,63,3,0,0,0,3,180,172,0,164,156,3,0,0,0,3,59,0
0,0,14,4,0,0,0,0,0,0,0,0,0,0,0,0,0,4,13,0
0,0,14,4,0,0,0,0,181,173,0,165,157,0,0,0,0,4,13,0
0,0,14,4,0,0,0,0,0,0,0,0,0,0,0,0,0,4,13,0
0,0,14,4,0,0,0,0,182,174,0,166,158,0,0,0,0,4,13,0
0,0,63,3,0,0,0,3,0,0,0,0,0,3,0,0,0,3,59,0
0,0,14,4,0,0,0,0,183,175,0,167,159,0,0,0,0,4,13,0
0,0,14,4,0,0,0,0,0,0,0,0,0,0,0,0,0,4,13,0
0,0,14,4,0,0,0,0,184,176,0,168,160,0,0,0,0,4,13,0
0,0,14,4,0,0,0,0,0,0,0,0,0,0,0,0,0,13,13,0
0,0,63,3,0,0,0,3,185,177,0,169,161,3,0,0,0,3,59,0
0,0,14,4,0,0,0,0,0,0,0,0,0,0,0,0,0,4,13,0
0,0,14,4,0,0,0,0,186,178,0,170,162,0,0,0,0,4,13,0
0,0,14,4,0,0,0,0,0,0,0,0,0,0,0,0,0,4,13,0
0,0,14,4,0,0,0,0,187,179,0,171,163,0,0,0,0,4,13,0
0,0,63,3,0,0,0,3,0,0,0,0,0,3,0,0,0,3,59,0
0,0,14,4,0,0,0,0,0,0,0,0,0,0,0,0,0,4,13,0
0,0,14,4,0,0,0,0,0,0,0,0,0,0,0,0,0,4,13,0
0,0,14,4,0,0,0,0,0,0,0,0,0,0,0,0,0,4,13,0
0,0,14,4,0,0,0,0,0,0,0,0,0,0,0,0,0,4,13,0
0,0,63,3,0,0,0,3,0,0,0,0,0,3,0,0,0,3,59,0
0,0,14,4,0,0,0,0,0,0,0,0,0,0,0,0,0,4,13,0
0,0,14,4,0,0,0,0,0,0,3,45,0,0,0,0,0,4,13,0
0,0,14,4,0,0,0,0,0,0,3,44,0,0,0,0,0,4,13,0
0,0,14,4,0,0,0,0,0,0,0,0,0,0,0,0,0,4,13,0
0,0,63,3,0,0,0,3,0,0,0,0,0,3,0,0,0,3,59,0
0,0,14,4,0,0,0,0,0,0,0,0,0,0,0,0,0,4,13,0
0,0,14,4,0,0,0,0,0,0,0,0,0,0,0,0,0,4,13,0
0,0,14,4,0,0,0,0,0,0,0,0,0,0,0,0,0,4,13,0
0,0,14,4,0,0,0,0,0,0,0,0,0,0,0,0,0,4,13,0
0,0,63,3,0,0,0,0,0,0,0,0,0,0,0,0,0,3,59,0
0,0,63,3,0,0,0,3,3,3,3,3,3,3,0,0,0,3,59,0
0,0,4,152,0,0,0,152,152,152,152,152,152,152,0,0,0,152,4,0
0,0,0,0,0,0,0,0,0,0,0,0,0,0,0,0,0,0,0,0
0,0,0,0,0,0,0,0,0,0,0,0,0,0,0,0,0,0,0,0
0,0,0,0,0,0,0,0,0,0,0,0,0,0,0,0,0,0,0,0
0,0,0,0,0,0,0,0,0,0,0,0,0,0,0,0,0,0,0,0
0,0,0,0,0,0,0,0,0,0,0,0,0,0,0,0,0,0,0,0
0,0,0,0,0,0,0,0,0,0,0,0,0,0,0,0,0,0,0,0
0,0,0,0,0,0,0,0,0,0,0,0,0,0,0,0,0,0,0,0
0,0,0,0,0,0,0,0,0,0,0,0,0,0,0,0,0,0,0,0
0,0,0,0,0,0,0,0,0,0,0,0,0,0,0,0,0,0,0,0
0,0,0,0,0,0,0,0,0,0,0,0,0,0,0,0,0,0,0,0
0,0,0,0,0,0,0,0,0,0,0,0,0,0,0,0,0,0,0,0
0,0,0,0,0,0,0,0,0,0,0,0,0,0,0,0,0,0,0,0
0,0,0,0,0,0,0,0,0,0,0,0,0,0,0,0,0,0,0,0
0,0,0,0,0,0,0,0,0,0,0,0,0,0,0,0,0,0,0,0
0,0,0,0,0,0,0,0,0,0,0,0,0,0,0,0,0,0,0,0
0,0,0,0,0,0,0,0,0,0,0,0,0,0,0,0,0,0,0,0
:endlayer
layer: 11
0,0,0,0,0,0,0,0,0,0,0,0,0,0,0,0,0,0,0,0
0,0,0,0,0,0,0,0,0,0,0,0,0,0,0,0,0,0,0,0
0,0,0,3,3,189,189,3,4,4,4,4,4,3,189,189,3,3,0,0
0,0,0,3,0,0,0,0,0,0,208,0,0,0,0,0,0,3,0,0
0,0,0,4,0,26,0,0,0,0,0,0,0,0,0,26,0,4,0,0
0,0,0,189,0,0,0,0,0,0,0,0,190,0,0,0,0,189,0,0
0,0,0,189,0,0,0,225,217,0,0,199,191,0,0,0,0,189,0,0
0,0,0,4,0,0,0,0,0,0,209,200,0,0,0,0,0,4,0,0
0,0,0,3,0,0,0,3,0,0,0,0,0,3,0,0,0,3,0,0
0,0,0,4,0,0,0,0,0,0,0,0,0,0,0,0,0,4,0,0
0,0,0,189,0,0,0,0,0,0,0,0,0,0,0,0,0,189,0,0
0,0,0,189,0,0,0,0,0,0,0,0,0,0,0,0,0,189,0,0
0,0,0,4,0,0,0,0,0,0,0,0,0,0,0,0,0,4,0,0
0,0,0,3,0,0,0,3,218,0,0,201,192,3,0,0,0,3,0,0
0,0,0,4,0,0,0,0,0,0,0,0,0,0,0,0,0,4,0,0
0,0,0,189,0,0,0,0,219,210,0,202,193,0,0,0,0,189,0,0
0,0,0,189,0,0,0,0,0,0,0,0,0,0,0,0,0,189,0,0
0,0,0,4,0,0,0,0,220,211,0,203,194,0,0,0,0,4,0,0
0,0,0,3,0,0,0,3,0,0,0,0,0,3,0,0,0,3,0,0
0,0,0,4,0,0,0,0,221,212,0,204,195,0,0,0,0,4,0,0
0,0,0,189,0,0,0,0,0,0,0,0,0,0,0,0,0,189,0,0
0,0,0,189,0,0,0,0,222,213,0,205,196,0,0,0,0,189,0,0
0,0,0,4,0,0,0,0,0,0,0,0,0,0,0,0,0,4,0,0
0,0,0,3,0,0,0,3,223,214,0,206,197,3,0,0,0,3,0,0
0,0,0,4,0,0,0,0,0,0,0,0,0,0,0,0,0,4,0,0
0,0,0,189,0,0,0,0,0,215,0,207,198,0,0,0,0,189,0,0
0,0,0,189,0,0,0,0,0,0,0,0,0,0,0,0,0,189,0,0
0,0,0,4,0,0,0,0,224,216,0,0,0,0,0,0,0,4,0,0
0,0,0,3,0,0,0,3,0,0,0,0,0,3,0,0,0,3,0,0
0,0,0,4,0,0,0,0,0,0,0,0,0,0,0,0,0,4,0,0
0,0,0,189,0,0,0,0,0,0,0,0,0,0,0,0,0,189,0,0
0,0,0,189,0,0,0,0,0,0,0,0,0,0,0,0,0,189,0,0
0,0,0,4,0,0,0,0,0,0,0,0,0,0,0,0,0,4,0,0
0,0,0,3,0,0,0,3,0,0,0,0,0,3,0,0,0,3,0,0
0,0,0,4,0,0,0,0,0,0,45,44,0,0,0,0,0,4,0,0
0,0,0,189,0,0,0,0,0,0,3,0,0,0,0,0,0,189,0,0
0,0,0,189,0,0,0,0,0,0,3,0,0,0,0,0,0,189,0,0
0,0,0,4,0,0,0,0,0,0,0,0,0,0,0,0,0,4,0,0
0,0,0,3,0,0,0,3,0,0,0,0,0,3,0,0,0,3,0,0
0,0,0,4,0,0,0,0,0,0,0,0,0,0,0,0,0,4,0,0
0,0,0,189,0,0,0,0,0,0,0,0,0,0,0,0,0,189,0,0
0,0,0,189,0,0,0,0,0,0,0,0,0,0,0,0,0,189,0,0
0,0,0,4,0,0,0,0,0,0,0,0,0,0,0,0,0,4,0,0
0,0,0,3,0,0,0,0,0,0,0,0,0,0,0,0,0,3,0,0
0,0,0,3,0,0,0,3,4,3,189,3,4,3,0,0,0,3,0,0
0,0,0,0,0,0,0,0,0,0,0,0,0,0,0,0,0,0,0,0
0,0,0,0,0,0,0,0,0,0,0,0,0,0,0,0,0,0,0,0
0,0,0,0,0,0,0,0,0,0,0,0,0,0,0,0,0,0,0,0
0,0,0,0,0,0,0,0,0,0,0,0,0,0,0,0,0,0,0,0
0,0,0,0,0,0,0,0,0,0,0,0,0,0,0,0,0,0,0,0
0,0,0,0,0,0,0,0,0,0,0,0,0,0,0,0,0,0,0,0
0,0,0,0,0,0,0,0,0,0,0,0,0,0,0,0,0,0,0,0
0,0,0,0,0,0,0,0,0,0,0,0,0,0,0,0,0,0,0,0
0,0,0,0,0,0,0,0,0,0,0,0,0,0,0,0,0,0,0,0
0,0,0,0,0,0,0,0,0,0,0,0,0,0,0,0,0,0,0,0
0,0,0,0,0,0,0,0,0,0,0,0,0,0,0,0,0,0,0,0
0,0,0,0,0,0,0,0,0,0,0,0,0,0,0,0,0,0,0,0
0,0,0,0,0,0,0,0,0,0,0,0,0,0,0,0,0,0,0,0
0,0,0,0,0,0,0,0,0,0,0,0,0,0,0,0,0,0,0,0
0,0,0,0,0,0,0,0,0,0,0,0,0,0,0,0,0,0,0,0
0,0,0,0,0,0,0,0,0,0,0,0,0,0,0,0,0,0,0,0
0,0,0,0,0,0,0,0,0,0,0,0,0,0,0,0,0,0,0,0
:endlayer
layer: 12
0,0,0,0,0,0,0,0,0,0,0,0,0,0,0,0,0,0,0,0
0,0,0,0,0,0,0,0,0,0,0,0,0,0,0,0,0,0,0,0
0,0,0,3,3,189,189,3,4,189,189,189,4,3,189,189,3,3,0,0
0,0,0,3,0,0,0,0,0,0,0,0,0,0,0,0,0,3,0,0
0,0,0,4,0,26,0,0,0,0,0,0,0,0,0,26,0,4,0,0
0,0,0,189,0,0,0,0,0,0,0,0,227,0,0,0,0,189,0,0
0,0,0,189,0,0,0,233,232,0,0,230,228,0,0,0,0,189,0,0
0,0,0,4,0,0,0,0,0,0,0,231,229,226,0,0,0,4,0,0
0,0,0,3,0,0,64,3,0,0,0,0,0,3,57,0,0,3,0,0
0,0,0,4,0,0,0,0,0,0,0,0,0,0,0,0,0,4,0,0
0,0,0,189,0,0,0,0,0,0,0,0,0,0,0,0,0,189,0,0
0,0,0,189,0,0,0,0,0,0,0,0,0,0,0,0,0,189,0,0
0,0,0,4,0,0,0,0,0,0,0,0,0,0,0,0,0,4,0,0
0,0,0,3,0,0,64,3,0,0,0,0,0,3,57,0,0,3,0,0
0,0,0,4,0,0,0,0,0,0,0,0,0,0,0,0,0,4,0,0
0,0,0,189,0,0,0,0,0,0,0,0,0,0,0,0,0,189,0,0
0,0,0,189,0,0,0,0,0,0,0,0,0,0,0,0,0,189,0,0
0,0,0,4,0,0,0,0,0,0,0,0,0,0,0,0,0,4,0,0
0,0,0,3,0,0,64,3,0,0,0,0,0,3,57,0,0,3,0,0
0,0,0,4,0,0,0,0,0,0,0,0,0,0,0,0,0,4,0,0
0,0,0,189,0,0,0,0,0,0,0,0,0,0,0,0,0,189,0,0
0,0,0,189,0,0,0,0,0,0,0,0,0,0,0,0,0,189,0,0
0,0,0,4,0,0,0,0,0,0,0,0,0,0,0,0,0,4,0,0
0,0,0,3,0,0,64,3,0,0,0,0,0,3,57,0,0,3,0,0
0,0,0,4,0,0,0,0,0,0,0,0,0,0,0,0,0,4,0,0
0,0,0,189,0,0,0,0,0,0,0,0,0,0,0,0,0,189,0,0
0,0,0,189,0,0,0,0,0,0,0,0,0,0,0,0,0,189,0,0
0,0,0,4,0,0,0,0,0,0,0,0,0,0,0,0,0,4,0,0
0,0,0,3,0,0,64,3,0,0,0,0,0,3,57,0,0,3,0,0
0,0,0,4,0,0,0,0,0,0,0,0,0,0,0,0,0,4,0,0
0,0,0,189,0,0,0,0,0,0,0,0,0,0,0,0,0,189,0,0
0,0,0,189,0,0,0,0,0,0,0,0,0,0,0,0,0,189,0,0
0,0,0,4,0,0,0,0,0,0,0,0,0,0,0,0,0,4,0,0
0,0,0,3,0,0,0,3,0,0,0,0,0,3,57,0,0,3,0,0
0,0,0,4,0,0,0,0,0,44,0,0,0,0,0,0,0,4,0,0
0,0,0,189,0,0,0,0,0,45,3,0,0,0,0,0,0,189,0,0
0,0,0,189,0,0,0,0,0,0,3,0,0,0,0,0,0,189,0,0
0,0,0,4,0,0,0,0,0,0,0,0,0,0,0,0,0,4,0,0
0,0,0,3,0,0,0,3,0,0,0,0,0,3,57,0,0,3,0,0
0,0,0,4,0,0,0,0,0,0,0,0,0,0,0,0,0,4,0,0
0,0,0,189,0,0,0,0,0,0,0,0,0,0,0,0,0,189,0,0
0,0,0,189,0,0,0,0,0,0,0,0,0,0,0,0,0,189,0,0
0,0,0,4,0,0,0,0,0,0,0,0,0,0,0,0,0,4,0,0
0,0,0,3,0,0,0,0,0,0,0,0,0,0,0,0,0,3,0,0
0,0,0,3,0,0,0,3,4,3,189,3,4,3,0,0,0,3,0,0
0,0,0,58,0,0,0,58,0,0,0,0,0,58,0,0,0,58,0,0
0,0,0,0,0,0,0,0,0,0,0,0,0,0,0,0,0,0,0,0
0,0,0,0,0,0,0,0,0,0,0,0,0,0,0,0,0,0,0,0
0,0,0,0,0,0,0,0,0,0,0,0,0,0,0,0,0,0,0,0
0,0,0,0,0,0,0,0,0,0,0,0,0,0,0,0,0,0,0,0
0,0,0,0,0,0,0,0,0,0,0,0,0,0,0,0,0,0,0,0
0,0,0,0,0,0,0,0,0,0,0,0,0,0,0,0,0,0,0,0
0,0,0,0,0,0,0,0,0,0,0,0,0,0,0,0,0,0,0,0
0,0,0,0,0,0,0,0,0,0,0,0,0,0,0,0,0,0,0,0
0,0,0,0,0,0,0,0,0,0,0,0,0,0,0,0,0,0,0,0
0,0,0,0,0,0,0,0,0,0,0,0,0,0,0,0,0,0,0,0
0,0,0,0,0,0,0,0,0,0,0,0,0,0,0,0,0,0,0,0
0,0,0,0,0,0,0,0,0,0,0,0,0,0,0,0,0,0,0,0
0,0,0,0,0,0,0,0,0,0,0,0,0,0,0,0,0,0,0,0
0,0,0,0,0,0,0,0,0,0,0,0,0,0,0,0,0,0,0,0
0,0,0,0,0,0,0,0,0,0,0,0,0,0,0,0,0,0,0,0
0,0,0,0,0,0,0,0,0,0,0,0,0,0,0,0,0,0,0,0
:endlayer
layer: 13
0,0,0,0,0,0,0,0,0,0,0,0,0,0,0,0,0,0,0,0
0,0,0,0,0,0,0,0,0,0,0,0,0,0,0,0,0,0,0,0
0,0,0,3,3,189,189,3,4,189,189,189,4,3,189,189,3,3,0,0
0,0,0,3,0,0,0,0,0,0,0,0,0,0,0,0,0,3,0,0
0,0,0,4,0,26,0,0,0,0,0,0,0,0,0,26,0,4,0,0
0,0,0,189,0,0,0,0,0,0,0,0,0,0,0,0,0,189,0,0
0,0,0,189,0,0,0,0,0,0,0,0,0,0,0,0,0,189,0,0
0,0,0,4,0,0,0,0,0,0,0,0,0,0,0,0,0,4,0,0
0,0,0,3,0,0,0,3,0,0,0,0,0,3,0,0,0,3,0,0
0,0,0,4,0,0,0,0,0,0,0,0,0,0,0,0,0,4,0,0
0,0,0,189,0,0,0,0,0,0,0,0,0,0,0,0,0,189,0,0
0,0,0,189,0,0,0,0,0,0,0,0,0,0,0,0,0,189,0,0
0,0,0,4,0,0,0,0,0,0,0,0,0,0,0,0,0,4,0,0
0,0,0,3,0,0,0,3,0,0,0,0,0,3,0,0,0,3,0,0
0,0,0,4,0,0,0,0,0,0,0,0,0,0,0,0,0,4,0,0
0,0,0,189,0,0,0,0,0,0,0,0,0,0,0,0,0,189,0,0
0,0,0,189,0,0,0,0,0,0,0,0,0,0,0,0,0,189,0,0
0,0,0,4,0,0,0,0,0,0,0,0,0,0,0,0,0,4,0,0
0,0,0,3,0,0,0,3,0,0,0,0,0,3,0,0,0,3,0,0
0,0,0,4,0,0,0,0,0,0,0,0,0,0,0,0,0,4,0,0
0,0,0,189,0,0,0,0,0,0,0,0,0,0,0,0,0,189,0,0
0,0,0,189,0,0,0,0,0,0,0,0,0,0,0,0,0,189,0,0
0,0,0,4,0,0,0,0,0,0,0,0,0,0,0,0,0,4,0,0
0,0,0,3,0,0,0,3,0,0,0,0,0,3,0,0,0,3,0,0
0,0,0,4,0,0,0,0,0,0,0,0,0,0,0,0,0,4,0,0
0,0,0,189,0,0,0,0,0,0,0,0,0,0,0,0,0,189,0,0
0,0,0,189,0,0,0,0,0,0,0,0,0,0,0,0,0,189,0,0
0,0,0,4,0,0,0,0,0,0,0,0,0,0,0,0,0,4,0,0
0,0,0,3,0,0,0,3,0,0,0,0,0,3,0,0,0,3,0,0
0,0,0,4,0,0,0,0,0,0,0,0,0,0,0,0,0,4,0,0
0,0,0,189,0,0,0,0,0,0,0,0,0,0,0,0,0,189,0,0
0,0,0,189,0,0,0,0,0,0,0,0,0,0,0,0,0,189,0,0
0,0,0,4,0,0,0,0,0,0,0,0,0,0,0,0,0,4,0,0
0,0,0,3,0,0,0,3,0,0,0,0,0,3,0,0,0,3,0,0
0,0,0,4,0,0,0,0,0,0,0,0,0,0,0,0,0,4,0,0
0,0,0,189,0,0,0,0,0,0,3,0,0,0,0,0,0,189,0,0
0,0,0,189,0,0,0,0,0,44,3,0,0,0,0,0,0,189,0,0
0,0,0,4,0,0,0,0,0,45,0,0,0,0,0,0,0,4,0,0
0,0,0,3,0,0,0,3,0,0,0,0,0,3,0,0,0,3,0,0
0,0,0,4,0,0,0,0,0,0,0,0,0,0,0,0,0,4,0,0
0,0,0,189,0,0,0,0,0,0,0,0,0,0,0,0,0,189,0,0
0,0,0,189,0,0,0,0,0,0,0,0,0,0,0,0,0,189,0,0
0,0,0,4,0,0,0,0,0,0,0,0,0,0,0,0,0,4,0,0
0,0,0,3,0,0,0,0,0,0,0,0,0,0,0,0,0,3,0,0
0,0,0,3,9,0,53,3,4,3,189,3,4,3,9,0,53,3,0,0
0,0,0,0,0,0,0,0,0,0,0,0,0,0,0,0,0,0,0,0
0,0,0,0,0,0,0,0,0,0,0,0,0,0,0,0,0,0,0,0
0,0,0,0,0,0,0,0,0,0,0,0,0,0,0,0,0,0,0,0
0,0,0,0,0,0,0,0,0,0,0,0,0,0,0,0,0,0,0,0
0,0,0,0,0,0,0,0,0,0,0,0,0,0,0,0,0,0,0,0
0,0,0,0,0,0,0,0,0,0,0,0,0,0,0,0,0,0,0,0
0,0,0,0,0,0,0,0,0,0,0,0,0,0,0,0,0,0,0,0
0,0,0,0,0,0,0,0,0,0,0,0,0,0,0,0,0,0,0,0
0,0,0,0,0,0,0,0,0,0,0,0,0,0,0,0,0,0,0,0
0,0,0,0,0,0,0,0,0,0,0,0,0,0,0,0,0,0,0,0
0,0,0,0,0,0,0,0,0,0,0,0,0,0,0,0,0,0,0,0
0,0,0,0,0,0,0,0,0,0,0,0,0,0,0,0,0,0,0,0
0,0,0,0,0,0,0,0,0,0,0,0,0,0,0,0,0,0,0,0
0,0,0,0,0,0,0,0,0,0,0,0,0,0,0,0,0,0,0,0
0,0,0,0,0,0,0,0,0,0,0,0,0,0,0,0,0,0,0,0
0,0,0,0,0,0,0,0,0,0,0,0,0,0,0,0,0,0,0,0
0,0,0,0,0,0,0,0,0,0,0,0,0,0,0,0,0,0,0,0
:endlayer
layer: 14
0,0,0,0,0,0,0,0,0,0,0,0,0,0,0,0,0,0,0,0
0,0,0,0,0,0,0,0,0,0,0,0,0,0,0,0,0,0,0,0
0,0,0,3,3,189,189,3,4,189,189,189,4,3,189,189,3,3,0,0
0,0,0,3,0,0,0,67,0,0,0,0,0,67,0,0,0,3,0,0
0,0,0,4,66,66,66,67,0,0,0,0,0,67,66,67,0,4,0,0
0,0,0,189,0,67,65,67,0,0,0,0,0,67,65,67,0,189,0,0
0,0,0,189,0,67,65,67,0,0,0,0,0,67,65,67,0,189,0,0
0,0,0,4,66,67,65,67,0,0,0,0,0,67,65,67,66,4,0,0
0,0,0,3,65,67,66,3,0,0,0,0,0,3,65,67,65,3,0,0
0,0,0,4,66,67,65,67,0,0,0,0,0,67,65,67,66,4,0,0
0,0,0,189,0,67,65,67,0,0,0,0,0,67,65,67,0,189,0,0
0,0,0,189,0,67,65,67,0,0,0,0,0,67,65,67,0,189,0,0
0,0,0,4,66,67,65,67,0,0,0,0,0,67,65,67,66,4,0,0
0,0,0,3,65,67,65,3,65,67,0,67,65,3,65,67,65,3,0,0
0,0,0,4,66,67,65,67,65,67,0,67,65,67,65,67,66,4,0,0
0,0,0,189,0,67,65,67,65,67,0,67,65,67,65,67,0,189,0,0
0,0,0,189,0,67,65,67,65,67,0,67,65,67,65,67,0,189,0,0
0,0,0,4,66,67,65,67,65,67,0,67,65,67,65,67,66,4,0,0
0,0,0,3,65,67,65,3,65,67,0,67,65,3,65,67,65,3,0,0
0,0,0,4,66,67,65,67,65,67,0,67,65,67,65,67,66,4,0,0
0,0,0,189,0,67,65,67,65,67,0,67,65,67,65,67,0,189,0,0
0,0,0,189,0,67,65,67,65,67,0,67,65,67,65,67,0,189,0,0
0,0,0,4,66,67,65,67,65,67,0,67,65,67,65,67,66,4,0,0
0,0,0,3,65,67,65,3,65,67,0,67,65,3,65,67,65,3,0,0
0,0,0,4,66,67,65,67,65,67,0,67,65,67,65,67,66,4,0,0
0,0,0,189,0,67,65,67,65,67,0,67,65,67,65,67,0,189,0,0
0,0,0,189,0,67,65,67,65,67,0,67,65,67,65,67,0,189,0,0
0,0,0,4,66,67,65,67,65,67,0,67,65,67,65,67,66,4,0,0
0,0,0,3,65,67,65,3,65,67,0,67,65,3,65,67,65,3,0,0
0,0,0,4,66,67,65,67,65,67,0,67,65,67,65,67,66,4,0,0
0,0,0,189,0,67,65,67,65,67,0,67,65,67,65,67,0,189,0,0
0,0,0,189,0,67,65,67,65,67,0,67,65,67,65,67,0,189,0,0
0,0,0,4,66,67,65,67,65,67,0,67,65,67,65,67,66,4,0,0
0,0,0,3,65,67,65,3,66,66,66,66,66,3,65,67,65,3,0,0
0,0,0,4,66,67,65,67,65,0,0,0,65,67,65,67,66,4,0,0
0,0,0,189,0,67,65,67,65,0,3,0,65,67,65,67,0,189,0,0
0,0,0,189,0,67,65,67,65,0,3,0,65,67,65,67,0,189,0,0
0,0,0,4,66,67,65,67,65,0,44,45,65,67,65,67,66,4,0,0
0,0,0,3,65,67,65,3,66,66,66,66,66,3,65,67,65,3,0,0
0,0,0,4,66,67,65,67,0,0,0,0,0,67,65,67,66,4,0,0
0,0,0,189,0,67,65,67,0,0,0,0,0,67,65,67,0,189,0,0
0,0,0,189,0,67,65,67,0,0,0,0,0,67,65,67,0,189,0,0
0,0,0,4,66,66,66,67,0,0,0,0,0,67,66,66,66,4,0,0
0,0,0,3,0,0,0,67,0,0,0,0,0,67,0,0,0,3,0,0
0,0,0,4,3,18,3,3,4,3,189,3,4,3,3,18,3,4,0,0
0,0,0,0,0,0,0,0,0,0,0,0,0,0,0,0,0,0,0,0
0,0,0,0,0,0,0,0,0,0,0,0,0,0,0,0,0,0,0,0
0,0,0,0,0,0,0,0,0,0,0,0,0,0,0,0,0,0,0,0
0,0,0,0,0,0,0,0,0,0,0,0,0,0,0,0,0,0,0,0
0,0,0,0,0,0,0,0,0,0,0,0,0,0,0,0,0,0,0,0
0,0,0,0,0,0,0,0,0,0,0,0,0,0,0,0,0,0,0,0
0,0,0,0,0,0,0,0,0,0,0,0,0,0,0,0,0,0,0,0
0,0,0,0,0,0,0,0,0,0,0,0,0,0,0,0,0,0,0,0
0,0,0,0,0,0,0,0,0,0,0,0,0,0,0,0,0,0,0,0
0,0,0,0,0,0,0,0,0,0,0,0,0,0,0,0,0,0,0,0
0,0,0,0,0,0,0,0,0,0,0,0,0,0,0,0,0,0,0,0
0,0,0,0,0,0,0,0,0,0,0,0,0,0,0,0,0,0,0,0
0,0,0,0,0,0,0,0,0,0,0,0,0,0,0,0,0,0,0,0
0,0,0,0,0,0,0,0,0,0,0,0,0,0,0,0,0,0,0,0
0,0,0,0,0,0,0,0,0,0,0,0,0,0,0,0,0,0,0,0
0,0,0,0,0,0,0,0,0,0,0,0,0,0,0,0,0,0,0,0
0,0,0,0,0,0,0,0,0,0,0,0,0,0,0,0,0,0,0,0
:endlayer
layer: 15
0,0,0,0,0,0,0,0,0,0,0,0,0,0,0,0,0,0,0,0
0,0,0,0,0,0,0,0,0,0,0,0,0,0,0,0,0,0,0,0
0,0,0,3,3,189,189,3,4,189,189,189,4,3,189,189,3,3,0,0
0,0,0,3,0,0,0,0,0,0,0,0,0,0,0,0,0,3,0,0
0,0,0,4,0,367,365,349,0,0,0,0,0,282,280,248,0,4,0,0
0,0,0,189,0,368,0,350,0,0,0,0,0,283,0,249,0,189,0,0
0,0,0,189,0,369,0,351,0,0,0,0,0,284,0,250,0,189,0,0
0,0,0,4,399,370,0,352,0,0,0,0,0,285,0,251,234,4,0,0
0,0,0,3,0,0,0,3,57,0,0,0,64,3,0,0,0,3,0,0
0,0,0,4,400,371,0,353,0,0,0,0,0,286,0,252,235,4,0,0
0,0,0,189,0,372,0,354,0,0,0,0,0,287,0,253,0,189,0,0
0,0,0,189,0,373,0,355,0,0,0,0,0,288,0,254,0,189,0,0
0,0,0,4,401,374,0,356,0,0,0,0,0,289,0,255,236,4,0,0
0,0,0,3,0,0,0,3,346,26,0,26,299,3,0,0,0,3,0,0
0,0,0,4,402,375,0,0,0,325,0,302,0,0,0,256,237,4,0,0
0,0,0,189,0,376,0,0,0,326,0,303,0,0,0,257,0,189,0,0
0,0,0,189,0,377,0,0,0,327,0,304,0,0,0,258,0,189,0,0
0,0,0,4,403,378,0,0,0,328,0,305,0,290,0,259,238,4,0,0
0,0,0,3,0,0,0,3,0,329,0,306,0,3,0,0,0,3,0,0
0,0,0,4,404,379,0,0,0,330,0,307,0,0,0,260,239,4,0,0
0,0,0,189,0,380,0,0,0,331,0,308,0,0,0,261,0,189,0,0
0,0,0,189,0,381,0,0,0,332,0,309,0,0,0,262,0,189,0,0
0,0,0,4,405,382,0,0,0,333,0,310,0,0,0,263,240,4,0,0
0,0,0,3,0,0,0,3,0,334,0,311,0,3,0,0,0,3,0,0
0,0,0,4,406,383,0,0,0,335,0,312,0,0,0,264,241,4,0,0
0,0,0,189,0,384,0,0,0,336,0,313,0,0,0,265,0,189,0,0
0,0,0,189,0,385,0,0,0,337,0,314,0,0,0,266,0,189,0,0
0,0,0,4,407,386,0,0,0,338,0,315,0,0,0,267,242,4,0,0
0,0,0,3,0,0,0,3,0,339,0,316,0,3,0,0,0,3,0,0
0,0,0,4,408,387,0,0,0,340,0,317,0,291,0,268,243,4,0,0
0,0,0,189,0,388,0,0,0,341,0,318,0,292,0,269,0,189,0,0
0,0,0,189,0,389,0,0,0,342,0,319,0,293,0,270,0,189,0,0
0,0,0,4,409,390,0,0,0,343,0,320,0,294,0,271,244,4,0,0
0,0,0,3,0,0,0,3,347,344,323,321,300,3,0,0,0,3,0,0
0,0,0,4,410,391,0,357,0,0,0,0,0,0,0,272,245,4,0,0
0,0,0,189,0,392,0,358,0,0,3,45,0,0,0,273,0,189,0,0
0,0,0,189,0,393,0,359,0,0,3,44,0,0,0,274,0,189,0,0
0,0,0,4,411,394,0,360,0,0,0,0,0,0,0,275,246,4,0,0
0,0,0,3,0,0,0,3,348,345,324,322,301,3,0,0,0,3,0,0
0,0,0,4,412,395,0,361,0,0,0,0,0,295,0,276,247,4,0,0
0,0,0,189,0,396,0,362,0,0,0,0,0,296,0,277,0,189,0,0
0,0,0,189,0,397,0,363,0,0,0,0,0,297,0,278,0,189,0,0
0,0,0,4,0,398,366,364,0,0,0,0,0,298,281,279,0,4,0,0
0,0,0,3,0,0,0,0,0,0,0,0,0,0,0,0,0,3,0,0
0,0,0,4,4,3,4,3,4,4,3,4,4,3,4,3,4,4,0,0
0,0,0,0,0,0,0,0,0,0,0,0,0,0,0,0,0,0,0,0
0,0,0,0,0,0,0,0,0,0,0,0,0,0,0,0,0,0,0,0
0,0,0,0,0,0,0,0,0,0,0,0,0,0,0,0,0,0,0,0
0,0,0,0,0,0,0,0,0,0,0,0,0,0,0,0,0,0,0,0
0,0,0,0,0,0,0,0,0,0,0,0,0,0,0,0,0,0,0,0
0,0,0,0,0,0,0,0,0,0,0,0,0,0,0,0,0,0,0,0
0,0,0,0,0,0,0,0,0,0,0,0,0,0,0,0,0,0,0,0
0,0,0,0,0,0,0,0,0,0,0,0,0,0,0,0,0,0,0,0
0,0,0,0,0,0,0,0,0,0,0,0,0,0,0,0,0,0,0,0
0,0,0,0,0,0,0,0,0,0,0,0,0,0,0,0,0,0,0,0
0,0,0,0,0,0,0,0,0,0,0,0,0,0,0,0,0,0,0,0
0,0,0,0,0,0,0,0,0,0,0,0,0,0,0,0,0,0,0,0
0,0,0,0,0,0,0,0,0,0,0,0,0,0,0,0,0,0,0,0
0,0,0,0,0,0,0,0,0,0,0,0,0,0,0,0,0,0,0,0
0,0,0,0,0,0,0,0,0,0,0,0,0,0,0,0,0,0,0,0
0,0,0,0,0,0,0,0,0,0,0,0,0,0,0,0,0,0,0,0
0,0,0,0,0,0,0,0,0,0,0,0,0,0,0,0,0,0,0,0
:endlayer
layer: 16
0,0,0,0,0,0,0,0,0,0,0,0,0,0,0,0,0,0,0,0
0,0,0,0,0,0,0,0,0,0,0,0,0,0,0,0,0,0,0,0
0,0,0,4,4,3,3,3,3,189,189,189,3,3,3,3,4,4,0,0
0,0,0,4,0,0,0,0,0,0,0,0,0,0,0,0,0,4,0,0
0,0,0,3,0,0,0,0,0,0,0,0,0,0,0,0,0,3,0,0
0,0,0,4,0,0,0,0,0,0,0,0,0,0,0,0,0,4,0,0
0,0,0,4,0,0,0,0,0,0,0,0,0,0,0,0,0,4,0,0
0,0,0,3,0,0,0,0,0,0,0,0,0,0,0,0,0,3,0,0
0,0,0,4,0,0,64,3,0,0,0,0,0,3,57,0,0,4,0,0
0,0,0,3,0,0,0,0,0,0,0,0,0,0,0,0,0,3,0,0
0,0,0,4,0,0,0,0,0,0,0,0,0,0,0,0,0,4,0,0
0,0,0,4,0,0,0,0,0,0,0,0,0,0,0,0,0,4,0,0
0,0,0,3,0,0,0,0,0,0,0,0,0,0,0,0,0,3,0,0
0,0,0,4,0,0,64,3,0,26,0,26,0,3,57,0,0,4,0,0
0,0,0,3,0,0,0,0,0,0,0,0,0,0,0,0,0,3,0,0
0,0,0,4,0,0,0,0,0,0,0,0,0,0,0,0,0,4,0,0
0,0,0,4,0,0,0,0,0,0,0,0,0,0,0,0,0,4,0,0
0,0,0,3,0,0,0,0,0,0,0,0,0,0,0,0,0,3,0,0
0,0,0,4,0,0,64,3,0,0,0,0,0,3,57,0,0,4,0,0
0,0,0,3,0,0,0,0,0,0,0,0,0,0,0,0,0,3,0,0
0,0,0,4,0,0,0,0,0,0,0,0,0,0,0,0,0,4,0,0
0,0,0,4,0,0,0,0,0,0,0,0,0,0,0,0,0,4,0,0
0,0,0,3,0,0,0,0,0,0,0,0,0,0,0,0,0,3,0,0
0,0,0,4,0,0,64,3,0,0,0,0,0,3,57,0,0,4,0,0
0,0,0,3,0,0,0,0,0,0,0,0,0,0,0,0,0,3,0,0
0,0,0,4,0,0,0,0,0,0,0,0,0,0,0,0,0,4,0,0
0,0,0,4,0,0,0,0,0,0,0,0,0,0,0,0,0,4,0,0
0,0,0,3,0,0,0,0,0,0,0,0,0,0,0,0,0,3,0,0
0,0,0,4,0,0,64,3,0,0,0,0,0,3,57,0,0,4,0,0
0,0,0,3,0,0,0,0,0,0,0,0,0,0,0,0,0,3,0,0
0,0,0,4,0,0,0,0,0,0,0,0,0,0,0,0,0,4,0,0
0,0,0,4,0,0,0,0,0,0,0,0,0,0,0,0,0,4,0,0
0,0,0,3,0,0,0,0,0,0,0,0,0,0,0,0,0,3,0,0
0,0,0,4,0,0,64,3,0,0,0,0,0,3,57,0,0,4,0,0
0,0,0,3,0,0,0,0,0,0,45,44,0,0,0,0,0,3,0,0
0,0,0,4,0,0,0,0,0,0,3,0,0,0,0,0,0,4,0,0
0,0,0,4,0,0,0,0,0,0,3,0,0,0,0,0,0,4,0,0
0,0,0,3,0,0,0,0,0,0,0,0,0,0,0,0,0,3,0,0
0,0,0,4,0,0,64,3,0,0,0,0,0,3,57,0,0,4,0,0
0,0,0,3,0,0,0,0,0,0,0,0,0,0,0,0,0,3,0,0
0,0,0,4,0,0,0,0,0,0,0,0,0,0,0,0,0,4,0,0
0,0,0,4,0,0,0,0,0,0,0,0,0,0,0,0,0,4,0,0
0,0,0,3,0,0,0,0,0,0,0,0,0,0,0,0,0,3,0,0
0,0,0,4,0,0,0,0,0,0,0,0,0,0,0,0,0,4,0,0
0,0,0,4,152,3,152,152,152,152,4,152,152,152,152,3,152,4,0,0
0,0,0,0,0,0,0,0,0,0,0,0,0,0,0,0,0,0,0,0
0,0,0,0,0,0,0,0,0,0,0,0,0,0,0,0,0,0,0,0
0,0,0,0,0,0,0,0,0,0,0,0,0,0,0,0,0,0,0,0
0,0,0,0,0,0,0,0,0,0,0,0,0,0,0,0,0,0,0,0
0,0,0,0,0,0,0,0,0,0,0,0,0,0,0,0,0,0,0,0
0,0,0,0,0,0,0,0,0,0,0,0,0,0,0,0,0,0,0,0
0,0,0,0,0,0,0,0,0,0,0,0,0,0,0,0,0,0,0,0
0,0,0,0,0,0,0,0,0,0,0,0,0,0,0,0,0,0,0,0
0,0,0,0,0,0,0,0,0,0,0,0,0,0,0,0,0,0,0,0
0,0,0,0,0,0,0,0,0,0,0,0,0,0,0,0,0,0,0,0
0,0,0,0,0,0,0,0,0,0,0,0,0,0,0,0,0,0,0,0
0,0,0,0,0,0,0,0,0,0,0,0,0,0,0,0,0,0,0,0
0,0,0,0,0,0,0,0,0,0,0,0,0,0,0,0,0,0,0,0
0,0,0,0,0,0,0,0,0,0,0,0,0,0,0,0,0,0,0,0
0,0,0,0,0,0,0,0,0,0,0,0,0,0,0,0,0,0,0,0
0,0,0,0,0,0,0,0,0,0,0,0,0,0,0,0,0,0,0,0
0,0,0,0,0,0,0,0,0,0,0,0,0,0,0,0,0,0,0,0
:endlayer
layer: 17
0,0,0,0,0,0,0,0,0,0,0,0,0,0,0,0,0,0,0,0
0,0,0,0,0,0,0,0,0,0,0,0,0,0,0,0,0,0,0,0
0,0,0,4,4,4,4,3,3,189,189,189,3,3,4,4,4,4,0,0
0,0,0,4,0,0,0,0,0,0,0,0,0,0,0,0,0,4,0,0
0,0,0,4,0,0,0,0,0,0,0,0,0,0,0,0,0,4,0,0
0,0,0,3,0,0,0,0,0,0,0,0,0,0,0,0,0,3,0,0
0,0,0,3,0,0,0,0,0,0,0,0,0,0,0,0,0,3,0,0
0,0,0,4,0,0,0,0,0,0,0,0,0,0,0,0,0,4,0,0
0,0,0,4,0,0,0,3,0,0,0,0,0,3,0,0,0,4,0,0
0,0,0,4,0,0,0,0,0,0,0,0,0,0,0,0,0,4,0,0
0,0,0,3,0,0,0,0,0,0,0,0,0,0,0,0,0,3,0,0
0,0,0,3,0,0,0,0,0,0,0,0,0,0,0,0,0,3,0,0
0,0,0,4,0,0,0,0,0,0,0,0,0,0,0,0,0,4,0,0
0,0,0,4,0,0,0,3,0,26,0,26,0,3,0,0,0,4,0,0
0,0,0,4,0,0,0,0,0,0,0,0,0,0,0,0,0,4,0,0
0,0,0,3,0,0,0,0,0,0,0,0,0,0,0,0,0,3,0,0
0,0,0,3,0,0,0,0,0,0,0,0,0,0,0,0,0,3,0,0
0,0,0,4,0,0,0,0,0,0,0,0,0,0,0,0,0,4,0,0
0,0,0,4,0,0,0,3,0,0,0,0,0,3,0,0,0,4,0,0
0,0,0,4,0,0,0,0,0,0,0,0,0,0,0,0,0,4,0,0
0,0,0,3,0,0,0,0,0,0,0,0,0,0,0,0,0,3,0,0
0,0,0,3,0,0,0,0,0,0,0,0,0,0,0,0,0,3,0,0
0,0,0,4,0,0,0,0,0,0,0,0,0,0,0,0,0,4,0,0
0,0,0,4,0,0,0,3,0,0,0,0,0,3,0,0,0,4,0,0
0,0,0,4,0,0,0,0,0,0,0,0,0,0,0,0,0,4,0,0
0,0,0,3,0,0,0,0,0,0,0,0,0,0,0,0,0,3,0,0
0,0,0,3,0,0,0,0,0,0,0,0,0,0,0,0,0,3,0,0
0,0,0,4,0,0,0,0,0,0,0,0,0,0,0,0,0,4,0,0
0,0,0,4,0,0,0,3,0,0,0,0,0,3,0,0,0,4,0,0
0,0,0,4,0,0,0,0,0,0,0,0,0,0,0,0,0,4,0,0
0,0,0,3,0,0,0,0,0,0,0,0,0,0,0,0,0,3,0,0
0,0,0,3,0,0,0,0,0,0,0,0,0,0,0,0,0,3,0,0
0,0,0,4,0,0,0,0,0,0,0,0,0,0,0,0,0,4,0,0
0,0,0,4,0,0,0,3,0,0,0,0,0,3,0,0,0,4,0,0
0,0,0,4,0,0,0,0,0,44,0,0,0,0,0,0,0,4,0,0
0,0,0,3,0,0,0,0,0,45,3,0,0,0,0,0,0,3,0,0
0,0,0,3,0,0,0,0,0,0,3,0,0,0,0,0,0,3,0,0
0,0,0,4,0,0,0,0,0,0,0,0,0,0,0,0,0,4,0,0
0,0,0,4,0,0,0,3,0,0,0,0,0,3,0,0,0,4,0,0
0,0,0,4,0,0,0,0,0,0,0,0,0,0,0,0,0,4,0,0
0,0,0,3,0,0,0,0,0,0,0,0,0,0,0,0,0,3,0,0
0,0,0,3,0,0,0,0,0,0,0,0,0,0,0,0,0,3,0,0
0,0,0,4,0,0,0,0,0,0,0,0,0,0,0,0,0,4,0,0
0,0,0,4,0,0,0,0,0,0,0,0,0,0,0,0,0,4,0,0
0,0,0,4,413,3,413,413,413,413,18,413,413,413,413,3,413,4,0,0
0,0,0,0,0,0,0,0,0,0,0,0,0,0,0,0,0,0,0,0
0,0,0,0,0,0,0,0,0,0,0,0,0,0,0,0,0,0,0,0
0,0,0,0,0,0,0,0,0,0,0,0,0,0,0,0,0,0,0,0
0,0,0,0,0,0,0,0,0,0,0,0,0,0,0,0,0,0,0,0
0,0,0,0,0,0,0,0,0,0,0,0,0,0,0,0,0,0,0,0
0,0,0,0,0,0,0,0,0,0,0,0,0,0,0,0,0,0,0,0
0,0,0,0,0,0,0,0,0,0,0,0,0,0,0,0,0,0,0,0
0,0,0,0,0,0,0,0,0,0,0,0,0,0,0,0,0,0,0,0
0,0,0,0,0,0,0,0,0,0,0,0,0,0,0,0,0,0,0,0
0,0,0,0,0,0,0,0,0,0,0,0,0,0,0,0,0,0,0,0
0,0,0,0,0,0,0,0,0,0,0,0,0,0,0,0,0,0,0,0
0,0,0,0,0,0,0,0,0,0,0,0,0,0,0,0,0,0,0,0
0,0,0,0,0,0,0,0,0,0,0,0,0,0,0,0,0,0,0,0
0,0,0,0,0,0,0,0,0,0,0,0,0,0,0,0,0,0,0,0
0,0,0,0,0,0,0,0,0,0,0,0,0,0,0,0,0,0,0,0
0,0,0,0,0,0,0,0,0,0,0,0,0,0,0,0,0,0,0,0
0,0,0,0,0,0,0,0,0,0,0,0,0,0,0,0,0,0,0,0
:endlayer
layer: 18
0,0,0,0,0,0,0,0,0,0,0,0,0,0,0,0,0,0,0,0
0,0,0,0,0,0,0,0,0,0,0,0,0,0,0,0,0,0,0,0
0,0,0,14,3,4,4,3,3,189,189,189,3,3,4,4,3,13,0,0
0,0,0,63,65,0,0,0,0,0,0,0,0,0,0,0,65,59,0,0
0,0,0,63,65,0,0,0,0,0,0,0,0,0,0,0,65,59,0,0
0,0,0,63,65,0,0,0,0,0,0,0,0,0,0,0,65,59,0,0
0,0,0,63,65,0,0,0,0,0,0,0,0,0,0,0,65,59,0,0
0,0,0,63,65,0,0,0,0,0,0,0,0,0,0,0,65,59,0,0
0,0,0,14,3,0,0,3,0,0,0,0,0,3,0,0,3,13,0,0
0,0,0,63,65,0,0,0,0,0,0,0,0,0,0,0,65,59,0,0
0,0,0,63,65,0,0,0,0,0,0,0,0,0,0,0,65,59,0,0
0,0,0,63,65,0,0,0,0,0,0,0,0,0,0,0,65,59,0,0
0,0,0,63,65,0,0,0,0,414,0,414,0,0,0,0,65,59,0,0
0,0,0,14,3,0,0,3,0,26,0,26,0,3,0,0,3,13,0,0
0,0,0,63,65,0,0,0,0,0,0,0,0,0,0,0,65,59,0,0
0,0,0,63,65,0,0,0,0,0,0,0,0,0,0,0,65,59,0,0
0,0,0,63,65,0,0,0,0,0,0,0,0,0,0,0,65,59,0,0
0,0,0,63,65,0,0,0,0,0,0,0,0,0,0,0,65,59,0,0
0,0,0,14,3,0,0,3,57,0,0,0,64,3,0,0,3,13,0,0
0,0,0,63,65,0,0,0,0,0,0,0,0,0,0,0,65,59,0,0
0,0,0,63,65,0,0,0,0,0,0,0,0,0,0,0,65,59,0,0
0,0,0,63,65,0,0,0,0,0,0,0,0,0,0,0,65,59,0,0
0,0,0,63,65,0,0,0,0,0,0,0,0,0,0,0,65,59,0,0
0,0,0,14,3,0,0,3,57,0,0,0,64,3,0,0,3,13,0,0
0,0,0,63,65,0,0,0,0,0,0,0,0,0,0,0,65,59,0,0
0,0,0,63,65,0,0,0,0,0,0,0,0,0,0,0,65,59,0,0
0,0,0,63,65,0,0,0,0,0,0,0,0,0,0,0,65,59,0,0
0,0,0,63,65,0,0,0,0,0,0,0,0,0,0,0,65,59,0,0
0,0,0,14,3,0,0,3,57,0,0,0,64,3,0,0,3,13,0,0
0,0,0,63,65,0,0,0,0,0,0,0,0,0,0,0,65,59,0,0
0,0,0,63,65,0,0,0,0,0,0,0,0,0,0,0,65,59,0,0
0,0,0,63,65,0,0,0,0,0,0,0,0,0,0,0,65,59,0,0
0,0,0,63,65,0,0,0,0,0,0,0,0,0,0,0,65,59,0,0
0,0,0,14,3,0,0,3,0,0,0,0,64,3,0,0,3,13,0,0
0,0,0,63,65,0,0,58,0,0,0,0,0,0,0,0,65,59,0,0
0,0,0,63,65,0,0,0,0,0,3,0,0,0,0,0,65,59,0,0
0,0,0,63,65,0,0,0,0,44,3,0,0,0,0,0,65,59,0,0
0,0,0,63,65,0,0,0,0,45,0,0,0,0,0,0,65,59,0,0
0,0,0,14,3,0,0,3,57,0,0,0,64,3,0,0,3,13,0,0
0,0,0,63,65,0,0,0,0,0,0,0,0,0,0,0,65,59,0,0
0,0,0,63,65,0,0,0,0,0,0,0,0,0,0,0,65,59,0,0
0,0,0,63,65,0,0,0,0,0,0,0,0,0,0,0,65,59,0,0
0,0,0,63,65,0,0,0,0,0,0,0,0,0,0,0,65,59,0,0
0,0,0,63,65,0,0,0,0,0,0,0,0,0,0,0,65,59,0,0
0,0,0,14,3,4,16,3,16,4,3,4,16,3,16,4,3,13,0,0
0,0,0,0,0,0,0,0,0,0,0,0,0,0,0,0,0,0,0,0
0,0,0,0,0,0,0,0,0,0,0,0,0,0,0,0,0,0,0,0
0,0,0,0,0,0,0,0,0,0,0,0,0,0,0,0,0,0,0,0
0,0,0,0,0,0,0,0,0,0,0,0,0,0,0,0,0,0,0,0
0,0,0,0,0,0,0,0,0,0,0,0,0,0,0,0,0,0,0,0
0,0,0,0,0,0,0,0,0,0,0,0,0,0,0,0,0,0,0,0
0,0,0,0,0,0,0,0,0,0,0,0,0,0,0,0,0,0,0,0
0,0,0,0,0,0,0,0,0,0,0,0,0,0,0,0,0,0,0,0
0,0,0,0,0,0,0,0,0,0,0,0,0,0,0,0,0,0,0,0
0,0,0,0,0,0,0,0,0,0,0,0,0,0,0,0,0,0,0,0
0,0,0,0,0,0,0,0,0,0,0,0,0,0,0,0,0,0,0,0
0,0,0,0,0,0,0,0,0,0,0,0,0,0,0,0,0,0,0,0
0,0,0,0,0,0,0,0,0,0,0,0,0,0,0,0,0,0,0,0
0,0,0,0,0,0,0,0,0,0,0,0,0,0,0,0,0,0,0,0
0,0,0,0,0,0,0,0,0,0,0,0,0,0,0,0,0,0,0,0
0,0,0,0,0,0,0,0,0,0,0,0,0,0,0,0,0,0,0,0
0,0,0,0,0,0,0,0,0,0,0,0,0,0,0,0,0,0,0,0
:endlayer
layer: 19
0,0,0,0,0,0,0,0,0,0,0,0,0,0,0,0,0,0,0,0
0,0,0,0,0,0,0,0,0,0,0,0,0,0,0,0,0,0,0,0
0,0,0,0,14,3,4,3,4,189,189,189,4,3,4,3,13,0,0,0
0,0,0,0,63,65,0,0,0,0,0,0,0,0,0,65,59,0,0,0
0,0,0,0,63,65,0,0,0,0,0,0,0,0,0,65,59,0,0,0
0,0,0,0,63,65,0,0,0,0,0,0,0,0,0,65,59,0,0,0
0,0,0,0,63,65,0,0,0,0,0,0,0,0,0,65,59,0,0,0
0,0,0,0,63,65,0,0,0,0,0,0,0,0,0,65,59,0,0,0
0,0,0,0,14,3,0,3,0,0,0,0,0,3,0,3,13,0,0,0
0,0,0,0,63,65,0,0,0,0,0,0,0,0,0,65,59,0,0,0
0,0,0,0,63,65,0,0,0,0,0,0,0,0,0,65,59,0,0,0
0,0,0,0,63,65,0,0,0,0,0,0,0,0,0,65,59,0,0,0
0,0,0,0,63,65,0,0,0,0,0,0,0,0,0,65,59,0,0,0
0,0,0,0,14,3,0,3,0,26,0,26,0,3,0,3,13,0,0,0
0,0,0,0,63,65,0,0,0,0,0,0,0,0,0,65,59,0,0,0
0,0,0,0,63,65,0,0,0,0,0,0,0,0,0,65,59,0,0,0
0,0,0,0,63,65,0,0,0,0,0,0,0,0,0,65,59,0,0,0
0,0,0,0,63,65,0,0,0,0,0,0,0,0,0,65,59,0,0,0
0,0,0,0,14,3,0,3,0,0,0,0,0,3,0,3,13,0,0,0
0,0,0,0,63,65,0,0,0,0,0,0,0,0,0,65,59,0,0,0
0,0,0,0,63,65,0,0,0,0,0,0,0,0,0,65,59,0,0,0
0,0,0,0,63,65,0,0,0,0,0,0,0,0,0,65,59,0,0,0
0,0,0,0,63,65,0,0,0,0,0,0,0,0,0,65,59,0,0,0
0,0,0,0,14,3,0,3,0,0,0,0,0,3,0,3,13,0,0,0
0,0,0,0,63,65,0,0,0,0,0,0,0,0,0,65,59,0,0,0
0,0,0,0,63,65,0,0,0,0,0,0,0,0,0,65,59,0,0,0
0,0,0,0,63,65,0,0,0,0,0,0,0,0,0,65,59,0,0,0
0,0,0,0,63,65,0,0,0,0,0,0,0,0,0,65,59,0,0,0
0,0,0,0,14,3,0,3,0,0,0,0,0,3,0,3,13,0,0,0
0,0,0,0,63,65,0,0,0,0,0,0,0,0,0,65,59,0,0,0
0,0,0,0,63,65,0,0,0,0,0,0,0,0,0,65,59,0,0,0
0,0,0,0,63,65,0,0,0,0,0,0,0,0,0,65,59,0,0,0
0,0,0,0,63,65,0,0,0,0,0,0,0,0,0,65,59,0,0,0
0,0,0,0,14,3,0,3,0,0,0,0,0,3,0,3,13,0,0,0
0,0,0,0,63,65,0,0,0,0,0,0,0,0,0,65,59,0,0,0
0,0,0,0,63,65,0,0,0,0,3,0,0,0,0,65,59,0,0,0
0,0,0,0,63,65,0,0,0,0,3,0,0,0,0,65,59,0,0,0
0,0,0,0,63,65,0,0,0,0,44,45,0,0,0,65,59,0,0,0
0,0,0,0,14,3,0,3,0,0,0,0,0,3,0,3,13,0,0,0
0,0,0,0,63,65,0,0,0,0,0,0,0,0,0,65,59,0,0,0
0,0,0,0,63,65,0,0,0,0,0,0,0,0,0,65,59,0,0,0
0,0,0,0,63,65,0,0,0,0,0,0,0,0,0,65,59,0,0,0
0,0,0,0,63,65,0,0,0,0,0,0,0,0,0,65,59,0,0,0
0,0,0,0,63,65,0,0,0,414,0,414,0,0,0,65,59,0,0,0
0,0,0,0,14,3,69,3,69,3,189,3,69,3,69,3,13,0,0,0
0,0,0,0,0,0,0,0,0,0,0,0,0,0,0,0,0,0,0,0
0,0,0,0,0,0,0,0,0,0,0,0,0,0,0,0,0,0,0,0
0,0,0,0,0,0,0,0,0,0,0,0,0,0,0,0,0,0,0,0
0,0,0,0,0,0,0,0,0,0,0,0,0,0,0,0,0,0,0,0
0,0,0,0,0,0,0,0,0,0,0,0,0,0,0,0,0,0,0,0
0,0,0,0,0,0,0,0,0,0,0,0,0,0,0,0,0,0,0,0
0,0,0,0,0,0,0,0,0,0,0,0,0,0,0,0,0,0,0,0
0,0,0,0,0,0,0,0,0,0,0,0,0,0,0,0,0,0,0,0
0,0,0,0,0,0,0,0,0,0,0,0,0,0,0,0,0,0,0,0
0,0,0,0,0,0,0,0,0,0,0,0,0,0,0,0,0,0,0,0
0,0,0,0,0,0,0,0,0,0,0,0,0,0,0,0,0,0,0,0
0,0,0,0,0,0,0,0,0,0,0,0,0,0,0,0,0,0,0,0
0,0,0,0,0,0,0,0,0,0,0,0,0,0,0,0,0,0,0,0
0,0,0,0,0,0,0,0,0,0,0,0,0,0,0,0,0,0,0,0
0,0,0,0,0,0,0,0,0,0,0,0,0,0,0,0,0,0,0,0
0,0,0,0,0,0,0,0,0,0,0,0,0,0,0,0,0,0,0,0
0,0,0,0,0,0,0,0,0,0,0,0,0,0,0,0,0,0,0,0
:endlayer
layer: 20
0,0,0,0,0,0,0,0,0,0,0,0,0,0,0,0,0,0,0,0
0,0,0,0,0,0,0,0,0,0,0,0,0,0,0,0,0,0,0,0
0,0,0,0,0,14,3,3,140,4,18,4,140,3,3,13,0,0,0,0
0,0,0,0,0,63,65,4,0,0,0,0,0,4,65,59,0,0,0,0
0,0,0,0,0,63,65,4,0,0,0,0,0,4,65,59,0,0,0,0
0,0,0,0,0,63,65,4,0,0,0,0,0,4,65,59,0,0,0,0
0,0,0,0,0,63,65,4,0,0,0,0,0,4,65,59,0,0,0,0
0,0,0,0,0,63,65,4,0,0,0,0,0,4,65,59,0,0,0,0
0,0,0,0,0,14,3,3,0,0,0,0,0,3,3,13,0,0,0,0
0,0,0,0,0,63,65,4,0,0,0,0,0,4,65,59,0,0,0,0
0,0,0,0,0,63,65,4,0,0,0,0,0,4,65,59,0,0,0,0
0,0,0,0,0,63,65,4,0,0,0,0,0,4,65,59,0,0,0,0
0,0,0,0,0,63,65,4,0,0,0,0,0,4,65,59,0,0,0,0
0,0,0,0,0,14,3,3,66,66,66,66,66,3,3,13,0,0,0,0
0,0,0,0,0,63,65,4,67,65,65,65,67,4,65,59,0,0,0,0
0,0,0,0,0,63,65,4,67,65,65,65,67,4,65,59,0,0,0,0
0,0,0,0,0,63,65,4,67,65,65,65,67,4,65,59,0,0,0,0
0,0,0,0,0,63,65,4,67,65,65,65,67,4,65,59,0,0,0,0
0,0,0,0,0,14,3,3,67,65,65,65,67,3,3,13,0,0,0,0
0,0,0,0,0,63,65,4,67,65,65,65,67,4,65,59,0,0,0,0
0,0,0,0,0,63,65,4,67,65,65,65,67,4,65,59,0,0,0,0
0,0,0,0,0,63,65,4,67,65,65,65,67,4,65,59,0,0,0,0
0,0,0,0,0,63,65,4,67,65,65,65,67,4,65,59,0,0,0,0
0,0,0,0,0,14,3,3,67,65,65,65,67,3,3,13,0,0,0,0
0,0,0,0,0,63,65,4,67,65,65,65,67,4,65,59,0,0,0,0
0,0,0,0,0,63,65,4,67,65,65,65,67,4,65,59,0,0,0,0
0,0,0,0,0,63,65,4,67,65,65,65,67,4,65,59,0,0,0,0
0,0,0,0,0,63,65,4,67,65,65,65,67,4,65,59,0,0,0,0
0,0,0,0,0,14,3,3,67,65,65,65,67,3,3,13,0,0,0,0
0,0,0,0,0,63,65,4,67,65,65,65,67,4,65,59,0,0,0,0
0,0,0,0,0,63,65,4,67,65,65,65,67,4,65,59,0,0,0,0
0,0,0,0,0,63,65,4,67,65,65,65,67,4,65,59,0,0,0,0
0,0,0,0,0,63,65,4,67,65,65,65,67,4,65,59,0,0,0,0
0,0,0,0,0,14,3,3,67,65,65,65,67,3,3,13,0,0,0,0
0,0,0,0,0,63,65,4,67,45,45,45,67,4,65,59,0,0,0,0
0,0,0,0,0,63,65,4,67,0,3,45,67,4,65,59,0,0,0,0
0,0,0,0,0,63,65,4,67,0,3,44,67,4,65,59,0,0,0,0
0,0,0,0,0,63,65,4,67,0,0,0,67,4,65,59,0,0,0,0
0,0,0,0,0,14,3,3,66,66,66,66,67,3,3,13,0,0,0,0
0,0,0,0,0,63,65,4,67,0,0,0,67,4,65,59,0,0,0,0
0,0,0,0,0,63,65,4,67,0,0,0,67,4,65,59,0,0,0,0
0,0,0,0,0,63,65,4,67,0,0,0,67,4,65,59,0,0,0,0
0,0,0,0,0,63,65,4,67,0,0,0,67,4,65,59,0,0,0,0
0,0,0,0,0,63,65,4,67,0,0,0,67,4,65,59,0,0,0,0
0,0,0,0,0,14,3,3,3,415,189,415,3,3,3,13,0,0,0,0
0,0,0,0,0,0,0,0,0,0,0,0,0,0,0,0,0,0,0,0
0,0,0,0,0,0,0,0,0,0,0,0,0,0,0,0,0,0,0,0
0,0,0,0,0,0,0,0,0,0,0,0,0,0,0,0,0,0,0,0
0,0,0,0,0,0,0,0,0,0,0,0,0,0,0,0,0,0,0,0
0,0,0,0,0,0,0,0,0,0,0,0,0,0,0,0,0,0,0,0
0,0,0,0,0,0,0,0,0,0,0,0,0,0,0,0,0,0,0,0
0,0,0,0,0,0,0,0,0,0,0,0,0,0,0,0,0,0,0,0
0,0,0,0,0,0,0,0,0,0,0,0,0,0,0,0,0,0,0,0
0,0,0,0,0,0,0,0,0,0,0,0,0,0,0,0,0,0,0,0
0,0,0,0,0,0,0,0,0,0,0,0,0,0,0,0,0,0,0,0
0,0,0,0,0,0,0,0,0,0,0,0,0,0,0,0,0,0,0,0
0,0,0,0,0,0,0,0,0,0,0,0,0,0,0,0,0,0,0,0
0,0,0,0,0,0,0,0,0,0,0,0,0,0,0,0,0,0,0,0
0,0,0,0,0,0,0,0,0,0,0,0,0,0,0,0,0,0,0,0
0,0,0,0,0,0,0,0,0,0,0,0,0,0,0,0,0,0,0,0
0,0,0,0,0,0,0,0,0,0,0,0,0,0,0,0,0,0,0,0
0,0,0,0,0,0,0,0,0,0,0,0,0,0,0,0,0,0,0,0
:endlayer
layer: 21
0,0,0,0,0,0,0,0,0,0,0,0,0,0,0,0,0,0,0,0
0,0,0,0,0,0,0,0,0,0,0,0,0,0,0,0,0,0,0,0
0,0,0,0,0,0,14,3,60,3,189,3,60,3,13,0,0,0,0,0
0,0,0,0,0,0,63,4,0,58,0,58,0,4,59,0,0,0,0,0
0,0,0,0,0,0,63,4,0,0,0,0,0,4,59,0,0,0,0,0
0,0,0,0,0,0,63,4,0,0,0,0,0,4,59,0,0,0,0,0
0,0,0,0,0,0,63,4,0,0,0,0,0,4,59,0,0,0,0,0
0,0,0,0,0,0,63,4,0,0,0,0,0,4,59,0,0,0,0,0
0,0,0,0,0,0,14,3,0,0,0,0,0,3,13,0,0,0,0,0
0,0,0,0,0,0,63,4,0,0,0,0,0,4,59,0,0,0,0,0
0,0,0,0,0,0,63,4,0,0,0,0,0,4,59,0,0,0,0,0
0,0,0,0,0,0,63,4,0,0,0,0,0,4,59,0,0,0,0,0
0,0,0,0,0,0,63,4,0,0,0,0,0,4,59,0,0,0,0,0
0,0,0,0,0,0,14,3,424,422,420,418,416,3,13,0,0,0,0,0
0,0,0,0,0,0,63,4,0,0,0,0,0,4,59,0,0,0,0,0
0,0,0,0,0,0,63,4,0,0,0,0,0,4,59,0,0,0,0,0
0,0,0,0,0,0,63,4,0,0,0,0,0,4,59,0,0,0,0,0
0,0,0,0,0,0,63,4,0,0,0,0,0,4,59,0,0,0,0,0
0,0,0,0,0,0,14,3,0,0,0,0,0,3,13,0,0,0,0,0
0,0,0,0,0,0,63,4,0,0,0,0,0,4,59,0,0,0,0,0
0,0,0,0,0,0,63,4,0,0,0,0,0,4,59,0,0,0,0,0
0,0,0,0,0,0,63,4,0,0,0,0,0,4,59,0,0,0,0,0
0,0,0,0,0,0,63,4,0,0,0,0,0,4,59,0,0,0,0,0
0,0,0,0,0,0,14,3,0,0,0,0,0,3,13,0,0,0,0,0
0,0,0,0,0,0,63,4,0,0,0,0,0,4,59,0,0,0,0,0
0,0,0,0,0,0,63,4,0,0,0,0,0,4,59,0,0,0,0,0
0,0,0,0,0,0,63,4,0,0,0,0,0,4,59,0,0,0,0,0
0,0,0,0,0,0,63,4,0,0,0,0,0,4,59,0,0,0,0,0
0,0,0,0,0,0,14,3,0,0,0,0,0,3,13,0,0,0,0,0
0,0,0,0,0,0,63,4,0,0,0,0,0,4,59,0,0,0,0,0
0,0,0,0,0,0,63,4,0,0,0,0,0,4,59,0,0,0,0,0
0,0,0,0,0,0,63,4,0,0,0,0,0,4,59,0,0,0,0,0
0,0,0,0,0,0,63,4,0,0,0,0,0,4,59,0,0,0,0,0
0,0,0,0,0,0,14,3,0,0,0,0,0,3,13,0,0,0,0,0
0,0,0,0,0,0,63,4,0,0,0,0,0,4,59,0,0,0,0,0
0,0,0,0,0,0,63,4,0,0,0,0,0,4,59,0,0,0,0,0
0,0,0,0,0,0,63,4,0,0,0,0,0,4,59,0,0,0,0,0
0,0,0,0,0,0,63,4,0,0,0,0,0,4,59,0,0,0,0,0
0,0,0,0,0,0,14,3,425,423,421,419,417,3,13,0,0,0,0,0
0,0,0,0,0,0,63,4,0,0,0,0,0,4,59,0,0,0,0,0
0,0,0,0,0,0,63,4,0,0,0,0,0,4,59,0,0,0,0,0
0,0,0,0,0,0,63,4,0,0,0,0,0,4,59,0,0,0,0,0
0,0,0,0,0,0,63,4,0,0,0,0,0,4,59,0,0,0,0,0
0,0,0,0,0,0,63,4,0,0,0,0,0,4,59,0,0,0,0,0
0,0,0,0,0,0,14,3,3,415,189,415,3,3,13,0,0,0,0,0
0,0,0,0,0,0,0,0,0,0,0,0,0,0,0,0,0,0,0,0
0,0,0,0,0,0,0,0,0,0,0,0,0,0,0,0,0,0,0,0
0,0,0,0,0,0,0,0,0,0,0,0,0,0,0,0,0,0,0,0
0,0,0,0,0,0,0,0,0,0,0,0,0,0,0,0,0,0,0,0
0,0,0,0,0,0,0,0,0,0,0,0,0,0,0,0,0,0,0,0
0,0,0,0,0,0,0,0,0,0,0,0,0,0,0,0,0,0,0,0
0,0,0,0,0,0,0,0,0,0,0,0,0,0,0,0,0,0,0,0
0,0,0,0,0,0,0,0,0,0,0,0,0,0,0,0,0,0,0,0
0,0,0,0,0,0,0,0,0,0,0,0,0,0,0,0,0,0,0,0
0,0,0,0,0,0,0,0,0,0,0,0,0,0,0,0,0,0,0,0
0,0,0,0,0,0,0,0,0,0,0,0,0,0,0,0,0,0,0,0
0,0,0,0,0,0,0,0,0,0,0,0,0,0,0,0,0,0,0,0
0,0,0,0,0,0,0,0,0,0,0,0,0,0,0,0,0,0,0,0
0,0,0,0,0,0,0,0,0,0,0,0,0,0,0,0,0,0,0,0
0,0,0,0,0,0,0,0,0,0,0,0,0,0,0,0,0,0,0,0
0,0,0,0,0,0,0,0,0,0,0,0,0,0,0,0,0,0,0,0
0,0,0,0,0,0,0,0,0,0,0,0,0,0,0,0,0,0,0,0
:endlayer
layer: 22
0,0,0,0,0,0,0,0,0,0,0,0,0,0,0,0,0,0,0,0
0,0,0,0,0,0,0,0,0,0,0,0,0,0,0,0,0,0,0,0
0,0,0,0,0,0,0,3,3,189,189,189,3,3,0,0,0,0,0,0
0,0,0,0,0,0,0,4,0,0,0,0,0,4,0,0,0,0,0,0
0,0,0,0,0,0,0,189,0,0,0,0,0,189,0,0,0,0,0,0
0,0,0,0,0,0,0,189,0,0,0,0,0,189,0,0,0,0,0,0
0,0,0,0,0,0,0,189,0,0,0,0,0,189,0,0,0,0,0,0
0,0,0,0,0,0,0,4,0,0,0,0,0,4,0,0,0,0,0,0
0,0,0,0,0,0,0,3,0,0,0,0,0,3,0,0,0,0,0,0
0,0,0,0,0,0,0,4,0,0,0,0,0,4,0,0,0,0,0,0
0,0,0,0,0,0,0,189,0,0,0,0,0,189,0,0,0,0,0,0
0,0,0,0,0,0,0,189,0,0,0,0,0,189,0,0,0,0,0,0
0,0,0,0,0,0,0,4,0,0,0,0,0,4,0,0,0,0,0,0
0,0,0,0,0,0,0,3,0,0,0,0,0,3,0,0,0,0,0,0
0,0,0,0,0,0,0,4,0,0,0,0,0,4,0,0,0,0,0,0
0,0,0,0,0,0,0,189,0,0,0,0,0,189,0,0,0,0,0,0
0,0,0,0,0,0,0,189,0,0,0,0,0,189,0,0,0,0,0,0
0,0,0,0,0,0,0,4,0,0,0,0,0,4,0,0,0,0,0,0
0,0,0,0,0,0,0,3,0,0,0,0,0,3,0,0,0,0,0,0
0,0,0,0,0,0,0,4,0,0,0,0,0,4,0,0,0,0,0,0
0,0,0,0,0,0,0,189,0,0,0,0,0,189,0,0,0,0,0,0
0,0,0,0,0,0,0,189,0,0,0,0,0,189,0,0,0,0,0,0
0,0,0,0,0,0,0,4,0,0,0,0,0,4,0,0,0,0,0,0
0,0,0,0,0,0,0,3,0,0,0,0,0,3,0,0,0,0,0,0
0,0,0,0,0,0,0,4,0,0,0,0,0,4,0,0,0,0,0,0
0,0,0,0,0,0,0,189,0,0,0,0,0,189,0,0,0,0,0,0
0,0,0,0,0,0,0,189,0,0,0,0,0,189,0,0,0,0,0,0
0,0,0,0,0,0,0,4,0,0,0,0,0,4,0,0,0,0,0,0
0,0,0,0,0,0,0,3,0,0,0,0,0,3,0,0,0,0,0,0
0,0,0,0,0,0,0,4,0,0,0,0,0,4,0,0,0,0,0,0
0,0,0,0,0,0,0,189,0,0,0,0,0,189,0,0,0,0,0,0
0,0,0,0,0,0,0,189,0,0,0,0,0,189,0,0,0,0,0,0
0,0,0,0,0,0,0,4,0,0,0,0,0,4,0,0,0,0,0,0
0,0,0,0,0,0,0,3,0,0,0,0,0,3,0,0,0,0,0,0
0,0,0,0,0,0,0,4,0,0,0,0,0,4,0,0,0,0,0,0
0,0,0,0,0,0,0,189,0,0,0,0,0,189,0,0,0,0,0,0
0,0,0,0,0,0,0,189,0,0,0,0,0,189,0,0,0,0,0,0
0,0,0,0,0,0,0,4,0,0,0,0,0,4,0,0,0,0,0,0
0,0,0,0,0,0,0,3,0,0,0,0,0,3,0,0,0,0,0,0
0,0,0,0,0,0,0,4,0,0,0,0,0,4,0,0,0,0,0,0
0,0,0,0,0,0,0,189,0,0,0,0,0,189,0,0,0,0,0,0
0,0,0,0,0,0,0,189,0,0,0,0,0,189,0,0,0,0,0,0
0,0,0,0,0,0,0,189,0,0,0,0,0,189,0,0,0,0,0,0
0,0,0,0,0,0,0,4,0,0,0,0,0,4,0,0,0,0,0,0
0,0,0,0,0,0,0,3,3,189,189,189,3,3,0,0,0,0,0,0
0,0,0,0,0,0,0,0,0,0,0,0,0,0,0,0,0,0,0,0
0,0,0,0,0,0,0,0,0,0,0,0,0,0,0,0,0,0,0,0
0,0,0,0,0,0,0,0,0,0,0,0,0,0,0,0,0,0,0,0
0,0,0,0,0,0,0,0,0,0,0,0,0,0,0,0,0,0,0,0
0,0,0,0,0,0,0,0,0,0,0,0,0,0,0,0,0,0,0,0
0,0,0,0,0,0,0,0,0,0,0,0,0,0,0,0,0,0,0,0
0,0,0,0,0,0,0,0,0,0,0,0,0,0,0,0,0,0,0,0
0,0,0,0,0,0,0,0,0,0,0,0,0,0,0,0,0,0,0,0
0,0,0,0,0,0,0,0,0,0,0,0,0,0,0,0,0,0,0,0
0,0,0,0,0,0,0,0,0,0,0,0,0,0,0,0,0,0,0,0
0,0,0,0,0,0,0,0,0,0,0,0,0,0,0,0,0,0,0,0
0,0,0,0,0,0,0,0,0,0,0,0,0,0,0,0,0,0,0,0
0,0,0,0,0,0,0,0,0,0,0,0,0,0,0,0,0,0,0,0
0,0,0,0,0,0,0,0,0,0,0,0,0,0,0,0,0,0,0,0
0,0,0,0,0,0,0,0,0,0,0,0,0,0,0,0,0,0,0,0
0,0,0,0,0,0,0,0,0,0,0,0,0,0,0,0,0,0,0,0
0,0,0,0,0,0,0,0,0,0,0,0,0,0,0,0,0,0,0,0
:endlayer
layer: 23
0,0,0,0,0,0,0,0,0,0,0,0,0,0,0,0,0,0,0,0
0,0,0,0,0,0,0,0,0,0,0,0,0,0,0,0,0,0,0,0
0,0,0,0,0,0,0,3,189,189,426,189,189,3,0,0,0,0,0,0
0,0,0,0,0,0,0,4,0,0,0,0,0,4,0,0,0,0,0,0
0,0,0,0,0,0,0,189,0,0,0,0,0,189,0,0,0,0,0,0
0,0,0,0,0,0,0,189,0,0,0,0,0,189,0,0,0,0,0,0
0,0,0,0,0,0,0,189,0,0,0,0,0,189,0,0,0,0,0,0
0,0,0,0,0,0,0,4,0,0,0,0,0,4,0,0,0,0,0,0
0,0,0,0,0,0,0,3,57,0,0,0,64,3,0,0,0,0,0,0
0,0,0,0,0,0,0,4,0,0,0,0,0,4,0,0,0,0,0,0
0,0,0,0,0,0,0,189,0,0,0,0,0,189,0,0,0,0,0,0
0,0,0,0,0,0,0,189,0,0,0,0,0,189,0,0,0,0,0,0
0,0,0,0,0,0,0,4,0,0,0,0,0,4,0,0,0,0,0,0
0,0,0,0,0,0,0,3,57,0,0,0,64,3,0,0,0,0,0,0
0,0,0,0,0,0,0,4,0,0,0,0,0,4,0,0,0,0,0,0
0,0,0,0,0,0,0,189,0,0,0,0,0,189,0,0,0,0,0,0
0,0,0,0,0,0,0,189,0,0,0,0,0,189,0,0,0,0,0,0
0,0,0,0,0,0,0,4,0,0,0,0,0,4,0,0,0,0,0,0
0,0,0,0,0,0,0,3,57,0,0,0,64,3,0,0,0,0,0,0
0,0,0,0,0,0,0,4,0,0,0,0,0,4,0,0,0,0,0,0
0,0,0,0,0,0,0,189,0,0,0,0,0,189,0,0,0,0,0,0
0,0,0,0,0,0,0,189,0,0,0,0,0,189,0,0,0,0,0,0
0,0,0,0,0,0,0,4,0,0,0,0,0,4,0,0,0,0,0,0
0,0,0,0,0,0,0,3,57,0,0,0,64,3,0,0,0,0,0,0
0,0,0,0,0,0,0,4,0,0,0,0,0,4,0,0,0,0,0,0
0,0,0,0,0,0,0,189,0,0,0,0,0,189,0,0,0,0,0,0
0,0,0,0,0,0,0,189,0,0,0,0,0,189,0,0,0,0,0,0
0,0,0,0,0,0,0,4,0,0,0,0,0,4,0,0,0,0,0,0
0,0,0,0,0,0,0,3,57,0,0,0,64,3,0,0,0,0,0,0
0,0,0,0,0,0,0,4,0,0,0,0,0,4,0,0,0,0,0,0
0,0,0,0,0,0,0,189,0,0,0,0,0,189,0,0,0,0,0,0
0,0,0,0,0,0,0,189,0,0,0,0,0,189,0,0,0,0,0,0
0,0,0,0,0,0,0,4,0,0,0,0,0,4,0,0,0,0,0,0
0,0,0,0,0,0,0,3,57,0,0,0,64,3,0,0,0,0,0,0
0,0,0,0,0,0,0,4,0,0,0,0,0,4,0,0,0,0,0,0
0,0,0,0,0,0,0,189,0,0,0,0,0,189,0,0,0,0,0,0
0,0,0,0,0,0,0,189,0,0,0,0,0,189,0,0,0,0,0,0
0,0,0,0,0,0,0,4,0,0,0,0,0,4,0,0,0,0,0,0
0,0,0,0,0,0,0,3,57,0,0,0,64,3,0,0,0,0,0,0
0,0,0,0,0,0,0,4,0,0,0,0,0,4,0,0,0,0,0,0
0,0,0,0,0,0,0,189,0,0,0,0,0,189,0,0,0,0,0,0
0,0,0,0,0,0,0,189,0,0,0,0,0,189,0,0,0,0,0,0
0,0,0,0,0,0,0,189,0,0,0,0,0,189,0,0,0,0,0,0
0,0,0,0,0,0,0,4,0,414,0,414,0,4,0,0,0,0,0,0
0,0,0,0,0,0,0,3,16,3,189,3,16,3,0,0,0,0,0,0
0,0,0,0,0,0,0,0,0,0,0,0,0,0,0,0,0,0,0,0
0,0,0,0,0,0,0,0,0,0,0,0,0,0,0,0,0,0,0,0
0,0,0,0,0,0,0,0,0,0,0,0,0,0,0,0,0,0,0,0
0,0,0,0,0,0,0,0,0,0,0,0,0,0,0,0,0,0,0,0
0,0,0,0,0,0,0,0,0,0,0,0,0,0,0,0,0,0,0,0
0,0,0,0,0,0,0,0,0,0,0,0,0,0,0,0,0,0,0,0
0,0,0,0,0,0,0,0,0,0,0,0,0,0,0,0,0,0,0,0
0,0,0,0,0,0,0,0,0,0,0,0,0,0,0,0,0,0,0,0
0,0,0,0,0,0,0,0,0,0,0,0,0,0,0,0,0,0,0,0
0,0,0,0,0,0,0,0,0,0,0,0,0,0,0,0,0,0,0,0
0,0,0,0,0,0,0,0,0,0,0,0,0,0,0,0,0,0,0,0
0,0,0,0,0,0,0,0,0,0,0,0,0,0,0,0,0,0,0,0
0,0,0,0,0,0,0,0,0,0,0,0,0,0,0,0,0,0,0,0
0,0,0,0,0,0,0,0,0,0,0,0,0,0,0,0,0,0,0,0
0,0,0,0,0,0,0,0,0,0,0,0,0,0,0,0,0,0,0,0
0,0,0,0,0,0,0,0,0,0,0,0,0,0,0,0,0,0,0,0
0,0,0,0,0,0,0,0,0,0,0,0,0,0,0,0,0,0,0,0
:endlayer
layer: 24
0,0,0,0,0,0,0,0,0,0,0,0,0,0,0,0,0,0,0,0
0,0,0,0,0,0,0,0,0,0,0,0,0,0,0,0,0,0,0,0
0,0,0,0,0,0,0,3,3,189,189,189,3,3,0,0,0,0,0,0
0,0,0,0,0,0,0,4,0,0,0,0,0,4,0,0,0,0,0,0
0,0,0,0,0,0,0,189,0,0,0,0,0,189,0,0,0,0,0,0
0,0,0,0,0,0,0,189,0,0,0,0,0,189,0,0,0,0,0,0
0,0,0,0,0,0,0,189,0,0,0,0,0,189,0,0,0,0,0,0
0,0,0,0,0,0,0,4,0,0,0,0,0,4,0,0,0,0,0,0
0,0,0,0,0,0,0,3,0,0,0,0,0,3,0,0,0,0,0,0
0,0,0,0,0,0,0,4,0,0,0,0,0,4,0,0,0,0,0,0
0,0,0,0,0,0,0,189,0,0,0,0,0,189,0,0,0,0,0,0
0,0,0,0,0,0,0,189,0,0,0,0,0,189,0,0,0,0,0,0
0,0,0,0,0,0,0,4,0,0,0,0,0,4,0,0,0,0,0,0
0,0,0,0,0,0,0,3,0,0,0,0,0,3,0,0,0,0,0,0
0,0,0,0,0,0,0,4,0,0,0,0,0,4,0,0,0,0,0,0
0,0,0,0,0,0,0,189,0,0,0,0,0,189,0,0,0,0,0,0
0,0,0,0,0,0,0,189,0,0,0,0,0,189,0,0,0,0,0,0
0,0,0,0,0,0,0,4,0,0,0,0,0,4,0,0,0,0,0,0
0,0,0,0,0,0,0,3,0,0,0,0,0,3,0,0,0,0,0,0
0,0,0,0,0,0,0,4,0,0,0,0,0,4,0,0,0,0,0,0
0,0,0,0,0,0,0,189,0,0,0,0,0,189,0,0,0,0,0,0
0,0,0,0,0,0,0,189,0,0,0,0,0,189,0,0,0,0,0,0
0,0,0,0,0,0,0,4,0,0,0,0,0,4,0,0,0,0,0,0
0,0,0,0,0,0,0,3,0,0,0,0,0,3,0,0,0,0,0,0
0,0,0,0,0,0,0,4,0,0,0,0,0,4,0,0,0,0,0,0
0,0,0,0,0,0,0,189,0,0,0,0,0,189,0,0,0,0,0,0
0,0,0,0,0,0,0,189,0,0,0,0,0,189,0,0,0,0,0,0
0,0,0,0,0,0,0,4,0,0,0,0,0,4,0,0,0,0,0,0
0,0,0,0,0,0,0,3,0,0,0,0,0,3,0,0,0,0,0,0
0,0,0,0,0,0,0,4,0,0,0,0,0,4,0,0,0,0,0,0
0,0,0,0,0,0,0,189,0,0,0,0,0,189,0,0,0,0,0,0
0,0,0,0,0,0,0,189,0,0,0,0,0,189,0,0,0,0,0,0
0,0,0,0,0,0,0,4,0,0,0,0,0,4,0,0,0,0,0,0
0,0,0,0,0,0,0,3,0,0,0,0,0,3,0,0,0,0,0,0
0,0,0,0,0,0,0,4,0,0,0,0,0,4,0,0,0,0,0,0
0,0,0,0,0,0,0,189,0,0,0,0,0,189,0,0,0,0,0,0
0,0,0,0,0,0,0,189,0,0,0,0,0,189,0,0,0,0,0,0
0,0,0,0,0,0,0,4,0,0,0,0,0,4,0,0,0,0,0,0
0,0,0,0,0,0,0,3,0,0,0,0,0,3,0,0,0,0,0,0
0,0,0,0,0,0,0,4,0,0,0,0,0,4,0,0,0,0,0,0
0,0,0,0,0,0,0,189,0,0,0,0,0,189,0,0,0,0,0,0
0,0,0,0,0,0,0,189,0,0,0,0,0,189,0,0,0,0,0,0
0,0,0,0,0,0,0,189,0,0,0,0,0,189,0,0,0,0,0,0
0,0,0,0,0,0,0,4,0,0,0,0,0,4,0,0,0,0,0,0
0,0,0,0,0,0,0,3,69,16,3,16,69,3,0,0,0,0,0,0
0,0,0,0,0,0,0,0,0,0,0,0,0,0,0,0,0,0,0,0
0,0,0,0,0,0,0,0,0,0,0,0,0,0,0,0,0,0,0,0
0,0,0,0,0,0,0,0,0,0,0,0,0,0,0,0,0,0,0,0
0,0,0,0,0,0,0,0,0,0,0,0,0,0,0,0,0,0,0,0
0,0,0,0,0,0,0,0,0,0,0,0,0,0,0,0,0,0,0,0
0,0,0,0,0,0,0,0,0,0,0,0,0,0,0,0,0,0,0,0
0,0,0,0,0,0,0,0,0,0,0,0,0,0,0,0,0,0,0,0
0,0,0,0,0,0,0,0,0,0,0,0,0,0,0,0,0,0,0,0
0,0,0,0,0,0,0,0,0,0,0,0,0,0,0,0,0,0,0,0
0,0,0,0,0,0,0,0,0,0,0,0,0,0,0,0,0,0,0,0
0,0,0,0,0,0,0,0,0,0,0,0,0,0,0,0,0,0,0,0
0,0,0,0,0,0,0,0,0,0,0,0,0,0,0,0,0,0,0,0
0,0,0,0,0,0,0,0,0,0,0,0,0,0,0,0,0,0,0,0
0,0,0,0,0,0,0,0,0,0,0,0,0,0,0,0,0,0,0,0
0,0,0,0,0,0,0,0,0,0,0,0,0,0,0,0,0,0,0,0
0,0,0,0,0,0,0,0,0,0,0,0,0,0,0,0,0,0,0,0
0,0,0,0,0,0,0,0,0,0,0,0,0,0,0,0,0,0,0,0
:endlayer
layer: 25
0,0,0,0,0,0,0,0,0,0,0,0,0,0,0,0,0,0,0,0
0,0,0,0,0,0,0,0,0,0,0,0,0,0,0,0,0,0,0,0
0,0,0,0,0,0,0,3,3,3,189,3,3,3,0,0,0,0,0,0
0,0,0,0,0,0,0,3,0,58,0,58,0,3,0,0,0,0,0,0
0,0,0,0,0,0,0,4,0,0,0,0,0,4,0,0,0,0,0,0
0,0,0,0,0,0,0,189,0,0,0,0,0,189,0,0,0,0,0,0
0,0,0,0,0,0,0,4,0,0,0,0,0,4,0,0,0,0,0,0
0,0,0,0,0,0,0,3,0,0,0,0,0,3,0,0,0,0,0,0
0,0,0,0,0,0,0,14,3,0,0,0,3,13,0,0,0,0,0,0
0,0,0,0,0,0,0,3,0,0,0,0,0,3,0,0,0,0,0,0
0,0,0,0,0,0,0,4,0,0,0,0,0,4,0,0,0,0,0,0
0,0,0,0,0,0,0,4,0,0,0,0,0,4,0,0,0,0,0,0
0,0,0,0,0,0,0,3,0,0,0,0,0,3,0,0,0,0,0,0
0,0,0,0,0,0,0,14,3,0,0,0,3,13,0,0,0,0,0,0
0,0,0,0,0,0,0,3,0,0,0,0,0,3,0,0,0,0,0,0
0,0,0,0,0,0,0,4,0,0,0,0,0,4,0,0,0,0,0,0
0,0,0,0,0,0,0,4,0,0,0,0,0,4,0,0,0,0,0,0
0,0,0,0,0,0,0,3,0,0,0,0,0,3,0,0,0,0,0,0
0,0,0,0,0,0,0,14,3,0,0,0,3,13,0,0,0,0,0,0
0,0,0,0,0,0,0,3,0,0,0,0,0,3,0,0,0,0,0,0
0,0,0,0,0,0,0,4,0,0,0,0,0,4,0,0,0,0,0,0
0,0,0,0,0,0,0,4,0,0,0,0,0,4,0,0,0,0,0,0
0,0,0,0,0,0,0,3,0,0,0,0,0,3,0,0,0,0,0,0
0,0,0,0,0,0,0,14,3,0,0,0,3,13,0,0,0,0,0,0
0,0,0,0,0,0,0,3,0,0,0,0,0,3,0,0,0,0,0,0
0,0,0,0,0,0,0,4,0,0,0,0,0,4,0,0,0,0,0,0
0,0,0,0,0,0,0,4,0,0,0,0,0,4,0,0,0,0,0,0
0,0,0,0,0,0,0,3,0,0,0,0,0,3,0,0,0,0,0,0
0,0,0,0,0,0,0,14,3,0,0,0,3,13,0,0,0,0,0,0
0,0,0,0,0,0,0,3,0,0,0,0,0,3,0,0,0,0,0,0
0,0,0,0,0,0,0,4,0,0,0,0,0,4,0,0,0,0,0,0
0,0,0,0,0,0,0,4,0,0,0,0,0,4,0,0,0,0,0,0
0,0,0,0,0,0,0,3,0,0,0,0,0,3,0,0,0,0,0,0
0,0,0,0,0,0,0,14,3,0,0,0,3,13,0,0,0,0,0,0
0,0,0,0,0,0,0,3,0,0,0,0,0,3,0,0,0,0,0,0
0,0,0,0,0,0,0,4,0,0,0,0,0,4,0,0,0,0,0,0
0,0,0,0,0,0,0,4,0,0,0,0,0,4,0,0,0,0,0,0
0,0,0,0,0,0,0,3,0,0,0,0,0,3,0,0,0,0,0,0
0,0,0,0,0,0,0,14,3,0,0,0,3,13,0,0,0,0,0,0
0,0,0,0,0,0,0,3,0,0,0,0,0,3,0,0,0,0,0,0
0,0,0,0,0,0,0,4,0,0,0,0,0,4,0,0,0,0,0,0
0,0,0,0,0,0,0,189,0,0,0,0,0,189,0,0,0,0,0,0
0,0,0,0,0,0,0,4,0,0,0,0,0,4,0,0,0,0,0,0
0,0,0,0,0,0,0,3,0,0,0,0,0,3,0,0,0,0,0,0
0,0,0,0,0,0,0,3,3,69,4,69,3,3,0,0,0,0,0,0
0,0,0,0,0,0,0,0,0,0,0,0,0,0,0,0,0,0,0,0
0,0,0,0,0,0,0,0,0,0,0,0,0,0,0,0,0,0,0,0
0,0,0,0,0,0,0,0,0,0,0,0,0,0,0,0,0,0,0,0
0,0,0,0,0,0,0,0,0,0,0,0,0,0,0,0,0,0,0,0
0,0,0,0,0,0,0,0,0,0,0,0,0,0,0,0,0,0,0,0
0,0,0,0,0,0,0,0,0,0,0,0,0,0,0,0,0,0,0,0
0,0,0,0,0,0,0,0,0,0,0,0,0,0,0,0,0,0,0,0
0,0,0,0,0,0,0,0,0,0,0,0,0,0,0,0,0,0,0,0
0,0,0,0,0,0,0,0,0,0,0,0,0,0,0,0,0,0,0,0
0,0,0,0,0,0,0,0,0,0,0,0,0,0,0,0,0,0,0,0
0,0,0,0,0,0,0,0,0,0,0,0,0,0,0,0,0,0,0,0
0,0,0,0,0,0,0,0,0,0,0,0,0,0,0,0,0,0,0,0
0,0,0,0,0,0,0,0,0,0,0,0,0,0,0,0,0,0,0,0
0,0,0,0,0,0,0,0,0,0,0,0,0,0,0,0,0,0,0,0
0,0,0,0,0,0,0,0,0,0,0,0,0,0,0,0,0,0,0,0
0,0,0,0,0,0,0,0,0,0,0,0,0,0,0,0,0,0,0,0
0,0,0,0,0,0,0,0,0,0,0,0,0,0,0,0,0,0,0,0
:endlayer
layer: 26
0,0,0,0,0,0,0,0,0,0,0,0,0,0,0,0,0,0,0,0
0,0,0,0,0,0,0,0,0,0,0,0,0,0,0,0,0,0,0,0
0,0,0,0,0,0,0,3,4,3,3,3,4,3,0,0,0,0,0,0
0,0,0,0,0,0,0,14,0,0,0,0,0,13,0,0,0,0,0,0
0,0,0,0,0,0,0,3,0,0,0,0,0,3,0,0,0,0,0,0
0,0,0,0,0,0,0,4,0,0,0,0,0,4,0,0,0,0,0,0
0,0,0,0,0,0,0,3,0,0,0,0,0,3,0,0,0,0,0,0
0,0,0,0,0,0,0,14,0,0,0,0,0,13,0,0,0,0,0,0
0,0,0,0,0,0,0,14,0,3,0,3,0,13,0,0,0,0,0,0
0,0,0,0,0,0,0,14,0,0,0,0,0,13,0,0,0,0,0,0
0,0,0,0,0,0,0,3,0,0,0,0,0,3,0,0,0,0,0,0
0,0,0,0,0,0,0,3,0,0,0,0,0,3,0,0,0,0,0,0
0,0,0,0,0,0,0,14,0,0,0,0,0,13,0,0,0,0,0,0
0,0,0,0,0,0,0,14,0,3,0,3,0,13,0,0,0,0,0,0
0,0,0,0,0,0,0,14,0,0,0,0,0,13,0,0,0,0,0,0
0,0,0,0,0,0,0,3,0,0,0,0,0,3,0,0,0,0,0,0
0,0,0,0,0,0,0,3,0,0,0,0,0,3,0,0,0,0,0,0
0,0,0,0,0,0,0,14,0,0,0,0,0,13,0,0,0,0,0,0
0,0,0,0,0,0,0,14,0,3,0,3,0,13,0,0,0,0,0,0
0,0,0,0,0,0,0,14,0,0,0,0,0,13,0,0,0,0,0,0
0,0,0,0,0,0,0,3,0,0,0,0,0,3,0,0,0,0,0,0
0,0,0,0,0,0,0,3,0,0,0,0,0,3,0,0,0,0,0,0
0,0,0,0,0,0,0,14,0,0,0,0,0,13,0,0,0,0,0,0
0,0,0,0,0,0,0,14,0,3,0,3,0,13,0,0,0,0,0,0
0,0,0,0,0,0,0,14,0,0,0,0,0,13,0,0,0,0,0,0
0,0,0,0,0,0,0,3,0,0,0,0,0,3,0,0,0,0,0,0
0,0,0,0,0,0,0,3,0,0,0,0,0,3,0,0,0,0,0,0
0,0,0,0,0,0,0,14,0,0,0,0,0,13,0,0,0,0,0,0
0,0,0,0,0,0,0,14,0,3,0,3,0,13,0,0,0,0,0,0
0,0,0,0,0,0,0,14,0,0,0,0,0,13,0,0,0,0,0,0
0,0,0,0,0,0,0,3,0,0,0,0,0,3,0,0,0,0,0,0
0,0,0,0,0,0,0,3,0,0,0,0,0,3,0,0,0,0,0,0
0,0,0,0,0,0,0,14,0,0,0,0,0,13,0,0,0,0,0,0
0,0,0,0,0,0,0,14,0,3,427,3,0,13,0,0,0,0,0,0
0,0,0,0,0,0,0,14,0,0,0,0,0,13,0,0,0,0,0,0
0,0,0,0,0,0,0,3,0,0,0,0,0,3,0,0,0,0,0,0
0,0,0,0,0,0,0,3,0,0,0,0,0,3,0,0,0,0,0,0
0,0,0,0,0,0,0,14,0,0,0,0,0,13,0,0,0,0,0,0
0,0,0,0,0,0,0,14,0,3,0,3,0,13,0,0,0,0,0,0
0,0,0,0,0,0,0,14,0,0,0,0,0,13,0,0,0,0,0,0
0,0,0,0,0,0,0,3,0,0,0,0,0,3,0,0,0,0,0,0
0,0,0,0,0,0,0,4,0,0,0,0,0,4,0,0,0,0,0,0
0,0,0,0,0,0,0,3,0,0,0,0,0,3,0,0,0,0,0,0
0,0,0,0,0,0,0,14,0,0,0,0,0,13,0,0,0,0,0,0
0,0,0,0,0,0,0,3,16,3,18,3,16,3,0,0,0,0,0,0
0,0,0,0,0,0,0,0,0,0,0,0,0,0,0,0,0,0,0,0
0,0,0,0,0,0,0,0,0,0,0,0,0,0,0,0,0,0,0,0
0,0,0,0,0,0,0,0,0,0,0,0,0,0,0,0,0,0,0,0
0,0,0,0,0,0,0,0,0,0,0,0,0,0,0,0,0,0,0,0
0,0,0,0,0,0,0,0,0,0,0,0,0,0,0,0,0,0,0,0
0,0,0,0,0,0,0,0,0,0,0,0,0,0,0,0,0,0,0,0
0,0,0,0,0,0,0,0,0,0,0,0,0,0,0,0,0,0,0,0
0,0,0,0,0,0,0,0,0,0,0,0,0,0,0,0,0,0,0,0
0,0,0,0,0,0,0,0,0,0,0,0,0,0,0,0,0,0,0,0
0,0,0,0,0,0,0,0,0,0,0,0,0,0,0,0,0,0,0,0
0,0,0,0,0,0,0,0,0,0,0,0,0,0,0,0,0,0,0,0
0,0,0,0,0,0,0,0,0,0,0,0,0,0,0,0,0,0,0,0
0,0,0,0,0,0,0,0,0,0,0,0,0,0,0,0,0,0,0,0
0,0,0,0,0,0,0,0,0,0,0,0,0,0,0,0,0,0,0,0
0,0,0,0,0,0,0,0,0,0,0,0,0,0,0,0,0,0,0,0
0,0,0,0,0,0,0,0,0,0,0,0,0,0,0,0,0,0,0,0
0,0,0,0,0,0,0,0,0,0,0,0,0,0,0,0,0,0,0,0
:endlayer
layer: 27
0,0,0,0,0,0,0,0,0,0,0,0,0,0,0,0,0,0,0,0
0,0,0,0,0,0,0,0,0,0,0,0,0,0,0,0,0,0,0,0
0,0,0,0,0,0,0,3,4,4,3,4,4,3,0,0,0,0,0,0
0,0,0,0,0,0,0,14,0,0,0,0,0,59,0,0,0,0,0,0
0,0,0,0,0,0,0,14,0,0,0,0,0,59,0,0,0,0,0,0
0,0,0,0,0,0,0,3,0,0,0,0,0,3,0,0,0,0,0,0
0,0,0,0,0,0,0,63,0,0,0,0,0,59,0,0,0,0,0,0
0,0,0,0,0,0,0,63,0,0,414,0,0,59,0,0,0,0,0,0
0,0,0,0,0,0,0,63,0,0,3,0,0,59,0,0,0,0,0,0
0,0,0,0,0,0,0,63,0,0,58,0,0,59,0,0,0,0,0,0
0,0,0,0,0,0,0,14,3,0,0,0,3,13,0,0,0,0,0,0
0,0,0,0,0,0,0,14,3,0,0,0,3,13,0,0,0,0,0,0
0,0,0,0,0,0,0,63,0,0,414,0,0,59,0,0,0,0,0,0
0,0,0,0,0,0,0,63,0,0,3,0,0,59,0,0,0,0,0,0
0,0,0,0,0,0,0,63,0,0,58,0,0,59,0,0,0,0,0,0
0,0,0,0,0,0,0,14,3,0,0,0,3,13,0,0,0,0,0,0
0,0,0,0,0,0,0,14,3,0,0,0,3,13,0,0,0,0,0,0
0,0,0,0,0,0,0,63,0,0,414,0,0,59,0,0,0,0,0,0
0,0,0,0,0,0,0,63,0,0,3,0,0,59,0,0,0,0,0,0
0,0,0,0,0,0,0,63,0,0,58,0,0,59,0,0,0,0,0,0
0,0,0,0,0,0,0,14,3,0,0,0,3,13,0,0,0,0,0,0
0,0,0,0,0,0,0,14,3,0,0,0,3,13,0,0,0,0,0,0
0,0,0,0,0,0,0,63,0,0,414,0,0,59,0,0,0,0,0,0
0,0,0,0,0,0,0,63,0,0,3,0,0,59,0,0,0,0,0,0
0,0,0,0,0,0,0,63,0,0,58,0,0,59,0,0,0,0,0,0
0,0,0,0,0,0,0,14,3,0,0,0,3,13,0,0,0,0,0,0
0,0,0,0,0,0,0,14,3,0,0,0,3,13,0,0,0,0,0,0
0,0,0,0,0,0,0,63,0,0,414,0,0,59,0,0,0,0,0,0
0,0,0,0,0,0,0,63,0,0,3,0,0,59,0,0,0,0,0,0
0,0,0,0,0,0,0,63,0,0,58,0,0,59,0,0,0,0,0,0
0,0,0,0,0,0,0,14,3,0,0,0,3,13,0,0,0,0,0,0
0,0,0,0,0,0,0,14,3,0,0,0,3,13,0,0,0,0,0,0
0,0,0,0,0,0,0,63,0,0,414,0,0,59,0,0,0,0,0,0
0,0,0,0,0,0,0,63,0,0,3,0,0,59,0,0,0,0,0,0
0,0,0,0,0,0,0,63,0,0,58,0,0,59,0,0,0,0,0,0
0,0,0,0,0,0,0,14,3,0,0,0,3,13,0,0,0,0,0,0
0,0,0,0,0,0,0,14,3,0,0,0,3,13,0,0,0,0,0,0
0,0,0,0,0,0,0,63,0,0,414,0,0,59,0,0,0,0,0,0
0,0,0,0,0,0,0,63,0,0,3,0,0,59,0,0,0,0,0,0
0,0,0,0,0,0,0,63,0,0,58,0,0,59,0,0,0,0,0,0
0,0,0,0,0,0,0,63,0,0,0,0,0,59,0,0,0,0,0,0
0,0,0,0,0,0,0,3,0,0,0,0,0,3,0,0,0,0,0,0
0,0,0,0,0,0,0,63,0,0,0,0,0,59,0,0,0,0,0,0
0,0,0,0,0,0,0,63,0,0,0,0,0,59,0,0,0,0,0,0
0,0,0,0,0,0,0,3,69,16,3,16,69,3,0,0,0,0,0,0
0,0,0,0,0,0,0,0,0,0,0,0,0,0,0,0,0,0,0,0
0,0,0,0,0,0,0,0,0,0,0,0,0,0,0,0,0,0,0,0
0,0,0,0,0,0,0,0,0,0,0,0,0,0,0,0,0,0,0,0
0,0,0,0,0,0,0,0,0,0,0,0,0,0,0,0,0,0,0,0
0,0,0,0,0,0,0,0,0,0,0,0,0,0,0,0,0,0,0,0
0,0,0,0,0,0,0,0,0,0,0,0,0,0,0,0,0,0,0,0
0,0,0,0,0,0,0,0,0,0,0,0,0,0,0,0,0,0,0,0
0,0,0,0,0,0,0,0,0,0,0,0,0,0,0,0,0,0,0,0
0,0,0,0,0,0,0,0,0,0,0,0,0,0,0,0,0,0,0,0
0,0,0,0,0,0,0,0,0,0,0,0,0,0,0,0,0,0,0,0
0,0,0,0,0,0,0,0,0,0,0,0,0,0,0,0,0,0,0,0
0,0,0,0,0,0,0,0,0,0,0,0,0,0,0,0,0,0,0,0
0,0,0,0,0,0,0,0,0,0,0,0,0,0,0,0,0,0,0,0
0,0,0,0,0,0,0,0,0,0,0,0,0,0,0,0,0,0,0,0
0,0,0,0,0,0,0,0,0,0,0,0,0,0,0,0,0,0,0,0
0,0,0,0,0,0,0,0,0,0,0,0,0,0,0,0,0,0,0,0
0,0,0,0,0,0,0,0,0,0,0,0,0,0,0,0,0,0,0,0
:endlayer
layer: 28
0,0,0,0,0,0,0,0,0,0,0,0,0,0,0,0,0,0,0,0
0,0,0,0,0,0,0,0,0,0,0,0,0,0,0,0,0,0,0,0
0,0,0,0,0,0,0,14,3,4,4,4,3,13,0,0,0,0,0,0
0,0,0,0,0,0,0,63,65,0,0,0,65,59,0,0,0,0,0,0
0,0,0,0,0,0,0,63,65,0,0,0,65,59,0,0,0,0,0,0
0,0,0,0,0,0,0,14,3,0,0,0,3,13,0,0,0,0,0,0
0,0,0,0,0,0,0,63,65,0,0,0,65,59,0,0,0,0,0,0
0,0,0,0,0,0,0,63,65,0,0,0,65,59,0,0,0,0,0,0
0,0,0,0,0,0,0,63,65,0,3,0,65,59,0,0,0,0,0,0
0,0,0,0,0,0,0,63,65,0,0,0,65,59,0,0,0,0,0,0
0,0,0,0,0,0,0,14,65,3,0,3,65,13,0,0,0,0,0,0
0,0,0,0,0,0,0,14,65,3,0,3,65,13,0,0,0,0,0,0
0,0,0,0,0,0,0,63,65,0,0,0,65,59,0,0,0,0,0,0
0,0,0,0,0,0,0,63,65,0,3,0,65,59,0,0,0,0,0,0
0,0,0,0,0,0,0,63,65,0,0,0,65,59,0,0,0,0,0,0
0,0,0,0,0,0,0,14,65,3,0,3,65,13,0,0,0,0,0,0
0,0,0,0,0,0,0,14,65,3,0,3,65,13,0,0,0,0,0,0
0,0,0,0,0,0,0,63,65,0,0,0,65,59,0,0,0,0,0,0
0,0,0,0,0,0,0,63,65,0,3,0,65,59,0,0,0,0,0,0
0,0,0,0,0,0,0,63,65,0,0,0,65,59,0,0,0,0,0,0
0,0,0,0,0,0,0,14,65,3,0,3,65,13,0,0,0,0,0,0
0,0,0,0,0,0,0,14,65,3,0,3,65,13,0,0,0,0,0,0
0,0,0,0,0,0,0,63,65,0,0,0,65,59,0,0,0,0,0,0
0,0,0,0,0,0,0,63,65,0,3,0,65,59,0,0,0,0,0,0
0,0,0,0,0,0,0,63,65,0,0,0,65,59,0,0,0,0,0,0
0,0,0,0,0,0,0,14,65,3,0,3,65,13,0,0,0,0,0,0
0,0,0,0,0,0,0,14,65,3,0,3,65,13,0,0,0,0,0,0
0,0,0,0,0,0,0,63,65,0,0,0,65,59,0,0,0,0,0,0
0,0,0,0,0,0,0,63,65,0,3,0,65,59,0,0,0,0,0,0
0,0,0,0,0,0,0,63,65,0,0,0,65,59,0,0,0,0,0,0
0,0,0,0,0,0,0,14,65,3,0,3,65,13,0,0,0,0,0,0
0,0,0,0,0,0,0,14,65,3,0,3,65,13,0,0,0,0,0,0
0,0,0,0,0,0,0,63,65,0,0,0,65,59,0,0,0,0,0,0
0,0,0,0,0,0,0,63,65,0,3,0,65,59,0,0,0,0,0,0
0,0,0,0,0,0,0,63,65,0,0,0,65,59,0,0,0,0,0,0
0,0,0,0,0,0,0,14,65,3,0,3,65,13,0,0,0,0,0,0
0,0,0,0,0,0,0,14,65,3,0,3,65,13,0,0,0,0,0,0
0,0,0,0,0,0,0,63,65,0,0,0,65,59,0,0,0,0,0,0
0,0,0,0,0,0,0,63,65,0,3,0,65,59,0,0,0,0,0,0
0,0,0,0,0,0,0,63,65,0,0,0,65,59,0,0,0,0,0,0
0,0,0,0,0,0,0,63,65,0,0,0,65,59,0,0,0,0,0,0
0,0,0,0,0,0,0,14,3,0,0,0,3,13,0,0,0,0,0,0
0,0,0,0,0,0,0,63,65,0,0,0,65,59,0,0,0,0,0,0
0,0,0,0,0,0,0,63,65,0,0,0,65,59,0,0,0,0,0,0
0,0,0,0,0,0,0,14,3,69,3,69,3,13,0,0,0,0,0,0
0,0,0,0,0,0,0,0,0,0,0,0,0,0,0,0,0,0,0,0
0,0,0,0,0,0,0,0,0,0,0,0,0,0,0,0,0,0,0,0
0,0,0,0,0,0,0,0,0,0,0,0,0,0,0,0,0,0,0,0
0,0,0,0,0,0,0,0,0,0,0,0,0,0,0,0,0,0,0,0
0,0,0,0,0,0,0,0,0,0,0,0,0,0,0,0,0,0,0,0
0,0,0,0,0,0,0,0,0,0,0,0,0,0,0,0,0,0,0,0
0,0,0,0,0,0,0,0,0,0,0,0,0,0,0,0,0,0,0,0
0,0,0,0,0,0,0,0,0,0,0,0,0,0,0,0,0,0,0,0
0,0,0,0,0,0,0,0,0,0,0,0,0,0,0,0,0,0,0,0
0,0,0,0,0,0,0,0,0,0,0,0,0,0,0,0,0,0,0,0
0,0,0,0,0,0,0,0,0,0,0,0,0,0,0,0,0,0,0,0
0,0,0,0,0,0,0,0,0,0,0,0,0,0,0,0,0,0,0,0
0,0,0,0,0,0,0,0,0,0,0,0,0,0,0,0,0,0,0,0
0,0,0,0,0,0,0,0,0,0,0,0,0,0,0,0,0,0,0,0
0,0,0,0,0,0,0,0,0,0,0,0,0,0,0,0,0,0,0,0
0,0,0,0,0,0,0,0,0,0,0,0,0,0,0,0,0,0,0,0
0,0,0,0,0,0,0,0,0,0,0,0,0,0,0,0,0,0,0,0
:endlayer
layer: 29
0,0,0,0,0,0,0,0,0,0,0,0,0,0,0,0,0,0,0,0
0,0,0,0,0,0,0,0,0,0,0,0,0,0,0,0,0,0,0,0
0,0,0,0,0,0,0,0,14,3,4,3,13,0,0,0,0,0,0,0
0,0,0,0,0,0,0,0,63,65,0,65,59,0,0,0,0,0,0,0
0,0,0,0,0,0,0,0,63,65,0,65,59,0,0,0,0,0,0,0
0,0,0,0,0,0,0,0,14,3,0,3,13,0,0,0,0,0,0,0
0,0,0,0,0,0,0,0,63,65,0,65,59,0,0,0,0,0,0,0
0,0,0,0,0,0,0,0,63,65,0,65,59,0,0,0,0,0,0,0
0,0,0,0,0,0,0,0,63,65,3,65,59,0,0,0,0,0,0,0
0,0,0,0,0,0,0,0,63,65,0,65,59,0,0,0,0,0,0,0
0,0,0,0,0,0,0,0,14,65,3,65,13,0,0,0,0,0,0,0
0,0,0,0,0,0,0,0,14,65,3,65,13,0,0,0,0,0,0,0
0,0,0,0,0,0,0,0,63,65,0,65,59,0,0,0,0,0,0,0
0,0,0,0,0,0,0,0,63,65,3,65,59,0,0,0,0,0,0,0
0,0,0,0,0,0,0,0,63,65,0,65,59,0,0,0,0,0,0,0
0,0,0,0,0,0,0,0,14,65,3,65,13,0,0,0,0,0,0,0
0,0,0,0,0,0,0,0,14,65,3,65,13,0,0,0,0,0,0,0
0,0,0,0,0,0,0,0,63,65,0,65,59,0,0,0,0,0,0,0
0,0,0,0,0,0,0,0,63,65,3,65,59,0,0,0,0,0,0,0
0,0,0,0,0,0,0,0,63,65,0,65,59,0,0,0,0,0,0,0
0,0,0,0,0,0,0,0,14,65,3,65,13,0,0,0,0,0,0,0
0,0,0,0,0,0,0,0,14,65,3,65,13,0,0,0,0,0,0,0
0,0,0,0,0,0,0,0,63,65,0,65,59,0,0,0,0,0,0,0
0,0,0,0,0,0,0,0,63,65,3,65,59,0,0,0,0,0,0,0
0,0,0,0,0,0,0,0,63,65,0,65,59,0,0,0,0,0,0,0
0,0,0,0,0,0,0,0,14,65,3,65,13,0,0,0,0,0,0,0
0,0,0,0,0,0,0,0,14,65,3,65,13,0,0,0,0,0,0,0
0,0,0,0,0,0,0,0,63,65,0,65,59,0,0,0,0,0,0,0
0,0,0,0,0,0,0,0,63,65,3,65,59,0,0,0,0,0,0,0
0,0,0,0,0,0,0,0,63,65,0,65,59,0,0,0,0,0,0,0
0,0,0,0,0,0,0,0,14,65,3,65,13,0,0,0,0,0,0,0
0,0,0,0,0,0,0,0,14,65,3,65,13,0,0,0,0,0,0,0
0,0,0,0,0,0,0,0,63,65,0,65,59,0,0,0,0,0,0,0
0,0,0,0,0,0,0,0,63,65,3,65,59,0,0,0,0,0,0,0
0,0,0,0,0,0,0,0,63,65,0,65,59,0,0,0,0,0,0,0
0,0,0,0,0,0,0,0,14,65,3,65,13,0,0,0,0,0,0,0
0,0,0,0,0,0,0,0,14,65,3,65,13,0,0,0,0,0,0,0
0,0,0,0,0,0,0,0,63,65,0,65,59,0,0,0,0,0,0,0
0,0,0,0,0,0,0,0,63,65,3,65,59,0,0,0,0,0,0,0
0,0,0,0,0,0,0,0,63,65,0,65,59,0,0,0,0,0,0,0
0,0,0,0,0,0,0,0,63,65,0,65,59,0,0,0,0,0,0,0
0,0,0,0,0,0,0,0,14,3,0,3,13,0,0,0,0,0,0,0
0,0,0,0,0,0,0,0,63,65,0,65,59,0,0,0,0,0,0,0
0,0,0,0,0,0,0,0,63,65,0,65,59,0,0,0,0,0,0,0
0,0,0,0,0,0,0,0,14,3,4,3,13,0,0,0,0,0,0,0
0,0,0,0,0,0,0,0,0,0,0,0,0,0,0,0,0,0,0,0
0,0,0,0,0,0,0,0,0,0,0,0,0,0,0,0,0,0,0,0
0,0,0,0,0,0,0,0,0,0,0,0,0,0,0,0,0,0,0,0
0,0,0,0,0,0,0,0,0,0,0,0,0,0,0,0,0,0,0,0
0,0,0,0,0,0,0,0,0,0,0,0,0,0,0,0,0,0,0,0
0,0,0,0,0,0,0,0,0,0,0,0,0,0,0,0,0,0,0,0
0,0,0,0,0,0,0,0,0,0,0,0,0,0,0,0,0,0,0,0
0,0,0,0,0,0,0,0,0,0,0,0,0,0,0,0,0,0,0,0
0,0,0,0,0,0,0,0,0,0,0,0,0,0,0,0,0,0,0,0
0,0,0,0,0,0,0,0,0,0,0,0,0,0,0,0,0,0,0,0
0,0,0,0,0,0,0,0,0,0,0,0,0,0,0,0,0,0,0,0
0,0,0,0,0,0,0,0,0,0,0,0,0,0,0,0,0,0,0,0
0,0,0,0,0,0,0,0,0,0,0,0,0,0,0,0,0,0,0,0
0,0,0,0,0,0,0,0,0,0,0,0,0,0,0,0,0,0,0,0
0,0,0,0,0,0,0,0,0,0,0,0,0,0,0,0,0,0,0,0
0,0,0,0,0,0,0,0,0,0,0,0,0,0,0,0,0,0,0,0
0,0,0,0,0,0,0,0,0,0,0,0,0,0,0,0,0,0,0,0
:endlayer
layer: 30
0,0,0,0,0,0,0,0,0,0,0,0,0,0,0,0,0,0,0,0
0,0,0,0,0,0,0,0,0,0,0,0,0,0,0,0,0,0,0,0
0,0,0,0,0,0,0,0,0,14,3,13,0,0,0,0,0,0,0,0
0,0,0,0,0,0,0,0,0,63,65,59,0,0,0,0,0,0,0,0
0,0,0,0,0,0,0,0,0,63,65,59,0,0,0,0,0,0,0,0
0,0,0,0,0,0,0,0,0,14,3,13,0,0,0,0,0,0,0,0
0,0,0,0,0,0,0,0,0,63,65,59,0,0,0,0,0,0,0,0
0,0,0,0,0,0,0,0,0,63,65,59,0,0,0,0,0,0,0,0
0,0,0,0,0,0,0,0,0,63,65,59,0,0,0,0,0,0,0,0
0,0,0,0,0,0,0,0,0,63,65,59,0,0,0,0,0,0,0,0
0,0,0,0,0,0,0,0,0,14,65,13,0,0,0,0,0,0,0,0
0,0,0,0,0,0,0,0,0,14,65,13,0,0,0,0,0,0,0,0
0,0,0,0,0,0,0,0,0,63,65,59,0,0,0,0,0,0,0,0
0,0,0,0,0,0,0,0,0,63,65,59,0,0,0,0,0,0,0,0
0,0,0,0,0,0,0,0,0,63,65,59,0,0,0,0,0,0,0,0
0,0,0,0,0,0,0,0,0,14,65,13,0,0,0,0,0,0,0,0
0,0,0,0,0,0,0,0,0,14,65,13,0,0,0,0,0,0,0,0
0,0,0,0,0,0,0,0,0,63,65,59,0,0,0,0,0,0,0,0
0,0,0,0,0,0,0,0,0,63,65,59,0,0,0,0,0,0,0,0
0,0,0,0,0,0,0,0,0,63,65,59,0,0,0,0,0,0,0,0
0,0,0,0,0,0,0,0,0,14,65,13,0,0,0,0,0,0,0,0
0,0,0,0,0,0,0,0,0,14,65,13,0,0,0,0,0,0,0,0
0,0,0,0,0,0,0,0,0,63,65,59,0,0,0,0,0,0,0,0
0,0,0,0,0,0,0,0,0,63,65,59,0,0,0,0,0,0,0,0
0,0,0,0,0,0,0,0,0,63,65,59,0,0,0,0,0,0,0,0
0,0,0,0,0,0,0,0,0,14,65,13,0,0,0,0,0,0,0,0
0,0,0,0,0,0,0,0,0,14,65,13,0,0,0,0,0,0,0,0
0,0,0,0,0,0,0,0,0,63,65,59,0,0,0,0,0,0,0,0
0,0,0,0,0,0,0,0,0,63,65,59,0,0,0,0,0,0,0,0
0,0,0,0,0,0,0,0,0,63,65,59,0,0,0,0,0,0,0,0
0,0,0,0,0,0,0,0,0,14,65,13,0,0,0,0,0,0,0,0
0,0,0,0,0,0,0,0,0,14,65,13,0,0,0,0,0,0,0,0
0,0,0,0,0,0,0,0,0,63,65,59,0,0,0,0,0,0,0,0
0,0,0,0,0,0,0,0,0,63,65,59,0,0,0,0,0,0,0,0
0,0,0,0,0,0,0,0,0,63,65,59,0,0,0,0,0,0,0,0
0,0,0,0,0,0,0,0,0,14,65,13,0,0,0,0,0,0,0,0
0,0,0,0,0,0,0,0,0,14,65,13,0,0,0,0,0,0,0,0
0,0,0,0,0,0,0,0,0,63,65,59,0,0,0,0,0,0,0,0
0,0,0,0,0,0,0,0,0,63,65,59,0,0,0,0,0,0,0,0
0,0,0,0,0,0,0,0,0,63,65,59,0,0,0,0,0,0,0,0
0,0,0,0,0,0,0,0,0,63,65,59,0,0,0,0,0,0,0,0
0,0,0,0,0,0,0,0,0,14,3,13,0,0,0,0,0,0,0,0
0,0,0,0,0,0,0,0,0,63,65,59,0,0,0,0,0,0,0,0
0,0,0,0,0,0,0,0,0,63,65,59,0,0,0,0,0,0,0,0
0,0,0,0,0,0,0,0,0,14,3,13,0,0,0,0,0,0,0,0
0,0,0,0,0,0,0,0,0,0,0,0,0,0,0,0,0,0,0,0
0,0,0,0,0,0,0,0,0,0,0,0,0,0,0,0,0,0,0,0
0,0,0,0,0,0,0,0,0,0,0,0,0,0,0,0,0,0,0,0
0,0,0,0,0,0,0,0,0,0,0,0,0,0,0,0,0,0,0,0
0,0,0,0,0,0,0,0,0,0,0,0,0,0,0,0,0,0,0,0
0,0,0,0,0,0,0,0,0,0,0,0,0,0,0,0,0,0,0,0
0,0,0,0,0,0,0,0,0,0,0,0,0,0,0,0,0,0,0,0
0,0,0,0,0,0,0,0,0,0,0,0,0,0,0,0,0,0,0,0
0,0,0,0,0,0,0,0,0,0,0,0,0,0,0,0,0,0,0,0
0,0,0,0,0,0,0,0,0,0,0,0,0,0,0,0,0,0,0,0
0,0,0,0,0,0,0,0,0,0,0,0,0,0,0,0,0,0,0,0
0,0,0,0,0,0,0,0,0,0,0,0,0,0,0,0,0,0,0,0
0,0,0,0,0,0,0,0,0,0,0,0,0,0,0,0,0,0,0,0
0,0,0,0,0,0,0,0,0,0,0,0,0,0,0,0,0,0,0,0
0,0,0,0,0,0,0,0,0,0,0,0,0,0,0,0,0,0,0,0
0,0,0,0,0,0,0,0,0,0,0,0,0,0,0,0,0,0,0,0
0,0,0,0,0,0,0,0,0,0,0,0,0,0,0,0,0,0,0,0
:endlayer
layer: 31
0,0,0,0,0,0,0,0,0,0,0,0,0,0,0,0,0,0,0,0
0,0,0,0,0,0,0,0,0,0,0,0,0,0,0,0,0,0,0,0
0,0,0,0,0,0,0,0,0,0,44,0,0,0,0,0,0,0,0,0
0,0,0,0,0,0,0,0,0,0,428,0,0,0,0,0,0,0,0,0
0,0,0,0,0,0,0,0,0,0,428,0,0,0,0,0,0,0,0,0
0,0,0,0,0,0,0,0,0,0,44,0,0,0,0,0,0,0,0,0
0,0,0,0,0,0,0,0,0,0,428,0,0,0,0,0,0,0,0,0
0,0,0,0,0,0,0,0,0,0,428,0,0,0,0,0,0,0,0,0
0,0,0,0,0,0,0,0,0,0,428,0,0,0,0,0,0,0,0,0
0,0,0,0,0,0,0,0,0,0,428,0,0,0,0,0,0,0,0,0
0,0,0,0,0,0,0,0,0,0,44,0,0,0,0,0,0,0,0,0
0,0,0,0,0,0,0,0,0,0,44,0,0,0,0,0,0,0,0,0
0,0,0,0,0,0,0,0,0,0,428,0,0,0,0,0,0,0,0,0
0,0,0,0,0,0,0,0,0,0,428,0,0,0,0,0,0,0,0,0
0,0,0,0,0,0,0,0,0,0,428,0,0,0,0,0,0,0,0,0
0,0,0,0,0,0,0,0,0,0,44,0,0,0,0,0,0,0,0,0
0,0,0,0,0,0,0,0,0,0,44,0,0,0,0,0,0,0,0,0
0,0,0,0,0,0,0,0,0,0,428,0,0,0,0,0,0,0,0,0
0,0,0,0,0,0,0,0,0,0,428,0,0,0,0,0,0,0,0,0
0,0,0,0,0,0,0,0,0,0,428,0,0,0,0,0,0,0,0,0
0,0,0,0,0,0,0,0,0,0,44,0,0,0,0,0,0,0,0,0
0,0,0,0,0,0,0,0,0,0,44,0,0,0,0,0,0,0,0,0
0,0,0,0,0,0,0,0,0,0,428,0,0,0,0,0,0,0,0,0
0,0,0,0,0,0,0,0,0,0,428,0,0,0,0,0,0,0,0,0
0,0,0,0,0,0,0,0,0,0,428,0,0,0,0,0,0,0,0,0
0,0,0,0,0,0,0,0,0,0,44,0,0,0,0,0,0,0,0,0
0,0,0,0,0,0,0,0,0,0,44,0,0,0,0,0,0,0,0,0
0,0,0,0,0,0,0,0,0,0,428,0,0,0,0,0,0,0,0,0
0,0,0,0,0,0,0,0,0,0,428,0,0,0,0,0,0,0,0,0
0,0,0,0,0,0,0,0,0,0,428,0,0,0,0,0,0,0,0,0
0,0,0,0,0,0,0,0,0,0,44,0,0,0,0,0,0,0,0,0
0,0,0,0,0,0,0,0,0,0,44,0,0,0,0,0,0,0,0,0
0,0,0,0,0,0,0,0,0,0,428,0,0,0,0,0,0,0,0,0
0,0,0,0,0,0,0,0,0,0,428,0,0,0,0,0,0,0,0,0
0,0,0,0,0,0,0,0,0,0,428,0,0,0,0,0,0,0,0,0
0,0,0,0,0,0,0,0,0,0,44,0,0,0,0,0,0,0,0,0
0,0,0,0,0,0,0,0,0,0,44,0,0,0,0,0,0,0,0,0
0,0,0,0,0,0,0,0,0,0,428,0,0,0,0,0,0,0,0,0
0,0,0,0,0,0,0,0,0,0,428,0,0,0,0,0,0,0,0,0
0,0,0,0,0,0,0,0,0,0,428,0,0,0,0,0,0,0,0,0
0,0,0,0,0,0,0,0,0,0,428,0,0,0,0,0,0,0,0,0
0,0,0,0,0,0,0,0,0,0,44,0,0,0,0,0,0,0,0,0
0,0,0,0,0,0,0,0,0,0,428,0,0,0,0,0,0,0,0,0
0,0,0,0,0,0,0,0,0,0,428,0,0,0,0,0,0,0,0,0
0,0,0,0,0,0,0,0,0,0,44,0,0,0,0,0,0,0,0,0
0,0,0,0,0,0,0,0,0,0,0,0,0,0,0,0,0,0,0,0
0,0,0,0,0,0,0,0,0,0,0,0,0,0,0,0,0,0,0,0
0,0,0,0,0,0,0,0,0,0,0,0,0,0,0,0,0,0,0,0
0,0,0,0,0,0,0,0,0,0,0,0,0,0,0,0,0,0,0,0
0,0,0,0,0,0,0,0,0,0,0,0,0,0,0,0,0,0,0,0
0,0,0,0,0,0,0,0,0,0,0,0,0,0,0,0,0,0,0,0
0,0,0,0,0,0,0,0,0,0,0,0,0,0,0,0,0,0,0,0
0,0,0,0,0,0,0,0,0,0,0,0,0,0,0,0,0,0,0,0
0,0,0,0,0,0,0,0,0,0,0,0,0,0,0,0,0,0,0,0
0,0,0,0,0,0,0,0,0,0,0,0,0,0,0,0,0,0,0,0
0,0,0,0,0,0,0,0,0,0,0,0,0,0,0,0,0,0,0,0
0,0,0,0,0,0,0,0,0,0,0,0,0,0,0,0,0,0,0,0
0,0,0,0,0,0,0,0,0,0,0,0,0,0,0,0,0,0,0,0
0,0,0,0,0,0,0,0,0,0,0,0,0,0,0,0,0,0,0,0
0,0,0,0,0,0,0,0,0,0,0,0,0,0,0,0,0,0,0,0
0,0,0,0,0,0,0,0,0,0,0,0,0,0,0,0,0,0,0,0
0,0,0,0,0,0,0,0,0,0,0,0,0,0,0,0,0,0,0,0
:endlayer
layer: 32
0,0,0,0,0,0,0,0,0,0,0,0,0,0,0,0,0,0,0,0
0,0,0,0,0,0,0,0,0,0,0,0,0,0,0,0,0,0,0,0
0,0,0,0,0,0,0,0,0,0,0,0,0,0,0,0,0,0,0,0
0,0,0,0,0,0,0,0,0,0,0,0,0,0,0,0,0,0,0,0
0,0,0,0,0,0,0,0,0,0,0,0,0,0,0,0,0,0,0,0
0,0,0,0,0,0,0,0,0,0,0,0,0,0,0,0,0,0,0,0
0,0,0,0,0,0,0,0,0,0,0,0,0,0,0,0,0,0,0,0
0,0,0,0,0,0,0,0,0,0,0,0,0,0,0,0,0,0,0,0
0,0,0,0,0,0,0,0,0,0,0,0,0,0,0,0,0,0,0,0
0,0,0,0,0,0,0,0,0,0,0,0,0,0,0,0,0,0,0,0
0,0,0,0,0,0,0,0,0,0,0,0,0,0,0,0,0,0,0,0
0,0,0,0,0,0,0,0,0,0,0,0,0,0,0,0,0,0,0,0
0,0,0,0,0,0,0,0,0,0,0,0,0,0,0,0,0,0,0,0
0,0,0,0,0,0,0,0,0,0,0,0,0,0,0,0,0,0,0,0
0,0,0,0,0,0,0,0,0,0,0,0,0,0,0,0,0,0,0,0
0,0,0,0,0,0,0,0,0,0,0,0,0,0,0,0,0,0,0,0
0,0,0,0,0,0,0,0,0,0,0,0,0,0,0,0,0,0,0,0
0,0,0,0,0,0,0,0,0,0,0,0,0,0,0,0,0,0,0,0
0,0,0,0,0,0,0,0,0,0,0,0,0,0,0,0,0,0,0,0
0,0,0,0,0,0,0,0,0,0,0,0,0,0,0,0,0,0,0,0
0,0,0,0,0,0,0,0,0,0,0,0,0,0,0,0,0,0,0,0
0,0,0,0,0,0,0,0,0,0,0,0,0,0,0,0,0,0,0,0
0,0,0,0,0,0,0,0,0,0,0,0,0,0,0,0,0,0,0,0
0,0,0,0,0,0,0,0,0,0,0,0,0,0,0,0,0,0,0,0
0,0,0,0,0,0,0,0,0,0,0,0,0,0,0,0,0,0,0,0
0,0,0,0,0,0,0,0,0,0,0,0,0,0,0,0,0,0,0,0
0,0,0,0,0,0,0,0,0,0,0,0,0,0,0,0,0,0,0,0
0,0,0,0,0,0,0,0,0,0,0,0,0,0,0,0,0,0,0,0
0,0,0,0,0,0,0,0,0,0,0,0,0,0,0,0,0,0,0,0
0,0,0,0,0,0,0,0,0,0,0,0,0,0,0,0,0,0,0,0
0,0,0,0,0,0,0,0,0,0,0,0,0,0,0,0,0,0,0,0
0,0,0,0,0,0,0,0,0,0,0,0,0,0,0,0,0,0,0,0
0,0,0,0,0,0,0,0,0,0,0,0,0,0,0,0,0,0,0,0
0,0,0,0,0,0,0,0,0,0,0,0,0,0,0,0,0,0,0,0
0,0,0,0,0,0,0,0,0,0,0,0,0,0,0,0,0,0,0,0
0,0,0,0,0,0,0,0,0,0,0,0,0,0,0,0,0,0,0,0
0,0,0,0,0,0,0,0,0,0,0,0,0,0,0,0,0,0,0,0
0,0,0,0,0,0,0,0,0,0,0,0,0,0,0,0,0,0,0,0
0,0,0,0,0,0,0,0,0,0,0,0,0,0,0,0,0,0,0,0
0,0,0,0,0,0,0,0,0,0,0,0,0,0,0,0,0,0,0,0
0,0,0,0,0,0,0,0,0,0,0,0,0,0,0,0,0,0,0,0
0,0,0,0,0,0,0,0,0,0,0,0,0,0,0,0,0,0,0,0
0,0,0,0,0,0,0,0,0,0,0,0,0,0,0,0,0,0,0,0
0,0,0,0,0,0,0,0,0,0,0,0,0,0,0,0,0,0,0,0
0,0,0,0,0,0,0,0,0,0,0,0,0,0,0,0,0,0,0,0
0,0,0,0,0,0,0,0,0,0,0,0,0,0,0,0,0,0,0,0
0,0,0,0,0,0,0,0,0,0,0,0,0,0,0,0,0,0,0,0
0,0,0,0,0,0,0,0,0,0,0,0,0,0,0,0,0,0,0,0
0,0,0,0,0,0,0,0,0,0,0,0,0,0,0,0,0,0,0,0
0,0,0,0,0,0,0,0,0,0,0,0,0,0,0,0,0,0,0,0
0,0,0,0,0,0,0,0,0,0,0,0,0,0,0,0,0,0,0,0
0,0,0,0,0,0,0,0,0,0,0,0,0,0,0,0,0,0,0,0
0,0,0,0,0,0,0,0,0,0,0,0,0,0,0,0,0,0,0,0
0,0,0,0,0,0,0,0,0,0,0,0,0,0,0,0,0,0,0,0
0,0,0,0,0,0,0,0,0,0,0,0,0,0,0,0,0,0,0,0
0,0,0,0,0,0,0,0,0,0,0,0,0,0,0,0,0,0,0,0
0,0,0,0,0,0,0,0,0,0,0,0,0,0,0,0,0,0,0,0
0,0,0,0,0,0,0,0,0,0,0,0,0,0,0,0,0,0,0,0
0,0,0,0,0,0,0,0,0,0,0,0,0,0,0,0,0,0,0,0
0,0,0,0,0,0,0,0,0,0,0,0,0,0,0,0,0,0,0,0
0,0,0,0,0,0,0,0,0,0,0,0,0,0,0,0,0,0,0,0
0,0,0,0,0,0,0,0,0,0,0,0,0,0,0,0,0,0,0,0
:endlayer
layer: 33
0,0,0,0,0,0,0,0,0,0,0,0,0,0,0,0,0,0,0,0
0,0,0,0,0,0,0,0,0,0,0,0,0,0,0,0,0,0,0,0
0,0,0,0,0,0,0,0,0,0,0,0,0,0,0,0,0,0,0,0
0,0,0,0,0,0,0,0,0,0,0,0,0,0,0,0,0,0,0,0
0,0,0,0,0,0,0,0,0,0,0,0,0,0,0,0,0,0,0,0
0,0,0,0,0,0,0,0,0,0,0,0,0,0,0,0,0,0,0,0
0,0,0,0,0,0,0,0,0,0,0,0,0,0,0,0,0,0,0,0
0,0,0,0,0,0,0,0,0,0,0,0,0,0,0,0,0,0,0,0
0,0,0,0,0,0,0,0,0,0,0,0,0,0,0,0,0,0,0,0
0,0,0,0,0,0,0,0,0,0,0,0,0,0,0,0,0,0,0,0
0,0,0,0,0,0,0,0,0,0,0,0,0,0,0,0,0,0,0,0
0,0,0,0,0,0,0,0,0,0,0,0,0,0,0,0,0,0,0,0
0,0,0,0,0,0,0,0,0,0,0,0,0,0,0,0,0,0,0,0
0,0,0,0,0,0,0,0,0,0,0,0,0,0,0,0,0,0,0,0
0,0,0,0,0,0,0,0,0,0,0,0,0,0,0,0,0,0,0,0
0,0,0,0,0,0,0,0,0,0,0,0,0,0,0,0,0,0,0,0
0,0,0,0,0,0,0,0,0,0,0,0,0,0,0,0,0,0,0,0
0,0,0,0,0,0,0,0,0,0,0,0,0,0,0,0,0,0,0,0
0,0,0,0,0,0,0,0,0,0,0,0,0,0,0,0,0,0,0,0
0,0,0,0,0,0,0,0,0,0,0,0,0,0,0,0,0,0,0,0
0,0,0,0,0,0,0,0,0,0,0,0,0,0,0,0,0,0,0,0
0,0,0,0,0,0,0,0,0,0,0,0,0,0,0,0,0,0,0,0
0,0,0,0,0,0,0,0,0,0,0,0,0,0,0,0,0,0,0,0
0,0,0,0,0,0,0,0,0,0,0,0,0,0,0,0,0,0,0,0
0,0,0,0,0,0,0,0,0,0,0,0,0,0,0,0,0,0,0,0
0,0,0,0,0,0,0,0,0,0,0,0,0,0,0,0,0,0,0,0
0,0,0,0,0,0,0,0,0,0,0,0,0,0,0,0,0,0,0,0
0,0,0,0,0,0,0,0,0,0,0,0,0,0,0,0,0,0,0,0
0,0,0,0,0,0,0,0,0,0,0,0,0,0,0,0,0,0,0,0
0,0,0,0,0,0,0,0,0,0,0,0,0,0,0,0,0,0,0,0
0,0,0,0,0,0,0,0,0,0,0,0,0,0,0,0,0,0,0,0
0,0,0,0,0,0,0,0,0,0,0,0,0,0,0,0,0,0,0,0
0,0,0,0,0,0,0,0,0,0,0,0,0,0,0,0,0,0,0,0
0,0,0,0,0,0,0,0,0,0,0,0,0,0,0,0,0,0,0,0
0,0,0,0,0,0,0,0,0,0,0,0,0,0,0,0,0,0,0,0
0,0,0,0,0,0,0,0,0,0,0,0,0,0,0,0,0,0,0,0
0,0,0,0,0,0,0,0,0,0,0,0,0,0,0,0,0,0,0,0
0,0,0,0,0,0,0,0,0,0,0,0,0,0,0,0,0,0,0,0
0,0,0,0,0,0,0,0,0,0,0,0,0,0,0,0,0,0,0,0
0,0,0,0,0,0,0,0,0,0,0,0,0,0,0,0,0,0,0,0
0,0,0,0,0,0,0,0,0,0,0,0,0,0,0,0,0,0,0,0
0,0,0,0,0,0,0,0,0,0,0,0,0,0,0,0,0,0,0,0
0,0,0,0,0,0,0,0,0,0,0,0,0,0,0,0,0,0,0,0
0,0,0,0,0,0,0,0,0,0,0,0,0,0,0,0,0,0,0,0
0,0,0,0,0,0,0,0,0,0,0,0,0,0,0,0,0,0,0,0
0,0,0,0,0,0,0,0,0,0,0,0,0,0,0,0,0,0,0,0
0,0,0,0,0,0,0,0,0,0,0,0,0,0,0,0,0,0,0,0
0,0,0,0,0,0,0,0,0,0,0,0,0,0,0,0,0,0,0,0
0,0,0,0,0,0,0,0,0,0,0,0,0,0,0,0,0,0,0,0
0,0,0,0,0,0,0,0,0,0,0,0,0,0,0,0,0,0,0,0
0,0,0,0,0,0,0,0,0,0,0,0,0,0,0,0,0,0,0,0
0,0,0,0,0,0,0,0,0,0,0,0,0,0,0,0,0,0,0,0
0,0,0,0,0,0,0,0,0,0,0,0,0,0,0,0,0,0,0,0
0,0,0,0,0,0,0,0,0,0,0,0,0,0,0,0,0,0,0,0
0,0,0,0,0,0,0,0,0,0,0,0,0,0,0,0,0,0,0,0
0,0,0,0,0,0,0,0,0,0,0,0,0,0,0,0,0,0,0,0
0,0,0,0,0,0,0,0,0,0,0,0,0,0,0,0,0,0,0,0
0,0,0,0,0,0,0,0,0,0,0,0,0,0,0,0,0,0,0,0
0,0,0,0,0,0,0,0,0,0,0,0,0,0,0,0,0,0,0,0
0,0,0,0,0,0,0,0,0,0,0,0,0,0,0,0,0,0,0,0
0,0,0,0,0,0,0,0,0,0,0,0,0,0,0,0,0,0,0,0
0,0,0,0,0,0,0,0,0,0,0,0,0,0,0,0,0,0,0,0
:endlayer
layer: 34
0,0,0,0,0,0,0,0,0,0,0,0,0,0,0,0,0,0,0,0
0,0,0,0,0,0,0,0,0,0,0,0,0,0,0,0,0,0,0,0
0,0,0,0,0,0,0,0,0,0,0,0,0,0,0,0,0,0,0,0
0,0,0,0,0,0,0,0,0,0,0,0,0,0,0,0,0,0,0,0
0,0,0,0,0,0,0,0,0,0,0,0,0,0,0,0,0,0,0,0
0,0,0,0,0,0,0,0,0,0,0,0,0,0,0,0,0,0,0,0
0,0,0,0,0,0,0,0,0,0,0,0,0,0,0,0,0,0,0,0
0,0,0,0,0,0,0,0,0,0,0,0,0,0,0,0,0,0,0,0
0,0,0,0,0,0,0,0,0,0,0,0,0,0,0,0,0,0,0,0
0,0,0,0,0,0,0,0,0,0,0,0,0,0,0,0,0,0,0,0
0,0,0,0,0,0,0,0,0,0,0,0,0,0,0,0,0,0,0,0
0,0,0,0,0,0,0,0,0,0,0,0,0,0,0,0,0,0,0,0
0,0,0,0,0,0,0,0,0,0,0,0,0,0,0,0,0,0,0,0
0,0,0,0,0,0,0,0,0,0,0,0,0,0,0,0,0,0,0,0
0,0,0,0,0,0,0,0,0,0,0,0,0,0,0,0,0,0,0,0
0,0,0,0,0,0,0,0,0,0,0,0,0,0,0,0,0,0,0,0
0,0,0,0,0,0,0,0,0,0,0,0,0,0,0,0,0,0,0,0
0,0,0,0,0,0,0,0,0,0,0,0,0,0,0,0,0,0,0,0
0,0,0,0,0,0,0,0,0,0,0,0,0,0,0,0,0,0,0,0
0,0,0,0,0,0,0,0,0,0,0,0,0,0,0,0,0,0,0,0
0,0,0,0,0,0,0,0,0,0,0,0,0,0,0,0,0,0,0,0
0,0,0,0,0,0,0,0,0,0,0,0,0,0,0,0,0,0,0,0
0,0,0,0,0,0,0,0,0,0,0,0,0,0,0,0,0,0,0,0
0,0,0,0,0,0,0,0,0,0,0,0,0,0,0,0,0,0,0,0
0,0,0,0,0,0,0,0,0,0,0,0,0,0,0,0,0,0,0,0
0,0,0,0,0,0,0,0,0,0,0,0,0,0,0,0,0,0,0,0
0,0,0,0,0,0,0,0,0,0,0,0,0,0,0,0,0,0,0,0
0,0,0,0,0,0,0,0,0,0,0,0,0,0,0,0,0,0,0,0
0,0,0,0,0,0,0,0,0,0,0,0,0,0,0,0,0,0,0,0
0,0,0,0,0,0,0,0,0,0,0,0,0,0,0,0,0,0,0,0
0,0,0,0,0,0,0,0,0,0,0,0,0,0,0,0,0,0,0,0
0,0,0,0,0,0,0,0,0,0,0,0,0,0,0,0,0,0,0,0
0,0,0,0,0,0,0,0,0,0,0,0,0,0,0,0,0,0,0,0
0,0,0,0,0,0,0,0,0,0,0,0,0,0,0,0,0,0,0,0
0,0,0,0,0,0,0,0,0,0,0,0,0,0,0,0,0,0,0,0
0,0,0,0,0,0,0,0,0,0,0,0,0,0,0,0,0,0,0,0
0,0,0,0,0,0,0,0,0,0,0,0,0,0,0,0,0,0,0,0
0,0,0,0,0,0,0,0,0,0,0,0,0,0,0,0,0,0,0,0
0,0,0,0,0,0,0,0,0,0,0,0,0,0,0,0,0,0,0,0
0,0,0,0,0,0,0,0,0,0,0,0,0,0,0,0,0,0,0,0
0,0,0,0,0,0,0,0,0,0,0,0,0,0,0,0,0,0,0,0
0,0,0,0,0,0,0,0,0,0,0,0,0,0,0,0,0,0,0,0
0,0,0,0,0,0,0,0,0,0,0,0,0,0,0,0,0,0,0,0
0,0,0,0,0,0,0,0,0,0,0,0,0,0,0,0,0,0,0,0
0,0,0,0,0,0,0,0,0,0,0,0,0,0,0,0,0,0,0,0
0,0,0,0,0,0,0,0,0,0,0,0,0,0,0,0,0,0,0,0
0,0,0,0,0,0,0,0,0,0,0,0,0,0,0,0,0,0,0,0
0,0,0,0,0,0,0,0,0,0,0,0,0,0,0,0,0,0,0,0
0,0,0,0,0,0,0,0,0,0,0,0,0,0,0,0,0,0,0,0
0,0,0,0,0,0,0,0,0,0,0,0,0,0,0,0,0,0,0,0
0,0,0,0,0,0,0,0,0,0,0,0,0,0,0,0,0,0,0,0
0,0,0,0,0,0,0,0,0,0,0,0,0,0,0,0,0,0,0,0
0,0,0,0,0,0,0,0,0,0,0,0,0,0,0,0,0,0,0,0
0,0,0,0,0,0,0,0,0,0,0,0,0,0,0,0,0,0,0,0
0,0,0,0,0,0,0,0,0,0,0,0,0,0,0,0,0,0,0,0
0,0,0,0,0,0,0,0,0,0,0,0,0,0,0,0,0,0,0,0
0,0,0,0,0,0,0,0,0,0,0,0,0,0,0,0,0,0,0,0
0,0,0,0,0,0,0,0,0,0,0,0,0,0,0,0,0,0,0,0
0,0,0,0,0,0,0,0,0,0,0,0,0,0,0,0,0,0,0,0
0,0,0,0,0,0,0,0,0,0,0,0,0,0,0,0,0,0,0,0
0,0,0,0,0,0,0,0,0,0,0,0,0,0,0,0,0,0,0,0
0,0,0,0,0,0,0,0,0,0,0,0,0,0,0,0,0,0,0,0
:endlayer
layer: 35
0,0,0,0,0,0,0,0,0,0,0,0,0,0,0,0,0,0,0,0
0,0,0,0,0,0,0,0,0,0,0,0,0,0,0,0,0,0,0,0
0,0,0,0,0,0,0,0,0,0,0,0,0,0,0,0,0,0,0,0
0,0,0,0,0,0,0,0,0,0,0,0,0,0,0,0,0,0,0,0
0,0,0,0,0,0,0,0,0,0,0,0,0,0,0,0,0,0,0,0
0,0,0,0,0,0,0,0,0,0,0,0,0,0,0,0,0,0,0,0
0,0,0,0,0,0,0,0,0,0,0,0,0,0,0,0,0,0,0,0
0,0,0,0,0,0,0,0,0,0,0,0,0,0,0,0,0,0,0,0
0,0,0,0,0,0,0,0,0,0,0,0,0,0,0,0,0,0,0,0
0,0,0,0,0,0,0,0,0,0,0,0,0,0,0,0,0,0,0,0
0,0,0,0,0,0,0,0,0,0,0,0,0,0,0,0,0,0,0,0
0,0,0,0,0,0,0,0,0,0,0,0,0,0,0,0,0,0,0,0
0,0,0,0,0,0,0,0,0,0,0,0,0,0,0,0,0,0,0,0
0,0,0,0,0,0,0,0,0,0,0,0,0,0,0,0,0,0,0,0
0,0,0,0,0,0,0,0,0,0,0,0,0,0,0,0,0,0,0,0
0,0,0,0,0,0,0,0,0,0,0,0,0,0,0,0,0,0,0,0
0,0,0,0,0,0,0,0,0,0,0,0,0,0,0,0,0,0,0,0
0,0,0,0,0,0,0,0,0,0,0,0,0,0,0,0,0,0,0,0
0,0,0,0,0,0,0,0,0,0,0,0,0,0,0,0,0,0,0,0
0,0,0,0,0,0,0,0,0,0,0,0,0,0,0,0,0,0,0,0
0,0,0,0,0,0,0,0,0,0,0,0,0,0,0,0,0,0,0,0
0,0,0,0,0,0,0,0,0,0,0,0,0,0,0,0,0,0,0,0
0,0,0,0,0,0,0,0,0,0,0,0,0,0,0,0,0,0,0,0
0,0,0,0,0,0,0,0,0,0,0,0,0,0,0,0,0,0,0,0
0,0,0,0,0,0,0,0,0,0,0,0,0,0,0,0,0,0,0,0
0,0,0,0,0,0,0,0,0,0,0,0,0,0,0,0,0,0,0,0
0,0,0,0,0,0,0,0,0,0,0,0,0,0,0,0,0,0,0,0
0,0,0,0,0,0,0,0,0,0,0,0,0,0,0,0,0,0,0,0
0,0,0,0,0,0,0,0,0,0,0,0,0,0,0,0,0,0,0,0
0,0,0,0,0,0,0,0,0,0,0,0,0,0,0,0,0,0,0,0
0,0,0,0,0,0,0,0,0,0,0,0,0,0,0,0,0,0,0,0
0,0,0,0,0,0,0,0,0,0,0,0,0,0,0,0,0,0,0,0
0,0,0,0,0,0,0,0,0,0,0,0,0,0,0,0,0,0,0,0
0,0,0,0,0,0,0,0,0,0,0,0,0,0,0,0,0,0,0,0
0,0,0,0,0,0,0,0,0,0,0,0,0,0,0,0,0,0,0,0
0,0,0,0,0,0,0,0,0,0,0,0,0,0,0,0,0,0,0,0
0,0,0,0,0,0,0,0,0,0,0,0,0,0,0,0,0,0,0,0
0,0,0,0,0,0,0,0,0,0,0,0,0,0,0,0,0,0,0,0
0,0,0,0,0,0,0,0,0,0,0,0,0,0,0,0,0,0,0,0
0,0,0,0,0,0,0,0,0,0,0,0,0,0,0,0,0,0,0,0
0,0,0,0,0,0,0,0,0,0,0,0,0,0,0,0,0,0,0,0
0,0,0,0,0,0,0,0,0,0,0,0,0,0,0,0,0,0,0,0
0,0,0,0,0,0,0,0,0,0,0,0,0,0,0,0,0,0,0,0
0,0,0,0,0,0,0,0,0,0,0,0,0,0,0,0,0,0,0,0
0,0,0,0,0,0,0,0,0,0,0,0,0,0,0,0,0,0,0,0
0,0,0,0,0,0,0,0,0,0,0,0,0,0,0,0,0,0,0,0
0,0,0,0,0,0,0,0,0,0,0,0,0,0,0,0,0,0,0,0
0,0,0,0,0,0,0,0,0,0,0,0,0,0,0,0,0,0,0,0
0,0,0,0,0,0,0,0,0,0,0,0,0,0,0,0,0,0,0,0
0,0,0,0,0,0,0,0,0,0,0,0,0,0,0,0,0,0,0,0
0,0,0,0,0,0,0,0,0,0,0,0,0,0,0,0,0,0,0,0
0,0,0,0,0,0,0,0,0,0,0,0,0,0,0,0,0,0,0,0
0,0,0,0,0,0,0,0,0,0,0,0,0,0,0,0,0,0,0,0
0,0,0,0,0,0,0,0,0,0,0,0,0,0,0,0,0,0,0,0
0,0,0,0,0,0,0,0,0,0,0,0,0,0,0,0,0,0,0,0
0,0,0,0,0,0,0,0,0,0,0,0,0,0,0,0,0,0,0,0
0,0,0,0,0,0,0,0,0,0,0,0,0,0,0,0,0,0,0,0
0,0,0,0,0,0,0,0,0,0,0,0,0,0,0,0,0,0,0,0
0,0,0,0,0,0,0,0,0,0,0,0,0,0,0,0,0,0,0,0
0,0,0,0,0,0,0,0,0,0,0,0,0,0,0,0,0,0,0,0
0,0,0,0,0,0,0,0,0,0,0,0,0,0,0,0,0,0,0,0
0,0,0,0,0,0,0,0,0,0,0,0,0,0,0,0,0,0,0,0
:endlayer
layer: 36
0,0,0,0,0,0,0,0,0,0,0,0,0,0,0,0,0,0,0,0
0,0,0,0,0,0,0,0,0,0,0,0,0,0,0,0,0,0,0,0
0,0,0,0,0,0,0,0,0,0,0,0,0,0,0,0,0,0,0,0
0,0,0,0,0,0,0,0,0,0,0,0,0,0,0,0,0,0,0,0
0,0,0,0,0,0,0,0,0,0,0,0,0,0,0,0,0,0,0,0
0,0,0,0,0,0,0,0,0,0,0,0,0,0,0,0,0,0,0,0
0,0,0,0,0,0,0,0,0,0,0,0,0,0,0,0,0,0,0,0
0,0,0,0,0,0,0,0,0,0,0,0,0,0,0,0,0,0,0,0
0,0,0,0,0,0,0,0,0,0,0,0,0,0,0,0,0,0,0,0
0,0,0,0,0,0,0,0,0,0,0,0,0,0,0,0,0,0,0,0
0,0,0,0,0,0,0,0,0,0,0,0,0,0,0,0,0,0,0,0
0,0,0,0,0,0,0,0,0,0,0,0,0,0,0,0,0,0,0,0
0,0,0,0,0,0,0,0,0,0,0,0,0,0,0,0,0,0,0,0
0,0,0,0,0,0,0,0,0,0,0,0,0,0,0,0,0,0,0,0
0,0,0,0,0,0,0,0,0,0,0,0,0,0,0,0,0,0,0,0
0,0,0,0,0,0,0,0,0,0,0,0,0,0,0,0,0,0,0,0
0,0,0,0,0,0,0,0,0,0,0,0,0,0,0,0,0,0,0,0
0,0,0,0,0,0,0,0,0,0,0,0,0,0,0,0,0,0,0,0
0,0,0,0,0,0,0,0,0,0,0,0,0,0,0,0,0,0,0,0
0,0,0,0,0,0,0,0,0,0,0,0,0,0,0,0,0,0,0,0
0,0,0,0,0,0,0,0,0,0,0,0,0,0,0,0,0,0,0,0
0,0,0,0,0,0,0,0,0,0,0,0,0,0,0,0,0,0,0,0
0,0,0,0,0,0,0,0,0,0,0,0,0,0,0,0,0,0,0,0
0,0,0,0,0,0,0,0,0,0,0,0,0,0,0,0,0,0,0,0
0,0,0,0,0,0,0,0,0,0,0,0,0,0,0,0,0,0,0,0
0,0,0,0,0,0,0,0,0,0,0,0,0,0,0,0,0,0,0,0
0,0,0,0,0,0,0,0,0,0,0,0,0,0,0,0,0,0,0,0
0,0,0,0,0,0,0,0,0,0,0,0,0,0,0,0,0,0,0,0
0,0,0,0,0,0,0,0,0,0,0,0,0,0,0,0,0,0,0,0
0,0,0,0,0,0,0,0,0,0,0,0,0,0,0,0,0,0,0,0
0,0,0,0,0,0,0,0,0,0,0,0,0,0,0,0,0,0,0,0
