# Ancient Warfare Structure Template File
# Auto-generated structure template file. created on: 11/9/2016 at: 4:18:37
# Lines beginning with # denote comments

header:
version=2.1
name=ReignNetherTower
size=20,56,26
offset=8,0,22
:endheader

#### VALIDATION ####
validation:
type=ground
survival=true
worldGenEnabled=true
unique=false
preserveBlocks=false
selectionWeight=100
clusterValue=100
minDuplicateDistance=100
dimensionWhiteList=true
dimensionList=
biomeWhiteList=true
biomeList=hell
leveling=10
fill=8
border=0
validTargetBlocks=minecraft:netherrack,minecraft:soul_sand
blockSwap=false
data:
:enddata
:endvalidation

#### LAYERS ####
layer: 0
0,0,0,0,0,0,0,0,0,0,0,0,0,0,0,0,0,0,0,0
0,0,0,0,0,0,0,0,0,0,0,0,0,0,0,0,0,0,0,0
0,6,6,6,6,6,6,6,6,6,6,6,6,6,6,6,0,0,0,0
0,2,2,2,2,2,2,2,2,2,2,2,2,2,2,2,0,0,0,0
0,3,3,3,3,2,2,2,2,2,2,2,2,2,2,2,0,0,0,0
0,2,3,3,3,2,2,2,2,2,2,2,3,3,3,3,0,0,0,0
0,2,2,2,2,4,2,2,2,2,2,2,2,2,2,2,0,0,0,0
0,2,2,2,2,2,2,2,2,2,2,2,2,2,2,2,0,0,0,0
0,2,2,2,2,2,2,2,2,2,2,2,2,2,2,2,0,0,0,0
0,2,2,2,2,2,2,2,2,2,2,2,2,2,2,2,0,0,0,0
0,2,2,2,2,2,2,2,2,2,2,2,2,2,2,2,0,0,0,0
0,2,2,2,2,2,3,2,2,6,2,2,2,2,2,2,0,0,0,0
0,2,2,2,2,2,2,5,6,6,2,2,2,2,2,2,0,0,0,0
0,2,2,2,2,2,2,5,5,2,2,2,2,2,2,2,0,0,0,0
0,2,2,2,2,2,3,2,2,2,2,2,2,2,2,2,0,0,0,0
0,2,2,2,2,2,2,2,2,2,2,2,2,2,2,2,0,0,0,0
0,2,2,2,2,2,2,2,2,2,2,2,2,2,2,2,0,0,0,0
0,2,2,2,2,2,2,2,2,2,2,2,2,2,2,2,0,0,0,0
0,2,2,2,2,2,2,2,2,2,2,4,2,2,2,2,0,0,0,0
0,3,3,3,3,2,2,2,2,2,2,2,3,3,3,2,0,0,0,0
0,2,2,2,2,2,2,2,2,2,2,2,3,3,3,3,0,0,0,0
0,2,2,2,2,2,2,2,2,2,2,2,2,2,2,2,0,0,0,0
0,1,1,1,1,1,1,1,1,1,1,1,1,1,1,1,0,0,0,0
0,0,0,0,0,0,0,0,0,0,0,0,0,0,0,0,0,0,0,0
0,0,0,0,0,0,0,0,0,0,0,0,0,0,0,0,0,0,0,0
0,0,0,0,0,0,0,0,0,0,0,0,0,0,0,0,0,0,0,0
:endlayer
layer: 1
0,0,0,0,0,0,0,0,0,0,0,0,0,0,0,0,0,0,0,0
0,0,0,0,0,0,0,0,0,0,0,0,0,0,0,0,0,0,0,0
0,0,0,0,0,0,0,0,0,0,0,0,0,0,0,0,0,0,0,0
0,8,6,6,6,0,0,0,0,0,0,0,6,6,6,7,0,0,0,0
0,8,9,10,7,0,0,0,0,0,0,0,8,10,9,7,0,0,0,0
0,2,2,2,2,11,0,0,0,0,0,11,2,2,2,2,0,0,0,0
0,2,2,2,2,12,0,0,0,0,0,13,14,15,16,2,0,0,0,0
0,2,0,0,0,0,0,0,0,0,0,0,13,14,15,2,0,0,0,0
0,2,0,0,0,0,0,0,0,0,0,0,0,13,14,2,0,0,0,0
0,2,0,18,2,0,0,0,0,0,0,2,17,0,13,2,0,0,0,0
0,2,0,0,0,0,0,0,0,0,0,0,0,0,0,2,0,0,0,0
0,2,0,0,0,0,6,6,6,6,0,0,0,0,0,2,0,0,0,0
0,2,0,0,0,0,8,9,9,7,0,0,0,0,0,2,0,0,0,0
0,2,0,0,0,0,8,9,9,7,0,0,0,0,0,2,0,0,0,0
0,2,0,0,0,0,1,1,1,1,0,0,0,0,0,2,0,0,0,0
0,2,13,0,0,0,0,0,0,0,0,0,0,0,0,2,0,0,0,0
0,2,14,18,2,0,0,0,0,0,0,2,17,0,0,2,0,0,0,0
0,2,15,14,13,0,0,0,0,0,0,0,0,0,0,2,0,0,0,0
0,2,16,15,14,13,0,0,0,0,0,12,2,2,2,2,0,0,0,0
0,2,2,2,2,11,0,0,0,0,0,11,2,2,2,2,0,0,0,0
0,8,9,10,7,0,0,0,0,0,0,0,8,10,9,7,0,0,0,0
0,8,1,1,1,0,0,0,0,0,0,0,1,1,1,7,0,0,0,0
0,0,0,0,0,0,0,0,0,0,0,0,0,0,0,0,0,0,0,0
0,0,0,0,0,0,0,0,0,0,0,0,0,0,0,0,0,0,0,0
0,0,0,0,0,0,0,0,0,0,0,0,0,0,0,0,0,0,0,0
0,0,0,0,0,0,0,0,0,0,0,0,0,0,0,0,0,0,0,0
:endlayer
layer: 2
0,0,0,0,0,0,0,0,0,0,0,0,0,0,0,0,0,0,0,0
0,0,0,0,0,0,0,0,0,0,0,0,0,0,0,0,0,0,0,0
0,0,0,0,0,0,0,0,0,0,0,0,0,0,0,0,0,0,0,0
0,0,0,0,0,0,0,0,0,0,0,0,0,0,0,0,0,0,0,0
0,0,9,2,0,0,0,0,0,0,0,0,0,2,9,0,0,0,0,0
0,2,0,0,2,11,0,0,0,0,0,11,2,4,16,2,0,0,0,0
0,2,2,2,2,0,0,0,0,0,0,0,0,0,15,2,0,0,0,0
0,2,0,0,0,0,0,0,0,0,0,0,0,0,0,2,0,0,0,0
0,2,0,0,0,0,0,0,0,0,0,0,0,0,0,2,0,0,0,0
0,2,0,18,2,0,0,0,0,0,0,2,17,0,0,2,0,0,0,0
0,2,0,0,0,0,0,0,0,0,0,0,0,0,0,2,0,0,0,0
0,2,0,0,0,0,0,0,0,0,0,0,0,0,0,2,0,0,0,0
0,2,20,0,0,0,0,9,9,0,0,0,0,0,19,2,0,0,0,0
0,2,0,0,0,0,0,9,9,0,0,0,0,0,0,2,0,0,0,0
0,2,0,0,0,0,0,0,0,0,0,0,0,0,0,2,0,0,0,0
0,2,0,0,0,0,0,0,0,0,0,0,0,0,0,2,0,0,0,0
0,2,0,18,2,0,0,0,0,0,0,2,17,0,0,2,0,0,0,0
0,2,0,0,0,0,0,0,0,0,0,0,0,0,0,2,0,0,0,0
0,2,15,0,0,0,0,0,0,0,0,0,2,2,2,2,0,0,0,0
0,2,16,4,2,11,0,0,0,0,0,11,2,0,0,2,0,0,0,0
0,0,9,2,0,0,0,0,0,0,0,0,0,2,9,0,0,0,0,0
0,0,0,0,0,0,0,0,0,0,0,0,0,0,0,0,0,0,0,0
0,0,0,0,0,0,0,0,0,0,0,0,0,0,0,0,0,0,0,0
0,0,0,0,0,0,0,0,0,0,0,0,0,0,0,0,0,0,0,0
0,0,0,0,0,0,0,0,0,0,0,0,0,0,0,0,0,0,0,0
0,0,0,0,0,0,0,0,0,0,0,0,0,0,0,0,0,0,0,0
:endlayer
layer: 3
0,0,0,0,0,0,0,0,0,0,0,0,0,0,0,0,0,0,0,0
0,0,0,0,0,0,0,0,0,0,0,0,0,0,0,0,0,0,0,0
0,0,0,0,0,0,0,0,0,0,0,0,0,0,0,0,0,0,0,0
0,0,0,0,0,0,0,0,0,0,0,0,0,0,0,0,0,0,0,0
0,0,9,2,0,0,0,0,0,0,0,0,0,2,9,0,0,0,0,0
0,2,4,4,2,11,0,0,0,0,0,11,2,4,16,2,0,0,0,0
0,2,1,1,7,0,0,0,0,0,0,0,0,0,0,2,0,0,0,0
0,2,0,0,0,0,0,0,0,0,0,0,0,0,0,2,0,0,0,0
0,2,0,0,0,0,0,0,0,0,0,0,0,0,0,2,0,0,0,0
0,2,0,18,2,0,0,0,0,0,0,2,17,0,0,2,0,0,0,0
0,2,0,0,0,0,0,0,0,0,0,0,0,0,0,2,0,0,0,0
0,2,0,0,0,0,0,0,0,0,0,0,0,0,0,2,0,0,0,0
0,2,0,0,0,0,0,9,9,0,0,0,0,0,0,2,0,0,0,0
0,2,0,0,0,0,0,9,9,0,0,0,0,0,0,2,0,0,0,0
0,2,0,0,0,0,0,0,0,0,0,0,0,0,0,2,0,0,0,0
0,2,0,0,0,0,0,0,0,0,0,0,0,0,0,2,0,0,0,0
0,2,0,18,2,0,0,0,0,0,0,2,17,0,0,2,0,0,0,0
0,2,0,0,0,0,0,0,0,0,0,0,0,0,0,2,0,0,0,0
0,2,0,0,0,0,0,0,0,0,0,0,8,6,6,2,0,0,0,0
0,2,16,4,2,11,0,0,0,0,0,11,2,4,4,2,0,0,0,0
0,0,9,2,0,0,0,0,0,0,0,0,0,2,9,0,0,0,0,0
0,0,0,0,0,0,0,0,0,0,0,0,0,0,0,0,0,0,0,0
0,0,0,0,0,0,0,0,0,0,0,0,0,0,0,0,0,0,0,0
0,0,0,0,0,0,0,0,0,0,0,0,0,0,0,0,0,0,0,0
0,0,0,0,0,0,0,0,0,0,0,0,0,0,0,0,0,0,0,0
0,0,0,0,0,0,0,0,0,0,0,0,0,0,0,0,0,0,0,0
:endlayer
layer: 4
0,0,0,0,0,0,0,0,0,0,0,0,0,0,0,0,0,0,0,0
0,0,0,0,0,0,0,0,0,0,0,0,0,0,0,0,0,0,0,0
0,0,0,0,0,0,0,0,0,0,0,0,0,0,0,0,0,0,0,0
0,0,0,0,0,0,0,0,0,0,0,0,0,0,0,0,0,0,0,0
0,0,9,2,0,0,0,0,0,0,0,0,0,2,9,0,0,0,0,0
0,2,12,12,2,11,0,0,0,0,0,11,2,12,16,2,0,0,0,0
19,2,0,0,0,0,0,0,0,0,0,0,0,0,0,2,0,0,0,0
0,2,0,0,0,0,0,0,0,0,0,0,0,0,0,2,0,0,0,0
0,2,0,0,0,0,0,0,0,0,0,0,0,0,0,2,0,0,0,0
0,2,0,18,2,0,0,0,0,0,0,2,17,0,0,2,0,0,0,0
0,2,0,0,0,0,0,0,0,0,0,0,0,0,0,2,0,0,0,0
19,2,0,0,0,0,0,0,0,0,0,0,0,0,0,2,0,0,0,0
0,2,0,0,0,0,0,9,9,0,0,0,0,0,0,2,0,0,0,0
0,2,0,0,0,0,0,9,9,0,0,0,0,0,0,2,0,0,0,0
0,2,0,0,0,0,0,0,0,0,0,0,0,0,0,2,0,0,0,0
0,2,0,0,0,0,0,0,0,0,0,0,0,0,0,2,0,0,0,0
0,2,0,18,2,0,0,0,0,0,0,2,17,0,0,2,0,0,0,0
0,2,0,0,0,0,0,0,0,0,0,0,0,0,0,2,0,0,0,0
19,2,0,0,0,0,0,0,0,0,0,0,0,0,0,2,0,0,0,0
0,2,16,12,2,11,0,0,0,0,0,11,2,12,12,2,0,0,0,0
0,0,9,2,0,0,0,0,0,0,0,0,0,2,9,0,0,0,0,0
0,0,0,0,0,0,0,0,0,0,0,0,0,0,0,0,0,0,0,0
0,0,0,0,0,0,0,0,0,0,0,0,0,0,0,0,0,0,0,0
0,0,0,0,0,0,0,0,0,0,0,0,0,0,0,0,0,0,0,0
0,0,0,0,0,0,0,0,0,0,0,0,0,0,0,0,0,0,0,0
0,0,0,0,0,0,0,0,0,0,0,0,0,0,0,0,0,0,0,0
:endlayer
layer: 5
0,0,0,0,0,0,0,0,0,0,0,0,0,0,0,0,0,0,0,0
0,0,0,0,0,0,0,0,0,0,0,0,0,0,0,0,0,0,0,0
0,0,0,0,0,0,0,0,0,0,0,0,0,0,0,0,0,0,0,0
0,0,0,0,0,0,0,0,0,0,0,0,0,0,0,0,0,0,0,0
0,0,9,2,0,0,0,0,0,0,0,0,0,2,9,0,0,0,0,0
0,2,0,0,2,22,0,0,0,0,0,21,2,0,16,2,0,0,0,0
0,2,0,0,0,0,0,0,0,0,0,0,0,0,0,2,0,0,0,0
0,2,0,0,0,0,0,0,0,0,0,0,0,0,0,2,0,0,0,0
0,2,0,0,0,0,0,0,0,0,0,0,0,0,0,2,0,0,0,0
0,2,0,18,2,0,0,0,0,0,0,2,17,0,0,2,0,0,0,0
0,2,0,0,0,0,0,0,0,0,0,0,0,0,0,2,0,0,0,0
0,2,0,0,0,0,0,0,0,0,0,0,0,0,0,2,0,0,0,0
0,2,0,0,0,0,0,9,9,0,0,0,0,0,0,2,0,0,0,0
0,2,0,0,0,0,0,9,9,0,0,0,0,0,0,2,0,0,0,0
0,2,0,0,0,0,0,0,0,0,0,0,0,0,0,2,0,0,0,0
0,2,0,0,0,0,0,0,0,0,0,0,0,0,0,2,0,0,0,0
0,2,0,18,2,0,0,0,0,0,0,2,17,0,0,2,0,0,0,0
0,2,0,0,0,0,0,0,0,0,0,0,0,0,0,2,0,0,0,0
0,2,0,0,0,0,0,0,0,0,0,0,0,0,0,2,0,0,0,0
0,2,16,0,2,22,0,0,0,0,0,21,2,0,0,2,0,0,0,0
0,0,9,2,0,0,0,0,0,0,0,0,0,2,9,0,0,0,0,0
0,0,0,0,0,0,0,0,0,0,0,0,0,0,0,0,0,0,0,0
0,0,0,0,0,0,0,0,0,0,0,0,0,0,0,0,0,0,0,0
0,0,0,0,0,0,0,0,0,0,0,0,0,0,0,0,0,0,0,0
0,0,0,0,0,0,0,0,0,0,0,0,0,0,0,0,0,0,0,0
0,0,0,0,0,0,0,0,0,0,0,0,0,0,0,0,0,0,0,0
:endlayer
layer: 6
0,0,0,0,0,0,0,0,0,0,0,0,0,0,0,0,0,0,0,0
0,0,0,0,0,0,0,0,0,0,0,0,0,0,0,0,0,0,0,0
0,0,0,0,0,0,0,0,0,0,0,0,0,0,0,0,0,0,0,0
0,0,0,0,0,0,0,0,0,0,0,0,0,0,0,0,0,0,0,0
0,0,9,2,0,23,0,0,0,0,0,23,0,2,9,0,0,0,0,0
0,2,0,0,2,25,2,22,26,21,2,25,2,0,16,2,0,0,0,0
0,2,0,0,0,0,0,0,0,0,0,0,0,0,0,2,0,0,0,0
0,2,0,0,0,0,0,0,0,0,0,0,0,0,0,2,0,0,0,0
0,2,0,0,0,0,0,0,0,0,0,0,0,0,0,2,0,0,0,0
0,2,0,18,2,0,0,0,0,0,0,2,17,0,0,2,0,0,0,0
0,2,0,0,0,0,0,0,0,0,0,0,0,0,0,2,0,0,0,0
0,2,0,0,0,0,28,28,28,28,0,0,0,0,0,2,0,0,0,0
0,2,0,0,0,0,21,9,9,22,0,0,0,0,0,2,0,0,0,0
0,2,0,0,0,0,21,9,9,22,0,0,0,0,0,2,0,0,0,0
0,2,0,0,0,0,27,27,27,27,0,0,0,0,0,2,0,0,0,0
0,2,0,0,0,0,0,0,0,0,0,0,0,0,0,2,0,0,0,0
0,2,0,18,2,0,0,0,0,0,0,2,17,0,0,2,0,0,0,0
0,2,0,0,0,0,0,0,0,0,0,0,0,0,0,2,0,0,0,0
0,2,0,0,0,0,0,0,0,0,0,0,0,0,0,2,0,0,0,0
0,2,16,0,2,25,2,22,26,21,2,25,2,0,0,2,0,0,0,0
0,0,9,2,0,24,0,0,0,0,0,23,0,2,9,0,0,0,0,0
0,0,0,0,0,0,0,0,0,0,0,0,0,0,0,0,0,0,0,0
0,0,0,0,0,0,0,0,0,0,0,0,0,0,0,0,0,0,0,0
0,0,0,0,0,0,0,0,0,0,0,0,0,0,0,0,0,0,0,0
0,0,0,0,0,0,0,0,0,0,0,0,0,0,0,0,0,0,0,0
0,0,0,0,0,0,0,0,0,0,0,0,0,0,0,0,0,0,0,0
:endlayer
layer: 7
0,0,0,0,0,0,0,0,0,0,0,0,0,0,0,0,0,0,0,0
0,0,0,0,0,0,0,0,0,0,0,0,0,0,0,0,0,0,0,0
0,0,0,0,0,0,0,0,0,0,0,0,0,0,0,0,0,0,0,0
0,0,0,28,28,0,0,0,0,0,0,0,21,28,28,22,0,0,0,0
0,0,9,10,22,28,28,28,28,28,28,28,21,10,9,22,0,0,0,0
0,2,2,2,2,2,2,2,2,2,2,2,2,0,16,2,0,0,0,0
0,2,0,0,0,0,0,0,0,0,0,0,0,0,0,2,0,0,0,0
0,2,0,0,0,0,0,0,0,0,0,0,0,0,0,2,0,0,0,0
0,2,0,0,0,0,0,0,0,0,0,0,0,0,0,2,0,0,0,0
0,2,0,18,2,2,2,2,2,2,2,2,17,0,0,2,0,0,0,0
0,2,0,0,2,21,28,28,28,28,22,2,0,0,0,2,0,0,0,0
0,2,0,0,2,21,2,2,2,2,22,2,0,0,0,2,0,0,0,0
0,2,0,0,2,21,2,5,5,2,22,2,0,0,0,2,0,0,0,0
0,2,0,0,2,21,2,5,5,2,22,2,0,0,0,2,0,0,0,0
0,2,0,0,2,21,2,2,2,2,22,2,0,0,0,2,0,0,0,0
0,2,0,0,2,21,27,27,27,27,27,2,0,0,0,2,0,0,0,0
0,2,0,18,2,2,2,2,2,2,2,2,17,0,0,2,0,0,0,0
0,2,0,0,0,0,0,0,0,0,0,0,0,0,0,2,0,0,0,0
0,2,0,0,0,0,0,0,0,0,0,0,0,0,0,2,0,0,0,0
0,2,16,0,2,2,2,2,2,2,2,2,2,2,2,2,0,0,0,0
0,21,9,10,22,27,27,27,27,27,27,27,21,10,9,0,0,0,0,0
0,21,27,27,22,0,0,0,0,0,0,0,27,27,0,0,0,0,0,0
0,0,0,0,0,0,0,0,0,0,0,0,0,0,0,0,0,0,0,0
0,0,0,0,0,0,0,0,0,0,0,0,0,0,0,0,0,0,0,0
0,0,0,0,0,0,0,0,0,0,0,0,0,0,0,0,0,0,0,0
0,0,0,0,0,0,0,0,0,0,0,0,0,0,0,0,0,0,0,0
:endlayer
layer: 8
0,0,0,0,0,0,0,0,0,0,0,0,0,0,0,0,0,0,0,0
0,0,0,0,0,0,0,0,0,0,0,0,0,0,0,0,0,0,0,0
0,0,0,0,0,0,0,0,0,0,0,0,0,0,0,0,0,0,0,0
0,6,6,6,6,6,6,6,6,6,6,6,6,6,6,6,0,0,0,0
0,8,5,10,10,10,10,10,10,10,10,10,10,10,5,7,0,0,0,0
0,2,2,2,2,2,2,2,2,2,2,2,2,2,15,2,0,0,0,0
0,2,2,2,2,2,2,2,2,2,2,2,2,2,2,2,0,0,0,0
0,2,2,2,2,2,2,2,2,2,2,2,2,2,2,2,0,0,0,0
0,2,2,1,1,1,1,1,1,1,1,1,1,2,2,2,0,0,0,0
0,2,2,0,0,0,0,0,0,0,0,0,0,2,2,2,0,0,0,0
0,2,2,7,0,0,2,0,0,0,2,0,8,2,2,2,0,0,0,0
0,2,2,7,0,0,0,0,0,0,0,0,8,2,2,2,0,0,0,0
0,2,2,7,0,0,0,0,0,0,0,0,8,2,2,2,0,0,0,0
0,2,2,7,0,0,0,0,0,0,0,0,8,2,2,2,0,0,0,0
0,2,2,7,0,18,2,0,0,0,0,2,8,2,2,2,0,0,0,0
0,2,2,7,0,0,0,0,0,0,0,0,8,2,2,2,0,0,0,0
0,2,2,0,0,0,0,0,0,0,0,0,0,2,2,2,0,0,0,0
0,2,2,7,6,6,6,6,6,6,6,6,6,2,2,2,0,0,0,0
0,2,2,2,2,2,2,2,2,2,2,2,2,2,2,2,0,0,0,0
0,2,15,2,2,2,2,2,2,2,2,2,2,2,2,2,0,0,0,0
0,8,5,10,10,10,10,10,10,10,10,10,10,10,5,7,0,0,0,0
0,1,1,1,1,1,1,1,1,1,1,1,1,1,1,1,0,0,0,0
0,0,0,0,0,0,0,0,0,0,0,0,0,0,0,0,0,0,0,0
0,0,0,0,0,0,0,0,0,0,0,0,0,0,0,0,0,0,0,0
0,0,0,0,0,0,0,0,0,0,0,0,0,0,0,0,0,0,0,0
0,0,0,0,0,0,0,0,0,0,0,0,0,0,0,0,0,0,0,0
:endlayer
layer: 9
0,0,0,0,0,0,0,0,0,0,0,0,0,0,0,0,0,0,0,0
0,0,0,0,0,0,0,0,0,0,0,0,0,0,0,0,0,0,0,0
0,0,0,0,0,0,0,0,0,0,0,0,0,0,0,0,0,0,0,0
0,0,0,0,0,0,0,0,0,0,0,0,0,0,0,0,0,0,0,0
0,0,6,6,6,6,6,6,6,6,6,6,6,6,6,0,0,0,0,0
0,2,0,0,0,0,0,0,0,0,0,0,0,0,0,2,0,0,0,0
0,2,0,0,0,0,0,0,0,0,0,0,0,0,0,2,0,0,0,0
0,2,31,0,0,0,0,0,0,0,0,0,0,0,0,2,0,0,0,0
0,2,0,0,0,0,0,0,0,0,0,0,0,0,0,2,0,0,0,0
0,2,0,0,0,0,0,0,0,0,0,0,0,0,0,2,0,0,0,0
0,2,0,0,0,0,2,0,0,0,2,0,0,0,0,2,0,0,0,0
0,2,0,0,0,0,0,0,0,0,0,0,0,0,0,2,0,0,0,0
0,2,0,0,0,0,0,0,0,0,0,0,0,0,0,2,0,0,0,0
0,2,0,0,0,0,0,0,0,0,0,0,0,0,0,2,0,0,0,0
0,2,0,0,0,18,2,0,0,0,0,2,0,0,30,2,0,0,0,0
0,2,0,0,0,0,0,0,0,0,0,0,0,0,0,2,0,0,0,0
0,2,0,0,0,0,0,0,0,0,0,0,0,0,0,2,0,0,0,0
0,2,0,0,0,0,0,0,0,0,0,0,0,0,0,2,0,0,0,0
0,2,0,0,0,0,0,0,0,0,0,0,0,0,0,2,0,0,0,0
0,2,0,0,0,0,0,0,0,0,0,0,0,29,0,2,0,0,0,0
0,0,1,1,1,1,1,1,1,1,1,1,1,1,1,0,0,0,0,0
0,0,0,0,0,0,0,0,0,0,0,0,0,0,0,0,0,0,0,0
0,0,0,0,0,0,0,0,0,0,0,0,0,0,0,0,0,0,0,0
0,0,0,0,0,0,0,0,0,0,0,0,0,0,0,0,0,0,0,0
0,0,0,0,0,0,0,0,0,0,0,0,0,0,0,0,0,0,0,0
0,0,0,0,0,0,0,0,0,0,0,0,0,0,0,0,0,0,0,0
:endlayer
layer: 10
0,0,0,0,0,0,0,0,0,0,0,0,0,0,0,0,0,0,0,0
0,0,0,0,0,0,0,0,0,0,0,0,0,0,0,0,0,0,0,0
0,0,0,0,0,0,0,0,0,0,0,0,0,0,0,0,0,0,0,0
0,0,0,0,0,0,0,0,0,0,0,0,0,0,0,0,0,0,0,0
0,0,0,0,0,0,0,0,0,0,0,0,0,0,0,0,0,0,0,0
0,8,6,6,6,6,6,6,6,6,6,6,6,6,6,7,0,0,0,0
0,8,0,0,0,0,0,0,0,0,0,0,0,0,0,7,0,0,0,0
0,8,0,0,0,0,0,0,0,0,0,0,0,0,0,7,0,0,0,0
0,8,0,0,0,0,0,0,0,0,0,0,0,0,0,7,0,0,0,0
0,8,0,0,0,0,0,0,0,0,0,0,0,0,0,7,0,0,0,0
0,8,0,0,0,0,2,0,0,0,2,0,0,0,0,7,0,0,0,0
0,8,0,0,0,0,0,0,0,0,0,0,0,0,0,7,0,0,0,0
0,8,0,0,0,0,0,0,0,0,0,0,0,0,0,7,0,0,0,0
0,8,0,0,0,0,0,0,0,0,0,0,0,0,0,7,0,0,0,0
0,8,0,0,0,18,2,0,0,0,0,2,0,0,0,7,0,0,0,0
0,8,0,0,0,0,0,0,0,0,0,0,0,0,0,7,0,0,0,0
0,8,0,0,0,0,0,0,0,0,0,0,0,0,0,7,0,0,0,0
0,8,0,0,0,0,0,0,0,0,0,0,0,0,0,7,0,0,0,0
0,8,0,0,0,0,0,0,0,0,0,0,0,0,0,7,0,0,0,0
0,8,1,1,1,1,1,1,1,1,1,1,1,1,1,7,0,0,0,0
0,0,0,0,0,0,0,0,0,0,0,0,0,0,0,0,0,0,0,0
0,0,0,0,0,0,0,0,0,0,0,0,0,0,0,0,0,0,0,0
0,0,0,0,0,0,0,0,0,0,0,0,0,0,0,0,0,0,0,0
0,0,0,0,0,0,0,0,0,0,0,0,0,0,0,0,0,0,0,0
0,0,0,0,0,0,0,0,0,0,0,0,0,0,0,0,0,0,0,0
0,0,0,0,0,0,0,0,0,0,0,0,0,0,0,0,0,0,0,0
:endlayer
layer: 11
0,0,0,0,0,0,0,0,0,0,0,0,0,0,0,0,0,0,0,0
0,0,0,0,0,0,0,0,0,0,0,0,0,0,0,0,0,0,0,0
0,0,0,0,0,0,0,0,0,0,0,0,0,0,0,0,0,0,0,0
0,0,0,0,0,0,0,0,0,0,0,0,0,0,0,0,0,0,0,0
0,0,0,0,0,0,0,0,0,0,0,0,0,0,0,0,0,0,0,0
0,0,0,0,0,0,0,0,0,0,0,0,0,0,0,0,0,0,0,0
0,0,8,2,2,2,2,2,2,6,6,6,6,6,7,0,0,0,0,0
0,0,8,0,0,0,0,0,2,2,0,0,0,0,7,0,0,0,0,0
0,0,8,0,0,0,0,0,2,0,0,0,0,0,7,0,0,0,0,0
0,0,8,0,0,0,0,0,0,0,0,0,0,0,7,0,0,0,0,0
0,0,8,0,0,0,2,0,0,0,2,0,0,0,7,0,0,0,0,0
0,0,8,0,0,0,0,0,0,0,0,2,0,0,7,0,0,0,0,0
0,0,8,2,2,2,0,0,0,0,0,2,0,0,7,0,0,0,0,0
0,0,8,0,0,0,0,0,0,0,0,2,0,0,7,0,0,0,0,0
0,0,8,0,0,18,2,0,0,0,0,2,0,0,7,0,0,0,0,0
0,0,8,0,0,0,0,0,0,0,0,0,0,0,7,0,0,0,0,0
0,0,8,0,0,0,0,0,2,0,0,0,0,0,7,0,0,0,0,0
0,0,8,0,0,0,0,0,2,0,0,0,0,0,7,0,0,0,0,0
0,0,8,1,1,1,1,1,1,2,2,2,2,2,7,0,0,0,0,0
0,0,0,0,0,0,0,0,0,0,0,0,0,0,0,0,0,0,0,0
0,0,0,0,0,0,0,0,0,0,0,0,0,0,0,0,0,0,0,0
0,0,0,0,0,0,0,0,0,0,0,0,0,0,0,0,0,0,0,0
0,0,0,0,0,0,0,0,0,0,0,0,0,0,0,0,0,0,0,0
0,0,0,0,0,0,0,0,0,0,0,0,0,0,0,0,0,0,0,0
0,0,0,0,0,0,0,0,0,0,0,0,0,0,0,0,0,0,0,0
0,0,0,0,0,0,0,0,0,0,0,0,0,0,0,0,0,0,0,0
:endlayer
layer: 12
0,0,0,0,0,0,0,0,0,0,0,0,0,0,0,0,0,0,0,0
0,0,0,0,0,0,0,0,0,0,0,0,0,0,0,0,0,0,0,0
0,0,0,0,0,0,0,0,0,0,0,0,0,0,0,0,0,0,0,0
0,0,0,0,0,0,0,0,0,0,0,0,0,0,0,0,0,0,0,0
0,0,0,0,0,0,0,0,0,0,0,0,0,0,0,0,0,0,0,0
0,0,0,0,0,0,0,0,0,0,0,0,0,0,0,0,0,0,0,0
0,0,0,6,6,6,6,6,6,0,0,0,0,0,0,0,0,0,0,0
0,0,0,8,0,0,2,2,10,2,2,2,2,7,0,0,0,0,0,0
0,0,0,8,0,2,2,2,9,2,2,2,0,7,0,0,0,0,0,0
0,0,0,8,0,2,2,2,2,2,2,2,0,7,0,0,0,0,0,0
0,0,0,8,0,2,2,2,2,2,2,2,2,7,0,0,0,0,0,0
0,0,0,8,2,2,2,2,2,2,2,2,0,7,0,0,0,0,0,0
0,0,0,8,15,9,2,2,2,2,2,9,2,7,0,0,0,0,0,0
0,0,0,8,2,2,2,2,2,2,2,2,2,7,0,0,0,0,0,0
0,0,0,8,0,18,2,2,2,2,2,2,0,7,0,0,0,0,0,0
0,0,0,8,0,32,32,2,2,2,32,32,0,7,0,0,0,0,0,0
0,0,0,8,0,4,32,2,9,2,32,4,0,7,0,0,0,0,0,0
0,0,0,8,2,2,2,2,2,2,2,2,0,7,0,0,0,0,0,0
0,0,0,0,0,0,0,0,0,1,1,1,1,1,0,0,0,0,0,0
0,0,0,0,0,0,0,0,0,0,0,0,0,0,0,0,0,0,0,0
0,0,0,0,0,0,0,0,0,0,0,0,0,0,0,0,0,0,0,0
0,0,0,0,0,0,0,0,0,0,0,0,0,0,0,0,0,0,0,0
0,0,0,0,0,0,0,0,0,0,0,0,0,0,0,0,0,0,0,0
0,0,0,0,0,0,0,0,0,0,0,0,0,0,0,0,0,0,0,0
0,0,0,0,0,0,0,0,0,0,0,0,0,0,0,0,0,0,0,0
0,0,0,0,0,0,0,0,0,0,0,0,0,0,0,0,0,0,0,0
:endlayer
layer: 13
0,0,0,0,0,0,0,0,0,0,0,0,0,0,0,0,0,0,0,0
0,0,0,0,0,0,0,0,0,0,0,0,0,0,0,0,0,0,0,0
0,0,0,0,0,0,0,0,0,0,0,0,0,0,0,0,0,0,0,0
0,0,0,0,0,0,0,0,0,0,0,0,0,0,0,0,0,0,0,0
0,0,0,0,0,0,0,0,0,0,0,0,0,0,0,0,0,0,0,0
0,0,0,0,0,0,0,0,0,0,0,0,0,0,0,0,0,0,0,0
0,0,0,0,0,0,0,0,0,0,0,0,0,0,0,0,0,0,0,0
0,0,0,0,2,2,2,7,33,8,2,2,2,0,0,0,0,0,0,0
0,0,0,0,2,0,0,35,9,35,0,0,2,0,0,0,0,0,0,0
0,0,0,0,2,0,0,35,35,35,36,0,2,0,0,0,0,0,0,0
0,0,0,0,2,0,0,0,0,0,0,0,2,0,0,0,0,0,0,0
0,0,0,0,1,35,35,0,0,0,35,35,1,0,0,0,0,0,0,0
0,0,0,0,33,9,35,1,1,1,35,9,33,0,0,0,0,0,0,0
0,0,0,0,6,35,35,0,0,0,35,35,6,0,0,0,0,0,0,0
0,0,0,0,2,0,0,0,0,0,0,0,2,0,0,0,0,0,0,0
0,0,0,0,2,34,34,35,35,35,34,34,2,0,0,0,0,0,0,0
0,0,0,0,2,0,34,35,9,35,34,12,2,0,0,0,0,0,0,0
0,0,0,0,2,2,2,7,33,8,2,2,2,0,0,0,0,0,0,0
0,0,0,0,0,0,0,0,0,0,0,0,0,0,0,0,0,0,0,0
0,0,0,0,0,0,0,0,0,0,0,0,0,0,0,0,0,0,0,0
0,0,0,0,0,0,0,0,0,0,0,0,0,0,0,0,0,0,0,0
0,0,0,0,0,0,0,0,0,0,0,0,0,0,0,0,0,0,0,0
0,0,0,0,0,0,0,0,0,0,0,0,0,0,0,0,0,0,0,0
0,0,0,0,0,0,0,0,0,0,0,0,0,0,0,0,0,0,0,0
0,0,0,0,0,0,0,0,0,0,0,0,0,0,0,0,0,0,0,0
0,0,0,0,0,0,0,0,0,0,0,0,0,0,0,0,0,0,0,0
:endlayer
layer: 14
0,0,0,0,0,0,0,0,0,0,0,0,0,0,0,0,0,0,0,0
0,0,0,0,0,0,0,0,0,0,0,0,0,0,0,0,0,0,0,0
0,0,0,0,0,0,0,0,0,0,0,0,0,0,0,0,0,0,0,0
0,0,0,0,0,0,0,0,0,0,0,0,0,0,0,0,0,0,0,0
0,0,0,0,0,0,0,0,0,0,0,0,0,0,0,0,0,0,0,0
0,0,0,0,0,0,0,0,0,0,0,0,0,0,0,0,0,0,0,0
0,0,0,0,0,0,0,0,0,0,0,0,0,0,0,0,0,0,0,0
0,0,0,0,2,2,2,22,26,21,2,2,2,0,0,0,0,0,0,0
0,0,0,0,2,0,0,0,9,0,0,0,2,0,0,0,0,0,0,0
0,0,0,0,2,0,0,0,0,0,0,0,2,0,0,0,0,0,0,0
0,0,0,0,2,0,0,2,2,2,0,0,2,0,0,0,0,0,0,0
0,0,0,0,27,0,0,1,1,1,0,0,27,0,0,0,0,0,0,0
0,0,0,0,26,9,0,0,0,0,0,9,26,0,0,0,0,0,0,0
0,0,0,0,28,0,0,0,0,0,0,0,28,0,0,0,0,0,0,0
0,0,0,0,2,0,0,0,0,0,0,0,2,0,0,0,0,0,0,0
0,0,0,0,2,0,0,0,0,0,0,0,2,0,0,0,0,0,0,0
0,0,0,0,2,0,0,0,9,0,0,0,2,0,0,0,0,0,0,0
0,0,0,0,2,2,2,22,26,21,2,2,2,0,0,0,0,0,0,0
0,0,0,0,0,0,0,0,0,0,0,0,0,0,0,0,0,0,0,0
0,0,0,0,0,0,0,0,0,0,0,0,0,0,0,0,0,0,0,0
0,0,0,0,0,0,0,0,0,0,0,0,0,0,0,0,0,0,0,0
0,0,0,0,0,0,0,0,0,0,0,0,0,0,0,0,0,0,0,0
0,0,0,0,0,0,0,0,0,0,0,0,0,0,0,0,0,0,0,0
0,0,0,0,0,0,0,0,0,0,0,0,0,0,0,0,0,0,0,0
0,0,0,0,0,0,0,0,0,0,0,0,0,0,0,0,0,0,0,0
0,0,0,0,0,0,0,0,0,0,0,0,0,0,0,0,0,0,0,0
:endlayer
layer: 15
0,0,0,0,0,0,0,0,0,0,0,0,0,0,0,0,0,0,0,0
0,0,0,0,0,0,0,0,0,0,0,0,0,0,0,0,0,0,0,0
0,0,0,0,0,0,0,0,0,0,0,0,0,0,0,0,0,0,0,0
0,0,0,0,0,0,0,0,0,0,0,0,0,0,0,0,0,0,0,0
0,0,0,0,0,0,0,0,0,0,0,0,0,0,0,0,0,0,0,0
0,0,0,0,0,0,0,0,0,0,0,0,0,0,0,0,0,0,0,0
0,0,0,0,0,0,0,0,0,0,0,0,0,0,0,0,0,0,0,0
0,0,0,0,2,2,2,2,2,2,2,2,2,0,0,0,0,0,0,0
0,0,0,0,2,32,32,2,5,2,32,32,2,0,0,0,0,0,0,0
0,0,0,0,2,32,32,2,2,2,32,32,2,0,0,0,0,0,0,0
0,0,0,0,2,2,2,1,1,1,2,2,2,0,0,0,0,0,0,0
0,0,0,0,2,2,2,0,0,0,2,2,2,0,0,0,0,0,0,0
0,0,0,0,2,5,2,0,0,0,2,5,2,0,0,0,0,0,0,0
0,0,0,0,2,2,2,0,0,0,2,2,2,0,0,0,0,0,0,0
0,0,0,0,2,2,2,2,2,2,2,2,2,0,0,0,0,0,0,0
0,0,0,0,2,32,32,2,2,2,32,32,2,0,0,0,0,0,0,0
0,0,0,0,2,32,32,2,5,2,32,32,2,0,0,0,0,0,0,0
0,0,0,0,2,2,2,2,2,2,2,2,2,0,0,0,0,0,0,0
0,0,0,0,0,0,0,0,0,0,0,0,0,0,0,0,0,0,0,0
0,0,0,0,0,0,0,0,0,0,0,0,0,0,0,0,0,0,0,0
0,0,0,0,0,0,0,0,0,0,0,0,0,0,0,0,0,0,0,0
0,0,0,0,0,0,0,0,0,0,0,0,0,0,0,0,0,0,0,0
0,0,0,0,0,0,0,0,0,0,0,0,0,0,0,0,0,0,0,0
0,0,0,0,0,0,0,0,0,0,0,0,0,0,0,0,0,0,0,0
0,0,0,0,0,0,0,0,0,0,0,0,0,0,0,0,0,0,0,0
0,0,0,0,0,0,0,0,0,0,0,0,0,0,0,0,0,0,0,0
:endlayer
layer: 16
0,0,0,0,0,0,0,0,0,0,0,0,0,0,0,0,0,0,0,0
0,0,0,0,0,0,0,0,0,0,0,0,0,0,0,0,0,0,0,0
0,0,0,0,0,0,0,0,0,0,0,0,0,0,0,0,0,0,0,0
0,0,0,0,0,0,0,0,0,0,0,0,0,0,0,0,0,0,0,0
0,0,0,0,0,0,0,0,0,0,0,0,0,0,0,0,0,0,0,0
0,0,0,0,0,0,0,0,0,0,0,0,0,0,0,0,0,0,0,0
0,0,0,0,0,0,0,0,0,0,0,0,0,0,0,0,0,0,0,0
0,0,0,0,2,2,2,2,2,2,2,2,2,0,0,0,0,0,0,0
0,0,0,0,2,34,40,35,0,35,34,34,2,0,0,0,0,0,0,0
0,0,0,0,2,34,34,35,35,35,34,34,2,0,0,0,0,0,0,0
0,0,0,0,2,6,6,0,0,0,0,0,2,0,0,0,0,0,0,0
0,0,0,0,2,35,35,0,0,0,35,35,2,0,0,0,0,0,0,0
0,0,0,0,2,0,35,0,0,0,35,0,2,0,0,0,0,0,0,0
0,0,0,0,2,35,35,0,0,0,35,35,2,0,0,0,0,0,0,0
0,0,0,0,2,39,0,0,0,0,0,38,2,0,0,0,0,0,0,0
0,0,0,0,2,34,34,35,35,35,34,37,2,0,0,0,0,0,0,0
0,0,0,0,2,34,34,35,0,35,34,34,2,0,0,0,0,0,0,0
0,0,0,0,2,2,2,2,2,2,2,2,2,0,0,0,0,0,0,0
0,0,0,0,0,0,0,0,0,0,0,0,0,0,0,0,0,0,0,0
0,0,0,0,0,0,0,0,0,0,0,0,0,0,0,0,0,0,0,0
0,0,0,0,0,0,0,0,0,0,0,0,0,0,0,0,0,0,0,0
0,0,0,0,0,0,0,0,0,0,0,0,0,0,0,0,0,0,0,0
0,0,0,0,0,0,0,0,0,0,0,0,0,0,0,0,0,0,0,0
0,0,0,0,0,0,0,0,0,0,0,0,0,0,0,0,0,0,0,0
0,0,0,0,0,0,0,0,0,0,0,0,0,0,0,0,0,0,0,0
0,0,0,0,0,0,0,0,0,0,0,0,0,0,0,0,0,0,0,0
:endlayer
layer: 17
0,0,0,0,0,0,0,0,0,0,0,0,0,0,0,0,0,0,0,0
0,0,0,0,0,0,0,0,0,0,0,0,0,0,0,0,0,0,0,0
0,0,0,0,0,0,0,0,0,0,0,0,0,0,0,0,0,0,0,0
0,0,0,0,0,0,0,0,0,0,0,0,0,0,0,0,0,0,0,0
0,0,0,0,0,0,0,0,0,0,0,0,0,0,0,0,0,0,0,0
0,0,0,0,0,0,0,0,0,0,0,0,0,0,0,0,0,0,0,0
0,0,0,0,0,0,0,0,0,0,0,0,0,0,0,0,0,0,0,0
0,0,0,0,2,2,2,2,2,2,2,2,2,0,0,0,0,0,0,0
0,0,0,0,2,0,0,0,0,0,0,0,2,0,0,0,0,0,0,0
0,0,0,0,2,0,0,0,0,0,0,0,2,0,0,0,0,0,0,0
0,0,0,0,2,0,0,0,0,0,0,0,2,0,0,0,0,0,0,0
0,0,0,0,2,6,6,0,0,0,0,0,2,0,0,0,0,0,0,0
0,0,0,0,2,0,0,0,0,0,0,0,2,0,0,0,0,0,0,0
0,0,0,0,2,0,0,0,0,0,0,0,2,0,0,0,0,0,0,0
0,0,0,0,2,0,0,0,0,0,0,0,2,0,0,0,0,0,0,0
0,0,0,0,2,0,0,0,0,0,0,0,2,0,0,0,0,0,0,0
0,0,0,0,2,0,0,0,0,0,0,0,2,0,0,0,0,0,0,0
0,0,0,0,2,2,2,2,2,2,2,2,2,0,0,0,0,0,0,0
0,0,0,0,0,0,0,0,0,0,0,0,0,0,0,0,0,0,0,0
0,0,0,0,0,0,0,0,0,0,0,0,0,0,0,0,0,0,0,0
0,0,0,0,0,0,0,0,0,0,0,0,0,0,0,0,0,0,0,0
0,0,0,0,0,0,0,0,0,0,0,0,0,0,0,0,0,0,0,0
0,0,0,0,0,0,0,0,0,0,0,0,0,0,0,0,0,0,0,0
0,0,0,0,0,0,0,0,0,0,0,0,0,0,0,0,0,0,0,0
0,0,0,0,0,0,0,0,0,0,0,0,0,0,0,0,0,0,0,0
0,0,0,0,0,0,0,0,0,0,0,0,0,0,0,0,0,0,0,0
:endlayer
layer: 18
0,0,0,0,0,0,0,0,0,0,0,0,0,0,0,0,0,0,0,0
0,0,0,0,0,0,0,0,0,0,0,0,0,0,0,0,0,0,0,0
0,0,0,0,0,0,0,0,0,0,0,0,0,0,0,0,0,0,0,0
0,0,0,0,0,0,0,0,0,0,0,0,0,0,0,0,0,0,0,0
0,0,0,0,0,0,0,0,0,0,0,0,0,0,0,0,0,0,0,0
0,0,0,0,0,0,0,0,0,0,0,0,0,0,0,0,0,0,0,0
0,0,0,0,0,0,0,0,0,0,0,0,0,0,0,0,0,0,0,0
0,0,0,0,2,2,2,2,2,2,2,2,2,0,0,0,0,0,0,0
0,0,0,0,2,0,0,0,0,0,0,0,2,0,0,0,0,0,0,0
0,0,0,0,2,0,0,0,0,0,0,0,2,0,0,0,0,0,0,0
0,0,0,0,2,0,0,0,0,0,0,0,2,0,0,0,0,0,0,0
0,0,0,0,2,0,0,0,0,0,0,0,2,0,0,0,0,0,0,0
0,0,0,0,2,6,6,0,0,0,0,0,2,0,0,0,0,0,0,0
0,0,0,0,2,0,0,0,0,0,0,0,2,0,0,0,0,0,0,0
0,0,0,0,2,0,0,0,0,0,0,0,2,0,0,0,0,0,0,0
0,0,0,0,2,0,0,0,0,0,0,0,2,0,0,0,0,0,0,0
0,0,0,0,2,0,0,0,0,0,0,0,2,0,0,0,0,0,0,0
0,0,0,0,2,2,2,2,2,2,2,2,2,0,0,0,0,0,0,0
0,0,0,0,0,0,0,0,0,0,0,0,0,0,0,0,0,0,0,0
0,0,0,0,0,0,0,0,0,0,0,0,0,0,0,0,0,0,0,0
0,0,0,0,0,0,0,0,0,0,0,0,0,0,0,0,0,0,0,0
0,0,0,0,0,0,0,0,0,0,0,0,0,0,0,0,0,0,0,0
0,0,0,0,0,0,0,0,0,0,0,0,0,0,0,0,0,0,0,0
0,0,0,0,0,0,0,0,0,0,0,0,0,0,0,0,0,0,0,0
0,0,0,0,0,0,0,0,0,0,0,0,0,0,0,0,0,0,0,0
0,0,0,0,0,0,0,0,0,0,0,0,0,0,0,0,0,0,0,0
:endlayer
layer: 19
0,0,0,0,0,0,0,0,0,0,0,0,0,0,0,0,0,0,0,0
0,0,0,0,0,0,0,0,0,0,0,0,0,0,0,0,0,0,0,0
0,0,0,0,0,0,0,0,0,0,0,0,0,0,0,0,0,0,0,0
0,0,0,0,0,0,0,0,0,0,0,0,0,0,0,0,0,0,0,0
0,0,0,0,0,0,0,0,0,0,0,0,0,0,0,0,0,0,0,0
0,0,0,0,0,0,0,0,0,0,0,0,0,0,0,0,0,0,0,0
0,0,0,0,0,0,0,0,0,0,0,0,0,0,0,0,0,0,0,0
0,0,0,0,2,2,2,2,2,2,2,2,2,0,0,0,0,0,0,0
0,0,0,0,2,0,0,0,0,0,0,0,2,0,0,0,0,0,0,0
0,0,0,0,2,0,0,0,0,0,0,0,2,0,0,0,0,0,0,0
0,0,0,0,2,0,0,0,0,0,0,0,2,0,0,0,0,0,0,0
0,0,0,0,2,0,0,0,0,0,0,0,2,0,0,0,0,0,0,0
0,0,0,0,2,0,0,0,0,0,0,0,2,0,0,0,0,0,0,0
0,0,0,0,2,6,6,0,0,0,0,0,2,0,0,0,0,0,0,0
0,0,0,0,2,2,2,2,0,0,0,0,2,0,0,0,0,0,0,0
0,0,0,0,2,2,2,2,0,0,0,0,2,0,0,0,0,0,0,0
0,0,0,0,2,2,2,2,0,0,0,0,2,0,0,0,0,0,0,0
0,0,0,0,2,2,2,2,2,2,2,2,2,0,0,0,0,0,0,0
0,0,0,0,0,0,0,0,0,0,0,0,0,0,0,0,0,0,0,0
0,0,0,0,0,0,0,0,0,0,0,0,0,0,0,0,0,0,0,0
0,0,0,0,0,0,0,0,0,0,0,0,0,0,0,0,0,0,0,0
0,0,0,0,0,0,0,0,0,0,0,0,0,0,0,0,0,0,0,0
0,0,0,0,0,0,0,0,0,0,0,0,0,0,0,0,0,0,0,0
0,0,0,0,0,0,0,0,0,0,0,0,0,0,0,0,0,0,0,0
0,0,0,0,0,0,0,0,0,0,0,0,0,0,0,0,0,0,0,0
0,0,0,0,0,0,0,0,0,0,0,0,0,0,0,0,0,0,0,0
:endlayer
layer: 20
0,0,0,0,0,0,0,0,0,0,0,0,0,0,0,0,0,0,0,0
0,0,0,0,0,0,0,0,0,0,0,0,0,0,0,0,0,0,0,0
0,0,0,0,0,0,0,0,0,0,0,0,0,0,0,0,0,0,0,0
0,0,0,0,0,0,0,0,0,0,0,0,0,0,0,0,0,0,0,0
0,0,0,0,0,0,0,0,0,0,0,0,0,0,0,0,0,0,0,0
0,0,0,0,0,0,0,0,0,0,0,0,0,0,0,0,0,0,0,0
0,0,0,0,0,0,0,0,0,0,0,0,0,0,0,0,0,0,0,0
0,0,0,0,2,2,2,2,2,2,2,2,2,0,0,0,0,0,0,0
0,0,0,0,2,0,0,0,0,0,0,0,2,0,0,0,0,0,0,0
0,0,0,0,2,0,0,0,0,0,0,0,2,0,0,0,0,0,0,0
0,0,0,0,2,0,0,0,0,0,0,0,2,0,0,0,0,0,0,0
0,0,0,0,2,0,0,0,0,0,0,0,2,0,0,0,0,0,0,0
0,0,0,0,2,0,0,0,0,0,0,0,2,0,0,0,0,0,0,0
0,0,0,0,2,0,0,0,0,0,0,0,2,0,0,0,0,0,0,0
0,0,0,0,2,0,0,8,0,0,0,0,2,0,0,0,0,0,0,0
0,0,0,0,2,0,0,8,0,0,0,0,2,0,0,0,0,0,0,0
0,0,0,0,2,41,0,0,0,0,0,0,2,0,0,0,0,0,0,0
0,0,0,0,2,2,2,2,2,2,2,2,2,0,0,0,0,0,0,0
0,0,0,0,0,0,0,0,0,0,0,0,0,0,0,0,0,0,0,0
0,0,0,0,0,0,0,0,0,0,0,0,0,0,0,0,0,0,0,0
0,0,0,0,0,0,0,0,0,0,0,0,0,0,0,0,0,0,0,0
0,0,0,0,0,0,0,0,0,0,0,0,0,0,0,0,0,0,0,0
0,0,0,0,0,0,0,0,0,0,0,0,0,0,0,0,0,0,0,0
0,0,0,0,0,0,0,0,0,0,0,0,0,0,0,0,0,0,0,0
0,0,0,0,0,0,0,0,0,0,0,0,0,0,0,0,0,0,0,0
0,0,0,0,0,0,0,0,0,0,0,0,0,0,0,0,0,0,0,0
:endlayer
layer: 21
0,0,0,0,0,0,0,0,0,0,0,0,0,0,0,0,0,0,0,0
0,0,0,0,0,0,0,0,0,0,0,0,0,0,0,0,0,0,0,0
0,0,0,0,0,0,0,0,0,0,0,0,0,0,0,0,0,0,0,0
0,0,0,0,0,0,0,0,0,0,0,0,0,0,0,0,0,0,0,0
0,0,0,0,0,0,0,0,0,0,0,0,0,0,0,0,0,0,0,0
0,0,0,0,0,0,0,0,0,0,0,0,0,0,0,0,0,0,0,0
0,0,0,0,0,0,28,0,0,0,28,0,0,0,0,0,0,0,0,0
0,0,0,0,2,2,2,2,2,2,2,2,2,0,0,0,0,0,0,0
0,0,0,0,2,0,0,2,2,2,0,0,2,0,0,0,0,0,0,0
0,0,0,0,2,0,0,0,0,0,0,0,2,0,0,0,0,0,0,0
0,0,0,21,2,0,0,0,0,0,0,0,2,22,0,0,0,0,0,0
0,0,0,0,2,0,0,0,0,0,0,2,2,0,0,0,0,0,0,0
0,0,0,0,2,2,0,0,0,0,0,2,2,0,0,0,0,0,0,0
0,0,0,0,2,0,0,0,0,0,0,2,2,0,0,0,0,0,0,0
0,0,0,21,2,0,0,0,8,0,0,0,2,22,0,0,0,0,0,0
0,0,0,0,2,0,0,0,8,0,0,0,2,0,0,0,0,0,0,0
0,0,0,0,2,0,0,0,2,0,0,0,2,0,0,0,0,0,0,0
0,0,0,0,2,2,2,2,2,2,2,2,2,0,0,0,0,0,0,0
0,0,0,0,0,0,27,0,0,0,27,0,0,0,0,0,0,0,0,0
0,0,0,0,0,0,0,0,0,0,0,0,0,0,0,0,0,0,0,0
0,0,0,0,0,0,0,0,0,0,0,0,0,0,0,0,0,0,0,0
0,0,0,0,0,0,0,0,0,0,0,0,0,0,0,0,0,0,0,0
0,0,0,0,0,0,0,0,0,0,0,0,0,0,0,0,0,0,0,0
0,0,0,0,0,0,0,0,0,0,0,0,0,0,0,0,0,0,0,0
0,0,0,0,0,0,0,0,0,0,0,0,0,0,0,0,0,0,0,0
0,0,0,0,0,0,0,0,0,0,0,0,0,0,0,0,0,0,0,0
:endlayer
layer: 22
0,0,0,0,0,0,0,0,0,0,0,0,0,0,0,0,0,0,0,0
0,0,0,0,0,0,0,0,0,0,0,0,0,0,0,0,0,0,0,0
0,0,0,0,0,0,0,0,0,0,0,0,0,0,0,0,0,0,0,0
0,0,0,0,0,0,0,0,0,0,0,0,0,0,0,0,0,0,0,0
0,0,0,0,0,0,0,0,0,0,0,0,0,0,0,0,0,0,0,0
0,0,0,0,0,28,28,28,0,28,28,28,0,0,0,0,0,0,0,0
0,0,0,0,0,21,4,22,0,21,4,22,0,0,0,0,0,0,0,0
0,0,0,0,2,2,2,2,2,2,2,2,2,0,0,0,0,0,0,0
0,0,0,0,2,2,2,2,9,2,2,2,2,0,0,0,0,0,0,0
0,0,21,28,2,2,2,2,2,2,2,2,2,28,22,0,0,0,0,0
0,0,21,4,2,2,2,2,0,2,2,2,2,4,22,0,0,0,0,0
0,0,21,27,2,2,2,2,0,2,2,2,2,27,22,0,0,0,0,0
0,0,0,0,2,5,2,2,2,2,2,9,2,0,0,0,0,0,0,0
0,0,21,28,2,2,2,0,0,2,2,2,2,28,22,0,0,0,0,0
0,0,21,4,2,2,0,0,0,8,2,0,2,4,22,0,0,0,0,0
0,0,21,27,2,2,0,0,2,2,2,2,2,27,22,0,0,0,0,0
0,0,0,0,2,2,2,2,9,2,0,2,2,0,0,0,0,0,0,0
0,0,0,0,2,2,2,2,2,2,2,2,2,0,0,0,0,0,0,0
0,0,0,0,0,21,4,22,0,21,4,22,0,0,0,0,0,0,0,0
0,0,0,0,0,27,27,27,0,27,27,27,0,0,0,0,0,0,0,0
0,0,0,0,0,0,0,0,0,0,0,0,0,0,0,0,0,0,0,0
0,0,0,0,0,0,0,0,0,0,0,0,0,0,0,0,0,0,0,0
0,0,0,0,0,0,0,0,0,0,0,0,0,0,0,0,0,0,0,0
0,0,0,0,0,0,0,0,0,0,0,0,0,0,0,0,0,0,0,0
0,0,0,0,0,0,0,0,0,0,0,0,0,0,0,0,0,0,0,0
0,0,0,0,0,0,0,0,0,0,0,0,0,0,0,0,0,0,0,0
:endlayer
layer: 23
0,0,0,0,0,0,0,0,0,0,0,0,0,0,0,0,0,0,0,0
0,0,0,0,0,0,0,0,0,0,0,0,0,0,0,0,0,0,0,0
0,0,0,0,0,0,0,0,0,0,0,0,0,0,0,0,0,0,0,0
0,0,0,0,0,0,0,0,0,0,0,0,0,0,0,0,0,0,0,0
0,0,0,0,0,0,0,0,0,0,0,0,0,0,0,0,0,0,0,0
0,0,0,0,0,0,0,0,0,0,0,0,0,0,0,0,0,0,0,0
0,0,0,0,0,0,12,0,0,0,12,0,0,0,0,0,0,0,0,0
0,0,0,0,2,2,2,2,6,2,2,2,2,0,0,0,0,0,0,0
0,0,0,0,2,42,0,2,9,2,0,0,2,0,0,0,0,0,0,0
0,0,0,0,2,0,0,2,0,0,0,0,2,0,0,0,0,0,0,0
0,0,0,12,2,0,0,0,0,0,2,2,2,12,0,0,0,0,0,0
0,0,0,0,2,2,2,17,0,0,0,0,2,0,0,0,0,0,0,0
0,0,0,0,8,9,0,0,0,0,0,9,7,0,0,0,0,0,0,0
0,0,0,0,2,2,2,0,0,0,0,0,2,0,0,0,0,0,0,0
0,0,0,12,2,0,0,0,0,0,2,2,2,12,0,0,0,0,0,0
0,0,0,0,2,0,0,35,35,35,2,0,2,0,0,0,0,0,0,0
0,0,0,0,2,0,0,35,9,35,0,0,2,0,0,0,0,0,0,0
0,0,0,0,2,2,2,2,1,2,2,2,2,0,0,0,0,0,0,0
0,0,0,0,0,0,12,0,0,0,12,0,0,0,0,0,0,0,0,0
0,0,0,0,0,0,0,0,0,0,0,0,0,0,0,0,0,0,0,0
0,0,0,0,0,0,0,0,0,0,0,0,0,0,0,0,0,0,0,0
0,0,0,0,0,0,0,0,0,0,0,0,0,0,0,0,0,0,0,0
0,0,0,0,0,0,0,0,0,0,0,0,0,0,0,0,0,0,0,0
0,0,0,0,0,0,0,0,0,0,0,0,0,0,0,0,0,0,0,0
0,0,0,0,0,0,0,0,0,0,0,0,0,0,0,0,0,0,0,0
0,0,0,0,0,0,0,0,0,0,0,0,0,0,0,0,0,0,0,0
:endlayer
layer: 24
0,0,0,0,0,0,0,0,0,0,0,0,0,0,0,0,0,0,0,0
0,0,0,0,0,0,0,0,0,0,0,0,0,0,0,0,0,0,0,0
0,0,0,0,0,0,0,0,0,0,0,0,0,0,0,0,0,0,0,0
0,0,0,0,0,0,0,0,0,0,0,0,0,0,0,0,0,0,0,0
0,0,0,0,0,0,0,0,0,0,0,0,0,0,0,0,0,0,0,0
0,0,0,0,0,0,0,0,0,0,0,0,0,0,0,0,0,0,0,0
0,0,0,0,0,0,0,0,0,0,0,0,0,0,0,0,0,0,0,0
0,0,0,0,2,2,2,2,0,2,2,2,2,0,0,0,0,0,0,0
0,0,0,0,2,0,0,2,9,2,0,0,2,0,0,0,0,0,0,0
0,0,0,0,2,0,0,2,0,0,0,0,2,0,0,0,0,0,0,0
0,0,0,0,2,0,0,0,0,0,2,2,2,0,0,0,0,0,0,0
0,0,0,0,2,2,2,17,0,0,0,0,2,0,0,0,0,0,0,0
0,0,0,0,0,9,0,0,0,0,0,9,0,0,0,0,0,0,0,0
0,0,0,0,2,2,2,0,0,0,0,0,2,0,0,0,0,0,0,0
0,0,0,0,2,0,0,0,0,0,2,2,2,0,0,0,0,0,0,0
0,0,0,0,2,0,0,0,0,0,2,0,2,0,0,0,0,0,0,0
0,0,0,0,2,0,0,0,9,0,0,0,2,0,0,0,0,0,0,0
0,0,0,0,2,2,2,2,0,2,2,2,2,0,0,0,0,0,0,0
0,0,0,0,0,0,0,0,0,0,0,0,0,0,0,0,0,0,0,0
0,0,0,0,0,0,0,0,0,0,0,0,0,0,0,0,0,0,0,0
0,0,0,0,0,0,0,0,0,0,0,0,0,0,0,0,0,0,0,0
0,0,0,0,0,0,0,0,0,0,0,0,0,0,0,0,0,0,0,0
0,0,0,0,0,0,0,0,0,0,0,0,0,0,0,0,0,0,0,0
0,0,0,0,0,0,0,0,0,0,0,0,0,0,0,0,0,0,0,0
0,0,0,0,0,0,0,0,0,0,0,0,0,0,0,0,0,0,0,0
0,0,0,0,0,0,0,0,0,0,0,0,0,0,0,0,0,0,0,0
:endlayer
layer: 25
0,0,0,0,0,0,0,0,0,0,0,0,0,0,0,0,0,0,0,0
0,0,0,0,0,0,0,0,0,0,0,0,0,0,0,0,0,0,0,0
0,0,0,0,0,0,0,0,0,0,0,0,0,0,0,0,0,0,0,0
0,0,0,0,0,0,0,0,0,0,0,0,0,0,0,0,0,0,0,0
0,0,0,0,0,0,0,0,0,0,0,0,0,0,0,0,0,0,0,0
0,0,0,0,0,0,0,0,0,0,0,0,0,0,0,0,0,0,0,0
0,0,0,0,0,0,0,0,0,0,0,0,0,0,0,0,0,0,0,0
0,0,0,0,2,2,2,2,0,2,2,2,2,0,0,0,0,0,0,0
0,0,0,0,2,44,0,2,9,2,0,0,2,0,0,0,0,0,0,0
0,0,0,0,2,0,0,2,0,2,0,0,2,0,0,0,0,0,0,0
0,0,0,0,2,0,0,0,0,0,2,2,2,0,0,0,0,0,0,0
0,0,0,0,2,2,2,17,0,0,0,19,2,0,0,0,0,0,0,0
0,0,0,0,0,9,0,0,0,0,0,9,0,0,0,0,0,0,0,0
0,0,0,0,2,2,2,0,0,0,0,19,2,0,0,0,0,0,0,0
0,0,0,0,2,0,0,0,0,0,2,2,2,0,0,0,0,0,0,0
0,0,0,0,2,0,0,0,0,0,2,0,2,0,0,0,0,0,0,0
0,0,0,0,2,2,2,43,9,0,0,0,2,0,0,0,0,0,0,0
0,0,0,0,2,2,2,2,0,2,2,2,2,0,0,0,0,0,0,0
0,0,0,0,0,0,0,0,0,0,0,0,0,0,0,0,0,0,0,0
0,0,0,0,0,0,0,0,0,0,0,0,0,0,0,0,0,0,0,0
0,0,0,0,0,0,0,0,0,0,0,0,0,0,0,0,0,0,0,0
0,0,0,0,0,0,0,0,0,0,0,0,0,0,0,0,0,0,0,0
0,0,0,0,0,0,0,0,0,0,0,0,0,0,0,0,0,0,0,0
0,0,0,0,0,0,0,0,0,0,0,0,0,0,0,0,0,0,0,0
0,0,0,0,0,0,0,0,0,0,0,0,0,0,0,0,0,0,0,0
0,0,0,0,0,0,0,0,0,0,0,0,0,0,0,0,0,0,0,0
:endlayer
layer: 26
0,0,0,0,0,0,0,0,0,0,0,0,0,0,0,0,0,0,0,0
0,0,0,0,0,0,0,0,0,0,0,0,0,0,0,0,0,0,0,0
0,0,0,0,0,0,0,0,0,0,0,0,0,0,0,0,0,0,0,0
0,0,0,0,0,0,0,0,0,0,0,0,0,0,0,0,0,0,0,0
0,0,0,0,0,0,0,0,0,0,0,0,0,0,0,0,0,0,0,0
0,0,0,0,0,0,0,0,0,0,0,0,0,0,0,0,0,0,0,0
0,0,0,0,0,0,0,0,0,0,0,0,0,0,0,0,0,0,0,0
0,0,0,0,2,2,2,2,28,2,2,2,2,0,0,0,0,0,0,0
0,0,0,0,2,0,2,2,5,2,0,0,2,0,0,0,0,0,0,0
0,0,0,0,2,2,2,2,2,2,0,0,2,0,0,0,0,0,0,0
0,0,0,0,2,2,2,0,0,2,2,2,2,0,0,0,0,0,0,0
0,0,0,0,2,2,2,17,0,2,2,2,2,0,0,0,0,0,0,0
0,0,0,0,21,5,2,0,0,0,2,5,22,0,0,0,0,0,0,0
0,0,0,0,2,2,2,0,0,0,2,2,2,0,0,0,0,0,0,0
0,0,0,0,2,2,2,0,0,0,2,2,2,0,0,0,0,0,0,0
0,0,0,0,2,2,2,2,2,2,46,45,2,0,0,0,0,0,0,0
0,0,0,0,2,2,2,2,5,2,0,0,2,0,0,0,0,0,0,0
0,0,0,0,2,2,2,2,27,2,2,2,2,0,0,0,0,0,0,0
0,0,0,0,0,0,0,0,0,0,0,0,0,0,0,0,0,0,0,0
0,0,0,0,0,0,0,0,0,0,0,0,0,0,0,0,0,0,0,0
0,0,0,0,0,0,0,0,0,0,0,0,0,0,0,0,0,0,0,0
0,0,0,0,0,0,0,0,0,0,0,0,0,0,0,0,0,0,0,0
0,0,0,0,0,0,0,0,0,0,0,0,0,0,0,0,0,0,0,0
0,0,0,0,0,0,0,0,0,0,0,0,0,0,0,0,0,0,0,0
0,0,0,0,0,0,0,0,0,0,0,0,0,0,0,0,0,0,0,0
0,0,0,0,0,0,0,0,0,0,0,0,0,0,0,0,0,0,0,0
:endlayer
layer: 27
0,0,0,0,0,0,0,0,0,0,0,0,0,0,0,0,0,0,0,0
0,0,0,0,0,0,0,0,0,0,0,0,0,0,0,0,0,0,0,0
0,0,0,0,0,0,0,0,0,0,0,0,0,0,0,0,0,0,0,0
0,0,0,0,0,0,0,0,0,0,0,0,0,0,0,0,0,0,0,0
0,0,0,0,0,0,0,0,0,0,0,0,0,0,0,0,0,0,0,0
0,0,0,0,0,0,0,0,0,0,0,0,0,0,0,0,0,0,0,0
0,0,0,28,28,28,28,0,0,0,0,28,28,28,0,0,0,0,0,0
0,0,0,21,0,2,2,2,2,2,2,2,2,22,0,0,0,0,0,0
0,0,0,21,2,0,0,35,0,35,0,0,2,22,0,0,0,0,0,0
0,0,0,21,2,0,0,35,35,35,0,0,2,22,0,0,0,0,0,0
0,0,0,0,2,0,0,0,0,6,0,2,2,0,0,0,0,0,0,0
0,0,0,0,2,0,0,0,0,2,35,35,2,0,0,0,0,0,0,0
0,0,0,0,2,0,0,0,0,0,35,0,2,0,0,0,0,0,0,0
0,0,0,0,2,0,0,0,0,0,35,35,2,0,0,0,0,0,0,0
0,0,0,0,2,0,0,0,0,0,0,0,2,0,0,0,0,0,0,0
0,0,0,21,2,0,0,35,35,35,0,0,2,22,0,0,0,0,0,0
0,0,0,21,2,2,2,35,0,35,28,28,2,22,0,0,0,0,0,0
0,0,0,21,4,4,2,2,2,2,4,4,10,22,0,0,0,0,0,0
0,0,0,27,27,27,0,0,0,0,27,27,27,27,0,0,0,0,0,0
0,0,0,0,0,0,0,0,0,0,0,0,0,0,0,0,0,0,0,0
0,0,0,0,0,0,0,0,0,0,0,0,0,0,0,0,0,0,0,0
0,0,0,0,0,0,0,0,0,0,0,0,0,0,0,0,0,0,0,0
0,0,0,0,0,0,0,0,0,0,0,0,0,0,0,0,0,0,0,0
0,0,0,0,0,0,0,0,0,0,0,0,0,0,0,0,0,0,0,0
0,0,0,0,0,0,0,0,0,0,0,0,0,0,0,0,0,0,0,0
0,0,0,0,0,0,0,0,0,0,0,0,0,0,0,0,0,0,0,0
:endlayer
layer: 28
0,0,0,0,0,0,0,0,0,0,0,0,0,0,0,0,0,0,0,0
0,0,0,0,0,0,0,0,0,0,0,0,0,0,0,0,0,0,0,0
0,0,0,0,0,0,0,0,0,0,0,0,0,0,0,0,0,0,0,0
0,0,0,0,0,0,0,0,0,0,0,0,0,0,0,0,0,0,0,0
0,0,0,0,0,0,0,0,0,0,0,0,0,0,0,0,0,0,0,0
0,0,0,0,0,0,0,0,0,0,0,0,0,0,0,0,0,0,0,0
0,0,0,2,2,2,2,28,28,28,28,2,2,2,0,0,0,0,0,0
0,0,0,2,2,2,2,2,2,2,2,2,0,2,0,0,0,0,0,0
0,0,0,2,2,0,0,0,0,0,0,0,2,2,0,0,0,0,0,0
0,0,0,2,2,0,0,0,0,0,0,0,2,2,0,0,0,0,0,0
0,0,0,21,2,0,0,0,0,0,0,2,2,22,0,0,0,0,0,0
0,0,0,21,2,0,0,0,0,6,0,0,2,22,0,0,0,0,0,0
0,0,0,21,2,0,0,0,0,2,0,0,2,22,0,0,0,0,0,0
0,0,0,21,2,0,0,0,0,2,0,0,2,22,0,0,0,0,0,0
0,0,0,21,2,0,0,0,0,0,0,0,2,22,0,0,0,0,0,0
0,0,0,2,2,0,0,0,0,0,0,0,2,2,0,0,0,0,0,0
0,0,0,2,35,35,2,2,2,2,35,35,2,2,0,0,0,0,0,0
0,0,0,2,12,12,10,10,10,2,12,12,2,2,0,0,0,0,0,0
0,0,0,2,2,2,27,27,27,27,2,2,2,2,0,0,0,0,0,0
0,0,0,0,0,0,0,0,0,0,0,0,0,0,0,0,0,0,0,0
0,0,0,0,0,0,0,0,0,0,0,0,0,0,0,0,0,0,0,0
0,0,0,0,0,0,0,0,0,0,0,0,0,0,0,0,0,0,0,0
0,0,0,0,0,0,0,0,0,0,0,0,0,0,0,0,0,0,0,0
0,0,0,0,0,0,0,0,0,0,0,0,0,0,0,0,0,0,0,0
0,0,0,0,0,0,0,0,0,0,0,0,0,0,0,0,0,0,0,0
0,0,0,0,0,0,0,0,0,0,0,0,0,0,0,0,0,0,0,0
:endlayer
layer: 29
0,0,0,0,0,0,0,0,0,0,0,0,0,0,0,0,0,0,0,0
0,0,0,0,0,0,0,0,0,0,0,0,0,0,0,0,0,0,0,0
0,0,0,0,0,0,0,0,0,0,0,0,0,0,0,0,0,0,0,0
0,0,0,0,0,0,0,0,0,0,0,0,0,0,0,0,0,0,0,0
0,0,0,0,0,0,0,0,0,0,0,0,0,0,0,0,0,0,0,0
0,0,0,0,0,0,0,0,0,0,0,0,28,28,0,0,0,0,0,0
0,0,0,2,2,2,2,2,2,2,2,2,2,2,0,0,0,0,0,0
0,0,0,2,2,2,2,2,2,2,2,2,2,2,0,0,0,0,0,0
0,0,0,2,2,0,0,0,0,0,0,0,2,2,0,0,0,0,0,0
0,0,0,2,2,0,0,0,0,0,0,0,2,2,0,0,0,0,0,0
0,0,0,2,2,0,0,0,0,0,0,2,2,2,0,0,0,0,0,0
0,0,0,2,2,0,0,0,0,0,0,0,2,2,0,0,0,0,0,0
0,0,0,2,2,0,0,0,0,6,0,0,2,2,0,0,0,0,0,0
0,0,0,2,2,0,0,0,0,2,0,0,2,2,0,0,0,0,0,0
0,0,0,2,2,0,0,0,0,0,0,0,2,2,0,0,0,0,0,0
0,0,0,2,2,0,0,0,0,0,0,0,2,2,0,0,0,0,0,0
0,0,0,2,2,2,2,2,2,2,2,2,2,2,0,0,0,0,0,0
0,0,0,2,0,0,10,10,10,2,2,2,2,2,0,0,0,0,0,0
0,0,0,2,2,2,2,2,2,2,2,2,2,2,0,0,0,0,0,0
0,0,0,27,27,0,0,0,0,0,0,0,0,0,0,0,0,0,0,0
0,0,0,0,0,0,0,0,0,0,0,0,0,0,0,0,0,0,0,0
0,0,0,0,0,0,0,0,0,0,0,0,0,0,0,0,0,0,0,0
0,0,0,0,0,0,0,0,0,0,0,0,0,0,0,0,0,0,0,0
0,0,0,0,0,0,0,0,0,0,0,0,0,0,0,0,0,0,0,0
0,0,0,0,0,0,0,0,0,0,0,0,0,0,0,0,0,0,0,0
0,0,0,0,0,0,0,0,0,0,0,0,0,0,0,0,0,0,0,0
:endlayer
layer: 30
0,0,0,0,0,0,0,0,0,0,0,0,0,0,0,0,0,0,0,0
0,0,0,0,0,0,0,0,0,0,0,0,0,0,0,0,0,0,0,0
0,0,0,0,0,0,0,0,0,0,0,0,0,0,0,0,0,0,0,0
0,0,0,0,0,0,0,0,0,0,0,0,0,0,0,0,0,0,0,0
0,0,0,0,0,0,0,0,0,0,0,0,28,28,28,0,0,0,0,0
0,0,28,28,28,0,0,0,0,0,0,2,2,2,22,0,0,0,0,0
0,0,21,2,2,2,2,2,2,2,2,2,2,2,22,0,0,0,0,0
0,0,21,2,2,2,9,9,9,9,9,2,2,2,0,0,0,0,0,0
0,0,0,2,2,2,2,2,2,2,2,2,2,2,0,0,0,0,0,0
0,0,0,2,2,2,0,0,0,0,0,2,2,2,0,0,0,0,0,0
0,0,0,2,2,2,0,0,0,0,0,2,9,2,0,0,0,0,0,0
0,0,0,2,2,2,0,0,0,0,0,2,9,2,0,0,0,0,0,0
0,0,0,2,9,2,0,0,0,0,0,2,9,2,0,0,0,0,0,0
0,0,0,2,9,2,0,0,0,6,0,2,2,2,0,0,0,0,0,0
0,0,0,2,9,2,0,0,0,2,0,2,2,2,0,0,0,0,0,0
0,0,0,2,15,2,2,2,2,2,2,2,2,2,0,0,0,0,0,0
0,0,0,2,2,2,2,2,2,2,2,2,2,2,0,0,0,0,0,0
0,0,0,2,2,2,9,9,9,9,9,2,2,2,22,0,0,0,0,0
0,0,21,2,2,2,2,2,2,2,2,2,2,2,22,0,0,0,0,0
0,0,21,2,2,2,0,0,0,0,0,0,27,27,27,0,0,0,0,0
0,0,27,27,27,0,0,0,0,0,0,0,0,0,0,0,0,0,0,0
0,0,0,0,0,0,0,0,0,0,0,0,0,0,0,0,0,0,0,0
0,0,0,0,0,0,0,0,0,0,0,0,0,0,0,0,0,0,0,0
0,0,0,0,0,0,0,0,0,0,0,0,0,0,0,0,0,0,0,0
0,0,0,0,0,0,0,0,0,0,0,0,0,0,0,0,0,0,0,0
0,0,0,0,0,0,0,0,0,0,0,0,0,0,0,0,0,0,0,0
:endlayer
layer: 31
0,0,0,0,0,0,0,0,0,0,0,0,0,0,0,0,0,0,0,0
0,0,0,0,0,0,0,0,0,0,0,0,0,0,0,0,0,0,0,0
0,0,0,0,0,0,0,0,0,0,0,0,0,0,0,0,0,0,0,0
0,0,0,0,0,0,0,0,0,0,0,0,28,28,28,0,0,0,0,0
0,0,28,28,28,0,0,0,0,0,0,21,2,0,53,22,0,0,0,0
0,21,52,0,2,22,0,0,0,0,0,2,50,0,51,22,0,0,0,0
0,21,0,0,2,2,2,7,0,8,2,2,0,0,2,22,0,0,0,0
0,21,2,0,50,2,9,9,9,9,9,0,0,2,27,0,0,0,0,0
0,0,27,2,0,0,0,0,0,0,0,0,0,2,0,0,0,0,0,0
0,0,0,2,0,0,0,0,0,0,0,0,0,2,0,0,0,0,0,0
0,0,0,2,0,0,0,0,0,0,0,0,9,1,0,0,0,0,0,0
0,0,0,2,0,0,0,0,0,0,0,0,9,0,0,0,0,0,0,0
0,0,0,1,9,0,0,0,0,0,0,0,9,6,0,0,0,0,0,0
0,0,0,0,9,0,0,0,0,0,0,0,0,2,0,0,0,0,0,0
0,0,0,6,9,0,0,0,0,0,0,0,0,2,0,0,0,0,0,0
0,0,0,2,0,0,0,0,0,0,0,0,0,2,0,0,0,0,0,0
0,0,0,2,0,0,0,0,0,0,0,0,0,2,28,0,0,0,0,0
0,0,28,2,0,0,9,9,9,9,9,2,0,0,0,22,0,0,0,0
0,21,2,17,0,2,2,7,0,8,2,2,0,0,0,22,0,0,0,0
0,21,0,0,0,2,0,0,0,0,0,21,0,49,48,22,0,0,0,0
0,21,0,47,0,22,0,0,0,0,0,0,27,27,27,0,0,0,0,0
0,0,27,27,27,0,0,0,0,0,0,0,0,0,0,0,0,0,0,0
0,0,0,0,0,0,0,0,0,0,0,0,0,0,0,0,0,0,0,0
0,0,0,0,0,0,0,0,0,0,0,0,0,0,0,0,0,0,0,0
0,0,0,0,0,0,0,0,0,0,0,0,0,0,0,0,0,0,0,0
0,0,0,0,0,0,0,0,0,0,0,0,0,0,0,0,0,0,0,0
:endlayer
layer: 32
0,0,0,0,0,0,0,0,0,0,0,0,0,0,0,0,0,0,0,0
0,0,0,0,0,0,0,0,0,0,0,0,0,0,0,0,0,0,0,0
0,0,0,0,0,0,0,0,0,0,0,0,0,0,0,0,0,0,0,0
0,0,0,0,0,0,0,0,0,0,0,0,2,2,2,0,0,0,0,0
0,0,2,2,2,0,0,0,0,0,0,2,2,0,0,2,0,0,0,0
0,2,2,2,2,2,0,0,0,0,0,2,50,0,0,2,0,0,0,0
0,2,2,0,2,0,2,0,0,0,2,2,0,0,2,2,0,0,0,0
0,2,2,0,50,2,9,9,9,9,9,0,0,0,2,0,0,0,0,0
0,0,2,0,0,0,0,0,0,0,0,0,0,2,0,0,0,0,0,0
0,0,0,2,0,0,0,0,0,0,0,0,0,2,0,0,0,0,0,0
0,0,0,2,0,0,0,0,0,0,0,0,9,0,0,0,0,0,0,0
0,0,0,2,0,0,0,0,0,0,0,0,9,0,0,0,0,0,0,0
0,0,0,0,9,0,0,0,0,0,0,0,9,0,0,0,0,0,0,0
0,0,0,0,9,0,0,0,0,0,0,0,0,2,0,0,0,0,0,0
0,0,0,0,9,0,0,0,0,0,0,0,0,2,0,0,0,0,0,0
0,0,0,2,0,0,0,0,0,0,0,0,0,2,0,0,0,0,0,0
0,0,0,2,0,0,0,0,0,0,0,0,0,18,2,0,0,0,0,0
0,0,2,0,0,0,9,9,9,9,9,2,0,0,0,2,0,0,0,0
0,2,2,17,0,2,2,0,0,0,2,0,0,0,0,2,0,0,0,0
0,2,0,0,0,2,0,0,0,0,0,2,0,0,0,2,0,0,0,0
0,2,0,0,0,2,0,0,0,0,0,0,2,2,2,0,0,0,0,0
0,0,2,2,2,0,0,0,0,0,0,0,0,0,0,0,0,0,0,0
0,0,0,0,0,0,0,0,0,0,0,0,0,0,0,0,0,0,0,0
0,0,0,0,0,0,0,0,0,0,0,0,0,0,0,0,0,0,0,0
0,0,0,0,0,0,0,0,0,0,0,0,0,0,0,0,0,0,0,0
0,0,0,0,0,0,0,0,0,0,0,0,0,0,0,0,0,0,0,0
:endlayer
layer: 33
0,0,0,0,0,0,0,0,0,0,0,0,0,0,0,0,0,0,0,0
0,0,0,0,0,0,0,0,0,0,0,0,0,0,0,0,0,0,0,0
0,0,0,0,0,0,0,0,0,0,0,0,0,0,0,0,0,0,0,0
0,0,0,0,0,0,0,0,0,0,0,0,2,6,2,0,0,0,0,0
0,0,2,6,2,0,0,0,0,0,0,2,2,4,0,2,0,0,0,0
0,2,0,4,0,2,0,0,0,0,0,2,50,2,4,7,0,0,0,0
0,8,4,2,2,0,2,22,0,21,2,2,0,0,2,2,0,0,0,0
0,2,2,0,50,2,9,9,9,9,9,0,0,0,2,0,0,0,0,0
0,0,2,0,0,0,0,0,0,0,0,0,0,2,0,0,0,0,0,0
0,0,0,2,0,0,0,0,0,0,0,0,0,2,0,0,0,0,0,0
0,0,0,2,0,0,0,0,0,0,0,0,9,27,0,0,0,0,0,0
0,0,0,2,0,0,0,0,0,0,0,0,9,0,0,0,0,0,0,0
0,0,0,27,9,0,0,0,0,0,0,0,9,28,0,0,0,0,0,0
0,0,0,0,9,0,0,0,0,0,0,0,0,2,0,0,0,0,0,0
0,0,0,28,9,0,0,0,0,0,0,0,0,2,0,0,0,0,0,0
0,0,0,2,0,0,0,0,0,0,0,0,0,2,0,0,0,0,0,0
0,0,0,2,0,0,0,0,0,0,0,0,0,18,2,0,0,0,0,0
0,0,2,0,0,0,9,9,9,9,9,2,2,2,2,2,0,0,0,0
0,2,2,17,0,2,2,22,0,21,2,0,2,2,4,7,0,0,0,0
0,8,4,2,2,2,0,0,0,0,0,2,2,4,0,2,0,0,0,0
0,2,0,4,2,2,0,0,0,0,0,0,2,1,2,0,0,0,0,0
0,0,2,1,2,0,0,0,0,0,0,0,0,0,0,0,0,0,0,0
0,0,0,0,0,0,0,0,0,0,0,0,0,0,0,0,0,0,0,0
0,0,0,0,0,0,0,0,0,0,0,0,0,0,0,0,0,0,0,0
0,0,0,0,0,0,0,0,0,0,0,0,0,0,0,0,0,0,0,0
0,0,0,0,0,0,0,0,0,0,0,0,0,0,0,0,0,0,0,0
:endlayer
layer: 34
0,0,0,0,0,0,0,0,0,0,0,0,0,0,0,0,0,0,0,0
0,0,0,0,0,0,0,0,0,0,0,0,0,0,0,0,0,0,0,0
0,0,0,0,0,0,0,0,0,0,0,0,0,0,0,0,0,0,0,0
0,0,0,0,0,0,0,0,0,0,0,0,2,0,2,0,0,0,0,0
0,0,2,0,2,0,0,0,0,0,0,2,0,12,0,2,0,0,0,0
0,2,0,12,0,2,0,0,0,0,0,2,0,0,12,0,0,0,0,0
0,0,12,0,55,0,2,2,2,2,2,2,0,0,0,2,0,0,0,0
0,2,0,0,0,2,5,5,5,5,5,2,0,0,2,0,0,0,0,0
0,0,2,0,0,2,2,2,2,2,2,2,0,2,0,0,0,0,0,0
0,0,0,2,2,2,0,0,0,0,0,2,2,2,0,0,0,0,0,0
0,0,0,2,2,2,0,0,0,0,0,2,5,2,0,0,0,0,0,0
0,0,0,2,2,2,0,0,0,0,0,2,5,2,0,0,0,0,0,0
0,0,0,2,5,2,0,0,0,0,0,2,5,2,0,0,0,0,0,0
0,0,0,2,5,2,0,0,0,0,0,2,2,2,0,0,0,0,0,0
0,0,0,2,5,2,0,0,0,0,0,2,2,2,0,0,0,0,0,0
0,0,0,2,2,2,0,0,0,0,0,2,2,2,0,0,0,0,0,0
0,0,0,2,0,2,2,2,2,2,2,2,0,0,2,0,0,0,0,0
0,0,2,0,0,2,5,5,5,5,5,2,0,0,0,2,0,0,0,0
0,2,54,0,0,2,2,2,2,2,2,0,0,0,12,0,0,0,0,0
0,0,12,0,0,2,0,0,0,0,0,2,0,12,0,2,0,0,0,0
0,2,0,12,0,2,0,0,0,0,0,0,2,0,2,0,0,0,0,0
0,0,2,0,2,0,0,0,0,0,0,0,0,0,0,0,0,0,0,0
0,0,0,0,0,0,0,0,0,0,0,0,0,0,0,0,0,0,0,0
0,0,0,0,0,0,0,0,0,0,0,0,0,0,0,0,0,0,0,0
0,0,0,0,0,0,0,0,0,0,0,0,0,0,0,0,0,0,0,0
0,0,0,0,0,0,0,0,0,0,0,0,0,0,0,0,0,0,0,0
:endlayer
layer: 35
0,0,0,0,0,0,0,0,0,0,0,0,0,0,0,0,0,0,0,0
0,0,0,0,0,0,0,0,0,0,0,0,0,0,0,0,0,0,0,0
0,0,0,0,0,0,0,0,0,0,0,0,0,0,0,0,0,0,0,0
0,0,0,0,0,0,0,0,0,0,0,0,2,0,2,0,0,0,0,0
0,0,2,0,2,0,0,0,0,0,0,2,0,0,0,2,0,0,0,0
0,2,0,0,0,2,0,0,0,0,0,2,0,0,0,0,0,0,0,0
0,0,0,0,0,0,2,2,2,2,2,0,0,0,0,2,0,0,0,0
0,2,0,0,0,0,0,0,0,0,0,0,0,0,2,0,0,0,0,0
0,0,2,0,0,0,0,0,0,0,0,0,0,2,0,0,0,0,0,0
0,0,0,2,0,0,0,0,0,0,0,0,0,2,0,0,0,0,0,0
0,0,0,2,0,0,0,0,0,0,0,0,0,2,0,0,0,0,0,0
0,0,0,2,0,0,0,0,0,0,0,0,0,2,0,0,0,0,0,0
0,0,0,2,0,0,0,0,0,0,0,0,0,2,0,0,0,0,0,0
0,0,0,2,0,0,0,0,0,0,0,0,0,2,0,0,0,0,0,0
0,0,0,2,0,0,0,0,0,0,0,0,0,2,0,0,0,0,0,0
0,0,0,2,0,0,0,0,0,0,0,0,0,2,0,0,0,0,0,0
0,0,0,2,0,0,0,0,0,0,0,0,2,2,2,0,0,0,0,0
0,0,2,0,0,0,0,0,0,0,0,2,0,0,0,2,0,0,0,0
0,2,0,0,0,0,2,2,2,2,2,2,0,0,0,0,0,0,0,0
0,0,0,0,0,2,0,0,0,0,0,2,0,0,0,2,0,0,0,0
0,2,0,0,0,2,0,0,0,0,0,0,2,0,2,0,0,0,0,0
0,0,2,0,2,0,0,0,0,0,0,0,0,0,0,0,0,0,0,0
0,0,0,0,0,0,0,0,0,0,0,0,0,0,0,0,0,0,0,0
0,0,0,0,0,0,0,0,0,0,0,0,0,0,0,0,0,0,0,0
0,0,0,0,0,0,0,0,0,0,0,0,0,0,0,0,0,0,0,0
0,0,0,0,0,0,0,0,0,0,0,0,0,0,0,0,0,0,0,0
:endlayer
layer: 36
0,0,0,0,0,0,0,0,0,0,0,0,0,0,0,0,0,0,0,0
0,0,0,0,0,0,0,0,0,0,0,0,0,0,0,0,0,0,0,0
0,0,0,0,0,0,0,0,0,0,0,0,0,0,0,0,0,0,0,0
0,0,0,0,0,0,0,0,0,0,0,0,2,28,2,0,0,0,0,0
0,0,2,28,2,0,0,0,0,0,0,2,0,0,0,2,0,0,0,0
0,2,0,0,0,2,0,0,0,0,0,2,0,0,0,22,0,0,0,0
0,21,0,0,0,0,2,0,2,0,2,0,0,0,2,2,0,0,0,0
0,2,0,0,0,0,0,0,0,0,0,0,0,0,2,0,0,0,0,0
0,0,2,2,0,0,0,0,0,0,0,0,0,2,0,0,0,0,0,0
0,0,0,0,0,0,0,0,0,0,0,0,0,0,0,0,0,0,0,0
0,0,0,2,0,0,0,0,0,0,0,0,0,2,0,0,0,0,0,0
0,0,0,0,0,0,0,0,0,0,0,0,0,0,0,0,0,0,0,0
0,0,0,2,0,0,0,0,0,0,0,0,0,2,0,0,0,0,0,0
0,0,0,0,0,0,0,0,0,0,0,0,0,0,0,0,0,0,0,0
0,0,0,2,0,0,0,0,0,0,0,0,0,2,0,0,0,0,0,0
0,0,0,0,0,0,0,0,0,0,0,0,0,0,0,0,0,0,0,0
0,0,0,2,0,0,0,0,0,0,0,0,2,2,2,0,0,0,0,0
0,0,2,0,0,0,0,0,0,0,0,2,0,0,0,2,0,0,0,0
0,2,2,0,0,0,2,0,2,0,2,2,0,0,0,22,0,0,0,0
0,21,0,0,0,2,0,0,0,0,0,2,0,0,0,2,0,0,0,0
0,2,0,0,0,2,0,0,0,0,0,0,2,27,2,0,0,0,0,0
0,0,2,27,2,0,0,0,0,0,0,0,0,0,0,0,0,0,0,0
0,0,0,0,0,0,0,0,0,0,0,0,0,0,0,0,0,0,0,0
0,0,0,0,0,0,0,0,0,0,0,0,0,0,0,0,0,0,0,0
0,0,0,0,0,0,0,0,0,0,0,0,0,0,0,0,0,0,0,0
0,0,0,0,0,0,0,0,0,0,0,0,0,0,0,0,0,0,0,0
:endlayer
layer: 37
0,0,0,0,0,0,0,0,0,0,0,0,0,0,0,0,0,0,0,0
0,0,0,0,0,0,0,0,0,0,0,0,0,0,0,0,0,0,0,0
0,0,0,0,0,0,0,0,0,0,0,0,0,0,0,0,0,0,0,0
0,0,0,0,0,0,0,0,0,0,0,0,2,2,2,0,0,0,0,0
0,0,2,2,2,0,0,0,0,0,0,2,0,0,0,2,0,0,0,0
0,2,0,2,0,2,0,0,0,0,0,2,0,0,0,2,0,0,0,0
0,2,0,0,2,2,0,0,0,0,0,2,0,0,0,2,0,0,0,0
0,2,0,0,0,2,0,0,0,0,0,0,0,2,2,0,0,0,0,0
0,0,2,2,2,0,0,0,0,0,0,0,0,0,0,0,0,0,0,0
0,0,0,0,0,0,0,0,0,0,0,0,0,0,0,0,0,0,0,0
0,0,0,0,0,0,0,0,0,0,0,0,0,0,0,0,0,0,0,0
0,0,0,0,0,0,0,0,0,0,0,0,0,0,0,0,0,0,0,0
0,0,0,0,0,0,0,0,0,0,0,0,0,0,0,0,0,0,0,0
0,0,0,0,0,0,0,0,0,0,0,0,0,0,0,0,0,0,0,0
0,0,0,0,0,0,0,0,0,0,0,0,0,0,0,0,0,0,0,0
0,0,0,0,0,0,0,0,0,0,0,0,0,0,0,0,0,0,0,0
0,0,0,0,0,0,0,0,0,0,0,0,2,2,2,0,0,0,0,0
0,0,2,2,0,0,0,0,0,0,0,2,0,0,0,2,0,0,0,0
0,2,0,0,0,2,0,0,0,0,0,2,2,0,0,2,0,0,0,0
0,2,0,0,0,2,0,0,0,0,0,2,0,2,0,2,0,0,0,0
0,2,0,0,0,2,0,0,0,0,0,0,2,2,2,0,0,0,0,0
0,0,2,2,2,0,0,0,0,0,0,0,0,0,0,0,0,0,0,0
0,0,0,0,0,0,0,0,0,0,0,0,0,0,0,0,0,0,0,0
0,0,0,0,0,0,0,0,0,0,0,0,0,0,0,0,0,0,0,0
0,0,0,0,0,0,0,0,0,0,0,0,0,0,0,0,0,0,0,0
0,0,0,0,0,0,0,0,0,0,0,0,0,0,0,0,0,0,0,0
:endlayer
layer: 38
0,0,0,0,0,0,0,0,0,0,0,0,0,0,0,0,0,0,0,0
0,0,0,0,0,0,0,0,0,0,0,0,0,0,0,0,0,0,0,0
0,0,0,0,0,0,0,0,0,0,0,0,0,0,0,0,0,0,0,0
0,0,0,0,0,0,0,0,0,0,0,0,6,6,6,0,0,0,0,0
0,0,6,6,6,0,0,0,0,0,0,8,2,2,2,7,0,0,0,0
0,8,0,0,0,7,0,0,0,0,0,8,2,0,2,7,0,0,0,0
0,8,0,0,0,7,0,0,0,0,0,8,2,0,2,7,0,0,0,0
0,8,0,0,0,7,0,0,0,0,0,0,1,1,1,0,0,0,0,0
0,0,1,1,1,0,0,0,0,0,0,0,0,0,0,0,0,0,0,0
0,0,0,0,0,0,0,0,0,0,0,0,0,0,0,0,0,0,0,0
0,0,0,0,0,0,0,0,0,0,0,0,0,0,0,0,0,0,0,0
0,0,0,0,0,0,0,0,0,0,0,0,0,0,0,0,0,0,0,0
0,0,0,0,0,0,0,0,0,0,0,0,0,0,0,0,0,0,0,0
0,0,0,0,0,0,0,0,0,0,0,0,0,0,0,0,0,0,0,0
0,0,0,0,0,0,0,0,0,0,0,0,0,0,0,0,0,0,0,0
0,0,0,0,0,0,0,0,0,0,0,0,0,0,0,0,0,0,0,0
0,0,0,0,0,0,0,0,0,0,0,0,6,6,6,0,0,0,0,0
0,0,6,6,6,0,0,0,0,0,0,8,0,0,0,7,0,0,0,0
0,8,2,0,2,7,0,0,0,0,0,8,0,0,0,7,0,0,0,0
0,8,2,0,2,7,0,0,0,0,0,8,0,0,0,7,0,0,0,0
0,8,2,2,2,7,0,0,0,0,0,0,1,1,1,0,0,0,0,0
0,0,1,1,1,0,0,0,0,0,0,0,0,0,0,0,0,0,0,0
0,0,0,0,0,0,0,0,0,0,0,0,0,0,0,0,0,0,0,0
0,0,0,0,0,0,0,0,0,0,0,0,0,0,0,0,0,0,0,0
0,0,0,0,0,0,0,0,0,0,0,0,0,0,0,0,0,0,0,0
0,0,0,0,0,0,0,0,0,0,0,0,0,0,0,0,0,0,0,0
:endlayer
layer: 39
0,0,0,0,0,0,0,0,0,0,0,0,0,0,0,0,0,0,0,0
0,0,0,0,0,0,0,0,0,0,0,0,0,0,0,0,0,0,0,0
0,0,0,0,0,0,0,0,0,0,0,0,0,0,0,0,0,0,0,0
0,0,0,0,0,0,0,0,0,0,0,0,0,0,0,0,0,0,0,0
0,0,0,0,0,0,0,0,0,0,0,0,2,2,2,0,0,0,0,0
0,0,2,2,2,0,0,0,0,0,0,0,2,0,2,0,0,0,0,0
0,0,2,2,2,0,0,0,0,0,0,0,2,2,2,0,0,0,0,0
0,0,2,2,2,0,0,0,0,0,0,0,0,0,0,0,0,0,0,0
0,0,0,0,0,0,0,0,0,0,0,0,0,0,0,0,0,0,0,0
0,0,0,0,0,0,0,0,0,0,0,0,0,0,0,0,0,0,0,0
0,0,0,0,0,0,0,0,0,0,0,0,0,0,0,0,0,0,0,0
0,0,0,0,0,0,0,0,0,0,0,0,0,0,0,0,0,0,0,0
0,0,0,0,0,0,0,0,0,0,0,0,0,0,0,0,0,0,0,0
0,0,0,0,0,0,0,0,0,0,0,0,0,0,0,0,0,0,0,0
0,0,0,0,0,0,0,0,0,0,0,0,0,0,0,0,0,0,0,0
0,0,0,0,0,0,0,0,0,0,0,0,0,0,0,0,0,0,0,0
0,0,0,0,0,0,0,0,0,0,0,0,0,0,0,0,0,0,0,0
0,0,0,0,0,0,0,0,0,0,0,0,2,2,2,0,0,0,0,0
0,0,2,2,2,0,0,0,0,0,0,0,2,2,2,0,0,0,0,0
0,0,2,0,2,0,0,0,0,0,0,0,2,2,2,0,0,0,0,0
0,0,2,2,2,0,0,0,0,0,0,0,0,0,0,0,0,0,0,0
0,0,0,0,0,0,0,0,0,0,0,0,0,0,0,0,0,0,0,0
0,0,0,0,0,0,0,0,0,0,0,0,0,0,0,0,0,0,0,0
0,0,0,0,0,0,0,0,0,0,0,0,0,0,0,0,0,0,0,0
0,0,0,0,0,0,0,0,0,0,0,0,0,0,0,0,0,0,0,0
0,0,0,0,0,0,0,0,0,0,0,0,0,0,0,0,0,0,0,0
:endlayer
layer: 40
0,0,0,0,0,0,0,0,0,0,0,0,0,0,0,0,0,0,0,0
0,0,0,0,0,0,0,0,0,0,0,0,0,0,0,0,0,0,0,0
0,0,0,0,0,0,0,0,0,0,0,0,0,0,0,0,0,0,0,0
0,0,0,0,0,0,0,0,0,0,0,0,0,0,0,0,0,0,0,0
0,0,0,0,0,0,0,0,0,0,0,0,2,2,2,0,0,0,0,0
0,0,2,2,2,0,0,0,0,0,0,0,2,0,2,0,0,0,0,0
0,0,2,56,2,0,0,0,0,0,0,0,2,2,2,0,0,0,0,0
0,0,2,2,2,0,0,0,0,0,0,0,0,0,0,0,0,0,0,0
0,0,0,0,0,0,0,0,0,0,0,0,0,0,0,0,0,0,0,0
0,0,0,0,0,0,0,0,0,0,0,0,0,0,0,0,0,0,0,0
0,0,0,0,0,0,0,0,0,0,0,0,0,0,0,0,0,0,0,0
0,0,0,0,0,0,0,0,0,0,0,0,0,0,0,0,0,0,0,0
0,0,0,0,0,0,0,0,0,0,0,0,0,0,0,0,0,0,0,0
0,0,0,0,0,0,0,0,0,0,0,0,0,0,0,0,0,0,0,0
0,0,0,0,0,0,0,0,0,0,0,0,0,0,0,0,0,0,0,0
0,0,0,0,0,0,0,0,0,0,0,0,0,0,0,0,0,0,0,0
0,0,0,0,0,0,0,0,0,0,0,0,0,0,0,0,0,0,0,0
0,0,0,0,0,0,0,0,0,0,0,0,2,2,2,0,0,0,0,0
0,0,2,2,2,0,0,0,0,0,0,0,2,56,2,0,0,0,0,0
0,0,2,0,2,0,0,0,0,0,0,0,2,2,2,0,0,0,0,0
0,0,2,2,2,0,0,0,0,0,0,0,0,0,0,0,0,0,0,0
0,0,0,0,0,0,0,0,0,0,0,0,0,0,0,0,0,0,0,0
0,0,0,0,0,0,0,0,0,0,0,0,0,0,0,0,0,0,0,0
0,0,0,0,0,0,0,0,0,0,0,0,0,0,0,0,0,0,0,0
0,0,0,0,0,0,0,0,0,0,0,0,0,0,0,0,0,0,0,0
0,0,0,0,0,0,0,0,0,0,0,0,0,0,0,0,0,0,0,0
:endlayer
layer: 41
0,0,0,0,0,0,0,0,0,0,0,0,0,0,0,0,0,0,0,0
0,0,0,0,0,0,0,0,0,0,0,0,0,0,0,0,0,0,0,0
0,0,0,0,0,0,0,0,0,0,0,0,0,0,0,0,0,0,0,0
0,0,0,0,0,0,0,0,0,0,0,0,0,0,0,0,0,0,0,0
0,0,0,0,0,0,0,0,0,0,0,0,0,6,0,0,0,0,0,0
0,0,0,6,0,0,0,0,0,0,0,0,8,2,7,0,0,0,0,0
0,0,8,56,7,0,0,0,0,0,0,0,0,1,0,0,0,0,0,0
0,0,0,1,0,0,0,0,0,0,0,0,0,0,0,0,0,0,0,0
0,0,0,0,0,0,0,0,0,0,0,0,0,0,0,0,0,0,0,0
0,0,0,0,0,0,0,0,0,0,0,0,0,0,0,0,0,0,0,0
0,0,0,0,0,0,0,0,0,0,0,0,0,0,0,0,0,0,0,0
0,0,0,0,0,0,0,0,0,0,0,0,0,0,0,0,0,0,0,0
0,0,0,0,0,0,0,0,0,0,0,0,0,0,0,0,0,0,0,0
0,0,0,0,0,0,0,0,0,0,0,0,0,0,0,0,0,0,0,0
0,0,0,0,0,0,0,0,0,0,0,0,0,0,0,0,0,0,0,0
0,0,0,0,0,0,0,0,0,0,0,0,0,0,0,0,0,0,0,0
0,0,0,0,0,0,0,0,0,0,0,0,0,0,0,0,0,0,0,0
0,0,0,0,0,0,0,0,0,0,0,0,0,6,0,0,0,0,0,0
0,0,0,6,0,0,0,0,0,0,0,0,8,56,7,0,0,0,0,0
0,0,8,2,7,0,0,0,0,0,0,0,0,1,0,0,0,0,0,0
0,0,0,1,0,0,0,0,0,0,0,0,0,0,0,0,0,0,0,0
0,0,0,0,0,0,0,0,0,0,0,0,0,0,0,0,0,0,0,0
0,0,0,0,0,0,0,0,0,0,0,0,0,0,0,0,0,0,0,0
0,0,0,0,0,0,0,0,0,0,0,0,0,0,0,0,0,0,0,0
0,0,0,0,0,0,0,0,0,0,0,0,0,0,0,0,0,0,0,0
0,0,0,0,0,0,0,0,0,0,0,0,0,0,0,0,0,0,0,0
:endlayer
layer: 42
0,0,0,0,0,0,0,0,0,0,0,0,0,0,0,0,0,0,0,0
0,0,0,0,0,0,0,0,0,0,0,0,0,0,0,0,0,0,0,0
0,0,0,0,0,0,0,0,0,0,0,0,0,0,0,0,0,0,0,0
0,0,0,0,0,0,0,0,0,0,0,0,0,0,0,0,0,0,0,0
0,0,0,0,0,0,0,0,0,0,0,0,0,0,0,0,0,0,0,0
0,0,0,0,0,0,0,0,0,0,0,0,0,2,0,0,0,0,0,0
0,0,0,2,0,0,0,0,0,0,0,0,0,0,0,0,0,0,0,0
0,0,0,0,0,0,0,0,0,0,0,0,0,0,0,0,0,0,0,0
0,0,0,0,0,0,0,0,0,0,0,0,0,0,0,0,0,0,0,0
0,0,0,0,0,0,0,0,0,0,0,0,0,0,0,0,0,0,0,0
0,0,0,0,0,0,0,0,0,0,0,0,0,0,0,0,0,0,0,0
0,0,0,0,0,0,0,0,0,0,0,0,0,0,0,0,0,0,0,0
0,0,0,0,0,0,0,0,0,0,0,0,0,0,0,0,0,0,0,0
0,0,0,0,0,0,0,0,0,0,0,0,0,0,0,0,0,0,0,0
0,0,0,0,0,0,0,0,0,0,0,0,0,0,0,0,0,0,0,0
0,0,0,0,0,0,0,0,0,0,0,0,0,0,0,0,0,0,0,0
0,0,0,0,0,0,0,0,0,0,0,0,0,0,0,0,0,0,0,0
0,0,0,0,0,0,0,0,0,0,0,0,0,0,0,0,0,0,0,0
0,0,0,0,0,0,0,0,0,0,0,0,0,2,0,0,0,0,0,0
0,0,0,2,0,0,0,0,0,0,0,0,0,0,0,0,0,0,0,0
0,0,0,0,0,0,0,0,0,0,0,0,0,0,0,0,0,0,0,0
0,0,0,0,0,0,0,0,0,0,0,0,0,0,0,0,0,0,0,0
0,0,0,0,0,0,0,0,0,0,0,0,0,0,0,0,0,0,0,0
0,0,0,0,0,0,0,0,0,0,0,0,0,0,0,0,0,0,0,0
0,0,0,0,0,0,0,0,0,0,0,0,0,0,0,0,0,0,0,0
0,0,0,0,0,0,0,0,0,0,0,0,0,0,0,0,0,0,0,0
:endlayer
layer: 43
0,0,0,0,0,0,0,0,0,0,0,0,0,0,0,0,0,0,0,0
0,0,0,0,0,0,0,0,0,0,0,0,0,0,0,0,0,0,0,0
0,0,0,0,0,0,0,0,0,0,0,0,0,0,0,0,0,0,0,0
0,0,0,0,0,0,0,0,0,0,0,0,0,0,0,0,0,0,0,0
0,0,0,0,0,0,0,0,0,0,0,0,0,0,0,0,0,0,0,0
0,0,0,0,0,0,0,0,0,0,0,0,0,2,0,0,0,0,0,0
0,0,0,2,0,0,0,0,0,0,0,0,0,0,0,0,0,0,0,0
0,0,0,0,0,0,0,0,0,0,0,0,0,0,0,0,0,0,0,0
0,0,0,0,0,0,0,0,0,0,0,0,0,0,0,0,0,0,0,0
0,0,0,0,0,0,0,0,0,0,0,0,0,0,0,0,0,0,0,0
0,0,0,0,0,0,0,0,0,0,0,0,0,0,0,0,0,0,0,0
0,0,0,0,0,0,0,0,0,0,0,0,0,0,0,0,0,0,0,0
0,0,0,0,0,0,0,0,0,0,0,0,0,0,0,0,0,0,0,0
0,0,0,0,0,0,0,0,0,0,0,0,0,0,0,0,0,0,0,0
0,0,0,0,0,0,0,0,0,0,0,0,0,0,0,0,0,0,0,0
0,0,0,0,0,0,0,0,0,0,0,0,0,0,0,0,0,0,0,0
0,0,0,0,0,0,0,0,0,0,0,0,0,0,0,0,0,0,0,0
0,0,0,0,0,0,0,0,0,0,0,0,0,0,0,0,0,0,0,0
0,0,0,0,0,0,0,0,0,0,0,0,0,2,0,0,0,0,0,0
0,0,0,2,0,0,0,0,0,0,0,0,0,0,0,0,0,0,0,0
0,0,0,0,0,0,0,0,0,0,0,0,0,0,0,0,0,0,0,0
0,0,0,0,0,0,0,0,0,0,0,0,0,0,0,0,0,0,0,0
0,0,0,0,0,0,0,0,0,0,0,0,0,0,0,0,0,0,0,0
0,0,0,0,0,0,0,0,0,0,0,0,0,0,0,0,0,0,0,0
0,0,0,0,0,0,0,0,0,0,0,0,0,0,0,0,0,0,0,0
0,0,0,0,0,0,0,0,0,0,0,0,0,0,0,0,0,0,0,0
:endlayer
layer: 44
0,0,0,0,0,0,0,0,0,0,0,0,0,0,0,0,0,0,0,0
0,0,0,0,0,0,0,0,0,0,0,0,0,0,0,0,0,0,0,0
0,0,0,0,0,0,0,0,0,0,0,0,0,0,0,0,0,0,0,0
0,0,0,0,0,0,0,0,0,0,0,0,0,0,0,0,0,0,0,0
0,0,0,0,0,0,0,0,0,0,0,0,0,0,0,0,0,0,0,0
0,0,0,0,0,0,0,0,0,0,0,0,0,11,0,0,0,0,0,0
0,0,0,11,0,0,0,0,0,0,0,0,0,0,0,0,0,0,0,0
0,0,0,0,0,0,0,0,0,0,0,0,0,0,0,0,0,0,0,0
0,0,0,0,0,0,0,0,0,0,0,0,0,0,0,0,0,0,0,0
0,0,0,0,0,0,0,0,0,0,0,0,0,0,0,0,0,0,0,0
0,0,0,0,0,0,0,0,0,0,0,0,0,0,0,0,0,0,0,0
0,0,0,0,0,0,0,0,0,0,0,0,0,0,0,0,0,0,0,0
0,0,0,0,0,0,0,0,0,0,0,0,0,0,0,0,0,0,0,0
0,0,0,0,0,0,0,0,0,0,0,0,0,0,0,0,0,0,0,0
0,0,0,0,0,0,0,0,0,0,0,0,0,0,0,0,0,0,0,0
0,0,0,0,0,0,0,0,0,0,0,0,0,0,0,0,0,0,0,0
0,0,0,0,0,0,0,0,0,0,0,0,0,0,0,0,0,0,0,0
0,0,0,0,0,0,0,0,0,0,0,0,0,0,0,0,0,0,0,0
0,0,0,0,0,0,0,0,0,0,0,0,0,11,0,0,0,0,0,0
0,0,0,11,0,0,0,0,0,0,0,0,0,0,0,0,0,0,0,0
0,0,0,0,0,0,0,0,0,0,0,0,0,0,0,0,0,0,0,0
0,0,0,0,0,0,0,0,0,0,0,0,0,0,0,0,0,0,0,0
0,0,0,0,0,0,0,0,0,0,0,0,0,0,0,0,0,0,0,0
0,0,0,0,0,0,0,0,0,0,0,0,0,0,0,0,0,0,0,0
0,0,0,0,0,0,0,0,0,0,0,0,0,0,0,0,0,0,0,0
0,0,0,0,0,0,0,0,0,0,0,0,0,0,0,0,0,0,0,0
:endlayer
layer: 45
0,0,0,0,0,0,0,0,0,0,0,0,0,0,0,0,0,0,0,0
0,0,0,0,0,0,0,0,0,0,0,0,0,0,0,0,0,0,0,0
0,0,0,0,0,0,0,0,0,0,0,0,0,0,0,0,0,0,0,0
0,0,0,0,0,0,0,0,0,0,0,0,0,0,0,0,0,0,0,0
0,0,0,0,0,0,0,0,0,0,0,0,0,0,0,0,0,0,0,0
0,0,0,0,0,0,0,0,0,0,0,0,0,11,0,0,0,0,0,0
0,0,0,11,0,0,0,0,0,0,0,0,0,0,0,0,0,0,0,0
0,0,0,0,0,0,0,0,0,0,0,0,0,0,0,0,0,0,0,0
0,0,0,0,0,0,0,0,0,0,0,0,0,0,0,0,0,0,0,0
0,0,0,0,0,0,0,0,0,0,0,0,0,0,0,0,0,0,0,0
0,0,0,0,0,0,0,0,0,0,0,0,0,0,0,0,0,0,0,0
0,0,0,0,0,0,0,0,0,0,0,0,0,0,0,0,0,0,0,0
0,0,0,0,0,0,0,0,0,0,0,0,0,0,0,0,0,0,0,0
0,0,0,0,0,0,0,0,0,0,0,0,0,0,0,0,0,0,0,0
0,0,0,0,0,0,0,0,0,0,0,0,0,0,0,0,0,0,0,0
0,0,0,0,0,0,0,0,0,0,0,0,0,0,0,0,0,0,0,0
0,0,0,0,0,0,0,0,0,0,0,0,0,0,0,0,0,0,0,0
0,0,0,0,0,0,0,0,0,0,0,0,0,0,0,0,0,0,0,0
0,0,0,0,0,0,0,0,0,0,0,0,0,11,0,0,0,0,0,0
0,0,0,11,0,0,0,0,0,0,0,0,0,0,0,0,0,0,0,0
0,0,0,0,0,0,0,0,0,0,0,0,0,0,0,0,0,0,0,0
0,0,0,0,0,0,0,0,0,0,0,0,0,0,0,0,0,0,0,0
0,0,0,0,0,0,0,0,0,0,0,0,0,0,0,0,0,0,0,0
0,0,0,0,0,0,0,0,0,0,0,0,0,0,0,0,0,0,0,0
0,0,0,0,0,0,0,0,0,0,0,0,0,0,0,0,0,0,0,0
0,0,0,0,0,0,0,0,0,0,0,0,0,0,0,0,0,0,0,0
:endlayer
layer: 46
0,0,0,0,0,0,0,0,0,0,0,0,0,0,0,0,0,0,0,0
0,0,0,0,0,0,0,0,0,0,0,0,0,0,0,0,0,0,0,0
0,0,0,0,0,0,0,0,0,0,0,0,0,0,0,0,0,0,0,0
0,0,0,0,0,0,0,0,0,0,0,0,0,0,0,0,0,0,0,0
0,0,0,0,0,0,0,0,0,0,0,0,0,0,0,0,0,0,0,0
0,0,0,0,0,0,0,0,0,0,0,0,0,0,0,0,0,0,0,0
0,0,0,0,0,0,0,0,0,0,0,0,0,0,0,0,0,0,0,0
0,0,0,0,0,0,0,0,0,0,0,0,0,0,0,0,0,0,0,0
0,0,0,0,0,0,0,0,0,0,0,0,0,0,0,0,0,0,0,0
0,0,0,0,0,0,0,0,0,0,0,0,0,0,0,0,0,0,0,0
0,0,0,0,0,0,0,0,0,0,0,0,0,0,0,0,0,0,0,0
0,0,0,0,0,0,0,0,0,0,0,0,0,0,0,0,0,0,0,0
0,0,0,0,0,0,0,0,0,0,0,0,0,0,0,0,0,0,0,0
0,0,0,0,0,0,0,0,0,0,0,0,0,0,0,0,0,0,0,0
0,0,0,0,0,0,0,0,0,0,0,0,0,0,0,0,0,0,0,0
0,0,0,0,0,0,0,0,0,0,0,0,0,0,0,0,0,0,0,0
0,0,0,0,0,0,0,0,0,0,0,0,0,0,0,0,0,0,0,0
0,0,0,0,0,0,0,0,0,0,0,0,0,0,0,0,0,0,0,0
0,0,0,0,0,0,0,0,0,0,0,0,0,0,0,0,0,0,0,0
0,0,0,0,0,0,0,0,0,0,0,0,0,0,0,0,0,0,0,0
0,0,0,0,0,0,0,0,0,0,0,0,0,0,0,0,0,0,0,0
0,0,0,0,0,0,0,0,0,0,0,0,0,0,0,0,0,0,0,0
0,0,0,0,0,0,0,0,0,0,0,0,0,0,0,0,0,0,0,0
0,0,0,0,0,0,0,0,0,0,0,0,0,0,0,0,0,0,0,0
0,0,0,0,0,0,0,0,0,0,0,0,0,0,0,0,0,0,0,0
0,0,0,0,0,0,0,0,0,0,0,0,0,0,0,0,0,0,0,0
:endlayer
layer: 47
0,0,0,0,0,0,0,0,0,0,0,0,0,0,0,0,0,0,0,0
0,0,0,0,0,0,0,0,0,0,0,0,0,0,0,0,0,0,0,0
0,0,0,0,0,0,0,0,0,0,0,0,0,0,0,0,0,0,0,0
0,0,0,0,0,0,0,0,0,0,0,0,0,0,0,0,0,0,0,0
0,0,0,0,0,0,0,0,0,0,0,0,0,0,0,0,0,0,0,0
0,0,0,0,0,0,0,0,0,0,0,0,0,0,0,0,0,0,0,0
0,0,0,0,0,0,0,0,0,0,0,0,0,0,0,0,0,0,0,0
0,0,0,0,0,0,0,0,0,0,0,0,0,0,0,0,0,0,0,0
0,0,0,0,0,0,0,0,0,0,0,0,0,0,0,0,0,0,0,0
0,0,0,0,0,0,0,0,0,0,0,0,0,0,0,0,0,0,0,0
0,0,0,0,0,0,0,0,0,0,0,0,0,0,0,0,0,0,0,0
0,0,0,0,0,0,0,0,0,0,0,0,0,0,0,0,0,0,0,0
0,0,0,0,0,0,0,0,0,0,0,0,0,0,0,0,0,0,0,0
0,0,0,0,0,0,0,0,0,0,0,0,0,0,0,0,0,0,0,0
0,0,0,0,0,0,0,0,0,0,0,0,0,0,0,0,0,0,0,0
0,0,0,0,0,0,0,0,0,0,0,0,0,0,0,0,0,0,0,0
0,0,0,0,0,0,0,0,0,0,0,0,0,0,0,0,0,0,0,0
0,0,0,0,0,0,0,0,0,0,0,0,0,0,0,0,0,0,0,0
0,0,0,0,0,0,0,0,0,0,0,0,0,0,0,0,0,0,0,0
0,0,0,0,0,0,0,0,0,0,0,0,0,0,0,0,0,0,0,0
0,0,0,0,0,0,0,0,0,0,0,0,0,0,0,0,0,0,0,0
0,0,0,0,0,0,0,0,0,0,0,0,0,0,0,0,0,0,0,0
0,0,0,0,0,0,0,0,0,0,0,0,0,0,0,0,0,0,0,0
0,0,0,0,0,0,0,0,0,0,0,0,0,0,0,0,0,0,0,0
0,0,0,0,0,0,0,0,0,0,0,0,0,0,0,0,0,0,0,0
0,0,0,0,0,0,0,0,0,0,0,0,0,0,0,0,0,0,0,0
:endlayer
layer: 48
0,0,0,0,0,0,0,0,0,0,0,0,0,0,0,0,0,0,0,0
0,0,0,0,0,0,0,0,0,0,0,0,0,0,0,0,0,0,0,0
0,0,0,0,0,0,0,0,0,0,0,0,0,0,0,0,0,0,0,0
0,0,0,0,0,0,0,0,0,0,0,0,0,0,0,0,0,0,0,0
0,0,0,0,0,0,0,0,0,0,0,0,0,0,0,0,0,0,0,0
0,0,0,0,0,0,0,0,0,0,0,0,0,0,0,0,0,0,0,0
0,0,0,0,0,0,0,0,0,0,0,0,0,0,0,0,0,0,0,0
0,0,0,0,0,0,0,0,0,0,0,0,0,0,0,0,0,0,0,0
0,0,0,0,0,0,0,0,0,0,0,0,0,0,0,0,0,0,0,0
0,0,0,0,0,0,0,0,0,0,0,0,0,0,0,0,0,0,0,0
0,0,0,0,0,0,0,0,0,0,0,0,0,0,0,0,0,0,0,0
0,0,0,0,0,0,0,0,0,0,0,0,0,0,0,0,0,0,0,0
0,0,0,0,0,0,0,0,0,0,0,0,0,0,0,0,0,0,0,0
0,0,0,0,0,0,0,0,0,0,0,0,0,0,0,0,0,0,0,0
0,0,0,0,0,0,0,0,0,0,0,0,0,0,0,0,0,0,0,0
0,0,0,0,0,0,0,0,0,0,0,0,0,0,0,0,0,0,0,0
0,0,0,0,0,0,0,0,0,0,0,0,0,0,0,0,0,0,0,0
0,0,0,0,0,0,0,0,0,0,0,0,0,0,0,0,0,0,0,0
0,0,0,0,0,0,0,0,0,0,0,0,0,0,0,0,0,0,0,0
0,0,0,0,0,0,0,0,0,0,0,0,0,0,0,0,0,0,0,0
0,0,0,0,0,0,0,0,0,0,0,0,0,0,0,0,0,0,0,0
0,0,0,0,0,0,0,0,0,0,0,0,0,0,0,0,0,0,0,0
0,0,0,0,0,0,0,0,0,0,0,0,0,0,0,0,0,0,0,0
0,0,0,0,0,0,0,0,0,0,0,0,0,0,0,0,0,0,0,0
0,0,0,0,0,0,0,0,0,0,0,0,0,0,0,0,0,0,0,0
0,0,0,0,0,0,0,0,0,0,0,0,0,0,0,0,0,0,0,0
:endlayer
layer: 49
0,0,0,0,0,0,0,0,0,0,0,0,0,0,0,0,0,0,0,0
0,0,0,0,0,0,0,0,0,0,0,0,0,0,0,0,0,0,0,0
0,0,0,0,0,0,0,0,0,0,0,0,0,0,0,0,0,0,0,0
0,0,0,0,0,0,0,0,0,0,0,0,0,0,0,0,0,0,0,0
0,0,0,0,0,0,0,0,0,0,0,0,0,0,0,0,0,0,0,0
0,0,0,0,0,0,0,0,0,0,0,0,0,0,0,0,0,0,0,0
0,0,0,0,0,0,0,0,0,0,0,0,0,0,0,0,0,0,0,0
0,0,0,0,0,0,0,0,0,0,0,0,0,0,0,0,0,0,0,0
0,0,0,0,0,0,0,0,0,0,0,0,0,0,0,0,0,0,0,0
0,0,0,0,0,0,0,0,0,0,0,0,0,0,0,0,0,0,0,0
0,0,0,0,0,0,0,0,0,0,0,0,0,0,0,0,0,0,0,0
0,0,0,0,0,0,0,0,0,0,0,0,0,0,0,0,0,0,0,0
0,0,0,0,0,0,0,0,0,0,0,0,0,0,0,0,0,0,0,0
0,0,0,0,0,0,0,0,0,0,0,0,0,0,0,0,0,0,0,0
0,0,0,0,0,0,0,0,0,0,0,0,0,0,0,0,0,0,0,0
0,0,0,0,0,0,0,0,0,0,0,0,0,0,0,0,0,0,0,0
0,0,0,0,0,0,0,0,0,0,0,0,0,0,0,0,0,0,0,0
0,0,0,0,0,0,0,0,0,0,0,0,0,0,0,0,0,0,0,0
0,0,0,0,0,0,0,0,0,0,0,0,0,0,0,0,0,0,0,0
0,0,0,0,0,0,0,0,0,0,0,0,0,0,0,0,0,0,0,0
0,0,0,0,0,0,0,0,0,0,0,0,0,0,0,0,0,0,0,0
0,0,0,0,0,0,0,0,0,0,0,0,0,0,0,0,0,0,0,0
0,0,0,0,0,0,0,0,0,0,0,0,0,0,0,0,0,0,0,0
0,0,0,0,0,0,0,0,0,0,0,0,0,0,0,0,0,0,0,0
0,0,0,0,0,0,0,0,0,0,0,0,0,0,0,0,0,0,0,0
0,0,0,0,0,0,0,0,0,0,0,0,0,0,0,0,0,0,0,0
:endlayer
layer: 50
0,0,0,0,0,0,0,0,0,0,0,0,0,0,0,0,0,0,0,0
0,0,0,0,0,0,0,0,0,0,0,0,0,0,0,0,0,0,0,0
0,0,0,0,0,0,0,0,0,0,0,0,0,0,0,0,0,0,0,0
0,0,0,0,0,0,0,0,0,0,0,0,0,0,0,0,0,0,0,0
0,0,0,0,0,0,0,0,0,0,0,0,0,0,0,0,0,0,0,0
0,0,0,0,0,0,0,0,0,0,0,0,0,0,0,0,0,0,0,0
0,0,0,0,0,0,0,0,0,0,0,0,0,0,0,0,0,0,0,0
0,0,0,0,0,0,0,0,0,0,0,0,0,0,0,0,0,0,0,0
0,0,0,0,0,0,0,0,0,0,0,0,0,0,0,0,0,0,0,0
0,0,0,0,0,0,0,0,0,0,0,0,0,0,0,0,0,0,0,0
0,0,0,0,0,0,0,0,0,0,0,0,0,0,0,0,0,0,0,0
0,0,0,0,0,0,0,0,0,0,0,0,0,0,0,0,0,0,0,0
0,0,0,0,0,0,0,0,0,0,0,0,0,0,0,0,0,0,0,0
0,0,0,0,0,0,0,0,0,0,0,0,0,0,0,0,0,0,0,0
0,0,0,0,0,0,0,0,0,0,0,0,0,0,0,0,0,0,0,0
0,0,0,0,0,0,0,0,0,0,0,0,0,0,0,0,0,0,0,0
0,0,0,0,0,0,0,0,0,0,0,0,0,0,0,0,0,0,0,0
0,0,0,0,0,0,0,0,0,0,0,0,0,0,0,0,0,0,0,0
0,0,0,0,0,0,0,0,0,0,0,0,0,0,0,0,0,0,0,0
0,0,0,0,0,0,0,0,0,0,0,0,0,0,0,0,0,0,0,0
0,0,0,0,0,0,0,0,0,0,0,0,0,0,0,0,0,0,0,0
0,0,0,0,0,0,0,0,0,0,0,0,0,0,0,0,0,0,0,0
0,0,0,0,0,0,0,0,0,0,0,0,0,0,0,0,0,0,0,0
0,0,0,0,0,0,0,0,0,0,0,0,0,0,0,0,0,0,0,0
0,0,0,0,0,0,0,0,0,0,0,0,0,0,0,0,0,0,0,0
0,0,0,0,0,0,0,0,0,0,0,0,0,0,0,0,0,0,0,0
:endlayer
layer: 51
0,0,0,0,0,0,0,0,0,0,0,0,0,0,0,0,0,0,0,0
0,0,0,0,0,0,0,0,0,0,0,0,0,0,0,0,0,0,0,0
0,0,0,0,0,0,0,0,0,0,0,0,0,0,0,0,0,0,0,0
0,0,0,0,0,0,0,0,0,0,0,0,0,0,0,0,0,0,0,0
0,0,0,0,0,0,0,0,0,0,0,0,0,0,0,0,0,0,0,0
0,0,0,0,0,0,0,0,0,0,0,0,0,0,0,0,0,0,0,0
0,0,0,0,0,0,0,0,0,0,0,0,0,0,0,0,0,0,0,0
0,0,0,0,0,0,0,0,0,0,0,0,0,0,0,0,0,0,0,0
0,0,0,0,0,0,0,0,0,0,0,0,0,0,0,0,0,0,0,0
0,0,0,0,0,0,0,0,0,0,0,0,0,0,0,0,0,0,0,0
0,0,0,0,0,0,0,0,0,0,0,0,0,0,0,0,0,0,0,0
0,0,0,0,0,0,0,0,0,0,0,0,0,0,0,0,0,0,0,0
0,0,0,0,0,0,0,0,0,0,0,0,0,0,0,0,0,0,0,0
0,0,0,0,0,0,0,0,0,0,0,0,0,0,0,0,0,0,0,0
0,0,0,0,0,0,0,0,0,0,0,0,0,0,0,0,0,0,0,0
0,0,0,0,0,0,0,0,0,0,0,0,0,0,0,0,0,0,0,0
0,0,0,0,0,0,0,0,0,0,0,0,0,0,0,0,0,0,0,0
0,0,0,0,0,0,0,0,0,0,0,0,0,0,0,0,0,0,0,0
0,0,0,0,0,0,0,0,0,0,0,0,0,0,0,0,0,0,0,0
0,0,0,0,0,0,0,0,0,0,0,0,0,0,0,0,0,0,0,0
0,0,0,0,0,0,0,0,0,0,0,0,0,0,0,0,0,0,0,0
0,0,0,0,0,0,0,0,0,0,0,0,0,0,0,0,0,0,0,0
0,0,0,0,0,0,0,0,0,0,0,0,0,0,0,0,0,0,0,0
0,0,0,0,0,0,0,0,0,0,0,0,0,0,0,0,0,0,0,0
0,0,0,0,0,0,0,0,0,0,0,0,0,0,0,0,0,0,0,0
0,0,0,0,0,0,0,0,0,0,0,0,0,0,0,0,0,0,0,0
:endlayer
layer: 52
0,0,0,0,0,0,0,0,0,0,0,0,0,0,0,0,0,0,0,0
0,0,0,0,0,0,0,0,0,0,0,0,0,0,0,0,0,0,0,0
0,0,0,0,0,0,0,0,0,0,0,0,0,0,0,0,0,0,0,0
0,0,0,0,0,0,0,0,0,0,0,0,0,0,0,0,0,0,0,0
0,0,0,0,0,0,0,0,0,0,0,0,0,0,0,0,0,0,0,0
0,0,0,0,0,0,0,0,0,0,0,0,0,0,0,0,0,0,0,0
0,0,0,0,0,0,0,0,0,0,0,0,0,0,0,0,0,0,0,0
0,0,0,0,0,0,0,0,0,0,0,0,0,0,0,0,0,0,0,0
0,0,0,0,0,0,0,0,0,0,0,0,0,0,0,0,0,0,0,0
0,0,0,0,0,0,0,0,0,0,0,0,0,0,0,0,0,0,0,0
0,0,0,0,0,0,0,0,0,0,0,0,0,0,0,0,0,0,0,0
0,0,0,0,0,0,0,0,0,0,0,0,0,0,0,0,0,0,0,0
0,0,0,0,0,0,0,0,0,0,0,0,0,0,0,0,0,0,0,0
0,0,0,0,0,0,0,0,0,0,0,0,0,0,0,0,0,0,0,0
0,0,0,0,0,0,0,0,0,0,0,0,0,0,0,0,0,0,0,0
0,0,0,0,0,0,0,0,0,0,0,0,0,0,0,0,0,0,0,0
0,0,0,0,0,0,0,0,0,0,0,0,0,0,0,0,0,0,0,0
0,0,0,0,0,0,0,0,0,0,0,0,0,0,0,0,0,0,0,0
0,0,0,0,0,0,0,0,0,0,0,0,0,0,0,0,0,0,0,0
0,0,0,0,0,0,0,0,0,0,0,0,0,0,0,0,0,0,0,0
0,0,0,0,0,0,0,0,0,0,0,0,0,0,0,0,0,0,0,0
0,0,0,0,0,0,0,0,0,0,0,0,0,0,0,0,0,0,0,0
0,0,0,0,0,0,0,0,0,0,0,0,0,0,0,0,0,0,0,0
0,0,0,0,0,0,0,0,0,0,0,0,0,0,0,0,0,0,0,0
0,0,0,0,0,0,0,0,0,0,0,0,0,0,0,0,0,0,0,0
0,0,0,0,0,0,0,0,0,0,0,0,0,0,0,0,0,0,0,0
:endlayer
layer: 53
0,0,0,0,0,0,0,0,0,0,0,0,0,0,0,0,0,0,0,0
0,0,0,0,0,0,0,0,0,0,0,0,0,0,0,0,0,0,0,0
0,0,0,0,0,0,0,0,0,0,0,0,0,0,0,0,0,0,0,0
0,0,0,0,0,0,0,0,0,0,0,0,0,0,0,0,0,0,0,0
0,0,0,0,0,0,0,0,0,0,0,0,0,0,0,0,0,0,0,0
0,0,0,0,0,0,0,0,0,0,0,0,0,0,0,0,0,0,0,0
0,0,0,0,0,0,0,0,0,0,0,0,0,0,0,0,0,0,0,0
0,0,0,0,0,0,0,0,0,0,0,0,0,0,0,0,0,0,0,0
0,0,0,0,0,0,0,0,0,0,0,0,0,0,0,0,0,0,0,0
0,0,0,0,0,0,0,0,0,0,0,0,0,0,0,0,0,0,0,0
0,0,0,0,0,0,0,0,0,0,0,0,0,0,0,0,0,0,0,0
0,0,0,0,0,0,0,0,0,0,0,0,0,0,0,0,0,0,0,0
0,0,0,0,0,0,0,0,0,0,0,0,0,0,0,0,0,0,0,0
0,0,0,0,0,0,0,0,0,0,0,0,0,0,0,0,0,0,0,0
0,0,0,0,0,0,0,0,0,0,0,0,0,0,0,0,0,0,0,0
0,0,0,0,0,0,0,0,0,0,0,0,0,0,0,0,0,0,0,0
0,0,0,0,0,0,0,0,0,0,0,0,0,0,0,0,0,0,0,0
0,0,0,0,0,0,0,0,0,0,0,0,0,0,0,0,0,0,0,0
0,0,0,0,0,0,0,0,0,0,0,0,0,0,0,0,0,0,0,0
0,0,0,0,0,0,0,0,0,0,0,0,0,0,0,0,0,0,0,0
0,0,0,0,0,0,0,0,0,0,0,0,0,0,0,0,0,0,0,0
0,0,0,0,0,0,0,0,0,0,0,0,0,0,0,0,0,0,0,0
0,0,0,0,0,0,0,0,0,0,0,0,0,0,0,0,0,0,0,0
0,0,0,0,0,0,0,0,0,0,0,0,0,0,0,0,0,0,0,0
0,0,0,0,0,0,0,0,0,0,0,0,0,0,0,0,0,0,0,0
0,0,0,0,0,0,0,0,0,0,0,0,0,0,0,0,0,0,0,0
:endlayer
layer: 54
0,0,0,0,0,0,0,0,0,0,0,0,0,0,0,0,0,0,0,0
0,0,0,0,0,0,0,0,0,0,0,0,0,0,0,0,0,0,0,0
0,0,0,0,0,0,0,0,0,0,0,0,0,0,0,0,0,0,0,0
0,0,0,0,0,0,0,0,0,0,0,0,0,0,0,0,0,0,0,0
0,0,0,0,0,0,0,0,0,0,0,0,0,0,0,0,0,0,0,0
0,0,0,0,0,0,0,0,0,0,0,0,0,0,0,0,0,0,0,0
0,0,0,0,0,0,0,0,0,0,0,0,0,0,0,0,0,0,0,0
0,0,0,0,0,0,0,0,0,0,0,0,0,0,0,0,0,0,0,0
0,0,0,0,0,0,0,0,0,0,0,0,0,0,0,0,0,0,0,0
0,0,0,0,0,0,0,0,0,0,0,0,0,0,0,0,0,0,0,0
0,0,0,0,0,0,0,0,0,0,0,0,0,0,0,0,0,0,0,0
0,0,0,0,0,0,0,0,0,0,0,0,0,0,0,0,0,0,0,0
0,0,0,0,0,0,0,0,0,0,0,0,0,0,0,0,0,0,0,0
0,0,0,0,0,0,0,0,0,0,0,0,0,0,0,0,0,0,0,0
0,0,0,0,0,0,0,0,0,0,0,0,0,0,0,0,0,0,0,0
0,0,0,0,0,0,0,0,0,0,0,0,0,0,0,0,0,0,0,0
0,0,0,0,0,0,0,0,0,0,0,0,0,0,0,0,0,0,0,0
0,0,0,0,0,0,0,0,0,0,0,0,0,0,0,0,0,0,0,0
0,0,0,0,0,0,0,0,0,0,0,0,0,0,0,0,0,0,0,0
0,0,0,0,0,0,0,0,0,0,0,0,0,0,0,0,0,0,0,0
0,0,0,0,0,0,0,0,0,0,0,0,0,0,0,0,0,0,0,0
0,0,0,0,0,0,0,0,0,0,0,0,0,0,0,0,0,0,0,0
0,0,0,0,0,0,0,0,0,0,0,0,0,0,0,0,0,0,0,0
0,0,0,0,0,0,0,0,0,0,0,0,0,0,0,0,0,0,0,0
0,0,0,0,0,0,0,0,0,0,0,0,0,0,0,0,0,0,0,0
0,0,0,0,0,0,0,0,0,0,0,0,0,0,0,0,0,0,0,0
:endlayer
layer: 55
0,0,0,0,0,0,0,0,0,0,0,0,0,0,0,0,0,0,0,0
0,0,0,0,0,0,0,0,0,0,0,0,0,0,0,0,0,0,0,0
0,0,0,0,0,0,0,0,0,0,0,0,0,0,0,0,0,0,0,0
0,0,0,0,0,0,0,0,0,0,0,0,0,0,0,0,0,0,0,0
0,0,0,0,0,0,0,0,0,0,0,0,0,0,0,0,0,0,0,0
0,0,0,0,0,0,0,0,0,0,0,0,0,0,0,0,0,0,0,0
0,0,0,0,0,0,0,0,0,0,0,0,0,0,0,0,0,0,0,0
0,0,0,0,0,0,0,0,0,0,0,0,0,0,0,0,0,0,0,0
0,0,0,0,0,0,0,0,0,0,0,0,0,0,0,0,0,0,0,0
0,0,0,0,0,0,0,0,0,0,0,0,0,0,0,0,0,0,0,0
0,0,0,0,0,0,0,0,0,0,0,0,0,0,0,0,0,0,0,0
0,0,0,0,0,0,0,0,0,0,0,0,0,0,0,0,0,0,0,0
0,0,0,0,0,0,0,0,0,0,0,0,0,0,0,0,0,0,0,0
0,0,0,0,0,0,0,0,0,0,0,0,0,0,0,0,0,0,0,0
0,0,0,0,0,0,0,0,0,0,0,0,0,0,0,0,0,0,0,0
0,0,0,0,0,0,0,0,0,0,0,0,0,0,0,0,0,0,0,0
0,0,0,0,0,0,0,0,0,0,0,0,0,0,0,0,0,0,0,0
0,0,0,0,0,0,0,0,0,0,0,0,0,0,0,0,0,0,0,0
0,0,0,0,0,0,0,0,0,0,0,0,0,0,0,0,0,0,0,0
0,0,0,0,0,0,0,0,0,0,0,0,0,0,0,0,0,0,0,0
0,0,0,0,0,0,0,0,0,0,0,0,0,0,0,0,0,0,0,0
0,0,0,0,0,0,0,0,0,0,0,0,0,0,0,0,0,0,0,0
0,0,0,0,0,0,0,0,0,0,0,0,0,0,0,0,0,0,0,0
0,0,0,0,0,0,0,0,0,0,0,0,0,0,0,0,0,0,0,0
0,0,0,0,0,0,0,0,0,0,0,0,0,0,0,0,0,0,0,0
0,0,0,0,0,0,0,0,0,0,0,0,0,0,0,0,0,0,0,0
:endlayer

#### RULES ####
rule:
plugin=vanillaBlocks
number=1
data:
JSON:{{"val":{"buildPass":{"val":"0","id":"pi"},"blockName":{"val":"minecraft:nether_brick_stairs","id":"ss"},"meta":{"val":"3","id":"pi"}},"id":"ct"}}
:enddata
:endrule

rule:
plugin=vanillaBlocks
number=2
data:
JSON:{{"val":{"buildPass":{"val":"0","id":"pi"},"blockName":{"val":"minecraft:nether_brick","id":"ss"},"meta":{"val":"0","id":"pi"}},"id":"ct"}}
:enddata
:endrule

rule:
plugin=vanillaBlocks
number=3
data:
JSON:{{"val":{"buildPass":{"val":"0","id":"pi"},"blockName":{"val":"minecraft:stone","id":"ss"},"meta":{"val":"0","id":"pi"}},"id":"ct"}}
:enddata
:endrule

rule:
plugin=vanillaBlocks
number=4
data:
JSON:{{"val":{"buildPass":{"val":"0","id":"pi"},"blockName":{"val":"minecraft:netherrack","id":"ss"},"meta":{"val":"0","id":"pi"}},"id":"ct"}}
:enddata
:endrule

rule:
plugin=vanillaBlocks
number=5
data:
JSON:{{"val":{"buildPass":{"val":"0","id":"pi"},"blockName":{"val":"minecraft:lava","id":"ss"},"meta":{"val":"0","id":"pi"}},"id":"ct"}}
:enddata
:endrule

rule:
plugin=vanillaBlocks
number=6
data:
JSON:{{"val":{"buildPass":{"val":"0","id":"pi"},"blockName":{"val":"minecraft:nether_brick_stairs","id":"ss"},"meta":{"val":"2","id":"pi"}},"id":"ct"}}
:enddata
:endrule

rule:
plugin=vanillaBlocks
number=7
data:
JSON:{{"val":{"buildPass":{"val":"0","id":"pi"},"blockName":{"val":"minecraft:nether_brick_stairs","id":"ss"},"meta":{"val":"1","id":"pi"}},"id":"ct"}}
:enddata
:endrule

rule:
plugin=vanillaBlocks
number=8
data:
JSON:{{"val":{"buildPass":{"val":"0","id":"pi"},"blockName":{"val":"minecraft:nether_brick_stairs","id":"ss"},"meta":{"val":"0","id":"pi"}},"id":"ct"}}
:enddata
:endrule

rule:
plugin=vanillaBlocks
number=9
data:
JSON:{{"val":{"buildPass":{"val":"0","id":"pi"},"blockName":{"val":"minecraft:lava","id":"ss"},"meta":{"val":"8","id":"pi"}},"id":"ct"}}
:enddata
:endrule

rule:
plugin=vanillaBlocks
number=10
data:
JSON:{{"val":{"buildPass":{"val":"0","id":"pi"},"blockName":{"val":"minecraft:stonebrick","id":"ss"},"meta":{"val":"0","id":"pi"}},"id":"ct"}}
:enddata
:endrule

rule:
plugin=vanillaBlocks
number=11
data:
JSON:{{"val":{"buildPass":{"val":"0","id":"pi"},"blockName":{"val":"minecraft:nether_brick_fence","id":"ss"},"meta":{"val":"0","id":"pi"}},"id":"ct"}}
:enddata
:endrule

rule:
plugin=vanillaBlocks
number=12
data:
JSON:{{"val":{"buildPass":{"val":"0","id":"pi"},"blockName":{"val":"minecraft:fire","id":"ss"},"meta":{"val":"15","id":"pi"}},"id":"ct"}}
:enddata
:endrule

rule:
plugin=vanillaBlocks
number=13
data:
JSON:{{"val":{"buildPass":{"val":"0","id":"pi"},"blockName":{"val":"minecraft:lava","id":"ss"},"meta":{"val":"6","id":"pi"}},"id":"ct"}}
:enddata
:endrule

rule:
plugin=vanillaBlocks
number=14
data:
JSON:{{"val":{"buildPass":{"val":"0","id":"pi"},"blockName":{"val":"minecraft:lava","id":"ss"},"meta":{"val":"4","id":"pi"}},"id":"ct"}}
:enddata
:endrule

rule:
plugin=vanillaBlocks
number=15
data:
JSON:{{"val":{"buildPass":{"val":"0","id":"pi"},"blockName":{"val":"minecraft:lava","id":"ss"},"meta":{"val":"2","id":"pi"}},"id":"ct"}}
:enddata
:endrule

rule:
plugin=vanillaBlocks
number=16
data:
JSON:{{"val":{"buildPass":{"val":"0","id":"pi"},"blockName":{"val":"minecraft:lava","id":"ss"},"meta":{"val":"10","id":"pi"}},"id":"ct"}}
:enddata
:endrule

rule:
plugin=vanillaBlocks
number=17
data:
JSON:{{"val":{"buildPass":{"val":"2","id":"pi"},"blockName":{"val":"minecraft:ladder","id":"ss"},"meta":{"val":"5","id":"pi"}},"id":"ct"}}
:enddata
:endrule

rule:
plugin=vanillaBlocks
number=18
data:
JSON:{{"val":{"buildPass":{"val":"2","id":"pi"},"blockName":{"val":"minecraft:ladder","id":"ss"},"meta":{"val":"4","id":"pi"}},"id":"ct"}}
:enddata
:endrule

rule:
plugin=vanillaBlocks
number=19
data:
JSON:{{"val":{"buildPass":{"val":"2","id":"pi"},"blockName":{"val":"minecraft:torch","id":"ss"},"meta":{"val":"2","id":"pi"}},"id":"ct"}}
:enddata
:endrule

rule:
plugin=vanillaBlocks
number=20
data:
JSON:{{"val":{"buildPass":{"val":"2","id":"pi"},"blockName":{"val":"minecraft:torch","id":"ss"},"meta":{"val":"1","id":"pi"}},"id":"ct"}}
:enddata
:endrule

rule:
plugin=vanillaBlocks
number=21
data:
JSON:{{"val":{"buildPass":{"val":"0","id":"pi"},"blockName":{"val":"minecraft:nether_brick_stairs","id":"ss"},"meta":{"val":"4","id":"pi"}},"id":"ct"}}
:enddata
:endrule

rule:
plugin=vanillaBlocks
number=22
data:
JSON:{{"val":{"buildPass":{"val":"0","id":"pi"},"blockName":{"val":"minecraft:nether_brick_stairs","id":"ss"},"meta":{"val":"5","id":"pi"}},"id":"ct"}}
:enddata
:endrule

rule:
plugin=vanillaBlocks
number=23
data:
JSON:{{"val":{"buildPass":{"val":"2","id":"pi"},"blockName":{"val":"minecraft:trapdoor","id":"ss"},"meta":{"val":"12","id":"pi"}},"id":"ct"}}
:enddata
:endrule

rule:
plugin=vanillaBlocks
number=24
data:
JSON:{{"val":{"buildPass":{"val":"2","id":"pi"},"blockName":{"val":"minecraft:trapdoor","id":"ss"},"meta":{"val":"13","id":"pi"}},"id":"ct"}}
:enddata
:endrule

rule:
plugin=vanillaBlocks
number=25
data:
JSON:{{"val":{"buildPass":{"val":"0","id":"pi"},"blockName":{"val":"minecraft:glowstone","id":"ss"},"meta":{"val":"0","id":"pi"}},"id":"ct"}}
:enddata
:endrule

rule:
plugin=vanillaBlocks
number=26
data:
JSON:{{"val":{"buildPass":{"val":"0","id":"pi"},"blockName":{"val":"minecraft:stone_slab","id":"ss"},"meta":{"val":"14","id":"pi"}},"id":"ct"}}
:enddata
:endrule

rule:
plugin=vanillaBlocks
number=27
data:
JSON:{{"val":{"buildPass":{"val":"0","id":"pi"},"blockName":{"val":"minecraft:nether_brick_stairs","id":"ss"},"meta":{"val":"7","id":"pi"}},"id":"ct"}}
:enddata
:endrule

rule:
plugin=vanillaBlocks
number=28
data:
JSON:{{"val":{"buildPass":{"val":"0","id":"pi"},"blockName":{"val":"minecraft:nether_brick_stairs","id":"ss"},"meta":{"val":"6","id":"pi"}},"id":"ct"}}
:enddata
:endrule

rule:
plugin=vanillaInventory
number=29
data:
JSON:{{"val":{"buildPass":{"val":"0","id":"pi"},"blockName":{"val":"minecraft:chest","id":"ss"},"meta":{"val":"2","id":"pi"},"lootLevel":{"val":"2","id":"pi"},"teData":{"val":{"x":{"val":"-1256","id":"pi"},"y":{"val":"16","id":"pi"},"z":{"val":"1048","id":"pi"},"id":{"val":"Chest","id":"ss"}},"id":"ct"},"inventoryData":{"val":{"length":{"val":"27","id":"pi"},"inventoryContents":{"val":[],"id":"ls"}},"id":"ct"}},"id":"ct"}}
:enddata
:endrule

rule:
plugin=vanillaLogic
number=30
data:
JSON:{{"val":{"buildPass":{"val":"0","id":"pi"},"blockName":{"val":"minecraft:mob_spawner","id":"ss"},"meta":{"val":"0","id":"pi"},"teData":{"val":{"EntityId":{"val":"LavaSlime","id":"ss"},"MaxNearbyEntities":{"val":"6","id":"ps"},"RequiredPlayerRange":{"val":"16","id":"ps"},"SpawnCount":{"val":"4","id":"ps"},"id":{"val":"MobSpawner","id":"ss"},"MaxSpawnDelay":{"val":"800","id":"ps"},"SpawnRange":{"val":"4","id":"ps"},"Delay":{"val":"0","id":"ps"},"MinSpawnDelay":{"val":"200","id":"ps"}},"id":"ct"}},"id":"ct"}}
:enddata
:endrule

rule:
plugin=vanillaLogic
number=31
data:
JSON:{{"val":{"buildPass":{"val":"0","id":"pi"},"blockName":{"val":"minecraft:mob_spawner","id":"ss"},"meta":{"val":"0","id":"pi"},"teData":{"val":{"EntityId":{"val":"LavaSlime","id":"ss"},"MaxNearbyEntities":{"val":"6","id":"ps"},"RequiredPlayerRange":{"val":"16","id":"ps"},"SpawnCount":{"val":"4","id":"ps"},"id":{"val":"MobSpawner","id":"ss"},"MaxSpawnDelay":{"val":"800","id":"ps"},"SpawnRange":{"val":"4","id":"ps"},"Delay":{"val":"0","id":"ps"},"MinSpawnDelay":{"val":"200","id":"ps"}},"id":"ct"}},"id":"ct"}}
:enddata
:endrule

rule:
plugin=vanillaBlocks
number=32
data:
JSON:{{"val":{"buildPass":{"val":"0","id":"pi"},"blockName":{"val":"minecraft:soul_sand","id":"ss"},"meta":{"val":"0","id":"pi"}},"id":"ct"}}
:enddata
:endrule

rule:
plugin=vanillaBlocks
number=33
data:
JSON:{{"val":{"buildPass":{"val":"0","id":"pi"},"blockName":{"val":"minecraft:stone_slab","id":"ss"},"meta":{"val":"6","id":"pi"}},"id":"ct"}}
:enddata
:endrule

rule:
plugin=vanillaBlocks
number=34
data:
JSON:{{"val":{"buildPass":{"val":"2","id":"pi"},"blockName":{"val":"minecraft:nether_wart","id":"ss"},"meta":{"val":"3","id":"pi"}},"id":"ct"}}
:enddata
:endrule

rule:
plugin=vanillaBlocks
number=35
data:
JSON:{{"val":{"buildPass":{"val":"0","id":"pi"},"blockName":{"val":"minecraft:iron_bars","id":"ss"},"meta":{"val":"0","id":"pi"}},"id":"ct"}}
:enddata
:endrule

rule:
plugin=vanillaInventory
number=36
data:
JSON:{{"val":{"buildPass":{"val":"0","id":"pi"},"blockName":{"val":"minecraft:chest","id":"ss"},"meta":{"val":"2","id":"pi"},"lootLevel":{"val":"2","id":"pi"},"teData":{"val":{"x":{"val":"-1253","id":"pi"},"y":{"val":"20","id":"pi"},"z":{"val":"1058","id":"pi"},"id":{"val":"Chest","id":"ss"}},"id":"ct"},"inventoryData":{"val":{"length":{"val":"27","id":"pi"},"inventoryContents":{"val":[],"id":"ls"}},"id":"ct"}},"id":"ct"}}
:enddata
:endrule

rule:
plugin=vanillaBlocks
number=37
data:
JSON:{{"val":{"buildPass":{"val":"2","id":"pi"},"blockName":{"val":"minecraft:nether_wart","id":"ss"},"meta":{"val":"1","id":"pi"}},"id":"ct"}}
:enddata
:endrule

rule:
plugin=vanillaLogic
number=38
data:
JSON:{{"val":{"buildPass":{"val":"0","id":"pi"},"blockName":{"val":"minecraft:mob_spawner","id":"ss"},"meta":{"val":"0","id":"pi"},"teData":{"val":{"EntityId":{"val":"Skeleton","id":"ss"},"MaxNearbyEntities":{"val":"6","id":"ps"},"RequiredPlayerRange":{"val":"16","id":"ps"},"SpawnCount":{"val":"4","id":"ps"},"id":{"val":"MobSpawner","id":"ss"},"MaxSpawnDelay":{"val":"800","id":"ps"},"SpawnRange":{"val":"4","id":"ps"},"Delay":{"val":"0","id":"ps"},"MinSpawnDelay":{"val":"200","id":"ps"}},"id":"ct"}},"id":"ct"}}
:enddata
:endrule

rule:
plugin=vanillaLogic
number=39
data:
JSON:{{"val":{"buildPass":{"val":"0","id":"pi"},"blockName":{"val":"minecraft:mob_spawner","id":"ss"},"meta":{"val":"0","id":"pi"},"teData":{"val":{"EntityId":{"val":"Skeleton","id":"ss"},"MaxNearbyEntities":{"val":"6","id":"ps"},"RequiredPlayerRange":{"val":"16","id":"ps"},"SpawnCount":{"val":"4","id":"ps"},"id":{"val":"MobSpawner","id":"ss"},"MaxSpawnDelay":{"val":"800","id":"ps"},"SpawnRange":{"val":"4","id":"ps"},"Delay":{"val":"0","id":"ps"},"MinSpawnDelay":{"val":"200","id":"ps"}},"id":"ct"}},"id":"ct"}}
:enddata
:endrule

rule:
plugin=vanillaBlocks
number=40
data:
JSON:{{"val":{"buildPass":{"val":"2","id":"pi"},"blockName":{"val":"minecraft:nether_wart","id":"ss"},"meta":{"val":"2","id":"pi"}},"id":"ct"}}
:enddata
:endrule

rule:
plugin=vanillaLogic
number=41
data:
JSON:{{"val":{"buildPass":{"val":"0","id":"pi"},"blockName":{"val":"minecraft:mob_spawner","id":"ss"},"meta":{"val":"0","id":"pi"},"teData":{"val":{"EntityId":{"val":"Blaze","id":"ss"},"MaxNearbyEntities":{"val":"6","id":"ps"},"RequiredPlayerRange":{"val":"16","id":"ps"},"SpawnCount":{"val":"4","id":"ps"},"id":{"val":"MobSpawner","id":"ss"},"MaxSpawnDelay":{"val":"800","id":"ps"},"SpawnRange":{"val":"4","id":"ps"},"Delay":{"val":"0","id":"ps"},"MinSpawnDelay":{"val":"200","id":"ps"}},"id":"ct"}},"id":"ct"}}
:enddata
:endrule

rule:
plugin=vanillaInventory
number=42
data:
JSON:{{"val":{"buildPass":{"val":"0","id":"pi"},"blockName":{"val":"minecraft:chest","id":"ss"},"meta":{"val":"2","id":"pi"},"lootLevel":{"val":"2","id":"pi"},"teData":{"val":{"x":{"val":"-1248","id":"pi"},"y":{"val":"30","id":"pi"},"z":{"val":"1059","id":"pi"},"id":{"val":"Chest","id":"ss"}},"id":"ct"},"inventoryData":{"val":{"length":{"val":"27","id":"pi"},"inventoryContents":{"val":[],"id":"ls"}},"id":"ct"}},"id":"ct"}}
:enddata
:endrule

rule:
plugin=vanillaBlocks
number=43
data:
JSON:{{"val":{"buildPass":{"val":"2","id":"pi"},"blockName":{"val":"minecraft:torch","id":"ss"},"meta":{"val":"4","id":"pi"}},"id":"ct"}}
:enddata
:endrule

rule:
plugin=vanillaLogic
number=44
data:
JSON:{{"val":{"buildPass":{"val":"0","id":"pi"},"blockName":{"val":"minecraft:mob_spawner","id":"ss"},"meta":{"val":"0","id":"pi"},"teData":{"val":{"EntityId":{"val":"Blaze","id":"ss"},"MaxNearbyEntities":{"val":"6","id":"ps"},"RequiredPlayerRange":{"val":"16","id":"ps"},"SpawnCount":{"val":"4","id":"ps"},"id":{"val":"MobSpawner","id":"ss"},"MaxSpawnDelay":{"val":"800","id":"ps"},"SpawnRange":{"val":"4","id":"ps"},"Delay":{"val":"0","id":"ps"},"MinSpawnDelay":{"val":"200","id":"ps"}},"id":"ct"}},"id":"ct"}}
:enddata
:endrule

rule:
plugin=vanillaLogic
number=45
data:
JSON:{{"val":{"buildPass":{"val":"0","id":"pi"},"blockName":{"val":"minecraft:mob_spawner","id":"ss"},"meta":{"val":"0","id":"pi"},"teData":{"val":{"EntityId":{"val":"Skeleton","id":"ss"},"MaxNearbyEntities":{"val":"6","id":"ps"},"RequiredPlayerRange":{"val":"16","id":"ps"},"SpawnCount":{"val":"4","id":"ps"},"id":{"val":"MobSpawner","id":"ss"},"MaxSpawnDelay":{"val":"800","id":"ps"},"SpawnRange":{"val":"4","id":"ps"},"Delay":{"val":"0","id":"ps"},"MinSpawnDelay":{"val":"200","id":"ps"}},"id":"ct"}},"id":"ct"}}
:enddata
:endrule

rule:
plugin=vanillaLogic
number=46
data:
JSON:{{"val":{"buildPass":{"val":"0","id":"pi"},"blockName":{"val":"minecraft:mob_spawner","id":"ss"},"meta":{"val":"0","id":"pi"},"teData":{"val":{"EntityId":{"val":"LavaSlime","id":"ss"},"MaxNearbyEntities":{"val":"6","id":"ps"},"RequiredPlayerRange":{"val":"16","id":"ps"},"SpawnCount":{"val":"4","id":"ps"},"id":{"val":"MobSpawner","id":"ss"},"MaxSpawnDelay":{"val":"800","id":"ps"},"SpawnRange":{"val":"4","id":"ps"},"Delay":{"val":"0","id":"ps"},"MinSpawnDelay":{"val":"200","id":"ps"}},"id":"ct"}},"id":"ct"}}
:enddata
:endrule

rule:
plugin=vanillaLogic
number=47
data:
JSON:{{"val":{"buildPass":{"val":"0","id":"pi"},"blockName":{"val":"minecraft:mob_spawner","id":"ss"},"meta":{"val":"0","id":"pi"},"teData":{"val":{"EntityId":{"val":"Blaze","id":"ss"},"MaxNearbyEntities":{"val":"6","id":"ps"},"RequiredPlayerRange":{"val":"16","id":"ps"},"SpawnCount":{"val":"4","id":"ps"},"id":{"val":"MobSpawner","id":"ss"},"MaxSpawnDelay":{"val":"800","id":"ps"},"SpawnRange":{"val":"4","id":"ps"},"Delay":{"val":"0","id":"ps"},"MinSpawnDelay":{"val":"200","id":"ps"}},"id":"ct"}},"id":"ct"}}
:enddata
:endrule

rule:
plugin=vanillaInventory
number=48
data:
JSON:{{"val":{"buildPass":{"val":"0","id":"pi"},"blockName":{"val":"minecraft:chest","id":"ss"},"meta":{"val":"2","id":"pi"},"lootLevel":{"val":"1","id":"pi"},"teData":{"val":{"x":{"val":"-1257","id":"pi"},"y":{"val":"38","id":"pi"},"z":{"val":"1048","id":"pi"},"id":{"val":"Chest","id":"ss"}},"id":"ct"},"inventoryData":{"val":{"length":{"val":"27","id":"pi"},"inventoryContents":{"val":[],"id":"ls"}},"id":"ct"}},"id":"ct"}}
:enddata
:endrule

rule:
plugin=vanillaLogic
number=49
data:
JSON:{{"val":{"buildPass":{"val":"0","id":"pi"},"blockName":{"val":"minecraft:mob_spawner","id":"ss"},"meta":{"val":"0","id":"pi"},"teData":{"val":{"EntityId":{"val":"LavaSlime","id":"ss"},"MaxNearbyEntities":{"val":"6","id":"ps"},"RequiredPlayerRange":{"val":"16","id":"ps"},"SpawnCount":{"val":"4","id":"ps"},"id":{"val":"MobSpawner","id":"ss"},"MaxSpawnDelay":{"val":"800","id":"ps"},"SpawnRange":{"val":"4","id":"ps"},"Delay":{"val":"0","id":"ps"},"MinSpawnDelay":{"val":"200","id":"ps"}},"id":"ct"}},"id":"ct"}}
:enddata
:endrule

rule:
plugin=vanillaBlocks
number=50
data:
JSON:{{"val":{"buildPass":{"val":"2","id":"pi"},"blockName":{"val":"minecraft:ladder","id":"ss"},"meta":{"val":"3","id":"pi"}},"id":"ct"}}
:enddata
:endrule

rule:
plugin=vanillaInventory
number=51
data:
JSON:{{"val":{"buildPass":{"val":"0","id":"pi"},"blockName":{"val":"minecraft:chest","id":"ss"},"meta":{"val":"2","id":"pi"},"lootLevel":{"val":"0","id":"pi"},"teData":{"val":{"x":{"val":"-1257","id":"pi"},"y":{"val":"38","id":"pi"},"z":{"val":"1062","id":"pi"},"id":{"val":"Chest","id":"ss"}},"id":"ct"},"inventoryData":{"val":{"length":{"val":"27","id":"pi"},"inventoryContents":{"val":[],"id":"ls"}},"id":"ct"}},"id":"ct"}}
:enddata
:endrule

rule:
plugin=vanillaLogic
number=52
data:
JSON:{{"val":{"buildPass":{"val":"0","id":"pi"},"blockName":{"val":"minecraft:mob_spawner","id":"ss"},"meta":{"val":"0","id":"pi"},"teData":{"val":{"EntityId":{"val":"Blaze","id":"ss"},"MaxNearbyEntities":{"val":"6","id":"ps"},"RequiredPlayerRange":{"val":"16","id":"ps"},"SpawnCount":{"val":"4","id":"ps"},"id":{"val":"MobSpawner","id":"ss"},"MaxSpawnDelay":{"val":"800","id":"ps"},"SpawnRange":{"val":"4","id":"ps"},"Delay":{"val":"0","id":"ps"},"MinSpawnDelay":{"val":"200","id":"ps"}},"id":"ct"}},"id":"ct"}}
:enddata
:endrule

rule:
plugin=vanillaLogic
number=53
data:
JSON:{{"val":{"buildPass":{"val":"0","id":"pi"},"blockName":{"val":"minecraft:mob_spawner","id":"ss"},"meta":{"val":"0","id":"pi"},"teData":{"val":{"EntityId":{"val":"Skeleton","id":"ss"},"MaxNearbyEntities":{"val":"6","id":"ps"},"RequiredPlayerRange":{"val":"16","id":"ps"},"SpawnCount":{"val":"4","id":"ps"},"id":{"val":"MobSpawner","id":"ss"},"MaxSpawnDelay":{"val":"800","id":"ps"},"SpawnRange":{"val":"4","id":"ps"},"Delay":{"val":"0","id":"ps"},"MinSpawnDelay":{"val":"200","id":"ps"}},"id":"ct"}},"id":"ct"}}
:enddata
:endrule

rule:
plugin=vanillaInventory
number=54
data:
JSON:{{"val":{"buildPass":{"val":"0","id":"pi"},"blockName":{"val":"minecraft:chest","id":"ss"},"meta":{"val":"2","id":"pi"},"lootLevel":{"val":"1","id":"pi"},"teData":{"val":{"x":{"val":"-1245","id":"pi"},"y":{"val":"41","id":"pi"},"z":{"val":"1049","id":"pi"},"id":{"val":"Chest","id":"ss"}},"id":"ct"},"inventoryData":{"val":{"length":{"val":"27","id":"pi"},"inventoryContents":{"val":[],"id":"ls"}},"id":"ct"}},"id":"ct"}}
:enddata
:endrule

rule:
plugin=vanillaInventory
number=55
data:
JSON:{{"val":{"buildPass":{"val":"0","id":"pi"},"blockName":{"val":"minecraft:chest","id":"ss"},"meta":{"val":"2","id":"pi"},"lootLevel":{"val":"3","id":"pi"},"teData":{"val":{"x":{"val":"-1247","id":"pi"},"y":{"val":"41","id":"pi"},"z":{"val":"1061","id":"pi"},"id":{"val":"Chest","id":"ss"}},"id":"ct"},"inventoryData":{"val":{"length":{"val":"27","id":"pi"},"inventoryContents":{"val":[],"id":"ls"}},"id":"ct"}},"id":"ct"}}
:enddata
:endrule

rule:
plugin=vanillaBlocks
number=56
data:
JSON:{{"val":{"buildPass":{"val":"0","id":"pi"},"blockName":{"val":"minecraft:planks","id":"ss"},"meta":{"val":"0","id":"pi"}},"id":"ct"}}
:enddata
:endrule

#### ENTITIES ####
