# Ancient Warfare Structure Template File
# Auto-generated structure template file. created on: 3/14/2015 at: 23:1:13
# Lines beginning with # denote comments

header:
version=2.1
name=ImperialMillNewFangled
size=19,62,19
offset=6,4,17
:endheader

#### VALIDATION ####
validation:
type=ground
survival=false
worldGenEnabled=true
unique=false
preserveBlocks=false
selectionWeight=30
clusterValue=20
minDuplicateDistance=60
dimensionWhiteList=false
dimensionList=
biomeWhiteList=true
biomeList=highlands_lowlands,origin valley,highlands_valley,orchard,meadow,lavender fields,flower field,meadow forest,highlands_meadow,green hills
leveling=8
fill=4
border=4
validTargetBlocks=minecraft:dirt,minecraft:sand,minecraft:stone,minecraft:diamond_ore,minecraft:gravel,minecraft:lapis_ore,minecraft:redstone_ore,minecraft:stained_hardened_clay,minecraft:gold_ore,minecraft:clay,minecraft:coal_ore,minecraft:iron_ore,minecraft:grass
blockSwap=false
data:
:enddata
:endvalidation

#### LAYERS ####
layer: 0
1,1,1,1,1,1,1,1,1,1,1,1,1,1,1,1,1,1,1
1,1,1,1,1,1,1,1,1,1,1,1,1,1,1,1,1,1,1
1,1,1,1,1,1,1,1,1,1,1,1,1,1,1,1,1,1,1
1,1,1,1,1,1,1,1,1,1,1,1,1,1,1,1,1,1,1
1,1,1,1,1,1,1,1,1,1,1,1,1,1,1,1,1,1,1
1,1,1,1,1,1,1,1,1,1,1,1,1,1,1,1,1,1,1
1,1,1,1,1,1,1,1,1,1,1,1,1,1,1,1,1,1,1
1,1,1,1,1,1,1,1,1,1,1,1,1,1,1,1,1,1,1
1,1,1,1,1,1,1,1,1,1,1,1,1,1,1,1,1,1,1
1,1,1,1,1,1,1,1,1,1,1,1,1,1,1,1,1,1,1
1,1,1,1,1,1,1,1,1,1,1,1,1,1,1,1,1,1,1
1,1,1,1,1,1,1,1,1,1,1,1,1,1,1,1,1,1,1
1,1,1,1,1,1,1,1,1,1,1,1,1,1,1,1,1,1,1
1,1,1,1,1,1,1,1,1,1,1,1,1,1,1,1,1,1,1
1,1,1,1,1,1,1,1,1,1,1,1,1,1,1,1,1,1,1
1,1,1,1,1,1,1,1,1,1,1,1,1,1,1,1,1,1,1
1,1,1,1,1,1,1,1,1,1,1,1,1,1,1,1,1,1,1
1,1,1,1,1,1,1,1,1,1,1,1,1,1,1,1,1,1,1
1,1,1,1,1,1,1,1,1,1,1,1,1,1,1,1,1,1,1
:endlayer
layer: 1
1,1,1,1,1,1,1,1,1,1,1,1,1,1,1,1,1,1,1
1,1,1,1,1,1,1,1,1,1,1,1,1,1,1,1,1,1,1
1,1,1,1,1,1,1,1,1,1,1,1,1,1,1,1,1,1,1
1,1,1,1,1,1,1,1,1,1,1,1,1,1,1,1,1,1,1
1,1,1,1,1,1,1,1,1,1,1,1,1,1,1,1,1,1,1
1,1,1,1,1,1,1,1,1,1,1,1,1,1,1,1,1,1,1
1,1,1,1,1,1,1,1,1,1,1,1,1,1,1,1,1,1,1
1,1,1,1,1,1,1,1,1,1,1,1,1,1,1,1,1,1,1
1,1,1,1,1,1,1,1,1,1,1,1,1,1,1,1,1,1,1
1,1,1,1,1,1,1,1,1,1,1,1,1,1,1,1,1,1,1
1,1,1,1,1,1,1,1,1,1,1,1,1,1,1,1,1,1,1
1,1,1,1,1,1,1,1,1,1,1,1,1,1,1,1,1,1,1
1,1,1,1,1,1,1,1,1,1,1,1,1,1,1,1,1,1,1
1,1,1,1,1,1,1,1,1,1,1,1,1,1,1,1,1,1,1
1,1,1,1,1,1,1,1,1,1,1,1,1,1,1,1,1,1,1
1,1,1,1,1,1,1,1,1,1,1,1,1,1,1,1,1,1,1
1,1,1,1,1,1,1,1,1,1,1,1,1,1,1,1,1,1,1
1,1,1,1,1,1,1,1,1,1,1,1,1,1,1,1,1,1,1
1,1,1,1,1,1,1,1,1,1,1,1,1,1,1,1,1,1,1
:endlayer
layer: 2
1,1,1,1,1,1,1,1,1,1,1,1,1,1,1,1,1,1,1
1,1,1,1,1,1,1,1,1,1,1,1,1,1,1,1,1,1,1
1,1,2,2,2,2,2,2,2,2,2,2,2,2,2,2,2,1,1
1,1,2,2,2,2,2,2,2,2,2,2,2,2,2,2,2,1,1
1,1,2,2,2,2,2,2,2,2,2,2,2,2,2,2,2,1,1
1,1,2,2,2,2,2,2,2,2,2,2,2,2,2,2,2,1,1
1,1,2,2,2,2,2,2,2,2,2,2,2,2,2,2,2,1,1
1,1,2,2,2,2,2,2,2,2,2,2,2,2,2,2,2,1,1
1,1,2,2,2,2,2,2,2,2,2,2,2,2,2,2,2,1,1
1,1,2,2,2,2,2,2,2,2,2,2,2,2,2,2,2,1,1
1,1,2,2,2,2,2,2,2,2,2,2,2,2,2,2,2,1,1
1,1,2,2,2,2,2,2,2,2,2,2,2,2,2,2,2,1,1
1,1,2,2,2,2,2,2,2,2,2,2,2,2,2,2,2,1,1
1,1,2,2,2,2,2,2,2,2,2,2,2,2,2,2,2,1,1
1,1,2,2,2,2,2,2,2,2,2,2,2,2,2,2,2,1,1
1,1,2,2,2,2,2,2,2,2,2,2,2,2,2,2,2,1,1
1,1,2,2,2,2,2,2,2,2,2,2,2,2,2,2,2,1,1
1,1,1,1,1,1,1,1,1,1,1,1,1,1,1,1,1,1,1
1,1,1,1,1,1,1,1,1,1,1,1,1,1,1,1,1,1,1
:endlayer
layer: 3
3,3,3,3,3,3,3,3,3,3,3,3,3,3,3,3,3,3,3
3,3,3,3,3,3,3,3,3,2,3,3,3,3,3,3,3,3,3
3,3,3,3,3,3,3,3,3,2,3,3,3,3,3,3,3,3,3
3,3,3,2,2,2,2,2,2,2,2,2,2,2,2,2,3,3,3
3,3,3,2,2,2,2,2,2,2,2,2,2,2,2,2,3,3,3
3,3,3,2,2,2,2,2,2,2,2,2,2,2,2,4,3,3,3
3,3,3,2,2,2,2,2,2,2,2,2,2,2,2,4,3,3,3
3,3,3,2,2,2,2,2,2,2,2,2,2,2,2,4,3,3,3
3,3,3,2,2,2,2,2,2,2,2,2,2,2,2,2,3,3,3
3,3,3,2,2,2,2,2,2,2,2,2,2,2,2,2,3,3,3
3,3,3,2,2,2,2,2,2,2,2,2,2,2,2,2,3,3,3
3,3,3,4,2,2,2,2,2,2,2,2,2,2,2,2,3,3,3
3,3,3,4,2,2,2,2,2,2,2,2,2,2,2,2,3,3,3
3,3,3,4,2,2,2,2,2,2,2,2,2,2,2,2,3,3,3
3,3,3,2,2,2,2,2,2,2,2,2,2,2,2,2,3,3,3
3,3,3,2,2,2,2,2,2,2,4,4,4,2,2,2,3,3,3
3,3,3,3,3,2,3,3,3,3,3,3,3,3,3,3,3,3,3
3,3,3,3,3,2,3,3,3,3,3,3,3,3,3,3,3,3,3
3,3,3,3,3,3,3,3,3,3,3,3,3,3,3,3,3,3,3
:endlayer
layer: 4
0,0,0,0,5,5,5,0,0,0,0,0,0,0,0,5,0,0,5
0,6,6,6,6,6,6,6,6,7,6,6,6,6,6,6,6,6,5
0,6,0,0,0,5,5,0,0,0,0,0,0,0,0,0,0,6,5
0,6,0,8,8,8,8,8,8,9,8,8,8,10,8,8,5,6,5
0,6,0,8,8,8,8,8,0,0,0,0,0,0,0,8,0,6,0
0,6,5,8,8,8,8,11,0,0,0,0,0,0,0,6,0,6,0
0,6,5,12,0,0,0,0,0,0,0,0,0,0,0,6,0,6,0
5,6,5,8,13,0,0,0,0,0,0,0,0,0,0,6,0,6,0
0,6,0,8,14,0,0,0,6,15,16,6,0,0,0,8,0,6,0
0,6,0,8,8,0,0,0,8,8,8,8,0,0,8,8,5,6,5
0,6,0,8,0,0,0,0,0,0,17,18,0,0,6,8,0,6,5
0,6,0,6,0,0,19,19,19,0,0,0,0,0,20,8,0,6,5
0,6,0,6,0,0,19,21,19,0,0,0,0,0,22,8,5,6,5
0,6,0,6,0,0,19,19,19,0,0,0,0,0,6,8,0,6,0
5,6,5,8,0,0,0,0,0,0,0,0,0,0,23,8,0,6,0
5,6,5,8,8,9,8,8,8,8,6,6,6,8,8,8,5,6,5
5,6,5,0,0,0,0,0,5,0,5,0,0,5,0,0,0,6,5
0,6,6,6,6,24,6,6,6,6,6,6,6,6,6,6,6,6,0
0,0,0,0,0,0,0,0,5,0,5,5,5,0,0,0,0,0,5
:endlayer
layer: 5
0,0,0,0,0,0,0,0,0,0,0,0,0,0,0,0,0,0,0
0,25,0,0,0,0,0,0,0,0,0,0,0,0,0,0,0,25,0
0,0,0,0,0,0,0,0,0,0,26,0,0,0,0,0,0,0,0
0,0,0,2,2,2,2,2,2,27,2,2,2,6,2,2,0,0,0
0,0,0,2,2,2,2,2,0,0,0,0,0,0,0,4,0,0,0
0,0,0,2,2,2,11,0,0,0,0,0,0,0,0,6,0,0,0
0,0,0,6,0,28,0,0,0,0,0,0,0,0,0,6,0,0,0
0,0,0,2,6,0,0,0,0,0,0,0,0,0,0,6,0,0,0
0,0,0,2,6,0,0,0,6,6,6,6,0,0,29,4,0,0,0
0,0,0,2,4,0,0,0,4,2,2,2,0,0,2,2,0,0,0
0,0,0,4,0,0,0,0,0,0,6,6,0,0,6,2,0,0,0
0,0,0,6,0,0,0,0,0,0,0,0,0,0,6,2,0,0,0
0,0,0,6,0,0,0,2,0,0,0,0,0,0,6,2,0,0,0
0,0,0,6,0,0,0,0,0,0,0,0,0,0,6,2,0,0,0
0,0,0,4,0,0,0,0,0,0,0,0,0,0,0,2,0,0,0
0,0,0,2,2,30,2,2,2,4,6,6,6,4,2,2,0,0,0
0,0,0,0,31,0,0,0,0,0,0,0,0,0,0,0,0,0,0
0,25,0,0,0,0,0,0,0,0,0,0,0,0,0,0,0,25,0
0,0,0,0,0,0,0,0,0,0,0,0,0,0,0,0,0,0,0
:endlayer
layer: 6
0,0,0,0,0,0,0,0,0,0,0,0,0,0,0,0,0,0,0
0,0,0,0,0,0,0,0,0,0,0,0,0,0,0,0,0,0,0
0,0,0,0,0,0,29,0,0,0,0,29,0,0,0,0,0,0,0
0,0,0,8,8,8,8,8,8,6,8,8,8,6,8,8,0,0,0
0,0,0,8,8,8,8,8,0,0,0,0,0,0,0,8,0,0,0
0,0,0,8,8,11,0,0,0,0,0,0,0,0,0,6,0,0,0
0,0,0,6,0,0,0,0,0,0,0,0,0,0,0,6,0,0,0
0,0,0,8,32,0,0,0,0,0,0,0,0,0,0,6,0,0,0
0,0,33,8,34,0,0,0,6,35,36,6,0,0,0,8,0,0,0
0,0,0,8,8,0,0,0,8,8,8,8,6,6,8,8,0,0,0
0,0,0,8,0,0,0,0,0,0,37,38,0,0,6,8,0,0,0
0,0,0,6,0,0,0,39,0,0,0,0,0,0,40,8,0,0,0
0,0,0,6,0,0,39,2,39,0,0,0,0,0,41,8,42,0,0
0,0,0,6,0,0,0,39,0,0,0,0,0,0,6,8,0,0,0
0,0,0,8,0,0,0,0,0,0,0,0,0,0,33,8,0,0,0
0,0,0,8,8,6,8,8,8,8,6,6,6,8,8,8,0,0,0
0,0,0,0,0,0,0,28,0,0,0,0,0,0,0,0,0,0,0
0,0,0,0,0,0,0,0,0,0,0,0,0,0,0,0,0,0,0
0,0,0,0,0,0,0,0,0,0,0,0,0,0,0,0,0,0,0
:endlayer
layer: 7
0,0,0,0,0,0,0,0,0,0,0,0,0,0,0,0,0,0,0
0,0,0,0,0,0,0,0,0,0,0,0,0,0,0,0,0,0,0
0,0,43,0,0,0,44,0,0,0,0,0,44,0,0,0,43,0,0
0,0,0,2,2,2,2,2,2,8,2,2,2,8,2,2,0,0,0
0,0,0,2,0,45,2,2,28,0,28,0,0,0,0,2,0,0,0
0,0,0,2,0,0,0,0,0,0,0,0,0,0,0,8,0,0,0
0,0,0,8,0,0,0,0,0,0,0,0,0,0,0,8,46,0,0
0,0,0,2,6,0,0,0,0,0,0,0,0,0,0,8,0,0,0
0,0,47,2,6,0,0,0,6,6,6,6,0,0,0,2,0,0,0
0,0,0,2,2,8,8,8,2,2,2,2,8,8,2,2,0,0,0
0,0,0,2,28,0,0,0,28,0,6,6,0,0,6,2,46,0,0
0,0,0,8,0,0,0,48,0,0,0,0,0,0,6,2,0,0,0
0,0,0,8,0,0,49,2,50,0,0,0,0,0,6,2,0,0,0
0,0,0,8,0,0,0,51,0,0,0,0,0,0,6,2,0,0,0
0,0,0,2,29,0,29,0,0,0,0,0,0,29,0,2,0,0,0
0,0,0,2,2,8,2,2,2,2,8,8,8,2,2,2,0,0,0
0,0,0,0,0,0,0,0,0,0,0,0,0,0,0,0,0,0,0
0,0,0,0,0,0,0,0,0,0,0,0,0,0,0,0,0,0,0
0,0,0,0,0,0,0,0,0,0,0,0,0,0,0,0,0,0,0
:endlayer
layer: 8
0,0,0,0,0,0,0,0,0,0,0,0,0,0,0,0,0,0,0
0,0,0,0,0,0,0,0,0,0,0,0,0,0,0,0,0,0,0
0,0,52,0,0,0,52,0,0,0,0,0,52,0,0,0,52,0,0
0,0,0,2,2,2,2,2,2,2,2,2,2,2,2,2,0,0,0
0,0,0,2,0,0,45,2,53,53,53,53,53,53,53,2,0,0,0
0,0,0,2,0,0,0,2,53,53,53,53,53,53,53,2,0,0,0
0,0,0,2,2,2,2,2,53,53,53,53,53,53,53,2,52,0,0
0,0,0,2,53,53,53,53,53,53,53,53,53,53,53,2,0,0,0
0,0,52,2,2,2,2,2,2,53,53,53,53,53,53,2,0,0,0
0,0,0,52,54,54,54,54,54,54,53,53,53,53,53,2,0,0,0
0,0,0,52,54,0,55,55,55,0,52,2,2,2,2,2,52,0,0
0,0,0,52,54,54,8,8,8,54,54,54,54,54,56,52,0,0,0
0,0,0,52,54,54,8,21,8,54,54,54,54,54,54,52,0,0,0
0,0,0,52,54,54,8,8,8,54,54,54,54,54,54,52,0,0,0
0,0,0,52,54,54,54,54,54,54,54,54,54,54,54,52,0,0,0
0,0,0,52,52,52,52,52,52,52,52,52,52,52,52,52,0,0,0
0,0,0,0,0,0,0,0,0,0,0,0,0,0,0,0,0,0,0
0,0,0,0,0,0,0,0,0,0,0,0,0,0,0,0,0,0,0
0,0,0,0,0,0,0,0,0,0,0,0,0,0,0,0,0,0,0
:endlayer
layer: 9
0,0,0,0,0,0,0,0,0,0,0,0,0,0,0,0,0,0,0
0,0,0,0,0,0,0,0,0,0,0,0,0,0,0,0,0,0,0
0,0,52,8,8,8,52,8,8,8,8,8,52,8,8,8,52,0,0
0,0,8,0,0,0,0,0,0,0,0,0,0,0,57,58,8,0,0
0,0,8,0,0,0,0,0,0,0,0,0,0,0,57,58,8,0,0
0,0,8,0,0,0,0,6,0,0,0,0,52,0,0,0,8,0,0
0,0,8,0,0,0,0,0,0,0,39,39,39,0,0,23,52,0,0
0,0,8,59,60,0,0,55,55,55,39,2,39,0,0,61,8,0,0
0,0,52,8,8,8,0,0,0,8,8,39,39,0,0,62,8,0,0
0,0,0,6,0,0,0,0,0,0,8,0,0,0,0,63,8,0,0
0,0,0,6,0,55,0,55,0,55,52,8,2,8,9,8,52,0,0
0,0,0,6,0,0,8,8,8,0,0,0,0,0,0,6,0,0,0
0,0,0,6,0,0,8,52,8,0,0,0,0,0,0,6,0,0,0
0,0,0,6,0,0,8,8,8,0,0,0,0,0,0,6,0,0,0
0,0,0,6,0,0,0,0,0,0,0,0,0,0,0,6,0,0,0
0,0,0,6,6,6,6,6,6,6,6,6,6,6,6,6,0,0,0
0,0,0,0,0,0,0,0,0,0,0,0,0,0,0,0,0,0,0
0,0,0,0,0,0,0,0,0,0,0,0,0,0,0,0,0,0,0
0,0,0,0,0,0,0,0,0,0,0,0,0,0,0,0,0,0,0
:endlayer
layer: 10
0,0,0,0,0,0,0,0,0,0,0,0,0,0,0,0,0,0,0
0,0,0,0,0,0,0,0,0,0,0,0,0,0,0,0,0,0,0
0,0,52,2,64,2,52,2,64,2,64,2,52,2,64,2,52,0,0
0,0,2,0,0,0,0,0,0,0,0,0,0,0,0,0,2,0,0
0,0,64,0,0,0,0,0,0,0,0,0,0,0,0,0,64,0,0
0,0,2,0,0,0,0,6,0,0,0,0,52,0,0,0,2,0,0
0,0,64,0,0,0,0,6,0,0,0,19,0,0,0,0,52,0,0
0,0,2,0,0,0,0,6,0,0,19,0,19,0,0,0,2,0,0
0,0,52,2,2,2,0,6,0,2,52,19,0,0,0,0,64,0,0
0,0,0,0,0,0,0,21,0,0,2,0,0,29,0,0,2,0,0
0,0,0,0,0,55,55,21,55,55,52,2,64,2,65,2,52,0,0
0,0,0,0,0,0,8,8,8,0,0,0,0,28,0,0,0,0,0
0,0,0,0,0,33,8,52,8,42,0,0,0,0,0,0,0,0,0
0,0,0,0,0,0,8,8,8,0,0,0,0,0,0,0,0,0,0
0,0,0,0,0,0,0,28,0,0,0,0,0,0,0,0,0,0,0
0,0,0,25,0,0,0,0,0,0,0,0,0,0,0,25,0,0,0
0,0,0,0,0,0,0,0,0,0,0,0,0,0,0,0,0,0,0
0,0,0,0,0,0,0,0,0,0,0,0,0,0,0,0,0,0,0
0,0,0,0,0,0,0,0,0,0,0,0,0,0,0,0,0,0,0
:endlayer
layer: 11
0,0,0,0,0,0,0,0,0,0,0,0,0,0,0,0,0,0,0
0,0,0,0,0,0,0,0,0,0,0,0,0,0,0,0,0,0,0
0,0,52,8,64,8,52,8,64,8,64,8,52,8,64,8,52,0,0
0,0,8,0,0,0,28,0,0,0,0,0,28,0,0,0,8,0,0
0,0,64,0,0,0,0,0,0,0,0,0,0,0,0,0,64,0,0
0,0,8,0,0,0,0,0,0,0,0,33,52,42,0,0,8,0,0
0,0,64,0,0,0,0,0,0,0,0,0,0,0,0,33,52,0,0
0,0,8,0,0,0,0,0,0,0,29,0,0,0,0,0,8,0,0
0,0,52,8,8,8,0,0,0,8,52,42,0,0,0,0,64,0,0
0,0,0,0,28,0,0,0,0,0,8,0,0,0,0,0,8,0,0
0,0,0,0,0,55,0,55,0,55,52,8,64,8,6,8,52,0,0
0,0,0,0,0,0,0,66,0,0,0,0,0,0,0,0,0,0,0
0,0,0,0,0,0,66,52,66,0,0,0,0,0,0,0,0,0,0
0,0,0,0,0,0,0,66,0,0,0,0,0,0,0,0,0,0,0
0,0,0,0,0,0,0,0,0,0,0,0,0,0,0,0,0,0,0
0,0,0,0,0,0,0,0,0,0,0,0,0,0,0,0,0,0,0
0,0,0,0,0,0,0,0,0,0,0,0,0,0,0,0,0,0,0
0,0,0,0,0,0,0,0,0,0,0,0,0,0,0,0,0,0,0
0,0,0,0,0,0,0,0,0,0,0,0,0,0,0,0,0,0,0
:endlayer
layer: 12
0,0,0,0,0,0,0,0,0,0,0,0,0,0,0,0,0,0,0
0,0,0,0,0,0,0,0,0,0,0,0,0,0,0,0,0,0,0
0,0,52,2,8,2,52,2,8,2,8,2,52,2,8,2,52,0,0
0,0,2,0,0,0,0,0,28,0,28,0,0,0,0,0,2,0,0
0,0,8,0,0,0,0,0,0,0,0,0,0,0,0,0,8,0,0
0,0,2,42,0,0,0,0,0,0,0,0,52,0,0,33,2,0,0
0,0,8,0,0,0,0,0,0,0,0,0,0,0,0,0,52,0,0
0,0,2,0,0,29,0,0,0,29,0,0,0,0,0,33,2,0,0
0,0,52,2,2,2,8,8,8,2,52,0,0,0,0,0,8,0,0
0,0,0,0,0,0,0,0,0,0,2,0,0,0,0,0,2,0,0
0,0,0,0,0,0,55,55,55,0,52,2,8,2,8,2,52,0,0
0,0,0,0,0,0,0,54,0,0,0,0,0,0,0,0,0,0,0
0,0,0,0,0,0,54,52,54,0,0,0,0,0,0,0,0,0,0
0,0,0,0,0,0,0,54,0,0,0,0,0,0,0,0,0,0,0
0,0,0,0,0,0,0,0,0,0,0,0,0,0,0,0,0,0,0
0,0,0,0,0,0,0,0,0,0,0,0,0,0,0,0,0,0,0
0,0,0,0,0,0,0,0,0,0,0,0,0,0,0,0,0,0,0
0,0,0,0,0,0,0,0,0,0,0,0,0,0,0,0,0,0,0
0,0,0,0,0,0,0,0,0,0,0,0,0,0,0,0,0,0,0
:endlayer
layer: 13
0,0,0,0,0,0,0,0,0,0,0,0,0,0,0,0,0,0,0
0,54,54,54,54,54,54,54,54,54,54,54,54,54,54,54,54,54,0
0,54,53,55,55,55,55,55,55,55,55,55,55,55,55,55,55,54,0
0,54,55,52,0,0,52,0,0,0,0,0,52,0,0,52,55,54,0
0,54,55,0,52,0,52,0,0,0,0,0,52,0,52,0,55,54,0
0,54,55,0,0,52,52,52,52,52,52,52,52,52,0,0,55,54,0
0,54,55,0,52,0,52,0,0,0,0,0,52,52,52,52,55,54,0
0,54,55,52,0,0,52,0,0,0,0,52,0,52,0,0,55,54,0
0,54,55,55,55,51,51,51,51,51,53,0,0,0,52,0,55,54,0
0,54,54,54,54,0,0,0,0,0,49,0,0,0,0,52,55,54,0
0,0,0,0,0,0,0,0,0,0,49,55,55,55,55,55,55,54,0
0,0,0,0,0,0,0,0,0,0,54,54,54,54,54,54,54,54,0
0,0,0,0,0,0,0,52,0,0,0,0,0,0,0,0,0,0,0
0,0,0,0,0,0,0,0,0,0,0,0,0,0,0,0,0,0,0
0,0,0,0,0,0,0,0,0,0,0,0,0,0,0,0,0,0,0
0,0,0,0,0,0,0,0,0,0,0,0,0,0,0,0,0,0,0
0,0,0,0,0,0,0,0,0,0,0,0,0,0,0,0,0,0,0
0,0,0,0,0,0,0,0,0,0,0,0,0,0,0,0,0,0,0
0,0,0,0,0,0,0,0,0,0,0,0,0,0,0,0,0,0,0
:endlayer
layer: 14
0,0,0,0,0,0,0,0,0,0,0,0,0,0,0,0,0,0,0
0,0,0,0,0,0,0,0,0,0,0,0,0,0,0,0,0,0,0
0,0,0,0,0,0,0,0,0,0,0,0,0,0,0,0,0,0,0
0,0,0,54,54,54,54,54,54,54,54,54,54,54,54,54,0,0,0
0,0,0,54,55,55,55,55,55,55,55,55,55,55,55,54,0,0,0
0,0,0,54,55,52,52,55,55,55,55,55,52,52,55,54,0,0,0
0,0,0,54,55,55,55,55,55,55,55,55,55,52,55,54,0,0,0
0,0,0,54,54,54,54,54,54,54,54,54,55,52,55,54,0,0,0
0,0,0,0,0,0,0,0,0,0,0,54,55,55,55,54,0,0,0
0,0,0,0,0,0,0,0,0,0,0,54,54,54,54,54,0,0,0
0,0,0,0,0,0,0,0,0,0,0,0,0,0,0,0,0,0,0
0,0,0,0,0,0,0,0,0,0,0,0,0,0,0,0,0,0,0
0,0,0,0,0,0,0,21,0,0,0,0,0,0,0,0,0,0,0
0,0,0,0,0,0,0,0,0,0,0,0,0,0,0,0,0,0,0
0,0,0,0,0,0,0,0,0,0,0,0,0,0,0,0,0,0,0
0,0,0,0,0,0,0,0,0,0,0,0,0,0,0,0,0,0,0
0,0,0,0,0,0,0,0,0,0,0,0,0,0,0,0,0,0,0
0,0,0,0,0,0,0,0,0,0,0,0,0,0,0,0,0,0,0
0,0,0,0,0,0,0,0,0,0,0,0,0,0,0,0,0,0,0
:endlayer
layer: 15
0,0,0,0,0,0,0,0,0,0,0,0,0,0,0,0,0,0,0
0,0,0,0,0,0,0,0,0,0,0,0,0,0,0,0,0,0,0
0,0,0,0,0,0,0,0,0,0,0,0,0,0,0,0,0,0,0
0,0,0,0,0,0,0,0,0,0,0,0,0,0,0,0,0,0,0
0,0,0,0,0,0,0,0,0,0,0,0,0,0,0,0,0,0,0
0,0,0,0,0,54,54,54,54,54,54,54,54,54,0,0,0,0,0
0,0,0,0,0,0,0,0,0,0,0,0,0,54,0,0,0,0,0
0,0,0,0,0,0,0,0,0,0,0,0,0,54,0,0,0,0,0
0,0,0,0,0,0,0,0,0,0,0,0,0,0,0,0,0,0,0
0,0,0,0,6,6,0,0,0,0,6,0,0,0,0,0,0,0,0
0,0,0,0,0,6,6,0,0,6,6,0,0,0,0,0,0,0,0
0,0,0,0,0,0,6,6,6,6,0,0,0,0,0,0,0,0,0
0,0,0,0,0,0,6,4,6,0,0,0,0,0,0,0,0,0,0
0,0,0,0,0,6,6,6,6,0,0,0,0,0,0,0,0,0,0
0,0,0,0,6,6,0,0,6,6,0,0,0,0,0,0,0,0,0
0,0,0,0,6,0,0,0,0,6,6,0,0,0,0,0,0,0,0
0,0,0,0,0,0,0,0,0,0,0,0,0,0,0,0,0,0,0
0,0,0,0,0,0,0,0,0,0,0,0,0,0,0,0,0,0,0
0,0,0,0,0,0,0,0,0,0,0,0,0,0,0,0,0,0,0
:endlayer
layer: 16
0,0,0,0,0,0,0,0,0,0,0,0,0,0,0,0,0,0,0
0,0,0,0,0,0,0,0,0,0,0,0,0,0,0,0,0,0,0
0,0,0,0,0,0,0,0,0,0,0,0,0,0,0,0,0,0,0
0,0,0,0,0,0,0,0,0,0,0,0,0,0,0,0,0,0,0
0,0,0,0,0,0,0,0,0,0,0,0,0,0,0,0,0,0,0
0,0,0,0,0,0,0,0,0,0,0,0,0,0,0,0,0,0,0
0,0,0,0,0,0,0,0,0,0,0,0,0,0,0,0,0,0,0
0,0,0,0,0,0,0,0,0,0,0,0,0,0,0,0,0,0,0
0,0,0,0,0,0,0,0,0,0,0,0,0,0,0,0,0,0,0
0,0,0,0,67,0,0,0,0,0,67,0,0,0,0,0,0,0,0
0,0,0,0,0,67,0,0,0,67,0,0,0,0,0,0,0,0,0
0,0,0,0,0,0,67,0,67,0,0,0,0,0,0,0,0,0,0
0,0,0,0,0,0,0,52,0,0,0,0,0,0,0,0,0,0,0
0,0,0,0,0,0,67,0,67,0,0,0,0,0,0,0,0,0,0
0,0,0,0,0,67,0,0,0,67,0,0,0,0,0,0,0,0,0
0,0,0,0,67,0,0,0,0,0,67,0,0,0,0,0,0,0,0
0,0,0,0,0,0,0,0,0,0,0,0,0,0,0,0,0,0,0
0,0,0,0,0,0,0,0,0,0,0,0,0,0,0,0,0,0,0
0,0,0,0,0,0,0,0,0,0,0,0,0,0,0,0,0,0,0
:endlayer
layer: 17
0,0,0,0,0,0,0,0,0,0,0,0,0,0,0,0,0,0,0
0,0,0,0,0,0,0,0,0,0,0,0,0,0,0,0,0,0,0
0,0,0,0,0,0,0,0,0,0,0,0,0,0,0,0,0,0,0
0,0,0,0,0,0,0,0,0,0,0,0,0,0,0,0,0,0,0
0,0,0,0,0,0,0,0,0,0,0,0,0,0,0,0,0,0,0
0,0,0,0,0,0,0,0,0,0,0,0,0,0,0,0,0,0,0
0,0,0,0,0,0,0,0,0,0,0,0,0,0,0,0,0,0,0
0,0,0,0,0,0,0,0,0,0,0,0,0,0,0,0,0,0,0
0,0,0,0,0,0,0,0,0,0,0,0,0,0,0,0,0,0,0
0,0,0,0,67,0,0,0,0,0,67,0,0,0,0,0,0,0,0
0,0,0,0,0,67,0,0,0,67,0,0,0,0,0,0,0,0,0
0,0,0,0,0,0,67,0,67,0,0,0,0,0,0,0,0,0,0
0,0,0,0,0,0,0,52,0,0,0,0,0,0,0,0,0,0,0
0,0,0,0,0,0,67,0,67,0,0,0,0,0,0,0,0,0,0
0,0,0,0,0,67,0,0,0,67,0,0,0,0,0,0,0,0,0
0,0,0,0,67,0,0,0,0,0,67,0,0,0,0,0,0,0,0
0,0,0,0,0,0,0,0,0,0,0,0,0,0,0,0,0,0,0
0,0,0,0,0,0,0,0,0,0,0,0,0,0,0,0,0,0,0
0,0,0,0,0,0,0,0,0,0,0,0,0,0,0,0,0,0,0
:endlayer
layer: 18
0,0,0,0,0,0,0,0,0,0,0,0,0,0,0,0,0,0,0
0,0,0,0,0,0,0,0,0,0,0,0,0,0,0,0,0,0,0
0,0,0,0,0,0,0,0,0,0,0,0,0,0,0,0,0,0,0
0,0,0,0,0,0,0,0,0,0,0,0,0,0,0,0,0,0,0
0,0,0,0,0,0,0,0,0,0,0,0,0,0,0,0,0,0,0
0,0,0,0,0,0,0,0,0,0,0,0,0,0,0,0,0,0,0
0,0,0,0,0,0,0,0,0,0,0,0,0,0,0,0,0,0,0
0,0,0,0,0,0,0,0,0,0,0,0,0,0,0,0,0,0,0
0,0,0,0,0,0,0,0,0,0,0,0,0,0,0,0,0,0,0
0,0,0,0,67,0,0,0,0,0,67,0,0,0,0,0,0,0,0
0,0,0,0,0,67,0,0,0,67,0,0,0,0,0,0,0,0,0
0,0,0,0,0,0,67,0,67,0,0,0,0,0,0,0,0,0,0
0,0,0,0,0,0,0,52,0,0,0,0,0,0,0,0,0,0,0
0,0,0,0,0,0,67,0,67,0,0,0,0,0,0,0,0,0,0
0,0,0,0,0,67,0,0,0,67,0,0,0,0,0,0,0,0,0
0,0,0,0,67,0,0,0,0,0,67,0,0,0,0,0,0,0,0
0,0,0,0,0,0,0,0,0,0,0,0,0,0,0,0,0,0,0
0,0,0,0,0,0,0,0,0,0,0,0,0,0,0,0,0,0,0
0,0,0,0,0,0,0,0,0,0,0,0,0,0,0,0,0,0,0
:endlayer
layer: 19
0,0,0,0,0,0,0,0,0,0,0,0,0,0,0,0,0,0,0
0,0,0,0,0,0,0,0,0,0,0,0,0,0,0,0,0,0,0
0,0,0,0,0,0,0,0,0,0,0,0,0,0,0,0,0,0,0
0,0,0,0,0,0,0,0,0,0,0,0,0,0,0,0,0,0,0
0,0,0,0,0,0,0,0,0,0,0,0,0,0,0,0,0,0,0
0,0,0,0,0,0,0,0,0,0,0,0,0,0,0,0,0,0,0
0,0,0,0,0,0,0,0,0,0,0,0,0,0,0,0,0,0,0
0,0,0,0,0,0,0,0,0,0,0,0,0,0,0,0,0,0,0
0,0,0,0,0,0,0,0,0,0,0,0,0,0,0,0,0,0,0
0,0,0,0,6,6,0,0,0,0,6,0,0,0,0,0,0,0,0
0,0,0,0,0,6,6,0,0,6,6,0,0,0,0,0,0,0,0
0,0,0,0,0,0,6,6,6,6,0,0,0,0,0,0,0,0,0
0,0,0,0,0,0,6,4,6,0,0,0,0,0,0,0,0,0,0
0,0,0,0,0,6,6,6,6,0,0,0,0,0,0,0,0,0,0
0,0,0,0,6,6,0,0,6,6,0,0,0,0,0,0,0,0,0
0,0,0,0,6,0,0,0,0,6,6,0,0,0,0,0,0,0,0
0,0,0,0,0,0,0,0,0,0,0,0,0,0,0,0,0,0,0
0,0,0,0,0,0,0,0,0,0,0,0,0,0,0,0,0,0,0
0,0,0,0,0,0,0,0,0,0,0,0,0,0,0,0,0,0,0
:endlayer
layer: 20
0,0,0,0,0,0,0,0,0,0,0,0,0,0,0,0,0,0,0
0,0,0,0,0,0,0,0,0,0,0,0,0,0,0,0,0,0,0
0,0,0,0,0,0,0,0,0,0,0,0,0,0,0,0,0,0,0
0,0,0,0,0,0,0,0,0,0,0,0,0,0,0,0,0,0,0
0,0,0,0,0,0,0,0,0,0,0,0,0,0,0,0,0,0,0
0,0,0,0,0,0,0,0,0,0,0,0,0,0,0,0,0,0,0
0,0,0,0,0,0,0,0,0,0,0,0,0,0,0,0,0,0,0
0,0,0,0,0,0,0,0,0,0,0,0,0,0,0,0,0,0,0
0,0,0,0,0,0,0,0,0,0,0,0,0,0,0,0,0,0,0
0,0,0,0,67,0,0,0,0,0,67,0,0,0,0,0,0,0,0
0,0,0,0,0,67,0,0,0,67,0,0,0,0,0,0,0,0,0
0,0,0,0,0,0,67,0,67,0,0,0,0,0,0,0,0,0,0
0,0,0,0,0,0,0,52,0,0,0,0,0,0,0,0,0,0,0
0,0,0,0,0,0,67,0,67,0,0,0,0,0,0,0,0,0,0
0,0,0,0,0,67,0,0,0,67,0,0,0,0,0,0,0,0,0
0,0,0,0,67,0,0,0,0,0,67,0,0,0,0,0,0,0,0
0,0,0,0,0,0,0,0,0,0,0,0,0,0,0,0,0,0,0
0,0,0,0,0,0,0,0,0,0,0,0,0,0,0,0,0,0,0
0,0,0,0,0,0,0,0,0,0,0,0,0,0,0,0,0,0,0
:endlayer
layer: 21
0,0,0,0,0,0,0,0,0,0,0,0,0,0,0,0,0,0,0
0,0,0,0,0,0,0,0,0,0,0,0,0,0,0,0,0,0,0
0,0,0,0,0,0,0,0,0,0,0,0,0,0,0,0,0,0,0
0,0,0,0,0,0,0,0,0,0,0,0,0,0,0,0,0,0,0
0,0,0,0,0,0,0,0,0,0,0,0,0,0,0,0,0,0,0
0,0,0,0,0,0,0,0,0,0,0,0,0,0,0,0,0,0,0
0,0,0,0,0,0,0,0,0,0,0,0,0,0,0,0,0,0,0
0,0,0,0,0,0,0,0,0,0,0,0,0,0,0,0,0,0,0
0,0,0,0,0,0,0,0,0,0,0,0,0,0,0,0,0,0,0
0,0,0,0,67,0,0,0,0,0,67,0,0,0,0,0,0,0,0
0,0,0,0,0,67,0,0,0,67,0,0,0,0,0,0,0,0,0
0,0,0,0,0,0,67,0,67,0,0,0,0,0,0,0,0,0,0
0,0,0,0,0,0,0,52,0,0,0,0,0,0,0,0,0,0,0
0,0,0,0,0,0,67,0,67,0,0,0,0,0,0,0,0,0,0
0,0,0,0,0,67,0,0,0,67,0,0,0,0,0,0,0,0,0
0,0,0,0,67,0,0,0,0,0,67,0,0,0,0,0,0,0,0
0,0,0,0,0,0,0,0,0,0,0,0,0,0,0,0,0,0,0
0,0,0,0,0,0,0,0,0,0,0,0,0,0,0,0,0,0,0
0,0,0,0,0,0,0,0,0,0,0,0,0,0,0,0,0,0,0
:endlayer
layer: 22
0,0,0,0,0,0,0,0,0,0,0,0,0,0,0,0,0,0,0
0,0,0,0,0,0,0,0,0,0,0,0,0,0,0,0,0,0,0
0,0,0,0,0,0,0,0,0,0,0,0,0,0,0,0,0,0,0
0,0,0,0,0,0,0,0,0,0,0,0,0,0,0,0,0,0,0
0,0,0,0,0,0,0,0,0,0,0,0,0,0,0,0,0,0,0
0,0,0,0,0,0,0,0,0,0,0,0,0,0,0,0,0,0,0
0,0,0,0,0,0,0,0,0,0,0,0,0,0,0,0,0,0,0
0,0,0,0,0,0,0,0,0,0,0,0,0,0,0,0,0,0,0
0,0,0,0,0,0,0,0,0,0,0,0,0,0,0,0,0,0,0
0,0,0,0,67,0,0,0,0,0,67,0,0,0,0,0,0,0,0
0,0,0,0,0,67,0,0,0,67,0,0,0,0,0,0,0,0,0
0,0,0,0,0,0,67,0,67,0,0,0,0,0,0,0,0,0,0
0,0,0,0,0,0,0,52,0,0,0,0,0,0,0,0,0,0,0
0,0,0,0,0,0,67,0,67,0,0,0,0,0,0,0,0,0,0
0,0,0,0,0,67,0,0,0,67,0,0,0,0,0,0,0,0,0
0,0,0,0,67,0,0,0,0,0,67,0,0,0,0,0,0,0,0
0,0,0,0,0,0,0,0,0,0,0,0,0,0,0,0,0,0,0
0,0,0,0,0,0,0,0,0,0,0,0,0,0,0,0,0,0,0
0,0,0,0,0,0,0,0,0,0,0,0,0,0,0,0,0,0,0
:endlayer
layer: 23
0,0,0,0,0,0,0,0,0,0,0,0,0,0,0,0,0,0,0
0,0,0,0,0,0,0,0,0,0,0,0,0,0,0,0,0,0,0
0,0,0,0,0,0,0,0,0,0,0,0,0,0,0,0,0,0,0
0,0,0,0,0,0,0,0,0,0,0,0,0,0,0,0,0,0,0
0,0,0,0,0,0,0,0,0,0,0,0,0,0,0,0,0,0,0
0,0,0,0,0,0,0,0,0,0,0,0,0,0,0,0,0,0,0
0,0,0,0,0,0,0,0,0,0,0,0,0,0,0,0,0,0,0
0,0,0,0,0,0,0,0,0,0,0,0,0,0,0,0,0,0,0
0,0,0,0,0,0,0,0,0,0,0,0,0,0,0,0,0,0,0
0,0,0,0,6,6,0,0,0,0,6,0,0,0,0,0,0,0,0
0,0,0,0,0,6,6,0,0,6,6,0,0,0,0,0,0,0,0
0,0,0,0,0,0,6,6,6,6,0,0,0,0,0,0,0,0,0
0,0,0,0,0,0,6,4,6,0,0,0,0,0,0,0,0,0,0
0,0,0,0,0,6,6,6,6,0,0,0,0,0,0,0,0,0,0
0,0,0,0,6,6,0,0,6,6,0,0,0,0,0,0,0,0,0
0,0,0,0,6,0,0,0,0,6,6,0,0,0,0,0,0,0,0
0,0,0,0,0,0,0,0,0,0,0,0,0,0,0,0,0,0,0
0,0,0,0,0,0,0,0,0,0,0,0,0,0,0,0,0,0,0
0,0,0,0,0,0,0,0,0,0,0,0,0,0,0,0,0,0,0
:endlayer
layer: 24
0,0,0,0,0,0,0,0,0,0,0,0,0,0,0,0,0,0,0
0,0,0,0,0,0,0,0,0,0,0,0,0,0,0,0,0,0,0
0,0,0,0,0,0,0,0,0,0,0,0,0,0,0,0,0,0,0
0,0,0,0,0,0,0,0,0,0,0,0,0,0,0,0,0,0,0
0,0,0,0,0,0,0,0,0,0,0,0,0,0,0,0,0,0,0
0,0,0,0,0,0,0,0,0,0,0,0,0,0,0,0,0,0,0
0,0,0,0,0,0,0,0,0,0,0,0,0,0,0,0,0,0,0
0,0,0,0,0,0,0,0,0,0,0,0,0,0,0,0,0,0,0
0,0,0,0,0,0,0,0,0,0,0,0,0,0,0,0,0,0,0
0,0,0,0,67,0,0,0,0,0,67,0,0,0,0,0,0,0,0
0,0,0,0,0,67,0,0,0,67,0,0,0,0,0,0,0,0,0
0,0,0,0,0,0,67,0,67,0,0,0,0,0,0,0,0,0,0
0,0,0,0,0,0,0,52,0,0,0,0,0,0,0,0,0,0,0
0,0,0,0,0,0,67,0,67,0,0,0,0,0,0,0,0,0,0
0,0,0,0,0,67,0,0,0,67,0,0,0,0,0,0,0,0,0
0,0,0,0,67,0,0,0,0,0,67,0,0,0,0,0,0,0,0
0,0,0,0,0,0,0,0,0,0,0,0,0,0,0,0,0,0,0
0,0,0,0,0,0,0,0,0,0,0,0,0,0,0,0,0,0,0
0,0,0,0,0,0,0,0,0,0,0,0,0,0,0,0,0,0,0
:endlayer
layer: 25
0,0,0,0,0,0,0,0,0,0,0,0,0,0,0,0,0,0,0
0,0,0,0,0,0,0,0,0,0,0,0,0,0,0,0,0,0,0
0,0,0,0,0,0,0,0,0,0,0,0,0,0,0,0,0,0,0
0,0,0,0,0,0,0,0,0,0,0,0,0,0,0,0,0,0,0
0,0,0,0,0,0,0,0,0,0,0,0,0,0,0,0,0,0,0
0,0,0,0,0,0,0,0,0,0,0,0,0,0,0,0,0,0,0
0,0,0,0,0,0,0,0,0,0,0,0,0,0,0,0,0,0,0
0,0,0,0,0,0,0,0,0,0,0,0,0,0,0,0,0,0,0
0,0,0,0,0,0,0,0,0,0,0,0,0,0,0,0,0,0,0
0,0,0,0,67,0,0,0,0,0,67,0,0,0,0,0,0,0,0
0,0,0,0,0,67,0,0,0,67,0,0,0,0,0,0,0,0,0
0,0,0,0,0,0,67,0,67,0,0,0,0,0,0,0,0,0,0
0,0,0,0,0,0,0,52,0,0,0,0,0,0,0,0,0,0,0
0,0,0,0,0,0,67,0,67,0,0,0,0,0,0,0,0,0,0
0,0,0,0,0,67,0,0,0,67,0,0,0,0,0,0,0,0,0
0,0,0,0,67,0,0,0,0,0,67,0,0,0,0,0,0,0,0
0,0,0,0,0,0,0,0,0,0,0,0,0,0,0,0,0,0,0
0,0,0,0,0,0,0,0,0,0,0,0,0,0,0,0,0,0,0
0,0,0,0,0,0,0,0,0,0,0,0,0,0,0,0,0,0,0
:endlayer
layer: 26
0,0,0,0,0,0,0,0,0,0,0,0,0,0,0,0,0,0,0
0,0,0,0,0,0,0,0,0,0,0,0,0,0,0,0,0,0,0
0,0,0,0,0,0,0,0,0,0,0,0,0,0,0,0,0,0,0
0,0,0,0,0,0,0,0,0,0,0,0,0,0,0,0,0,0,0
0,0,0,0,0,0,0,0,0,0,0,0,0,0,0,0,0,0,0
0,0,0,0,0,0,0,0,0,0,0,0,0,0,0,0,0,0,0
0,0,0,0,0,0,0,0,0,0,0,0,0,0,0,0,0,0,0
0,0,0,0,0,0,0,0,0,0,0,0,0,0,0,0,0,0,0
0,0,0,0,0,0,0,0,0,0,0,0,0,0,0,0,0,0,0
0,0,0,0,67,0,0,0,0,0,67,0,0,0,0,0,0,0,0
0,0,0,0,0,67,0,0,0,67,0,0,0,0,0,0,0,0,0
0,0,0,0,0,0,67,0,67,0,0,0,0,0,0,0,0,0,0
0,0,0,0,0,0,0,52,0,0,0,0,0,0,0,0,0,0,0
0,0,0,0,0,0,67,0,67,0,0,0,0,0,0,0,0,0,0
0,0,0,0,0,67,0,0,0,67,0,0,0,0,0,0,0,0,0
0,0,0,0,67,0,0,0,0,0,67,0,0,0,0,0,0,0,0
0,0,0,0,0,0,0,0,0,0,0,0,0,0,0,0,0,0,0
0,0,0,0,0,0,0,0,0,0,0,0,0,0,0,0,0,0,0
0,0,0,0,0,0,0,0,0,0,0,0,0,0,0,0,0,0,0
:endlayer
layer: 27
0,0,0,0,0,0,0,0,0,0,0,0,0,0,0,0,0,0,0
0,0,0,0,0,0,0,0,0,0,0,0,0,0,0,0,0,0,0
0,0,0,0,0,0,0,0,0,0,0,0,0,0,0,0,0,0,0
0,0,0,0,0,0,0,0,0,0,0,0,0,0,0,0,0,0,0
0,0,0,0,0,0,0,0,0,0,0,0,0,0,0,0,0,0,0
0,0,0,0,0,0,0,0,0,0,0,0,0,0,0,0,0,0,0
0,0,0,0,0,0,0,0,0,0,0,0,0,0,0,0,0,0,0
0,0,0,0,0,0,0,0,0,0,0,0,0,0,0,0,0,0,0
0,0,0,0,0,0,0,0,0,0,0,0,0,0,0,0,0,0,0
0,0,0,0,54,0,0,0,0,0,54,0,0,0,0,0,0,0,0
0,0,0,0,0,54,0,0,0,54,0,0,0,0,0,0,0,0,0
0,0,0,0,0,0,54,0,54,0,0,0,0,0,0,0,0,0,0
0,0,0,0,0,0,0,4,0,0,0,0,0,0,0,0,0,0,0
0,0,0,0,0,0,54,0,54,0,0,0,0,0,0,0,0,0,0
0,0,0,0,0,54,0,0,0,54,0,0,0,0,0,0,0,0,0
0,0,0,0,54,0,0,0,0,0,54,0,0,0,0,0,0,0,0
0,0,0,0,0,0,0,0,0,0,0,0,0,0,0,0,0,0,0
0,0,0,0,0,0,0,0,0,0,0,0,0,0,0,0,0,0,0
0,0,0,0,0,0,0,0,0,0,0,0,0,0,0,0,0,0,0
:endlayer
layer: 28
0,0,0,0,0,0,0,0,0,0,0,0,0,0,0,0,0,0,0
0,0,0,0,0,0,0,0,0,0,0,0,0,0,0,0,0,0,0
0,0,0,0,0,0,0,0,0,0,0,0,0,0,0,0,0,0,0
0,0,0,0,0,0,0,0,0,0,0,0,0,0,0,0,0,0,0
0,0,0,0,0,0,0,0,0,0,0,0,0,0,0,0,0,0,0
0,0,0,0,0,0,0,0,0,0,0,0,0,0,0,0,0,0,0
0,0,0,0,0,0,0,0,0,0,0,0,0,0,0,0,0,0,0
0,0,0,0,0,0,0,0,0,0,0,0,0,0,0,0,0,0,0
0,0,0,0,0,0,0,0,0,0,0,0,0,0,0,0,0,0,0
0,0,0,0,0,0,0,0,0,0,0,0,0,0,0,0,0,0,0
0,0,0,0,0,0,0,0,0,0,0,0,0,0,0,0,0,0,0
0,0,0,0,0,0,0,0,0,0,0,0,0,0,0,0,0,0,0
0,0,0,0,0,0,0,0,0,0,0,0,0,0,0,0,0,0,0
0,0,0,0,0,0,0,0,0,0,0,0,0,0,0,0,0,0,0
0,0,0,0,0,0,0,0,0,0,0,0,0,0,0,0,0,0,0
0,0,0,0,0,0,0,0,0,0,0,0,0,0,0,0,0,0,0
0,0,0,0,0,0,0,0,0,0,0,0,0,0,0,0,0,0,0
0,0,0,0,0,0,0,0,0,0,0,0,0,0,0,0,0,0,0
0,0,0,0,0,0,0,0,0,0,0,0,0,0,0,0,0,0,0
:endlayer
layer: 29
0,0,0,0,0,0,0,0,0,0,0,0,0,0,0,0,0,0,0
0,0,0,0,0,0,0,0,0,0,0,0,0,0,0,0,0,0,0
0,0,0,0,0,0,0,0,0,0,0,0,0,0,0,0,0,0,0
0,0,0,0,0,0,0,0,0,0,0,0,0,0,0,0,0,0,0
0,0,0,0,0,0,0,0,0,0,0,0,0,0,0,0,0,0,0
0,0,0,0,0,0,0,0,0,0,0,0,0,0,0,0,0,0,0
0,0,0,0,0,0,0,0,0,0,0,0,0,0,0,0,0,0,0
0,0,0,0,0,0,0,0,0,0,0,0,0,0,0,0,0,0,0
0,0,0,0,0,0,0,0,0,0,0,0,0,0,0,0,0,0,0
0,0,0,0,0,0,0,0,0,0,0,0,0,0,0,0,0,0,0
0,0,0,0,0,0,0,0,0,0,0,0,0,0,0,0,0,0,0
0,0,0,0,0,0,0,0,0,0,0,0,0,0,0,0,0,0,0
0,0,0,0,0,0,0,0,0,0,0,0,0,0,0,0,0,0,0
0,0,0,0,0,0,0,0,0,0,0,0,0,0,0,0,0,0,0
0,0,0,0,0,0,0,0,0,0,0,0,0,0,0,0,0,0,0
0,0,0,0,0,0,0,0,0,0,0,0,0,0,0,0,0,0,0
0,0,0,0,0,0,0,0,0,0,0,0,0,0,0,0,0,0,0
0,0,0,0,0,0,0,0,0,0,0,0,0,0,0,0,0,0,0
0,0,0,0,0,0,0,0,0,0,0,0,0,0,0,0,0,0,0
:endlayer
layer: 30
0,0,0,0,0,0,0,0,0,0,0,0,0,0,0,0,0,0,0
0,0,0,0,0,0,0,0,0,0,0,0,0,0,0,0,0,0,0
0,0,0,0,0,0,0,0,0,0,0,0,0,0,0,0,0,0,0
0,0,0,0,0,0,0,0,0,0,0,0,0,0,0,0,0,0,0
0,0,0,0,0,0,0,0,0,0,0,0,0,0,0,0,0,0,0
0,0,0,0,0,0,0,0,0,0,0,0,0,0,0,0,0,0,0
0,0,0,0,0,0,0,0,0,0,0,0,0,0,0,0,0,0,0
0,0,0,0,0,0,0,0,0,0,0,0,0,0,0,0,0,0,0
0,0,0,0,0,0,0,0,0,0,0,0,0,0,0,0,0,0,0
0,0,0,0,0,0,0,0,0,0,0,0,0,0,0,0,0,0,0
0,0,0,0,0,0,0,0,0,0,0,0,0,0,0,0,0,0,0
0,0,0,0,0,0,0,0,0,0,0,0,0,0,0,0,0,0,0
0,0,0,0,0,0,0,0,0,0,0,0,0,0,0,0,0,0,0
0,0,0,0,0,0,0,0,0,0,0,0,0,0,0,0,0,0,0
0,0,0,0,0,0,0,0,0,0,0,0,0,0,0,0,0,0,0
0,0,0,0,0,0,0,0,0,0,0,0,0,0,0,0,0,0,0
0,0,0,0,0,0,0,0,0,0,0,0,0,0,0,0,0,0,0
0,0,0,0,0,0,0,0,0,0,0,0,0,0,0,0,0,0,0
0,0,0,0,0,0,0,0,0,0,0,0,0,0,0,0,0,0,0
:endlayer
layer: 31
0,0,0,0,0,0,0,0,0,0,0,0,0,0,0,0,0,0,0
0,0,0,0,0,0,0,0,0,0,0,0,0,0,0,0,0,0,0
0,0,0,0,0,0,0,0,0,0,0,0,0,0,0,0,0,0,0
0,0,0,0,0,0,0,0,0,0,0,0,0,0,0,0,0,0,0
0,0,0,0,0,0,0,0,0,0,0,0,0,0,0,0,0,0,0
0,0,0,0,0,0,0,0,0,0,0,0,0,0,0,0,0,0,0
0,0,0,0,0,0,0,0,0,0,0,0,0,0,0,0,0,0,0
0,0,0,0,0,0,0,0,0,0,0,0,0,0,0,0,0,0,0
0,0,0,0,0,0,0,0,0,0,0,0,0,0,0,0,0,0,0
0,0,0,0,0,0,0,0,0,0,0,0,0,0,0,0,0,0,0
0,0,0,0,0,0,0,0,0,0,0,0,0,0,0,0,0,0,0
0,0,0,0,0,0,0,0,0,0,0,0,0,0,0,0,0,0,0
0,0,0,0,0,0,0,0,0,0,0,0,0,0,0,0,0,0,0
0,0,0,0,0,0,0,0,0,0,0,0,0,0,0,0,0,0,0
0,0,0,0,0,0,0,0,0,0,0,0,0,0,0,0,0,0,0
0,0,0,0,0,0,0,0,0,0,0,0,0,0,0,0,0,0,0
0,0,0,0,0,0,0,0,0,0,0,0,0,0,0,0,0,0,0
0,0,0,0,0,0,0,0,0,0,0,0,0,0,0,0,0,0,0
0,0,0,0,0,0,0,0,0,0,0,0,0,0,0,0,0,0,0
:endlayer
layer: 32
0,0,0,0,0,0,0,0,0,0,0,0,0,0,0,0,0,0,0
0,0,0,0,0,0,0,0,0,0,0,0,0,0,0,0,0,0,0
0,0,0,0,0,0,0,0,0,0,0,0,0,0,0,0,0,0,0
0,0,0,0,0,0,0,0,0,0,0,0,0,0,0,0,0,0,0
0,0,0,0,0,0,0,0,0,0,0,0,0,0,0,0,0,0,0
0,0,0,0,0,0,0,0,0,0,0,0,0,0,0,0,0,0,0
0,0,0,0,0,0,0,0,0,0,0,0,0,0,0,0,0,0,0
0,0,0,0,0,0,0,0,0,0,0,0,0,0,0,0,0,0,0
0,0,0,0,0,0,0,0,0,0,0,0,0,0,0,0,0,0,0
0,0,0,0,0,0,0,0,0,0,0,0,0,0,0,0,0,0,0
0,0,0,0,0,0,0,0,0,0,0,0,0,0,0,0,0,0,0
0,0,0,0,0,0,0,0,0,0,0,0,0,0,0,0,0,0,0
0,0,0,0,0,0,0,0,0,0,0,0,0,0,0,0,0,0,0
0,0,0,0,0,0,0,0,0,0,0,0,0,0,0,0,0,0,0
0,0,0,0,0,0,0,0,0,0,0,0,0,0,0,0,0,0,0
0,0,0,0,0,0,0,0,0,0,0,0,0,0,0,0,0,0,0
0,0,0,0,0,0,0,0,0,0,0,0,0,0,0,0,0,0,0
0,0,0,0,0,0,0,0,0,0,0,0,0,0,0,0,0,0,0
0,0,0,0,0,0,0,0,0,0,0,0,0,0,0,0,0,0,0
:endlayer
layer: 33
0,0,0,0,0,0,0,0,0,0,0,0,0,0,0,0,0,0,0
0,0,0,0,0,0,0,0,0,0,0,0,0,0,0,0,0,0,0
0,0,0,0,0,0,0,0,0,0,0,0,0,0,0,0,0,0,0
0,0,0,0,0,0,0,0,0,0,0,0,0,0,0,0,0,0,0
0,0,0,0,0,0,0,0,0,0,0,0,0,0,0,0,0,0,0
0,0,0,0,0,0,0,0,0,0,0,0,0,0,0,0,0,0,0
0,0,0,0,0,0,0,0,0,0,0,0,0,0,0,0,0,0,0
0,0,0,0,0,0,0,0,0,0,0,0,0,0,0,0,0,0,0
0,0,0,0,0,0,0,0,0,0,0,0,0,0,0,0,0,0,0
0,0,0,0,0,0,0,0,0,0,0,0,0,0,0,0,0,0,0
0,0,0,0,0,0,0,0,0,0,0,0,0,0,0,0,0,0,0
0,0,0,0,0,0,0,0,0,0,0,0,0,0,0,0,0,0,0
0,0,0,0,0,0,0,0,0,0,0,0,0,0,0,0,0,0,0
0,0,0,0,0,0,0,0,0,0,0,0,0,0,0,0,0,0,0
0,0,0,0,0,0,0,0,0,0,0,0,0,0,0,0,0,0,0
0,0,0,0,0,0,0,0,0,0,0,0,0,0,0,0,0,0,0
0,0,0,0,0,0,0,0,0,0,0,0,0,0,0,0,0,0,0
0,0,0,0,0,0,0,0,0,0,0,0,0,0,0,0,0,0,0
0,0,0,0,0,0,0,0,0,0,0,0,0,0,0,0,0,0,0
:endlayer
layer: 34
0,0,0,0,0,0,0,0,0,0,0,0,0,0,0,0,0,0,0
0,0,0,0,0,0,0,0,0,0,0,0,0,0,0,0,0,0,0
0,0,0,0,0,0,0,0,0,0,0,0,0,0,0,0,0,0,0
0,0,0,0,0,0,0,0,0,0,0,0,0,0,0,0,0,0,0
0,0,0,0,0,0,0,0,0,0,0,0,0,0,0,0,0,0,0
0,0,0,0,0,0,0,0,0,0,0,0,0,0,0,0,0,0,0
0,0,0,0,0,0,0,0,0,0,0,0,0,0,0,0,0,0,0
0,0,0,0,0,0,0,0,0,0,0,0,0,0,0,0,0,0,0
0,0,0,0,0,0,0,0,0,0,0,0,0,0,0,0,0,0,0
0,0,0,0,0,0,0,0,0,0,0,0,0,0,0,0,0,0,0
0,0,0,0,0,0,0,0,0,0,0,0,0,0,0,0,0,0,0
0,0,0,0,0,0,0,0,0,0,0,0,0,0,0,0,0,0,0
0,0,0,0,0,0,0,0,0,0,0,0,0,0,0,0,0,0,0
0,0,0,0,0,0,0,0,0,0,0,0,0,0,0,0,0,0,0
0,0,0,0,0,0,0,0,0,0,0,0,0,0,0,0,0,0,0
0,0,0,0,0,0,0,0,0,0,0,0,0,0,0,0,0,0,0
0,0,0,0,0,0,0,0,0,0,0,0,0,0,0,0,0,0,0
0,0,0,0,0,0,0,0,0,0,0,0,0,0,0,0,0,0,0
0,0,0,0,0,0,0,0,0,0,0,0,0,0,0,0,0,0,0
:endlayer
layer: 35
0,0,0,0,0,0,0,0,0,0,0,0,0,0,0,0,0,0,0
0,0,0,0,0,0,0,0,0,0,0,0,0,0,0,0,0,0,0
0,0,0,0,0,0,0,0,0,0,0,0,0,0,0,0,0,0,0
0,0,0,0,0,0,0,0,0,0,0,0,0,0,0,0,0,0,0
0,0,0,0,0,0,0,0,0,0,0,0,0,0,0,0,0,0,0
0,0,0,0,0,0,0,0,0,0,0,0,0,0,0,0,0,0,0
0,0,0,0,0,0,0,0,0,0,0,0,0,0,0,0,0,0,0
0,0,0,0,0,0,0,0,0,0,0,0,0,0,0,0,0,0,0
0,0,0,0,0,0,0,0,0,0,0,0,0,0,0,0,0,0,0
0,0,0,0,0,0,0,0,0,0,0,0,0,0,0,0,0,0,0
0,0,0,0,0,0,0,0,0,0,0,0,0,0,0,0,0,0,0
0,0,0,0,0,0,0,0,0,0,0,0,0,0,0,0,0,0,0
0,0,0,0,0,0,0,0,0,0,0,0,0,0,0,0,0,0,0
0,0,0,0,0,0,0,0,0,0,0,0,0,0,0,0,0,0,0
0,0,0,0,0,0,0,0,0,0,0,0,0,0,0,0,0,0,0
0,0,0,0,0,0,0,0,0,0,0,0,0,0,0,0,0,0,0
0,0,0,0,0,0,0,0,0,0,0,0,0,0,0,0,0,0,0
0,0,0,0,0,0,0,0,0,0,0,0,0,0,0,0,0,0,0
0,0,0,0,0,0,0,0,0,0,0,0,0,0,0,0,0,0,0
:endlayer
layer: 36
0,0,0,0,0,0,0,0,0,0,0,0,0,0,0,0,0,0,0
0,0,0,0,0,0,0,0,0,0,0,0,0,0,0,0,0,0,0
0,0,0,0,0,0,0,0,0,0,0,0,0,0,0,0,0,0,0
0,0,0,0,0,0,0,0,0,0,0,0,0,0,0,0,0,0,0
0,0,0,0,0,0,0,0,0,0,0,0,0,0,0,0,0,0,0
0,0,0,0,0,0,0,0,0,0,0,0,0,0,0,0,0,0,0
0,0,0,0,0,0,0,0,0,0,0,0,0,0,0,0,0,0,0
0,0,0,0,0,0,0,0,0,0,0,0,0,0,0,0,0,0,0
0,0,0,0,0,0,0,0,0,0,0,0,0,0,0,0,0,0,0
0,0,0,0,0,0,0,0,0,0,0,0,0,0,0,0,0,0,0
0,0,0,0,0,0,0,0,0,0,0,0,0,0,0,0,0,0,0
0,0,0,0,0,0,0,0,0,0,0,0,0,0,0,0,0,0,0
0,0,0,0,0,0,0,0,0,0,0,0,0,0,0,0,0,0,0
0,0,0,0,0,0,0,0,0,0,0,0,0,0,0,0,0,0,0
0,0,0,0,0,0,0,0,0,0,0,0,0,0,0,0,0,0,0
0,0,0,0,0,0,0,0,0,0,0,0,0,0,0,0,0,0,0
0,0,0,0,0,0,0,0,0,0,0,0,0,0,0,0,0,0,0
0,0,0,0,0,0,0,0,0,0,0,0,0,0,0,0,0,0,0
0,0,0,0,0,0,0,0,0,0,0,0,0,0,0,0,0,0,0
:endlayer
layer: 37
0,0,0,0,0,0,0,0,0,0,0,0,0,0,0,0,0,0,0
0,0,0,0,0,0,0,0,0,0,0,0,0,0,0,0,0,0,0
0,0,0,0,0,0,0,0,0,0,0,0,0,0,0,0,0,0,0
0,0,0,0,0,0,0,0,0,0,0,0,0,0,0,0,0,0,0
0,0,0,0,0,0,0,0,0,0,0,0,0,0,0,0,0,0,0
0,0,0,0,0,0,0,0,0,0,0,0,0,0,0,0,0,0,0
0,0,0,0,0,0,0,0,0,0,0,0,0,0,0,0,0,0,0
0,0,0,0,0,0,0,0,0,0,0,0,0,0,0,0,0,0,0
0,0,0,0,0,0,0,0,0,0,0,0,0,0,0,0,0,0,0
0,0,0,0,0,0,0,0,0,0,0,0,0,0,0,0,0,0,0
0,0,0,0,0,0,0,0,0,0,0,0,0,0,0,0,0,0,0
0,0,0,0,0,0,0,0,0,0,0,0,0,0,0,0,0,0,0
0,0,0,0,0,0,0,0,0,0,0,0,0,0,0,0,0,0,0
0,0,0,0,0,0,0,0,0,0,0,0,0,0,0,0,0,0,0
0,0,0,0,0,0,0,0,0,0,0,0,0,0,0,0,0,0,0
0,0,0,0,0,0,0,0,0,0,0,0,0,0,0,0,0,0,0
0,0,0,0,0,0,0,0,0,0,0,0,0,0,0,0,0,0,0
0,0,0,0,0,0,0,0,0,0,0,0,0,0,0,0,0,0,0
0,0,0,0,0,0,0,0,0,0,0,0,0,0,0,0,0,0,0
:endlayer
layer: 38
0,0,0,0,0,0,0,0,0,0,0,0,0,0,0,0,0,0,0
0,0,0,0,0,0,0,0,0,0,0,0,0,0,0,0,0,0,0
0,0,0,0,0,0,0,0,0,0,0,0,0,0,0,0,0,0,0
0,0,0,0,0,0,0,0,0,0,0,0,0,0,0,0,0,0,0
0,0,0,0,0,0,0,0,0,0,0,0,0,0,0,0,0,0,0
0,0,0,0,0,0,0,0,0,0,0,0,0,0,0,0,0,0,0
0,0,0,0,0,0,0,0,0,0,0,0,0,0,0,0,0,0,0
0,0,0,0,0,0,0,0,0,0,0,0,0,0,0,0,0,0,0
0,0,0,0,0,0,0,0,0,0,0,0,0,0,0,0,0,0,0
0,0,0,0,0,0,0,0,0,0,0,0,0,0,0,0,0,0,0
0,0,0,0,0,0,0,0,0,0,0,0,0,0,0,0,0,0,0
0,0,0,0,0,0,0,0,0,0,0,0,0,0,0,0,0,0,0
0,0,0,0,0,0,0,0,0,0,0,0,0,0,0,0,0,0,0
0,0,0,0,0,0,0,0,0,0,0,0,0,0,0,0,0,0,0
0,0,0,0,0,0,0,0,0,0,0,0,0,0,0,0,0,0,0
0,0,0,0,0,0,0,0,0,0,0,0,0,0,0,0,0,0,0
0,0,0,0,0,0,0,0,0,0,0,0,0,0,0,0,0,0,0
0,0,0,0,0,0,0,0,0,0,0,0,0,0,0,0,0,0,0
0,0,0,0,0,0,0,0,0,0,0,0,0,0,0,0,0,0,0
:endlayer
layer: 39
0,0,0,0,0,0,0,0,0,0,0,0,0,0,0,0,0,0,0
0,0,0,0,0,0,0,0,0,0,0,0,0,0,0,0,0,0,0
0,0,0,0,0,0,0,0,0,0,0,0,0,0,0,0,0,0,0
0,0,0,0,0,0,0,0,0,0,0,0,0,0,0,0,0,0,0
0,0,0,0,0,0,0,0,0,0,0,0,0,0,0,0,0,0,0
0,0,0,0,0,0,0,0,0,0,0,0,0,0,0,0,0,0,0
0,0,0,0,0,0,0,0,0,0,0,0,0,0,0,0,0,0,0
0,0,0,0,0,0,0,0,0,0,0,0,0,0,0,0,0,0,0
0,0,0,0,0,0,0,0,0,0,0,0,0,0,0,0,0,0,0
0,0,0,0,0,0,0,0,0,0,0,0,0,0,0,0,0,0,0
0,0,0,0,0,0,0,0,0,0,0,0,0,0,0,0,0,0,0
0,0,0,0,0,0,0,0,0,0,0,0,0,0,0,0,0,0,0
0,0,0,0,0,0,0,0,0,0,0,0,0,0,0,0,0,0,0
0,0,0,0,0,0,0,0,0,0,0,0,0,0,0,0,0,0,0
0,0,0,0,0,0,0,0,0,0,0,0,0,0,0,0,0,0,0
0,0,0,0,0,0,0,0,0,0,0,0,0,0,0,0,0,0,0
0,0,0,0,0,0,0,0,0,0,0,0,0,0,0,0,0,0,0
0,0,0,0,0,0,0,0,0,0,0,0,0,0,0,0,0,0,0
0,0,0,0,0,0,0,0,0,0,0,0,0,0,0,0,0,0,0
:endlayer
layer: 40
0,0,0,0,0,0,0,0,0,0,0,0,0,0,0,0,0,0,0
0,0,0,0,0,0,0,0,0,0,0,0,0,0,0,0,0,0,0
0,0,0,0,0,0,0,0,0,0,0,0,0,0,0,0,0,0,0
0,0,0,0,0,0,0,0,0,0,0,0,0,0,0,0,0,0,0
0,0,0,0,0,0,0,0,0,0,0,0,0,0,0,0,0,0,0
0,0,0,0,0,0,0,0,0,0,0,0,0,0,0,0,0,0,0
0,0,0,0,0,0,0,0,0,0,0,0,0,0,0,0,0,0,0
0,0,0,0,0,0,0,0,0,0,0,0,0,0,0,0,0,0,0
0,0,0,0,0,0,0,0,0,0,0,0,0,0,0,0,0,0,0
0,0,0,0,0,0,0,0,0,0,0,0,0,0,0,0,0,0,0
0,0,0,0,0,0,0,0,0,0,0,0,0,0,0,0,0,0,0
0,0,0,0,0,0,0,0,0,0,0,0,0,0,0,0,0,0,0
0,0,0,0,0,0,0,0,0,0,0,0,0,0,0,0,0,0,0
0,0,0,0,0,0,0,0,0,0,0,0,0,0,0,0,0,0,0
0,0,0,0,0,0,0,0,0,0,0,0,0,0,0,0,0,0,0
0,0,0,0,0,0,0,0,0,0,0,0,0,0,0,0,0,0,0
0,0,0,0,0,0,0,0,0,0,0,0,0,0,0,0,0,0,0
0,0,0,0,0,0,0,0,0,0,0,0,0,0,0,0,0,0,0
0,0,0,0,0,0,0,0,0,0,0,0,0,0,0,0,0,0,0
:endlayer
layer: 41
0,0,0,0,0,0,0,0,0,0,0,0,0,0,0,0,0,0,0
0,0,0,0,0,0,0,0,0,0,0,0,0,0,0,0,0,0,0
0,0,0,0,0,0,0,0,0,0,0,0,0,0,0,0,0,0,0
0,0,0,0,0,0,0,0,0,0,0,0,0,0,0,0,0,0,0
0,0,0,0,0,0,0,0,0,0,0,0,0,0,0,0,0,0,0
0,0,0,0,0,0,0,0,0,0,0,0,0,0,0,0,0,0,0
0,0,0,0,0,0,0,0,0,0,0,0,0,0,0,0,0,0,0
0,0,0,0,0,0,0,0,0,0,0,0,0,0,0,0,0,0,0
0,0,0,0,0,0,0,0,0,0,0,0,0,0,0,0,0,0,0
0,0,0,0,0,0,0,0,0,0,0,0,0,0,0,0,0,0,0
0,0,0,0,0,0,0,0,0,0,0,0,0,0,0,0,0,0,0
0,0,0,0,0,0,0,0,0,0,0,0,0,0,0,0,0,0,0
0,0,0,0,0,0,0,0,0,0,0,0,0,0,0,0,0,0,0
0,0,0,0,0,0,0,0,0,0,0,0,0,0,0,0,0,0,0
0,0,0,0,0,0,0,0,0,0,0,0,0,0,0,0,0,0,0
0,0,0,0,0,0,0,0,0,0,0,0,0,0,0,0,0,0,0
0,0,0,0,0,0,0,0,0,0,0,0,0,0,0,0,0,0,0
0,0,0,0,0,0,0,0,0,0,0,0,0,0,0,0,0,0,0
0,0,0,0,0,0,0,0,0,0,0,0,0,0,0,0,0,0,0
:endlayer
layer: 42
0,0,0,0,0,0,0,0,0,0,0,0,0,0,0,0,0,0,0
0,0,0,0,0,0,0,0,0,0,0,0,0,0,0,0,0,0,0
0,0,0,0,0,0,0,0,0,0,0,0,0,0,0,0,0,0,0
0,0,0,0,0,0,0,0,0,0,0,0,0,0,0,0,0,0,0
0,0,0,0,0,0,0,0,0,0,0,0,0,0,0,0,0,0,0
0,0,0,0,0,0,0,0,0,0,0,0,0,0,0,0,0,0,0
0,0,0,0,0,0,0,0,0,0,0,0,0,0,0,0,0,0,0
0,0,0,0,0,0,0,0,0,0,0,0,0,0,0,0,0,0,0
0,0,0,0,0,0,0,0,0,0,0,0,0,0,0,0,0,0,0
0,0,0,0,0,0,0,0,0,0,0,0,0,0,0,0,0,0,0
0,0,0,0,0,0,0,0,0,0,0,0,0,0,0,0,0,0,0
0,0,0,0,0,0,0,0,0,0,0,0,0,0,0,0,0,0,0
0,0,0,0,0,0,0,0,0,0,0,0,0,0,0,0,0,0,0
0,0,0,0,0,0,0,0,0,0,0,0,0,0,0,0,0,0,0
0,0,0,0,0,0,0,0,0,0,0,0,0,0,0,0,0,0,0
0,0,0,0,0,0,0,0,0,0,0,0,0,0,0,0,0,0,0
0,0,0,0,0,0,0,0,0,0,0,0,0,0,0,0,0,0,0
0,0,0,0,0,0,0,0,0,0,0,0,0,0,0,0,0,0,0
0,0,0,0,0,0,0,0,0,0,0,0,0,0,0,0,0,0,0
:endlayer
layer: 43
0,0,0,0,0,0,0,0,0,0,0,0,0,0,0,0,0,0,0
0,0,0,0,0,0,0,0,0,0,0,0,0,0,0,0,0,0,0
0,0,0,0,0,0,0,0,0,0,0,0,0,0,0,0,0,0,0
0,0,0,0,0,0,0,0,0,0,0,0,0,0,0,0,0,0,0
0,0,0,0,0,0,0,0,0,0,0,0,0,0,0,0,0,0,0
0,0,0,0,0,0,0,0,0,0,0,0,0,0,0,0,0,0,0
0,0,0,0,0,0,0,0,0,0,0,0,0,0,0,0,0,0,0
0,0,0,0,0,0,0,0,0,0,0,0,0,0,0,0,0,0,0
0,0,0,0,0,0,0,0,0,0,0,0,0,0,0,0,0,0,0
0,0,0,0,0,0,0,0,0,0,0,0,0,0,0,0,0,0,0
0,0,0,0,0,0,0,0,0,0,0,0,0,0,0,0,0,0,0
0,0,0,0,0,0,0,0,0,0,0,0,0,0,0,0,0,0,0
0,0,0,0,0,0,0,0,0,0,0,0,0,0,0,0,0,0,0
0,0,0,0,0,0,0,0,0,0,0,0,0,0,0,0,0,0,0
0,0,0,0,0,0,0,0,0,0,0,0,0,0,0,0,0,0,0
0,0,0,0,0,0,0,0,0,0,0,0,0,0,0,0,0,0,0
0,0,0,0,0,0,0,0,0,0,0,0,0,0,0,0,0,0,0
0,0,0,0,0,0,0,0,0,0,0,0,0,0,0,0,0,0,0
0,0,0,0,0,0,0,0,0,0,0,0,0,0,0,0,0,0,0
:endlayer
layer: 44
0,0,0,0,0,0,0,0,0,0,0,0,0,0,0,0,0,0,0
0,0,0,0,0,0,0,0,0,0,0,0,0,0,0,0,0,0,0
0,0,0,0,0,0,0,0,0,0,0,0,0,0,0,0,0,0,0
0,0,0,0,0,0,0,0,0,0,0,0,0,0,0,0,0,0,0
0,0,0,0,0,0,0,0,0,0,0,0,0,0,0,0,0,0,0
0,0,0,0,0,0,0,0,0,0,0,0,0,0,0,0,0,0,0
0,0,0,0,0,0,0,0,0,0,0,0,0,0,0,0,0,0,0
0,0,0,0,0,0,0,0,0,0,0,0,0,0,0,0,0,0,0
0,0,0,0,0,0,0,0,0,0,0,0,0,0,0,0,0,0,0
0,0,0,0,0,0,0,0,0,0,0,0,0,0,0,0,0,0,0
0,0,0,0,0,0,0,0,0,0,0,0,0,0,0,0,0,0,0
0,0,0,0,0,0,0,0,0,0,0,0,0,0,0,0,0,0,0
0,0,0,0,0,0,0,0,0,0,0,0,0,0,0,0,0,0,0
0,0,0,0,0,0,0,0,0,0,0,0,0,0,0,0,0,0,0
0,0,0,0,0,0,0,0,0,0,0,0,0,0,0,0,0,0,0
0,0,0,0,0,0,0,0,0,0,0,0,0,0,0,0,0,0,0
0,0,0,0,0,0,0,0,0,0,0,0,0,0,0,0,0,0,0
0,0,0,0,0,0,0,0,0,0,0,0,0,0,0,0,0,0,0
0,0,0,0,0,0,0,0,0,0,0,0,0,0,0,0,0,0,0
:endlayer
layer: 45
0,0,0,0,0,0,0,0,0,0,0,0,0,0,0,0,0,0,0
0,0,0,0,0,0,0,0,0,0,0,0,0,0,0,0,0,0,0
0,0,0,0,0,0,0,0,0,0,0,0,0,0,0,0,0,0,0
0,0,0,0,0,0,0,0,0,0,0,0,0,0,0,0,0,0,0
0,0,0,0,0,0,0,0,0,0,0,0,0,0,0,0,0,0,0
0,0,0,0,0,0,0,0,0,0,0,0,0,0,0,0,0,0,0
0,0,0,0,0,0,0,0,0,0,0,0,0,0,0,0,0,0,0
0,0,0,0,0,0,0,0,0,0,0,0,0,0,0,0,0,0,0
0,0,0,0,0,0,0,0,0,0,0,0,0,0,0,0,0,0,0
0,0,0,0,0,0,0,0,0,0,0,0,0,0,0,0,0,0,0
0,0,0,0,0,0,0,0,0,0,0,0,0,0,0,0,0,0,0
0,0,0,0,0,0,0,0,0,0,0,0,0,0,0,0,0,0,0
0,0,0,0,0,0,0,0,0,0,0,0,0,0,0,0,0,0,0
0,0,0,0,0,0,0,0,0,0,0,0,0,0,0,0,0,0,0
0,0,0,0,0,0,0,0,0,0,0,0,0,0,0,0,0,0,0
0,0,0,0,0,0,0,0,0,0,0,0,0,0,0,0,0,0,0
0,0,0,0,0,0,0,0,0,0,0,0,0,0,0,0,0,0,0
0,0,0,0,0,0,0,0,0,0,0,0,0,0,0,0,0,0,0
0,0,0,0,0,0,0,0,0,0,0,0,0,0,0,0,0,0,0
:endlayer
layer: 46
0,0,0,0,0,0,0,0,0,0,0,0,0,0,0,0,0,0,0
0,0,0,0,0,0,0,0,0,0,0,0,0,0,0,0,0,0,0
0,0,0,0,0,0,0,0,0,0,0,0,0,0,0,0,0,0,0
0,0,0,0,0,0,0,0,0,0,0,0,0,0,0,0,0,0,0
0,0,0,0,0,0,0,0,0,0,0,0,0,0,0,0,0,0,0
0,0,0,0,0,0,0,0,0,0,0,0,0,0,0,0,0,0,0
0,0,0,0,0,0,0,0,0,0,0,0,0,0,0,0,0,0,0
0,0,0,0,0,0,0,0,0,0,0,0,0,0,0,0,0,0,0
0,0,0,0,0,0,0,0,0,0,0,0,0,0,0,0,0,0,0
0,0,0,0,0,0,0,0,0,0,0,0,0,0,0,0,0,0,0
0,0,0,0,0,0,0,0,0,0,0,0,0,0,0,0,0,0,0
0,0,0,0,0,0,0,0,0,0,0,0,0,0,0,0,0,0,0
0,0,0,0,0,0,0,0,0,0,0,0,0,0,0,0,0,0,0
0,0,0,0,0,0,0,0,0,0,0,0,0,0,0,0,0,0,0
0,0,0,0,0,0,0,0,0,0,0,0,0,0,0,0,0,0,0
0,0,0,0,0,0,0,0,0,0,0,0,0,0,0,0,0,0,0
0,0,0,0,0,0,0,0,0,0,0,0,0,0,0,0,0,0,0
0,0,0,0,0,0,0,0,0,0,0,0,0,0,0,0,0,0,0
0,0,0,0,0,0,0,0,0,0,0,0,0,0,0,0,0,0,0
:endlayer
layer: 47
0,0,0,0,0,0,0,0,0,0,0,0,0,0,0,0,0,0,0
0,0,0,0,0,0,0,0,0,0,0,0,0,0,0,0,0,0,0
0,0,0,0,0,0,0,0,0,0,0,0,0,0,0,0,0,0,0
0,0,0,0,0,0,0,0,0,0,0,0,0,0,0,0,0,0,0
0,0,0,0,0,0,0,0,0,0,0,0,0,0,0,0,0,0,0
0,0,0,0,0,0,0,0,0,0,0,0,0,0,0,0,0,0,0
0,0,0,0,0,0,0,0,0,0,0,0,0,0,0,0,0,0,0
0,0,0,0,0,0,0,0,0,0,0,0,0,0,0,0,0,0,0
0,0,0,0,0,0,0,0,0,0,0,0,0,0,0,0,0,0,0
0,0,0,0,0,0,0,0,0,0,0,0,0,0,0,0,0,0,0
0,0,0,0,0,0,0,0,0,0,0,0,0,0,0,0,0,0,0
0,0,0,0,0,0,0,0,0,0,0,0,0,0,0,0,0,0,0
0,0,0,0,0,0,0,0,0,0,0,0,0,0,0,0,0,0,0
0,0,0,0,0,0,0,0,0,0,0,0,0,0,0,0,0,0,0
0,0,0,0,0,0,0,0,0,0,0,0,0,0,0,0,0,0,0
0,0,0,0,0,0,0,0,0,0,0,0,0,0,0,0,0,0,0
0,0,0,0,0,0,0,0,0,0,0,0,0,0,0,0,0,0,0
0,0,0,0,0,0,0,0,0,0,0,0,0,0,0,0,0,0,0
0,0,0,0,0,0,0,0,0,0,0,0,0,0,0,0,0,0,0
:endlayer
layer: 48
0,0,0,0,0,0,0,0,0,0,0,0,0,0,0,0,0,0,0
0,0,0,0,0,0,0,0,0,0,0,0,0,0,0,0,0,0,0
0,0,0,0,0,0,0,0,0,0,0,0,0,0,0,0,0,0,0
0,0,0,0,0,0,0,0,0,0,0,0,0,0,0,0,0,0,0
0,0,0,0,0,0,0,0,0,0,0,0,0,0,0,0,0,0,0
0,0,0,0,0,0,0,0,0,0,0,0,0,0,0,0,0,0,0
0,0,0,0,0,0,0,0,0,0,0,0,0,0,0,0,0,0,0
0,0,0,0,0,0,0,0,0,0,0,0,0,0,0,0,0,0,0
0,0,0,0,0,0,0,0,0,0,0,0,0,0,0,0,0,0,0
0,0,0,0,0,0,0,0,0,0,0,0,0,0,0,0,0,0,0
0,0,0,0,0,0,0,0,0,0,0,0,0,0,0,0,0,0,0
0,0,0,0,0,0,0,0,0,0,0,0,0,0,0,0,0,0,0
0,0,0,0,0,0,0,0,0,0,0,0,0,0,0,0,0,0,0
0,0,0,0,0,0,0,0,0,0,0,0,0,0,0,0,0,0,0
0,0,0,0,0,0,0,0,0,0,0,0,0,0,0,0,0,0,0
0,0,0,0,0,0,0,0,0,0,0,0,0,0,0,0,0,0,0
0,0,0,0,0,0,0,0,0,0,0,0,0,0,0,0,0,0,0
0,0,0,0,0,0,0,0,0,0,0,0,0,0,0,0,0,0,0
0,0,0,0,0,0,0,0,0,0,0,0,0,0,0,0,0,0,0
:endlayer
layer: 49
0,0,0,0,0,0,0,0,0,0,0,0,0,0,0,0,0,0,0
0,0,0,0,0,0,0,0,0,0,0,0,0,0,0,0,0,0,0
0,0,0,0,0,0,0,0,0,0,0,0,0,0,0,0,0,0,0
0,0,0,0,0,0,0,0,0,0,0,0,0,0,0,0,0,0,0
0,0,0,0,0,0,0,0,0,0,0,0,0,0,0,0,0,0,0
0,0,0,0,0,0,0,0,0,0,0,0,0,0,0,0,0,0,0
0,0,0,0,0,0,0,0,0,0,0,0,0,0,0,0,0,0,0
0,0,0,0,0,0,0,0,0,0,0,0,0,0,0,0,0,0,0
0,0,0,0,0,0,0,0,0,0,0,0,0,0,0,0,0,0,0
0,0,0,0,0,0,0,0,0,0,0,0,0,0,0,0,0,0,0
0,0,0,0,0,0,0,0,0,0,0,0,0,0,0,0,0,0,0
0,0,0,0,0,0,0,0,0,0,0,0,0,0,0,0,0,0,0
0,0,0,0,0,0,0,0,0,0,0,0,0,0,0,0,0,0,0
0,0,0,0,0,0,0,0,0,0,0,0,0,0,0,0,0,0,0
0,0,0,0,0,0,0,0,0,0,0,0,0,0,0,0,0,0,0
0,0,0,0,0,0,0,0,0,0,0,0,0,0,0,0,0,0,0
0,0,0,0,0,0,0,0,0,0,0,0,0,0,0,0,0,0,0
0,0,0,0,0,0,0,0,0,0,0,0,0,0,0,0,0,0,0
0,0,0,0,0,0,0,0,0,0,0,0,0,0,0,0,0,0,0
:endlayer
layer: 50
0,0,0,0,0,0,0,0,0,0,0,0,0,0,0,0,0,0,0
0,0,0,0,0,0,0,0,0,0,0,0,0,0,0,0,0,0,0
0,0,0,0,0,0,0,0,0,0,0,0,0,0,0,0,0,0,0
0,0,0,0,0,0,0,0,0,0,0,0,0,0,0,0,0,0,0
0,0,0,0,0,0,0,0,0,0,0,0,0,0,0,0,0,0,0
0,0,0,0,0,0,0,0,0,0,0,0,0,0,0,0,0,0,0
0,0,0,0,0,0,0,0,0,0,0,0,0,0,0,0,0,0,0
0,0,0,0,0,0,0,0,0,0,0,0,0,0,0,0,0,0,0
0,0,0,0,0,0,0,0,0,0,0,0,0,0,0,0,0,0,0
0,0,0,0,0,0,0,0,0,0,0,0,0,0,0,0,0,0,0
0,0,0,0,0,0,0,0,0,0,0,0,0,0,0,0,0,0,0
0,0,0,0,0,0,0,0,0,0,0,0,0,0,0,0,0,0,0
0,0,0,0,0,0,0,0,0,0,0,0,0,0,0,0,0,0,0
0,0,0,0,0,0,0,0,0,0,0,0,0,0,0,0,0,0,0
0,0,0,0,0,0,0,0,0,0,0,0,0,0,0,0,0,0,0
0,0,0,0,0,0,0,0,0,0,0,0,0,0,0,0,0,0,0
0,0,0,0,0,0,0,0,0,0,0,0,0,0,0,0,0,0,0
0,0,0,0,0,0,0,0,0,0,0,0,0,0,0,0,0,0,0
0,0,0,0,0,0,0,0,0,0,0,0,0,0,0,0,0,0,0
:endlayer
layer: 51
0,0,0,0,0,0,0,0,0,0,0,0,0,0,0,0,0,0,0
0,0,0,0,0,0,0,0,0,0,0,0,0,0,0,0,0,0,0
0,0,0,0,0,0,0,0,0,0,0,0,0,0,0,0,0,0,0
0,0,0,0,0,0,0,0,0,0,0,0,0,0,0,0,0,0,0
0,0,0,0,0,0,0,0,0,0,0,0,0,0,0,0,0,0,0
0,0,0,0,0,0,0,0,0,0,0,0,0,0,0,0,0,0,0
0,0,0,0,0,0,0,0,0,0,0,0,0,0,0,0,0,0,0
0,0,0,0,0,0,0,0,0,0,0,0,0,0,0,0,0,0,0
0,0,0,0,0,0,0,0,0,0,0,0,0,0,0,0,0,0,0
0,0,0,0,0,0,0,0,0,0,0,0,0,0,0,0,0,0,0
0,0,0,0,0,0,0,0,0,0,0,0,0,0,0,0,0,0,0
0,0,0,0,0,0,0,0,0,0,0,0,0,0,0,0,0,0,0
0,0,0,0,0,0,0,0,0,0,0,0,0,0,0,0,0,0,0
0,0,0,0,0,0,0,0,0,0,0,0,0,0,0,0,0,0,0
0,0,0,0,0,0,0,0,0,0,0,0,0,0,0,0,0,0,0
0,0,0,0,0,0,0,0,0,0,0,0,0,0,0,0,0,0,0
0,0,0,0,0,0,0,0,0,0,0,0,0,0,0,0,0,0,0
0,0,0,0,0,0,0,0,0,0,0,0,0,0,0,0,0,0,0
0,0,0,0,0,0,0,0,0,0,0,0,0,0,0,0,0,0,0
:endlayer
layer: 52
0,0,0,0,0,0,0,0,0,0,0,0,0,0,0,0,0,0,0
0,0,0,0,0,0,0,0,0,0,0,0,0,0,0,0,0,0,0
0,0,0,0,0,0,0,0,0,0,0,0,0,0,0,0,0,0,0
0,0,0,0,0,0,0,0,0,0,0,0,0,0,0,0,0,0,0
0,0,0,0,0,0,0,0,0,0,0,0,0,0,0,0,0,0,0
0,0,0,0,0,0,0,0,0,0,0,0,0,0,0,0,0,0,0
0,0,0,0,0,0,0,0,0,0,0,0,0,0,0,0,0,0,0
0,0,0,0,0,0,0,0,0,0,0,0,0,0,0,0,0,0,0
0,0,0,0,0,0,0,0,0,0,0,0,0,0,0,0,0,0,0
0,0,0,0,0,0,0,0,0,0,0,0,0,0,0,0,0,0,0
0,0,0,0,0,0,0,0,0,0,0,0,0,0,0,0,0,0,0
0,0,0,0,0,0,0,0,0,0,0,0,0,0,0,0,0,0,0
0,0,0,0,0,0,0,0,0,0,0,0,0,0,0,0,0,0,0
0,0,0,0,0,0,0,0,0,0,0,0,0,0,0,0,0,0,0
0,0,0,0,0,0,0,0,0,0,0,0,0,0,0,0,0,0,0
0,0,0,0,0,0,0,0,0,0,0,0,0,0,0,0,0,0,0
0,0,0,0,0,0,0,0,0,0,0,0,0,0,0,0,0,0,0
0,0,0,0,0,0,0,0,0,0,0,0,0,0,0,0,0,0,0
0,0,0,0,0,0,0,0,0,0,0,0,0,0,0,0,0,0,0
:endlayer
layer: 53
0,0,0,0,0,0,0,0,0,0,0,0,0,0,0,0,0,0,0
0,0,0,0,0,0,0,0,0,0,0,0,0,0,0,0,0,0,0
0,0,0,0,0,0,0,0,0,0,0,0,0,0,0,0,0,0,0
0,0,0,0,0,0,0,0,0,0,0,0,0,0,0,0,0,0,0
0,0,0,0,0,0,0,0,0,0,0,0,0,0,0,0,0,0,0
0,0,0,0,0,0,0,0,0,0,0,0,0,0,0,0,0,0,0
0,0,0,0,0,0,0,0,0,0,0,0,0,0,0,0,0,0,0
0,0,0,0,0,0,0,0,0,0,0,0,0,0,0,0,0,0,0
0,0,0,0,0,0,0,0,0,0,0,0,0,0,0,0,0,0,0
0,0,0,0,0,0,0,0,0,0,0,0,0,0,0,0,0,0,0
0,0,0,0,0,0,0,0,0,0,0,0,0,0,0,0,0,0,0
0,0,0,0,0,0,0,0,0,0,0,0,0,0,0,0,0,0,0
0,0,0,0,0,0,0,0,0,0,0,0,0,0,0,0,0,0,0
0,0,0,0,0,0,0,0,0,0,0,0,0,0,0,0,0,0,0
0,0,0,0,0,0,0,0,0,0,0,0,0,0,0,0,0,0,0
0,0,0,0,0,0,0,0,0,0,0,0,0,0,0,0,0,0,0
0,0,0,0,0,0,0,0,0,0,0,0,0,0,0,0,0,0,0
0,0,0,0,0,0,0,0,0,0,0,0,0,0,0,0,0,0,0
0,0,0,0,0,0,0,0,0,0,0,0,0,0,0,0,0,0,0
:endlayer
layer: 54
0,0,0,0,0,0,0,0,0,0,0,0,0,0,0,0,0,0,0
0,0,0,0,0,0,0,0,0,0,0,0,0,0,0,0,0,0,0
0,0,0,0,0,0,0,0,0,0,0,0,0,0,0,0,0,0,0
0,0,0,0,0,0,0,0,0,0,0,0,0,0,0,0,0,0,0
0,0,0,0,0,0,0,0,0,0,0,0,0,0,0,0,0,0,0
0,0,0,0,0,0,0,0,0,0,0,0,0,0,0,0,0,0,0
0,0,0,0,0,0,0,0,0,0,0,0,0,0,0,0,0,0,0
0,0,0,0,0,0,0,0,0,0,0,0,0,0,0,0,0,0,0
0,0,0,0,0,0,0,0,0,0,0,0,0,0,0,0,0,0,0
0,0,0,0,0,0,0,0,0,0,0,0,0,0,0,0,0,0,0
0,0,0,0,0,0,0,0,0,0,0,0,0,0,0,0,0,0,0
0,0,0,0,0,0,0,0,0,0,0,0,0,0,0,0,0,0,0
0,0,0,0,0,0,0,0,0,0,0,0,0,0,0,0,0,0,0
0,0,0,0,0,0,0,0,0,0,0,0,0,0,0,0,0,0,0
0,0,0,0,0,0,0,0,0,0,0,0,0,0,0,0,0,0,0
0,0,0,0,0,0,0,0,0,0,0,0,0,0,0,0,0,0,0
0,0,0,0,0,0,0,0,0,0,0,0,0,0,0,0,0,0,0
0,0,0,0,0,0,0,0,0,0,0,0,0,0,0,0,0,0,0
0,0,0,0,0,0,0,0,0,0,0,0,0,0,0,0,0,0,0
:endlayer
layer: 55
0,0,0,0,0,0,0,0,0,0,0,0,0,0,0,0,0,0,0
0,0,0,0,0,0,0,0,0,0,0,0,0,0,0,0,0,0,0
0,0,0,0,0,0,0,0,0,0,0,0,0,0,0,0,0,0,0
0,0,0,0,0,0,0,0,0,0,0,0,0,0,0,0,0,0,0
0,0,0,0,0,0,0,0,0,0,0,0,0,0,0,0,0,0,0
0,0,0,0,0,0,0,0,0,0,0,0,0,0,0,0,0,0,0
0,0,0,0,0,0,0,0,0,0,0,0,0,0,0,0,0,0,0
0,0,0,0,0,0,0,0,0,0,0,0,0,0,0,0,0,0,0
0,0,0,0,0,0,0,0,0,0,0,0,0,0,0,0,0,0,0
0,0,0,0,0,0,0,0,0,0,0,0,0,0,0,0,0,0,0
0,0,0,0,0,0,0,0,0,0,0,0,0,0,0,0,0,0,0
0,0,0,0,0,0,0,0,0,0,0,0,0,0,0,0,0,0,0
0,0,0,0,0,0,0,0,0,0,0,0,0,0,0,0,0,0,0
0,0,0,0,0,0,0,0,0,0,0,0,0,0,0,0,0,0,0
0,0,0,0,0,0,0,0,0,0,0,0,0,0,0,0,0,0,0
0,0,0,0,0,0,0,0,0,0,0,0,0,0,0,0,0,0,0
0,0,0,0,0,0,0,0,0,0,0,0,0,0,0,0,0,0,0
0,0,0,0,0,0,0,0,0,0,0,0,0,0,0,0,0,0,0
0,0,0,0,0,0,0,0,0,0,0,0,0,0,0,0,0,0,0
:endlayer
layer: 56
0,0,0,0,0,0,0,0,0,0,0,0,0,0,0,0,0,0,0
0,0,0,0,0,0,0,0,0,0,0,0,0,0,0,0,0,0,0
0,0,0,0,0,0,0,0,0,0,0,0,0,0,0,0,0,0,0
0,0,0,0,0,0,0,0,0,0,0,0,0,0,0,0,0,0,0
0,0,0,0,0,0,0,0,0,0,0,0,0,0,0,0,0,0,0
0,0,0,0,0,0,0,0,0,0,0,0,0,0,0,0,0,0,0
0,0,0,0,0,0,0,0,0,0,0,0,0,0,0,0,0,0,0
0,0,0,0,0,0,0,0,0,0,0,0,0,0,0,0,0,0,0
0,0,0,0,0,0,0,0,0,0,0,0,0,0,0,0,0,0,0
0,0,0,0,0,0,0,0,0,0,0,0,0,0,0,0,0,0,0
0,0,0,0,0,0,0,0,0,0,0,0,0,0,0,0,0,0,0
0,0,0,0,0,0,0,0,0,0,0,0,0,0,0,0,0,0,0
0,0,0,0,0,0,0,0,0,0,0,0,0,0,0,0,0,0,0
0,0,0,0,0,0,0,0,0,0,0,0,0,0,0,0,0,0,0
0,0,0,0,0,0,0,0,0,0,0,0,0,0,0,0,0,0,0
0,0,0,0,0,0,0,0,0,0,0,0,0,0,0,0,0,0,0
0,0,0,0,0,0,0,0,0,0,0,0,0,0,0,0,0,0,0
0,0,0,0,0,0,0,0,0,0,0,0,0,0,0,0,0,0,0
0,0,0,0,0,0,0,0,0,0,0,0,0,0,0,0,0,0,0
:endlayer
layer: 57
0,0,0,0,0,0,0,0,0,0,0,0,0,0,0,0,0,0,0
0,0,0,0,0,0,0,0,0,0,0,0,0,0,0,0,0,0,0
0,0,0,0,0,0,0,0,0,0,0,0,0,0,0,0,0,0,0
0,0,0,0,0,0,0,0,0,0,0,0,0,0,0,0,0,0,0
0,0,0,0,0,0,0,0,0,0,0,0,0,0,0,0,0,0,0
0,0,0,0,0,0,0,0,0,0,0,0,0,0,0,0,0,0,0
0,0,0,0,0,0,0,0,0,0,0,0,0,0,0,0,0,0,0
0,0,0,0,0,0,0,0,0,0,0,0,0,0,0,0,0,0,0
0,0,0,0,0,0,0,0,0,0,0,0,0,0,0,0,0,0,0
0,0,0,0,0,0,0,0,0,0,0,0,0,0,0,0,0,0,0
0,0,0,0,0,0,0,0,0,0,0,0,0,0,0,0,0,0,0
0,0,0,0,0,0,0,0,0,0,0,0,0,0,0,0,0,0,0
0,0,0,0,0,0,0,0,0,0,0,0,0,0,0,0,0,0,0
0,0,0,0,0,0,0,0,0,0,0,0,0,0,0,0,0,0,0
0,0,0,0,0,0,0,0,0,0,0,0,0,0,0,0,0,0,0
0,0,0,0,0,0,0,0,0,0,0,0,0,0,0,0,0,0,0
0,0,0,0,0,0,0,0,0,0,0,0,0,0,0,0,0,0,0
0,0,0,0,0,0,0,0,0,0,0,0,0,0,0,0,0,0,0
0,0,0,0,0,0,0,0,0,0,0,0,0,0,0,0,0,0,0
:endlayer
layer: 58
0,0,0,0,0,0,0,0,0,0,0,0,0,0,0,0,0,0,0
0,0,0,0,0,0,0,0,0,0,0,0,0,0,0,0,0,0,0
0,0,0,0,0,0,0,0,0,0,0,0,0,0,0,0,0,0,0
0,0,0,0,0,0,0,0,0,0,0,0,0,0,0,0,0,0,0
0,0,0,0,0,0,0,0,0,0,0,0,0,0,0,0,0,0,0
0,0,0,0,0,0,0,0,0,0,0,0,0,0,0,0,0,0,0
0,0,0,0,0,0,0,0,0,0,0,0,0,0,0,0,0,0,0
0,0,0,0,0,0,0,0,0,0,0,0,0,0,0,0,0,0,0
0,0,0,0,0,0,0,0,0,0,0,0,0,0,0,0,0,0,0
0,0,0,0,0,0,0,0,0,0,0,0,0,0,0,0,0,0,0
0,0,0,0,0,0,0,0,0,0,0,0,0,0,0,0,0,0,0
0,0,0,0,0,0,0,0,0,0,0,0,0,0,0,0,0,0,0
0,0,0,0,0,0,0,0,0,0,0,0,0,0,0,0,0,0,0
0,0,0,0,0,0,0,0,0,0,0,0,0,0,0,0,0,0,0
0,0,0,0,0,0,0,0,0,0,0,0,0,0,0,0,0,0,0
0,0,0,0,0,0,0,0,0,0,0,0,0,0,0,0,0,0,0
0,0,0,0,0,0,0,0,0,0,0,0,0,0,0,0,0,0,0
0,0,0,0,0,0,0,0,0,0,0,0,0,0,0,0,0,0,0
0,0,0,0,0,0,0,0,0,0,0,0,0,0,0,0,0,0,0
:endlayer
layer: 59
0,0,0,0,0,0,0,0,0,0,0,0,0,0,0,0,0,0,0
0,0,0,0,0,0,0,0,0,0,0,0,0,0,0,0,0,0,0
0,0,0,0,0,0,0,0,0,0,0,0,0,0,0,0,0,0,0
0,0,0,0,0,0,0,0,0,0,0,0,0,0,0,0,0,0,0
0,0,0,0,0,0,0,0,0,0,0,0,0,0,0,0,0,0,0
0,0,0,0,0,0,0,0,0,0,0,0,0,0,0,0,0,0,0
0,0,0,0,0,0,0,0,0,0,0,0,0,0,0,0,0,0,0
0,0,0,0,0,0,0,0,0,0,0,0,0,0,0,0,0,0,0
0,0,0,0,0,0,0,0,0,0,0,0,0,0,0,0,0,0,0
0,0,0,0,0,0,0,0,0,0,0,0,0,0,0,0,0,0,0
0,0,0,0,0,0,0,0,0,0,0,0,0,0,0,0,0,0,0
0,0,0,0,0,0,0,0,0,0,0,0,0,0,0,0,0,0,0
0,0,0,0,0,0,0,0,0,0,0,0,0,0,0,0,0,0,0
0,0,0,0,0,0,0,0,0,0,0,0,0,0,0,0,0,0,0
0,0,0,0,0,0,0,0,0,0,0,0,0,0,0,0,0,0,0
0,0,0,0,0,0,0,0,0,0,0,0,0,0,0,0,0,0,0
0,0,0,0,0,0,0,0,0,0,0,0,0,0,0,0,0,0,0
0,0,0,0,0,0,0,0,0,0,0,0,0,0,0,0,0,0,0
0,0,0,0,0,0,0,0,0,0,0,0,0,0,0,0,0,0,0
:endlayer
layer: 60
0,0,0,0,0,0,0,0,0,0,0,0,0,0,0,0,0,0,0
0,0,0,0,0,0,0,0,0,0,0,0,0,0,0,0,0,0,0
0,0,0,0,0,0,0,0,0,0,0,0,0,0,0,0,0,0,0
0,0,0,0,0,0,0,0,0,0,0,0,0,0,0,0,0,0,0
0,0,0,0,0,0,0,0,0,0,0,0,0,0,0,0,0,0,0
0,0,0,0,0,0,0,0,0,0,0,0,0,0,0,0,0,0,0
0,0,0,0,0,0,0,0,0,0,0,0,0,0,0,0,0,0,0
0,0,0,0,0,0,0,0,0,0,0,0,0,0,0,0,0,0,0
0,0,0,0,0,0,0,0,0,0,0,0,0,0,0,0,0,0,0
0,0,0,0,0,0,0,0,0,0,0,0,0,0,0,0,0,0,0
0,0,0,0,0,0,0,0,0,0,0,0,0,0,0,0,0,0,0
0,0,0,0,0,0,0,0,0,0,0,0,0,0,0,0,0,0,0
0,0,0,0,0,0,0,0,0,0,0,0,0,0,0,0,0,0,0
0,0,0,0,0,0,0,0,0,0,0,0,0,0,0,0,0,0,0
0,0,0,0,0,0,0,0,0,0,0,0,0,0,0,0,0,0,0
0,0,0,0,0,0,0,0,0,0,0,0,0,0,0,0,0,0,0
0,0,0,0,0,0,0,0,0,0,0,0,0,0,0,0,0,0,0
0,0,0,0,0,0,0,0,0,0,0,0,0,0,0,0,0,0,0
0,0,0,0,0,0,0,0,0,0,0,0,0,0,0,0,0,0,0
:endlayer
layer: 61
0,0,0,0,0,0,0,0,0,0,0,0,0,0,0,0,0,0,0
0,0,0,0,0,0,0,0,0,0,0,0,0,0,0,0,0,0,0
0,0,0,0,0,0,0,0,0,0,0,0,0,0,0,0,0,0,0
0,0,0,0,0,0,0,0,0,0,0,0,0,0,0,0,0,0,0
0,0,0,0,0,0,0,0,0,0,0,0,0,0,0,0,0,0,0
0,0,0,0,0,0,0,0,0,0,0,0,0,0,0,0,0,0,0
0,0,0,0,0,0,0,0,0,0,0,0,0,0,0,0,0,0,0
0,0,0,0,0,0,0,0,0,0,0,0,0,0,0,0,0,0,0
0,0,0,0,0,0,0,0,0,0,0,0,0,0,0,0,0,0,0
0,0,0,0,0,0,0,0,0,0,0,0,0,0,0,0,0,0,0
0,0,0,0,0,0,0,0,0,0,0,0,0,0,0,0,0,0,0
0,0,0,0,0,0,0,0,0,0,0,0,0,0,0,0,0,0,0
0,0,0,0,0,0,0,0,0,0,0,0,0,0,0,0,0,0,0
0,0,0,0,0,0,0,0,0,0,0,0,0,0,0,0,0,0,0
0,0,0,0,0,0,0,0,0,0,0,0,0,0,0,0,0,0,0
0,0,0,0,0,0,0,0,0,0,0,0,0,0,0,0,0,0,0
0,0,0,0,0,0,0,0,0,0,0,0,0,0,0,0,0,0,0
0,0,0,0,0,0,0,0,0,0,0,0,0,0,0,0,0,0,0
0,0,0,0,0,0,0,0,0,0,0,0,0,0,0,0,0,0,0
:endlayer

#### RULES ####
rule:
plugin=vanillaBlocks
number=1
data:
JSON:{{"val":{"blockName":{"val":"minecraft:dirt","id":"ss"},"meta":{"val":"0","id":"pi"},"buildPass":{"val":"0","id":"pi"}},"id":"ct"}}
:enddata
:endrule

rule:
plugin=vanillaBlocks
number=2
data:
JSON:{{"val":{"blockName":{"val":"minecraft:cobblestone","id":"ss"},"meta":{"val":"0","id":"pi"},"buildPass":{"val":"0","id":"pi"}},"id":"ct"}}
:enddata
:endrule

rule:
plugin=vanillaBlocks
number=3
data:
JSON:{{"val":{"blockName":{"val":"minecraft:grass","id":"ss"},"meta":{"val":"0","id":"pi"},"buildPass":{"val":"0","id":"pi"}},"id":"ct"}}
:enddata
:endrule

rule:
plugin=vanillaBlocks
number=4
data:
JSON:{{"val":{"blockName":{"val":"minecraft:double_stone_slab","id":"ss"},"meta":{"val":"0","id":"pi"},"buildPass":{"val":"0","id":"pi"}},"id":"ct"}}
:enddata
:endrule

rule:
plugin=vanillaBlocks
number=5
data:
JSON:{{"val":{"blockName":{"val":"minecraft:tallgrass","id":"ss"},"meta":{"val":"1","id":"pi"},"buildPass":{"val":"2","id":"pi"}},"id":"ct"}}
:enddata
:endrule

rule:
plugin=vanillaBlocks
number=6
data:
JSON:{{"val":{"blockName":{"val":"minecraft:fence","id":"ss"},"meta":{"val":"0","id":"pi"},"buildPass":{"val":"0","id":"pi"}},"id":"ct"}}
:enddata
:endrule

rule:
plugin=vanillaBlocks
number=7
data:
JSON:{{"val":{"blockName":{"val":"minecraft:fence_gate","id":"ss"},"meta":{"val":"0","id":"pi"},"buildPass":{"val":"0","id":"pi"}},"id":"ct"}}
:enddata
:endrule

rule:
plugin=vanillaBlocks
number=8
data:
JSON:{{"val":{"blockName":{"val":"minecraft:stonebrick","id":"ss"},"meta":{"val":"0","id":"pi"},"buildPass":{"val":"0","id":"pi"}},"id":"ct"}}
:enddata
:endrule

rule:
plugin=vanillaDoors
number=9
data:
JSON:{{"val":{"sideFlag":{"val":"8","id":"pb"},"blockName":{"val":"minecraft:wooden_door","id":"ss"},"meta":{"val":"1","id":"pi"},"buildPass":{"val":"2","id":"pi"}},"id":"ct"}}
:enddata
:endrule

rule:
plugin=vanillaBlocks
number=10
data:
JSON:{{"val":{"blockName":{"val":"minecraft:stone_brick_stairs","id":"ss"},"meta":{"val":"2","id":"pi"},"buildPass":{"val":"0","id":"pi"}},"id":"ct"}}
:enddata
:endrule

rule:
plugin=vanillaBlocks
number=11
data:
JSON:{{"val":{"blockName":{"val":"minecraft:stone_stairs","id":"ss"},"meta":{"val":"1","id":"pi"},"buildPass":{"val":"0","id":"pi"}},"id":"ct"}}
:enddata
:endrule

rule:
plugin=vanillaBlocks
number=12
data:
JSON:{{"val":{"blockName":{"val":"minecraft:stone_brick_stairs","id":"ss"},"meta":{"val":"0","id":"pi"},"buildPass":{"val":"0","id":"pi"}},"id":"ct"}}
:enddata
:endrule

rule:
plugin=vanillaInventory
number=13
data:
JSON:{{"val":{"lootLevel":{"val":"0","id":"pi"},"inventoryData":{"val":{"length":{"val":"27","id":"pi"},"inventoryContents":{"val":[{"val":{"item":{"val":"minecraft:wheat","id":"ss"},"damage":{"val":"0","id":"pi"},"quantity":{"val":"1","id":"pi"},"slot":{"val":"0","id":"pi"}},"id":"ct"},{"val":{"item":{"val":"minecraft:wheat","id":"ss"},"damage":{"val":"0","id":"pi"},"quantity":{"val":"1","id":"pi"},"slot":{"val":"1","id":"pi"}},"id":"ct"},{"val":{"item":{"val":"minecraft:wheat","id":"ss"},"damage":{"val":"0","id":"pi"},"quantity":{"val":"1","id":"pi"},"slot":{"val":"2","id":"pi"}},"id":"ct"},{"val":{"item":{"val":"minecraft:wheat","id":"ss"},"damage":{"val":"0","id":"pi"},"quantity":{"val":"1","id":"pi"},"slot":{"val":"3","id":"pi"}},"id":"ct"},{"val":{"item":{"val":"minecraft:wheat","id":"ss"},"damage":{"val":"0","id":"pi"},"quantity":{"val":"1","id":"pi"},"slot":{"val":"4","id":"pi"}},"id":"ct"},{"val":{"item":{"val":"minecraft:wheat","id":"ss"},"damage":{"val":"0","id":"pi"},"quantity":{"val":"1","id":"pi"},"slot":{"val":"5","id":"pi"}},"id":"ct"},{"val":{"item":{"val":"minecraft:wheat","id":"ss"},"damage":{"val":"0","id":"pi"},"quantity":{"val":"1","id":"pi"},"slot":{"val":"6","id":"pi"}},"id":"ct"},{"val":{"item":{"val":"minecraft:wheat","id":"ss"},"damage":{"val":"0","id":"pi"},"quantity":{"val":"1","id":"pi"},"slot":{"val":"7","id":"pi"}},"id":"ct"},{"val":{"item":{"val":"minecraft:wheat","id":"ss"},"damage":{"val":"0","id":"pi"},"quantity":{"val":"1","id":"pi"},"slot":{"val":"8","id":"pi"}},"id":"ct"},{"val":{"item":{"val":"minecraft:wheat","id":"ss"},"damage":{"val":"0","id":"pi"},"quantity":{"val":"1","id":"pi"},"slot":{"val":"9","id":"pi"}},"id":"ct"},{"val":{"item":{"val":"minecraft:wheat","id":"ss"},"damage":{"val":"0","id":"pi"},"quantity":{"val":"1","id":"pi"},"slot":{"val":"10","id":"pi"}},"id":"ct"},{"val":{"item":{"val":"minecraft:wheat","id":"ss"},"damage":{"val":"0","id":"pi"},"quantity":{"val":"1","id":"pi"},"slot":{"val":"11","id":"pi"}},"id":"ct"},{"val":{"item":{"val":"minecraft:wheat","id":"ss"},"damage":{"val":"0","id":"pi"},"quantity":{"val":"1","id":"pi"},"slot":{"val":"12","id":"pi"}},"id":"ct"},{"val":{"item":{"val":"minecraft:wheat","id":"ss"},"damage":{"val":"0","id":"pi"},"quantity":{"val":"1","id":"pi"},"slot":{"val":"13","id":"pi"}},"id":"ct"},{"val":{"item":{"val":"minecraft:wheat","id":"ss"},"damage":{"val":"0","id":"pi"},"quantity":{"val":"1","id":"pi"},"slot":{"val":"14","id":"pi"}},"id":"ct"},{"val":{"item":{"val":"minecraft:wheat","id":"ss"},"damage":{"val":"0","id":"pi"},"quantity":{"val":"1","id":"pi"},"slot":{"val":"15","id":"pi"}},"id":"ct"},{"val":{"item":{"val":"minecraft:wheat","id":"ss"},"damage":{"val":"0","id":"pi"},"quantity":{"val":"1","id":"pi"},"slot":{"val":"16","id":"pi"}},"id":"ct"},{"val":{"item":{"val":"minecraft:wheat","id":"ss"},"damage":{"val":"0","id":"pi"},"quantity":{"val":"1","id":"pi"},"slot":{"val":"17","id":"pi"}},"id":"ct"},{"val":{"item":{"val":"minecraft:wheat","id":"ss"},"damage":{"val":"0","id":"pi"},"quantity":{"val":"1","id":"pi"},"slot":{"val":"18","id":"pi"}},"id":"ct"},{"val":{"item":{"val":"minecraft:wheat","id":"ss"},"damage":{"val":"0","id":"pi"},"quantity":{"val":"1","id":"pi"},"slot":{"val":"19","id":"pi"}},"id":"ct"},{"val":{"item":{"val":"minecraft:wheat","id":"ss"},"damage":{"val":"0","id":"pi"},"quantity":{"val":"1","id":"pi"},"slot":{"val":"20","id":"pi"}},"id":"ct"},{"val":{"item":{"val":"minecraft:wheat","id":"ss"},"damage":{"val":"0","id":"pi"},"quantity":{"val":"1","id":"pi"},"slot":{"val":"21","id":"pi"}},"id":"ct"},{"val":{"item":{"val":"minecraft:wheat","id":"ss"},"damage":{"val":"0","id":"pi"},"quantity":{"val":"1","id":"pi"},"slot":{"val":"22","id":"pi"}},"id":"ct"},{"val":{"item":{"val":"minecraft:wheat","id":"ss"},"damage":{"val":"0","id":"pi"},"quantity":{"val":"1","id":"pi"},"slot":{"val":"23","id":"pi"}},"id":"ct"},{"val":{"item":{"val":"minecraft:wheat","id":"ss"},"damage":{"val":"0","id":"pi"},"quantity":{"val":"1","id":"pi"},"slot":{"val":"24","id":"pi"}},"id":"ct"},{"val":{"item":{"val":"minecraft:wheat","id":"ss"},"damage":{"val":"0","id":"pi"},"quantity":{"val":"1","id":"pi"},"slot":{"val":"25","id":"pi"}},"id":"ct"},{"val":{"item":{"val":"minecraft:wheat","id":"ss"},"damage":{"val":"0","id":"pi"},"quantity":{"val":"1","id":"pi"},"slot":{"val":"26","id":"pi"}},"id":"ct"}],"id":"ls"}},"id":"ct"},"teData":{"val":{"id":{"val":"Chest","id":"ss"},"z":{"val":"970","id":"pi"},"y":{"val":"73","id":"pi"},"x":{"val":"1531","id":"pi"}},"id":"ct"},"blockName":{"val":"minecraft:chest","id":"ss"},"meta":{"val":"5","id":"pi"},"buildPass":{"val":"0","id":"pi"}},"id":"ct"}}
:enddata
:endrule

rule:
plugin=vanillaInventory
number=14
data:
JSON:{{"val":{"lootLevel":{"val":"0","id":"pi"},"inventoryData":{"val":{"length":{"val":"27","id":"pi"},"inventoryContents":{"val":[{"val":{"item":{"val":"minecraft:wheat","id":"ss"},"damage":{"val":"0","id":"pi"},"quantity":{"val":"1","id":"pi"},"slot":{"val":"0","id":"pi"}},"id":"ct"},{"val":{"item":{"val":"minecraft:wheat","id":"ss"},"damage":{"val":"0","id":"pi"},"quantity":{"val":"1","id":"pi"},"slot":{"val":"1","id":"pi"}},"id":"ct"},{"val":{"item":{"val":"minecraft:wheat","id":"ss"},"damage":{"val":"0","id":"pi"},"quantity":{"val":"1","id":"pi"},"slot":{"val":"2","id":"pi"}},"id":"ct"},{"val":{"item":{"val":"minecraft:wheat","id":"ss"},"damage":{"val":"0","id":"pi"},"quantity":{"val":"1","id":"pi"},"slot":{"val":"3","id":"pi"}},"id":"ct"},{"val":{"item":{"val":"minecraft:wheat","id":"ss"},"damage":{"val":"0","id":"pi"},"quantity":{"val":"1","id":"pi"},"slot":{"val":"4","id":"pi"}},"id":"ct"},{"val":{"item":{"val":"minecraft:wheat","id":"ss"},"damage":{"val":"0","id":"pi"},"quantity":{"val":"1","id":"pi"},"slot":{"val":"5","id":"pi"}},"id":"ct"},{"val":{"item":{"val":"minecraft:wheat","id":"ss"},"damage":{"val":"0","id":"pi"},"quantity":{"val":"1","id":"pi"},"slot":{"val":"6","id":"pi"}},"id":"ct"},{"val":{"item":{"val":"minecraft:wheat","id":"ss"},"damage":{"val":"0","id":"pi"},"quantity":{"val":"1","id":"pi"},"slot":{"val":"7","id":"pi"}},"id":"ct"},{"val":{"item":{"val":"minecraft:wheat","id":"ss"},"damage":{"val":"0","id":"pi"},"quantity":{"val":"1","id":"pi"},"slot":{"val":"8","id":"pi"}},"id":"ct"},{"val":{"item":{"val":"minecraft:wheat","id":"ss"},"damage":{"val":"0","id":"pi"},"quantity":{"val":"1","id":"pi"},"slot":{"val":"9","id":"pi"}},"id":"ct"},{"val":{"item":{"val":"minecraft:wheat","id":"ss"},"damage":{"val":"0","id":"pi"},"quantity":{"val":"1","id":"pi"},"slot":{"val":"10","id":"pi"}},"id":"ct"},{"val":{"item":{"val":"minecraft:wheat","id":"ss"},"damage":{"val":"0","id":"pi"},"quantity":{"val":"1","id":"pi"},"slot":{"val":"11","id":"pi"}},"id":"ct"},{"val":{"item":{"val":"minecraft:wheat","id":"ss"},"damage":{"val":"0","id":"pi"},"quantity":{"val":"1","id":"pi"},"slot":{"val":"12","id":"pi"}},"id":"ct"},{"val":{"item":{"val":"minecraft:wheat","id":"ss"},"damage":{"val":"0","id":"pi"},"quantity":{"val":"1","id":"pi"},"slot":{"val":"13","id":"pi"}},"id":"ct"},{"val":{"item":{"val":"minecraft:wheat","id":"ss"},"damage":{"val":"0","id":"pi"},"quantity":{"val":"1","id":"pi"},"slot":{"val":"14","id":"pi"}},"id":"ct"},{"val":{"item":{"val":"minecraft:wheat","id":"ss"},"damage":{"val":"0","id":"pi"},"quantity":{"val":"1","id":"pi"},"slot":{"val":"15","id":"pi"}},"id":"ct"},{"val":{"item":{"val":"minecraft:wheat","id":"ss"},"damage":{"val":"0","id":"pi"},"quantity":{"val":"1","id":"pi"},"slot":{"val":"16","id":"pi"}},"id":"ct"},{"val":{"item":{"val":"minecraft:wheat","id":"ss"},"damage":{"val":"0","id":"pi"},"quantity":{"val":"1","id":"pi"},"slot":{"val":"17","id":"pi"}},"id":"ct"},{"val":{"item":{"val":"minecraft:wheat","id":"ss"},"damage":{"val":"0","id":"pi"},"quantity":{"val":"1","id":"pi"},"slot":{"val":"18","id":"pi"}},"id":"ct"},{"val":{"item":{"val":"minecraft:wheat","id":"ss"},"damage":{"val":"0","id":"pi"},"quantity":{"val":"1","id":"pi"},"slot":{"val":"19","id":"pi"}},"id":"ct"},{"val":{"item":{"val":"minecraft:wheat","id":"ss"},"damage":{"val":"0","id":"pi"},"quantity":{"val":"1","id":"pi"},"slot":{"val":"20","id":"pi"}},"id":"ct"},{"val":{"item":{"val":"minecraft:wheat","id":"ss"},"damage":{"val":"0","id":"pi"},"quantity":{"val":"1","id":"pi"},"slot":{"val":"21","id":"pi"}},"id":"ct"},{"val":{"item":{"val":"minecraft:wheat","id":"ss"},"damage":{"val":"0","id":"pi"},"quantity":{"val":"1","id":"pi"},"slot":{"val":"22","id":"pi"}},"id":"ct"},{"val":{"item":{"val":"minecraft:wheat","id":"ss"},"damage":{"val":"0","id":"pi"},"quantity":{"val":"1","id":"pi"},"slot":{"val":"23","id":"pi"}},"id":"ct"},{"val":{"item":{"val":"minecraft:wheat","id":"ss"},"damage":{"val":"0","id":"pi"},"quantity":{"val":"1","id":"pi"},"slot":{"val":"24","id":"pi"}},"id":"ct"},{"val":{"item":{"val":"minecraft:wheat","id":"ss"},"damage":{"val":"0","id":"pi"},"quantity":{"val":"1","id":"pi"},"slot":{"val":"25","id":"pi"}},"id":"ct"},{"val":{"item":{"val":"minecraft:wheat","id":"ss"},"damage":{"val":"0","id":"pi"},"quantity":{"val":"1","id":"pi"},"slot":{"val":"26","id":"pi"}},"id":"ct"}],"id":"ls"}},"id":"ct"},"teData":{"val":{"id":{"val":"Chest","id":"ss"},"z":{"val":"971","id":"pi"},"y":{"val":"73","id":"pi"},"x":{"val":"1531","id":"pi"}},"id":"ct"},"blockName":{"val":"minecraft:chest","id":"ss"},"meta":{"val":"5","id":"pi"},"buildPass":{"val":"0","id":"pi"}},"id":"ct"}}
:enddata
:endrule

rule:
plugin=vanillaInventory
number=15
data:
JSON:{{"val":{"lootLevel":{"val":"0","id":"pi"},"inventoryData":{"val":{"length":{"val":"27","id":"pi"},"inventoryContents":{"val":[],"id":"ls"}},"id":"ct"},"teData":{"val":{"id":{"val":"Chest","id":"ss"},"z":{"val":"971","id":"pi"},"y":{"val":"73","id":"pi"},"x":{"val":"1536","id":"pi"}},"id":"ct"},"blockName":{"val":"minecraft:chest","id":"ss"},"meta":{"val":"3","id":"pi"},"buildPass":{"val":"0","id":"pi"}},"id":"ct"}}
:enddata
:endrule

rule:
plugin=vanillaInventory
number=16
data:
JSON:{{"val":{"lootLevel":{"val":"0","id":"pi"},"inventoryData":{"val":{"length":{"val":"27","id":"pi"},"inventoryContents":{"val":[],"id":"ls"}},"id":"ct"},"teData":{"val":{"id":{"val":"Chest","id":"ss"},"z":{"val":"971","id":"pi"},"y":{"val":"73","id":"pi"},"x":{"val":"1537","id":"pi"}},"id":"ct"},"blockName":{"val":"minecraft:chest","id":"ss"},"meta":{"val":"3","id":"pi"},"buildPass":{"val":"0","id":"pi"}},"id":"ct"}}
:enddata
:endrule

rule:
plugin=vanillaInventory
number=17
data:
JSON:{{"val":{"lootLevel":{"val":"0","id":"pi"},"inventoryData":{"val":{"length":{"val":"27","id":"pi"},"inventoryContents":{"val":[{"val":{"item":{"val":"minecraft:wheat","id":"ss"},"damage":{"val":"0","id":"pi"},"quantity":{"val":"1","id":"pi"},"slot":{"val":"1","id":"pi"}},"id":"ct"},{"val":{"item":{"val":"minecraft:wheat","id":"ss"},"damage":{"val":"0","id":"pi"},"quantity":{"val":"1","id":"pi"},"slot":{"val":"4","id":"pi"}},"id":"ct"},{"val":{"item":{"val":"minecraft:wheat","id":"ss"},"damage":{"val":"0","id":"pi"},"quantity":{"val":"1","id":"pi"},"slot":{"val":"7","id":"pi"}},"id":"ct"},{"val":{"item":{"val":"minecraft:wheat","id":"ss"},"damage":{"val":"0","id":"pi"},"quantity":{"val":"1","id":"pi"},"slot":{"val":"11","id":"pi"}},"id":"ct"},{"val":{"item":{"val":"minecraft:wheat","id":"ss"},"damage":{"val":"0","id":"pi"},"quantity":{"val":"1","id":"pi"},"slot":{"val":"12","id":"pi"}},"id":"ct"},{"val":{"item":{"val":"minecraft:wheat","id":"ss"},"damage":{"val":"0","id":"pi"},"quantity":{"val":"1","id":"pi"},"slot":{"val":"13","id":"pi"}},"id":"ct"},{"val":{"item":{"val":"minecraft:wheat","id":"ss"},"damage":{"val":"0","id":"pi"},"quantity":{"val":"1","id":"pi"},"slot":{"val":"14","id":"pi"}},"id":"ct"},{"val":{"item":{"val":"minecraft:wheat","id":"ss"},"damage":{"val":"0","id":"pi"},"quantity":{"val":"1","id":"pi"},"slot":{"val":"15","id":"pi"}},"id":"ct"},{"val":{"item":{"val":"minecraft:wheat","id":"ss"},"damage":{"val":"0","id":"pi"},"quantity":{"val":"1","id":"pi"},"slot":{"val":"17","id":"pi"}},"id":"ct"},{"val":{"item":{"val":"minecraft:wheat","id":"ss"},"damage":{"val":"0","id":"pi"},"quantity":{"val":"1","id":"pi"},"slot":{"val":"18","id":"pi"}},"id":"ct"},{"val":{"item":{"val":"minecraft:wheat","id":"ss"},"damage":{"val":"0","id":"pi"},"quantity":{"val":"1","id":"pi"},"slot":{"val":"19","id":"pi"}},"id":"ct"},{"val":{"item":{"val":"minecraft:wheat","id":"ss"},"damage":{"val":"0","id":"pi"},"quantity":{"val":"1","id":"pi"},"slot":{"val":"21","id":"pi"}},"id":"ct"},{"val":{"item":{"val":"minecraft:wheat","id":"ss"},"damage":{"val":"0","id":"pi"},"quantity":{"val":"1","id":"pi"},"slot":{"val":"24","id":"pi"}},"id":"ct"},{"val":{"item":{"val":"minecraft:wheat","id":"ss"},"damage":{"val":"0","id":"pi"},"quantity":{"val":"1","id":"pi"},"slot":{"val":"26","id":"pi"}},"id":"ct"}],"id":"ls"}},"id":"ct"},"teData":{"val":{"id":{"val":"Chest","id":"ss"},"z":{"val":"973","id":"pi"},"y":{"val":"73","id":"pi"},"x":{"val":"1537","id":"pi"}},"id":"ct"},"blockName":{"val":"minecraft:chest","id":"ss"},"meta":{"val":"3","id":"pi"},"buildPass":{"val":"0","id":"pi"}},"id":"ct"}}
:enddata
:endrule

rule:
plugin=vanillaInventory
number=18
data:
JSON:{{"val":{"lootLevel":{"val":"0","id":"pi"},"inventoryData":{"val":{"length":{"val":"27","id":"pi"},"inventoryContents":{"val":[{"val":{"item":{"val":"minecraft:wheat","id":"ss"},"damage":{"val":"0","id":"pi"},"quantity":{"val":"1","id":"pi"},"slot":{"val":"0","id":"pi"}},"id":"ct"},{"val":{"item":{"val":"minecraft:wheat","id":"ss"},"damage":{"val":"0","id":"pi"},"quantity":{"val":"1","id":"pi"},"slot":{"val":"2","id":"pi"}},"id":"ct"},{"val":{"item":{"val":"minecraft:wheat","id":"ss"},"damage":{"val":"0","id":"pi"},"quantity":{"val":"1","id":"pi"},"slot":{"val":"4","id":"pi"}},"id":"ct"},{"val":{"item":{"val":"minecraft:wheat","id":"ss"},"damage":{"val":"0","id":"pi"},"quantity":{"val":"1","id":"pi"},"slot":{"val":"9","id":"pi"}},"id":"ct"},{"val":{"item":{"val":"minecraft:wheat","id":"ss"},"damage":{"val":"0","id":"pi"},"quantity":{"val":"1","id":"pi"},"slot":{"val":"11","id":"pi"}},"id":"ct"},{"val":{"item":{"val":"minecraft:wheat","id":"ss"},"damage":{"val":"0","id":"pi"},"quantity":{"val":"1","id":"pi"},"slot":{"val":"12","id":"pi"}},"id":"ct"},{"val":{"item":{"val":"minecraft:wheat","id":"ss"},"damage":{"val":"0","id":"pi"},"quantity":{"val":"1","id":"pi"},"slot":{"val":"14","id":"pi"}},"id":"ct"},{"val":{"item":{"val":"minecraft:wheat","id":"ss"},"damage":{"val":"0","id":"pi"},"quantity":{"val":"1","id":"pi"},"slot":{"val":"15","id":"pi"}},"id":"ct"},{"val":{"item":{"val":"minecraft:wheat","id":"ss"},"damage":{"val":"0","id":"pi"},"quantity":{"val":"1","id":"pi"},"slot":{"val":"16","id":"pi"}},"id":"ct"},{"val":{"item":{"val":"minecraft:wheat","id":"ss"},"damage":{"val":"0","id":"pi"},"quantity":{"val":"1","id":"pi"},"slot":{"val":"18","id":"pi"}},"id":"ct"},{"val":{"item":{"val":"minecraft:wheat","id":"ss"},"damage":{"val":"0","id":"pi"},"quantity":{"val":"1","id":"pi"},"slot":{"val":"20","id":"pi"}},"id":"ct"},{"val":{"item":{"val":"minecraft:wheat","id":"ss"},"damage":{"val":"0","id":"pi"},"quantity":{"val":"1","id":"pi"},"slot":{"val":"23","id":"pi"}},"id":"ct"},{"val":{"item":{"val":"minecraft:wheat","id":"ss"},"damage":{"val":"0","id":"pi"},"quantity":{"val":"1","id":"pi"},"slot":{"val":"24","id":"pi"}},"id":"ct"},{"val":{"item":{"val":"minecraft:wheat","id":"ss"},"damage":{"val":"0","id":"pi"},"quantity":{"val":"1","id":"pi"},"slot":{"val":"26","id":"pi"}},"id":"ct"}],"id":"ls"}},"id":"ct"},"teData":{"val":{"id":{"val":"Chest","id":"ss"},"z":{"val":"973","id":"pi"},"y":{"val":"73","id":"pi"},"x":{"val":"1538","id":"pi"}},"id":"ct"},"blockName":{"val":"minecraft:chest","id":"ss"},"meta":{"val":"3","id":"pi"},"buildPass":{"val":"0","id":"pi"}},"id":"ct"}}
:enddata
:endrule

rule:
plugin=vanillaBlocks
number=19
data:
JSON:{{"val":{"blockName":{"val":"minecraft:stone_slab","id":"ss"},"meta":{"val":"0","id":"pi"},"buildPass":{"val":"0","id":"pi"}},"id":"ct"}}
:enddata
:endrule

rule:
plugin=vanillaInventory
number=20
data:
JSON:{{"val":{"lootLevel":{"val":"0","id":"pi"},"inventoryData":{"val":{"length":{"val":"27","id":"pi"},"inventoryContents":{"val":[{"val":{"item":{"val":"minecraft:wheat_seeds","id":"ss"},"damage":{"val":"0","id":"pi"},"quantity":{"val":"1","id":"pi"},"slot":{"val":"0","id":"pi"}},"id":"ct"},{"val":{"item":{"val":"minecraft:wheat_seeds","id":"ss"},"damage":{"val":"0","id":"pi"},"quantity":{"val":"1","id":"pi"},"slot":{"val":"1","id":"pi"}},"id":"ct"},{"val":{"item":{"val":"minecraft:wheat_seeds","id":"ss"},"damage":{"val":"0","id":"pi"},"quantity":{"val":"1","id":"pi"},"slot":{"val":"2","id":"pi"}},"id":"ct"},{"val":{"item":{"val":"minecraft:wheat_seeds","id":"ss"},"damage":{"val":"0","id":"pi"},"quantity":{"val":"1","id":"pi"},"slot":{"val":"3","id":"pi"}},"id":"ct"},{"val":{"item":{"val":"minecraft:wheat_seeds","id":"ss"},"damage":{"val":"0","id":"pi"},"quantity":{"val":"1","id":"pi"},"slot":{"val":"4","id":"pi"}},"id":"ct"},{"val":{"item":{"val":"minecraft:wheat_seeds","id":"ss"},"damage":{"val":"0","id":"pi"},"quantity":{"val":"1","id":"pi"},"slot":{"val":"5","id":"pi"}},"id":"ct"},{"val":{"item":{"val":"minecraft:wheat_seeds","id":"ss"},"damage":{"val":"0","id":"pi"},"quantity":{"val":"1","id":"pi"},"slot":{"val":"6","id":"pi"}},"id":"ct"},{"val":{"item":{"val":"minecraft:wheat_seeds","id":"ss"},"damage":{"val":"0","id":"pi"},"quantity":{"val":"1","id":"pi"},"slot":{"val":"7","id":"pi"}},"id":"ct"},{"val":{"item":{"val":"minecraft:wheat_seeds","id":"ss"},"damage":{"val":"0","id":"pi"},"quantity":{"val":"1","id":"pi"},"slot":{"val":"8","id":"pi"}},"id":"ct"},{"val":{"item":{"val":"minecraft:wheat_seeds","id":"ss"},"damage":{"val":"0","id":"pi"},"quantity":{"val":"1","id":"pi"},"slot":{"val":"9","id":"pi"}},"id":"ct"},{"val":{"item":{"val":"minecraft:wheat_seeds","id":"ss"},"damage":{"val":"0","id":"pi"},"quantity":{"val":"1","id":"pi"},"slot":{"val":"10","id":"pi"}},"id":"ct"},{"val":{"item":{"val":"minecraft:wheat_seeds","id":"ss"},"damage":{"val":"0","id":"pi"},"quantity":{"val":"1","id":"pi"},"slot":{"val":"11","id":"pi"}},"id":"ct"},{"val":{"item":{"val":"minecraft:wheat_seeds","id":"ss"},"damage":{"val":"0","id":"pi"},"quantity":{"val":"1","id":"pi"},"slot":{"val":"12","id":"pi"}},"id":"ct"},{"val":{"item":{"val":"minecraft:wheat_seeds","id":"ss"},"damage":{"val":"0","id":"pi"},"quantity":{"val":"1","id":"pi"},"slot":{"val":"13","id":"pi"}},"id":"ct"},{"val":{"item":{"val":"minecraft:wheat_seeds","id":"ss"},"damage":{"val":"0","id":"pi"},"quantity":{"val":"1","id":"pi"},"slot":{"val":"14","id":"pi"}},"id":"ct"},{"val":{"item":{"val":"minecraft:wheat_seeds","id":"ss"},"damage":{"val":"0","id":"pi"},"quantity":{"val":"1","id":"pi"},"slot":{"val":"15","id":"pi"}},"id":"ct"},{"val":{"item":{"val":"minecraft:wheat_seeds","id":"ss"},"damage":{"val":"0","id":"pi"},"quantity":{"val":"1","id":"pi"},"slot":{"val":"16","id":"pi"}},"id":"ct"},{"val":{"item":{"val":"minecraft:wheat_seeds","id":"ss"},"damage":{"val":"0","id":"pi"},"quantity":{"val":"1","id":"pi"},"slot":{"val":"17","id":"pi"}},"id":"ct"},{"val":{"item":{"val":"minecraft:wheat_seeds","id":"ss"},"damage":{"val":"0","id":"pi"},"quantity":{"val":"1","id":"pi"},"slot":{"val":"18","id":"pi"}},"id":"ct"},{"val":{"item":{"val":"minecraft:wheat_seeds","id":"ss"},"damage":{"val":"0","id":"pi"},"quantity":{"val":"1","id":"pi"},"slot":{"val":"19","id":"pi"}},"id":"ct"},{"val":{"item":{"val":"minecraft:wheat_seeds","id":"ss"},"damage":{"val":"0","id":"pi"},"quantity":{"val":"1","id":"pi"},"slot":{"val":"20","id":"pi"}},"id":"ct"},{"val":{"item":{"val":"minecraft:wheat_seeds","id":"ss"},"damage":{"val":"0","id":"pi"},"quantity":{"val":"1","id":"pi"},"slot":{"val":"21","id":"pi"}},"id":"ct"},{"val":{"item":{"val":"minecraft:wheat_seeds","id":"ss"},"damage":{"val":"0","id":"pi"},"quantity":{"val":"1","id":"pi"},"slot":{"val":"22","id":"pi"}},"id":"ct"},{"val":{"item":{"val":"minecraft:wheat_seeds","id":"ss"},"damage":{"val":"0","id":"pi"},"quantity":{"val":"1","id":"pi"},"slot":{"val":"23","id":"pi"}},"id":"ct"},{"val":{"item":{"val":"minecraft:wheat_seeds","id":"ss"},"damage":{"val":"0","id":"pi"},"quantity":{"val":"1","id":"pi"},"slot":{"val":"24","id":"pi"}},"id":"ct"},{"val":{"item":{"val":"minecraft:wheat_seeds","id":"ss"},"damage":{"val":"0","id":"pi"},"quantity":{"val":"1","id":"pi"},"slot":{"val":"25","id":"pi"}},"id":"ct"},{"val":{"item":{"val":"minecraft:wheat_seeds","id":"ss"},"damage":{"val":"0","id":"pi"},"quantity":{"val":"1","id":"pi"},"slot":{"val":"26","id":"pi"}},"id":"ct"}],"id":"ls"}},"id":"ct"},"teData":{"val":{"id":{"val":"Chest","id":"ss"},"z":{"val":"974","id":"pi"},"y":{"val":"73","id":"pi"},"x":{"val":"1541","id":"pi"}},"id":"ct"},"blockName":{"val":"minecraft:chest","id":"ss"},"meta":{"val":"4","id":"pi"},"buildPass":{"val":"0","id":"pi"}},"id":"ct"}}
:enddata
:endrule

rule:
plugin=vanillaBlocks
number=21
data:
JSON:{{"val":{"blockName":{"val":"minecraft:iron_block","id":"ss"},"meta":{"val":"0","id":"pi"},"buildPass":{"val":"0","id":"pi"}},"id":"ct"}}
:enddata
:endrule

rule:
plugin=vanillaInventory
number=22
data:
JSON:{{"val":{"lootLevel":{"val":"0","id":"pi"},"inventoryData":{"val":{"length":{"val":"27","id":"pi"},"inventoryContents":{"val":[{"val":{"item":{"val":"minecraft:wheat_seeds","id":"ss"},"damage":{"val":"0","id":"pi"},"quantity":{"val":"1","id":"pi"},"slot":{"val":"0","id":"pi"}},"id":"ct"},{"val":{"item":{"val":"minecraft:wheat_seeds","id":"ss"},"damage":{"val":"0","id":"pi"},"quantity":{"val":"1","id":"pi"},"slot":{"val":"1","id":"pi"}},"id":"ct"},{"val":{"item":{"val":"minecraft:wheat_seeds","id":"ss"},"damage":{"val":"0","id":"pi"},"quantity":{"val":"1","id":"pi"},"slot":{"val":"2","id":"pi"}},"id":"ct"},{"val":{"item":{"val":"minecraft:wheat_seeds","id":"ss"},"damage":{"val":"0","id":"pi"},"quantity":{"val":"1","id":"pi"},"slot":{"val":"3","id":"pi"}},"id":"ct"},{"val":{"item":{"val":"minecraft:wheat_seeds","id":"ss"},"damage":{"val":"0","id":"pi"},"quantity":{"val":"1","id":"pi"},"slot":{"val":"4","id":"pi"}},"id":"ct"},{"val":{"item":{"val":"minecraft:wheat_seeds","id":"ss"},"damage":{"val":"0","id":"pi"},"quantity":{"val":"1","id":"pi"},"slot":{"val":"5","id":"pi"}},"id":"ct"},{"val":{"item":{"val":"minecraft:wheat_seeds","id":"ss"},"damage":{"val":"0","id":"pi"},"quantity":{"val":"1","id":"pi"},"slot":{"val":"6","id":"pi"}},"id":"ct"},{"val":{"item":{"val":"minecraft:wheat_seeds","id":"ss"},"damage":{"val":"0","id":"pi"},"quantity":{"val":"1","id":"pi"},"slot":{"val":"7","id":"pi"}},"id":"ct"},{"val":{"item":{"val":"minecraft:wheat_seeds","id":"ss"},"damage":{"val":"0","id":"pi"},"quantity":{"val":"1","id":"pi"},"slot":{"val":"8","id":"pi"}},"id":"ct"},{"val":{"item":{"val":"minecraft:wheat_seeds","id":"ss"},"damage":{"val":"0","id":"pi"},"quantity":{"val":"1","id":"pi"},"slot":{"val":"9","id":"pi"}},"id":"ct"},{"val":{"item":{"val":"minecraft:wheat_seeds","id":"ss"},"damage":{"val":"0","id":"pi"},"quantity":{"val":"1","id":"pi"},"slot":{"val":"10","id":"pi"}},"id":"ct"},{"val":{"item":{"val":"minecraft:wheat_seeds","id":"ss"},"damage":{"val":"0","id":"pi"},"quantity":{"val":"1","id":"pi"},"slot":{"val":"11","id":"pi"}},"id":"ct"},{"val":{"item":{"val":"minecraft:wheat_seeds","id":"ss"},"damage":{"val":"0","id":"pi"},"quantity":{"val":"1","id":"pi"},"slot":{"val":"12","id":"pi"}},"id":"ct"},{"val":{"item":{"val":"minecraft:wheat_seeds","id":"ss"},"damage":{"val":"0","id":"pi"},"quantity":{"val":"1","id":"pi"},"slot":{"val":"13","id":"pi"}},"id":"ct"},{"val":{"item":{"val":"minecraft:wheat_seeds","id":"ss"},"damage":{"val":"0","id":"pi"},"quantity":{"val":"1","id":"pi"},"slot":{"val":"14","id":"pi"}},"id":"ct"},{"val":{"item":{"val":"minecraft:wheat_seeds","id":"ss"},"damage":{"val":"0","id":"pi"},"quantity":{"val":"1","id":"pi"},"slot":{"val":"15","id":"pi"}},"id":"ct"},{"val":{"item":{"val":"minecraft:wheat_seeds","id":"ss"},"damage":{"val":"0","id":"pi"},"quantity":{"val":"1","id":"pi"},"slot":{"val":"16","id":"pi"}},"id":"ct"},{"val":{"item":{"val":"minecraft:wheat_seeds","id":"ss"},"damage":{"val":"0","id":"pi"},"quantity":{"val":"1","id":"pi"},"slot":{"val":"17","id":"pi"}},"id":"ct"},{"val":{"item":{"val":"minecraft:wheat_seeds","id":"ss"},"damage":{"val":"0","id":"pi"},"quantity":{"val":"1","id":"pi"},"slot":{"val":"18","id":"pi"}},"id":"ct"},{"val":{"item":{"val":"minecraft:wheat_seeds","id":"ss"},"damage":{"val":"0","id":"pi"},"quantity":{"val":"1","id":"pi"},"slot":{"val":"19","id":"pi"}},"id":"ct"},{"val":{"item":{"val":"minecraft:wheat_seeds","id":"ss"},"damage":{"val":"0","id":"pi"},"quantity":{"val":"1","id":"pi"},"slot":{"val":"20","id":"pi"}},"id":"ct"},{"val":{"item":{"val":"minecraft:wheat_seeds","id":"ss"},"damage":{"val":"0","id":"pi"},"quantity":{"val":"1","id":"pi"},"slot":{"val":"21","id":"pi"}},"id":"ct"},{"val":{"item":{"val":"minecraft:wheat_seeds","id":"ss"},"damage":{"val":"0","id":"pi"},"quantity":{"val":"1","id":"pi"},"slot":{"val":"22","id":"pi"}},"id":"ct"},{"val":{"item":{"val":"minecraft:wheat_seeds","id":"ss"},"damage":{"val":"0","id":"pi"},"quantity":{"val":"1","id":"pi"},"slot":{"val":"23","id":"pi"}},"id":"ct"},{"val":{"item":{"val":"minecraft:wheat_seeds","id":"ss"},"damage":{"val":"0","id":"pi"},"quantity":{"val":"1","id":"pi"},"slot":{"val":"24","id":"pi"}},"id":"ct"},{"val":{"item":{"val":"minecraft:wheat_seeds","id":"ss"},"damage":{"val":"0","id":"pi"},"quantity":{"val":"1","id":"pi"},"slot":{"val":"25","id":"pi"}},"id":"ct"},{"val":{"item":{"val":"minecraft:wheat_seeds","id":"ss"},"damage":{"val":"0","id":"pi"},"quantity":{"val":"1","id":"pi"},"slot":{"val":"26","id":"pi"}},"id":"ct"}],"id":"ls"}},"id":"ct"},"teData":{"val":{"id":{"val":"Chest","id":"ss"},"z":{"val":"975","id":"pi"},"y":{"val":"73","id":"pi"},"x":{"val":"1541","id":"pi"}},"id":"ct"},"blockName":{"val":"minecraft:chest","id":"ss"},"meta":{"val":"4","id":"pi"},"buildPass":{"val":"0","id":"pi"}},"id":"ct"}}
:enddata
:endrule

rule:
plugin=vanillaBlocks
number=23
data:
JSON:{{"val":{"blockName":{"val":"minecraft:crafting_table","id":"ss"},"meta":{"val":"0","id":"pi"},"buildPass":{"val":"0","id":"pi"}},"id":"ct"}}
:enddata
:endrule

rule:
plugin=vanillaBlocks
number=24
data:
JSON:{{"val":{"blockName":{"val":"minecraft:fence_gate","id":"ss"},"meta":{"val":"2","id":"pi"},"buildPass":{"val":"0","id":"pi"}},"id":"ct"}}
:enddata
:endrule

rule:
plugin=vanillaBlocks
number=25
data:
JSON:{{"val":{"blockName":{"val":"minecraft:torch","id":"ss"},"meta":{"val":"5","id":"pi"},"buildPass":{"val":"2","id":"pi"}},"id":"ct"}}
:enddata
:endrule

rule:
plugin=vanillaSign
number=26
data:
JSON:{{"val":{"blockName":{"val":"minecraft:wall_sign","id":"ss"},"signContents1":{"val":"New Fangled","id":"ss"},"signContents2":{"val":"Mill","id":"ss"},"signContents0":{"val":"","id":"ss"},"meta":{"val":"2","id":"pi"},"signContents3":{"val":"","id":"ss"},"buildPass":{"val":"2","id":"pi"}},"id":"ct"}}
:enddata
:endrule

rule:
plugin=vanillaDoors
number=27
data:
JSON:{{"val":{"sideFlag":{"val":"0","id":"pb"},"blockName":{"val":"minecraft:wooden_door","id":"ss"},"meta":{"val":"8","id":"pi"},"buildPass":{"val":"2","id":"pi"}},"id":"ct"}}
:enddata
:endrule

rule:
plugin=vanillaBlocks
number=28
data:
JSON:{{"val":{"blockName":{"val":"minecraft:torch","id":"ss"},"meta":{"val":"3","id":"pi"},"buildPass":{"val":"2","id":"pi"}},"id":"ct"}}
:enddata
:endrule

rule:
plugin=vanillaBlocks
number=29
data:
JSON:{{"val":{"blockName":{"val":"minecraft:torch","id":"ss"},"meta":{"val":"4","id":"pi"},"buildPass":{"val":"2","id":"pi"}},"id":"ct"}}
:enddata
:endrule

rule:
plugin=vanillaDoors
number=30
data:
JSON:{{"val":{"sideFlag":{"val":"0","id":"pb"},"blockName":{"val":"minecraft:wooden_door","id":"ss"},"meta":{"val":"8","id":"pi"},"buildPass":{"val":"2","id":"pi"}},"id":"ct"}}
:enddata
:endrule

rule:
plugin=vanillaSign
number=31
data:
JSON:{{"val":{"blockName":{"val":"minecraft:wall_sign","id":"ss"},"signContents1":{"val":"New Fangled","id":"ss"},"signContents2":{"val":"Mill","id":"ss"},"signContents0":{"val":"","id":"ss"},"meta":{"val":"3","id":"pi"},"signContents3":{"val":"","id":"ss"},"buildPass":{"val":"2","id":"pi"}},"id":"ct"}}
:enddata
:endrule

rule:
plugin=vanillaInventory
number=32
data:
JSON:{{"val":{"lootLevel":{"val":"0","id":"pi"},"inventoryData":{"val":{"length":{"val":"27","id":"pi"},"inventoryContents":{"val":[{"val":{"item":{"val":"minecraft:wheat","id":"ss"},"damage":{"val":"0","id":"pi"},"quantity":{"val":"1","id":"pi"},"slot":{"val":"22","id":"pi"}},"id":"ct"}],"id":"ls"}},"id":"ct"},"teData":{"val":{"id":{"val":"Chest","id":"ss"},"z":{"val":"970","id":"pi"},"y":{"val":"75","id":"pi"},"x":{"val":"1531","id":"pi"}},"id":"ct"},"blockName":{"val":"minecraft:chest","id":"ss"},"meta":{"val":"5","id":"pi"},"buildPass":{"val":"0","id":"pi"}},"id":"ct"}}
:enddata
:endrule

rule:
plugin=vanillaBlocks
number=33
data:
JSON:{{"val":{"blockName":{"val":"minecraft:torch","id":"ss"},"meta":{"val":"2","id":"pi"},"buildPass":{"val":"2","id":"pi"}},"id":"ct"}}
:enddata
:endrule

rule:
plugin=vanillaInventory
number=34
data:
JSON:{{"val":{"lootLevel":{"val":"0","id":"pi"},"inventoryData":{"val":{"length":{"val":"27","id":"pi"},"inventoryContents":{"val":[{"val":{"item":{"val":"minecraft:wheat","id":"ss"},"damage":{"val":"0","id":"pi"},"quantity":{"val":"1","id":"pi"},"slot":{"val":"3","id":"pi"}},"id":"ct"}],"id":"ls"}},"id":"ct"},"teData":{"val":{"id":{"val":"Chest","id":"ss"},"z":{"val":"971","id":"pi"},"y":{"val":"75","id":"pi"},"x":{"val":"1531","id":"pi"}},"id":"ct"},"blockName":{"val":"minecraft:chest","id":"ss"},"meta":{"val":"5","id":"pi"},"buildPass":{"val":"0","id":"pi"}},"id":"ct"}}
:enddata
:endrule

rule:
plugin=vanillaInventory
number=35
data:
JSON:{{"val":{"lootLevel":{"val":"0","id":"pi"},"inventoryData":{"val":{"length":{"val":"27","id":"pi"},"inventoryContents":{"val":[],"id":"ls"}},"id":"ct"},"teData":{"val":{"id":{"val":"Chest","id":"ss"},"z":{"val":"971","id":"pi"},"y":{"val":"75","id":"pi"},"x":{"val":"1536","id":"pi"}},"id":"ct"},"blockName":{"val":"minecraft:chest","id":"ss"},"meta":{"val":"3","id":"pi"},"buildPass":{"val":"0","id":"pi"}},"id":"ct"}}
:enddata
:endrule

rule:
plugin=vanillaInventory
number=36
data:
JSON:{{"val":{"lootLevel":{"val":"0","id":"pi"},"inventoryData":{"val":{"length":{"val":"27","id":"pi"},"inventoryContents":{"val":[],"id":"ls"}},"id":"ct"},"teData":{"val":{"id":{"val":"Chest","id":"ss"},"z":{"val":"971","id":"pi"},"y":{"val":"75","id":"pi"},"x":{"val":"1537","id":"pi"}},"id":"ct"},"blockName":{"val":"minecraft:chest","id":"ss"},"meta":{"val":"3","id":"pi"},"buildPass":{"val":"0","id":"pi"}},"id":"ct"}}
:enddata
:endrule

rule:
plugin=vanillaInventory
number=37
data:
JSON:{{"val":{"lootLevel":{"val":"0","id":"pi"},"inventoryData":{"val":{"length":{"val":"27","id":"pi"},"inventoryContents":{"val":[{"val":{"item":{"val":"minecraft:wheat","id":"ss"},"damage":{"val":"0","id":"pi"},"quantity":{"val":"1","id":"pi"},"slot":{"val":"6","id":"pi"}},"id":"ct"},{"val":{"item":{"val":"minecraft:wheat","id":"ss"},"damage":{"val":"0","id":"pi"},"quantity":{"val":"1","id":"pi"},"slot":{"val":"8","id":"pi"}},"id":"ct"},{"val":{"item":{"val":"minecraft:wheat","id":"ss"},"damage":{"val":"0","id":"pi"},"quantity":{"val":"1","id":"pi"},"slot":{"val":"11","id":"pi"}},"id":"ct"},{"val":{"item":{"val":"minecraft:wheat","id":"ss"},"damage":{"val":"0","id":"pi"},"quantity":{"val":"1","id":"pi"},"slot":{"val":"12","id":"pi"}},"id":"ct"},{"val":{"item":{"val":"minecraft:wheat","id":"ss"},"damage":{"val":"0","id":"pi"},"quantity":{"val":"1","id":"pi"},"slot":{"val":"13","id":"pi"}},"id":"ct"},{"val":{"item":{"val":"minecraft:wheat","id":"ss"},"damage":{"val":"0","id":"pi"},"quantity":{"val":"1","id":"pi"},"slot":{"val":"15","id":"pi"}},"id":"ct"},{"val":{"item":{"val":"minecraft:wheat","id":"ss"},"damage":{"val":"0","id":"pi"},"quantity":{"val":"1","id":"pi"},"slot":{"val":"20","id":"pi"}},"id":"ct"},{"val":{"item":{"val":"minecraft:wheat","id":"ss"},"damage":{"val":"0","id":"pi"},"quantity":{"val":"1","id":"pi"},"slot":{"val":"21","id":"pi"}},"id":"ct"},{"val":{"item":{"val":"minecraft:wheat","id":"ss"},"damage":{"val":"0","id":"pi"},"quantity":{"val":"1","id":"pi"},"slot":{"val":"22","id":"pi"}},"id":"ct"},{"val":{"item":{"val":"minecraft:wheat","id":"ss"},"damage":{"val":"0","id":"pi"},"quantity":{"val":"1","id":"pi"},"slot":{"val":"24","id":"pi"}},"id":"ct"},{"val":{"item":{"val":"minecraft:wheat","id":"ss"},"damage":{"val":"0","id":"pi"},"quantity":{"val":"1","id":"pi"},"slot":{"val":"25","id":"pi"}},"id":"ct"}],"id":"ls"}},"id":"ct"},"teData":{"val":{"id":{"val":"Chest","id":"ss"},"z":{"val":"973","id":"pi"},"y":{"val":"75","id":"pi"},"x":{"val":"1537","id":"pi"}},"id":"ct"},"blockName":{"val":"minecraft:chest","id":"ss"},"meta":{"val":"3","id":"pi"},"buildPass":{"val":"0","id":"pi"}},"id":"ct"}}
:enddata
:endrule

rule:
plugin=vanillaInventory
number=38
data:
JSON:{{"val":{"lootLevel":{"val":"0","id":"pi"},"inventoryData":{"val":{"length":{"val":"27","id":"pi"},"inventoryContents":{"val":[{"val":{"item":{"val":"minecraft:wheat","id":"ss"},"damage":{"val":"0","id":"pi"},"quantity":{"val":"1","id":"pi"},"slot":{"val":"4","id":"pi"}},"id":"ct"},{"val":{"item":{"val":"minecraft:wheat","id":"ss"},"damage":{"val":"0","id":"pi"},"quantity":{"val":"1","id":"pi"},"slot":{"val":"7","id":"pi"}},"id":"ct"},{"val":{"item":{"val":"minecraft:wheat","id":"ss"},"damage":{"val":"0","id":"pi"},"quantity":{"val":"1","id":"pi"},"slot":{"val":"8","id":"pi"}},"id":"ct"},{"val":{"item":{"val":"minecraft:wheat","id":"ss"},"damage":{"val":"0","id":"pi"},"quantity":{"val":"1","id":"pi"},"slot":{"val":"10","id":"pi"}},"id":"ct"},{"val":{"item":{"val":"minecraft:wheat","id":"ss"},"damage":{"val":"0","id":"pi"},"quantity":{"val":"1","id":"pi"},"slot":{"val":"11","id":"pi"}},"id":"ct"},{"val":{"item":{"val":"minecraft:wheat","id":"ss"},"damage":{"val":"0","id":"pi"},"quantity":{"val":"1","id":"pi"},"slot":{"val":"14","id":"pi"}},"id":"ct"},{"val":{"item":{"val":"minecraft:wheat","id":"ss"},"damage":{"val":"0","id":"pi"},"quantity":{"val":"1","id":"pi"},"slot":{"val":"19","id":"pi"}},"id":"ct"},{"val":{"item":{"val":"minecraft:wheat","id":"ss"},"damage":{"val":"0","id":"pi"},"quantity":{"val":"1","id":"pi"},"slot":{"val":"20","id":"pi"}},"id":"ct"},{"val":{"item":{"val":"minecraft:wheat","id":"ss"},"damage":{"val":"0","id":"pi"},"quantity":{"val":"1","id":"pi"},"slot":{"val":"21","id":"pi"}},"id":"ct"},{"val":{"item":{"val":"minecraft:wheat","id":"ss"},"damage":{"val":"0","id":"pi"},"quantity":{"val":"1","id":"pi"},"slot":{"val":"22","id":"pi"}},"id":"ct"}],"id":"ls"}},"id":"ct"},"teData":{"val":{"id":{"val":"Chest","id":"ss"},"z":{"val":"973","id":"pi"},"y":{"val":"75","id":"pi"},"x":{"val":"1538","id":"pi"}},"id":"ct"},"blockName":{"val":"minecraft:chest","id":"ss"},"meta":{"val":"3","id":"pi"},"buildPass":{"val":"0","id":"pi"}},"id":"ct"}}
:enddata
:endrule

rule:
plugin=vanillaBlocks
number=39
data:
JSON:{{"val":{"blockName":{"val":"minecraft:stone","id":"ss"},"meta":{"val":"0","id":"pi"},"buildPass":{"val":"0","id":"pi"}},"id":"ct"}}
:enddata
:endrule

rule:
plugin=vanillaInventory
number=40
data:
JSON:{{"val":{"lootLevel":{"val":"0","id":"pi"},"inventoryData":{"val":{"length":{"val":"27","id":"pi"},"inventoryContents":{"val":[{"val":{"item":{"val":"minecraft:wheat_seeds","id":"ss"},"damage":{"val":"0","id":"pi"},"quantity":{"val":"1","id":"pi"},"slot":{"val":"0","id":"pi"}},"id":"ct"},{"val":{"item":{"val":"minecraft:wheat_seeds","id":"ss"},"damage":{"val":"0","id":"pi"},"quantity":{"val":"1","id":"pi"},"slot":{"val":"1","id":"pi"}},"id":"ct"},{"val":{"item":{"val":"minecraft:wheat_seeds","id":"ss"},"damage":{"val":"0","id":"pi"},"quantity":{"val":"1","id":"pi"},"slot":{"val":"2","id":"pi"}},"id":"ct"},{"val":{"item":{"val":"minecraft:wheat_seeds","id":"ss"},"damage":{"val":"0","id":"pi"},"quantity":{"val":"1","id":"pi"},"slot":{"val":"3","id":"pi"}},"id":"ct"},{"val":{"item":{"val":"minecraft:wheat_seeds","id":"ss"},"damage":{"val":"0","id":"pi"},"quantity":{"val":"1","id":"pi"},"slot":{"val":"4","id":"pi"}},"id":"ct"},{"val":{"item":{"val":"minecraft:wheat_seeds","id":"ss"},"damage":{"val":"0","id":"pi"},"quantity":{"val":"1","id":"pi"},"slot":{"val":"5","id":"pi"}},"id":"ct"},{"val":{"item":{"val":"minecraft:wheat_seeds","id":"ss"},"damage":{"val":"0","id":"pi"},"quantity":{"val":"1","id":"pi"},"slot":{"val":"6","id":"pi"}},"id":"ct"},{"val":{"item":{"val":"minecraft:wheat_seeds","id":"ss"},"damage":{"val":"0","id":"pi"},"quantity":{"val":"1","id":"pi"},"slot":{"val":"7","id":"pi"}},"id":"ct"},{"val":{"item":{"val":"minecraft:wheat_seeds","id":"ss"},"damage":{"val":"0","id":"pi"},"quantity":{"val":"1","id":"pi"},"slot":{"val":"8","id":"pi"}},"id":"ct"},{"val":{"item":{"val":"minecraft:wheat_seeds","id":"ss"},"damage":{"val":"0","id":"pi"},"quantity":{"val":"1","id":"pi"},"slot":{"val":"9","id":"pi"}},"id":"ct"},{"val":{"item":{"val":"minecraft:wheat_seeds","id":"ss"},"damage":{"val":"0","id":"pi"},"quantity":{"val":"1","id":"pi"},"slot":{"val":"10","id":"pi"}},"id":"ct"},{"val":{"item":{"val":"minecraft:wheat_seeds","id":"ss"},"damage":{"val":"0","id":"pi"},"quantity":{"val":"1","id":"pi"},"slot":{"val":"11","id":"pi"}},"id":"ct"},{"val":{"item":{"val":"minecraft:wheat_seeds","id":"ss"},"damage":{"val":"0","id":"pi"},"quantity":{"val":"1","id":"pi"},"slot":{"val":"12","id":"pi"}},"id":"ct"},{"val":{"item":{"val":"minecraft:wheat_seeds","id":"ss"},"damage":{"val":"0","id":"pi"},"quantity":{"val":"1","id":"pi"},"slot":{"val":"13","id":"pi"}},"id":"ct"},{"val":{"item":{"val":"minecraft:wheat_seeds","id":"ss"},"damage":{"val":"0","id":"pi"},"quantity":{"val":"1","id":"pi"},"slot":{"val":"14","id":"pi"}},"id":"ct"},{"val":{"item":{"val":"minecraft:wheat_seeds","id":"ss"},"damage":{"val":"0","id":"pi"},"quantity":{"val":"1","id":"pi"},"slot":{"val":"15","id":"pi"}},"id":"ct"},{"val":{"item":{"val":"minecraft:wheat_seeds","id":"ss"},"damage":{"val":"0","id":"pi"},"quantity":{"val":"1","id":"pi"},"slot":{"val":"16","id":"pi"}},"id":"ct"},{"val":{"item":{"val":"minecraft:wheat_seeds","id":"ss"},"damage":{"val":"0","id":"pi"},"quantity":{"val":"1","id":"pi"},"slot":{"val":"17","id":"pi"}},"id":"ct"},{"val":{"item":{"val":"minecraft:wheat_seeds","id":"ss"},"damage":{"val":"0","id":"pi"},"quantity":{"val":"1","id":"pi"},"slot":{"val":"18","id":"pi"}},"id":"ct"},{"val":{"item":{"val":"minecraft:wheat_seeds","id":"ss"},"damage":{"val":"0","id":"pi"},"quantity":{"val":"1","id":"pi"},"slot":{"val":"19","id":"pi"}},"id":"ct"},{"val":{"item":{"val":"minecraft:wheat_seeds","id":"ss"},"damage":{"val":"0","id":"pi"},"quantity":{"val":"1","id":"pi"},"slot":{"val":"20","id":"pi"}},"id":"ct"},{"val":{"item":{"val":"minecraft:wheat_seeds","id":"ss"},"damage":{"val":"0","id":"pi"},"quantity":{"val":"1","id":"pi"},"slot":{"val":"21","id":"pi"}},"id":"ct"},{"val":{"item":{"val":"minecraft:wheat_seeds","id":"ss"},"damage":{"val":"0","id":"pi"},"quantity":{"val":"1","id":"pi"},"slot":{"val":"22","id":"pi"}},"id":"ct"},{"val":{"item":{"val":"minecraft:wheat_seeds","id":"ss"},"damage":{"val":"0","id":"pi"},"quantity":{"val":"1","id":"pi"},"slot":{"val":"23","id":"pi"}},"id":"ct"},{"val":{"item":{"val":"minecraft:wheat_seeds","id":"ss"},"damage":{"val":"0","id":"pi"},"quantity":{"val":"1","id":"pi"},"slot":{"val":"24","id":"pi"}},"id":"ct"},{"val":{"item":{"val":"minecraft:wheat_seeds","id":"ss"},"damage":{"val":"0","id":"pi"},"quantity":{"val":"1","id":"pi"},"slot":{"val":"25","id":"pi"}},"id":"ct"},{"val":{"item":{"val":"minecraft:wheat_seeds","id":"ss"},"damage":{"val":"0","id":"pi"},"quantity":{"val":"1","id":"pi"},"slot":{"val":"26","id":"pi"}},"id":"ct"}],"id":"ls"}},"id":"ct"},"teData":{"val":{"id":{"val":"Chest","id":"ss"},"z":{"val":"974","id":"pi"},"y":{"val":"75","id":"pi"},"x":{"val":"1541","id":"pi"}},"id":"ct"},"blockName":{"val":"minecraft:chest","id":"ss"},"meta":{"val":"4","id":"pi"},"buildPass":{"val":"0","id":"pi"}},"id":"ct"}}
:enddata
:endrule

rule:
plugin=vanillaInventory
number=41
data:
JSON:{{"val":{"lootLevel":{"val":"0","id":"pi"},"inventoryData":{"val":{"length":{"val":"27","id":"pi"},"inventoryContents":{"val":[{"val":{"item":{"val":"minecraft:wheat_seeds","id":"ss"},"damage":{"val":"0","id":"pi"},"quantity":{"val":"1","id":"pi"},"slot":{"val":"0","id":"pi"}},"id":"ct"},{"val":{"item":{"val":"minecraft:wheat_seeds","id":"ss"},"damage":{"val":"0","id":"pi"},"quantity":{"val":"1","id":"pi"},"slot":{"val":"1","id":"pi"}},"id":"ct"},{"val":{"item":{"val":"minecraft:wheat_seeds","id":"ss"},"damage":{"val":"0","id":"pi"},"quantity":{"val":"1","id":"pi"},"slot":{"val":"2","id":"pi"}},"id":"ct"},{"val":{"item":{"val":"minecraft:wheat_seeds","id":"ss"},"damage":{"val":"0","id":"pi"},"quantity":{"val":"1","id":"pi"},"slot":{"val":"3","id":"pi"}},"id":"ct"},{"val":{"item":{"val":"minecraft:wheat_seeds","id":"ss"},"damage":{"val":"0","id":"pi"},"quantity":{"val":"1","id":"pi"},"slot":{"val":"4","id":"pi"}},"id":"ct"},{"val":{"item":{"val":"minecraft:wheat_seeds","id":"ss"},"damage":{"val":"0","id":"pi"},"quantity":{"val":"1","id":"pi"},"slot":{"val":"5","id":"pi"}},"id":"ct"},{"val":{"item":{"val":"minecraft:wheat_seeds","id":"ss"},"damage":{"val":"0","id":"pi"},"quantity":{"val":"1","id":"pi"},"slot":{"val":"6","id":"pi"}},"id":"ct"},{"val":{"item":{"val":"minecraft:wheat_seeds","id":"ss"},"damage":{"val":"0","id":"pi"},"quantity":{"val":"1","id":"pi"},"slot":{"val":"7","id":"pi"}},"id":"ct"},{"val":{"item":{"val":"minecraft:wheat_seeds","id":"ss"},"damage":{"val":"0","id":"pi"},"quantity":{"val":"1","id":"pi"},"slot":{"val":"8","id":"pi"}},"id":"ct"},{"val":{"item":{"val":"minecraft:wheat_seeds","id":"ss"},"damage":{"val":"0","id":"pi"},"quantity":{"val":"1","id":"pi"},"slot":{"val":"9","id":"pi"}},"id":"ct"},{"val":{"item":{"val":"minecraft:wheat_seeds","id":"ss"},"damage":{"val":"0","id":"pi"},"quantity":{"val":"1","id":"pi"},"slot":{"val":"10","id":"pi"}},"id":"ct"},{"val":{"item":{"val":"minecraft:wheat_seeds","id":"ss"},"damage":{"val":"0","id":"pi"},"quantity":{"val":"1","id":"pi"},"slot":{"val":"11","id":"pi"}},"id":"ct"},{"val":{"item":{"val":"minecraft:wheat_seeds","id":"ss"},"damage":{"val":"0","id":"pi"},"quantity":{"val":"1","id":"pi"},"slot":{"val":"12","id":"pi"}},"id":"ct"},{"val":{"item":{"val":"minecraft:wheat_seeds","id":"ss"},"damage":{"val":"0","id":"pi"},"quantity":{"val":"1","id":"pi"},"slot":{"val":"13","id":"pi"}},"id":"ct"},{"val":{"item":{"val":"minecraft:wheat_seeds","id":"ss"},"damage":{"val":"0","id":"pi"},"quantity":{"val":"1","id":"pi"},"slot":{"val":"14","id":"pi"}},"id":"ct"},{"val":{"item":{"val":"minecraft:wheat_seeds","id":"ss"},"damage":{"val":"0","id":"pi"},"quantity":{"val":"1","id":"pi"},"slot":{"val":"15","id":"pi"}},"id":"ct"},{"val":{"item":{"val":"minecraft:wheat_seeds","id":"ss"},"damage":{"val":"0","id":"pi"},"quantity":{"val":"1","id":"pi"},"slot":{"val":"16","id":"pi"}},"id":"ct"},{"val":{"item":{"val":"minecraft:wheat_seeds","id":"ss"},"damage":{"val":"0","id":"pi"},"quantity":{"val":"1","id":"pi"},"slot":{"val":"17","id":"pi"}},"id":"ct"},{"val":{"item":{"val":"minecraft:wheat_seeds","id":"ss"},"damage":{"val":"0","id":"pi"},"quantity":{"val":"1","id":"pi"},"slot":{"val":"18","id":"pi"}},"id":"ct"},{"val":{"item":{"val":"minecraft:wheat_seeds","id":"ss"},"damage":{"val":"0","id":"pi"},"quantity":{"val":"1","id":"pi"},"slot":{"val":"19","id":"pi"}},"id":"ct"},{"val":{"item":{"val":"minecraft:wheat_seeds","id":"ss"},"damage":{"val":"0","id":"pi"},"quantity":{"val":"1","id":"pi"},"slot":{"val":"20","id":"pi"}},"id":"ct"},{"val":{"item":{"val":"minecraft:wheat_seeds","id":"ss"},"damage":{"val":"0","id":"pi"},"quantity":{"val":"1","id":"pi"},"slot":{"val":"21","id":"pi"}},"id":"ct"},{"val":{"item":{"val":"minecraft:wheat_seeds","id":"ss"},"damage":{"val":"0","id":"pi"},"quantity":{"val":"1","id":"pi"},"slot":{"val":"22","id":"pi"}},"id":"ct"},{"val":{"item":{"val":"minecraft:wheat_seeds","id":"ss"},"damage":{"val":"0","id":"pi"},"quantity":{"val":"1","id":"pi"},"slot":{"val":"23","id":"pi"}},"id":"ct"},{"val":{"item":{"val":"minecraft:wheat_seeds","id":"ss"},"damage":{"val":"0","id":"pi"},"quantity":{"val":"1","id":"pi"},"slot":{"val":"24","id":"pi"}},"id":"ct"},{"val":{"item":{"val":"minecraft:wheat_seeds","id":"ss"},"damage":{"val":"0","id":"pi"},"quantity":{"val":"1","id":"pi"},"slot":{"val":"25","id":"pi"}},"id":"ct"},{"val":{"item":{"val":"minecraft:wheat_seeds","id":"ss"},"damage":{"val":"0","id":"pi"},"quantity":{"val":"1","id":"pi"},"slot":{"val":"26","id":"pi"}},"id":"ct"}],"id":"ls"}},"id":"ct"},"teData":{"val":{"id":{"val":"Chest","id":"ss"},"z":{"val":"975","id":"pi"},"y":{"val":"75","id":"pi"},"x":{"val":"1541","id":"pi"}},"id":"ct"},"blockName":{"val":"minecraft:chest","id":"ss"},"meta":{"val":"4","id":"pi"},"buildPass":{"val":"0","id":"pi"}},"id":"ct"}}
:enddata
:endrule

rule:
plugin=vanillaBlocks
number=42
data:
JSON:{{"val":{"blockName":{"val":"minecraft:torch","id":"ss"},"meta":{"val":"1","id":"pi"},"buildPass":{"val":"2","id":"pi"}},"id":"ct"}}
:enddata
:endrule

rule:
plugin=vanillaBlocks
number=43
data:
JSON:{{"val":{"blockName":{"val":"minecraft:wooden_slab","id":"ss"},"meta":{"val":"8","id":"pi"},"buildPass":{"val":"0","id":"pi"}},"id":"ct"}}
:enddata
:endrule

rule:
plugin=vanillaBlocks
number=44
data:
JSON:{{"val":{"blockName":{"val":"minecraft:oak_stairs","id":"ss"},"meta":{"val":"6","id":"pi"},"buildPass":{"val":"0","id":"pi"}},"id":"ct"}}
:enddata
:endrule

rule:
plugin=vanillaBlocks
number=45
data:
JSON:{{"val":{"blockName":{"val":"minecraft:stone_stairs","id":"ss"},"meta":{"val":"0","id":"pi"},"buildPass":{"val":"0","id":"pi"}},"id":"ct"}}
:enddata
:endrule

rule:
plugin=vanillaBlocks
number=46
data:
JSON:{{"val":{"blockName":{"val":"minecraft:oak_stairs","id":"ss"},"meta":{"val":"5","id":"pi"},"buildPass":{"val":"0","id":"pi"}},"id":"ct"}}
:enddata
:endrule

rule:
plugin=vanillaBlocks
number=47
data:
JSON:{{"val":{"blockName":{"val":"minecraft:oak_stairs","id":"ss"},"meta":{"val":"4","id":"pi"},"buildPass":{"val":"0","id":"pi"}},"id":"ct"}}
:enddata
:endrule

rule:
plugin=vanillaBlocks
number=48
data:
JSON:{{"val":{"blockName":{"val":"minecraft:oak_stairs","id":"ss"},"meta":{"val":"2","id":"pi"},"buildPass":{"val":"0","id":"pi"}},"id":"ct"}}
:enddata
:endrule

rule:
plugin=vanillaBlocks
number=49
data:
JSON:{{"val":{"blockName":{"val":"minecraft:oak_stairs","id":"ss"},"meta":{"val":"0","id":"pi"},"buildPass":{"val":"0","id":"pi"}},"id":"ct"}}
:enddata
:endrule

rule:
plugin=vanillaBlocks
number=50
data:
JSON:{{"val":{"blockName":{"val":"minecraft:oak_stairs","id":"ss"},"meta":{"val":"1","id":"pi"},"buildPass":{"val":"0","id":"pi"}},"id":"ct"}}
:enddata
:endrule

rule:
plugin=vanillaBlocks
number=51
data:
JSON:{{"val":{"blockName":{"val":"minecraft:oak_stairs","id":"ss"},"meta":{"val":"3","id":"pi"},"buildPass":{"val":"0","id":"pi"}},"id":"ct"}}
:enddata
:endrule

rule:
plugin=vanillaBlocks
number=52
data:
JSON:{{"val":{"blockName":{"val":"minecraft:log","id":"ss"},"meta":{"val":"0","id":"pi"},"buildPass":{"val":"0","id":"pi"}},"id":"ct"}}
:enddata
:endrule

rule:
plugin=vanillaBlocks
number=53
data:
JSON:{{"val":{"blockName":{"val":"minecraft:double_stone_slab","id":"ss"},"meta":{"val":"2","id":"pi"},"buildPass":{"val":"0","id":"pi"}},"id":"ct"}}
:enddata
:endrule

rule:
plugin=vanillaBlocks
number=54
data:
JSON:{{"val":{"blockName":{"val":"minecraft:stone_slab","id":"ss"},"meta":{"val":"2","id":"pi"},"buildPass":{"val":"0","id":"pi"}},"id":"ct"}}
:enddata
:endrule

rule:
plugin=vanillaBlocks
number=55
data:
JSON:{{"val":{"blockName":{"val":"minecraft:planks","id":"ss"},"meta":{"val":"0","id":"pi"},"buildPass":{"val":"0","id":"pi"}},"id":"ct"}}
:enddata
:endrule

rule:
plugin=vanillaBlocks
number=56
data:
JSON:{{"val":{"blockName":{"val":"minecraft:stone_stairs","id":"ss"},"meta":{"val":"3","id":"pi"},"buildPass":{"val":"0","id":"pi"}},"id":"ct"}}
:enddata
:endrule

rule:
plugin=vanillaBlocks
number=57
data:
