# Ancient Warfare Structure Template File
# Auto-generated structure template file. created on: 1/5/2015 at: 12:16:55
# Lines beginning with # denote comments

header:
version=2.1
name=NewTownHall
size=40,51,44
offset=17,6,42
:endheader

#### VALIDATION ####
validation:
type=ground
survival=false
worldGenEnabled=false
unique=false
preserveBlocks=false
selectionWeight=0
clusterValue=0
minDuplicateDistance=0
dimensionWhiteList=false
dimensionList=
biomeWhiteList=false
biomeList=
leveling=0
fill=0
border=0
validTargetBlocks=
blockSwap=false
data:
:enddata
:endvalidation

#### LAYERS ####
layer: 0
1,1,1,1,1,1,1,1,1,1,1,1,1,1,1,1,1,1,1,1,1,1,1,1,1,1,1,1,1,1,1,1,1,1,1,1,1,1,1,1
1,1,1,1,1,1,1,1,1,1,1,1,1,1,1,1,1,1,1,1,1,1,1,1,1,1,1,1,1,1,1,1,1,1,1,1,1,1,1,1
1,1,1,1,1,1,1,1,1,1,1,1,1,1,1,1,1,1,1,1,1,1,1,1,1,1,1,1,1,1,1,1,1,1,1,1,1,1,1,1
1,1,1,1,1,1,1,1,1,1,1,1,1,1,1,1,1,1,1,1,1,1,1,1,1,1,1,1,1,1,1,1,1,1,1,1,1,1,1,1
1,1,1,1,1,1,1,1,1,1,1,1,1,1,1,1,1,1,1,1,1,1,1,1,1,1,1,1,1,1,1,1,1,1,1,1,1,1,1,1
1,1,1,1,1,1,1,1,1,1,1,1,1,1,1,1,1,1,1,1,1,1,1,1,1,1,1,1,1,1,1,1,1,1,1,1,1,1,1,1
1,1,1,1,1,1,1,1,1,1,1,1,1,1,1,1,1,1,1,1,1,1,1,1,1,1,1,1,1,1,1,1,1,1,1,1,1,1,1,1
1,1,1,1,1,1,1,1,1,1,1,1,1,1,1,1,1,1,1,1,1,1,1,1,1,1,1,1,1,1,1,1,1,1,1,1,1,1,1,1
1,1,1,1,1,1,1,1,1,1,1,1,1,1,1,1,1,1,1,1,1,1,1,1,1,1,1,1,1,1,1,1,1,1,1,1,1,1,1,1
1,1,1,1,1,1,1,1,1,1,1,1,1,1,1,1,1,1,1,1,1,1,1,1,1,1,1,1,1,1,1,1,1,1,1,1,1,1,1,1
1,1,1,1,1,1,1,1,1,1,1,1,1,1,1,1,1,1,1,1,1,1,1,1,1,1,1,1,1,1,1,1,1,1,1,1,1,1,1,1
1,1,1,1,1,1,1,1,1,1,1,1,1,1,1,1,1,1,1,1,1,1,1,1,1,1,1,1,1,1,1,1,1,1,1,1,1,1,1,1
1,1,1,1,1,1,1,1,1,1,1,1,1,1,1,1,1,1,1,1,1,1,1,1,1,1,1,1,1,1,1,1,1,1,1,1,1,1,1,1
1,1,1,1,1,1,1,1,1,1,1,1,1,1,1,1,1,1,1,1,1,1,1,1,1,1,1,1,1,1,1,1,1,1,1,1,1,1,1,1
1,1,1,1,1,1,1,1,1,1,1,1,1,1,1,1,1,1,1,1,1,1,1,1,1,1,1,1,1,1,1,1,1,1,1,1,1,1,1,1
1,1,1,1,1,1,1,1,1,1,1,1,1,1,1,1,1,1,1,1,1,1,1,1,1,1,1,1,1,1,1,1,1,1,1,1,1,1,1,1
1,1,1,1,1,1,1,1,1,1,1,1,1,1,1,1,1,1,1,1,1,1,1,1,1,1,1,1,1,1,1,1,1,1,1,1,1,1,1,1
1,1,1,1,1,1,1,1,1,1,1,1,1,1,1,1,1,1,1,1,1,1,1,1,1,1,1,1,1,1,1,1,1,1,1,1,1,1,1,1
1,1,1,1,1,1,1,1,1,1,1,1,1,1,1,1,1,1,1,1,1,1,1,1,1,1,1,1,1,1,1,1,1,1,1,1,1,1,1,1
1,1,1,1,1,1,1,1,1,1,1,1,1,1,1,1,1,1,1,1,1,1,1,1,1,1,1,1,1,1,1,1,1,1,1,1,1,1,1,1
1,1,1,1,1,1,1,1,1,1,1,1,1,1,1,1,1,1,1,1,1,1,1,1,1,1,1,1,1,1,1,1,1,1,1,1,1,1,1,1
1,1,1,1,1,1,1,1,1,1,1,1,1,1,1,1,1,1,1,1,1,1,1,1,1,1,1,1,1,1,1,1,1,1,1,1,1,1,1,1
1,1,1,1,1,1,1,1,1,1,1,1,1,1,1,1,1,1,1,1,1,1,1,1,1,1,1,1,1,1,1,1,1,1,1,1,1,1,1,1
1,1,1,1,1,1,1,1,1,1,1,1,1,1,1,1,1,1,1,1,1,1,1,1,1,1,1,1,1,1,1,1,1,1,1,1,1,1,1,1
1,1,1,1,1,1,1,1,1,1,1,1,1,1,1,1,1,1,1,1,1,1,1,1,1,1,1,1,1,1,1,1,1,1,1,1,1,1,1,1
1,1,1,1,1,1,1,1,1,1,1,1,1,1,1,1,1,1,1,1,1,1,1,1,1,1,1,1,1,1,1,1,1,1,1,1,1,1,1,1
1,1,1,1,1,1,1,1,1,1,1,1,1,1,1,1,1,1,1,1,1,1,1,1,1,1,1,1,1,1,1,1,1,1,1,1,1,1,1,1
1,1,1,1,1,1,1,1,1,1,1,1,1,1,1,1,1,1,1,1,1,1,1,1,1,1,1,1,1,1,1,1,1,1,1,1,1,1,1,1
1,1,1,1,1,1,1,1,1,1,1,1,1,1,1,1,1,1,1,1,1,1,1,1,1,1,1,1,1,1,1,1,1,1,1,1,1,1,1,1
1,1,1,1,1,1,1,1,1,1,1,1,1,1,1,1,1,1,1,1,1,1,1,1,1,1,1,1,1,1,1,1,1,1,1,1,1,1,1,1
1,1,1,1,1,1,1,1,1,1,1,1,1,1,1,1,1,1,1,1,1,1,1,1,1,1,1,1,1,1,1,1,1,1,1,1,1,1,1,1
1,1,1,1,1,1,1,1,1,1,1,1,1,1,1,1,1,1,1,1,1,1,1,1,1,1,1,1,1,1,1,1,1,1,1,1,1,1,1,1
1,1,1,1,1,1,1,1,1,1,1,1,1,1,1,1,1,1,1,1,1,1,1,1,1,1,1,1,1,1,1,1,1,1,1,1,1,1,1,1
1,1,1,1,1,1,1,1,1,1,1,1,1,1,1,1,1,1,1,1,1,1,1,1,1,1,1,1,1,1,1,1,1,1,1,1,1,1,1,1
1,1,1,1,1,1,1,1,1,1,1,1,1,1,1,1,1,1,1,1,1,1,1,1,1,1,1,1,1,1,1,1,1,1,1,1,1,1,1,1
1,1,1,1,1,1,1,1,1,1,1,1,1,1,1,1,1,1,1,1,1,1,1,1,1,1,1,1,1,1,1,1,1,1,1,1,1,1,1,1
1,1,1,1,1,1,1,1,1,1,1,1,1,1,1,1,1,1,1,1,1,1,1,1,1,1,1,1,1,1,1,1,1,1,1,1,1,1,1,1
1,1,1,1,1,1,1,1,1,1,1,1,1,1,1,1,1,1,1,1,1,1,1,1,1,1,1,1,1,1,1,1,1,1,1,1,1,1,1,1
1,1,1,1,1,1,1,1,1,1,1,1,1,1,1,1,1,1,1,1,1,1,1,1,1,1,1,1,1,1,1,1,1,1,1,1,1,1,1,1
1,1,1,1,1,1,1,1,1,1,1,1,1,1,1,1,1,1,1,1,1,1,1,1,1,1,1,1,1,1,1,1,1,1,1,1,1,1,1,1
1,1,1,1,1,1,1,1,1,1,1,1,1,1,1,1,1,1,1,1,1,1,1,1,1,1,1,1,1,1,1,1,1,1,1,1,1,1,1,1
1,1,1,1,1,1,1,1,1,1,1,1,1,1,1,1,1,1,1,1,1,1,1,1,1,1,1,1,1,1,1,1,1,1,1,1,1,1,1,1
1,1,1,1,1,1,1,1,1,1,1,1,1,1,1,1,1,1,1,1,1,1,1,1,1,1,1,1,1,1,1,1,1,1,1,1,1,1,1,1
1,1,1,1,1,1,1,1,1,1,1,1,1,1,1,1,1,1,1,1,1,1,1,1,1,1,1,1,1,1,1,1,1,1,1,1,1,1,1,1
:endlayer
layer: 1
1,1,1,1,1,1,1,1,1,1,1,1,1,1,1,1,1,1,1,1,1,1,1,1,1,1,1,1,1,1,1,1,1,1,1,1,1,1,1,1
1,1,1,1,1,1,1,1,1,1,1,1,1,1,1,1,1,1,1,1,1,1,1,1,1,1,1,1,1,1,1,1,1,1,1,1,1,1,1,1
1,1,1,1,1,1,1,1,1,1,1,1,1,1,1,1,1,1,1,1,1,1,1,1,1,1,1,1,1,1,1,1,1,1,1,1,1,1,1,1
1,1,1,1,1,1,1,1,1,1,1,1,1,1,1,1,1,1,1,1,1,1,1,1,1,1,1,1,1,1,1,1,1,1,1,1,1,1,1,1
1,1,1,1,1,1,1,1,1,1,1,1,1,1,1,1,1,1,1,1,1,1,1,1,1,1,1,1,1,1,1,1,1,1,1,1,1,1,1,1
1,1,1,1,1,1,1,1,1,1,1,1,1,1,1,1,1,1,1,1,1,1,1,1,1,1,1,1,1,1,1,1,1,1,1,1,1,1,1,1
1,1,1,1,1,1,1,1,1,1,1,1,1,1,1,1,1,1,1,1,1,1,1,1,1,1,1,1,1,1,1,1,1,1,1,1,1,1,1,1
1,1,1,1,1,1,1,1,1,1,1,1,1,1,1,1,1,1,1,1,1,1,1,1,1,1,1,1,1,1,1,1,1,1,1,1,1,1,1,1
1,1,1,1,1,1,1,1,1,1,1,1,1,1,1,1,1,1,1,1,1,1,1,1,1,1,1,1,1,1,1,1,1,1,1,1,1,1,1,1
1,1,1,1,1,1,1,1,1,1,1,1,1,1,1,1,1,1,1,1,1,1,1,1,1,1,1,1,1,1,1,1,1,1,1,1,1,1,1,1
1,1,1,1,1,1,1,1,1,1,1,1,1,1,1,1,1,1,1,1,1,1,1,1,1,1,1,1,1,1,1,1,1,1,1,1,1,1,1,1
1,1,1,1,1,1,1,1,1,1,1,1,1,1,1,1,1,1,1,1,1,1,1,1,1,1,1,1,1,1,1,1,1,1,1,1,1,1,1,1
1,1,1,1,1,1,1,1,1,1,1,1,1,1,1,1,1,1,1,1,1,1,1,1,1,1,1,1,1,1,1,1,1,1,1,1,1,1,1,1
1,1,1,1,1,1,1,1,1,1,1,1,1,1,1,1,1,1,1,1,1,1,1,1,1,1,1,1,1,1,1,1,1,1,1,1,1,1,1,1
1,1,1,1,1,1,1,1,1,1,1,1,1,1,1,1,1,1,1,1,1,1,1,1,1,1,1,1,1,1,1,1,1,1,1,1,1,1,1,1
1,1,1,1,1,1,1,1,1,1,1,1,1,1,1,1,1,1,1,1,1,1,1,1,1,1,1,1,1,1,1,1,1,1,1,1,1,1,1,1
1,1,1,1,1,1,1,1,1,1,1,1,1,1,1,1,1,1,1,1,1,1,1,1,1,1,1,1,1,1,1,1,1,1,1,1,1,1,1,1
1,1,1,1,1,1,1,1,1,1,1,1,1,1,1,1,1,1,1,1,1,1,1,1,1,1,1,1,1,1,1,1,1,1,1,1,1,1,1,1
1,1,1,1,1,1,1,1,1,1,1,1,1,1,1,1,1,1,1,1,1,1,1,1,1,1,1,1,1,1,1,1,1,1,1,1,1,1,1,1
1,1,1,1,1,1,1,1,1,1,1,1,1,1,1,1,1,1,1,1,1,1,1,1,1,1,1,1,1,1,1,1,1,1,1,1,1,1,1,1
1,1,1,1,1,1,1,1,1,1,1,1,1,1,1,1,1,1,1,1,1,1,1,1,1,1,1,1,1,1,1,1,1,1,1,1,1,1,1,1
1,1,1,1,1,1,1,1,1,1,1,1,1,1,1,1,1,1,1,1,1,1,1,1,1,1,1,1,1,1,1,1,1,1,1,1,1,1,1,1
1,1,1,1,1,1,1,1,1,1,1,1,1,1,1,1,1,1,1,1,1,1,1,1,1,1,1,1,1,1,1,1,1,1,1,1,1,1,1,1
1,1,1,1,1,1,1,1,1,1,1,1,1,1,1,1,1,1,1,1,1,1,1,1,1,1,1,1,1,1,1,1,1,1,1,1,1,1,1,1
1,1,1,1,1,1,1,1,1,1,1,1,1,1,1,1,1,1,1,1,1,1,1,1,1,1,1,1,1,1,1,1,1,1,1,1,1,1,1,1
1,1,1,1,1,1,1,1,1,1,1,1,1,1,1,1,1,1,1,1,1,1,1,1,1,1,1,1,1,1,1,1,1,1,1,1,1,1,1,1
1,1,1,1,1,1,1,1,1,1,1,1,1,1,1,1,1,1,1,1,1,1,1,1,1,1,1,1,1,1,1,1,1,1,1,1,1,1,1,1
1,1,1,1,1,1,1,1,1,1,1,1,1,1,1,1,1,1,1,1,1,1,1,1,1,1,1,1,1,1,1,1,1,1,1,1,1,1,1,1
1,1,1,1,1,1,1,1,1,1,1,1,1,1,1,1,1,1,1,1,1,1,1,1,1,1,1,1,1,1,1,1,1,1,1,1,1,1,1,1
1,1,1,1,1,1,1,1,1,1,1,1,1,1,1,1,1,1,1,1,1,1,1,1,1,1,1,1,1,1,1,1,1,1,1,1,1,1,1,1
1,1,1,1,1,1,1,1,1,1,1,1,1,1,1,1,1,1,1,1,1,1,1,1,1,1,1,1,1,1,1,1,1,1,1,1,1,1,1,1
1,1,1,1,1,1,1,1,1,1,1,1,1,1,1,1,1,1,1,1,1,1,1,1,1,1,1,1,1,1,1,1,1,1,1,1,1,1,1,1
1,1,1,1,1,1,1,1,1,1,1,1,1,1,1,1,1,1,1,1,1,1,1,1,1,1,1,1,1,1,1,1,1,1,1,1,1,1,1,1
1,1,1,1,1,1,1,1,1,1,1,1,1,1,1,1,1,1,1,1,1,1,1,1,1,1,1,1,1,1,1,1,1,1,1,1,1,1,1,1
1,1,1,1,1,1,1,1,1,1,1,1,1,1,1,1,1,1,1,1,1,1,1,1,1,1,1,1,1,1,1,1,1,1,1,1,1,1,1,1
1,1,1,1,1,1,1,1,1,1,1,1,1,1,1,1,1,1,1,1,1,1,1,1,1,1,1,1,1,1,1,1,1,1,1,1,1,1,1,1
1,1,1,1,1,1,1,1,1,1,1,1,1,1,1,1,1,1,1,1,1,1,1,1,1,1,1,1,1,1,1,1,1,1,1,1,1,1,1,1
1,1,1,1,1,1,1,1,1,1,1,1,1,1,1,1,1,1,1,1,1,1,1,1,1,1,1,1,1,1,1,1,1,1,1,1,1,1,1,1
1,1,1,1,1,1,1,1,1,1,1,1,1,1,1,1,1,1,1,1,1,1,1,1,1,1,1,1,1,1,1,1,1,1,1,1,1,1,1,1
1,1,1,1,1,1,1,1,1,1,1,1,1,1,1,1,1,1,1,1,1,1,1,1,1,1,1,1,1,1,1,1,1,1,1,1,1,1,1,1
1,1,1,1,1,1,1,1,1,1,1,1,1,1,1,1,1,1,1,1,1,1,1,1,1,1,1,1,1,1,1,1,1,1,1,1,1,1,1,1
1,1,1,1,1,1,1,1,1,1,1,1,1,1,1,1,1,1,1,1,1,1,1,1,1,1,1,1,1,1,1,1,1,1,1,1,1,1,1,1
1,1,1,1,1,1,1,1,1,1,1,1,1,1,1,1,1,1,1,1,1,1,1,1,1,1,1,1,1,1,1,1,1,1,1,1,1,1,1,1
1,1,1,1,1,1,1,1,1,1,1,1,1,1,1,1,1,1,1,1,1,1,1,1,1,1,1,1,1,1,1,1,1,1,1,1,1,1,1,1
:endlayer
layer: 2
1,1,1,1,1,1,1,1,1,1,1,1,1,1,1,1,1,1,1,1,1,1,1,1,1,1,1,1,1,1,1,1,1,1,1,1,1,1,1,1
1,1,1,1,1,1,1,1,1,1,1,1,1,1,1,1,1,1,1,1,1,1,1,1,1,1,1,1,1,1,1,1,1,1,1,1,1,1,1,1
1,1,1,1,1,1,1,1,1,1,1,1,1,1,1,1,1,1,1,1,1,1,1,1,1,1,1,1,1,1,1,1,1,1,1,1,1,1,1,1
1,1,1,1,1,1,1,1,1,1,1,1,1,1,1,1,1,1,1,1,1,1,1,1,1,1,1,1,1,1,1,1,1,1,1,1,1,1,1,1
1,1,1,1,1,1,1,1,1,1,1,1,1,1,1,1,1,1,1,1,1,1,1,1,1,1,1,1,1,1,1,1,1,1,1,1,1,1,1,1
1,1,1,1,1,1,1,1,1,1,1,1,1,1,1,1,1,1,1,1,1,1,1,1,1,1,1,1,1,1,1,1,1,1,1,1,1,1,1,1
1,1,1,1,1,1,1,1,1,1,1,1,1,1,1,1,1,1,1,1,1,1,1,1,1,1,1,1,1,1,1,1,1,1,1,1,1,1,1,1
1,1,1,1,1,1,1,1,1,1,1,1,1,1,1,1,1,1,1,1,1,1,1,1,1,1,1,1,1,1,1,1,1,1,1,1,1,1,1,1
1,1,1,1,1,1,1,1,1,1,1,1,1,1,1,1,1,1,1,1,1,1,1,1,1,1,1,1,1,1,1,1,1,1,1,1,1,1,1,1
1,1,1,1,1,1,1,1,1,1,1,1,1,1,1,1,1,1,1,1,1,1,1,1,1,1,1,1,1,1,1,1,1,1,1,1,1,1,1,1
1,1,1,1,1,1,1,1,1,1,1,1,1,1,1,1,1,1,1,1,1,1,1,1,1,1,1,1,1,1,1,1,1,1,1,1,1,1,1,1
1,1,1,1,1,1,1,1,1,1,1,1,1,1,1,1,1,1,1,1,1,1,1,1,1,1,1,1,1,1,1,1,1,1,1,1,1,1,1,1
1,1,1,1,1,1,1,1,1,1,1,1,1,1,1,1,1,1,1,1,1,1,1,1,1,1,1,1,1,1,1,1,1,1,1,1,1,1,1,1
1,1,1,1,1,1,1,1,1,1,1,1,1,1,1,1,1,1,1,1,1,1,1,1,1,1,1,1,1,1,1,1,1,1,1,1,1,1,1,1
1,1,1,1,1,1,1,1,1,1,1,1,1,1,1,1,1,1,1,1,1,1,1,1,1,1,1,1,1,1,1,1,1,1,1,1,1,1,1,1
1,1,1,1,1,1,1,1,1,1,1,1,1,1,1,1,1,1,1,1,1,1,1,1,1,1,1,1,1,1,1,1,1,1,1,1,1,1,1,1
1,1,1,1,1,1,1,1,1,1,1,1,1,1,1,1,1,1,1,1,1,1,1,1,1,1,1,1,1,1,1,1,1,1,1,1,1,1,1,1
1,1,1,1,1,1,1,1,1,1,1,1,1,1,1,1,1,1,1,1,1,1,1,1,1,1,1,1,1,1,1,1,1,1,1,1,1,1,1,1
1,1,1,1,1,1,1,1,1,1,1,1,1,1,1,1,1,1,1,1,1,1,1,1,1,1,1,1,1,1,1,1,1,1,1,1,1,1,1,1
1,1,1,1,1,1,1,1,1,1,1,1,1,1,1,1,1,1,1,1,1,1,1,1,1,1,1,1,1,1,1,1,1,1,1,1,1,1,1,1
1,1,1,1,1,1,1,1,1,1,1,1,1,1,1,1,1,1,1,1,1,1,1,1,1,1,1,1,1,1,1,1,1,1,1,1,1,1,1,1
1,1,1,1,1,1,1,1,1,1,1,1,1,1,1,1,1,1,1,1,1,1,1,1,1,1,1,1,1,1,1,1,1,1,1,1,1,1,1,1
1,1,1,1,1,1,1,1,1,1,1,1,1,1,1,1,1,1,1,1,1,1,1,1,1,1,1,1,1,1,1,1,1,1,1,1,1,1,1,1
1,1,1,1,1,1,1,1,1,1,1,1,1,1,1,1,1,1,1,1,1,1,1,1,1,1,1,1,1,1,1,1,1,1,1,1,1,1,1,1
1,1,1,1,1,1,1,1,1,1,1,1,1,1,1,1,1,1,1,1,1,1,1,1,1,1,1,1,1,1,1,1,1,1,1,1,1,1,1,1
1,1,1,1,1,1,1,1,1,1,1,1,1,1,1,1,1,1,1,1,1,1,1,1,1,1,1,1,1,1,1,1,1,1,1,1,1,1,1,1
1,1,1,1,1,1,1,1,1,1,1,1,1,1,1,1,1,1,1,1,1,1,1,1,1,1,1,1,1,1,1,1,1,1,1,1,1,1,1,1
1,1,1,1,1,1,1,1,1,1,1,1,1,1,1,1,1,1,1,1,1,1,1,1,1,1,1,1,1,1,1,1,1,1,1,1,1,1,1,1
1,1,1,1,1,1,1,1,1,1,1,1,1,1,1,1,1,1,1,1,1,1,1,1,1,1,1,1,1,1,1,1,1,1,1,1,1,1,1,1
1,1,1,1,1,1,1,1,1,1,1,1,1,1,1,1,1,1,1,1,1,1,1,1,1,1,1,1,1,1,1,1,1,1,1,1,1,1,1,1
1,1,1,1,1,1,1,1,1,1,1,1,1,1,1,1,1,1,1,1,1,1,1,1,1,1,1,1,1,1,1,1,1,1,1,1,1,1,1,1
1,1,1,1,1,1,1,1,1,1,1,1,1,1,1,1,1,1,1,1,1,1,1,1,1,1,1,1,1,1,1,1,1,1,1,1,1,1,1,1
1,1,1,1,1,1,1,1,1,1,1,1,1,1,1,1,1,1,1,1,1,1,1,1,1,1,1,1,1,1,1,1,1,1,1,1,1,1,1,1
1,1,1,1,1,1,1,1,1,1,1,1,1,1,1,1,1,1,1,1,1,1,1,1,1,1,1,1,1,1,1,1,1,1,1,1,1,1,1,1
1,1,1,1,1,1,1,1,1,1,1,1,1,1,1,1,1,1,1,1,1,1,1,1,1,1,1,1,1,1,1,1,1,1,1,1,1,1,1,1
1,1,1,1,1,1,1,1,1,1,1,1,1,1,1,1,1,1,1,1,1,1,1,1,1,1,1,1,1,1,1,1,1,1,1,1,1,1,1,1
1,1,1,1,1,1,1,1,1,1,1,1,1,1,1,1,1,1,1,1,1,1,1,1,1,1,1,1,1,1,1,1,1,1,1,1,1,1,1,1
1,1,1,1,1,1,1,1,1,1,1,1,1,1,1,1,1,1,1,1,1,1,1,1,1,1,1,1,1,1,1,1,1,1,1,1,1,1,1,1
1,1,1,1,1,1,1,1,1,1,1,1,1,1,1,1,1,1,1,1,1,1,1,1,1,1,1,1,1,1,1,1,1,1,1,1,1,1,1,1
1,1,1,1,1,1,1,1,1,1,1,1,1,1,1,1,1,1,1,1,1,1,1,1,1,1,1,1,1,1,1,1,1,1,1,1,1,1,1,1
1,1,1,1,1,1,1,1,1,1,1,1,1,1,1,1,1,1,1,1,1,1,1,1,1,1,1,1,1,1,1,1,1,1,1,1,1,1,1,1
1,1,1,1,1,1,1,1,1,1,1,1,1,1,1,1,1,1,1,1,1,1,1,1,1,1,1,1,1,1,1,1,1,1,1,1,1,1,1,1
1,1,1,1,1,1,1,1,1,1,1,1,1,1,1,1,1,1,1,1,1,1,1,1,1,1,1,1,1,1,1,1,1,1,1,1,1,1,1,1
1,1,1,1,1,1,1,1,1,1,1,1,1,1,1,1,1,1,1,1,1,1,1,1,1,1,1,1,1,1,1,1,1,1,1,1,1,1,1,1
:endlayer
layer: 3
1,1,1,1,1,1,1,1,1,1,1,1,1,1,1,1,1,1,1,1,1,1,1,1,1,1,1,1,1,1,1,1,1,1,1,1,1,1,1,1
1,1,1,1,1,1,1,1,1,1,1,1,1,1,1,1,1,1,1,1,1,1,1,1,1,1,1,1,1,1,1,1,1,1,1,1,1,1,1,1
1,1,1,1,1,1,1,1,1,1,1,1,1,1,1,1,1,1,1,1,1,1,1,1,1,1,1,1,1,1,1,1,1,1,1,1,1,1,1,1
1,1,1,1,1,1,1,1,1,1,1,1,1,1,1,1,1,1,1,1,1,1,1,1,1,1,1,1,1,1,1,1,1,1,1,1,1,1,1,1
1,1,1,1,1,1,1,1,1,1,1,1,1,1,1,1,1,1,1,1,1,1,1,1,1,1,1,1,1,1,1,1,1,1,1,1,1,1,1,1
1,1,1,1,1,1,1,1,1,1,1,1,1,1,1,1,1,1,1,1,1,1,1,1,1,1,1,1,1,1,1,1,1,1,1,1,1,1,1,1
1,1,1,1,1,1,1,1,1,1,1,1,1,1,1,1,1,1,1,1,1,1,1,1,1,1,1,1,1,1,1,1,1,1,1,1,1,1,1,1
1,1,1,1,1,1,1,1,1,1,1,1,1,1,1,1,1,1,1,1,1,1,1,1,1,1,1,1,1,1,1,1,1,1,1,1,1,1,1,1
1,1,1,1,1,1,1,1,1,1,1,1,1,1,1,1,1,1,1,1,1,1,1,1,1,1,1,1,1,1,1,1,1,1,1,1,1,1,1,1
1,1,1,1,1,1,1,1,1,1,1,1,1,1,1,1,1,1,1,1,1,1,1,1,1,1,1,1,1,1,1,1,1,1,1,1,1,1,1,1
1,1,1,1,1,1,1,1,1,1,1,1,1,1,1,1,1,1,1,1,1,1,1,1,1,1,1,1,1,1,1,1,1,1,1,1,1,1,1,1
1,1,1,1,1,1,1,1,1,1,1,1,1,1,1,1,1,1,1,1,1,1,1,1,1,1,1,1,1,1,1,1,1,1,1,1,1,1,1,1
1,1,1,1,1,1,1,1,1,1,1,1,1,1,1,1,1,1,1,1,1,1,1,1,1,1,1,1,1,1,1,1,1,1,1,1,1,1,1,1
1,1,1,1,1,1,1,1,1,1,1,1,1,1,1,1,1,1,1,1,1,1,1,1,1,1,1,1,1,1,1,1,1,1,1,1,1,1,1,1
1,1,1,1,1,1,1,1,1,1,1,1,1,1,1,1,1,1,1,1,1,1,1,1,1,1,1,1,1,1,1,1,1,1,1,1,1,1,1,1
1,1,1,1,1,1,1,1,1,1,1,1,1,1,1,1,1,1,1,1,1,1,1,1,1,1,1,1,1,1,1,1,1,1,1,1,1,1,1,1
1,1,1,1,1,1,1,1,1,1,1,1,1,1,1,1,1,1,1,1,1,1,1,1,1,1,1,1,1,1,1,1,1,1,1,1,1,1,1,1
1,1,1,1,1,1,1,1,1,1,1,1,1,1,1,1,1,1,1,1,1,1,1,1,1,1,1,1,1,1,1,1,1,1,1,1,1,1,1,1
1,1,1,1,1,1,1,1,1,1,1,1,1,1,1,1,1,1,1,1,1,1,1,1,1,1,1,1,1,1,1,1,1,1,1,1,1,1,1,1
1,1,1,1,1,1,1,1,1,1,1,1,1,1,1,1,1,1,1,1,1,1,1,1,1,1,1,1,1,1,1,1,1,1,1,1,1,1,1,1
1,1,1,1,1,1,1,1,1,1,1,1,1,1,1,1,1,1,1,1,1,1,1,1,1,1,1,1,1,1,1,1,1,1,1,1,1,1,1,1
1,1,1,1,1,1,1,1,1,1,1,1,1,1,1,1,1,1,1,1,1,1,1,1,1,1,1,1,1,1,1,1,1,1,1,1,1,1,1,1
1,1,1,1,1,1,1,1,1,1,1,1,1,1,1,1,1,1,1,1,1,1,1,1,1,1,1,1,1,1,1,1,1,1,1,1,1,1,1,1
1,1,1,1,1,1,1,1,1,1,1,1,1,1,1,1,1,1,1,1,1,1,1,1,1,1,1,1,1,1,1,1,1,1,1,1,1,1,1,1
1,1,1,1,1,1,1,1,1,1,1,1,1,1,1,1,1,1,1,1,1,1,1,1,1,1,1,1,1,1,1,1,1,1,1,1,1,1,1,1
1,1,1,1,1,1,1,1,1,1,1,1,1,1,1,1,1,1,1,1,1,1,1,1,1,1,1,1,1,1,1,1,1,1,1,1,1,1,1,1
1,1,1,1,1,1,1,1,1,1,1,1,1,1,1,1,1,1,1,1,1,1,1,1,1,1,1,1,1,1,1,1,1,1,1,1,1,1,1,1
1,1,1,1,1,1,1,1,1,1,1,1,1,1,1,1,1,1,1,1,1,1,1,1,1,1,1,1,1,1,1,1,1,1,1,1,1,1,1,1
1,1,1,1,1,1,1,1,1,1,1,1,1,1,1,1,1,1,1,1,1,1,1,1,1,1,1,1,1,1,1,1,1,1,1,1,1,1,1,1
1,1,1,1,1,1,1,1,1,1,1,1,1,1,1,1,1,1,1,1,1,1,1,1,1,1,1,1,1,1,1,1,1,1,1,1,1,1,1,1
1,1,1,1,1,1,1,1,1,1,1,1,1,1,1,1,1,1,1,1,1,1,1,1,1,1,1,1,1,1,1,1,1,1,1,1,1,1,1,1
1,1,1,1,1,1,1,1,1,1,1,1,1,1,1,1,1,1,1,1,1,1,1,1,1,1,1,1,1,1,1,1,1,1,1,1,1,1,1,1
1,1,1,1,1,1,1,1,1,1,1,1,1,1,1,1,1,1,1,1,1,1,1,1,1,1,1,1,1,1,1,1,1,1,1,1,1,1,1,1
1,1,1,1,1,1,1,1,1,1,1,1,1,1,1,1,1,1,1,1,1,1,1,1,1,1,1,1,1,1,1,1,1,1,1,1,1,1,1,1
1,1,1,1,1,1,1,1,1,1,1,1,1,1,1,1,1,1,1,1,1,1,1,1,1,1,1,1,1,1,1,1,1,1,1,1,1,1,1,1
1,1,1,1,1,1,1,1,1,1,1,1,1,1,1,1,1,1,1,1,1,1,1,1,1,1,1,1,1,1,1,1,1,1,1,1,1,1,1,1
1,1,1,1,1,1,1,1,1,1,1,1,1,1,1,1,1,1,1,1,1,1,1,1,1,1,1,1,1,1,1,1,1,1,1,1,1,1,1,1
1,1,1,1,1,1,1,1,1,1,1,1,1,1,1,1,1,1,1,1,1,1,1,1,1,1,1,1,1,1,1,1,1,1,1,1,1,1,1,1
1,1,1,1,1,1,1,1,1,1,1,1,1,1,1,1,1,1,1,1,1,1,1,1,1,1,1,1,1,1,1,1,1,1,1,1,1,1,1,1
1,1,1,1,1,1,1,1,1,1,1,1,1,1,1,1,1,1,1,1,1,1,1,1,1,1,1,1,1,1,1,1,1,1,1,1,1,1,1,1
1,1,1,1,1,1,1,1,1,1,1,1,1,1,1,1,1,1,1,1,1,1,1,1,1,1,1,1,1,1,1,1,1,1,1,1,1,1,1,1
1,1,1,1,1,1,1,1,1,1,1,1,1,1,1,1,1,1,1,1,1,1,1,1,1,1,1,1,1,1,1,1,1,1,1,1,1,1,1,1
1,1,1,1,1,1,1,1,1,1,1,1,1,1,1,1,1,1,1,1,1,1,1,1,1,1,1,1,1,1,1,1,1,1,1,1,1,1,1,1
1,1,1,1,1,1,1,1,1,1,1,1,1,1,1,1,1,1,1,1,1,1,1,1,1,1,1,1,1,1,1,1,1,1,1,1,1,1,1,1
:endlayer
layer: 4
1,1,1,1,1,1,1,1,1,1,1,1,1,1,1,1,1,1,1,1,1,1,1,1,1,1,1,1,1,1,1,1,1,1,1,1,1,1,1,3
1,1,1,1,1,1,1,1,1,1,1,1,1,1,1,1,1,1,1,1,1,1,1,1,1,1,1,1,1,1,1,1,1,1,1,1,1,1,1,3
1,1,1,1,1,1,1,1,1,1,1,1,1,1,1,1,1,1,1,1,1,1,1,1,1,1,1,1,1,1,1,1,1,1,1,1,1,1,1,3
1,1,1,1,1,1,1,1,1,1,1,1,1,1,1,1,1,1,1,1,1,1,1,1,1,1,1,1,1,1,1,1,1,1,1,1,1,1,1,3
1,1,1,1,1,1,1,1,1,1,1,1,1,1,1,1,1,1,1,1,1,1,1,1,1,1,1,1,1,1,1,1,1,1,1,1,1,1,1,3
1,1,1,1,1,1,1,1,1,1,1,1,1,1,1,1,1,1,1,1,1,1,1,1,1,1,1,1,1,1,1,1,1,1,1,1,1,1,1,3
1,1,1,1,1,1,1,1,1,1,1,1,1,1,1,1,1,1,1,1,1,1,1,1,1,1,1,1,1,1,1,1,1,1,1,1,1,1,1,3
1,1,1,1,1,1,1,1,1,1,1,1,1,1,1,1,1,1,1,1,1,1,1,1,1,1,1,1,1,1,1,1,1,1,1,1,1,1,1,3
1,1,1,1,1,1,1,1,1,1,1,1,1,1,1,1,1,1,1,1,1,1,1,1,1,1,1,1,1,1,1,1,1,1,1,1,1,1,1,3
1,1,1,1,1,1,1,1,1,1,1,1,1,1,1,1,1,1,1,1,1,1,1,1,1,1,1,1,1,1,1,1,1,1,1,1,1,1,1,3
1,1,1,1,1,1,1,1,1,1,1,1,1,1,1,1,1,1,1,1,1,1,1,1,1,1,1,1,1,1,1,1,1,1,1,1,1,1,1,3
1,1,1,1,1,1,1,1,1,1,1,1,1,1,1,1,1,1,1,1,1,1,1,1,1,1,1,1,1,1,1,1,1,1,1,1,1,1,1,3
1,1,1,1,1,1,1,1,1,1,1,1,1,1,1,1,1,1,1,1,1,1,1,1,1,1,1,1,1,1,1,1,1,1,1,1,1,1,1,3
1,1,1,1,1,1,1,1,1,1,1,1,1,1,1,1,1,1,1,1,1,1,1,1,1,1,1,1,1,1,1,1,1,1,1,1,1,1,1,3
1,1,1,1,1,1,1,1,1,1,1,1,1,1,1,1,1,1,1,1,1,1,1,1,1,1,1,1,1,1,1,1,1,1,1,1,1,1,1,3
1,1,1,1,1,1,1,1,1,1,1,1,1,1,1,1,1,1,1,1,1,1,1,1,1,1,1,1,1,1,1,1,1,1,1,1,1,1,1,3
1,1,1,1,1,1,1,1,1,1,1,1,1,1,1,1,1,1,1,1,1,1,1,1,1,1,1,1,1,1,1,1,1,1,1,1,1,1,1,3
1,1,1,1,1,1,1,1,1,1,1,1,1,1,1,1,1,1,1,1,1,1,1,1,1,1,1,1,1,1,1,1,1,1,1,1,1,1,1,3
1,1,1,1,1,1,1,1,1,1,1,1,1,1,1,1,1,1,1,1,1,1,1,1,1,1,1,1,1,1,1,1,1,1,1,1,1,1,1,3
1,1,1,1,1,1,1,1,1,1,1,1,1,1,1,1,1,1,1,1,1,1,1,1,1,1,1,1,1,1,1,1,1,1,1,1,1,1,1,3
1,1,1,1,1,1,1,1,1,1,1,1,1,1,1,1,1,1,1,1,1,1,1,1,1,1,1,1,1,1,1,1,1,1,1,1,1,1,1,3
1,1,1,1,1,1,1,1,1,1,1,1,1,1,1,1,1,1,1,1,1,1,1,1,1,1,1,1,1,1,1,1,1,1,1,1,1,1,1,3
1,1,1,1,1,1,1,1,1,1,1,1,1,1,1,1,1,1,1,1,1,1,1,1,1,1,1,1,1,1,1,1,1,1,1,1,1,1,1,3
1,1,1,1,1,1,1,1,1,1,1,1,1,1,1,1,1,1,1,1,1,1,1,1,1,1,1,1,1,1,1,1,1,1,1,1,1,1,1,3
1,1,1,1,1,1,1,1,1,1,1,1,1,1,1,1,1,1,1,1,1,1,1,1,1,1,1,1,1,1,1,1,1,1,1,1,1,1,1,3
1,1,1,1,1,1,1,1,1,1,1,1,1,1,1,1,1,1,1,1,1,1,1,1,1,1,1,1,1,1,1,1,1,1,1,1,1,1,1,3
1,1,1,1,1,1,1,1,1,1,1,1,1,1,1,1,1,1,1,1,1,1,1,1,1,1,1,1,1,1,1,1,1,1,1,1,1,1,1,3
1,1,1,1,1,1,1,1,1,1,1,1,1,1,1,1,1,1,1,1,1,1,1,1,1,1,1,1,1,1,1,1,1,1,1,1,1,1,1,3
1,1,1,1,1,1,1,1,1,1,1,1,1,1,1,1,1,1,1,1,1,1,1,1,1,1,1,1,1,1,1,1,1,1,1,1,1,1,1,3
1,1,1,1,1,1,1,1,1,1,1,1,1,1,1,1,1,1,1,1,1,1,1,1,1,1,1,1,1,1,1,1,1,1,1,1,1,1,1,3
1,1,1,1,1,1,1,1,1,1,1,1,1,1,1,1,1,1,1,1,1,1,1,1,1,1,1,1,1,1,1,1,1,1,1,1,1,1,1,3
1,1,1,1,1,1,1,1,1,1,1,1,1,1,1,1,1,1,1,1,1,1,1,1,1,1,1,1,1,1,1,1,1,1,1,1,1,1,1,3
1,1,1,1,1,1,1,1,1,1,1,1,1,1,1,1,1,1,1,1,1,1,1,1,1,1,1,1,1,1,1,1,1,1,1,1,1,1,1,3
1,1,1,1,1,1,1,1,1,1,1,1,1,1,1,1,1,1,1,1,1,1,1,1,1,1,1,1,1,1,1,1,1,1,1,1,1,1,1,3
1,1,1,1,1,1,1,1,1,1,1,1,1,1,1,1,1,1,1,1,1,1,1,1,1,1,1,1,1,1,1,1,1,1,1,1,1,1,1,3
1,1,1,1,1,1,1,1,1,1,1,1,1,1,1,1,1,1,1,1,1,1,1,1,1,1,1,1,1,1,1,1,1,1,1,1,1,1,1,3
1,1,1,1,1,1,1,1,1,1,1,1,1,1,1,1,1,1,1,1,1,1,1,1,1,1,1,1,1,1,1,1,1,1,1,1,1,1,1,3
1,1,1,1,1,1,1,1,1,1,1,1,1,1,1,1,1,1,1,1,1,1,1,1,1,1,1,1,1,1,1,1,1,1,1,1,1,1,1,3
1,1,1,1,1,1,1,1,1,1,1,1,1,1,1,1,1,1,1,1,1,1,1,1,1,1,1,1,1,1,1,1,1,1,1,1,1,1,1,3
2,2,2,2,2,2,2,2,2,2,2,2,2,2,2,2,2,2,2,2,2,2,2,2,2,2,2,2,2,2,2,2,2,2,2,2,2,2,2,2
3,3,3,2,2,2,2,2,2,2,2,2,2,2,2,2,2,2,2,2,2,2,2,2,2,2,2,2,2,2,2,2,2,2,2,2,3,3,3,2
3,3,3,2,2,2,2,2,2,2,2,2,2,2,2,2,2,2,2,2,2,2,2,2,2,2,2,2,2,2,2,2,2,2,2,2,3,3,3,2
3,3,3,2,2,2,2,2,2,2,2,2,2,2,2,2,2,2,2,2,2,2,2,2,2,2,2,2,2,2,2,2,2,2,2,2,3,3,3,2
2,2,2,2,2,2,2,2,2,2,2,2,2,2,2,2,2,2,2,2,2,2,2,2,2,2,2,2,2,2,2,2,2,2,2,2,2,2,2,2
:endlayer
layer: 5
2,2,2,3,4,3,4,3,2,2,2,2,2,2,2,2,2,2,2,2,2,2,2,2,2,2,2,2,2,2,2,3,4,3,4,3,2,2,2,2
2,2,3,3,3,3,3,3,3,2,2,2,2,2,2,2,2,2,2,2,2,2,2,2,2,2,2,2,2,2,3,3,3,3,3,3,3,2,2,2
2,3,3,3,3,3,3,3,3,3,2,2,2,2,2,2,2,2,2,2,2,2,2,2,2,2,2,2,2,3,3,3,3,3,3,3,3,3,2,2
3,3,3,5,5,5,5,5,5,5,5,5,5,5,5,5,5,5,5,5,5,5,5,5,5,5,5,5,5,5,5,5,5,5,5,5,3,3,3,2
4,3,3,5,5,5,5,5,5,5,5,5,5,5,5,5,5,5,5,5,5,5,5,5,5,5,5,5,5,5,5,5,5,5,5,5,3,3,4,2
3,3,3,5,5,5,5,5,5,5,5,5,5,5,5,5,5,5,5,5,5,5,5,5,5,5,5,5,5,5,5,5,5,5,5,5,3,3,3,2
4,3,3,5,5,5,5,5,5,5,5,5,5,5,5,5,5,5,5,5,5,5,5,5,6,5,5,5,5,5,5,5,5,5,5,5,3,3,4,2
3,3,3,5,5,5,5,5,5,5,5,5,5,5,5,5,5,5,5,5,5,5,5,5,6,5,5,5,5,5,5,5,5,5,5,5,3,3,3,2
2,3,3,5,5,5,5,5,5,5,5,5,5,5,5,5,5,5,5,5,5,5,5,5,5,5,5,5,5,5,5,5,5,5,5,5,3,3,2,2
2,2,3,5,5,5,5,5,5,5,5,5,5,5,5,5,5,5,5,5,5,5,5,5,5,5,6,6,6,6,6,6,6,5,5,5,3,2,2,2
2,2,2,5,5,5,5,5,5,5,5,5,5,5,5,5,5,5,5,5,5,5,5,5,5,5,5,5,5,5,5,5,5,5,5,5,2,2,2,2
2,2,2,5,5,5,5,5,5,5,5,5,5,5,5,5,5,5,5,5,5,5,5,5,5,5,5,5,5,5,5,5,5,5,5,5,2,2,2,2
2,2,2,5,5,5,5,5,5,5,5,5,5,5,5,5,5,5,5,5,5,5,5,5,5,5,5,5,5,5,5,5,5,5,5,5,2,2,2,2
2,2,2,5,5,5,5,5,5,5,5,5,5,5,5,5,5,5,5,5,5,5,5,5,5,5,5,5,5,5,5,5,5,5,5,5,2,2,2,2
2,2,2,5,5,5,5,5,5,5,5,5,5,5,5,5,5,5,5,5,5,5,5,5,5,5,5,5,5,5,5,5,5,5,5,5,2,2,2,2
2,2,2,5,5,5,5,5,5,5,5,5,5,5,5,5,5,5,5,5,5,5,5,5,5,5,5,5,5,5,5,5,5,5,5,5,2,2,2,2
2,2,2,5,5,5,5,5,5,5,5,5,5,5,5,5,5,5,5,5,5,5,5,5,5,5,6,6,6,6,6,6,6,5,5,5,2,2,2,2
2,2,2,5,5,5,5,5,5,5,5,5,5,5,5,5,5,5,5,5,5,5,5,5,5,5,5,5,5,5,5,5,5,5,5,5,2,2,2,2
2,2,2,5,5,5,5,5,5,5,5,5,5,5,5,5,5,5,5,5,5,5,5,5,5,5,5,5,5,5,5,5,5,5,5,5,2,2,2,2
2,2,2,5,5,5,5,5,5,5,5,5,5,5,5,5,5,5,5,5,5,5,5,5,5,5,5,5,5,5,5,5,5,5,5,5,2,2,2,2
2,2,2,5,5,5,5,5,5,5,5,5,5,5,5,5,5,5,5,5,5,5,5,5,5,5,5,5,5,5,5,5,5,5,5,5,2,2,2,2
2,2,2,5,5,5,5,5,5,5,5,5,5,5,5,5,5,5,5,5,5,5,5,5,5,5,5,5,5,5,5,5,5,5,5,5,2,2,2,2
2,2,2,5,5,5,5,5,5,5,5,5,5,5,5,5,5,5,5,5,5,5,5,5,5,5,5,5,5,5,5,5,5,5,5,5,2,2,2,2
2,2,2,5,5,5,5,5,5,5,5,5,5,5,5,5,5,5,5,5,5,5,5,5,5,5,6,6,6,6,6,6,6,5,5,5,2,2,2,2
2,2,2,5,5,5,5,5,5,5,5,5,5,5,5,5,5,5,5,5,5,5,5,5,5,5,5,5,5,5,5,5,5,5,5,5,2,2,2,2
2,2,2,5,5,5,5,5,5,5,5,5,5,5,5,5,5,5,5,5,5,5,5,5,5,5,5,5,5,5,5,5,5,5,5,5,2,2,2,2
2,2,2,5,5,5,5,5,5,5,5,5,5,5,5,5,5,5,5,5,5,5,5,5,5,5,5,5,5,5,5,5,5,5,5,5,2,2,2,2
2,2,2,5,5,5,5,5,5,5,5,5,5,5,5,5,5,5,5,5,5,5,5,5,5,5,5,5,5,5,5,5,5,5,5,5,2,2,2,2
2,2,2,5,5,5,5,5,5,5,5,5,5,5,5,5,5,5,5,5,5,5,5,5,5,5,5,5,5,5,5,5,5,5,5,5,2,2,2,2
2,2,3,5,5,5,5,5,5,5,5,5,5,5,5,5,5,5,5,5,5,5,5,5,5,5,5,5,5,5,5,5,5,5,5,5,3,2,2,2
2,3,3,5,5,5,5,5,5,5,5,5,5,5,5,5,5,5,5,5,5,5,5,5,5,5,5,5,5,5,5,5,5,5,5,5,3,3,2,2
3,3,3,5,5,5,5,5,5,5,5,5,5,5,5,5,5,5,5,5,5,5,5,5,5,5,5,5,5,5,5,5,5,5,5,5,3,3,3,2
4,3,3,5,5,5,5,5,5,5,5,5,5,5,5,5,5,5,5,5,5,5,5,5,5,5,5,5,5,5,5,5,5,5,5,5,3,3,4,2
3,3,3,5,5,5,5,5,5,5,5,5,5,5,5,5,5,5,5,5,5,5,5,5,5,5,5,5,5,5,5,5,5,5,5,5,3,3,3,2
4,3,3,5,5,5,5,5,5,5,5,5,5,5,5,5,5,5,5,5,5,5,5,5,5,5,5,5,5,5,5,5,5,5,5,5,3,3,4,2
3,3,3,5,5,5,5,5,5,5,5,5,5,5,5,5,5,5,5,5,5,5,5,5,5,5,5,5,5,5,5,5,5,5,5,5,3,3,3,2
2,3,3,3,3,3,3,3,3,3,2,2,2,2,2,2,4,6,4,4,4,3,4,2,2,2,2,2,2,3,3,3,3,3,3,3,3,3,2,2
2,2,3,3,3,3,3,3,3,2,2,2,2,2,2,2,3,3,6,3,6,3,6,2,2,2,2,2,2,2,3,3,3,3,3,3,3,2,2,2
2,2,2,3,4,3,4,3,2,2,2,2,2,2,2,2,4,3,4,3,4,3,4,2,2,2,2,2,2,2,2,3,4,3,4,3,2,2,2,2
2,2,2,2,2,2,2,2,2,2,2,2,2,2,2,2,2,2,2,2,2,2,2,2,2,2,2,2,2,2,2,2,2,2,2,2,2,2,2,2
2,2,2,2,2,2,2,2,2,2,2,2,2,2,2,2,2,2,2,2,2,2,2,2,2,2,2,2,2,2,2,2,2,2,2,2,2,2,2,2
2,5,2,2,2,2,2,2,2,2,2,2,2,2,2,2,2,2,2,2,2,2,2,2,2,2,2,2,2,2,2,2,2,2,2,2,2,5,2,2
2,2,2,2,2,2,2,2,2,2,2,2,2,2,2,2,2,2,2,2,2,2,2,2,2,2,2,2,2,2,2,2,2,2,2,2,2,2,2,2
2,2,2,2,2,2,2,2,2,2,2,2,2,2,2,2,2,2,2,2,2,2,2,2,2,2,2,2,2,2,2,2,2,2,2,2,2,2,2,2
:endlayer
layer: 6
0,0,0,6,10,6,10,6,0,0,0,0,0,0,0,0,0,0,0,0,0,0,0,0,0,0,0,0,0,0,0,6,10,6,10,6,0,0,0,0
0,0,6,6,6,6,6,6,6,0,0,0,0,0,0,0,0,0,0,0,0,0,0,0,0,0,0,0,0,0,6,6,6,6,6,6,6,0,0,0
0,6,6,6,8,6,6,6,6,6,0,0,0,0,0,0,0,0,0,0,0,0,0,0,0,0,0,0,0,6,6,6,6,6,6,6,6,6,0,0
6,6,6,6,0,0,0,6,6,6,6,0,0,0,0,0,0,0,0,0,0,0,0,0,0,0,0,0,6,6,6,6,0,0,0,6,6,6,6,0
7,6,6,0,0,0,0,0,6,6,0,6,10,6,10,6,10,6,10,6,10,6,10,6,10,6,10,6,0,6,6,0,0,0,0,0,6,6,17,0
6,6,8,0,0,0,0,0,6,6,6,6,6,6,6,6,6,6,6,6,6,6,6,6,6,6,6,6,6,6,6,0,0,0,18,0,6,6,6,0
7,6,6,0,0,0,0,0,6,6,6,6,6,6,6,6,6,6,6,6,6,6,6,6,6,6,6,6,6,6,6,0,0,0,16,0,6,6,17,0
6,6,6,6,0,0,0,0,0,0,0,0,0,0,0,0,0,0,0,0,0,0,0,0,6,0,0,0,15,16,16,16,0,16,16,6,6,6,6,0
0,6,6,6,6,6,8,0,0,0,0,0,0,0,0,0,0,0,0,0,0,0,0,0,0,0,0,0,15,16,16,16,6,6,6,6,6,6,0,0
0,0,6,6,6,6,6,0,0,0,0,0,0,0,0,0,0,0,0,0,0,0,0,0,6,0,6,6,6,6,6,6,6,6,6,6,6,0,0,0
0,0,0,6,0,6,6,0,0,0,6,0,0,0,0,6,0,0,0,0,6,0,0,0,6,0,0,6,0,0,0,0,6,6,0,6,0,0,0,0
0,0,0,0,6,6,6,0,0,0,0,0,0,0,0,0,0,0,0,0,0,0,0,0,6,0,0,6,0,0,0,0,6,6,6,0,0,0,0,0
0,0,0,0,7,6,6,0,0,0,0,0,0,0,0,0,0,0,0,0,0,0,0,0,6,0,0,6,0,0,0,0,6,6,17,0,0,0,0,0
0,0,0,0,6,6,6,0,0,0,0,0,0,0,0,0,0,0,0,0,0,0,0,0,6,0,0,0,0,0,0,0,6,6,6,0,0,0,0,0
0,0,0,0,7,6,6,0,0,0,6,0,0,0,0,6,0,0,0,0,6,0,0,0,6,0,0,6,0,0,0,0,6,6,17,0,0,0,0,0
0,0,0,0,6,6,6,0,0,0,0,0,0,0,0,0,0,0,0,0,0,0,0,0,6,0,0,6,0,0,0,0,6,6,6,0,0,0,0,0
0,0,0,0,7,6,6,0,0,0,0,0,0,0,0,0,0,0,0,0,0,0,0,0,6,0,6,6,6,6,6,6,6,6,17,0,0,0,0,0
0,0,0,0,6,6,6,0,0,0,0,0,0,0,0,0,0,0,0,0,0,0,0,0,6,0,0,6,0,0,0,0,6,6,6,0,0,0,0,0
0,0,0,0,7,6,6,0,0,0,0,0,0,0,0,0,0,0,0,0,0,0,0,0,6,0,0,6,0,0,0,0,6,6,17,0,0,0,0,0
0,0,0,0,6,6,6,0,0,0,6,0,0,0,0,6,0,0,0,0,6,0,0,0,6,0,0,6,0,0,0,0,6,6,6,0,0,0,0,0
0,0,0,0,7,6,6,0,0,0,0,0,0,0,0,0,0,0,0,0,0,0,0,0,6,0,0,0,0,0,0,0,6,6,17,0,0,0,0,0
0,0,0,0,6,6,6,0,0,0,0,0,0,0,0,0,0,0,0,0,0,0,0,0,6,0,0,6,0,0,0,0,6,6,6,0,0,0,0,0
0,0,0,0,7,6,6,0,0,0,0,0,0,0,0,0,0,0,0,0,0,0,0,0,6,0,0,6,0,0,0,0,6,6,17,0,0,0,0,0
0,0,0,0,6,6,6,0,0,0,0,0,0,0,0,0,0,0,0,0,0,0,0,0,6,0,6,6,6,6,6,6,6,6,6,0,0,0,0,0
0,0,0,0,7,6,6,0,0,0,6,0,0,0,0,6,0,0,0,0,6,0,0,0,6,0,0,6,0,0,0,0,6,6,17,0,0,0,0,0
0,0,0,0,6,6,6,0,0,0,0,0,0,0,0,0,0,0,0,0,0,0,0,0,6,0,0,6,0,0,0,0,6,6,6,0,0,0,0,0
0,0,0,0,7,6,6,0,0,0,0,0,0,0,0,0,0,0,0,0,0,0,0,0,6,0,0,6,0,0,0,0,6,6,17,0,0,0,0,0
0,0,0,0,6,6,6,0,0,0,0,0,0,0,0,0,0,0,0,0,0,0,0,0,6,0,0,0,0,0,0,0,6,6,6,0,0,0,0,0
0,0,0,6,0,6,6,0,0,0,6,0,0,0,0,6,0,0,0,0,6,0,0,0,6,0,0,6,0,0,0,0,6,6,0,6,0,0,0,0
0,0,6,6,6,6,6,0,0,0,0,0,0,0,0,0,0,0,0,0,0,0,0,0,6,0,0,6,0,0,0,0,6,6,6,6,6,0,0,0
0,6,6,6,6,6,8,0,0,0,0,0,0,0,0,0,0,0,0,0,0,0,0,0,0,0,0,6,0,0,0,0,8,6,6,6,6,6,0,0
6,6,6,6,0,0,0,0,0,0,0,0,0,0,0,0,0,0,0,0,0,0,0,0,6,0,0,6,0,0,0,0,0,0,0,6,6,6,6,0
7,6,6,0,0,0,0,0,6,6,6,6,6,6,6,6,6,6,6,6,6,6,6,6,6,6,6,6,6,6,6,0,0,0,0,0,6,6,17,0
6,6,6,0,0,0,0,0,8,6,6,6,6,6,6,6,6,6,6,6,6,6,6,6,6,6,6,6,6,6,6,0,0,0,0,0,6,6,6,0
7,6,6,0,0,0,0,0,6,6,0,6,9,6,9,6,0,11,0,0,0,14,0,6,9,6,9,6,0,6,8,0,0,0,0,0,6,6,17,0
6,6,6,8,0,0,0,8,6,6,6,0,0,0,0,0,6,6,0,0,0,6,6,0,0,0,0,0,6,6,6,6,0,0,0,6,6,6,6,0
0,6,6,6,6,6,8,6,6,6,0,0,0,0,0,0,0,11,0,0,0,14,0,0,0,0,0,0,0,6,6,6,6,6,6,6,6,6,0,0
0,0,6,6,6,6,6,6,6,0,0,0,0,0,0,0,6,6,0,0,0,6,6,0,0,0,0,0,0,0,6,6,6,6,6,6,6,0,0,0
0,0,0,6,9,6,9,6,0,0,0,0,0,0,0,0,0,11,0,0,0,14,0,0,0,0,0,0,0,0,0,6,9,6,9,6,0,0,0,0
0,0,0,0,0,0,0,0,0,0,0,0,0,0,0,0,6,6,0,0,0,6,6,0,0,0,0,0,0,0,0,0,0,0,0,0,0,0,0,0
0,0,0,0,0,0,0,0,0,0,0,0,0,0,0,0,0,11,0,0,0,14,0,0,0,0,0,0,0,0,0,0,0,0,0,0,0,0,0,0
0,5,0,0,0,0,0,0,0,0,0,0,0,0,0,0,6,6,13,13,13,6,6,0,0,0,0,0,0,0,0,0,0,0,0,0,0,5,0,0
0,0,0,0,0,0,0,0,0,0,0,0,0,0,0,0,0,6,12,12,12,6,0,0,0,0,0,0,0,0,0,0,0,0,0,0,0,0,0,0
0,0,0,0,0,0,0,0,0,0,0,0,0,0,0,0,0,0,0,0,0,0,0,0,0,0,0,0,0,0,0,0,0,0,0,0,0,0,0,0
:endlayer
layer: 7
0,0,0,6,0,6,0,6,0,0,0,0,0,0,0,0,0,0,0,0,0,0,0,0,0,0,0,0,0,0,0,6,0,6,0,6,0,0,0,0
0,0,6,6,6,6,6,6,6,0,0,0,0,0,0,0,0,0,0,0,0,0,0,0,0,0,0,0,0,0,6,6,6,6,6,6,6,0,0,0
0,6,6,6,6,6,6,6,6,6,0,0,0,0,0,0,0,0,0,0,0,0,0,0,0,0,0,0,0,6,6,6,6,6,6,6,6,6,0,0
6,6,6,6,0,0,0,6,6,6,6,0,0,0,0,0,0,0,0,0,0,0,0,0,0,0,0,0,6,6,6,6,0,0,0,6,6,6,6,0
0,6,6,0,0,0,0,0,6,6,0,6,0,6,0,6,0,6,0,6,0,6,0,6,0,6,0,6,0,6,6,0,0,0,0,0,6,6,0,0
6,6,6,0,0,0,0,0,6,6,6,6,6,6,6,6,6,6,6,6,6,6,6,6,6,6,6,6,6,6,6,0,0,0,0,0,6,6,6,0
0,6,6,0,0,0,0,0,6,6,6,6,6,6,6,6,6,6,6,6,6,6,6,6,6,6,6,6,6,6,6,0,0,0,18,0,6,6,0,0
6,6,6,6,0,0,0,0,0,0,0,0,0,0,0,0,0,0,0,0,0,0,0,0,6,0,0,0,0,15,16,16,0,16,16,6,6,6,6,0
0,6,6,6,6,6,6,0,0,0,0,0,0,0,0,0,0,0,0,0,0,0,0,0,0,0,0,0,0,15,16,16,6,6,6,6,6,6,0,0
0,0,6,6,6,6,6,0,0,0,0,0,0,0,0,0,0,0,0,0,0,0,0,0,6,0,7,6,6,6,6,6,6,6,6,6,6,0,0,0
0,0,0,6,0,6,6,0,0,0,6,0,0,0,0,6,0,0,0,0,6,0,0,0,6,0,0,6,0,0,0,0,6,6,0,6,0,0,0,0
0,0,0,0,6,6,6,0,0,0,0,0,0,0,0,0,0,0,0,0,0,0,0,0,6,0,0,6,0,0,0,0,6,6,6,0,0,0,0,0
0,0,0,0,0,6,6,0,0,0,0,0,0,0,0,0,0,0,0,0,0,0,0,0,6,0,0,6,0,0,0,0,6,6,0,0,0,0,0,0
0,0,0,0,6,6,6,0,0,0,0,0,0,0,0,0,0,0,0,0,0,0,0,0,6,0,0,0,0,0,0,0,6,6,6,0,0,0,0,0
0,0,0,0,0,6,6,0,0,0,6,0,0,0,0,6,0,0,0,0,6,0,0,0,6,0,0,6,0,0,0,0,6,6,0,0,0,0,0,0
0,0,0,0,6,6,6,0,0,0,0,0,0,0,0,0,0,0,0,0,0,0,0,0,6,0,0,6,0,0,0,0,6,6,6,0,0,0,0,0
0,0,0,0,0,6,6,0,0,0,0,0,0,0,0,0,0,0,0,0,0,0,0,0,6,0,7,6,6,6,6,6,6,6,0,0,0,0,0,0
0,0,0,0,6,6,6,0,0,0,0,0,0,0,0,0,0,0,0,0,0,0,0,0,6,0,0,6,0,0,0,0,6,6,6,0,0,0,0,0
0,0,0,0,0,6,6,0,0,0,0,0,0,0,0,0,0,0,0,0,0,0,0,0,6,0,0,6,0,0,0,0,6,6,0,0,0,0,0,0
0,0,0,0,6,6,6,0,0,0,6,0,0,0,0,6,0,0,0,0,6,0,0,0,6,0,0,6,0,0,0,0,6,6,6,0,0,0,0,0
0,0,0,0,0,6,6,0,0,0,0,0,0,0,0,0,0,0,0,0,0,0,0,0,6,0,0,0,0,0,0,0,6,6,0,0,0,0,0,0
0,0,0,0,6,6,6,0,0,0,0,0,0,0,0,0,0,0,0,0,0,0,0,0,6,0,0,6,0,0,0,0,6,6,6,0,0,0,0,0
0,0,0,0,0,6,6,0,0,0,0,0,0,0,0,0,0,0,0,0,0,0,0,0,6,0,0,6,0,0,0,0,6,6,0,0,0,0,0,0
0,0,0,0,6,6,6,0,0,0,0,0,0,0,0,0,0,0,0,0,0,0,0,0,6,0,7,6,6,6,6,6,6,6,6,0,0,0,0,0
0,0,0,0,0,6,6,0,0,0,6,0,0,0,0,6,0,0,0,0,6,0,0,0,6,0,0,6,0,0,0,0,6,6,0,0,0,0,0,0
0,0,0,0,6,6,6,0,0,0,0,0,0,0,0,0,0,0,0,0,0,0,0,0,6,0,0,6,0,0,0,0,6,6,6,0,0,0,0,0
0,0,0,0,0,6,6,0,0,0,0,0,0,0,0,0,0,0,0,0,0,0,0,0,6,0,0,6,0,0,0,0,6,6,0,0,0,0,0,0
0,0,0,0,6,6,6,0,0,0,0,0,0,0,0,0,0,0,0,0,0,0,0,0,6,0,0,0,0,0,0,0,6,6,6,0,0,0,0,0
0,0,0,6,0,6,6,0,0,0,6,0,0,0,0,6,0,0,0,0,6,0,0,0,6,0,0,6,0,0,0,0,6,6,0,6,0,0,0,0
0,0,6,6,6,6,6,0,0,0,0,0,0,0,0,0,0,0,0,0,0,0,0,0,6,0,0,6,0,0,0,0,6,6,6,6,6,0,0,0
0,6,6,6,6,6,6,0,0,0,0,0,0,0,0,0,0,0,0,0,0,0,0,0,0,0,0,6,0,0,0,0,6,6,6,6,6,6,0,0
6,6,6,6,0,0,0,0,0,0,0,0,0,0,0,0,0,0,0,0,0,0,0,0,6,0,0,6,0,0,0,0,0,0,0,6,6,6,6,0
0,6,6,0,0,0,0,0,6,6,6,6,6,6,6,6,6,6,6,6,6,6,6,6,6,6,6,6,6,6,6,0,0,0,0,0,6,6,0,0
6,6,6,0,0,0,0,0,6,6,6,6,6,6,6,6,6,6,6,6,6,6,6,6,6,6,6,6,6,6,6,0,0,0,0,0,6,6,6,0
0,6,6,0,0,0,0,0,6,6,0,6,0,6,0,6,0,7,0,0,0,17,0,6,0,6,0,6,0,6,6,0,0,0,0,0,6,6,0,0
6,6,6,6,0,0,0,6,6,6,6,0,0,0,0,0,6,6,0,0,0,6,6,0,0,0,0,0,6,6,6,6,0,0,0,6,6,6,6,0
0,6,6,6,6,6,6,6,6,6,0,0,0,0,0,0,0,7,0,0,0,17,0,0,0,0,0,0,0,6,6,6,6,6,6,6,6,6,0,0
0,0,6,6,6,6,6,6,6,0,0,0,0,0,0,0,6,6,0,0,0,6,6,0,0,0,0,0,0,0,6,6,6,6,6,6,6,0,0,0
0,0,0,6,0,6,0,6,0,0,0,0,0,0,0,0,0,7,0,0,0,17,0,0,0,0,0,0,0,0,0,6,0,6,0,6,0,0,0,0
0,0,0,0,0,0,0,0,0,0,0,0,0,0,0,0,6,6,0,0,0,6,6,0,0,0,0,0,0,0,0,0,0,0,0,0,0,0,0,0
0,0,0,0,0,0,0,0,0,0,0,0,0,0,0,0,0,6,13,13,13,6,0,0,0,0,0,0,0,0,0,0,0,0,0,0,0,0,0,0
0,19,0,0,0,0,0,0,0,0,0,0,0,0,0,0,7,6,12,12,12,6,17,0,0,0,0,0,0,0,0,0,0,0,0,0,0,19,0,0
0,0,0,0,0,0,0,0,0,0,0,0,0,0,0,0,0,9,0,0,0,9,0,0,0,0,0,0,0,0,0,0,0,0,0,0,0,0,0,0
0,0,0,0,0,0,0,0,0,0,0,0,0,0,0,0,0,0,0,0,0,0,0,0,0,0,0,0,0,0,0,0,0,0,0,0,0,0,0,0
:endlayer
layer: 8
0,0,20,6,0,6,0,6,23,0,0,0,0,0,0,0,0,0,0,0,0,0,0,0,0,0,0,0,0,0,20,6,0,6,0,6,21,0,0,0
0,20,6,6,6,6,6,6,6,23,0,0,0,0,0,0,0,0,0,0,0,0,0,0,0,0,0,0,0,20,6,6,6,6,6,6,6,21,0,0
20,6,6,6,6,6,6,6,6,6,23,0,0,0,0,0,0,0,0,0,0,0,0,0,0,0,0,0,20,6,6,6,6,6,6,6,6,6,21,0
6,6,6,6,0,0,0,6,6,6,6,23,0,21,0,21,0,21,0,21,0,21,0,21,0,21,0,20,6,6,6,6,23,0,0,6,6,6,6,23
0,6,6,0,0,0,0,0,6,6,0,6,0,6,0,6,0,6,0,6,0,6,0,6,0,6,0,6,0,6,6,22,0,0,0,0,6,6,0,0
6,6,6,0,0,0,0,0,6,6,6,6,6,6,6,6,6,6,6,6,6,6,6,6,6,6,6,6,6,6,6,0,0,0,0,0,6,6,6,23
0,6,6,0,0,0,0,0,6,6,6,6,6,6,6,6,6,6,6,6,6,6,6,6,6,6,6,6,6,6,6,0,0,0,0,0,6,6,0,0
6,6,6,6,0,0,0,0,0,0,0,0,0,0,0,0,0,0,0,0,0,0,0,0,6,0,0,0,0,0,15,16,16,25,0,6,6,6,6,23
22,6,6,6,6,6,6,0,0,0,0,0,0,0,0,0,0,0,0,0,0,0,0,0,0,0,0,0,0,0,15,16,6,6,6,6,6,6,22,0
0,22,6,6,6,6,6,0,0,0,21,0,0,0,0,21,0,0,0,0,21,0,0,0,6,0,0,6,6,6,6,6,6,6,6,6,6,22,0,0
0,0,22,6,0,6,6,0,0,20,6,23,0,0,20,6,23,0,0,20,6,23,0,0,6,0,0,24,0,0,0,0,6,6,0,6,22,0,0,0
0,0,0,22,6,6,6,0,0,0,22,0,0,0,0,22,0,0,0,0,22,0,0,0,6,0,0,24,0,0,0,0,6,6,6,22,0,0,0,0
0,0,0,0,0,6,6,0,0,0,0,0,0,0,0,0,0,0,0,0,0,0,0,0,6,0,0,6,0,0,0,0,6,6,0,0,0,0,0,0
0,0,0,20,6,6,6,0,0,0,0,0,0,0,0,21,0,0,0,0,21,0,0,0,6,0,0,0,0,0,0,0,6,6,6,23,0,0,0,0
0,0,0,0,0,6,6,0,0,20,6,23,0,0,20,6,23,0,0,20,6,23,0,0,6,0,0,6,0,0,0,0,6,6,0,0,0,0,0,0
0,0,0,20,6,6,6,0,0,0,22,0,0,0,0,22,0,0,0,0,22,0,0,0,6,0,0,24,0,0,0,0,6,6,6,23,0,0,0,0
0,0,0,0,0,6,6,0,0,0,0,0,0,0,0,0,0,0,0,0,0,0,0,0,6,0,0,6,6,6,6,6,6,6,0,0,0,0,0,0
0,0,0,20,6,6,6,0,0,0,0,0,0,0,0,0,0,0,0,0,0,0,0,0,6,0,0,24,0,0,0,0,6,6,6,23,0,0,0,0
0,0,0,0,0,6,6,0,0,0,21,0,0,0,0,21,0,0,0,0,21,0,0,0,6,0,0,24,0,0,0,0,6,6,0,0,0,0,0,0
0,0,0,20,6,6,6,0,0,20,6,23,0,0,20,6,23,0,0,20,6,23,0,0,6,0,0,6,0,0,0,0,6,6,6,23,0,0,0,0
0,0,0,0,0,6,6,0,0,0,22,0,0,0,0,22,0,0,0,0,22,0,0,0,6,0,0,0,0,0,0,0,6,6,0,0,0,0,0,0
0,0,0,20,6,6,6,0,0,0,0,0,0,0,0,0,0,0,0,0,0,0,0,0,6,0,0,6,0,0,0,0,6,6,6,23,0,0,0,0
0,0,0,0,0,6,6,0,0,0,0,0,0,0,0,0,0,0,0,0,0,0,0,0,6,0,0,24,0,0,0,0,6,6,0,0,0,0,0,0
0,0,0,20,6,6,6,0,0,0,21,0,0,0,0,21,0,0,0,0,21,0,0,0,6,0,0,6,6,6,6,6,6,6,6,23,0,0,0,0
0,0,0,0,0,6,6,0,0,20,6,23,0,0,20,6,23,0,0,20,6,23,0,0,6,0,0,24,0,0,0,0,6,6,0,0,0,0,0,0
0,0,0,20,6,6,6,0,0,0,22,0,0,0,0,22,0,0,0,0,22,0,0,0,6,0,0,24,0,0,0,0,6,6,6,23,0,0,0,0
0,0,0,0,0,6,6,0,0,0,0,0,0,0,0,0,0,0,0,0,0,0,0,0,6,0,0,6,0,0,0,0,6,6,0,0,0,0,0,0
0,0,0,21,6,6,6,0,0,0,21,0,0,0,0,21,0,0,0,0,21,0,0,0,6,0,0,0,0,0,0,0,6,6,6,21,0,0,0,0
0,0,21,6,0,6,6,0,0,20,6,23,0,0,20,6,23,0,0,20,6,23,0,0,6,0,0,6,0,0,0,0,6,6,0,6,21,0,0,0
0,21,6,6,6,6,6,0,0,0,22,0,0,0,0,22,0,0,0,0,22,0,0,0,6,0,0,24,0,0,0,0,6,6,6,6,6,21,0,0
21,6,6,6,6,6,6,0,0,0,0,0,0,0,0,0,0,0,0,0,0,0,0,0,0,0,0,24,0,0,0,0,6,6,6,6,6,6,0,0
6,6,6,6,0,0,0,0,0,0,0,0,0,0,0,0,0,0,0,0,0,0,0,0,6,0,0,24,0,0,0,0,0,0,0,6,6,6,6,23
0,6,6,0,0,0,0,0,6,6,6,6,6,6,6,6,6,6,6,6,6,6,6,6,6,6,6,6,6,6,6,0,0,0,0,0,6,6,0,0
6,6,6,0,0,0,0,0,6,6,6,6,6,6,6,6,6,6,6,6,6,6,6,6,6,6,6,6,6,6,6,0,0,0,0,0,6,6,6,23
0,6,6,0,0,0,0,0,6,6,0,6,0,6,0,6,0,11,0,0,0,14,0,6,0,6,0,6,0,6,6,0,0,0,0,0,6,6,0,0
6,6,6,6,0,0,0,6,6,6,6,22,0,22,0,20,6,6,0,0,0,6,6,23,0,22,0,22,6,6,6,6,0,0,0,6,6,6,6,23
20,6,6,6,6,6,6,6,6,6,22,0,0,0,0,0,0,11,0,0,0,14,0,0,0,0,0,0,22,6,6,6,6,6,6,6,6,6,22,0
0,20,6,6,6,6,6,6,6,22,0,0,0,0,0,20,6,6,0,0,0,6,6,23,0,0,0,0,0,22,6,6,6,6,6,6,6,22,0,0
0,0,0,6,0,6,0,6,22,0,0,0,0,0,0,0,0,11,0,0,0,14,0,0,0,0,0,0,0,0,22,6,0,6,0,6,22,0,0,0
0,0,0,22,0,22,0,22,0,0,0,0,0,0,0,20,6,6,13,13,13,6,6,23,0,0,0,0,0,0,0,22,0,22,0,22,0,0,0,0
0,0,0,0,0,0,0,0,0,0,0,0,0,0,0,0,22,6,12,12,12,6,22,0,0,0,0,0,0,0,0,0,0,0,0,0,0,0,0,0
0,19,0,0,0,0,0,0,0,0,0,0,0,0,0,0,0,9,0,0,0,9,0,0,0,0,0,0,0,0,0,0,0,0,0,0,0,19,0,0
0,0,0,0,0,0,0,0,0,0,0,0,0,0,0,0,0,0,0,0,0,0,0,0,0,0,0,0,0,0,0,0,0,0,0,0,0,0,0,0
0,0,0,0,0,0,0,0,0,0,0,0,0,0,0,0,0,0,0,0,0,0,0,0,0,0,0,0,0,0,0,0,0,0,0,0,0,0,0,0
:endlayer
layer: 9
0,0,0,10,0,10,0,10,0,0,0,0,0,0,0,0,0,0,0,0,0,0,0,0,0,0,0,0,0,0,0,10,0,10,0,10,0,0,0,0
0,0,7,6,6,6,6,6,17,0,0,0,0,0,0,0,0,0,0,0,0,0,0,0,0,0,0,0,0,0,7,6,6,6,6,6,17,0,0,0
0,10,6,6,6,6,6,6,6,10,0,0,0,0,0,0,0,0,0,0,0,0,0,0,0,0,0,0,0,10,6,6,6,6,6,6,6,10,0,0
7,6,6,6,0,0,0,6,6,6,17,0,0,0,0,0,0,0,0,0,0,0,0,0,0,0,0,0,7,6,6,6,16,0,0,6,6,6,17,0
0,6,6,0,0,0,0,0,6,6,0,10,0,10,0,10,0,10,0,10,0,10,0,10,0,10,0,10,0,6,6,16,16,0,0,0,6,6,0,0
7,6,6,0,0,0,0,0,6,6,6,6,6,6,6,6,6,6,6,6,6,6,6,6,6,6,6,6,6,6,6,16,16,0,0,0,6,6,17,0
0,6,6,0,0,0,0,0,6,6,6,6,6,6,6,6,6,6,6,6,6,6,6,6,6,6,6,6,6,6,6,12,12,0,0,0,6,6,0,0
7,6,6,6,0,0,0,0,0,0,0,0,0,0,0,0,0,0,0,0,0,0,0,0,6,0,0,0,0,0,0,0,0,0,0,6,6,6,17,0
0,9,6,6,6,6,6,0,0,0,0,0,0,0,0,0,0,0,0,0,0,0,0,20,6,0,0,0,0,0,0,0,6,6,6,6,6,9,0,0
0,0,7,6,6,6,6,0,0,0,0,0,0,0,0,0,0,0,0,0,0,0,0,0,6,0,0,6,6,6,6,6,6,6,6,6,17,0,0,0
0,0,0,9,0,6,6,0,0,0,6,0,0,0,0,6,0,0,0,0,6,0,0,0,6,0,0,24,0,0,0,0,6,6,0,9,0,0,0,0
0,0,0,0,7,6,6,0,0,0,0,0,0,0,0,0,0,0,0,0,0,0,0,0,6,0,0,24,0,0,0,0,6,6,17,0,0,0,0,0
0,0,0,0,0,6,6,0,0,0,0,0,0,0,0,0,0,0,0,0,0,0,0,0,6,0,0,6,0,0,0,0,6,6,0,0,0,0,0,0
0,0,0,0,7,6,6,0,0,0,0,0,0,0,0,0,0,0,0,0,0,0,0,0,6,0,0,0,0,0,0,0,6,6,17,0,0,0,0,0
0,0,0,0,0,6,6,0,0,0,6,0,0,0,0,6,0,0,0,0,6,0,0,0,6,0,0,6,0,0,0,0,6,6,0,0,0,0,0,0
0,0,0,0,7,6,6,0,0,0,0,0,0,0,0,0,0,0,0,0,0,0,0,0,6,0,0,24,0,0,0,0,6,6,17,0,0,0,0,0
0,0,0,0,0,6,6,0,0,0,0,0,0,0,0,0,0,0,0,0,0,0,0,0,6,0,0,6,6,6,6,6,6,6,0,0,0,0,0,0
0,0,0,0,7,6,6,0,0,0,0,0,0,0,0,0,0,0,0,0,0,0,0,0,6,0,0,24,0,0,0,0,6,6,17,0,0,0,0,0
0,0,0,0,0,6,6,0,0,0,0,0,0,0,0,0,0,0,0,0,0,0,0,0,6,0,0,24,0,0,0,0,6,6,0,0,0,0,0,0
0,0,0,0,7,6,6,0,0,0,6,0,0,0,0,6,0,0,0,0,6,0,0,0,6,0,0,6,0,0,0,0,6,6,17,0,0,0,0,0
0,0,0,0,0,6,6,0,0,0,0,0,0,0,0,0,0,0,0,0,0,0,0,0,6,0,0,0,0,0,0,0,6,6,0,0,0,0,0,0
0,0,0,0,7,6,6,0,0,0,0,0,0,0,0,0,0,0,0,0,0,0,0,0,6,0,0,6,0,0,0,0,6,6,17,0,0,0,0,0
0,0,0,0,0,6,6,0,0,0,0,0,0,0,0,0,0,0,0,0,0,0,0,0,6,0,0,24,0,0,0,0,6,6,0,0,0,0,0,0
0,0,0,0,7,6,6,0,0,0,0,0,0,0,0,0,0,0,0,0,0,0,0,0,6,0,0,6,6,6,6,6,6,6,17,0,0,0,0,0
0,0,0,0,0,6,6,0,0,0,6,0,0,0,0,6,0,0,0,0,6,0,0,0,6,0,0,24,0,0,0,0,6,6,0,0,0,0,0,0
0,0,0,0,7,6,6,0,0,0,0,0,0,0,0,0,0,0,0,0,0,0,0,0,6,0,0,24,0,0,0,0,6,6,17,0,0,0,0,0
0,0,0,0,0,6,6,0,0,0,0,0,0,0,0,0,0,0,0,0,0,0,0,0,6,0,0,6,0,0,0,0,6,6,0,0,0,0,0,0
0,0,0,0,7,6,6,0,0,0,0,0,0,0,0,0,0,0,0,0,0,0,0,0,6,0,0,0,0,0,0,0,6,6,17,0,0,0,0,0
0,0,0,10,0,6,6,0,0,0,6,0,0,0,0,6,0,0,0,0,6,0,0,0,6,0,0,6,0,0,0,0,6,6,0,10,0,0,0,0
0,0,7,6,6,6,6,0,0,0,0,0,0,0,0,0,0,0,0,0,0,0,0,0,6,0,0,24,0,0,0,0,6,6,6,6,17,0,0,0
0,10,6,6,6,6,6,0,0,0,0,0,0,0,0,0,0,0,0,0,0,0,0,20,6,0,0,24,0,0,0,0,6,6,6,6,6,10,0,0
7,6,6,6,0,0,0,0,0,0,0,0,0,0,0,0,0,0,0,0,0,0,0,0,6,0,0,24,0,0,0,0,0,0,0,6,6,6,17,0
0,6,6,0,0,0,0,0,6,6,6,6,6,6,6,6,6,6,6,6,6,6,6,6,6,6,6,6,6,6,6,0,0,0,0,0,6,6,0,0
7,6,6,0,0,0,0,0,6,6,6,6,6,6,6,6,6,6,6,6,6,6,6,6,6,6,6,6,6,6,6,0,0,0,0,0,6,6,17,0
0,6,6,0,0,0,0,0,6,6,0,9,0,9,0,9,0,7,0,0,0,17,0,9,0,9,0,9,0,6,6,0,0,0,0,0,6,6,0,0
7,6,6,6,0,0,0,6,6,6,17,0,0,0,0,0,7,6,0,0,0,6,17,0,0,0,0,0,7,6,6,6,0,0,0,6,6,6,17,0
0,9,6,6,6,6,6,6,6,9,0,0,0,0,0,0,0,7,0,0,0,17,0,0,0,0,0,0,0,9,6,6,6,6,6,6,6,9,0,0
0,0,7,6,6,6,6,6,17,0,0,0,0,0,0,0,7,6,0,0,0,6,17,0,0,0,0,0,0,0,7,6,6,6,6,6,17,0,0,0
0,0,0,9,0,9,0,9,0,0,0,0,0,0,0,0,0,7,13,13,13,17,0,0,0,0,0,0,0,0,0,9,0,9,0,9,0,0,0,0
0,0,0,0,0,0,0,0,0,0,0,0,0,0,0,0,7,6,12,12,12,6,17,0,0,0,0,0,0,0,0,0,0,0,0,0,0,0,0,0
0,21,0,0,0,0,0,0,0,0,0,0,0,0,0,0,0,9,0,0,0,9,0,0,0,0,0,0,0,0,0,0,0,0,0,0,0,21,0,0
20,26,23,0,0,0,0,0,0,0,0,0,0,0,0,0,0,0,0,0,0,0,0,0,0,0,0,0,0,0,0,0,0,0,0,0,20,26,23,0
0,22,0,0,0,0,0,0,0,0,0,0,0,0,0,0,0,0,0,0,0,0,0,0,0,0,0,0,0,0,0,0,0,0,0,0,0,22,0,0
0,0,0,0,0,0,0,0,0,0,0,0,0,0,0,0,0,0,0,0,0,0,0,0,0,0,0,0,0,0,0,0,0,0,0,0,0,0,0,0
:endlayer
layer: 10
0,0,0,27,27,27,27,27,0,0,0,0,0,0,0,0,0,0,0,0,0,0,0,0,0,0,0,0,0,0,0,27,27,27,27,27,0,0,0,0
0,0,27,6,6,6,6,6,27,0,0,0,0,0,0,0,0,0,0,0,0,0,0,0,0,0,0,0,0,0,27,6,6,6,6,6,27,0,0,0
0,27,6,6,6,6,6,6,6,27,0,0,0,0,0,0,0,0,0,0,0,0,0,0,0,0,0,0,0,27,6,6,6,6,6,6,6,27,0,0
27,6,6,6,23,0,0,6,6,6,27,0,0,0,0,0,0,0,0,0,0,0,0,0,0,0,0,0,27,6,6,6,16,0,20,6,6,6,27,0
27,6,6,22,0,0,0,0,6,6,27,27,27,0,0,0,27,27,27,0,27,27,27,0,0,0,27,27,27,6,6,16,16,0,0,22,6,6,27,0
27,6,6,0,0,0,0,0,6,6,6,6,6,6,6,6,6,6,6,6,6,6,6,6,6,6,6,6,6,6,6,12,12,0,0,0,6,6,27,0
27,6,6,0,0,0,0,20,6,6,6,6,6,6,6,6,6,6,6,6,6,6,6,6,6,6,6,6,6,6,6,0,0,0,0,21,6,6,27,0
27,6,6,6,0,0,21,0,22,0,6,0,0,22,0,6,0,0,0,0,6,0,0,0,6,0,0,0,0,0,22,0,0,0,0,6,6,6,27,0
0,27,6,6,6,6,6,23,0,0,6,0,0,0,0,6,0,0,0,0,6,0,0,0,6,0,0,0,0,0,0,20,6,6,6,6,6,27,0,0
0,0,27,6,6,6,6,0,0,0,6,0,0,0,0,6,0,0,0,0,6,0,0,0,6,14,11,6,6,6,6,6,6,6,6,6,27,0,0,0
0,0,0,27,27,6,6,6,6,6,6,6,6,6,6,6,6,6,6,6,6,6,6,6,6,0,0,24,0,0,0,22,6,6,27,27,0,0,0,0
0,0,0,0,27,6,6,0,0,0,6,0,0,0,0,6,0,0,0,0,6,0,0,0,6,0,0,24,0,0,0,0,6,6,27,0,0,0,0,0
0,0,0,0,27,6,6,0,0,0,6,0,0,0,0,6,0,0,0,0,6,0,0,0,6,0,20,6,23,0,0,0,6,6,27,0,0,0,0,0
0,0,0,0,0,6,6,0,0,0,6,0,0,0,0,6,0,0,0,0,6,0,0,0,6,0,0,24,0,0,0,20,6,6,0,0,0,0,0,0
0,0,0,0,0,6,6,6,6,6,6,6,6,6,6,6,6,6,6,6,6,6,6,6,6,0,20,6,23,0,0,0,6,6,0,0,0,0,0,0
0,0,0,0,0,6,6,0,0,0,6,0,0,0,0,6,0,0,0,0,6,0,0,0,6,0,0,24,0,0,0,0,6,6,0,0,0,0,0,0
0,0,0,0,27,6,6,23,0,0,6,0,0,0,0,6,0,0,0,0,6,0,0,0,6,14,11,6,6,6,6,6,6,6,27,0,0,0,0,0
0,0,0,0,27,6,6,0,0,0,6,0,0,0,0,6,0,0,0,0,6,0,0,0,6,0,0,24,0,0,0,22,6,6,27,0,0,0,0,0
0,0,0,0,27,6,6,0,0,0,6,0,0,0,0,6,0,0,0,0,6,0,0,0,6,0,0,24,0,0,0,0,6,6,27,0,0,0,0,0
0,0,0,0,0,6,6,6,6,6,6,6,6,6,6,6,6,6,6,6,6,6,6,6,6,0,20,6,23,0,0,0,6,6,0,0,0,0,0,0
0,0,0,0,27,6,6,0,0,0,6,0,0,0,0,0,0,0,0,0,0,0,0,0,6,0,0,24,0,0,0,20,6,6,27,0,0,0,0,0
0,0,0,0,27,6,6,0,0,0,6,0,0,0,0,0,0,0,0,0,0,0,0,0,6,0,20,6,23,0,0,0,6,6,27,0,0,0,0,0
0,0,0,0,27,6,6,0,0,0,6,0,0,0,0,0,0,0,0,0,0,0,0,0,6,0,0,24,0,0,0,0,6,6,27,0,0,0,0,0
0,0,0,0,0,6,6,0,0,0,6,0,0,0,0,0,0,0,0,0,0,0,0,0,6,14,11,6,6,6,6,6,6,6,0,0,0,0,0,0
0,0,0,0,0,6,6,6,6,6,6,6,6,6,6,6,6,6,6,6,6,6,6,6,6,0,0,24,0,0,0,22,6,6,0,0,0,0,0,0
0,0,0,0,0,6,6,0,0,0,6,0,0,0,0,0,0,0,0,0,0,0,0,0,6,0,0,24,0,0,0,0,6,6,0,0,0,0,0,0
0,0,0,0,27,6,6,0,0,0,6,0,0,0,0,0,0,0,0,0,0,0,0,0,6,0,20,6,23,0,0,0,6,6,27,0,0,0,0,0
0,0,0,0,27,6,6,0,0,0,6,0,0,0,0,0,0,0,0,0,0,0,0,0,6,0,0,24,0,0,0,0,6,6,27,0,0,0,0,0
0,0,0,27,27,6,6,6,6,6,6,6,6,6,6,6,6,6,6,6,6,6,6,6,6,0,20,6,23,0,0,0,6,6,27,27,0,0,0,0
0,0,27,6,6,6,6,0,0,0,6,0,0,0,0,6,0,0,0,0,6,0,0,0,6,0,0,24,0,0,0,0,6,6,6,6,27,0,0,0
0,27,6,6,6,6,6,23,0,0,6,0,0,0,0,6,0,0,0,0,6,0,0,0,6,0,0,24,0,0,0,20,6,6,6,6,6,27,0,0
27,6,6,6,0,0,22,0,21,0,6,0,0,0,0,6,0,0,21,0,6,0,0,0,6,21,0,24,0,0,21,0,22,0,0,6,6,6,27,0
27,6,6,0,0,0,0,20,6,6,6,6,6,6,6,6,6,6,6,6,6,6,6,6,6,6,6,6,6,6,6,23,0,0,0,0,6,6,27,0
27,6,6,0,0,0,0,0,6,6,6,6,6,6,6,6,6,6,6,6,6,6,6,6,6,6,6,6,6,6,6,0,0,0,0,0,6,28,27,0
27,6,6,21,0,0,0,0,6,6,27,27,27,0,0,0,0,6,0,0,0,6,0,0,0,0,27,27,27,6,6,0,0,0,0,21,6,6,27,0
27,6,6,6,23,0,0,6,6,6,27,0,0,0,0,0,0,11,0,0,0,14,0,0,0,0,0,0,27,6,6,6,0,0,20,6,6,6,27,0
0,27,6,6,6,6,6,6,6,27,0,0,0,0,0,0,0,6,0,0,0,6,0,0,0,0,0,0,0,27,6,6,6,6,6,6,6,27,0,0
0,0,27,6,6,6,6,6,27,0,0,0,0,0,0,0,0,11,13,13,13,14,0,0,0,0,0,0,0,0,27,6,6,28,6,6,27,0,0,0
0,0,0,27,27,27,27,27,0,0,0,0,0,0,0,0,0,6,12,12,12,6,0,0,0,0,0,0,0,0,0,27,27,27,27,27,0,0,0,0
0,0,0,0,0,0,0,0,0,0,0,0,0,0,0,0,0,9,0,0,0,9,0,0,0,0,0,0,0,0,0,0,0,0,0,0,0,0,0,0
0,19,0,0,0,0,0,0,0,0,0,0,0,0,0,0,0,0,0,0,0,0,0,0,0,0,0,0,0,0,0,0,0,0,0,0,0,19,0,0
19,19,19,0,0,0,0,0,0,0,0,0,0,0,0,0,0,0,0,0,0,0,0,0,0,0,0,0,0,0,0,0,0,0,0,0,19,19,19,0
0,19,0,0,0,0,0,0,0,0,0,0,0,0,0,0,0,0,0,0,0,0,0,0,0,0,0,0,0,0,0,0,0,0,0,0,0,19,0,0
0,0,0,0,0,0,0,0,0,0,0,0,0,0,0,0,0,0,0,0,0,0,0,0,0,0,0,0,0,0,0,0,0,0,0,0,0,0,0,0
:endlayer
layer: 11
0,0,0,27,27,27,27,27,0,0,0,0,0,0,0,0,0,0,0,0,0,0,0,0,0,0,0,0,0,0,0,27,27,27,27,27,0,0,0,0
0,0,27,6,6,28,6,6,27,0,0,0,0,0,0,0,0,0,0,0,0,0,0,0,0,0,0,0,0,0,27,6,6,28,6,6,27,0,0,0
0,27,6,6,6,6,6,6,6,27,0,0,0,0,0,0,0,0,0,0,0,0,0,0,0,0,0,0,0,27,6,6,6,6,6,6,6,27,0,0
27,6,6,6,16,16,16,6,6,6,27,0,0,0,0,0,0,0,0,0,0,0,0,0,0,0,0,0,27,6,6,6,0,15,16,6,6,6,27,0
27,6,6,16,16,16,16,16,6,6,27,27,27,30,30,30,27,27,27,30,27,27,27,30,30,30,27,27,27,6,6,0,0,15,16,16,6,6,27,0
27,28,6,16,16,16,16,16,6,6,6,6,6,6,6,6,6,6,6,6,6,6,6,6,6,6,6,6,6,6,6,0,0,16,16,16,6,28,27,0
27,6,6,16,16,16,16,16,6,6,6,6,6,6,6,6,6,6,6,6,6,6,6,6,6,6,6,6,6,6,6,0,0,16,16,16,6,6,27,0
27,6,6,6,16,16,16,16,16,16,16,16,16,16,16,16,16,16,16,16,16,16,16,16,16,16,16,16,16,16,16,0,0,16,16,6,6,6,27,0
0,27,6,6,6,6,6,16,16,16,16,16,16,16,16,16,16,16,16,16,16,16,16,16,16,16,16,16,16,16,16,16,6,6,6,6,6,27,0,0
0,0,27,6,6,6,6,16,16,16,16,16,16,16,16,16,16,16,16,16,16,16,16,16,16,16,16,16,16,16,16,16,6,6,6,6,27,0,0,0
0,0,0,27,27,6,6,16,16,16,16,16,16,16,16,16,16,16,16,16,16,16,16,16,16,16,16,16,16,16,16,16,6,6,27,27,0,0,0,0
0,0,0,0,27,6,6,16,16,16,16,16,16,16,16,16,16,16,16,16,16,16,16,16,16,16,16,16,16,16,16,16,6,6,27,0,0,0,0,0
0,0,0,0,27,6,6,16,16,16,16,16,16,16,16,16,16,16,16,16,16,16,16,16,16,16,16,16,16,16,16,16,6,6,27,0,0,0,0,0
0,0,0,0,30,6,6,16,16,16,16,16,16,16,16,16,16,16,16,16,16,16,16,16,16,16,16,16,16,16,16,16,6,6,30,0,0,0,0,0
0,0,0,0,30,6,6,16,16,16,16,16,16,16,16,16,16,16,16,16,16,16,16,16,16,16,16,16,16,16,16,16,6,6,30,0,0,0,0,0
0,0,0,0,30,6,6,16,16,16,16,16,16,16,16,16,16,16,16,16,16,16,16,16,16,16,16,16,16,16,16,16,6,6,30,0,0,0,0,0
0,0,0,0,27,6,6,16,16,16,16,16,16,16,16,16,16,16,16,16,16,16,16,16,16,16,16,16,16,16,16,16,6,6,27,0,0,0,0,0
0,0,0,0,27,6,6,16,16,16,16,16,16,16,16,16,16,16,16,16,16,16,16,16,16,16,16,16,16,16,16,16,6,6,27,0,0,0,0,0
0,0,0,0,27,6,6,16,16,16,16,16,16,16,16,16,16,16,16,16,16,16,16,16,16,16,16,16,16,16,16,16,6,6,27,0,0,0,0,0
0,0,0,0,30,6,6,16,16,16,16,16,16,16,16,16,16,16,16,16,16,16,16,16,16,16,16,16,16,16,16,16,6,6,30,0,0,0,0,0
0,0,0,0,27,6,6,16,16,16,16,16,16,16,16,16,16,16,16,16,16,16,16,16,16,16,16,16,16,16,16,16,6,6,27,0,0,0,0,0
0,0,0,0,27,6,6,16,16,16,16,16,16,16,16,16,16,16,16,16,16,16,16,16,16,16,16,16,16,16,16,16,6,6,27,0,0,0,0,0
0,0,0,0,27,6,6,16,16,16,16,16,16,16,16,16,16,16,16,16,16,16,16,16,16,16,16,16,16,16,16,16,6,6,27,0,0,0,0,0
0,0,0,0,30,6,6,16,16,16,16,16,16,16,16,16,16,16,16,16,16,16,16,16,16,16,16,16,16,16,16,16,6,6,30,0,0,0,0,0
0,0,0,0,30,6,6,16,16,16,16,16,16,16,16,16,16,16,16,16,16,16,16,16,16,16,16,16,16,16,16,16,6,6,30,0,0,0,0,0
0,0,0,0,30,6,6,16,16,16,16,16,16,16,16,16,16,16,16,16,16,16,16,16,16,16,16,16,16,16,16,16,6,6,30,0,0,0,0,0
0,0,0,0,27,6,6,16,16,16,16,16,16,16,16,16,16,16,16,16,16,16,16,16,16,16,16,16,16,16,16,16,6,6,27,0,0,0,0,0
0,0,0,0,27,6,6,16,16,16,16,16,16,16,16,16,16,16,16,16,16,16,16,16,16,16,16,16,16,16,16,16,6,6,27,0,0,0,0,0
0,0,0,27,27,6,6,16,16,16,16,16,16,16,16,16,16,16,16,16,16,16,16,16,16,16,16,16,16,16,16,16,6,6,27,27,0,0,0,0
0,0,27,6,6,6,6,16,16,16,16,16,16,16,16,16,16,16,16,16,16,16,16,16,16,16,16,16,16,16,16,16,6,6,6,6,27,0,0,0
0,27,6,6,6,6,6,16,16,16,16,16,16,16,16,16,16,16,16,16,16,16,16,16,16,16,16,16,16,16,16,16,6,6,6,6,6,27,0,0
27,6,6,6,16,16,16,16,16,16,16,16,16,16,16,16,16,16,16,16,16,16,16,16,16,16,16,16,16,16,16,16,16,16,16,6,6,6,27,0
27,6,6,16,16,16,16,16,6,6,6,6,6,6,6,6,6,6,16,16,16,6,6,6,6,6,6,6,6,6,6,16,16,16,16,16,6,6,27,0
27,28,6,16,16,16,16,16,6,6,6,6,6,6,6,6,6,6,16,16,16,6,6,6,6,6,6,6,6,6,6,16,16,16,16,16,6,28,27,0
27,6,6,16,16,16,16,16,6,6,27,27,27,30,30,30,30,6,16,16,16,6,30,30,30,30,27,27,27,6,6,16,16,16,16,16,6,6,27,0
27,6,6,6,16,16,16,6,6,6,27,0,0,0,0,0,27,6,16,16,16,6,27,0,0,0,0,0,27,6,6,6,16,16,16,6,6,6,27,0
0,27,6,6,6,6,6,6,6,27,0,0,0,0,0,0,30,6,16,16,16,6,30,0,0,0,0,0,0,27,6,6,6,6,6,6,6,27,0,0
0,0,27,6,6,28,6,6,27,0,0,0,0,0,0,0,30,6,12,12,12,6,30,0,0,0,0,0,0,0,27,6,6,28,6,6,27,0,0,0
0,0,0,27,27,27,27,27,0,0,0,0,0,0,0,0,30,9,0,0,0,9,30,0,0,0,0,0,0,0,0,27,27,27,27,27,0,0,0,0
0,0,0,0,0,0,0,0,0,0,0,0,0,0,0,0,0,0,0,0,0,0,0,0,0,0,0,0,0,0,0,0,0,0,0,0,0,0,0,0
0,29,0,0,0,0,0,0,0,0,0,0,0,0,0,0,0,0,0,0,0,0,0,0,0,0,0,0,0,0,0,0,0,0,0,0,0,29,0,0
29,0,29,0,0,0,0,0,0,0,0,0,0,0,0,0,0,0,0,0,0,0,0,0,0,0,0,0,0,0,0,0,0,0,0,0,29,0,29,0
0,29,0,0,0,0,0,0,0,0,0,0,0,0,0,0,0,0,0,0,0,0,0,0,0,0,0,0,0,0,0,0,0,0,0,0,0,29,0,0
0,0,0,0,0,0,0,0,0,0,0,0,0,0,0,0,0,0,0,0,0,0,0,0,0,0,0,0,0,0,0,0,0,0,0,0,0,0,0,0
:endlayer
layer: 12
0,0,0,0,0,0,0,0,0,0,0,0,0,0,0,0,0,0,0,0,0,0,0,0,0,0,0,0,0,0,0,0,0,0,0,0,0,0,0,0
0,0,11,6,17,32,7,6,14,0,0,0,0,0,0,0,0,0,0,0,0,0,0,0,0,0,0,0,0,0,11,6,17,32,7,6,14,0,0,0
0,32,6,6,6,6,6,6,6,32,0,0,0,0,0,0,0,0,0,0,0,0,0,0,0,0,0,0,0,32,6,6,6,6,6,6,6,32,0,0
0,6,6,6,0,0,0,6,6,6,0,0,0,0,0,0,0,0,0,0,0,0,0,0,0,0,0,0,0,6,6,6,0,0,0,6,6,6,0,0
0,9,6,0,0,0,0,0,6,9,0,0,0,30,30,30,0,0,0,30,0,0,0,30,30,30,0,0,0,9,6,0,0,0,0,0,6,9,0,0
0,11,6,33,33,34,16,16,6,6,35,35,35,6,6,6,35,35,35,28,35,35,35,6,6,6,35,35,35,6,6,0,0,34,33,33,6,14,0,0
0,10,6,16,16,36,16,16,6,6,6,6,6,6,6,6,6,6,6,6,6,6,6,6,6,6,6,6,6,6,6,0,0,36,16,16,6,10,0,0
0,6,6,6,16,36,0,36,16,33,0,0,0,0,37,42,26,26,26,26,26,26,26,41,37,0,0,0,0,33,16,36,21,36,16,6,6,6,0,0
0,31,6,6,6,6,6,16,37,0,0,0,0,0,0,42,26,26,26,26,26,26,26,41,0,0,0,0,0,0,37,16,6,6,6,6,6,31,0,0
0,0,11,6,17,6,6,33,0,0,0,0,0,0,0,42,26,26,26,26,26,26,26,41,0,0,0,0,0,0,0,33,6,6,7,6,14,0,0,0
0,0,0,0,0,35,6,0,0,0,0,0,0,0,0,42,26,26,26,26,26,26,26,41,0,0,0,0,0,0,0,0,6,35,0,0,0,0,0,0
0,0,0,0,0,35,6,0,0,0,0,0,39,0,0,26,38,38,38,38,38,38,38,26,0,0,39,0,0,0,0,0,6,35,0,0,0,0,0,0
0,0,0,0,0,35,6,0,0,0,0,26,26,26,0,0,40,40,40,40,40,40,40,0,0,26,26,26,0,0,0,0,6,35,0,0,0,0,0,0
0,0,0,0,30,6,6,0,0,0,0,26,26,26,26,41,40,43,43,43,43,43,40,42,26,26,26,26,0,0,0,0,6,6,30,0,0,0,0,0
0,0,0,0,30,6,6,37,0,0,0,26,26,26,26,41,40,43,44,44,44,43,40,42,26,26,26,26,0,0,0,37,6,6,30,0,0,0,0,0
0,0,0,0,30,6,6,0,0,0,0,26,26,26,26,41,40,43,44,44,44,43,40,42,26,26,26,26,0,0,0,0,6,6,30,0,0,0,0,0
0,0,0,0,0,35,6,0,0,0,0,26,26,26,26,41,40,43,44,44,44,43,40,42,26,26,26,26,0,0,0,0,6,35,0,0,0,0,0,0
0,0,0,0,0,35,6,0,0,0,0,26,26,26,26,41,40,43,44,44,44,43,40,42,26,26,26,26,0,0,0,0,6,35,0,0,0,0,0,0
0,0,0,0,0,35,6,0,0,0,0,26,26,26,26,41,40,43,44,44,44,43,40,42,26,26,26,26,0,0,0,0,6,35,0,0,0,0,0,0
0,0,0,0,30,28,6,37,0,0,0,26,26,26,26,41,40,43,44,44,44,43,40,42,26,26,26,26,0,0,0,37,6,28,30,0,0,0,0,0
0,0,0,0,0,35,6,0,0,0,0,26,26,26,26,41,40,43,44,44,44,43,40,42,26,26,26,26,0,0,0,0,6,35,0,0,0,0,0,0
0,0,0,0,0,35,6,0,0,0,0,26,26,26,26,41,40,43,43,43,43,43,40,42,26,26,26,26,0,0,0,0,6,35,0,0,0,0,0,0
0,0,0,0,0,35,6,0,0,0,0,26,26,26,26,41,40,40,40,40,40,40,40,42,26,26,26,26,0,0,0,0,6,35,0,0,0,0,0,0
0,0,0,0,30,6,6,0,0,0,0,26,26,26,38,26,40,40,40,40,40,40,40,26,38,26,26,26,0,0,0,0,6,6,30,0,0,0,0,0
0,0,0,0,30,6,6,37,0,0,0,0,38,40,40,40,40,40,40,40,40,40,40,40,40,40,38,0,0,0,0,37,6,6,30,0,0,0,0,0
0,0,0,0,30,6,6,6,0,0,0,6,0,6,6,6,6,6,40,40,40,6,6,6,6,6,0,6,0,0,0,6,6,6,30,0,0,0,0,0
0,0,0,0,0,35,6,0,0,0,0,0,0,0,0,0,0,28,40,40,40,28,0,0,0,0,0,0,0,0,0,0,6,35,0,0,0,0,0,0
0,0,0,0,0,35,6,0,0,0,0,0,0,0,0,0,0,0,0,0,0,0,0,0,0,0,0,0,0,0,0,0,6,35,0,0,0,0,0,0
0,0,0,0,0,35,6,0,0,0,0,0,0,0,0,0,0,0,0,0,0,0,0,0,0,0,0,0,0,0,0,0,6,35,0,0,0,0,0,0
0,0,11,6,17,6,6,33,0,0,0,0,0,0,0,0,0,0,0,0,0,0,0,0,0,0,0,0,0,0,0,33,6,6,7,6,14,0,0,0
0,32,6,6,6,6,6,16,33,0,0,0,0,0,0,0,0,0,0,0,0,0,0,0,0,0,0,0,0,0,33,16,6,6,6,6,6,32,0,0
0,6,6,6,0,16,16,36,16,33,0,0,0,0,0,0,0,0,6,45,6,0,0,0,0,0,0,0,0,33,16,36,26,26,0,6,6,6,0,0
0,9,6,0,0,16,16,0,6,6,6,6,6,6,6,6,6,6,0,0,0,6,6,6,6,6,6,6,6,6,6,26,26,26,0,0,6,9,0,0
0,11,6,0,0,34,36,36,6,6,35,35,35,6,6,6,35,6,0,0,0,6,35,6,6,6,35,35,35,6,6,36,36,34,0,0,6,14,0,0
0,10,6,0,0,33,16,16,6,10,0,0,0,30,30,30,30,6,0,0,0,6,30,30,30,30,0,0,0,10,6,16,16,33,0,0,6,10,0,0
0,6,6,6,0,33,16,6,6,6,0,0,0,0,0,0,27,6,0,0,0,6,27,0,0,0,0,0,0,6,6,6,16,33,0,6,6,6,0,0
0,31,6,6,6,6,6,6,6,31,0,0,0,0,0,0,30,6,0,0,0,6,30,0,0,0,0,0,0,31,6,6,6,6,6,6,6,31,0,0
0,0,11,6,17,31,7,6,14,0,0,0,0,0,0,0,30,9,0,0,0,9,30,0,0,0,0,0,0,0,11,6,17,31,7,6,14,0,0,0
0,0,0,0,0,0,0,0,0,0,0,0,0,0,0,0,0,0,0,0,0,0,0,0,0,0,0,0,0,0,0,0,0,0,0,0,0,0,0,0
0,0,0,0,0,0,0,0,0,0,0,0,0,0,0,0,0,0,0,0,0,0,0,0,0,0,0,0,0,0,0,0,0,0,0,0,0,0,0,0
0,0,0,0,0,0,0,0,0,0,0,0,0,0,0,0,0,0,0,0,0,0,0,0,0,0,0,0,0,0,0,0,0,0,0,0,0,0,0,0
0,0,0,0,0,0,0,0,0,0,0,0,0,0,0,0,0,0,0,0,0,0,0,0,0,0,0,0,0,0,0,0,0,0,0,0,0,0,0,0
0,0,0,0,0,0,0,0,0,0,0,0,0,0,0,0,0,0,0,0,0,0,0,0,0,0,0,0,0,0,0,0,0,0,0,0,0,0,0,0
0,0,0,0,0,0,0,0,0,0,0,0,0,0,0,0,0,0,0,0,0,0,0,0,0,0,0,0,0,0,0,0,0,0,0,0,0,0,0,0
:endlayer
layer: 13
0,0,0,0,0,0,0,0,0,0,0,0,0,0,0,0,0,0,0,0,0,0,0,0,0,0,0,0,0,0,0,0,0,0,0,0,0,0,0,0
0,0,7,6,32,0,32,6,17,0,0,0,0,0,0,0,0,0,0,0,0,0,0,0,0,0,0,0,0,0,7,6,32,0,32,6,17,0,0,0
0,10,6,6,6,46,6,6,6,10,0,0,0,0,0,0,0,0,0,0,0,0,0,0,0,0,0,0,0,10,6,6,6,46,6,6,6,10,0,0
0,6,6,6,0,0,20,6,6,6,0,0,0,0,0,0,0,0,0,0,0,0,0,0,0,0,0,0,0,6,6,6,23,0,0,6,6,6,0,0
0,11,6,0,0,0,0,0,6,14,0,0,0,0,0,0,0,0,0,0,0,0,0,0,0,0,0,0,0,11,6,0,0,0,0,0,6,14,0,0
0,0,46,0,0,34,36,36,6,6,11,47,14,7,32,17,11,47,14,28,11,47,14,7,32,17,32,47,14,6,6,36,36,34,0,0,46,0,0,0
0,11,6,0,0,33,16,16,6,6,6,6,6,6,6,6,6,6,6,6,6,6,6,6,6,6,6,6,6,6,6,16,16,33,0,0,6,14,0,0
0,6,6,6,0,33,16,33,0,0,0,0,0,0,37,0,19,0,0,37,0,0,19,0,37,0,0,0,0,0,0,33,16,33,0,6,6,6,0,0
0,9,6,6,6,6,6,0,37,0,0,0,0,0,0,0,43,43,26,26,26,43,43,0,0,0,0,0,0,0,37,0,6,6,6,6,6,9,0,0
0,0,7,6,31,6,6,0,0,0,0,0,0,0,0,0,43,43,38,38,38,43,43,0,0,0,0,0,0,0,0,0,6,6,31,6,17,0,0,0
0,0,0,0,0,32,6,0,0,0,0,0,0,0,0,0,43,43,48,48,48,43,43,0,0,0,0,0,0,0,0,0,6,32,0,0,0,0,0,0
0,0,0,0,0,47,6,0,0,0,0,0,0,0,0,19,0,0,0,0,0,0,0,19,0,0,0,0,0,0,0,0,6,47,0,0,0,0,0,0
0,0,0,0,0,11,6,0,0,0,0,26,39,26,0,0,0,0,0,0,0,0,0,0,0,26,39,26,0,0,0,0,6,31,0,0,0,0,0,0
0,0,0,0,0,10,6,0,0,0,0,26,26,41,40,0,0,0,0,0,0,0,0,0,40,42,26,26,0,0,0,0,6,10,0,0,0,0,0,0
0,0,0,0,0,11,6,37,0,0,0,26,26,41,40,0,0,0,0,0,0,0,0,0,40,42,26,26,0,0,0,37,6,14,0,0,0,0,0,0
0,0,0,0,0,9,6,0,0,0,0,26,26,41,40,0,0,0,0,0,0,0,0,0,40,42,26,26,0,0,0,0,6,9,0,0,0,0,0,0
0,0,0,0,0,32,6,0,0,0,0,26,26,41,40,0,0,0,0,0,0,0,0,0,40,42,26,26,0,0,0,0,6,32,0,0,0,0,0,0
0,0,0,0,0,47,6,0,0,0,0,26,26,41,40,0,0,0,0,0,0,0,0,0,40,42,26,26,0,0,0,0,6,47,0,0,0,0,0,0
0,0,0,0,0,31,6,0,0,0,0,26,26,41,40,0,0,0,0,0,0,0,0,0,40,42,26,26,0,0,0,0,6,31,0,0,0,0,0,0
0,0,0,0,0,28,6,37,0,0,0,26,26,41,40,0,0,0,0,0,0,0,0,0,40,42,26,26,0,0,0,37,6,28,0,0,0,0,0,0
0,0,0,0,0,32,6,0,0,0,0,26,26,41,40,0,0,0,0,0,0,0,0,0,40,42,26,26,0,0,0,0,6,32,0,0,0,0,0,0
0,0,0,0,0,47,6,0,0,0,0,26,26,41,40,0,0,0,0,0,0,0,0,0,40,42,26,26,0,0,0,0,6,47,0,0,0,0,0,0
0,0,0,0,0,31,6,0,0,0,0,26,26,41,40,0,0,0,0,0,0,0,0,0,40,42,26,26,0,0,0,0,6,31,0,0,0,0,0,0
0,0,0,0,0,10,6,0,0,0,0,26,38,26,0,19,0,0,0,0,0,0,0,19,0,26,38,26,0,0,0,0,6,10,0,0,0,0,0,0
0,0,0,0,0,11,6,37,0,0,0,0,0,0,0,0,0,0,0,0,0,0,0,0,0,0,0,0,0,0,0,37,6,14,0,0,0,0,0,0
0,0,0,0,0,9,6,6,0,0,0,6,0,6,6,6,6,6,0,0,0,6,6,6,6,6,0,6,0,0,0,6,6,9,0,0,0,0,0,0
0,0,0,0,0,32,6,0,0,0,0,0,0,0,0,0,0,28,0,0,0,28,0,0,0,0,0,0,0,0,0,0,6,14,0,0,0,0,0,0
0,0,0,0,0,47,6,0,0,0,0,0,0,0,0,0,0,0,0,0,0,0,0,0,0,0,0,0,0,0,0,0,6,47,0,0,0,0,0,0
0,0,0,0,0,31,6,0,0,0,0,0,0,0,0,0,0,0,0,0,0,0,0,0,0,0,0,0,0,0,0,0,6,31,0,0,0,0,0,0
0,0,7,6,32,6,6,0,0,0,0,0,0,0,0,0,0,0,0,0,0,0,0,0,0,0,0,0,0,0,0,0,6,6,32,6,17,0,0,0
0,10,6,6,6,6,6,0,0,0,0,0,0,0,0,0,0,0,0,0,0,0,0,0,0,0,0,0,0,0,0,0,6,6,6,6,6,10,0,0
0,6,6,6,0,36,16,33,0,0,0,0,0,0,0,0,0,0,6,49,6,0,0,0,0,0,0,0,0,0,0,33,16,36,0,6,6,6,0,0
0,11,6,22,0,36,16,16,6,6,6,6,6,6,6,6,6,6,22,0,22,6,6,6,6,6,6,6,6,6,6,16,16,36,0,0,6,14,0,0
0,0,46,0,0,34,33,33,6,6,11,47,31,7,31,17,11,9,0,0,0,9,14,7,31,17,11,47,14,6,6,33,33,34,0,0,46,0,0,0
0,11,6,0,0,0,0,0,6,14,0,0,0,0,0,0,0,10,0,0,0,10,0,0,0,0,0,0,0,11,6,0,0,0,0,0,6,14,0,0
0,6,6,6,0,0,0,6,6,6,0,0,0,0,0,0,0,10,0,0,0,10,0,0,0,0,0,0,0,6,6,6,0,0,0,6,6,6,0,0
0,9,6,6,6,46,6,6,6,9,0,0,0,0,0,0,0,10,0,0,0,10,0,0,0,0,0,0,0,9,6,6,6,46,6,6,6,9,0,0
0,0,7,6,31,29,31,6,17,0,0,0,0,0,0,0,0,0,0,0,0,0,0,0,0,0,0,0,0,0,7,6,31,29,31,6,17,0,0,0
0,0,0,0,0,0,0,0,0,0,0,0,0,0,0,0,0,0,0,0,0,0,0,0,0,0,0,0,0,0,0,0,0,0,0,0,0,0,0,0
0,0,0,0,0,0,0,0,0,0,0,0,0,0,0,0,0,0,0,0,0,0,0,0,0,0,0,0,0,0,0,0,0,0,0,0,0,0,0,0
0,0,0,0,0,0,0,0,0,0,0,0,0,0,0,0,0,0,0,0,0,0,0,0,0,0,0,0,0,0,0,0,0,0,0,0,0,0,0,0
0,0,0,0,0,0,0,0,0,0,0,0,0,0,0,0,0,0,0,0,0,0,0,0,0,0,0,0,0,0,0,0,0,0,0,0,0,0,0,0
0,0,0,0,0,0,0,0,0,0,0,0,0,0,0,0,0,0,0,0,0,0,0,0,0,0,0,0,0,0,0,0,0,0,0,0,0,0,0,0
0,0,0,0,0,0,0,0,0,0,0,0,0,0,0,0,0,0,0,0,0,0,0,0,0,0,0,0,0,0,0,0,0,0,0,0,0,0,0,0
:endlayer
layer: 14
0,0,0,0,0,0,0,0,0,0,0,0,0,0,0,0,0,0,0,0,0,0,0,0,0,0,0,0,0,0,0,0,0,0,0,0,0,0,0,0
0,0,0,6,50,0,50,6,0,0,0,0,0,0,0,0,0,0,0,0,0,0,0,0,0,0,0,0,0,0,0,6,50,0,50,6,0,0,0,0
0,0,6,6,6,46,6,6,6,0,0,0,0,0,0,0,0,0,0,0,0,0,0,0,0,0,0,0,0,0,6,6,6,46,6,6,6,0,0,0
0,6,6,6,0,36,16,6,6,6,0,0,0,0,0,0,0,0,0,0,0,0,0,0,0,0,0,0,0,6,6,6,16,36,0,6,6,6,0,0
0,50,6,0,0,36,16,16,6,50,0,0,0,0,0,0,0,0,0,0,0,0,0,0,0,0,0,0,0,50,6,16,16,36,0,0,6,50,0,0
0,0,46,0,0,34,33,33,6,6,50,0,50,0,10,0,50,0,50,28,50,0,50,0,10,0,50,0,50,6,6,33,33,34,0,0,46,0,0,0
0,50,6,0,0,0,0,0,6,6,6,46,6,6,6,6,6,46,6,6,6,46,6,6,6,6,6,46,6,6,6,0,0,0,0,0,6,50,0,0
0,6,6,6,0,0,0,0,0,0,0,0,0,0,37,0,29,0,0,37,0,0,29,0,37,0,0,0,0,0,0,0,0,0,0,6,6,6,0,0
0,0,6,6,6,6,6,0,37,0,0,0,0,0,0,0,0,0,42,26,41,0,0,0,0,0,0,0,0,0,37,0,6,6,6,6,6,0,0,0
0,0,0,6,50,6,6,0,0,0,0,0,0,0,0,0,0,0,0,0,0,0,0,0,0,0,0,0,0,0,0,0,6,6,50,6,0,0,0,0
0,0,0,0,0,50,6,0,0,0,0,0,0,0,0,0,0,0,51,51,51,0,0,0,0,0,0,0,0,0,0,0,6,50,0,0,0,0,0,0
0,0,0,0,0,0,46,0,0,0,0,0,0,0,0,29,0,0,0,0,0,0,0,29,0,0,0,0,0,0,0,0,46,0,0,0,0,0,0,0
0,0,0,0,0,50,6,0,0,0,20,26,0,19,0,0,0,0,0,0,0,0,0,0,0,19,0,26,23,0,0,0,6,50,0,0,0,0,0,0
0,0,0,0,0,0,6,0,0,0,0,41,40,0,0,0,0,0,0,0,0,0,0,0,0,0,40,42,0,0,0,0,6,0,0,0,0,0,0,0
0,0,0,0,0,7,6,37,0,0,20,41,40,0,0,0,0,0,0,0,0,0,0,0,0,0,40,42,23,0,0,37,6,17,0,0,0,0,0,0
0,0,0,0,0,0,6,0,0,0,0,41,40,0,0,0,0,0,0,0,0,0,0,0,0,0,40,42,0,0,0,0,6,0,0,0,0,0,0,0
0,0,0,0,0,50,6,0,0,0,0,41,40,0,0,0,0,0,0,0,0,0,0,0,0,0,40,42,0,0,0,0,6,50,0,0,0,0,0,0
0,0,0,0,0,0,46,0,0,0,0,41,40,0,0,0,0,0,0,0,0,0,0,0,0,0,40,42,0,0,0,0,46,0,0,0,0,0,0,0
0,0,0,0,0,50,6,0,0,0,0,41,40,0,0,0,0,0,0,0,0,0,0,0,0,0,40,42,0,0,0,0,6,50,0,0,0,0,0,0
0,0,0,0,0,28,6,37,0,0,20,41,40,0,0,0,0,0,0,0,0,0,0,0,0,0,40,42,23,0,0,37,6,28,0,0,0,0,0,0
0,0,0,0,0,50,6,0,0,0,0,41,40,0,0,0,0,0,0,0,0,0,0,0,0,0,40,42,0,0,0,0,6,50,0,0,0,0,0,0
0,0,0,0,0,0,46,0,0,0,0,41,40,0,0,0,0,0,0,0,0,0,0,0,0,0,40,42,0,0,0,0,46,0,0,0,0,0,0,0
0,0,0,0,0,50,6,0,0,0,0,41,40,0,0,0,0,0,0,0,0,0,0,0,0,0,40,42,0,0,0,0,6,50,0,0,0,0,0,0
0,0,0,0,0,0,6,0,0,0,20,26,0,19,0,29,0,0,0,0,0,0,0,29,0,19,0,26,23,0,0,0,6,0,0,0,0,0,0,0
0,0,0,0,0,7,6,37,0,0,0,0,0,0,0,0,0,0,0,0,0,0,0,0,0,0,0,0,0,0,0,37,6,17,0,0,0,0,0,0
0,0,0,0,0,0,6,6,0,0,0,6,0,6,6,6,6,6,0,0,0,6,6,6,6,6,0,6,0,0,0,6,6,0,0,0,0,0,0,0
0,0,0,0,0,50,6,0,0,0,0,0,0,0,0,0,0,28,0,0,0,28,0,0,0,0,0,0,0,0,0,0,6,50,0,0,0,0,0,0
0,0,0,0,0,0,46,0,0,0,0,0,0,0,0,0,0,0,0,0,0,0,0,0,0,0,0,0,0,0,0,0,46,0,0,0,0,0,0,0
0,0,0,0,0,50,6,0,0,0,0,0,0,0,0,0,0,0,0,0,0,0,0,0,0,0,0,0,0,0,0,0,6,50,0,0,0,0,0,0
0,0,0,6,50,6,6,0,0,0,0,0,0,0,0,0,0,0,0,0,0,0,0,0,0,0,0,0,0,0,0,0,6,6,50,6,0,0,0,0
0,0,6,6,6,6,6,0,0,0,0,0,0,0,0,0,0,0,21,0,21,0,0,0,0,0,0,0,0,0,0,0,6,6,6,6,6,0,0,0
0,6,6,6,16,33,0,0,0,0,0,0,0,0,0,0,0,0,6,31,6,0,0,0,0,0,0,0,0,0,0,0,0,33,16,6,6,6,0,0
0,50,6,16,16,33,0,0,6,6,6,46,6,6,6,6,6,6,0,0,0,6,6,6,6,6,6,46,6,6,6,0,0,33,16,16,6,50,0,0
0,0,46,36,36,34,0,0,6,6,50,0,50,0,9,0,50,22,0,0,0,22,50,0,9,0,50,0,50,6,6,0,0,34,36,36,46,0,0,0
0,50,6,0,0,0,0,0,6,50,0,0,0,0,0,0,0,0,0,0,0,0,0,0,0,0,0,0,0,50,6,0,0,0,0,0,6,50,0,0
0,6,6,6,0,0,0,6,6,6,23,0,0,0,0,0,0,0,0,0,0,0,0,0,0,0,0,0,20,6,6,6,0,0,0,6,6,6,0,0
0,0,6,6,6,46,6,6,6,0,0,0,0,0,0,0,0,0,0,0,0,0,0,0,0,0,0,0,0,0,6,6,6,46,6,6,6,0,0,0
0,0,0,6,50,0,50,6,0,0,0,0,0,0,0,0,0,0,0,0,0,0,0,0,0,0,0,0,0,0,0,6,50,0,50,6,0,0,0,0
0,0,0,0,0,0,0,0,0,0,0,0,0,0,0,0,0,0,0,0,0,0,0,0,0,0,0,0,0,0,0,0,0,0,0,0,0,0,0,0
0,0,0,0,0,0,0,0,0,0,0,0,0,0,0,0,0,0,0,0,0,0,0,0,0,0,0,0,0,0,0,0,0,0,0,0,0,0,0,0
0,0,0,0,0,0,0,0,0,0,0,0,0,0,0,0,0,0,0,0,0,0,0,0,0,0,0,0,0,0,0,0,0,0,0,0,0,0,0,0
0,0,0,0,0,0,0,0,0,0,0,0,0,0,0,0,0,0,0,0,0,0,0,0,0,0,0,0,0,0,0,0,0,0,0,0,0,0,0,0
0,0,0,0,0,0,0,0,0,0,0,0,0,0,0,0,0,0,0,0,0,0,0,0,0,0,0,0,0,0,0,0,0,0,0,0,0,0,0,0
0,0,0,0,0,0,0,0,0,0,0,0,0,0,0,0,0,0,0,0,0,0,0,0,0,0,0,0,0,0,0,0,0,0,0,0,0,0,0,0
:endlayer
layer: 15
0,0,0,0,0,0,0,0,0,0,0,0,0,0,0,0,0,0,0,0,0,0,0,0,0,0,0,0,0,0,0,0,0,0,0,0,0,0,0,0
0,0,11,6,10,0,10,6,14,0,0,0,0,0,0,0,0,0,0,0,0,0,0,0,0,0,0,0,0,0,11,6,10,0,10,6,14,0,0,0
0,32,6,6,6,46,6,6,6,32,0,0,0,0,0,0,0,0,0,0,0,0,0,0,0,0,0,0,0,32,6,6,6,46,6,6,6,32,0,0
0,6,6,6,16,33,0,6,6,6,0,0,0,0,0,0,0,0,0,0,0,0,0,0,0,0,0,0,0,6,6,6,0,33,16,6,6,6,0,0
0,7,6,16,16,33,0,0,6,17,0,0,0,0,0,0,0,0,0,0,0,0,0,0,0,0,0,0,0,7,6,0,0,33,16,16,6,17,0,0
0,0,46,36,36,34,0,0,6,6,50,0,50,0,50,0,50,0,50,28,50,0,50,0,50,0,50,0,50,6,6,0,0,34,36,36,46,0,0,0
0,7,6,0,0,0,0,0,6,6,6,46,6,6,6,6,6,46,6,6,6,46,6,6,6,6,6,46,6,6,6,0,0,0,0,20,6,17,0,0
0,6,6,6,23,0,0,0,0,0,0,0,0,0,37,0,0,0,0,37,0,0,0,0,37,0,0,0,0,0,0,0,0,0,0,6,6,6,0,0
0,31,6,6,6,6,6,0,37,0,0,0,0,0,0,0,0,0,0,26,0,0,0,0,0,0,0,0,0,0,37,0,6,6,6,6,6,31,0,0
0,0,11,6,9,6,6,0,0,0,0,0,0,0,0,0,0,0,0,0,0,0,0,0,0,0,0,0,0,0,0,0,6,6,9,6,14,0,0,0
0,0,0,0,0,50,6,0,0,0,0,0,0,0,0,0,0,0,0,0,0,0,0,0,0,0,0,0,0,0,0,0,6,50,0,0,0,0,0,0
0,0,0,0,0,0,46,0,0,0,0,0,0,0,0,0,0,0,0,0,0,0,0,0,0,0,0,0,0,0,0,0,46,0,0,0,0,0,0,0
0,0,0,0,0,50,6,0,0,0,0,19,0,29,0,0,0,0,0,0,0,0,0,0,0,29,0,19,0,0,0,0,6,50,0,0,0,0,0,0
0,0,0,0,0,0,6,0,0,0,0,0,0,0,0,0,0,0,0,0,0,0,0,0,0,0,0,0,0,0,0,0,6,0,0,0,0,0,0,0
0,0,0,0,0,50,6,37,0,0,0,0,0,0,0,0,0,0,0,0,0,0,0,0,0,0,0,0,0,0,0,37,6,50,0,0,0,0,0,0
0,0,0,0,0,0,6,0,0,0,0,0,0,0,0,0,0,0,0,0,0,0,0,0,0,0,0,0,0,0,0,0,6,0,0,0,0,0,0,0
0,0,0,0,0,50,6,0,0,0,0,0,0,0,0,0,0,0,0,0,0,0,0,0,0,0,0,0,0,0,0,0,6,50,0,0,0,0,0,0
0,0,0,0,0,0,46,0,0,0,0,0,0,0,0,0,0,0,0,0,0,0,0,0,0,0,0,0,0,0,0,0,46,0,0,0,0,0,0,0
0,0,0,0,0,50,6,0,0,0,0,0,0,0,0,0,0,0,0,0,0,0,0,0,0,0,0,0,0,0,0,0,6,50,0,0,0,0,0,0
0,0,0,0,0,28,6,37,0,0,0,0,0,0,0,0,0,0,0,0,0,0,0,0,0,0,0,0,0,0,0,37,6,28,0,0,0,0,0,0
0,0,0,0,0,50,6,0,0,0,0,0,0,0,0,0,0,0,0,0,0,0,0,0,0,0,0,0,0,0,0,0,6,50,0,0,0,0,0,0
0,0,0,0,0,0,46,0,0,0,0,0,0,0,0,0,0,0,0,0,0,0,0,0,0,0,0,0,0,0,0,0,46,0,0,0,0,0,0,0
0,0,0,0,0,50,6,0,0,0,0,0,0,0,0,0,0,0,0,0,0,0,0,0,0,0,0,0,0,0,0,0,6,50,0,0,0,0,0,0
0,0,0,0,0,0,6,0,0,0,0,19,0,29,0,0,0,0,0,0,0,0,0,0,0,29,0,19,0,0,0,0,6,0,0,0,0,0,0,0
0,0,0,0,0,50,6,37,0,0,0,21,0,0,0,0,0,21,0,0,0,21,0,0,0,0,0,21,0,0,0,37,6,50,0,0,0,0,0,0
0,0,0,0,0,0,6,6,14,0,11,6,0,6,6,6,6,6,14,0,11,6,6,6,6,6,0,6,14,0,11,6,6,0,0,0,0,0,0,0
0,0,0,0,0,50,6,22,0,0,0,22,0,22,0,0,0,28,0,0,0,28,0,0,0,22,0,22,0,0,0,22,6,50,0,0,0,0,0,0
0,0,0,0,0,0,46,0,0,0,0,0,0,0,0,0,0,0,0,0,0,0,0,0,0,0,0,0,0,0,0,0,46,0,0,0,0,0,0,0
0,0,0,0,0,50,6,0,0,0,0,0,0,0,0,0,0,0,0,0,0,0,0,0,0,0,0,0,0,0,0,0,6,50,0,0,0,0,0,0
0,0,11,6,10,6,6,0,0,0,0,0,0,0,0,0,0,0,0,0,0,0,0,0,0,0,0,0,0,0,0,0,6,6,10,6,14,0,0,0
0,32,6,6,6,6,6,0,0,0,0,0,0,0,0,0,0,0,0,0,0,0,0,0,0,0,0,0,0,0,0,0,6,6,6,6,6,32,0,0
0,6,6,6,0,0,0,0,0,0,0,0,0,0,0,0,0,0,7,10,17,0,0,0,0,0,0,0,0,0,0,0,0,0,0,6,6,6,0,0
0,7,6,0,0,0,0,0,6,6,6,46,6,6,6,6,6,6,14,22,11,6,6,6,6,6,6,46,6,6,6,0,0,0,0,0,6,17,0,0
0,0,46,33,33,34,0,0,6,6,50,0,50,0,50,0,50,0,0,0,0,0,50,0,50,0,50,0,50,6,6,0,0,34,33,33,46,0,0,0
0,7,6,16,16,36,0,21,6,17,0,0,0,0,0,0,0,0,0,0,0,0,0,0,0,0,0,0,0,7,6,21,0,36,16,16,6,17,0,0
0,6,6,6,16,36,0,6,6,6,0,0,0,0,0,0,0,0,0,0,0,0,0,0,0,0,0,0,0,6,6,6,0,36,16,6,6,6,0,0
0,31,6,6,6,46,6,6,6,31,0,0,0,0,0,0,0,0,0,0,0,0,0,0,0,0,0,0,0,31,6,6,6,46,6,6,6,31,0,0
0,0,11,6,9,0,9,6,14,0,0,0,0,0,0,0,0,0,0,0,0,0,0,0,0,0,0,0,0,0,11,6,9,0,9,6,14,0,0,0
0,0,0,0,0,0,0,0,0,0,0,0,0,0,0,0,0,0,0,0,0,0,0,0,0,0,0,0,0,0,0,0,0,0,0,0,0,0,0,0
0,0,0,0,0,0,0,0,0,0,0,0,0,0,0,0,0,0,0,0,0,0,0,0,0,0,0,0,0,0,0,0,0,0,0,0,0,0,0,0
0,0,0,0,0,0,0,0,0,0,0,0,0,0,0,0,0,0,0,0,0,0,0,0,0,0,0,0,0,0,0,0,0,0,0,0,0,0,0,0
0,0,0,0,0,0,0,0,0,0,0,0,0,0,0,0,0,0,0,0,0,0,0,0,0,0,0,0,0,0,0,0,0,0,0,0,0,0,0,0
0,0,0,0,0,0,0,0,0,0,0,0,0,0,0,0,0,0,0,0,0,0,0,0,0,0,0,0,0,0,0,0,0,0,0,0,0,0,0,0
0,0,0,0,0,0,0,0,0,0,0,0,0,0,0,0,0,0,0,0,0,0,0,0,0,0,0,0,0,0,0,0,0,0,0,0,0,0,0,0
:endlayer
layer: 16
0,0,0,0,0,0,0,0,0,0,0,0,0,0,0,0,0,0,0,0,0,0,0,0,0,0,0,0,0,0,0,0,0,0,0,0,0,0,0,0
0,0,7,6,14,10,11,6,17,0,0,0,0,0,0,0,0,0,0,0,0,0,0,0,0,0,0,0,0,0,7,6,14,10,11,6,17,0,0,0
0,10,6,6,6,6,6,6,6,10,0,0,0,0,0,0,0,0,0,0,0,0,0,0,0,0,0,0,0,10,6,6,6,6,6,6,6,10,0,0
0,6,6,6,0,0,0,6,6,6,0,0,0,0,0,0,0,0,0,0,0,0,0,0,0,0,0,0,0,6,6,6,0,0,0,6,6,6,0,0
0,31,6,0,0,0,0,0,6,31,0,0,0,0,0,0,0,0,0,0,0,0,0,0,0,0,0,0,0,31,6,0,0,0,0,0,6,31,0,0
0,7,6,33,33,34,0,0,6,6,7,47,17,0,32,0,7,47,17,28,7,47,17,0,32,0,7,47,17,6,6,0,0,34,33,33,6,17,0,0
0,32,6,16,16,36,0,0,6,6,6,6,6,6,6,6,6,6,6,6,6,6,6,6,6,6,6,6,6,6,6,0,0,36,16,16,6,32,0,0
0,6,6,6,16,36,0,0,6,6,23,22,0,0,37,0,0,22,0,37,0,22,0,0,37,0,0,22,20,6,6,0,0,36,16,6,6,6,0,0
0,9,6,6,6,6,6,6,37,22,0,0,0,0,0,0,0,0,0,51,0,0,0,0,0,0,0,0,0,22,37,6,6,6,6,6,6,9,0,0
0,0,7,6,14,6,6,6,23,0,0,0,0,0,0,0,0,0,0,0,0,0,0,0,0,0,0,0,0,0,20,6,6,6,11,6,17,0,0,0
0,0,0,0,0,10,6,22,0,0,0,0,0,0,0,0,0,0,0,0,0,0,0,0,0,0,0,0,0,0,0,22,6,10,0,0,0,0,0,0
0,0,0,0,0,47,6,23,0,0,0,0,0,0,0,0,0,0,0,0,0,0,0,0,0,0,0,0,0,0,0,20,6,47,0,0,0,0,0,0
0,0,0,0,0,9,6,0,0,0,0,29,0,0,0,0,0,0,0,0,0,0,0,0,0,0,0,29,0,0,0,0,6,9,0,0,0,0,0,0
0,0,0,0,0,0,6,0,0,0,0,0,0,0,0,0,0,0,0,0,0,0,0,0,0,0,0,0,0,0,0,0,6,0,0,0,0,0,0,0
0,0,0,0,0,11,6,37,0,0,0,0,0,0,0,0,0,0,0,0,0,0,0,0,0,0,0,0,0,0,0,37,6,14,0,0,0,0,0,0
0,0,0,0,0,0,6,0,0,0,0,0,0,0,0,0,0,0,0,0,0,0,0,0,0,0,0,0,0,0,0,0,6,0,0,0,0,0,0,0
0,0,0,0,0,10,6,0,0,0,0,0,0,0,0,0,0,0,0,0,0,0,0,0,0,0,0,0,0,0,0,0,6,10,0,0,0,0,0,0
0,0,0,0,0,47,6,23,0,0,0,0,0,0,0,0,0,0,0,0,0,0,0,0,0,0,0,0,0,0,0,20,6,47,0,0,0,0,0,0
0,0,0,0,0,9,6,0,0,0,0,0,0,0,0,0,0,0,0,0,0,0,0,0,0,0,0,0,0,0,0,0,6,9,0,0,0,0,0,0
0,0,0,0,0,28,6,37,0,0,0,0,0,0,0,0,0,0,0,0,0,0,0,0,0,0,0,0,0,0,0,37,6,28,0,0,0,0,0,0
0,0,0,0,0,10,6,0,0,0,0,0,0,0,0,0,0,0,0,0,0,0,0,0,0,0,0,0,0,0,0,0,6,10,0,0,0,0,0,0
0,0,0,0,0,47,6,23,0,0,0,0,0,0,0,0,0,0,0,0,0,0,0,0,0,0,0,0,0,0,0,20,6,47,0,0,0,0,0,0
0,0,0,0,0,9,6,0,0,0,0,0,0,0,0,0,0,0,0,0,0,0,0,0,0,0,0,0,0,0,0,0,6,9,0,0,0,0,0,0
0,0,0,0,0,0,6,0,0,0,0,29,0,0,0,0,0,0,0,0,0,0,0,0,0,0,0,29,0,0,0,0,6,0,0,0,0,0,0,0
0,0,0,0,0,11,6,37,0,0,0,0,0,0,0,0,0,0,0,0,0,0,0,0,0,0,0,0,0,0,0,37,6,14,0,0,0,0,0,0
0,0,0,0,0,0,6,6,6,6,6,6,6,6,6,6,6,6,6,6,6,6,6,6,6,6,6,6,6,6,6,6,6,0,0,0,0,0,0,0
0,0,0,0,0,10,6,0,0,0,0,0,0,0,0,0,0,28,0,22,0,28,0,0,0,0,0,0,0,0,0,0,6,10,0,0,0,0,0,0
0,0,0,0,0,47,6,23,0,0,0,0,0,0,0,0,0,0,0,0,0,0,0,0,0,0,0,0,0,0,0,20,6,47,0,0,0,0,0,0
0,0,0,0,0,9,6,21,0,0,0,0,0,0,0,0,0,0,0,0,0,0,0,0,0,0,0,0,0,0,0,21,6,9,0,0,0,0,0,0
0,0,7,6,14,6,6,6,23,0,0,0,0,0,0,0,0,0,0,0,0,0,0,0,0,0,0,0,0,0,20,6,6,6,11,6,17,0,0,0
0,10,6,6,6,6,6,6,0,21,0,0,0,0,0,0,0,0,0,0,0,0,0,0,0,0,0,0,0,21,0,6,6,6,6,6,6,10,0,0
0,6,6,6,0,0,0,0,6,6,23,21,0,0,0,0,0,0,0,0,0,0,0,0,0,0,0,21,20,6,6,0,0,0,0,6,6,6,0,0
0,31,6,0,0,0,0,0,6,6,6,6,6,6,6,6,6,6,6,6,6,6,6,6,6,6,6,6,6,6,6,0,0,0,0,0,6,31,0,0
0,7,6,0,0,34,36,36,6,6,7,47,17,0,31,0,7,0,0,0,0,0,17,0,31,0,7,47,17,6,6,36,36,34,0,0,6,17,0,0
0,32,6,0,0,33,16,16,6,32,0,0,0,0,0,0,0,0,0,0,0,0,0,0,0,0,0,0,0,32,6,16,16,33,0,0,6,32,0,0
0,6,6,6,0,33,16,6,6,6,0,0,0,0,0,0,0,0,0,0,0,0,0,0,0,0,0,0,0,6,6,6,16,33,0,6,6,6,0,0
0,9,6,6,6,6,6,6,6,9,0,0,0,0,0,0,0,0,0,0,0,0,0,0,0,0,0,0,0,9,6,6,6,6,6,6,6,9,0,0
0,0,7,6,14,9,11,6,17,0,0,0,0,0,0,0,0,0,0,0,0,0,0,0,0,0,0,0,0,0,7,6,14,9,11,6,17,0,0,0
0,0,0,0,0,0,0,0,0,0,0,0,0,0,0,0,0,0,0,0,0,0,0,0,0,0,0,0,0,0,0,0,0,0,0,0,0,0,0,0
0,0,0,0,0,0,0,0,0,0,0,0,0,0,0,0,0,0,0,0,0,0,0,0,0,0,0,0,0,0,0,0,0,0,0,0,0,0,0,0
0,0,0,0,0,0,0,0,0,0,0,0,0,0,0,0,0,0,0,0,0,0,0,0,0,0,0,0,0,0,0,0,0,0,0,0,0,0,0,0
0,0,0,0,0,0,0,0,0,0,0,0,0,0,0,0,0,0,0,0,0,0,0,0,0,0,0,0,0,0,0,0,0,0,0,0,0,0,0,0
0,0,0,0,0,0,0,0,0,0,0,0,0,0,0,0,0,0,0,0,0,0,0,0,0,0,0,0,0,0,0,0,0,0,0,0,0,0,0,0
0,0,0,0,0,0,0,0,0,0,0,0,0,0,0,0,0,0,0,0,0,0,0,0,0,0,0,0,0,0,0,0,0,0,0,0,0,0,0,0
:endlayer
layer: 17
0,0,0,27,27,27,27,27,0,0,0,0,0,0,0,0,0,0,0,0,0,0,0,0,0,0,0,0,0,0,0,27,27,27,27,27,0,0,0,0
0,0,27,6,6,28,6,6,27,0,0,0,0,0,0,0,0,0,0,0,0,0,0,0,0,0,0,0,0,0,27,6,6,28,6,6,27,0,0,0
0,27,6,6,6,6,6,6,6,27,0,0,0,0,0,0,0,0,0,0,0,0,0,0,0,0,0,0,0,27,6,6,6,6,6,6,6,27,0,0
27,6,6,6,0,0,0,6,6,6,27,0,0,0,0,0,0,0,0,0,0,0,0,0,0,0,0,0,27,6,6,6,0,0,0,6,6,6,27,0
27,6,6,0,0,0,0,22,6,6,27,27,27,0,0,0,27,27,27,0,27,27,27,0,0,0,27,27,27,6,6,22,0,0,0,0,6,6,27,0
27,28,6,0,0,34,36,36,6,6,6,6,6,11,10,14,6,6,6,28,6,6,6,11,10,14,6,6,6,6,6,36,36,34,0,0,6,28,27,0
27,6,6,0,0,33,16,16,6,6,6,6,6,6,6,6,6,6,6,6,6,6,6,6,6,6,6,6,6,6,6,16,16,33,0,0,6,6,27,0
27,6,6,6,0,33,16,16,6,53,53,53,53,53,53,53,53,53,53,53,53,53,53,53,53,53,53,53,53,53,6,16,16,33,0,6,6,6,27,0
0,27,6,6,6,6,6,6,37,0,0,0,0,0,22,0,0,0,0,22,0,0,0,0,22,0,0,0,0,0,37,6,6,6,6,6,6,27,0,0
0,0,27,6,6,6,6,52,0,0,0,0,0,0,0,0,0,0,0,0,0,0,0,0,0,0,0,0,0,0,0,52,6,6,6,6,27,0,0,0
0,0,0,27,27,6,6,52,0,0,0,0,0,0,0,0,0,0,0,0,0,0,0,0,0,0,0,0,0,0,0,52,6,6,27,27,0,0,0,0
0,0,0,0,27,6,6,52,0,0,0,0,0,0,0,0,0,0,0,0,0,0,0,0,0,0,0,0,0,0,0,52,6,6,27,0,0,0,0,0
0,0,0,0,27,6,6,52,0,0,0,0,0,0,0,0,0,0,0,0,0,0,0,0,0,0,0,0,0,0,0,52,6,6,27,0,0,0,0,0
0,0,0,0,0,32,6,52,0,0,0,0,0,0,0,0,0,0,0,0,0,0,0,0,0,0,0,0,0,0,0,52,6,32,0,0,0,0,0,0
0,0,0,0,0,7,6,52,23,0,0,0,0,0,0,0,0,0,0,0,0,0,0,0,0,0,0,0,0,0,20,52,6,17,0,0,0,0,0,0
0,0,0,0,0,31,6,52,0,0,0,0,0,0,0,0,0,0,0,0,0,0,0,0,0,0,0,0,0,0,0,52,6,31,0,0,0,0,0,0
0,0,0,0,27,6,6,52,0,0,0,0,0,0,0,0,0,0,0,0,0,0,0,0,0,0,0,0,0,0,0,52,6,6,27,0,0,0,0,0
0,0,0,0,27,6,6,52,0,0,0,0,0,0,0,0,0,0,0,0,0,0,0,0,0,0,0,0,0,0,0,52,6,6,27,0,0,0,0,0
0,0,0,0,27,6,6,52,0,0,0,0,0,0,0,0,0,0,0,0,0,0,0,0,0,0,0,0,0,0,0,52,6,6,27,0,0,0,0,0
0,0,0,0,0,28,6,52,23,0,0,0,0,0,0,0,0,0,0,0,0,0,0,0,0,0,0,0,0,0,20,52,6,28,0,0,0,0,0,0
0,0,0,0,27,6,6,52,0,0,0,0,0,0,0,0,0,0,0,0,0,0,0,0,0,0,0,0,0,0,0,52,6,6,27,0,0,0,0,0
0,0,0,0,27,6,6,52,0,0,0,0,0,0,0,0,0,0,0,0,0,0,0,0,0,0,0,0,0,0,0,52,6,6,27,0,0,0,0,0
0,0,0,0,27,6,6,52,0,0,0,0,0,0,0,0,0,0,0,0,0,0,0,0,0,0,0,0,0,0,0,52,6,6,27,0,0,0,0,0
0,0,0,0,0,32,6,52,0,0,0,0,0,0,0,0,0,0,0,0,0,0,0,0,0,0,0,0,0,0,0,52,6,32,0,0,0,0,0,0
0,0,0,0,0,7,6,52,23,0,0,0,0,0,0,0,0,0,0,0,0,0,0,0,0,0,0,0,0,0,20,52,6,17,0,0,0,0,0,0
0,0,0,0,0,31,6,6,6,6,6,6,6,6,6,6,6,6,6,6,6,6,6,6,6,6,6,6,6,6,6,6,6,31,0,0,0,0,0,0
0,0,0,0,27,6,6,0,0,0,0,0,0,0,0,0,0,28,0,0,0,28,0,0,0,0,0,0,0,0,0,0,6,6,27,0,0,0,0,0
0,0,0,0,27,6,6,0,0,0,0,0,0,0,0,0,0,0,0,0,0,0,0,0,0,0,0,0,0,0,0,0,6,6,27,0,0,0,0,0
0,0,0,27,27,6,6,0,0,0,0,0,0,0,0,0,0,0,0,0,0,0,0,0,0,0,0,0,0,0,0,0,6,6,27,27,0,0,0,0
0,0,27,6,6,6,6,0,0,0,0,0,0,0,0,0,0,0,0,0,0,0,0,0,0,0,0,0,0,0,0,0,6,6,6,6,27,0,0,0
0,27,6,6,6,6,6,6,0,0,0,0,0,0,0,0,0,0,0,0,0,0,0,0,0,0,0,0,0,0,0,6,6,6,6,6,6,27,0,0
27,6,6,6,23,36,16,26,6,0,0,0,0,0,0,0,0,0,0,0,0,0,0,0,0,0,0,0,0,0,6,26,16,36,20,6,6,6,27,0
27,6,6,0,0,36,16,16,6,6,6,6,6,6,6,6,6,6,6,6,6,6,6,6,6,6,6,6,6,6,6,16,16,36,0,0,6,6,27,0
27,28,6,0,0,34,33,33,6,6,6,6,6,11,9,14,6,6,6,28,6,6,6,11,9,14,6,6,6,6,6,33,33,34,0,0,6,28,27,0
27,6,6,0,0,0,0,0,6,6,27,27,27,0,0,0,27,27,27,0,27,27,27,0,0,0,27,27,27,6,6,0,0,0,0,0,6,6,27,0
27,6,6,6,0,0,0,6,6,6,27,0,0,0,0,0,0,0,0,0,0,0,0,0,0,0,0,0,27,6,6,6,0,0,0,6,6,6,27,0
0,27,6,6,6,6,6,6,6,27,0,0,0,0,0,0,0,0,0,0,0,0,0,0,0,0,0,0,0,27,6,6,6,6,6,6,6,27,0,0
0,0,27,6,6,28,6,6,27,0,0,0,0,0,0,0,0,0,0,0,0,0,0,0,0,0,0,0,0,0,27,6,6,28,6,6,27,0,0,0
0,0,0,27,27,27,27,27,0,0,0,0,0,0,0,0,0,0,0,0,0,0,0,0,0,0,0,0,0,0,0,27,27,27,27,27,0,0,0,0
0,0,0,0,0,0,0,0,0,0,0,0,0,0,0,0,0,0,0,0,0,0,0,0,0,0,0,0,0,0,0,0,0,0,0,0,0,0,0,0
0,0,0,0,0,0,0,0,0,0,0,0,0,0,0,0,0,0,0,0,0,0,0,0,0,0,0,0,0,0,0,0,0,0,0,0,0,0,0,0
0,0,0,0,0,0,0,0,0,0,0,0,0,0,0,0,0,0,0,0,0,0,0,0,0,0,0,0,0,0,0,0,0,0,0,0,0,0,0,0
0,0,0,0,0,0,0,0,0,0,0,0,0,0,0,0,0,0,0,0,0,0,0,0,0,0,0,0,0,0,0,0,0,0,0,0,0,0,0,0
0,0,0,0,0,0,0,0,0,0,0,0,0,0,0,0,0,0,0,0,0,0,0,0,0,0,0,0,0,0,0,0,0,0,0,0,0,0,0,0
:endlayer
layer: 18
0,0,0,0,0,0,0,0,0,0,0,0,0,0,0,0,0,0,0,0,0,0,0,0,0,0,0,0,0,0,0,0,0,0,0,0,0,0,0,0
0,0,11,6,17,32,7,6,14,0,0,0,0,0,0,0,0,0,0,0,0,0,0,0,0,0,0,0,0,0,11,6,17,32,7,6,14,0,0,0
0,32,6,6,6,6,6,6,6,32,0,0,0,0,0,0,0,0,0,0,0,0,0,0,0,0,0,0,0,32,6,6,6,6,6,6,6,32,0,0
0,6,6,6,0,36,16,6,6,6,0,0,0,0,0,0,0,0,0,0,0,0,0,0,0,0,0,0,0,6,6,6,16,36,0,6,6,6,0,0
0,9,6,0,0,36,16,16,6,9,0,0,0,30,30,30,0,0,0,30,0,0,0,30,30,30,0,0,0,9,6,16,16,36,0,0,6,9,0,0
0,11,6,0,0,34,33,33,6,6,35,35,35,6,6,6,35,35,35,28,35,35,35,6,6,6,35,35,35,6,6,33,33,34,0,0,6,14,0,0
0,10,6,0,0,0,0,0,6,6,6,6,6,6,6,6,6,6,6,6,6,6,6,6,6,6,6,6,6,6,6,0,0,0,0,0,6,10,0,0
0,6,6,6,0,0,0,0,6,0,0,0,0,0,37,0,0,0,0,37,0,0,0,0,37,0,0,0,0,0,6,0,0,0,0,6,6,6,0,0
0,31,6,6,6,6,6,6,37,0,0,0,0,0,0,0,0,0,0,0,0,0,0,0,0,0,0,0,0,0,37,6,6,6,6,6,6,31,0,0
0,0,11,6,17,6,6,0,0,0,0,0,0,0,0,0,0,0,0,0,0,0,0,0,0,0,0,0,0,0,0,0,6,6,7,6,14,0,0,0
0,0,0,0,0,35,6,0,0,0,0,0,0,0,0,0,0,0,0,0,0,0,0,0,0,0,0,0,0,0,0,0,6,35,0,0,0,0,0,0
0,0,0,0,0,35,6,0,0,0,0,0,0,0,0,0,0,0,0,0,0,0,0,0,0,0,0,0,0,0,0,0,6,35,0,0,0,0,0,0
0,0,0,0,0,35,6,0,0,0,0,0,0,0,0,0,0,0,0,0,0,0,0,0,0,0,0,0,0,0,0,0,6,35,0,0,0,0,0,0
0,0,0,0,30,6,6,0,0,0,0,0,0,0,0,0,0,0,0,0,0,0,0,0,0,0,0,0,0,0,0,0,6,6,30,0,0,0,0,0
0,0,0,0,30,6,6,37,0,0,0,0,0,0,0,0,0,0,0,0,0,0,0,0,0,0,0,0,0,0,0,37,6,6,30,0,0,0,0,0
0,0,0,0,30,6,6,0,0,0,0,0,0,0,0,0,0,0,0,0,0,0,0,0,0,0,0,0,0,0,0,0,6,6,30,0,0,0,0,0
0,0,0,0,0,35,6,0,0,0,0,0,0,0,0,0,0,0,0,0,0,0,0,0,0,0,0,0,0,0,0,0,6,35,0,0,0,0,0,0
0,0,0,0,0,35,6,0,0,0,0,0,0,0,0,0,0,0,0,0,0,0,0,0,0,0,0,0,0,0,0,0,6,35,0,0,0,0,0,0
0,0,0,0,0,35,6,0,0,0,0,0,0,0,0,0,0,0,0,0,0,0,0,0,0,0,0,0,0,0,0,0,6,35,0,0,0,0,0,0
0,0,0,0,30,28,6,37,0,0,0,0,0,0,0,0,0,0,0,0,0,0,0,0,0,0,0,0,0,0,0,37,6,28,30,0,0,0,0,0
0,0,0,0,0,35,6,0,0,0,0,0,0,0,0,0,0,0,0,0,0,0,0,0,0,0,0,0,0,0,0,0,6,35,0,0,0,0,0,0
0,0,0,0,0,35,6,0,0,0,0,0,0,0,0,0,0,0,0,0,0,0,0,0,0,0,0,0,0,0,0,0,6,35,0,0,0,0,0,0
0,0,0,0,0,35,6,0,0,0,0,0,0,0,0,0,0,0,0,0,0,0,0,0,0,0,0,0,0,0,0,0,6,35,0,0,0,0,0,0
0,0,0,0,30,6,6,0,0,0,0,0,0,0,0,0,0,0,0,0,0,0,0,0,0,0,0,0,0,0,0,0,6,6,30,0,0,0,0,0
0,0,0,0,30,6,6,37,0,0,0,0,0,0,0,0,0,0,0,0,0,0,0,0,0,0,0,0,0,0,0,37,6,6,30,0,0,0,0,0
0,0,0,0,30,6,6,39,39,39,39,39,39,39,39,39,39,39,39,39,39,39,39,39,39,39,39,39,39,39,39,39,6,6,30,0,0,0,0,0
0,0,0,0,0,35,6,26,26,26,26,26,26,26,26,26,26,26,26,26,26,26,26,26,26,26,26,26,26,26,26,26,6,35,0,0,0,0,0,0
0,0,0,0,0,35,6,26,26,26,26,26,26,26,26,26,26,26,26,26,26,26,26,26,26,26,26,26,26,26,26,26,6,35,0,0,0,0,0,0
0,0,0,0,0,35,6,26,26,26,26,26,26,26,26,26,26,26,26,26,26,26,26,26,26,26,26,26,26,26,26,26,6,35,0,0,0,0,0,0
0,0,11,6,17,6,6,26,26,26,26,26,26,26,26,26,26,26,26,26,26,26,26,26,26,26,26,26,26,26,26,26,6,6,7,6,14,0,0,0
0,32,6,6,6,6,6,26,26,26,26,26,26,26,26,26,26,26,26,26,26,26,26,26,26,26,26,26,26,26,26,26,6,6,6,6,6,32,0,0
0,6,6,6,16,33,0,54,26,26,26,26,26,26,26,26,26,26,26,26,26,26,26,26,26,26,26,26,26,26,26,54,0,33,16,6,6,6,0,0
0,9,6,16,16,33,0,0,6,6,6,6,6,6,6,6,6,6,6,6,6,6,6,6,6,6,6,6,6,6,6,0,0,33,16,16,6,9,0,0
0,11,6,36,36,34,0,0,6,6,35,35,35,6,6,6,35,35,35,28,35,35,35,6,6,6,35,35,35,6,6,0,0,34,36,36,6,14,0,0
0,10,6,0,0,0,0,0,6,10,0,0,0,30,30,30,0,0,0,30,0,0,0,30,30,30,0,0,0,10,6,0,0,0,0,0,6,10,0,0
0,6,6,6,0,0,0,6,6,6,0,0,0,0,0,0,0,0,0,0,0,0,0,0,0,0,0,0,0,6,6,6,0,0,0,6,6,6,0,0
0,31,6,6,6,6,6,6,6,31,0,0,0,0,0,0,0,0,0,0,0,0,0,0,0,0,0,0,0,31,6,6,6,6,6,6,6,31,0,0
0,0,11,6,17,31,7,6,14,0,0,0,0,0,0,0,0,0,0,0,0,0,0,0,0,0,0,0,0,0,11,6,17,31,7,6,14,0,0,0
0,0,0,0,0,0,0,0,0,0,0,0,0,0,0,0,0,0,0,0,0,0,0,0,0,0,0,0,0,0,0,0,0,0,0,0,0,0,0,0
0,0,0,0,0,0,0,0,0,0,0,0,0,0,0,0,0,0,0,0,0,0,0,0,0,0,0,0,0,0,0,0,0,0,0,0,0,0,0,0
0,0,0,0,0,0,0,0,0,0,0,0,0,0,0,0,0,0,0,0,0,0,0,0,0,0,0,0,0,0,0,0,0,0,0,0,0,0,0,0
0,0,0,0,0,0,0,0,0,0,0,0,0,0,0,0,0,0,0,0,0,0,0,0,0,0,0,0,0,0,0,0,0,0,0,0,0,0,0,0
0,0,0,0,0,0,0,0,0,0,0,0,0,0,0,0,0,0,0,0,0,0,0,0,0,0,0,0,0,0,0,0,0,0,0,0,0,0,0,0
0,0,0,0,0,0,0,0,0,0,0,0,0,0,0,0,0,0,0,0,0,0,0,0,0,0,0,0,0,0,0,0,0,0,0,0,0,0,0,0
:endlayer
layer: 19
0,0,0,0,0,0,0,0,0,0,0,0,0,0,0,0,0,0,0,0,0,0,0,0,0,0,0,0,0,0,0,0,0,0,0,0,0,0,0,0
0,0,7,6,32,0,32,6,17,0,0,0,0,0,0,0,0,0,0,0,0,0,0,0,0,0,0,0,0,0,7,6,32,0,32,6,17,0,0,0
0,10,6,6,6,46,6,6,6,10,0,0,0,0,0,0,0,0,0,0,0,0,0,0,0,0,0,0,0,10,6,6,6,46,6,6,6,10,0,0
0,6,6,6,16,33,0,6,6,6,0,0,0,0,0,0,0,0,0,0,0,0,0,0,0,0,0,0,0,6,6,6,0,33,16,6,6,6,0,0
0,11,6,16,16,33,0,0,6,14,0,0,0,0,0,0,0,0,0,0,0,0,0,0,0,0,0,0,0,11,6,0,0,33,16,16,6,14,0,0
0,0,46,36,36,34,0,0,6,6,11,47,14,7,32,17,11,47,14,28,11,47,14,7,32,17,11,47,14,6,6,0,0,34,36,36,46,0,0,0
0,11,6,21,0,0,0,0,6,6,6,6,6,6,6,6,6,6,6,6,6,6,6,6,6,6,6,6,6,6,6,0,0,0,0,21,6,14,0,0
0,6,6,6,0,0,0,0,6,0,0,0,0,0,37,0,0,0,0,37,0,0,0,0,37,0,0,0,0,0,6,0,0,0,0,6,6,6,0,0
0,9,6,6,6,6,6,6,37,0,0,0,0,0,0,0,0,0,0,0,0,0,0,0,0,0,0,0,0,0,37,6,6,6,6,6,6,9,0,0
0,0,7,6,31,6,6,0,0,0,0,0,0,0,0,0,0,0,0,0,0,0,0,0,0,0,0,0,0,0,0,0,6,6,31,6,17,0,0,0
0,0,0,0,0,32,6,0,0,0,0,0,0,0,0,0,0,0,0,0,0,0,0,0,0,0,0,0,0,0,0,0,6,32,0,0,0,0,0,0
0,0,0,0,0,47,6,0,0,0,0,0,0,0,0,0,0,0,0,0,0,0,0,0,0,0,0,0,0,0,0,0,6,47,0,0,0,0,0,0
0,0,0,0,0,31,6,0,0,0,0,0,0,0,0,0,0,0,0,0,0,0,0,0,0,0,0,0,0,0,0,0,6,31,0,0,0,0,0,0
0,0,0,0,0,10,6,0,0,0,0,0,0,0,0,0,0,0,0,0,0,0,0,0,0,0,0,0,0,0,0,0,6,10,0,0,0,0,0,0
0,0,0,0,0,11,6,37,0,0,0,0,0,0,0,0,0,0,0,0,0,0,0,0,0,0,0,0,0,0,0,37,6,14,0,0,0,0,0,0
0,0,0,0,0,9,6,0,0,0,0,0,0,0,0,0,0,0,0,0,0,0,0,0,0,0,0,0,0,0,0,0,6,9,0,0,0,0,0,0
0,0,0,0,0,32,6,0,0,0,0,0,0,0,0,0,0,0,0,0,0,0,0,0,0,0,0,0,0,0,0,0,6,32,0,0,0,0,0,0
0,0,0,0,0,47,6,0,0,0,0,0,0,0,0,0,0,0,0,0,0,0,0,0,0,0,0,0,0,0,0,0,6,47,0,0,0,0,0,0
0,0,0,0,0,31,6,0,0,0,0,0,0,0,0,0,0,0,0,0,0,0,0,0,0,0,0,0,0,0,0,0,6,31,0,0,0,0,0,0
0,0,0,0,0,28,6,37,0,0,0,0,0,0,0,0,0,0,0,0,0,0,0,0,0,0,0,0,0,0,0,37,6,28,0,0,0,0,0,0
0,0,0,0,0,32,6,0,0,0,0,0,0,0,0,0,0,0,0,0,0,0,0,0,0,0,0,0,0,0,0,0,6,32,0,0,0,0,0,0
0,0,0,0,0,47,6,0,0,0,0,0,0,0,0,0,0,0,0,0,0,0,0,0,0,0,0,0,0,0,0,0,6,47,0,0,0,0,0,0
0,0,0,0,0,31,6,0,0,0,0,0,0,0,0,0,0,0,0,0,0,0,0,0,0,0,0,0,0,0,0,0,6,31,0,0,0,0,0,0
0,0,0,0,0,10,6,0,0,0,0,0,0,0,0,0,0,0,0,0,0,0,0,0,0,0,0,0,0,0,0,0,6,10,0,0,0,0,0,0
0,0,0,0,0,11,6,37,0,0,0,0,0,0,0,0,0,0,0,0,0,0,0,0,0,0,0,0,0,0,0,37,6,14,0,0,0,0,0,0
0,0,0,0,0,9,6,0,0,0,0,0,0,0,0,0,0,0,0,0,0,0,0,0,0,0,0,0,0,0,0,0,6,9,0,0,0,0,0,0
0,0,0,0,0,32,6,19,19,19,19,37,19,19,19,19,19,37,19,19,19,37,19,19,19,19,19,37,19,19,19,19,6,32,0,0,0,0,0,0
0,0,0,0,0,47,6,0,0,0,0,0,0,0,0,0,0,0,0,0,0,0,0,0,0,0,0,0,0,0,0,0,6,47,0,0,0,0,0,0
0,0,0,0,0,31,6,0,0,0,0,0,0,0,0,0,0,0,0,0,0,0,0,0,0,0,0,0,0,0,0,0,6,31,0,0,0,0,0,0
0,0,7,6,32,6,6,0,0,0,0,0,0,0,0,0,0,0,0,0,0,0,0,0,0,0,0,0,0,0,0,0,6,6,32,6,17,0,0,0
0,10,6,6,6,6,6,0,37,0,0,0,0,0,0,0,0,0,0,0,0,0,0,0,0,0,0,0,0,0,37,0,6,6,6,6,6,10,0,0
0,6,6,6,0,0,0,0,0,0,0,0,0,0,37,0,0,0,0,37,0,0,0,0,37,0,0,0,0,0,0,0,0,0,0,6,6,6,0,0
0,11,6,0,0,0,0,0,6,6,6,6,6,6,6,6,6,6,6,6,6,6,6,6,6,6,6,6,6,6,6,0,0,0,0,0,6,14,0,0
0,0,46,33,33,34,0,0,6,6,11,47,14,7,31,17,11,47,14,28,11,47,14,7,31,17,11,47,14,6,6,0,0,34,33,33,46,0,0,0
0,11,6,16,16,36,0,0,6,14,0,0,0,0,0,0,0,0,0,0,0,0,0,0,0,0,0,0,0,11,6,0,0,36,16,16,6,14,0,0
0,6,6,6,16,36,20,6,6,6,0,0,0,0,0,0,0,0,0,0,0,0,0,0,0,0,0,0,0,6,6,6,23,36,16,6,6,6,0,0
0,9,6,6,6,46,6,6,6,9,0,0,0,0,0,0,0,0,0,0,0,0,0,0,0,0,0,0,0,9,6,6,6,46,6,6,6,9,0,0
0,0,7,6,31,29,31,6,17,0,0,0,0,0,0,0,0,0,0,0,0,0,0,0,0,0,0,0,0,0,7,6,31,29,31,6,17,0,0,0
0,0,0,0,0,0,0,0,0,0,0,0,0,0,0,0,0,0,0,0,0,0,0,0,0,0,0,0,0,0,0,0,0,0,0,0,0,0,0,0
0,0,0,0,0,0,0,0,0,0,0,0,0,0,0,0,0,0,0,0,0,0,0,0,0,0,0,0,0,0,0,0,0,0,0,0,0,0,0,0
0,0,0,0,0,0,0,0,0,0,0,0,0,0,0,0,0,0,0,0,0,0,0,0,0,0,0,0,0,0,0,0,0,0,0,0,0,0,0,0
0,0,0,0,0,0,0,0,0,0,0,0,0,0,0,0,0,0,0,0,0,0,0,0,0,0,0,0,0,0,0,0,0,0,0,0,0,0,0,0
0,0,0,0,0,0,0,0,0,0,0,0,0,0,0,0,0,0,0,0,0,0,0,0,0,0,0,0,0,0,0,0,0,0,0,0,0,0,0,0
0,0,0,0,0,0,0,0,0,0,0,0,0,0,0,0,0,0,0,0,0,0,0,0,0,0,0,0,0,0,0,0,0,0,0,0,0,0,0,0
:endlayer
layer: 20
0,0,0,0,0,0,0,0,0,0,0,0,0,0,0,0,0,0,0,0,0,0,0,0,0,0,0,0,0,0,0,0,0,0,0,0,0,0,0,0
0,0,0,6,50,0,50,6,0,0,0,0,0,0,0,0,0,0,0,0,0,0,0,0,0,0,0,0,0,0,0,6,50,0,50,6,0,0,0,0
0,0,6,6,6,46,6,6,6,0,0,0,0,0,0,0,0,0,0,0,0,0,0,0,0,0,0,0,0,0,6,6,6,46,6,6,6,0,0,0
0,6,6,6,0,0,0,6,6,6,0,0,0,0,0,0,0,0,0,0,0,0,0,0,0,0,0,0,0,6,6,6,0,0,0,6,6,6,0,0
0,50,6,0,0,0,0,0,6,50,0,0,0,0,0,0,0,0,0,0,0,0,0,0,0,0,0,0,0,50,6,0,0,0,0,0,6,50,0,0
0,0,46,33,33,34,0,0,6,6,50,0,50,0,10,0,50,0,50,28,50,0,50,0,10,0,50,0,50,6,6,0,0,34,33,33,46,0,0,0
0,50,6,16,16,36,0,0,6,6,6,46,6,6,6,6,6,46,6,6,6,46,6,6,6,6,6,46,6,6,6,0,0,36,16,16,6,50,0,0
0,6,6,6,16,36,0,0,6,0,0,0,0,0,37,0,0,0,0,37,0,0,0,0,37,0,0,0,0,0,6,0,0,36,16,6,6,6,0,0
0,0,6,6,6,6,6,6,37,0,0,0,0,0,0,0,0,0,0,0,0,0,0,0,0,0,0,0,0,0,37,6,6,6,6,6,6,0,0,0
0,0,0,6,50,6,6,0,0,0,0,0,0,0,0,0,0,0,0,0,0,0,0,0,0,0,0,0,0,0,0,0,6,6,50,6,0,0,0,0
0,0,0,0,0,50,6,0,0,0,0,0,0,0,0,0,0,0,0,0,0,0,0,0,0,0,0,0,0,0,0,0,6,50,0,0,0,0,0,0
0,0,0,0,0,0,46,0,0,0,0,0,0,0,0,0,0,0,0,0,0,0,0,0,0,0,0,0,0,0,0,0,46,0,0,0,0,0,0,0
0,0,0,0,0,50,6,0,0,0,0,0,0,0,0,0,0,0,0,0,0,0,0,0,0,0,0,0,0,0,0,0,6,50,0,0,0,0,0,0
0,0,0,0,0,0,6,0,0,0,0,0,0,0,0,0,0,0,0,0,0,0,0,0,0,0,0,0,0,0,0,0,6,0,0,0,0,0,0,0
0,0,0,0,0,7,6,37,0,0,0,0,0,0,0,0,0,0,0,0,0,0,0,0,0,0,0,0,0,0,0,37,6,17,0,0,0,0,0,0
0,0,0,0,0,0,6,0,0,0,0,0,0,0,0,0,0,0,0,0,0,0,0,0,0,0,0,0,0,0,0,0,6,0,0,0,0,0,0,0
0,0,0,0,0,50,6,0,0,0,0,0,0,0,0,0,0,0,0,0,0,0,0,0,0,0,0,0,0,0,0,0,6,50,0,0,0,0,0,0
0,0,0,0,0,0,46,0,0,0,0,0,0,0,0,0,0,0,0,0,0,0,0,0,0,0,0,0,0,0,0,0,46,0,0,0,0,0,0,0
0,0,0,0,0,50,6,0,0,0,0,0,0,0,0,0,0,0,0,19,0,0,0,0,0,0,0,0,0,0,0,0,6,50,0,0,0,0,0,0
0,0,0,0,0,28,6,37,0,0,0,0,0,0,0,0,0,0,19,19,19,0,0,0,0,0,0,0,0,0,0,37,6,28,0,0,0,0,0,0
0,0,0,0,0,50,6,0,0,0,0,0,0,0,0,0,0,0,0,19,0,0,0,0,0,0,0,0,0,0,0,0,6,50,0,0,0,0,0,0
0,0,0,0,0,0,46,0,0,0,0,0,0,0,0,0,0,0,0,0,0,0,0,0,0,0,0,0,0,0,0,0,46,0,0,0,0,0,0,0
0,0,0,0,0,50,6,0,0,0,0,0,0,0,0,0,0,0,0,0,0,0,0,0,0,0,0,0,0,0,0,0,6,50,0,0,0,0,0,0
0,0,0,0,0,0,6,0,0,0,0,0,0,0,0,0,0,0,0,0,0,0,0,0,0,0,0,0,0,0,0,0,6,0,0,0,0,0,0,0
0,0,0,0,0,7,6,37,0,0,0,0,0,0,0,0,0,0,0,0,0,0,0,0,0,0,0,0,0,0,0,37,6,17,0,0,0,0,0,0
0,0,0,0,0,0,6,0,0,0,0,0,0,0,0,0,0,0,0,0,0,0,0,0,0,0,0,0,0,0,0,0,6,0,0,0,0,0,0,0
0,0,0,0,0,50,6,0,0,0,0,37,0,0,0,0,0,37,0,0,0,37,0,0,0,0,0,37,0,0,0,0,6,50,0,0,0,0,0,0
0,0,0,0,0,0,46,0,0,0,0,0,0,0,0,0,0,0,0,0,0,0,0,0,0,0,0,0,0,0,0,0,46,0,0,0,0,0,0,0
0,0,0,0,0,50,6,0,0,0,0,0,0,0,0,0,0,0,0,0,0,0,0,0,0,0,0,0,0,0,0,0,6,50,0,0,0,0,0,0
0,0,0,6,50,6,6,0,0,0,0,0,0,0,0,0,0,0,0,0,0,0,0,0,0,0,0,0,0,0,0,0,6,6,50,6,0,0,0,0
0,0,6,6,6,6,6,0,37,0,0,0,0,0,0,0,0,0,0,0,0,0,0,0,0,0,0,0,0,0,37,0,6,6,6,6,6,0,0,0
0,6,6,6,0,0,0,0,0,0,0,0,0,0,37,0,0,0,0,37,0,0,0,0,37,0,0,0,0,0,0,0,0,0,0,6,6,6,0,0
0,50,6,0,0,0,0,0,6,6,6,46,6,6,6,6,6,46,6,6,6,46,6,6,6,6,6,46,6,6,6,0,0,0,0,0,6,50,0,0
0,0,46,0,0,34,36,36,6,6,50,0,50,0,9,0,50,0,50,28,50,0,50,0,9,0,50,0,50,6,6,36,36,34,0,0,46,0,0,0
0,50,6,0,0,33,16,16,6,50,0,0,0,0,0,0,0,0,0,0,0,0,0,0,0,0,0,0,0,50,6,16,16,33,0,0,6,50,0,0
0,6,6,6,0,33,16,6,6,6,0,0,0,0,0,0,0,0,0,0,0,0,0,0,0,0,0,0,0,6,6,6,16,33,0,6,6,6,0,0
0,0,6,6,6,46,6,6,6,0,0,0,0,0,0,0,0,0,0,0,0,0,0,0,0,0,0,0,0,0,6,6,6,46,6,6,6,0,0,0
0,0,0,6,50,0,50,6,0,0,0,0,0,0,0,0,0,0,0,0,0,0,0,0,0,0,0,0,0,0,0,6,50,0,50,6,0,0,0,0
0,0,0,0,0,0,0,0,0,0,0,0,0,0,0,0,0,0,0,0,0,0,0,0,0,0,0,0,0,0,0,0,0,0,0,0,0,0,0,0
0,0,0,0,0,0,0,0,0,0,0,0,0,0,0,0,0,0,0,0,0,0,0,0,0,0,0,0,0,0,0,0,0,0,0,0,0,0,0,0
0,0,0,0,0,0,0,0,0,0,0,0,0,0,0,0,0,0,0,0,0,0,0,0,0,0,0,0,0,0,0,0,0,0,0,0,0,0,0,0
0,0,0,0,0,0,0,0,0,0,0,0,0,0,0,0,0,0,0,0,0,0,0,0,0,0,0,0,0,0,0,0,0,0,0,0,0,0,0,0
0,0,0,0,0,0,0,0,0,0,0,0,0,0,0,0,0,0,0,0,0,0,0,0,0,0,0,0,0,0,0,0,0,0,0,0,0,0,0,0
0,0,0,0,0,0,0,0,0,0,0,0,0,0,0,0,0,0,0,0,0,0,0,0,0,0,0,0,0,0,0,0,0,0,0,0,0,0,0,0
:endlayer
layer: 21
0,0,0,0,0,0,0,0,0,0,0,0,0,0,0,0,0,0,0,0,0,0,0,0,0,0,0,0,0,0,0,0,0,0,0,0,0,0,0,0
0,0,11,6,10,0,10,6,14,0,0,0,0,0,0,0,0,0,0,0,0,0,0,0,0,0,0,0,0,0,11,6,10,0,10,6,14,0,0,0
0,32,6,6,6,46,6,6,6,32,0,0,0,0,0,0,0,0,0,0,0,0,0,0,0,0,0,0,0,32,6,6,6,46,6,6,6,32,0,0
0,6,6,6,0,0,0,6,6,6,0,0,0,0,0,0,0,0,0,0,0,0,0,0,0,0,0,0,0,6,6,6,0,0,0,6,6,6,0,0
0,7,6,0,0,0,0,22,6,17,0,0,0,0,0,0,0,0,0,0,0,0,0,0,0,0,0,0,0,7,6,22,0,0,0,0,6,17,0,0
0,0,46,0,0,34,36,36,6,6,50,0,50,0,50,0,50,0,50,28,50,0,50,0,50,0,50,0,50,6,6,36,36,34,0,0,46,0,0,0
0,7,6,0,0,33,16,16,6,6,6,46,6,6,6,6,6,46,6,6,6,46,6,6,6,6,6,46,6,6,6,16,16,33,0,0,6,17,0,0
0,6,6,6,0,33,16,16,6,0,0,0,0,0,37,0,0,0,0,37,0,0,0,0,37,0,0,0,0,0,6,16,16,33,0,6,6,6,0,0
0,31,6,6,6,6,6,6,37,0,0,0,0,0,0,0,0,0,0,0,0,0,0,0,0,0,0,0,0,0,37,6,6,6,6,6,6,31,0,0
0,0,11,6,9,6,6,0,0,0,0,0,0,0,0,0,0,0,0,0,0,0,0,0,0,0,0,0,0,0,0,0,6,6,9,6,14,0,0,0
0,0,0,0,0,50,6,0,0,0,0,0,0,0,0,0,0,0,0,0,0,0,0,0,0,0,0,0,0,0,0,0,6,50,0,0,0,0,0,0
0,0,0,0,0,0,46,0,0,0,0,0,0,0,0,0,0,0,0,0,0,0,0,0,0,0,0,0,0,0,0,0,46,0,0,0,0,0,0,0
0,0,0,0,0,50,6,0,0,0,0,0,0,0,0,0,0,0,0,0,0,0,0,0,0,0,0,0,0,0,0,0,6,50,0,0,0,0,0,0
0,0,0,0,0,0,6,0,0,0,0,0,0,0,0,0,0,0,0,0,0,0,0,0,0,0,0,0,0,0,0,0,6,0,0,0,0,0,0,0
0,0,0,0,0,50,6,37,0,0,0,0,0,0,0,0,0,0,0,0,0,0,0,0,0,0,0,0,0,0,0,37,6,50,0,0,0,0,0,0
0,0,0,0,0,0,6,0,0,0,0,0,0,0,0,0,0,0,0,0,0,0,0,0,0,0,0,0,0,0,0,0,6,0,0,0,0,0,0,0
0,0,0,0,0,50,6,0,0,0,0,0,0,0,0,0,0,0,0,0,0,0,0,0,0,0,0,0,0,0,0,0,6,50,0,0,0,0,0,0
0,0,0,0,0,0,46,0,0,0,0,0,0,0,0,0,0,0,0,0,0,0,0,0,0,0,0,0,0,0,0,0,46,0,0,0,0,0,0,0
0,0,0,0,0,50,6,0,0,0,0,0,0,0,0,0,0,0,0,29,0,0,0,0,0,0,0,0,0,0,0,0,6,50,0,0,0,0,0,0
0,0,0,0,0,28,6,37,0,0,0,0,0,0,0,0,0,0,29,19,29,0,0,0,0,0,0,0,0,0,0,37,6,28,0,0,0,0,0,0
0,0,0,0,0,50,6,0,0,0,0,0,0,0,0,0,0,0,0,29,0,0,0,0,0,0,0,0,0,0,0,0,6,50,0,0,0,0,0,0
0,0,0,0,0,0,46,0,0,0,0,0,0,0,0,0,0,0,0,0,0,0,0,0,0,0,0,0,0,0,0,0,46,0,0,0,0,0,0,0
0,0,0,0,0,50,6,0,0,0,0,0,0,0,0,0,0,0,0,0,0,0,0,0,0,0,0,0,0,0,0,0,6,50,0,0,0,0,0,0
0,0,0,0,0,0,6,0,0,0,0,0,0,0,0,0,0,0,0,0,0,0,0,0,0,0,0,0,0,0,0,0,6,0,0,0,0,0,0,0
0,0,0,0,0,50,6,37,0,0,0,0,0,0,0,0,0,0,0,0,0,0,0,0,0,0,0,0,0,0,0,37,6,50,0,0,0,0,0,0
0,0,0,0,0,0,6,0,0,0,0,0,0,0,0,0,0,0,0,0,0,0,0,0,0,0,0,0,0,0,0,0,6,0,0,0,0,0,0,0
0,0,0,0,0,50,6,0,0,0,0,37,0,0,0,0,0,37,0,0,0,37,0,0,0,0,0,37,0,0,0,0,6,50,0,0,0,0,0,0
0,0,0,0,0,0,46,0,0,0,0,0,0,0,0,0,0,0,0,0,0,0,0,0,0,0,0,0,0,0,0,0,46,0,0,0,0,0,0,0
0,0,0,0,0,50,6,0,0,0,0,0,0,0,0,0,0,0,0,0,0,0,0,0,0,0,0,0,0,0,0,0,6,50,0,0,0,0,0,0
0,0,11,6,10,6,6,0,0,0,0,0,0,0,0,0,0,0,0,0,0,0,0,0,0,0,0,0,0,0,0,0,6,6,10,6,14,0,0,0
0,32,6,6,6,6,6,0,37,0,0,0,0,0,0,0,0,0,0,0,0,0,0,0,0,0,0,0,0,0,37,0,6,6,6,6,6,32,0,0
0,6,6,6,23,36,16,16,0,0,0,0,0,0,37,0,0,0,0,37,0,0,0,0,37,0,0,0,0,0,0,16,16,36,20,6,6,6,0,0
0,7,6,0,0,36,16,16,6,6,6,46,6,6,6,6,6,46,6,6,6,46,6,6,6,6,6,46,6,6,6,16,16,36,0,0,6,17,0,0
0,0,46,0,0,34,33,33,6,6,50,0,50,0,50,0,50,0,50,28,50,0,50,0,50,0,50,0,50,6,6,33,33,34,0,0,46,0,0,0
0,7,6,0,0,0,0,0,6,17,0,0,0,0,0,0,0,0,0,0,0,0,0,0,0,0,0,0,0,7,6,0,0,0,0,0,6,17,0,0
0,6,6,6,0,0,0,6,6,6,0,0,0,0,0,0,0,0,0,0,0,0,0,0,0,0,0,0,0,6,6,6,0,0,0,6,6,6,0,0
0,31,6,6,6,46,6,6,6,31,0,0,0,0,0,0,0,0,0,0,0,0,0,0,0,0,0,0,0,31,6,6,6,46,6,6,6,31,0,0
0,0,11,6,9,0,9,6,14,0,0,0,0,0,0,0,0,0,0,0,0,0,0,0,0,0,0,0,0,0,11,6,9,0,9,6,14,0,0,0
0,0,0,0,0,0,0,0,0,0,0,0,0,0,0,0,0,0,0,0,0,0,0,0,0,0,0,0,0,0,0,0,0,0,0,0,0,0,0,0
0,0,0,0,0,0,0,0,0,0,0,0,0,0,0,0,0,0,0,0,0,0,0,0,0,0,0,0,0,0,0,0,0,0,0,0,0,0,0,0
0,0,0,0,0,0,0,0,0,0,0,0,0,0,0,0,0,0,0,0,0,0,0,0,0,0,0,0,0,0,0,0,0,0,0,0,0,0,0,0
0,0,0,0,0,0,0,0,0,0,0,0,0,0,0,0,0,0,0,0,0,0,0,0,0,0,0,0,0,0,0,0,0,0,0,0,0,0,0,0
0,0,0,0,0,0,0,0,0,0,0,0,0,0,0,0,0,0,0,0,0,0,0,0,0,0,0,0,0,0,0,0,0,0,0,0,0,0,0,0
0,0,0,0,0,0,0,0,0,0,0,0,0,0,0,0,0,0,0,0,0,0,0,0,0,0,0,0,0,0,0,0,0,0,0,0,0,0,0,0
:endlayer
layer: 22
0,0,0,0,0,0,0,0,0,0,0,0,0,0,0,0,0,0,0,0,0,0,0,0,0,0,0,0,0,0,0,0,0,0,0,0,0,0,0,0
0,0,7,6,14,10,11,6,17,0,0,0,0,0,0,0,0,0,0,0,0,0,0,0,0,0,0,0,0,0,7,6,14,10,11,6,17,0,0,0
0,10,6,6,6,6,6,6,6,10,0,0,0,0,0,0,0,0,0,0,0,0,0,0,0,0,0,0,0,10,6,6,6,6,6,6,6,10,0,0
0,6,6,6,0,36,16,6,6,6,0,0,0,0,0,0,0,0,0,0,0,0,0,0,0,0,0,0,0,6,6,6,16,36,0,6,6,6,0,0
0,31,6,0,0,36,16,16,6,31,0,0,0,0,0,0,0,0,0,0,0,0,0,0,0,0,0,0,0,31,6,16,16,36,0,0,6,31,0,0
0,7,6,0,0,34,33,33,6,6,7,47,17,0,32,0,7,47,17,28,7,47,17,0,32,0,7,47,17,6,6,33,33,34,0,0,6,17,0,0
0,32,6,0,0,0,0,0,6,6,6,6,6,6,6,6,6,6,6,6,6,6,6,6,6,6,6,6,6,6,6,0,0,0,0,0,6,32,0,0
0,6,6,6,0,0,0,0,6,0,0,22,0,0,37,0,0,22,0,37,0,22,0,0,37,0,0,22,0,0,6,0,0,0,0,6,6,6,0,0
0,9,6,6,6,6,6,6,37,0,0,0,0,0,0,0,0,0,0,0,0,0,0,0,0,0,0,0,0,0,37,6,6,6,6,6,6,9,0,0
0,0,7,6,14,6,6,0,0,0,0,0,0,0,0,0,0,0,0,0,0,0,0,0,0,0,0,0,0,0,0,0,6,6,11,6,17,0,0,0
0,0,0,0,0,10,6,0,0,0,0,0,0,0,0,0,0,0,0,0,0,0,0,0,0,0,0,0,0,0,0,0,6,10,0,0,0,0,0,0
0,0,0,0,0,47,6,23,0,0,0,0,0,0,0,0,0,0,0,0,0,0,0,0,0,0,0,0,0,0,0,20,6,47,0,0,0,0,0,0
0,0,0,0,0,9,6,0,0,0,0,0,0,0,0,0,0,0,0,0,0,0,0,0,0,0,0,0,0,0,0,0,6,9,0,0,0,0,0,0
0,0,0,0,0,0,6,0,0,0,0,0,0,0,0,0,0,0,0,0,0,0,0,0,0,0,0,0,0,0,0,0,6,0,0,0,0,0,0,0
0,0,0,0,0,11,6,37,0,0,0,0,0,0,0,0,0,0,0,0,0,0,0,0,0,0,0,0,0,0,0,37,6,14,0,0,0,0,0,0
0,0,0,0,0,0,6,0,0,0,0,0,0,0,0,0,0,0,0,0,0,0,0,0,0,0,0,0,0,0,0,0,6,0,0,0,0,0,0,0
0,0,0,0,0,10,6,0,0,0,0,0,0,0,0,0,0,0,0,0,0,0,0,0,0,0,0,0,0,0,0,0,6,10,0,0,0,0,0,0
0,0,0,0,0,47,6,23,0,0,0,0,0,0,0,0,0,0,0,0,0,0,0,0,0,0,0,0,0,0,0,20,6,47,0,0,0,0,0,0
0,0,0,0,0,9,6,0,0,0,0,0,0,0,0,0,0,0,0,0,0,0,0,0,0,0,0,0,0,0,0,0,6,9,0,0,0,0,0,0
0,0,0,0,0,28,6,37,0,0,0,0,0,0,0,0,0,0,0,19,0,0,0,0,0,0,0,0,0,0,0,37,6,28,0,0,0,0,0,0
0,0,0,0,0,10,6,0,0,0,0,0,0,0,0,0,0,0,0,0,0,0,0,0,0,0,0,0,0,0,0,0,6,10,0,0,0,0,0,0
0,0,0,0,0,47,6,23,0,0,0,0,0,0,0,0,0,0,0,0,0,0,0,0,0,0,0,0,0,0,0,20,6,47,0,0,0,0,0,0
0,0,0,0,0,9,6,0,0,0,0,0,0,0,0,0,0,0,0,0,0,0,0,0,0,0,0,0,0,0,0,0,6,9,0,0,0,0,0,0
0,0,0,0,0,0,6,0,0,0,0,0,0,0,0,0,0,0,0,0,0,0,0,0,0,0,0,0,0,0,0,0,6,0,0,0,0,0,0,0
0,0,0,0,0,11,6,37,0,0,0,0,0,0,0,0,0,0,0,0,0,0,0,0,0,0,0,0,0,0,0,37,6,14,0,0,0,0,0,0
0,0,0,0,0,0,6,0,0,0,0,21,0,0,0,0,0,21,0,0,0,21,0,0,0,0,0,21,0,0,0,0,6,0,0,0,0,0,0,0
0,0,0,0,0,10,6,0,0,0,0,37,0,0,0,0,0,37,0,0,0,37,0,0,0,0,0,37,0,0,0,0,6,10,0,0,0,0,0,0
0,0,0,0,0,47,6,23,0,0,0,22,0,0,0,0,0,22,0,0,0,22,0,0,0,0,0,22,0,0,0,20,6,47,0,0,0,0,0,0
0,0,0,0,0,9,6,21,0,0,0,0,0,0,0,0,0,0,0,0,0,0,0,0,0,0,0,0,0,0,0,21,6,9,0,0,0,0,0,0
0,0,7,6,14,6,6,6,23,0,0,0,0,0,0,0,0,0,0,0,0,0,0,0,0,0,0,0,0,0,20,6,6,6,11,6,17,0,0,0
0,10,6,6,6,6,6,6,37,21,0,0,0,0,21,0,0,0,0,21,0,0,0,0,21,0,0,0,0,21,37,6,6,6,6,6,6,10,0,0
0,6,6,6,16,33,0,0,6,6,23,21,0,0,37,0,0,21,0,37,0,21,0,0,37,0,0,21,20,6,6,0,0,33,16,6,6,6,0,0
0,31,6,16,16,33,0,0,6,6,6,6,6,6,6,6,6,6,6,6,6,6,6,6,6,6,6,6,6,6,6,0,0,33,16,16,6,31,0,0
0,7,6,36,36,34,0,0,6,6,7,47,17,0,31,0,7,47,17,28,7,47,17,0,31,0,7,47,17,6,6,0,0,34,36,36,6,17,0,0
0,32,6,21,0,0,0,0,6,32,0,0,0,0,0,0,0,0,0,0,0,0,0,0,0,0,0,0,0,32,6,0,0,0,0,0,6,32,0,0
0,6,6,6,0,0,0,6,6,6,0,0,0,0,0,0,0,0,0,0,0,0,0,0,0,0,0,0,0,6,6,6,0,0,0,6,6,6,0,0
0,9,6,6,6,6,6,6,6,9,0,0,0,0,0,0,0,0,0,0,0,0,0,0,0,0,0,0,0,9,6,6,6,6,6,6,6,9,0,0
0,0,7,6,14,9,11,6,17,0,0,0,0,0,0,0,0,0,0,0,0,0,0,0,0,0,0,0,0,0,7,6,14,9,11,6,17,0,0,0
0,0,0,0,0,0,0,0,0,0,0,0,0,0,0,0,0,0,0,0,0,0,0,0,0,0,0,0,0,0,0,0,0,0,0,0,0,0,0,0
0,0,0,0,0,0,0,0,0,0,0,0,0,0,0,0,0,0,0,0,0,0,0,0,0,0,0,0,0,0,0,0,0,0,0,0,0,0,0,0
0,0,0,0,0,0,0,0,0,0,0,0,0,0,0,0,0,0,0,0,0,0,0,0,0,0,0,0,0,0,0,0,0,0,0,0,0,0,0,0
0,0,0,0,0,0,0,0,0,0,0,0,0,0,0,0,0,0,0,0,0,0,0,0,0,0,0,0,0,0,0,0,0,0,0,0,0,0,0,0
0,0,0,0,0,0,0,0,0,0,0,0,0,0,0,0,0,0,0,0,0,0,0,0,0,0,0,0,0,0,0,0,0,0,0,0,0,0,0,0
0,0,0,0,0,0,0,0,0,0,0,0,0,0,0,0,0,0,0,0,0,0,0,0,0,0,0,0,0,0,0,0,0,0,0,0,0,0,0,0
:endlayer
layer: 23
0,0,0,27,27,27,27,27,0,0,0,0,0,0,0,0,0,0,0,0,0,0,0,0,0,0,0,0,0,0,0,27,27,27,27,27,0,0,0,0
0,0,27,6,6,28,6,6,27,0,0,0,0,0,0,0,0,0,0,0,0,0,0,0,0,0,0,0,0,0,27,6,6,28,6,6,27,0,0,0
0,27,6,6,6,6,6,6,6,27,0,0,0,0,0,0,0,0,0,0,0,0,0,0,0,0,0,0,0,27,6,6,6,6,6,6,6,27,0,0
27,6,6,6,16,33,0,6,6,6,27,0,0,0,0,0,0,0,0,0,0,0,0,0,0,0,0,0,27,6,6,6,0,33,16,6,6,6,27,0
27,6,6,16,16,33,0,0,6,6,27,27,27,0,0,0,27,27,27,0,27,27,27,0,0,0,27,27,27,6,6,0,0,33,16,16,6,6,27,0
27,28,6,36,36,34,0,0,6,6,6,6,6,11,10,14,6,6,6,28,6,6,6,11,10,14,6,6,6,6,6,0,0,34,36,36,6,28,27,0
27,6,6,21,0,0,0,0,6,6,6,6,6,6,6,6,6,6,6,6,6,6,6,6,6,6,6,6,6,6,6,0,0,0,0,21,6,6,27,0
27,6,6,6,0,0,0,0,6,53,53,52,53,53,53,53,53,52,53,53,53,52,53,53,53,53,53,52,53,53,6,0,0,0,0,6,6,6,27,0
0,27,6,6,6,6,6,6,37,0,0,52,0,0,0,0,0,52,0,0,0,52,0,0,0,0,0,52,0,0,37,6,6,6,6,6,6,27,0,0
0,0,27,6,6,6,6,52,0,0,0,52,0,0,0,0,0,52,0,0,0,52,0,0,0,0,0,52,0,0,0,52,6,6,6,6,27,0,0,0
0,0,0,27,27,6,6,52,0,0,0,52,0,0,0,0,0,52,0,0,0,52,0,0,0,0,0,52,0,0,0,52,6,6,27,27,0,0,0,0
0,0,0,0,27,6,6,52,53,53,53,52,53,53,53,53,53,52,53,53,53,52,53,53,53,53,53,52,53,53,53,52,6,6,27,0,0,0,0,0
0,0,0,0,27,6,6,52,0,0,0,52,0,0,0,0,0,52,0,0,0,52,0,0,0,0,0,52,0,0,0,52,6,6,27,0,0,0,0,0
0,0,0,0,0,32,6,52,0,0,0,52,0,0,0,0,0,52,0,0,0,52,0,0,0,0,0,52,0,0,0,52,6,32,0,0,0,0,0,0
0,0,0,0,0,7,6,52,0,0,0,52,0,0,0,0,0,52,0,0,0,52,0,0,0,0,0,52,0,0,0,52,6,17,0,0,0,0,0,0
0,0,0,0,0,31,6,52,0,0,0,52,0,0,0,0,0,52,0,0,0,52,0,0,0,0,0,52,0,0,0,52,6,31,0,0,0,0,0,0
0,0,0,0,27,6,6,52,0,0,0,52,0,0,0,0,0,52,0,0,0,52,0,0,0,0,0,52,0,0,0,52,6,6,27,0,0,0,0,0
0,0,0,0,27,6,6,52,53,53,53,52,53,53,53,53,53,52,53,53,53,52,53,53,53,53,53,52,53,53,53,52,6,6,27,0,0,0,0,0
0,0,0,0,27,6,6,52,0,0,0,52,0,0,0,0,0,52,0,21,0,52,0,0,0,0,0,52,0,0,0,52,6,6,27,0,0,0,0,0
0,0,0,0,0,28,6,52,0,0,0,52,0,0,0,0,0,52,20,26,23,52,0,0,0,0,0,52,0,0,0,52,6,28,0,0,0,0,0,0
0,0,0,0,27,6,6,52,0,0,0,52,0,0,0,0,0,52,0,22,0,52,0,0,0,0,0,52,0,0,0,52,6,6,27,0,0,0,0,0
0,0,0,0,27,6,6,52,53,53,53,52,53,53,53,53,53,52,53,53,53,52,53,53,53,53,53,52,53,53,53,52,6,6,27,0,0,0,0,0
0,0,0,0,27,6,6,52,0,0,0,52,0,0,0,0,0,52,0,0,0,52,0,0,0,0,0,52,0,0,0,52,6,6,27,0,0,0,0,0
0,0,0,0,0,32,6,52,0,0,0,52,0,0,0,0,0,52,0,0,0,52,0,0,0,0,0,52,0,0,0,52,6,32,0,0,0,0,0,0
0,0,0,0,0,7,6,52,0,0,0,52,0,0,0,0,0,52,0,0,0,52,0,0,0,0,0,52,0,0,0,52,6,17,0,0,0,0,0,0
0,0,0,0,0,31,6,52,0,0,0,52,0,0,0,0,0,52,0,0,0,52,0,0,0,0,0,52,0,0,0,52,6,31,0,0,0,0,0,0
0,0,0,0,27,6,6,53,53,53,53,52,53,53,53,53,53,52,53,53,53,52,53,53,53,53,53,52,53,53,53,53,6,6,27,0,0,0,0,0
0,0,0,0,27,6,6,52,0,0,0,52,0,0,0,0,0,52,0,0,0,52,0,0,0,0,0,52,0,0,0,52,6,6,27,0,0,0,0,0
0,0,0,27,27,6,6,52,0,0,0,52,0,0,0,0,0,52,0,0,0,52,0,0,0,0,0,52,0,0,0,52,6,6,27,27,0,0,0,0
0,0,27,6,6,6,6,52,0,0,0,52,0,0,0,0,0,52,0,0,0,52,0,0,0,0,0,52,0,0,0,52,6,6,6,6,27,0,0,0
0,27,6,6,6,6,6,6,37,0,0,52,0,0,0,0,0,52,0,0,0,52,0,0,0,0,0,52,0,0,37,6,6,6,6,6,6,27,0,0
27,6,6,6,0,0,0,0,6,53,53,52,53,53,53,53,53,52,53,53,53,52,53,53,53,53,53,52,53,53,6,0,0,0,0,6,6,6,27,0
27,6,6,0,0,0,0,0,6,6,6,6,6,6,6,6,6,6,6,6,6,6,6,6,6,6,6,6,6,6,6,0,0,0,0,0,6,6,27,0
27,28,6,33,33,34,0,0,6,6,6,6,6,11,9,14,6,6,6,28,6,6,6,11,9,14,6,6,6,6,6,0,0,34,33,33,6,28,27,0
27,6,6,16,16,36,0,21,6,6,27,27,27,0,0,0,27,27,27,0,27,27,27,0,0,0,27,27,27,6,6,0,0,36,16,16,6,6,27,0
27,6,6,6,16,36,0,6,6,6,27,0,0,0,0,0,0,0,0,0,0,0,0,0,0,0,0,0,27,6,6,6,23,36,16,6,6,6,27,0
0,27,6,6,6,6,6,6,6,27,0,0,0,0,0,0,0,0,0,0,0,0,0,0,0,0,0,0,0,27,6,6,6,6,6,6,6,27,0,0
0,0,27,6,6,28,6,6,27,0,0,0,0,0,0,0,0,0,0,0,0,0,0,0,0,0,0,0,0,0,27,6,6,28,6,6,27,0,0,0
0,0,0,27,27,27,27,27,0,0,0,0,0,0,0,0,0,0,0,0,0,0,0,0,0,0,0,0,0,0,0,27,27,27,27,27,0,0,0,0
0,0,0,0,0,0,0,0,0,0,0,0,0,0,0,0,0,0,0,0,0,0,0,0,0,0,0,0,0,0,0,0,0,0,0,0,0,0,0,0
0,0,0,0,0,0,0,0,0,0,0,0,0,0,0,0,0,0,0,0,0,0,0,0,0,0,0,0,0,0,0,0,0,0,0,0,0,0,0,0
0,0,0,0,0,0,0,0,0,0,0,0,0,0,0,0,0,0,0,0,0,0,0,0,0,0,0,0,0,0,0,0,0,0,0,0,0,0,0,0
0,0,0,0,0,0,0,0,0,0,0,0,0,0,0,0,0,0,0,0,0,0,0,0,0,0,0,0,0,0,0,0,0,0,0,0,0,0,0,0
0,0,0,0,0,0,0,0,0,0,0,0,0,0,0,0,0,0,0,0,0,0,0,0,0,0,0,0,0,0,0,0,0,0,0,0,0,0,0,0
:endlayer
layer: 24
0,0,0,0,0,0,0,0,0,0,0,0,0,0,0,0,0,0,0,0,0,0,0,0,0,0,0,0,0,0,0,0,0,0,0,0,0,0,0,0
0,0,11,6,17,32,7,6,14,0,0,0,0,0,0,0,0,0,0,0,0,0,0,0,0,0,0,0,0,0,11,6,17,32,7,6,14,0,0,0
0,32,6,6,6,6,6,6,6,32,0,0,0,0,0,0,0,0,0,0,0,0,0,0,0,0,0,0,0,32,6,6,6,6,6,6,6,32,0,0
0,6,6,6,0,0,0,6,6,6,0,0,0,0,0,0,0,0,0,0,0,0,0,0,0,0,0,0,0,6,6,6,0,0,0,6,6,6,0,0
0,9,6,0,0,0,0,0,6,9,0,0,0,30,30,30,0,0,0,30,0,0,0,30,30,30,0,0,0,9,6,0,0,0,0,0,6,9,0,0
0,11,6,33,33,34,0,0,6,6,35,35,35,6,6,6,35,35,35,28,35,35,35,6,6,6,35,35,35,6,6,0,0,34,33,33,6,14,0,0
0,10,6,16,16,36,0,0,6,6,6,6,6,6,6,6,6,6,6,6,6,6,6,6,6,6,6,6,6,6,6,0,0,36,16,16,6,10,0,0
0,6,6,6,16,36,0,0,6,26,26,26,26,26,26,26,26,26,26,26,26,26,26,26,26,26,26,26,26,26,6,0,0,36,16,6,6,6,0,0
0,31,6,6,6,6,6,6,26,26,26,26,26,26,26,26,26,26,26,26,26,26,26,26,26,26,26,26,26,26,26,6,6,6,6,6,6,31,0,0
0,0,11,6,17,6,6,26,26,26,26,26,26,26,26,26,26,26,26,26,26,26,26,26,26,26,26,26,26,26,26,26,6,6,7,6,14,0,0,0
0,0,0,0,0,35,6,26,26,26,26,26,26,26,26,26,26,26,26,26,26,26,26,26,26,26,26,26,26,26,26,26,6,35,0,0,0,0,0,0
0,0,0,0,0,35,6,26,26,26,26,26,26,26,26,26,26,26,26,26,26,26,26,26,26,26,26,26,26,26,26,26,6,35,0,0,0,0,0,0
0,0,0,0,0,35,6,26,26,26,26,26,26,26,26,26,26,26,26,26,26,26,26,26,26,26,26,26,26,26,26,26,6,35,0,0,0,0,0,0
0,0,0,0,30,6,6,26,26,26,26,26,26,26,26,26,26,26,26,26,26,26,26,26,26,26,26,26,26,26,26,26,6,6,30,0,0,0,0,0
0,0,0,0,30,6,6,26,26,26,26,26,26,26,26,26,26,26,26,26,26,26,26,26,26,26,26,26,26,26,26,26,6,6,30,0,0,0,0,0
0,0,0,0,30,6,6,26,26,26,26,26,26,26,26,26,26,26,26,26,26,26,26,26,26,26,26,26,26,26,26,26,6,6,30,0,0,0,0,0
0,0,0,0,0,35,6,26,26,26,26,26,26,26,26,26,26,26,26,26,26,26,26,26,26,26,26,26,26,26,26,26,6,35,0,0,0,0,0,0
0,0,0,0,0,35,6,26,26,26,26,26,26,26,26,26,26,26,26,26,26,26,26,26,26,26,26,26,26,26,26,26,6,35,0,0,0,0,0,0
0,0,0,0,0,35,6,26,26,26,26,26,26,26,26,26,26,26,26,26,26,26,26,26,26,26,26,26,26,26,26,26,6,35,0,0,0,0,0,0
0,0,0,0,30,28,6,26,26,26,26,26,26,26,26,26,26,26,26,26,26,26,26,26,26,26,26,26,26,26,26,26,6,28,30,0,0,0,0,0
0,0,0,0,0,35,6,26,26,26,26,26,26,26,26,26,26,26,26,26,26,26,26,26,26,26,26,26,26,26,26,26,6,35,0,0,0,0,0,0
0,0,0,0,0,35,6,26,26,26,26,26,26,26,26,26,26,26,26,26,26,26,26,26,26,26,26,26,26,26,26,26,6,35,0,0,0,0,0,0
0,0,0,0,0,35,6,26,26,26,26,26,26,26,26,26,26,26,26,26,26,26,26,26,26,26,26,26,26,26,26,26,6,35,0,0,0,0,0,0
0,0,0,0,30,6,6,26,26,26,26,26,26,26,26,26,26,26,26,26,26,26,26,26,26,26,26,26,26,26,26,26,6,6,30,0,0,0,0,0
0,0,0,0,30,6,6,26,26,26,26,26,26,26,26,26,26,26,26,26,26,26,26,26,26,26,26,26,26,26,26,26,6,6,30,0,0,0,0,0
0,0,0,0,30,6,6,26,26,26,26,26,26,26,26,26,26,26,26,26,26,26,26,26,26,26,26,26,26,26,26,26,6,6,30,0,0,0,0,0
0,0,0,0,0,35,6,26,26,26,26,26,26,26,26,26,26,26,26,26,26,26,26,26,26,26,26,26,26,26,26,26,6,35,0,0,0,0,0,0
0,0,0,0,0,35,6,26,26,26,26,26,26,26,26,26,26,26,26,26,26,26,26,26,26,26,26,26,26,26,26,26,6,35,0,0,0,0,0,0
0,0,0,0,0,35,6,26,26,26,26,26,26,26,26,26,26,26,26,26,26,26,26,26,26,26,26,26,26,26,26,26,6,35,0,0,0,0,0,0
0,0,11,6,17,6,6,26,26,26,26,26,26,26,26,26,26,26,26,26,26,26,26,26,26,26,26,26,26,26,26,26,6,6,7,6,14,0,0,0
0,32,6,6,6,6,6,6,26,26,26,26,26,26,26,26,26,26,26,26,26,26,26,26,26,26,26,26,26,26,26,6,6,6,6,6,6,32,0,0
0,6,6,6,0,0,0,0,6,26,26,26,26,26,26,26,26,26,26,26,26,26,26,26,26,26,26,26,26,26,6,22,0,0,0,6,6,6,0,0
0,9,6,0,0,0,0,0,6,6,6,6,6,6,6,6,6,6,6,6,6,6,6,6,6,6,6,6,6,6,6,0,0,0,0,0,6,9,0,0
0,11,6,0,0,34,36,36,6,6,35,35,35,6,6,6,35,35,35,28,35,35,35,6,6,6,35,35,35,6,6,36,36,34,0,0,6,14,0,0
0,10,6,0,0,33,16,16,6,10,0,0,0,30,30,30,0,0,0,30,0,0,0,30,30,30,0,0,0,10,6,16,16,33,0,0,6,10,0,0
0,6,6,6,0,33,16,6,6,6,0,0,0,0,0,0,0,0,0,0,0,0,0,0,0,0,0,0,0,6,6,6,16,33,0,6,6,6,0,0
0,31,6,6,6,6,6,6,6,31,0,0,0,0,0,0,0,0,0,0,0,0,0,0,0,0,0,0,0,31,6,6,6,6,6,6,6,31,0,0
0,0,11,6,17,31,7,6,14,0,0,0,0,0,0,0,0,0,0,0,0,0,0,0,0,0,0,0,0,0,11,6,17,31,7,6,14,0,0,0
0,0,0,0,0,0,0,0,0,0,0,0,0,0,0,0,0,0,0,0,0,0,0,0,0,0,0,0,0,0,0,0,0,0,0,0,0,0,0,0
0,0,0,0,0,0,0,0,0,0,0,0,0,0,0,0,0,0,0,0,0,0,0,0,0,0,0,0,0,0,0,0,0,0,0,0,0,0,0,0
0,0,0,0,0,0,0,0,0,0,0,0,0,0,0,0,0,0,0,0,0,0,0,0,0,0,0,0,0,0,0,0,0,0,0,0,0,0,0,0
0,0,0,0,0,0,0,0,0,0,0,0,0,0,0,0,0,0,0,0,0,0,0,0,0,0,0,0,0,0,0,0,0,0,0,0,0,0,0,0
0,0,0,0,0,0,0,0,0,0,0,0,0,0,0,0,0,0,0,0,0,0,0,0,0,0,0,0,0,0,0,0,0,0,0,0,0,0,0,0
0,0,0,0,0,0,0,0,0,0,0,0,0,0,0,0,0,0,0,0,0,0,0,0,0,0,0,0,0,0,0,0,0,0,0,0,0,0,0,0
:endlayer
layer: 25
0,0,0,0,0,0,0,0,0,0,0,0,0,0,0,0,0,0,0,0,0,0,0,0,0,0,0,0,0,0,0,0,0,0,0,0,0,0,0,0
0,0,7,6,32,0,32,6,17,0,0,0,0,0,0,0,0,0,0,0,0,0,0,0,0,0,0,0,0,0,7,6,32,0,32,6,17,0,0,0
0,10,6,6,6,46,6,6,6,10,0,0,0,0,0,0,0,0,0,0,0,0,0,0,0,0,0,0,0,10,6,6,6,46,6,6,6,10,0,0
0,6,6,6,0,0,0,6,6,6,0,0,0,0,0,0,0,0,0,0,0,0,0,0,0,0,0,0,0,6,6,6,0,0,0,6,6,6,0,0
0,11,6,0,0,0,0,22,6,14,0,0,0,0,0,0,0,0,0,0,0,0,0,0,0,0,0,0,0,11,6,22,0,0,0,0,6,14,0,0
0,0,46,0,0,34,36,36,6,6,11,47,14,7,32,17,11,47,14,28,11,47,14,7,32,17,11,47,14,6,6,36,36,34,0,0,46,0,0,0
0,11,6,0,0,33,16,16,6,6,6,6,6,6,6,6,6,6,6,6,6,6,6,6,6,6,6,6,6,6,6,16,16,33,0,0,6,14,0,0
0,6,6,6,0,33,16,16,54,0,0,0,0,0,26,0,0,0,0,26,0,0,0,0,26,0,0,0,0,0,54,16,16,33,0,6,6,6,0,0
0,9,6,6,6,6,6,54,54,0,0,0,0,0,26,0,0,0,0,26,0,0,0,0,26,0,0,0,0,0,54,54,6,6,6,6,6,9,0,0
0,0,7,6,31,6,6,0,0,0,0,0,0,0,26,0,0,0,0,26,0,0,0,0,26,0,0,0,0,0,0,0,6,6,31,6,17,0,0,0
0,0,0,0,0,32,6,0,0,0,0,0,0,0,26,0,0,0,0,26,0,0,0,0,26,0,0,0,0,0,0,0,6,32,0,0,0,0,0,0
0,0,0,0,0,47,6,0,0,0,0,0,0,0,26,0,0,0,0,26,0,0,0,0,26,0,0,0,0,0,0,0,6,47,0,0,0,0,0,0
0,0,0,0,0,31,6,0,0,0,0,0,0,0,26,0,0,0,0,26,0,0,0,0,26,0,0,0,0,0,0,0,6,31,0,0,0,0,0,0
0,0,0,0,0,10,6,0,0,0,0,6,6,6,6,6,56,6,6,6,26,26,56,26,26,26,26,56,26,26,26,26,6,10,0,0,0,0,0,0
0,0,0,0,0,11,6,0,0,0,0,6,26,0,0,0,0,0,26,6,0,0,0,0,0,0,0,0,0,0,0,0,6,14,0,0,0,0,0,0
0,0,0,0,0,9,6,0,0,0,0,6,0,0,0,0,0,0,0,6,0,0,0,0,0,0,0,0,0,0,0,0,6,9,0,0,0,0,0,0
0,0,0,0,0,32,6,0,0,0,0,0,0,0,0,0,0,0,0,6,0,0,0,0,0,0,0,0,0,0,0,0,6,32,0,0,0,0,0,0
0,0,0,0,0,47,6,0,0,0,0,0,0,0,0,0,0,0,0,6,0,0,0,0,0,38,0,0,0,0,0,0,6,47,0,0,0,0,0,0
0,0,0,0,0,31,6,0,0,0,0,6,0,0,0,0,0,0,0,6,0,0,0,41,19,19,19,42,0,0,0,0,6,31,0,0,0,0,0,0
0,0,0,0,0,28,6,0,0,0,0,6,26,0,0,0,0,0,0,0,0,0,0,0,19,19,19,0,0,0,0,0,6,28,0,0,0,0,0,0
0,0,0,0,0,32,6,0,0,0,0,6,26,0,0,0,0,0,0,0,0,0,0,41,19,26,19,42,0,0,0,0,6,32,0,0,0,0,0,0
0,0,0,0,0,47,6,0,0,0,0,6,26,0,0,0,0,0,0,6,0,0,0,0,19,19,19,0,0,0,0,0,6,47,0,0,0,0,0,0
0,0,0,0,0,31,6,0,0,0,0,6,26,0,0,0,0,0,0,6,0,0,0,41,19,19,19,42,0,0,0,0,6,31,0,0,0,0,0,0
0,0,0,0,0,10,6,0,0,0,0,6,38,0,0,0,0,0,0,6,0,0,0,0,0,39,0,0,0,0,0,0,6,10,0,0,0,0,0,0
0,0,0,0,0,11,6,0,0,0,0,6,0,0,0,0,0,0,26,6,0,0,0,0,0,0,0,0,0,0,0,0,6,14,0,0,0,0,0,0
0,0,0,0,0,9,6,0,0,0,0,6,6,6,55,6,6,6,6,6,26,26,45,26,26,0,0,0,0,0,0,0,6,9,0,0,0,0,0,0
0,0,0,0,0,32,6,0,0,0,0,0,0,26,0,0,0,0,0,26,0,0,0,0,26,0,0,0,0,0,0,0,6,32,0,0,0,0,0,0
0,0,0,0,0,47,6,0,0,0,0,0,0,26,0,0,0,0,0,26,0,0,0,0,26,0,0,0,0,0,0,0,6,47,0,0,0,0,0,0
0,0,0,0,0,31,6,0,0,0,0,0,0,26,0,0,0,0,0,26,0,0,0,0,26,0,0,0,0,0,0,0,6,31,0,0,0,0,0,0
0,0,7,6,32,6,6,0,0,0,0,0,0,26,0,0,0,0,0,26,0,0,0,0,26,0,0,0,0,0,0,0,6,6,32,6,17,0,0,0
0,10,6,6,6,6,6,54,54,0,0,0,0,26,0,0,0,0,0,26,0,0,0,0,26,0,0,0,0,0,54,54,6,6,6,6,6,10,0,0
0,6,6,6,23,36,16,16,54,0,0,0,0,26,0,0,0,0,0,26,0,0,0,0,26,0,0,0,0,0,54,16,16,36,0,6,6,6,0,0
0,11,6,0,0,36,16,16,6,6,6,6,6,6,6,6,6,6,6,6,6,6,6,6,6,6,6,6,6,6,6,16,16,36,0,0,6,14,0,0
0,0,46,0,0,34,33,33,6,6,11,47,14,7,31,17,11,47,14,28,11,47,14,7,31,17,11,47,14,6,6,33,33,34,0,0,46,0,0,0
0,11,6,0,0,0,0,0,6,14,0,0,0,0,0,0,0,0,0,0,0,0,0,0,0,0,0,0,0,11,6,0,0,0,0,0,6,14,0,0
0,6,6,6,0,0,0,6,6,6,0,0,0,0,0,0,0,0,0,0,0,0,0,0,0,0,0,0,0,6,6,6,0,0,0,6,6,6,0,0
0,9,6,6,6,46,6,6,6,9,0,0,0,0,0,0,0,0,0,0,0,0,0,0,0,0,0,0,0,9,6,6,6,46,6,6,6,9,0,0
0,0,7,6,31,29,31,6,17,0,0,0,0,0,0,0,0,0,0,0,0,0,0,0,0,0,0,0,0,0,7,6,31,29,31,6,17,0,0,0
0,0,0,0,0,0,0,0,0,0,0,0,0,0,0,0,0,0,0,0,0,0,0,0,0,0,0,0,0,0,0,0,0,0,0,0,0,0,0,0
0,0,0,0,0,0,0,0,0,0,0,0,0,0,0,0,0,0,0,0,0,0,0,0,0,0,0,0,0,0,0,0,0,0,0,0,0,0,0,0
0,0,0,0,0,0,0,0,0,0,0,0,0,0,0,0,0,0,0,0,0,0,0,0,0,0,0,0,0,0,0,0,0,0,0,0,0,0,0,0
0,0,0,0,0,0,0,0,0,0,0,0,0,0,0,0,0,0,0,0,0,0,0,0,0,0,0,0,0,0,0,0,0,0,0,0,0,0,0,0
0,0,0,0,0,0,0,0,0,0,0,0,0,0,0,0,0,0,0,0,0,0,0,0,0,0,0,0,0,0,0,0,0,0,0,0,0,0,0,0
0,0,0,0,0,0,0,0,0,0,0,0,0,0,0,0,0,0,0,0,0,0,0,0,0,0,0,0,0,0,0,0,0,0,0,0,0,0,0,0
:endlayer
layer: 26
0,0,0,0,0,0,0,0,0,0,0,0,0,0,0,0,0,0,0,0,0,0,0,0,0,0,0,0,0,0,0,0,0,0,0,0,0,0,0,0
0,0,0,6,50,0,50,6,0,0,0,0,0,0,0,0,0,0,0,0,0,0,0,0,0,0,0,0,0,0,0,6,50,0,50,6,0,0,0,0
0,0,6,6,6,46,6,6,6,0,0,0,0,0,0,0,0,0,0,0,0,0,0,0,0,0,0,0,0,0,6,6,6,46,6,6,6,0,0,0
0,6,6,6,0,36,16,6,6,6,0,0,0,0,0,0,0,0,0,0,0,0,0,0,0,0,0,0,0,6,6,6,16,36,0,6,6,6,0,0
0,50,6,0,0,36,16,16,6,50,0,0,0,0,0,0,0,0,0,0,0,0,0,0,0,0,0,0,0,50,6,16,16,36,0,0,6,50,0,0
0,0,46,0,0,34,33,33,6,6,50,0,50,0,10,0,50,0,50,28,50,0,50,0,10,0,50,0,50,6,6,33,33,34,0,0,46,0,0,0
0,50,6,0,0,0,0,0,6,6,6,46,6,6,6,6,6,46,6,6,6,46,6,6,6,6,6,46,6,6,6,0,0,0,0,0,6,50,0,0
