# Ancient Warfare Structure Template File
# Auto-generated structure template file. created on: 2/28/2017 at: 4:19:8
# Lines beginning with # denote comments

header:
version=2.1
name=unique_creeper_church_Dulciphi
size=25,20,29
offset=7,1,27
:endheader

#### VALIDATION ####
validation:
type=ground
survival=false
worldGenEnabled=false
unique=false
preserveBlocks=false
selectionWeight=0
clusterValue=0
minDuplicateDistance=0
dimensionWhiteList=false
dimensionList=
biomeWhiteList=false
biomeList=
leveling=0
fill=0
border=0
validTargetBlocks=
blockSwap=false
data:
:enddata
:endvalidation

#### LAYERS ####
layer: 0
1,1,1,1,1,1,1,1,1,1,1,1,1,1,1,1,1,1,1,1,1,1,1,1,1
1,2,2,2,2,2,2,2,2,2,2,2,2,1,1,1,1,1,1,1,1,1,1,1,1
1,2,1,1,1,2,1,1,1,1,2,2,2,2,2,2,2,2,2,2,2,2,1,1,1
1,2,1,1,1,2,1,1,1,1,1,2,2,2,2,2,2,2,2,2,2,2,1,1,1
1,2,1,1,1,2,1,2,2,2,1,1,1,2,2,2,2,2,2,2,2,2,1,1,1
1,2,1,1,1,2,2,1,2,2,2,2,1,2,2,2,2,2,2,2,2,2,1,1,1
1,2,2,2,2,2,1,2,2,1,2,2,1,2,2,2,2,2,2,2,2,2,1,1,1
1,2,1,1,2,2,1,1,2,2,2,2,1,2,2,2,2,2,2,2,2,2,1,1,1
1,2,1,2,2,2,2,2,2,2,2,2,2,2,2,2,2,2,2,2,2,2,1,1,1
1,2,2,2,2,1,1,1,1,1,1,1,2,2,2,2,2,2,2,2,2,2,1,1,1
1,2,2,2,2,2,2,2,2,2,2,1,2,2,2,2,2,2,2,2,2,2,1,1,1
1,2,2,2,2,2,2,2,2,1,1,2,2,1,1,1,1,1,1,1,1,1,1,1,1
1,2,2,2,2,2,2,2,2,2,2,2,2,1,1,1,1,1,1,3,1,1,1,1,1
1,2,1,2,2,2,2,2,2,2,2,2,2,1,1,1,1,1,1,3,1,1,1,1,1
1,2,1,2,2,2,2,2,2,2,2,2,2,1,1,2,1,1,1,3,1,1,1,1,1
1,2,2,2,2,2,2,2,2,2,1,2,2,1,1,1,1,1,1,3,1,1,1,1,1
1,2,2,2,2,2,2,2,2,2,1,2,2,1,1,1,1,1,1,3,1,1,1,1,1
1,2,2,1,2,1,2,2,2,2,2,2,2,1,1,1,1,1,1,3,1,1,1,1,1
1,2,2,2,2,2,2,2,2,2,2,2,2,1,1,1,1,1,1,3,1,2,1,1,1
1,2,2,2,2,2,2,2,2,2,2,2,2,1,1,1,1,1,1,3,1,1,1,1,1
1,2,2,2,2,2,2,2,2,2,2,2,2,1,1,1,1,1,1,3,1,2,1,1,1
1,2,2,2,2,2,2,2,2,2,2,2,2,1,1,1,1,1,1,3,1,1,1,1,1
1,2,2,2,2,2,2,2,2,2,1,2,2,1,1,1,1,1,1,3,1,1,1,1,1
1,2,2,2,2,2,2,2,2,2,2,2,2,1,1,1,1,1,1,3,1,1,1,1,1
1,2,1,2,2,2,2,2,1,2,2,2,2,1,1,1,1,1,1,1,1,1,1,1,1
1,2,2,1,2,2,2,2,2,2,2,2,2,1,1,1,1,1,1,1,1,1,1,1,1
1,2,2,2,2,2,2,2,2,2,2,2,2,1,1,1,1,1,1,1,1,1,1,1,1
1,1,1,1,1,1,2,2,1,1,1,1,1,1,1,1,1,1,1,1,1,1,1,1,1
1,1,1,1,1,1,1,1,1,1,1,1,1,1,1,1,1,1,1,1,1,1,1,1,1
:endlayer
layer: 1
4,0,0,0,0,0,0,0,0,0,0,0,0,4,0,0,0,0,0,0,0,0,0,0,5
0,6,7,7,7,7,7,7,7,7,7,7,6,0,0,0,0,0,0,0,0,0,0,0,0
0,7,8,8,8,8,8,8,8,8,8,8,8,7,7,7,7,7,7,7,7,7,0,0,0
0,7,8,8,8,8,8,8,8,8,8,8,8,8,8,8,8,8,8,8,8,7,0,0,0
0,7,8,8,8,8,8,8,8,8,8,8,8,8,9,9,9,9,9,9,8,7,0,0,0
0,7,8,8,8,8,8,8,8,8,8,8,8,8,9,9,9,9,9,9,8,7,0,0,0
0,6,8,8,8,8,8,8,8,8,8,8,8,8,9,9,9,9,9,9,8,7,0,0,0
0,7,8,8,8,8,8,8,8,8,8,8,8,8,9,9,9,9,9,9,8,7,0,0,0
0,7,8,10,8,8,8,8,8,8,8,8,8,8,9,9,9,9,9,9,8,7,0,0,0
0,7,8,8,8,8,8,8,8,8,8,8,8,8,8,8,8,8,8,8,8,7,0,0,0
0,7,11,12,8,8,8,8,8,8,13,13,6,7,7,7,7,7,7,7,7,7,4,4,0
4,6,11,11,8,8,8,8,8,8,13,13,6,0,0,0,0,0,14,15,16,0,0,4,0
0,7,11,13,13,8,8,8,8,8,13,13,7,0,0,0,0,0,0,0,0,0,0,4,0
0,7,8,13,13,8,8,8,8,8,13,13,7,0,0,0,0,0,0,0,0,0,0,4,0
0,7,8,13,13,8,8,8,8,8,13,13,7,0,0,17,0,0,0,0,0,18,0,19,0
0,7,8,9,9,9,9,9,9,9,8,8,7,0,0,0,0,0,0,0,0,0,0,4,0
0,7,8,9,9,9,9,9,9,9,8,8,7,0,0,0,0,0,0,0,0,20,0,4,0
0,7,8,8,8,8,9,9,8,8,8,8,7,0,0,0,0,0,0,0,0,0,0,4,0
0,7,8,8,8,8,9,9,8,8,8,8,7,0,21,0,0,0,0,0,0,22,0,4,0
0,7,8,8,8,8,9,9,8,8,8,8,7,0,0,0,23,0,0,0,0,0,0,4,0
0,7,8,8,8,8,9,9,8,8,8,8,7,0,24,0,0,0,0,0,0,25,0,4,0
0,7,8,8,8,8,9,9,8,8,8,8,7,0,0,0,26,0,0,0,0,0,0,4,0
0,7,8,8,8,8,9,9,8,8,8,8,7,0,27,0,0,0,0,0,0,28,0,4,0
0,7,8,8,8,8,9,9,8,8,8,8,7,0,0,0,0,0,0,0,0,0,0,4,0
0,7,8,8,8,8,9,9,8,8,8,8,7,4,4,4,4,4,4,29,4,4,4,4,0
0,7,8,8,8,8,9,9,8,8,8,8,7,0,0,0,0,0,0,0,0,0,0,0,0
0,6,7,7,7,6,6,6,6,7,7,7,6,0,0,0,0,0,0,0,0,0,0,0,0
5,0,0,0,0,0,15,15,0,0,0,0,0,0,0,0,0,0,5,0,0,0,0,0,0
0,0,4,0,0,0,0,0,0,0,0,4,0,0,0,0,0,0,0,0,0,0,0,0,0
:endlayer
layer: 2
4,0,0,0,0,0,0,0,0,0,0,0,0,4,0,0,0,0,0,0,0,0,0,0,30
0,6,7,31,31,31,31,31,31,31,31,7,6,0,0,0,0,0,0,0,0,0,0,0,0
0,7,32,0,0,0,0,0,0,0,0,33,6,7,7,7,7,7,7,7,7,7,0,0,0
0,34,0,0,0,0,0,0,0,0,0,35,6,0,0,0,0,0,0,0,36,7,0,0,0
0,34,0,0,0,0,0,0,0,0,0,0,0,0,0,37,37,37,37,0,0,7,0,0,0
0,7,0,0,0,0,0,0,0,0,0,0,0,0,0,5,5,5,5,0,0,7,0,0,0
0,6,38,38,38,0,0,0,0,0,0,0,0,0,0,5,5,5,5,0,0,7,0,0,0
0,7,39,40,6,0,0,0,0,0,0,0,0,0,0,5,5,5,5,0,0,7,0,0,0
0,7,0,0,41,0,0,0,0,0,0,0,6,0,0,42,42,42,42,0,0,7,0,0,0
0,7,7,7,7,0,0,0,0,0,0,0,6,0,0,0,0,0,0,0,43,7,0,0,0
0,7,0,0,41,0,0,0,0,0,0,0,6,7,7,7,7,7,7,41,7,7,0,0,0
4,6,44,45,6,0,0,0,0,46,0,0,6,47,0,0,0,0,0,0,0,47,0,0,0
0,7,0,14,6,6,6,6,6,6,0,0,7,0,48,48,48,0,0,0,0,0,0,0,0
0,7,0,6,6,6,6,6,6,6,0,0,7,48,48,48,48,48,0,0,0,0,0,30,0
0,7,41,6,49,49,50,50,49,49,0,0,7,48,48,17,48,48,0,0,0,0,0,0,0
0,7,0,0,0,0,51,52,0,0,0,0,7,48,48,48,48,48,0,0,0,0,0,30,0
0,7,0,0,0,0,0,0,0,0,0,0,7,53,53,48,48,0,0,0,0,0,0,0,0
0,7,0,0,0,0,0,0,0,0,0,0,7,0,0,0,0,0,0,0,0,0,0,0,0
0,34,0,0,0,0,0,0,0,0,0,0,7,0,0,0,0,0,0,0,0,0,0,0,0
0,7,0,54,54,54,0,0,54,54,54,0,7,0,0,0,55,0,0,0,0,0,0,0,0
0,34,0,0,0,0,0,0,0,0,0,0,7,0,0,0,0,0,0,0,0,0,0,0,0
0,7,0,54,54,54,0,0,54,54,54,0,7,0,0,0,56,0,0,0,0,0,0,0,0
0,34,0,0,0,0,0,0,0,0,0,0,7,0,0,0,0,0,0,0,0,0,0,0,0
0,7,0,54,54,54,0,0,54,54,54,0,7,0,0,0,0,0,0,0,0,0,0,0,0
0,34,0,0,0,0,0,0,0,0,0,0,7,30,0,0,0,0,30,0,30,0,0,30,0
0,7,0,0,0,0,0,0,0,0,0,0,7,0,0,0,0,0,0,0,0,0,0,0,0
0,6,7,34,7,6,57,41,6,7,34,7,6,0,0,0,0,0,0,0,0,0,0,0,0
30,0,0,0,47,0,0,0,0,47,0,0,0,0,0,0,0,0,30,0,0,0,0,0,0
0,0,4,0,0,0,0,0,0,0,0,4,0,0,0,0,0,0,0,0,0,0,0,0,0
:endlayer
layer: 3
4,0,0,0,0,0,0,0,0,0,0,0,0,4,0,0,0,0,0,0,0,0,0,0,0
58,6,7,31,31,59,31,31,59,31,31,7,6,60,0,0,0,0,61,0,0,0,0,0,0
0,7,62,0,0,0,0,0,0,0,0,63,6,7,7,7,7,7,7,7,7,7,0,0,0
0,34,0,0,0,0,0,0,0,0,0,0,6,60,0,0,0,0,0,0,56,7,0,0,0
0,34,0,0,0,0,0,0,0,0,0,0,0,0,0,0,0,0,0,0,0,7,0,0,0
0,7,0,0,0,0,0,0,0,0,0,0,0,0,0,64,64,64,64,0,0,7,0,0,0
58,6,0,0,0,0,0,0,0,0,0,0,0,0,0,64,64,64,64,0,0,7,60,0,0
0,7,38,38,38,0,0,0,0,0,0,0,0,0,0,64,64,64,64,0,0,7,0,0,0
0,7,65,0,66,0,0,0,0,0,0,0,6,0,0,0,0,0,0,0,0,7,0,0,0
0,7,7,7,7,0,0,0,0,0,0,0,6,60,0,0,0,0,0,0,56,7,0,0,0
58,7,0,0,67,0,0,0,0,0,0,0,6,7,7,34,34,34,7,68,7,7,0,0,0
4,6,69,70,6,71,0,0,0,72,0,0,6,0,0,0,0,0,0,0,0,0,0,0,0
58,7,73,0,74,75,75,75,75,75,0,0,7,0,0,0,0,0,0,0,0,0,0,0,0
0,7,0,6,0,0,0,0,0,0,0,0,7,0,0,48,0,0,0,0,0,0,0,0,0
0,7,76,6,0,0,5,5,0,0,0,0,7,0,48,17,48,0,0,0,0,0,0,0,0
0,7,0,77,0,0,0,0,0,0,0,0,7,0,0,48,0,0,0,0,0,0,0,0,0
58,7,0,0,0,0,0,0,0,0,0,0,7,0,0,0,0,0,0,0,0,0,0,0,0
0,7,60,0,0,0,0,0,0,0,0,58,7,0,0,0,0,0,0,0,0,0,0,0,0
0,34,0,0,0,0,0,0,0,0,0,0,7,0,0,0,0,0,0,0,0,0,0,0,0
0,7,60,0,0,0,0,0,0,0,0,58,7,0,0,0,78,0,0,0,0,0,0,0,0
0,34,0,0,0,0,0,0,0,0,0,0,7,0,0,0,0,0,0,0,0,0,0,0,0
58,7,60,0,0,0,0,0,0,0,0,58,7,0,0,0,56,0,0,0,0,0,0,0,0
0,34,0,0,0,0,0,0,0,0,0,0,7,0,0,0,0,0,0,0,0,0,0,0,0
0,7,60,0,0,0,0,0,0,0,0,58,7,0,0,0,0,0,0,0,0,0,0,0,0
0,34,0,0,0,0,0,0,0,0,0,0,7,0,0,0,0,0,0,0,0,0,0,0,0
0,7,0,0,0,0,0,0,0,0,0,0,7,0,0,0,0,0,0,0,0,0,0,0,0
0,6,7,34,7,6,79,80,6,7,34,7,6,0,0,0,0,0,0,0,0,0,0,0,0
0,0,0,0,0,0,0,0,0,0,0,0,0,0,0,0,0,0,0,0,0,0,0,0,0
0,0,4,0,0,0,0,0,0,0,0,4,0,0,0,0,0,0,0,0,0,0,0,0,0
:endlayer
layer: 4
4,0,0,0,0,0,0,0,0,0,0,0,0,4,0,0,0,0,0,0,0,0,0,0,0
0,6,7,31,31,59,59,59,59,31,31,7,6,0,0,0,0,0,0,0,0,0,0,0,0
0,7,0,0,0,0,0,0,0,0,0,0,6,7,7,7,7,7,7,7,7,7,0,0,0
0,34,0,0,0,0,0,0,0,0,0,58,6,0,0,0,0,0,0,0,56,7,0,0,0
0,34,0,0,0,0,0,0,0,0,0,0,0,0,0,0,0,0,0,0,0,7,0,0,0
0,7,0,0,0,0,0,0,0,0,0,0,0,0,0,0,0,0,0,0,0,7,0,0,0
0,6,0,0,0,0,0,0,0,0,0,0,0,0,0,0,0,0,0,0,0,7,0,0,0
0,7,0,0,0,0,0,0,0,0,0,0,0,0,0,0,0,0,0,0,0,7,0,0,0
0,7,38,38,38,0,0,0,0,0,0,0,6,0,0,0,0,0,0,0,0,7,0,0,0
0,7,8,8,8,13,13,13,13,13,13,13,6,0,0,0,0,0,0,0,56,7,0,0,0
0,7,13,13,8,13,13,13,13,13,13,13,6,7,7,34,34,34,7,7,7,7,0,0,0
4,6,13,13,8,13,13,13,13,13,13,13,6,0,0,0,0,0,0,0,0,0,0,0,0
0,7,8,8,47,75,0,75,0,75,13,13,7,0,48,48,48,0,0,0,0,0,0,0,0
0,7,13,8,0,0,0,0,0,0,13,13,7,48,48,48,48,48,0,0,0,0,0,0,0
0,7,8,8,0,0,81,81,0,0,13,13,7,48,48,17,48,48,0,0,0,0,0,0,0
0,7,13,13,0,0,0,0,0,0,13,13,7,48,48,48,48,48,0,0,0,0,0,0,0
0,7,13,13,0,0,0,0,0,0,13,13,7,0,48,48,48,0,0,0,0,0,0,0,0
0,7,13,13,0,0,0,0,0,0,13,13,7,0,0,0,0,0,0,0,0,0,0,0,0
0,7,13,13,0,0,0,0,0,0,13,13,7,0,0,0,0,0,0,0,0,0,0,0,0
0,7,13,13,0,0,0,0,0,0,13,13,7,0,0,0,82,0,0,0,0,0,0,0,0
0,7,13,13,0,0,0,0,0,0,13,13,7,0,0,0,0,0,0,0,0,0,0,0,0
0,7,13,13,0,0,0,0,0,0,13,13,7,0,0,0,0,0,0,0,0,0,0,0,0
0,7,13,13,0,0,0,0,0,0,13,13,7,0,0,0,0,0,0,0,0,0,0,0,0
0,7,13,13,13,13,13,13,13,13,13,13,7,0,0,0,0,0,0,0,0,0,0,0,0
0,7,13,13,13,13,13,13,13,13,13,13,7,0,0,0,0,0,0,0,0,0,0,0,0
0,7,13,13,13,13,83,83,13,13,13,13,7,0,0,0,0,0,0,0,0,0,0,0,0
0,6,7,7,7,6,84,85,6,7,7,7,6,0,0,0,0,0,0,0,0,0,0,0,0
0,13,13,13,13,13,13,13,13,13,13,13,13,0,0,0,0,0,0,0,0,0,0,0,0
0,13,8,13,13,13,13,13,13,13,13,8,13,0,0,0,0,0,0,0,0,0,0,0,0
:endlayer
layer: 5
4,0,0,0,0,0,0,0,0,0,0,0,0,4,0,0,0,0,0,0,0,0,0,0,0
0,6,7,31,31,31,59,59,31,31,31,7,6,0,0,0,0,0,0,0,0,0,0,0,0
0,7,0,0,0,0,0,0,0,0,0,0,6,7,7,7,7,7,7,7,7,7,0,0,0
0,34,0,0,0,0,0,0,0,0,0,0,6,0,0,0,0,0,0,0,0,7,0,0,0
0,34,0,0,0,0,0,0,0,0,0,0,0,0,0,0,0,0,0,0,0,7,0,0,0
0,7,0,0,0,0,0,0,0,0,0,0,0,0,0,0,0,0,0,0,0,7,0,0,0
0,6,0,0,0,0,0,0,0,0,0,0,0,0,0,0,0,0,0,86,87,7,0,0,0
0,7,0,0,0,0,0,0,0,0,0,0,0,0,0,0,0,0,0,0,0,7,0,0,0
0,7,0,0,0,0,0,0,0,0,0,0,6,0,0,0,0,0,0,0,0,7,0,0,0
0,7,0,0,0,75,75,75,75,75,75,75,6,0,0,0,0,0,0,0,0,7,0,0,0
0,7,0,0,0,0,0,0,0,0,0,0,6,7,7,7,7,7,7,7,7,7,0,0,0
4,6,0,75,75,75,75,75,75,75,75,0,6,0,0,0,0,0,0,0,0,0,0,0,0
0,7,0,75,0,75,75,75,75,75,75,0,7,0,0,0,0,0,0,0,0,0,0,0,0
0,7,0,75,0,0,0,0,0,0,75,0,7,0,0,48,0,0,0,0,0,0,0,0,0
0,7,0,75,0,0,0,0,0,0,75,0,7,0,48,17,48,0,0,0,0,0,0,0,0
0,7,0,75,0,0,0,0,0,0,75,0,7,0,0,48,0,0,0,0,0,0,0,0,0
0,7,0,75,0,0,0,0,0,0,75,0,7,0,0,0,0,0,0,0,0,0,0,0,0
0,7,0,75,0,0,0,0,0,0,75,0,34,0,0,0,0,0,0,0,0,0,0,0,0
0,7,0,75,0,0,0,0,0,0,75,0,34,0,0,0,0,0,0,0,0,0,0,0,0
0,7,0,75,0,0,0,0,0,0,75,0,34,0,0,0,0,0,0,0,0,0,0,0,0
0,7,0,75,0,0,0,0,0,0,75,0,34,0,0,0,0,0,0,0,0,0,0,0,0
0,88,0,75,0,89,0,0,89,0,75,0,7,0,0,0,0,0,0,0,0,0,0,0,0
0,88,0,75,0,0,0,0,0,0,75,0,7,0,0,0,0,0,0,0,0,0,0,0,0
0,88,0,75,75,75,75,75,75,75,75,0,7,0,0,0,0,0,0,0,0,0,0,0,0
0,7,0,0,0,0,0,0,0,0,0,0,7,0,0,0,0,0,0,0,0,0,0,0,0
0,7,0,0,0,0,0,0,0,0,0,0,7,0,0,0,0,0,0,0,0,0,0,0,0
0,6,7,7,90,90,31,31,90,90,7,44,6,0,0,0,0,0,0,0,0,0,0,0,0
0,91,0,0,0,0,0,0,0,0,0,0,91,0,0,0,0,0,0,0,0,0,0,0,0
0,91,91,91,91,91,91,91,91,91,91,91,91,0,0,0,0,0,0,0,0,0,0,0,0
:endlayer
layer: 6
4,0,0,0,0,0,0,0,0,0,0,0,0,4,0,0,0,0,0,0,0,0,0,0,0
0,6,7,31,31,31,92,92,31,31,31,7,6,6,38,38,38,38,38,38,38,38,0,0,0
85,7,0,0,0,0,0,0,0,0,0,0,6,7,7,7,7,7,7,7,7,7,0,0,0
93,34,0,0,0,0,0,0,0,0,0,0,6,0,0,0,0,0,0,0,0,7,0,0,0
83,34,0,0,0,0,0,0,0,0,0,0,0,0,0,0,0,0,0,0,0,7,0,0,0
85,7,0,0,0,94,0,0,94,0,0,0,0,0,0,0,0,0,0,0,0,7,0,0,0
0,6,0,0,0,86,0,0,86,0,0,0,0,0,0,0,0,0,0,5,0,7,0,0,0
0,7,0,0,0,0,0,0,0,0,0,0,0,0,0,0,0,0,0,0,0,7,0,0,0
0,7,0,0,0,0,0,0,0,0,0,0,6,0,0,0,0,0,0,0,0,7,0,0,0
0,7,0,0,0,0,0,0,0,0,0,0,6,0,0,0,0,0,0,0,0,7,0,0,0
0,7,0,0,0,0,0,0,0,0,0,0,6,7,7,7,7,7,7,7,7,7,0,0,0
4,6,0,0,0,0,0,0,0,0,0,0,6,37,37,37,37,37,37,37,37,15,0,0,0
0,7,0,0,0,0,0,0,0,0,0,0,7,0,0,0,0,0,0,0,0,0,0,0,0
0,7,0,0,0,0,0,0,0,0,0,0,7,0,0,0,0,0,0,0,0,0,0,0,0
0,7,0,0,0,0,0,0,0,0,0,0,7,0,0,17,0,0,0,0,0,0,0,0,0
0,7,0,0,0,0,0,0,0,0,0,0,7,0,0,0,0,0,0,0,0,0,0,0,0
0,7,0,0,0,0,0,0,0,0,0,0,7,0,0,0,0,0,0,0,0,0,0,0,0
0,7,0,0,0,0,0,0,0,0,0,0,34,0,0,0,0,0,0,0,0,0,0,0,0
0,7,0,0,0,0,0,0,0,0,0,0,34,0,0,0,0,0,0,0,0,0,0,0,0
0,7,0,0,0,0,0,0,0,0,0,0,34,0,0,0,0,0,0,0,0,0,0,0,0
0,7,0,0,0,0,0,0,0,0,0,0,34,0,0,0,0,0,0,0,0,0,0,0,0
0,88,0,0,0,86,0,0,86,0,0,0,7,0,0,0,0,0,0,0,0,0,0,0,0
0,88,0,0,0,0,0,0,0,0,0,0,7,0,0,0,0,0,0,0,0,0,0,0,0
0,88,0,0,0,0,0,0,0,0,0,0,7,0,0,0,0,0,0,0,0,0,0,0,0
0,7,0,0,0,0,0,0,0,0,0,0,7,0,0,0,0,0,0,0,0,0,0,0,0
0,7,0,0,0,0,0,0,0,0,95,0,7,0,0,0,0,0,0,0,0,0,0,0,0
0,6,7,7,90,90,31,31,90,90,7,96,6,0,0,0,0,0,0,0,0,0,0,0,0
0,0,0,47,0,0,0,0,0,0,47,0,0,0,0,0,0,0,0,0,0,0,0,0,0
0,0,0,0,0,0,0,0,0,0,0,0,0,0,0,0,0,0,0,0,0,0,0,0,0
:endlayer
layer: 7
14,0,0,0,0,0,0,0,0,0,0,0,0,16,0,0,0,0,0,0,0,0,0,0,0
14,6,7,31,92,59,31,31,59,92,31,7,6,16,0,0,0,0,0,0,0,0,0,0,0
14,7,0,0,0,0,0,0,0,0,0,0,6,97,42,42,42,42,42,42,42,38,0,0,0
14,7,0,0,0,0,0,0,0,0,0,0,6,0,0,0,0,0,0,0,0,6,0,0,0
14,7,0,0,0,0,0,0,0,0,0,0,6,0,0,0,0,0,0,0,0,7,0,0,0
14,7,0,0,0,0,0,0,0,0,0,0,6,0,0,0,0,0,0,0,0,7,0,0,0
14,6,0,0,0,5,0,0,5,0,0,0,6,0,0,0,0,0,0,5,5,7,0,0,0
14,7,0,0,0,0,0,0,0,0,0,0,6,0,0,0,0,0,0,0,0,7,0,0,0
14,7,0,0,0,0,0,0,0,0,0,0,6,0,0,0,0,0,0,0,0,7,0,0,0
14,7,0,0,0,0,0,0,0,0,0,0,6,0,0,0,0,0,0,0,0,6,0,0,0
14,7,0,0,0,0,0,0,0,0,0,0,6,37,37,37,37,37,37,37,37,15,0,0,0
14,6,0,0,0,0,0,0,0,0,0,0,6,0,0,0,0,0,0,0,0,0,0,0,0
0,7,0,0,0,0,0,0,0,0,0,0,7,0,0,0,0,0,0,0,0,0,0,0,0
0,7,0,0,0,0,0,0,0,0,0,0,7,0,0,48,0,0,0,0,0,0,0,0,0
0,7,0,0,0,0,0,0,0,0,0,0,7,0,48,48,48,0,0,0,0,0,0,0,0
0,7,0,0,0,0,0,0,0,0,0,0,7,0,0,48,0,0,0,0,0,0,0,0,0
0,7,60,0,0,0,0,0,0,0,0,58,7,0,0,0,0,0,0,0,0,0,0,0,0
0,7,0,0,0,0,0,0,0,0,0,0,34,0,0,0,0,0,0,0,0,0,0,0,0
0,7,0,0,0,0,0,0,0,0,0,0,34,0,0,0,0,0,0,0,0,0,0,0,0
0,7,0,0,0,0,0,0,0,0,0,0,34,0,0,0,0,0,0,0,0,0,0,0,0
0,7,0,0,0,0,0,0,0,0,0,0,34,0,0,0,0,0,0,0,0,0,0,0,0
0,7,0,0,0,5,0,0,5,0,0,58,7,0,0,0,0,0,0,0,0,0,0,0,0
0,7,0,0,0,0,0,0,0,0,0,0,7,0,0,0,0,0,0,0,0,0,0,0,0
0,7,0,0,0,0,0,0,0,0,0,0,7,0,0,0,0,0,0,0,0,0,0,0,0
0,7,0,0,0,0,0,0,0,0,0,0,7,0,0,0,0,0,0,0,0,0,0,0,0
0,7,0,0,0,0,0,0,0,0,0,0,7,0,0,0,0,0,0,0,0,0,0,0,0
0,6,7,7,90,90,31,31,90,90,7,7,6,0,0,0,0,0,0,0,0,0,0,0,0
0,0,0,0,0,0,0,0,0,0,0,0,0,0,0,0,0,0,0,0,0,0,0,0,0
0,0,0,0,0,0,0,0,0,0,0,0,0,0,0,0,0,0,0,0,0,0,0,0,0
:endlayer
layer: 8
0,14,0,0,0,0,0,0,0,0,0,0,16,0,0,0,0,0,0,0,0,0,0,0,0
0,14,7,31,92,92,31,31,92,92,31,7,16,0,0,0,0,0,0,0,0,0,0,0,0
0,98,0,0,0,0,0,0,0,0,0,0,97,0,0,0,0,0,0,0,0,0,0,0,0
0,98,0,0,0,0,0,0,0,0,0,0,97,42,42,42,42,42,42,42,42,38,0,0,0
0,98,0,0,0,0,0,0,0,0,0,0,6,0,0,0,0,0,0,0,0,6,0,0,0
0,98,0,0,0,0,0,0,0,0,0,0,6,0,0,0,0,0,0,0,0,7,0,0,0
0,98,0,0,0,5,0,0,5,0,0,0,6,0,0,0,0,0,0,0,0,7,0,0,0
0,98,0,0,0,0,0,0,0,0,0,0,6,0,0,0,0,0,0,0,0,7,0,0,0
0,98,0,0,0,0,0,0,0,0,0,0,6,0,0,0,0,0,0,0,0,6,0,0,0
0,98,0,0,0,0,0,0,0,0,0,0,97,37,37,37,37,37,37,37,37,15,0,0,0
0,98,0,0,0,0,0,0,0,0,0,0,97,0,0,0,0,0,0,0,0,0,0,0,0
0,98,0,0,0,0,0,0,0,0,0,0,97,0,0,0,0,0,0,0,0,0,0,0,0
0,98,0,0,0,0,0,0,0,0,0,0,97,0,0,0,0,0,0,0,0,0,0,0,0
0,98,0,0,0,0,0,0,0,0,0,0,97,0,0,0,0,0,0,0,0,0,0,0,0
0,98,0,0,0,0,0,0,0,0,0,0,97,0,0,0,0,0,0,0,0,0,0,0,0
0,98,0,0,0,0,0,0,0,0,0,0,97,0,0,0,0,0,0,0,0,0,0,0,0
0,98,0,0,0,0,0,0,0,0,0,0,97,0,0,0,0,0,0,0,0,0,0,0,0
0,98,0,0,0,0,0,0,0,0,0,0,97,0,0,0,0,0,0,0,0,0,0,0,0
0,98,0,0,0,0,0,0,0,0,0,0,97,0,0,0,0,0,0,0,0,0,0,0,0
0,98,0,0,0,0,0,0,0,0,0,0,97,0,0,0,0,0,0,0,0,0,0,0,0
0,98,0,0,0,0,0,0,0,0,0,0,97,0,0,0,0,0,0,0,0,0,0,0,0
0,98,0,0,0,5,0,0,5,0,0,0,97,0,0,0,0,0,0,0,0,0,0,0,0
0,98,0,0,0,0,0,0,0,0,0,0,97,0,0,0,0,0,0,0,0,0,0,0,0
0,98,0,0,0,0,0,0,0,0,0,0,97,0,0,0,0,0,0,0,0,0,0,0,0
0,98,0,0,0,0,0,0,0,0,0,0,97,0,0,0,0,0,0,0,0,0,0,0,0
0,98,0,0,0,0,0,0,0,0,0,0,97,0,0,0,0,0,0,0,0,0,0,0,0
0,14,6,7,90,31,31,31,31,90,7,6,16,0,0,0,0,0,0,0,0,0,0,0,0
0,14,0,0,0,0,0,0,0,0,0,0,16,0,0,0,0,0,0,0,0,0,0,0,0
0,0,0,0,0,0,0,0,0,0,0,0,0,0,0,0,0,0,0,0,0,0,0,0,0
:endlayer
layer: 9
0,0,14,0,0,0,0,0,0,0,0,16,0,0,0,0,0,0,0,0,0,0,0,0,0
0,0,14,7,31,31,31,31,31,31,7,16,0,0,0,0,0,0,0,0,0,0,0,0,0
0,0,98,0,0,0,0,0,0,0,0,97,0,0,0,0,0,0,0,0,0,0,0,0,0
0,0,98,0,0,0,0,0,0,0,0,97,0,0,0,0,0,0,0,0,0,0,0,0,0
0,0,98,0,0,0,0,0,0,0,0,97,42,42,42,42,42,42,42,42,42,38,0,0,0
0,0,98,0,0,0,0,0,0,0,0,0,6,0,0,0,0,0,0,0,0,6,0,0,0
0,0,98,0,0,5,0,0,5,0,0,0,6,0,0,0,0,0,0,0,0,7,0,0,0
0,0,98,0,0,0,0,0,0,0,0,0,6,0,0,0,0,0,0,0,0,6,0,0,0
0,0,98,0,0,0,0,0,0,0,0,37,37,37,37,37,37,37,37,37,37,15,0,0,0
0,0,98,0,0,0,0,0,0,0,0,97,0,0,0,0,0,0,0,0,0,0,0,0,0
0,0,98,0,0,0,0,0,0,0,0,97,0,0,0,0,0,0,0,0,0,0,0,0,0
0,0,98,0,0,0,0,0,0,0,0,97,0,0,0,0,0,0,0,0,0,0,0,0,0
0,0,98,0,0,0,0,0,0,0,0,97,0,0,0,0,0,0,0,0,0,0,0,0,0
0,0,98,0,0,0,0,0,0,0,0,97,0,0,0,0,0,0,0,0,0,0,0,0,0
0,0,98,0,0,0,0,0,0,0,0,97,0,0,0,0,0,0,0,0,0,0,0,0,0
0,0,98,0,0,0,0,0,0,0,0,97,0,0,0,0,0,0,0,0,0,0,0,0,0
0,0,98,0,0,0,0,0,0,0,0,97,0,0,0,0,0,0,0,0,0,0,0,0,0
0,0,98,0,99,86,0,0,86,87,0,97,0,0,0,0,0,0,0,0,0,0,0,0,0
0,0,98,0,0,0,0,0,0,0,0,97,0,0,0,0,0,0,0,0,0,0,0,0,0
0,0,98,0,0,0,0,0,0,0,0,97,0,0,0,0,0,0,0,0,0,0,0,0,0
0,0,98,0,0,0,0,0,0,0,0,97,0,0,0,0,0,0,0,0,0,0,0,0,0
0,0,98,0,0,5,0,0,5,0,0,97,0,0,0,0,0,0,0,0,0,0,0,0,0
0,0,98,0,0,0,0,0,0,0,0,97,0,0,0,0,0,0,0,0,0,0,0,0,0
0,0,98,0,0,0,0,0,0,0,0,97,0,0,0,0,0,0,0,0,0,0,0,0,0
0,0,98,0,0,0,0,0,0,0,0,97,0,0,0,0,0,0,0,0,0,0,0,0,0
0,0,98,0,0,0,0,0,0,0,0,97,0,0,0,0,0,0,0,0,0,0,0,0,0
0,0,14,7,90,90,31,31,90,90,7,16,0,0,0,0,0,0,0,0,0,0,0,0,0
0,0,14,0,0,0,0,0,0,0,0,16,0,0,0,0,0,0,0,0,0,0,0,0,0
0,0,0,0,0,0,0,0,0,0,0,0,0,0,0,0,0,0,0,0,0,0,0,0,0
:endlayer
layer: 10
0,0,0,14,0,0,0,0,0,0,16,0,0,0,0,0,0,0,0,0,0,0,0,0,0
0,0,0,14,7,31,31,31,31,7,16,0,0,0,0,0,0,0,0,0,0,0,0,0,0
0,0,0,98,0,0,0,0,0,0,97,0,0,0,0,0,0,0,0,0,0,0,0,0,0
0,0,0,98,0,0,0,0,0,0,97,0,0,0,0,0,0,0,0,0,0,0,0,0,0
0,0,0,98,0,0,0,0,0,0,97,0,0,0,0,0,0,0,0,0,0,0,0,0,0
0,0,0,98,0,0,0,0,0,0,42,42,42,42,42,42,42,42,42,42,42,38,0,0,0
0,0,0,98,0,5,0,0,5,0,6,6,6,6,6,6,6,6,6,6,6,6,0,0,0
0,0,0,98,0,0,0,0,0,0,97,37,37,37,37,37,37,37,37,37,37,15,0,0,0
0,0,0,98,0,0,0,0,0,0,97,0,0,0,0,0,0,0,0,0,0,0,0,0,0
0,0,0,98,0,0,0,0,0,0,97,0,0,0,0,0,0,0,0,0,0,0,0,0,0
0,0,0,98,0,0,0,0,0,0,97,0,0,0,0,0,0,0,0,0,0,0,0,0,0
0,0,0,98,0,0,0,0,0,0,97,0,0,0,0,0,0,0,0,0,0,0,0,0,0
0,0,0,98,0,0,0,0,0,0,97,0,0,0,0,0,0,0,0,0,0,0,0,0,0
0,0,0,98,0,0,0,0,0,0,97,0,0,0,0,0,0,0,0,0,0,0,0,0,0
0,0,0,98,0,0,0,0,0,0,97,0,0,0,0,0,0,0,0,0,0,0,0,0,0
0,0,0,98,0,0,0,0,0,0,97,0,0,0,0,0,0,0,0,0,0,0,0,0,0
0,0,0,98,0,0,0,0,0,0,97,0,0,0,0,0,0,0,0,0,0,0,0,0,0
0,0,0,98,0,5,0,0,5,0,97,0,0,0,0,0,0,0,0,0,0,0,0,0,0
0,0,0,98,0,0,0,0,0,0,97,0,0,0,0,0,0,0,0,0,0,0,0,0,0
0,0,0,98,0,0,0,0,0,0,97,0,0,0,0,0,0,0,0,0,0,0,0,0,0
0,0,0,98,0,0,0,0,0,0,97,0,0,0,0,0,0,0,0,0,0,0,0,0,0
0,0,0,98,0,5,0,0,5,0,97,0,0,0,0,0,0,0,0,0,0,0,0,0,0
0,0,0,98,0,0,0,0,0,0,97,0,0,0,0,0,0,0,0,0,0,0,0,0,0
0,0,0,98,0,0,0,0,0,0,97,0,0,0,0,0,0,0,0,0,0,0,0,0,0
0,0,0,98,0,0,0,0,0,0,97,0,0,0,0,0,0,0,0,0,0,0,0,0,0
0,0,0,98,0,0,0,0,0,0,97,0,0,0,0,0,0,0,0,0,0,0,0,0,0
0,0,0,14,7,90,31,31,90,7,16,0,0,0,0,0,0,0,0,0,0,0,0,0,0
0,0,0,14,0,0,0,0,0,0,16,0,0,0,0,0,0,0,0,0,0,0,0,0,0
0,0,0,0,0,0,0,0,0,0,0,0,0,0,0,0,0,0,0,0,0,0,0,0,0
:endlayer
layer: 11
0,0,0,0,14,0,0,0,0,16,0,0,0,0,0,0,0,0,0,0,0,0,0,0,0
0,0,0,0,14,7,7,7,7,16,0,0,0,0,0,0,0,0,0,0,0,0,0,0,0
0,0,0,0,98,0,0,0,0,97,0,0,0,0,0,0,0,0,0,0,0,0,0,0,0
0,0,0,0,98,0,0,0,0,97,0,0,0,0,0,0,0,0,0,0,0,0,0,0,0
0,0,0,0,98,0,0,0,0,97,0,0,0,0,0,0,0,0,0,0,0,0,0,0,0
0,0,0,0,98,0,0,0,0,97,0,0,0,0,0,0,0,0,0,0,0,0,0,0,0
0,0,0,0,98,5,0,0,5,97,100,100,100,100,100,100,100,100,100,100,100,6,0,0,0
0,0,0,0,98,0,0,0,0,97,0,0,0,0,0,0,0,0,0,0,0,0,0,0,0
0,0,0,0,98,0,0,0,0,97,0,0,0,0,0,0,0,0,0,0,0,0,0,0,0
0,0,0,0,98,0,0,0,0,97,0,0,0,0,0,0,0,0,0,0,0,0,0,0,0
0,0,0,0,98,0,0,0,0,97,0,0,0,0,0,0,0,0,0,0,0,0,0,0,0
0,0,0,0,98,0,0,0,0,97,0,0,0,0,0,0,0,0,0,0,0,0,0,0,0
0,0,0,0,98,0,0,0,0,97,0,0,0,0,0,0,0,0,0,0,0,0,0,0,0
0,0,0,0,98,0,0,0,0,97,0,0,0,0,0,0,0,0,0,0,0,0,0,0,0
0,0,0,0,98,0,0,0,0,97,0,0,0,0,0,0,0,0,0,0,0,0,0,0,0
0,0,0,0,98,0,0,0,0,97,0,0,0,0,0,0,0,0,0,0,0,0,0,0,0
0,0,0,0,98,0,0,0,0,97,0,0,0,0,0,0,0,0,0,0,0,0,0,0,0
0,0,0,0,98,5,0,0,5,97,0,0,0,0,0,0,0,0,0,0,0,0,0,0,0
0,0,0,0,98,0,0,0,0,97,0,0,0,0,0,0,0,0,0,0,0,0,0,0,0
0,0,0,0,98,0,0,0,0,97,0,0,0,0,0,0,0,0,0,0,0,0,0,0,0
0,0,0,0,98,0,0,0,0,97,0,0,0,0,0,0,0,0,0,0,0,0,0,0,0
0,0,0,0,98,5,0,0,5,97,0,0,0,0,0,0,0,0,0,0,0,0,0,0,0
0,0,0,0,98,0,0,0,0,97,0,0,0,0,0,0,0,0,0,0,0,0,0,0,0
0,0,0,0,98,0,0,0,0,97,0,0,0,0,0,0,0,0,0,0,0,0,0,0,0
0,0,0,0,98,0,0,0,0,97,0,0,0,0,0,0,0,0,0,0,0,0,0,0,0
0,0,0,0,98,0,0,0,0,97,0,0,0,0,0,0,0,0,0,0,0,0,0,0,0
0,0,0,0,14,7,90,90,7,16,0,0,0,0,0,0,0,0,0,0,0,0,0,0,0
0,0,0,0,14,0,0,0,0,16,0,0,0,0,0,0,0,0,0,0,0,0,0,0,0
0,0,0,0,0,0,0,0,0,0,0,0,0,0,0,0,0,0,0,0,0,0,0,0,0
:endlayer
layer: 12
0,0,0,0,0,14,0,0,16,0,0,0,0,0,0,0,0,0,0,0,0,0,0,0,0
0,0,0,0,0,14,7,7,16,0,0,0,0,0,0,0,0,0,0,0,0,0,0,0,0
0,0,0,0,0,98,84,85,97,0,0,0,0,0,0,0,0,0,0,0,0,0,0,0,0
0,0,0,0,0,98,84,85,97,0,0,0,0,0,0,0,0,0,0,0,0,0,0,0,0
0,0,0,0,0,98,84,85,97,0,0,0,0,0,0,0,0,0,0,0,0,0,0,0,0
0,0,0,0,0,98,84,85,97,0,0,0,0,0,0,0,0,0,0,0,0,0,0,0,0
0,0,0,0,0,98,84,85,97,0,0,0,0,0,0,0,0,0,0,0,0,30,0,0,0
0,0,0,0,0,98,84,85,97,0,0,0,0,0,0,0,0,0,0,0,0,0,0,0,0
0,0,0,0,0,98,84,85,97,0,0,0,0,0,0,0,0,0,0,0,0,0,0,0,0
0,0,0,0,0,98,84,85,97,0,0,0,0,0,0,0,0,0,0,0,0,0,0,0,0
0,0,0,0,0,98,84,85,97,0,0,0,0,0,0,0,0,0,0,0,0,0,0,0,0
0,0,0,0,0,98,84,85,97,0,0,0,0,0,0,0,0,0,0,0,0,0,0,0,0
0,0,0,0,0,98,84,85,97,0,0,0,0,0,0,0,0,0,0,0,0,0,0,0,0
0,0,0,0,0,98,84,85,97,0,0,0,0,0,0,0,0,0,0,0,0,0,0,0,0
0,0,0,0,0,98,84,85,97,0,0,0,0,0,0,0,0,0,0,0,0,0,0,0,0
0,0,0,0,0,98,84,85,97,0,0,0,0,0,0,0,0,0,0,0,0,0,0,0,0
0,0,0,0,0,98,84,85,97,0,0,0,0,0,0,0,0,0,0,0,0,0,0,0,0
0,0,0,0,0,98,84,85,97,0,0,0,0,0,0,0,0,0,0,0,0,0,0,0,0
0,0,0,0,0,98,84,85,97,0,0,0,0,0,0,0,0,0,0,0,0,0,0,0,0
0,0,0,0,0,98,84,85,97,0,0,0,0,0,0,0,0,0,0,0,0,0,0,0,0
0,0,0,0,0,98,84,85,97,0,0,0,0,0,0,0,0,0,0,0,0,0,0,0,0
0,0,0,0,0,98,84,85,97,0,0,0,0,0,0,0,0,0,0,0,0,0,0,0,0
0,0,0,0,0,98,84,85,97,0,0,0,0,0,0,0,0,0,0,0,0,0,0,0,0
0,0,0,0,0,98,84,85,97,0,0,0,0,0,0,0,0,0,0,0,0,0,0,0,0
0,0,0,0,0,98,84,85,97,0,0,0,0,0,0,0,0,0,0,0,0,0,0,0,0
0,0,0,0,0,98,84,85,97,0,0,0,0,0,0,0,0,0,0,0,0,0,0,0,0
0,0,0,0,0,14,6,6,16,0,0,0,0,0,0,0,0,0,0,0,0,0,0,0,0
0,0,0,0,0,14,0,0,16,0,0,0,0,0,0,0,0,0,0,0,0,0,0,0,0
0,0,0,0,0,0,0,0,0,0,0,0,0,0,0,0,0,0,0,0,0,0,0,0,0
:endlayer
layer: 13
0,0,0,0,0,0,14,16,0,0,0,0,0,0,0,0,0,0,0,0,0,0,0,0,0
0,0,0,0,0,0,14,16,0,0,0,0,0,0,0,0,0,0,0,0,0,0,0,0,0
0,0,0,0,0,0,14,16,0,0,0,0,0,0,0,0,0,0,0,0,0,0,0,0,0
0,0,0,0,0,0,14,16,0,0,0,0,0,0,0,0,0,0,0,0,0,0,0,0,0
0,0,0,0,0,0,14,16,0,0,0,0,0,0,0,0,0,0,0,0,0,0,0,0,0
0,0,0,0,0,0,14,16,0,0,0,0,0,0,0,0,0,0,0,0,0,0,0,0,0
0,0,0,0,0,0,14,16,0,0,0,0,0,0,0,0,0,0,0,0,0,0,0,0,0
0,0,0,0,0,0,14,16,0,0,0,0,0,0,0,0,0,0,0,0,0,0,0,0,0
0,0,0,0,0,0,14,16,0,0,0,0,0,0,0,0,0,0,0,0,0,0,0,0,0
0,0,0,0,0,0,14,16,0,0,0,0,0,0,0,0,0,0,0,0,0,0,0,0,0
0,0,0,0,0,0,14,16,0,0,0,0,0,0,0,0,0,0,0,0,0,0,0,0,0
0,0,0,0,0,0,14,16,0,0,0,0,0,0,0,0,0,0,0,0,0,0,0,0,0
0,0,0,0,0,0,14,16,0,0,0,0,0,0,0,0,0,0,0,0,0,0,0,0,0
0,0,0,0,0,0,14,16,0,0,0,0,0,0,0,0,0,0,0,0,0,0,0,0,0
0,0,0,0,0,0,14,16,0,0,0,0,0,0,0,0,0,0,0,0,0,0,0,0,0
0,0,0,0,0,0,14,16,0,0,0,0,0,0,0,0,0,0,0,0,0,0,0,0,0
0,0,0,0,0,0,14,16,0,0,0,0,0,0,0,0,0,0,0,0,0,0,0,0,0
0,0,0,0,0,0,14,16,0,0,0,0,0,0,0,0,0,0,0,0,0,0,0,0,0
0,0,0,0,0,0,14,16,0,0,0,0,0,0,0,0,0,0,0,0,0,0,0,0,0
0,0,0,0,0,0,14,16,0,0,0,0,0,0,0,0,0,0,0,0,0,0,0,0,0
0,0,0,0,0,0,14,16,0,0,0,0,0,0,0,0,0,0,0,0,0,0,0,0,0
0,0,0,0,0,0,14,16,0,0,0,0,0,0,0,0,0,0,0,0,0,0,0,0,0
0,0,0,0,0,0,14,16,0,0,0,0,0,0,0,0,0,0,0,0,0,0,0,0,0
0,0,0,0,0,0,14,16,0,0,0,0,0,0,0,0,0,0,0,0,0,0,0,0,0
0,0,0,0,0,0,14,16,0,0,0,0,0,0,0,0,0,0,0,0,0,0,0,0,0
0,0,0,0,0,0,14,16,0,0,0,0,0,0,0,0,0,0,0,0,0,0,0,0,0
0,0,0,0,0,0,14,16,0,0,0,0,0,0,0,0,0,0,0,0,0,0,0,0,0
0,0,0,0,0,0,15,15,0,0,0,0,0,0,0,0,0,0,0,0,0,0,0,0,0
0,0,0,0,0,0,0,0,0,0,0,0,0,0,0,0,0,0,0,0,0,0,0,0,0
:endlayer
layer: 14
0,0,0,0,0,0,0,0,0,0,0,0,0,0,0,0,0,0,0,0,0,0,0,0,0
0,0,0,0,0,0,0,0,0,0,0,0,0,0,0,0,0,0,0,0,0,0,0,0,0
0,0,0,0,0,0,0,0,0,0,0,0,0,0,0,0,0,0,0,0,0,0,0,0,0
0,0,0,0,0,0,0,0,0,0,0,0,0,0,0,0,0,0,0,0,0,0,0,0,0
0,0,0,0,0,0,0,0,0,0,0,0,0,0,0,0,0,0,0,0,0,0,0,0,0
0,0,0,0,0,0,0,0,0,0,0,0,0,0,0,0,0,0,0,0,0,0,0,0,0
0,0,0,0,0,0,0,0,0,0,0,0,0,0,0,0,0,0,0,0,0,0,0,0,0
0,0,0,0,0,0,0,0,0,0,0,0,0,0,0,0,0,0,0,0,0,0,0,0,0
0,0,0,0,0,0,0,0,0,0,0,0,0,0,0,0,0,0,0,0,0,0,0,0,0
0,0,0,0,0,0,0,0,0,0,0,0,0,0,0,0,0,0,0,0,0,0,0,0,0
0,0,0,0,0,0,0,0,0,0,0,0,0,0,0,0,0,0,0,0,0,0,0,0,0
0,0,0,0,0,0,0,0,0,0,0,0,0,0,0,0,0,0,0,0,0,0,0,0,0
0,0,0,0,0,0,0,0,0,0,0,0,0,0,0,0,0,0,0,0,0,0,0,0,0
0,0,0,0,0,0,0,0,0,0,0,0,0,0,0,0,0,0,0,0,0,0,0,0,0
0,0,0,0,0,0,0,0,0,0,0,0,0,0,0,0,0,0,0,0,0,0,0,0,0
0,0,0,0,0,0,0,0,0,0,0,0,0,0,0,0,0,0,0,0,0,0,0,0,0
0,0,0,0,0,0,0,0,0,0,0,0,0,0,0,0,0,0,0,0,0,0,0,0,0
0,0,0,0,0,0,0,0,0,0,0,0,0,0,0,0,0,0,0,0,0,0,0,0,0
0,0,0,0,0,0,0,0,0,0,0,0,0,0,0,0,0,0,0,0,0,0,0,0,0
0,0,0,0,0,0,0,0,0,0,0,0,0,0,0,0,0,0,0,0,0,0,0,0,0
0,0,0,0,0,0,0,0,0,0,0,0,0,0,0,0,0,0,0,0,0,0,0,0,0
0,0,0,0,0,0,0,0,0,0,0,0,0,0,0,0,0,0,0,0,0,0,0,0,0
0,0,0,0,0,0,0,0,0,0,0,0,0,0,0,0,0,0,0,0,0,0,0,0,0
0,0,0,0,0,0,0,0,0,0,0,0,0,0,0,0,0,0,0,0,0,0,0,0,0
0,0,0,0,0,0,0,0,0,0,0,0,0,0,0,0,0,0,0,0,0,0,0,0,0
0,0,0,0,0,0,0,0,0,0,0,0,0,0,0,0,0,0,0,0,0,0,0,0,0
0,0,0,0,0,0,0,0,0,0,0,0,0,0,0,0,0,0,0,0,0,0,0,0,0
0,0,0,0,0,0,0,0,0,0,0,0,0,0,0,0,0,0,0,0,0,0,0,0,0
0,0,0,0,0,0,0,0,0,0,0,0,0,0,0,0,0,0,0,0,0,0,0,0,0
:endlayer
layer: 15
0,0,0,0,0,0,0,0,0,0,0,0,0,0,0,0,0,0,0,0,0,0,0,0,0
0,0,0,0,0,0,0,0,0,0,0,0,0,0,0,0,0,0,0,0,0,0,0,0,0
0,0,0,0,0,0,0,0,0,0,0,0,0,0,0,0,0,0,0,0,0,0,0,0,0
0,0,0,0,0,0,0,0,0,0,0,0,0,0,0,0,0,0,0,0,0,0,0,0,0
0,0,0,0,0,0,0,0,0,0,0,0,0,0,0,0,0,0,0,0,0,0,0,0,0
0,0,0,0,0,0,0,0,0,0,0,0,0,0,0,0,0,0,0,0,0,0,0,0,0
0,0,0,0,0,0,0,0,0,0,0,0,0,0,0,0,0,0,0,0,0,0,0,0,0
0,0,0,0,0,0,0,0,0,0,0,0,0,0,0,0,0,0,0,0,0,0,0,0,0
0,0,0,0,0,0,0,0,0,0,0,0,0,0,0,0,0,0,0,0,0,0,0,0,0
0,0,0,0,0,0,0,0,0,0,0,0,0,0,0,0,0,0,0,0,0,0,0,0,0
0,0,0,0,0,0,0,0,0,0,0,0,0,0,0,0,0,0,0,0,0,0,0,0,0
0,0,0,0,0,0,0,0,0,0,0,0,0,0,0,0,0,0,0,0,0,0,0,0,0
0,0,0,0,0,0,0,0,0,0,0,0,0,0,0,0,0,0,0,0,0,0,0,0,0
0,0,0,0,0,0,0,0,0,0,0,0,0,0,0,0,0,0,0,0,0,0,0,0,0
0,0,0,0,0,0,0,0,0,0,0,0,0,0,0,0,0,0,0,0,0,0,0,0,0
0,0,0,0,0,0,0,0,0,0,0,0,0,0,0,0,0,0,0,0,0,0,0,0,0
0,0,0,0,0,0,0,0,0,0,0,0,0,0,0,0,0,0,0,0,0,0,0,0,0
0,0,0,0,0,0,0,0,0,0,0,0,0,0,0,0,0,0,0,0,0,0,0,0,0
0,0,0,0,0,0,0,0,0,0,0,0,0,0,0,0,0,0,0,0,0,0,0,0,0
0,0,0,0,0,0,0,0,0,0,0,0,0,0,0,0,0,0,0,0,0,0,0,0,0
0,0,0,0,0,0,0,0,0,0,0,0,0,0,0,0,0,0,0,0,0,0,0,0,0
0,0,0,0,0,0,0,0,0,0,0,0,0,0,0,0,0,0,0,0,0,0,0,0,0
0,0,0,0,0,0,0,0,0,0,0,0,0,0,0,0,0,0,0,0,0,0,0,0,0
0,0,0,0,0,0,0,0,0,0,0,0,0,0,0,0,0,0,0,0,0,0,0,0,0
0,0,0,0,0,0,0,0,0,0,0,0,0,0,0,0,0,0,0,0,0,0,0,0,0
0,0,0,0,0,0,0,0,0,0,0,0,0,0,0,0,0,0,0,0,0,0,0,0,0
0,0,0,0,0,0,0,0,0,0,0,0,0,0,0,0,0,0,0,0,0,0,0,0,0
0,0,0,0,0,0,0,0,0,0,0,0,0,0,0,0,0,0,0,0,0,0,0,0,0
0,0,0,0,0,0,0,0,0,0,0,0,0,0,0,0,0,0,0,0,0,0,0,0,0
:endlayer
layer: 16
0,0,0,0,0,0,0,0,0,0,0,0,0,0,0,0,0,0,0,0,0,0,0,0,0
0,0,0,0,0,0,0,0,0,0,0,0,0,0,0,0,0,0,0,0,0,0,0,0,0
0,0,0,0,0,0,0,0,0,0,0,0,0,0,0,0,0,0,0,0,0,0,0,0,0
0,0,0,0,0,0,0,0,0,0,0,0,0,0,0,0,0,0,0,0,0,0,0,0,0
0,0,0,0,0,0,0,0,0,0,0,0,0,0,0,0,0,0,0,0,0,0,0,0,0
0,0,0,0,0,0,0,0,0,0,0,0,0,0,0,0,0,0,0,0,0,0,0,0,0
0,0,0,0,0,0,0,0,0,0,0,0,0,0,0,0,0,0,0,0,0,0,0,0,0
0,0,0,0,0,0,0,0,0,0,0,0,0,0,0,0,0,0,0,0,0,0,0,0,0
0,0,0,0,0,0,0,0,0,0,0,0,0,0,0,0,0,0,0,0,0,0,0,0,0
0,0,0,0,0,0,0,0,0,0,0,0,0,0,0,0,0,0,0,0,0,0,0,0,0
0,0,0,0,0,0,0,0,0,0,0,0,0,0,0,0,0,0,0,0,0,0,0,0,0
0,0,0,0,0,0,0,0,0,0,0,0,0,0,0,0,0,0,0,0,0,0,0,0,0
0,0,0,0,0,0,0,0,0,0,0,0,0,0,0,0,0,0,0,0,0,0,0,0,0
0,0,0,0,0,0,0,0,0,0,0,0,0,0,0,0,0,0,0,0,0,0,0,0,0
0,0,0,0,0,0,0,0,0,0,0,0,0,0,0,0,0,0,0,0,0,0,0,0,0
0,0,0,0,0,0,0,0,0,0,0,0,0,0,0,0,0,0,0,0,0,0,0,0,0
0,0,0,0,0,0,0,0,0,0,0,0,0,0,0,0,0,0,0,0,0,0,0,0,0
0,0,0,0,0,0,0,0,0,0,0,0,0,0,0,0,0,0,0,0,0,0,0,0,0
0,0,0,0,0,0,0,0,0,0,0,0,0,0,0,0,0,0,0,0,0,0,0,0,0
0,0,0,0,0,0,0,0,0,0,0,0,0,0,0,0,0,0,0,0,0,0,0,0,0
0,0,0,0,0,0,0,0,0,0,0,0,0,0,0,0,0,0,0,0,0,0,0,0,0
0,0,0,0,0,0,0,0,0,0,0,0,0,0,0,0,0,0,0,0,0,0,0,0,0
0,0,0,0,0,0,0,0,0,0,0,0,0,0,0,0,0,0,0,0,0,0,0,0,0
0,0,0,0,0,0,0,0,0,0,0,0,0,0,0,0,0,0,0,0,0,0,0,0,0
0,0,0,0,0,0,0,0,0,0,0,0,0,0,0,0,0,0,0,0,0,0,0,0,0
0,0,0,0,0,0,0,0,0,0,0,0,0,0,0,0,0,0,0,0,0,0,0,0,0
0,0,0,0,0,0,0,0,0,0,0,0,0,0,0,0,0,0,0,0,0,0,0,0,0
0,0,0,0,0,0,0,0,0,0,0,0,0,0,0,0,0,0,0,0,0,0,0,0,0
0,0,0,0,0,0,0,0,0,0,0,0,0,0,0,0,0,0,0,0,0,0,0,0,0
:endlayer
layer: 17
0,0,0,0,0,0,0,0,0,0,0,0,0,0,0,0,0,0,0,0,0,0,0,0,0
0,0,0,0,0,0,0,0,0,0,0,0,0,0,0,0,0,0,0,0,0,0,0,0,0
0,0,0,0,0,0,0,0,0,0,0,0,0,0,0,0,0,0,0,0,0,0,0,0,0
0,0,0,0,0,0,0,0,0,0,0,0,0,0,0,0,0,0,0,0,0,0,0,0,0
0,0,0,0,0,0,0,0,0,0,0,0,0,0,0,0,0,0,0,0,0,0,0,0,0
0,0,0,0,0,0,0,0,0,0,0,0,0,0,0,0,0,0,0,0,0,0,0,0,0
0,0,0,0,0,0,0,0,0,0,0,0,0,0,0,0,0,0,0,0,0,0,0,0,0
0,0,0,0,0,0,0,0,0,0,0,0,0,0,0,0,0,0,0,0,0,0,0,0,0
0,0,0,0,0,0,0,0,0,0,0,0,0,0,0,0,0,0,0,0,0,0,0,0,0
0,0,0,0,0,0,0,0,0,0,0,0,0,0,0,0,0,0,0,0,0,0,0,0,0
0,0,0,0,0,0,0,0,0,0,0,0,0,0,0,0,0,0,0,0,0,0,0,0,0
0,0,0,0,0,0,0,0,0,0,0,0,0,0,0,0,0,0,0,0,0,0,0,0,0
0,0,0,0,0,0,0,0,0,0,0,0,0,0,0,0,0,0,0,0,0,0,0,0,0
0,0,0,0,0,0,0,0,0,0,0,0,0,0,0,0,0,0,0,0,0,0,0,0,0
0,0,0,0,0,0,0,0,0,0,0,0,0,0,0,0,0,0,0,0,0,0,0,0,0
0,0,0,0,0,0,0,0,0,0,0,0,0,0,0,0,0,0,0,0,0,0,0,0,0
0,0,0,0,0,0,0,0,0,0,0,0,0,0,0,0,0,0,0,0,0,0,0,0,0
0,0,0,0,0,0,0,0,0,0,0,0,0,0,0,0,0,0,0,0,0,0,0,0,0
0,0,0,0,0,0,0,0,0,0,0,0,0,0,0,0,0,0,0,0,0,0,0,0,0
0,0,0,0,0,0,0,0,0,0,0,0,0,0,0,0,0,0,0,0,0,0,0,0,0
0,0,0,0,0,0,0,0,0,0,0,0,0,0,0,0,0,0,0,0,0,0,0,0,0
0,0,0,0,0,0,0,0,0,0,0,0,0,0,0,0,0,0,0,0,0,0,0,0,0
0,0,0,0,0,0,0,0,0,0,0,0,0,0,0,0,0,0,0,0,0,0,0,0,0
0,0,0,0,0,0,0,0,0,0,0,0,0,0,0,0,0,0,0,0,0,0,0,0,0
0,0,0,0,0,0,0,0,0,0,0,0,0,0,0,0,0,0,0,0,0,0,0,0,0
0,0,0,0,0,0,0,0,0,0,0,0,0,0,0,0,0,0,0,0,0,0,0,0,0
0,0,0,0,0,0,0,0,0,0,0,0,0,0,0,0,0,0,0,0,0,0,0,0,0
0,0,0,0,0,0,0,0,0,0,0,0,0,0,0,0,0,0,0,0,0,0,0,0,0
0,0,0,0,0,0,0,0,0,0,0,0,0,0,0,0,0,0,0,0,0,0,0,0,0
:endlayer
layer: 18
0,0,0,0,0,0,0,0,0,0,0,0,0,0,0,0,0,0,0,0,0,0,0,0,0
0,0,0,0,0,0,0,0,0,0,0,0,0,0,0,0,0,0,0,0,0,0,0,0,0
0,0,0,0,0,0,0,0,0,0,0,0,0,0,0,0,0,0,0,0,0,0,0,0,0
0,0,0,0,0,0,0,0,0,0,0,0,0,0,0,0,0,0,0,0,0,0,0,0,0
0,0,0,0,0,0,0,0,0,0,0,0,0,0,0,0,0,0,0,0,0,0,0,0,0
0,0,0,0,0,0,0,0,0,0,0,0,0,0,0,0,0,0,0,0,0,0,0,0,0
0,0,0,0,0,0,0,0,0,0,0,0,0,0,0,0,0,0,0,0,0,0,0,0,0
0,0,0,0,0,0,0,0,0,0,0,0,0,0,0,0,0,0,0,0,0,0,0,0,0
0,0,0,0,0,0,0,0,0,0,0,0,0,0,0,0,0,0,0,0,0,0,0,0,0
0,0,0,0,0,0,0,0,0,0,0,0,0,0,0,0,0,0,0,0,0,0,0,0,0
0,0,0,0,0,0,0,0,0,0,0,0,0,0,0,0,0,0,0,0,0,0,0,0,0
0,0,0,0,0,0,0,0,0,0,0,0,0,0,0,0,0,0,0,0,0,0,0,0,0
0,0,0,0,0,0,0,0,0,0,0,0,0,0,0,0,0,0,0,0,0,0,0,0,0
0,0,0,0,0,0,0,0,0,0,0,0,0,0,0,0,0,0,0,0,0,0,0,0,0
0,0,0,0,0,0,0,0,0,0,0,0,0,0,0,0,0,0,0,0,0,0,0,0,0
0,0,0,0,0,0,0,0,0,0,0,0,0,0,0,0,0,0,0,0,0,0,0,0,0
0,0,0,0,0,0,0,0,0,0,0,0,0,0,0,0,0,0,0,0,0,0,0,0,0
0,0,0,0,0,0,0,0,0,0,0,0,0,0,0,0,0,0,0,0,0,0,0,0,0
0,0,0,0,0,0,0,0,0,0,0,0,0,0,0,0,0,0,0,0,0,0,0,0,0
0,0,0,0,0,0,0,0,0,0,0,0,0,0,0,0,0,0,0,0,0,0,0,0,0
0,0,0,0,0,0,0,0,0,0,0,0,0,0,0,0,0,0,0,0,0,0,0,0,0
0,0,0,0,0,0,0,0,0,0,0,0,0,0,0,0,0,0,0,0,0,0,0,0,0
0,0,0,0,0,0,0,0,0,0,0,0,0,0,0,0,0,0,0,0,0,0,0,0,0
0,0,0,0,0,0,0,0,0,0,0,0,0,0,0,0,0,0,0,0,0,0,0,0,0
0,0,0,0,0,0,0,0,0,0,0,0,0,0,0,0,0,0,0,0,0,0,0,0,0
0,0,0,0,0,0,0,0,0,0,0,0,0,0,0,0,0,0,0,0,0,0,0,0,0
0,0,0,0,0,0,0,0,0,0,0,0,0,0,0,0,0,0,0,0,0,0,0,0,0
0,0,0,0,0,0,0,0,0,0,0,0,0,0,0,0,0,0,0,0,0,0,0,0,0
0,0,0,0,0,0,0,0,0,0,0,0,0,0,0,0,0,0,0,0,0,0,0,0,0
:endlayer
layer: 19
0,0,0,0,0,0,0,0,0,0,0,0,0,0,0,0,0,0,0,0,0,0,0,0,0
0,0,0,0,0,0,0,0,0,0,0,0,0,0,0,0,0,0,0,0,0,0,0,0,0
0,0,0,0,0,0,0,0,0,0,0,0,0,0,0,0,0,0,0,0,0,0,0,0,0
0,0,0,0,0,0,0,0,0,0,0,0,0,0,0,0,0,0,0,0,0,0,0,0,0
0,0,0,0,0,0,0,0,0,0,0,0,0,0,0,0,0,0,0,0,0,0,0,0,0
0,0,0,0,0,0,0,0,0,0,0,0,0,0,0,0,0,0,0,0,0,0,0,0,0
0,0,0,0,0,0,0,0,0,0,0,0,0,0,0,0,0,0,0,0,0,0,0,0,0
0,0,0,0,0,0,0,0,0,0,0,0,0,0,0,0,0,0,0,0,0,0,0,0,0
0,0,0,0,0,0,0,0,0,0,0,0,0,0,0,0,0,0,0,0,0,0,0,0,0
0,0,0,0,0,0,0,0,0,0,0,0,0,0,0,0,0,0,0,0,0,0,0,0,0
0,0,0,0,0,0,0,0,0,0,0,0,0,0,0,0,0,0,0,0,0,0,0,0,0
0,0,0,0,0,0,0,0,0,0,0,0,0,0,0,0,0,0,0,0,0,0,0,0,0
0,0,0,0,0,0,0,0,0,0,0,0,0,0,0,0,0,0,0,0,0,0,0,0,0
0,0,0,0,0,0,0,0,0,0,0,0,0,0,0,0,0,0,0,0,0,0,0,0,0
0,0,0,0,0,0,0,0,0,0,0,0,0,0,0,0,0,0,0,0,0,0,0,0,0
0,0,0,0,0,0,0,0,0,0,0,0,0,0,0,0,0,0,0,0,0,0,0,0,0
0,0,0,0,0,0,0,0,0,0,0,0,0,0,0,0,0,0,0,0,0,0,0,0,0
0,0,0,0,0,0,0,0,0,0,0,0,0,0,0,0,0,0,0,0,0,0,0,0,0
0,0,0,0,0,0,0,0,0,0,0,0,0,0,0,0,0,0,0,0,0,0,0,0,0
0,0,0,0,0,0,0,0,0,0,0,0,0,0,0,0,0,0,0,0,0,0,0,0,0
0,0,0,0,0,0,0,0,0,0,0,0,0,0,0,0,0,0,0,0,0,0,0,0,0
0,0,0,0,0,0,0,0,0,0,0,0,0,0,0,0,0,0,0,0,0,0,0,0,0
0,0,0,0,0,0,0,0,0,0,0,0,0,0,0,0,0,0,0,0,0,0,0,0,0
0,0,0,0,0,0,0,0,0,0,0,0,0,0,0,0,0,0,0,0,0,0,0,0,0
0,0,0,0,0,0,0,0,0,0,0,0,0,0,0,0,0,0,0,0,0,0,0,0,0
0,0,0,0,0,0,0,0,0,0,0,0,0,0,0,0,0,0,0,0,0,0,0,0,0
0,0,0,0,0,0,0,0,0,0,0,0,0,0,0,0,0,0,0,0,0,0,0,0,0
0,0,0,0,0,0,0,0,0,0,0,0,0,0,0,0,0,0,0,0,0,0,0,0,0
0,0,0,0,0,0,0,0,0,0,0,0,0,0,0,0,0,0,0,0,0,0,0,0,0
:endlayer

#### RULES ####
rule:
plugin=vanillaBlocks
number=1
data:
JSON:{{"val":{"buildPass":{"val":"0","id":"pi"},"blockName":{"val":"minecraft:grass","id":"ss"},"meta":{"val":"0","id":"pi"}},"id":"ct"}}
:enddata
:endrule

rule:
plugin=vanillaBlocks
number=2
data:
JSON:{{"val":{"buildPass":{"val":"0","id":"pi"},"blockName":{"val":"minecraft:dirt","id":"ss"},"meta":{"val":"0","id":"pi"}},"id":"ct"}}
:enddata
:endrule

rule:
plugin=vanillaBlocks
number=3
data:
JSON:{{"val":{"buildPass":{"val":"0","id":"pi"},"blockName":{"val":"minecraft:gravel","id":"ss"},"meta":{"val":"0","id":"pi"}},"id":"ct"}}
:enddata
:endrule

rule:
plugin=vanillaBlocks
number=4
data:
JSON:{{"val":{"buildPass":{"val":"0","id":"pi"},"blockName":{"val":"minecraft:cobblestone_wall","id":"ss"},"meta":{"val":"0","id":"pi"}},"id":"ct"}}
:enddata
:endrule

rule:
plugin=vanillaBlocks
number=5
data:
JSON:{{"val":{"buildPass":{"val":"0","id":"pi"},"blockName":{"val":"minecraft:fence","id":"ss"},"meta":{"val":"0","id":"pi"}},"id":"ct"}}
:enddata
:endrule

rule:
plugin=vanillaBlocks
number=6
data:
JSON:{{"val":{"buildPass":{"val":"0","id":"pi"},"blockName":{"val":"minecraft:stonebrick","id":"ss"},"meta":{"val":"0","id":"pi"}},"id":"ct"}}
:enddata
:endrule

rule:
plugin=vanillaBlocks
number=7
data:
JSON:{{"val":{"buildPass":{"val":"0","id":"pi"},"blockName":{"val":"minecraft:stonebrick","id":"ss"},"meta":{"val":"2","id":"pi"}},"id":"ct"}}
:enddata
:endrule

rule:
plugin=vanillaBlocks
number=8
data:
JSON:{{"val":{"buildPass":{"val":"0","id":"pi"},"blockName":{"val":"minecraft:double_stone_slab","id":"ss"},"meta":{"val":"0","id":"pi"}},"id":"ct"}}
:enddata
:endrule

rule:
plugin=vanillaBlocks
number=9
data:
JSON:{{"val":{"buildPass":{"val":"0","id":"pi"},"blockName":{"val":"minecraft:wool","id":"ss"},"meta":{"val":"13","id":"pi"}},"id":"ct"}}
:enddata
:endrule

rule:
plugin=vanillaLogic
number=10
data:
JSON:{{"val":{"buildPass":{"val":"0","id":"pi"},"blockName":{"val":"AncientWarfareStructure:advanced_spawner","id":"ss"},"meta":{"val":"0","id":"pi"},"teData":{"val":{"id":{"val":"advanced_spawner_tile","id":"ss"},"spawnerSettings":{"val":{"minDelay":{"val":"0","id":"pi"},"spawnDelay":{"val":"3","id":"pi"},"lightSensitive":{"val":"0","id":"pb"},"spawnGroups":{"val":[{"val":{"settingsList":{"val":[{"val":{"remainingSpawnCount":{"val":"17","id":"pi"},"forced":{"val":"1","id":"pb"},"maxToSpawn":{"val":"1","id":"pi"},"entityId":{"val":"SpecialMobs.SpecialCreeper","id":"ss"},"customData":{"val":[],"id":"ls"},"minToSpawn":{"val":"1","id":"pi"}},"id":"ct"}],"id":"ls"},"groupWeight":{"val":"1","id":"pi"}},"id":"ct"}],"id":"ls"},"playerRange":{"val":"2","id":"pi"},"respondToRedstone":{"val":"0","id":"pb"},"inventory":{"val":{"itemList":{"val":[],"id":"ls"}},"id":"ct"},"spawnRange":{"val":"0","id":"pi"},"transparent":{"val":"0","id":"pb"},"maxDelay":{"val":"20","id":"pi"},"xpToDrop":{"val":"0","id":"pi"},"mobRange":{"val":"4","id":"pi"},"debugMode":{"val":"1","id":"pb"},"maxNearbyMonsters":{"val":"2","id":"pi"}},"id":"ct"}},"id":"ct"}},"id":"ct"}}
:enddata
:endrule

rule:
plugin=vanillaBlocks
number=11
data:
JSON:{{"val":{"buildPass":{"val":"0","id":"pi"},"blockName":{"val":"minecraft:soul_sand","id":"ss"},"meta":{"val":"0","id":"pi"}},"id":"ct"}}
:enddata
:endrule

rule:
plugin=vanillaLogic
number=12
data:
JSON:{{"val":{"buildPass":{"val":"0","id":"pi"},"blockName":{"val":"AncientWarfareStructure:advanced_spawner","id":"ss"},"meta":{"val":"0","id":"pi"},"teData":{"val":{"id":{"val":"advanced_spawner_tile","id":"ss"},"spawnerSettings":{"val":{"minDelay":{"val":"0","id":"pi"},"spawnDelay":{"val":"44","id":"pi"},"lightSensitive":{"val":"0","id":"pb"},"spawnGroups":{"val":[{"val":{"settingsList":{"val":[{"val":{"remainingSpawnCount":{"val":"3","id":"pi"},"forced":{"val":"1","id":"pb"},"maxToSpawn":{"val":"1","id":"pi"},"entityId":{"val":"BiomesOPlenty.Phantom","id":"ss"},"customData":{"val":[],"id":"ls"},"minToSpawn":{"val":"1","id":"pi"}},"id":"ct"}],"id":"ls"},"groupWeight":{"val":"1","id":"pi"}},"id":"ct"}],"id":"ls"},"playerRange":{"val":"2","id":"pi"},"respondToRedstone":{"val":"0","id":"pb"},"inventory":{"val":{"itemList":{"val":[],"id":"ls"}},"id":"ct"},"spawnRange":{"val":"0","id":"pi"},"transparent":{"val":"0","id":"pb"},"maxDelay":{"val":"200","id":"pi"},"xpToDrop":{"val":"0","id":"pi"},"mobRange":{"val":"4","id":"pi"},"debugMode":{"val":"1","id":"pb"},"maxNearbyMonsters":{"val":"8","id":"pi"}},"id":"ct"}},"id":"ct"}},"id":"ct"}}
:enddata
:endrule

rule:
plugin=vanillaBlocks
number=13
data:
JSON:{{"val":{"buildPass":{"val":"0","id":"pi"},"blockName":{"val":"minecraft:stone_slab","id":"ss"},"meta":{"val":"8","id":"pi"}},"id":"ct"}}
:enddata
:endrule

rule:
plugin=vanillaBlocks
number=14
data:
JSON:{{"val":{"buildPass":{"val":"0","id":"pi"},"blockName":{"val":"minecraft:stone_brick_stairs","id":"ss"},"meta":{"val":"0","id":"pi"}},"id":"ct"}}
:enddata
:endrule

rule:
plugin=vanillaBlocks
number=15
data:
JSON:{{"val":{"buildPass":{"val":"0","id":"pi"},"blockName":{"val":"minecraft:stone_brick_stairs","id":"ss"},"meta":{"val":"3","id":"pi"}},"id":"ct"}}
:enddata
:endrule

rule:
plugin=vanillaBlocks
number=16
data:
JSON:{{"val":{"buildPass":{"val":"0","id":"pi"},"blockName":{"val":"minecraft:stone_brick_stairs","id":"ss"},"meta":{"val":"1","id":"pi"}},"id":"ct"}}
:enddata
:endrule

rule:
plugin=vanillaBlocks
number=17
data:
JSON:{{"val":{"buildPass":{"val":"0","id":"pi"},"blockName":{"val":"minecraft:log","id":"ss"},"meta":{"val":"1","id":"pi"}},"id":"ct"}}
:enddata
:endrule

rule:
plugin=vanillaLogic
number=18
data:
JSON:{{"val":{"buildPass":{"val":"0","id":"pi"},"blockName":{"val":"GraveStone:GSGraveStone","id":"ss"},"meta":{"val":"0","id":"pi"},"teData":{"val":{"isLocalized":{"val":"0","id":"pb"},"DeathText":{"val":"","id":"ss"},"Enchanted":{"val":"0","id":"pb"},"Items":{"val":[],"id":"ls"},"id":{"val":"GSGraveStone","id":"ss"},"Age":{"val":"-1","id":"pi"},"GraveType":{"val":"22","id":"pb"}},"id":"ct"}},"id":"ct"}}
:enddata
:endrule

rule:
plugin=vanillaBlocks
number=19
data:
JSON:{{"val":{"buildPass":{"val":"0","id":"pi"},"blockName":{"val":"minecraft:fence_gate","id":"ss"},"meta":{"val":"3","id":"pi"}},"id":"ct"}}
:enddata
:endrule

rule:
plugin=vanillaLogic
number=20
data:
JSON:{{"val":{"buildPass":{"val":"0","id":"pi"},"blockName":{"val":"GraveStone:GSGraveStone","id":"ss"},"meta":{"val":"0","id":"pi"},"teData":{"val":{"isLocalized":{"val":"0","id":"pb"},"DeathText":{"val":"","id":"ss"},"Enchanted":{"val":"0","id":"pb"},"Items":{"val":[],"id":"ls"},"id":{"val":"GSGraveStone","id":"ss"},"Age":{"val":"-1","id":"pi"},"GraveType":{"val":"22","id":"pb"}},"id":"ct"}},"id":"ct"}}
:enddata
:endrule

rule:
plugin=vanillaLogic
number=21
data:
JSON:{{"val":{"buildPass":{"val":"0","id":"pi"},"blockName":{"val":"GraveStone:GSGraveStone","id":"ss"},"meta":{"val":"2","id":"pi"},"teData":{"val":{"isLocalized":{"val":"0","id":"pb"},"DeathText":{"val":"","id":"ss"},"Enchanted":{"val":"0","id":"pb"},"Items":{"val":[],"id":"ls"},"id":{"val":"GSGraveStone","id":"ss"},"Age":{"val":"-1","id":"pi"},"GraveType":{"val":"22","id":"pb"}},"id":"ct"}},"id":"ct"}}
:enddata
:endrule

rule:
plugin=vanillaLogic
number=22
data:
JSON:{{"val":{"buildPass":{"val":"0","id":"pi"},"blockName":{"val":"GraveStone:GSGraveStone","id":"ss"},"meta":{"val":"0","id":"pi"},"teData":{"val":{"isLocalized":{"val":"0","id":"pb"},"DeathText":{"val":"","id":"ss"},"Enchanted":{"val":"0","id":"pb"},"Items":{"val":[],"id":"ls"},"id":{"val":"GSGraveStone","id":"ss"},"Age":{"val":"-1","id":"pi"},"GraveType":{"val":"22","id":"pb"}},"id":"ct"}},"id":"ct"}}
:enddata
:endrule

rule:
plugin=vanillaLogic
number=23
data:
JSON:{{"val":{"buildPass":{"val":"0","id":"pi"},"blockName":{"val":"props:blockProps","id":"ss"},"meta":{"val":"0","id":"pi"},"teData":{"val":{"slaves":{"val":[{"val":["560","66","1296"],"id":"ai"},{"val":["560","67","1296"],"id":"ai"},{"val":["560","68","1296"],"id":"ai"}],"id":"ls"},"BlockType":{"val":"986","id":"pi"},"isRunning":{"val":"0","id":"pb"},"id":{"val":"com.mia.props.common.entities.TileParticleEmitter","id":"ss"},"BlockRotation":{"val":"8","id":"pi"}},"id":"ct"}},"id":"ct"}}
:enddata
:endrule

rule:
plugin=vanillaLogic
number=24
data:
JSON:{{"val":{"buildPass":{"val":"0","id":"pi"},"blockName":{"val":"GraveStone:GSGraveStone","id":"ss"},"meta":{"val":"2","id":"pi"},"teData":{"val":{"isLocalized":{"val":"0","id":"pb"},"DeathText":{"val":"","id":"ss"},"Enchanted":{"val":"0","id":"pb"},"Items":{"val":[],"id":"ls"},"id":{"val":"GSGraveStone","id":"ss"},"Age":{"val":"-1","id":"pi"},"GraveType":{"val":"22","id":"pb"}},"id":"ct"}},"id":"ct"}}
:enddata
:endrule

rule:
plugin=vanillaLogic
number=25
data:
JSON:{{"val":{"buildPass":{"val":"0","id":"pi"},"blockName":{"val":"GraveStone:GSGraveStone","id":"ss"},"meta":{"val":"0","id":"pi"},"teData":{"val":{"isLocalized":{"val":"0","id":"pb"},"DeathText":{"val":"","id":"ss"},"Enchanted":{"val":"0","id":"pb"},"Items":{"val":[],"id":"ls"},"id":{"val":"GSGraveStone","id":"ss"},"Age":{"val":"-1","id":"pi"},"GraveType":{"val":"22","id":"pb"}},"id":"ct"}},"id":"ct"}}
:enddata
:endrule

rule:
plugin=vanillaLogic
number=26
data:
JSON:{{"val":{"buildPass":{"val":"0","id":"pi"},"blockName":{"val":"GraveStone:GSMemorial","id":"ss"},"meta":{"val":"0","id":"pi"},"teData":{"val":{"isLocalized":{"val":"0","id":"pb"},"HangedMob":{"val":"1","id":"pb"},"DeathText":{"val":"","id":"ss"},"Enchanted":{"val":"0","id":"pb"},"HangedVillagerProfession":{"val":"0","id":"pi"},"id":{"val":"GSMemorial","id":"ss"},"GraveType":{"val":"116","id":"pb"}},"id":"ct"}},"id":"ct"}}
:enddata
:endrule

rule:
plugin=vanillaLogic
number=27
data:
JSON:{{"val":{"buildPass":{"val":"0","id":"pi"},"blockName":{"val":"GraveStone:GSGraveStone","id":"ss"},"meta":{"val":"2","id":"pi"},"teData":{"val":{"isLocalized":{"val":"0","id":"pb"},"DeathText":{"val":"","id":"ss"},"Enchanted":{"val":"0","id":"pb"},"Items":{"val":[],"id":"ls"},"id":{"val":"GSGraveStone","id":"ss"},"Age":{"val":"-1","id":"pi"},"GraveType":{"val":"22","id":"pb"}},"id":"ct"}},"id":"ct"}}
:enddata
:endrule

rule:
plugin=vanillaLogic
number=28
data:
JSON:{{"val":{"buildPass":{"val":"0","id":"pi"},"blockName":{"val":"GraveStone:GSGraveStone","id":"ss"},"meta":{"val":"0","id":"pi"},"teData":{"val":{"isLocalized":{"val":"0","id":"pb"},"DeathText":{"val":"","id":"ss"},"Enchanted":{"val":"0","id":"pb"},"Items":{"val":[],"id":"ls"},"id":{"val":"GSGraveStone","id":"ss"},"Age":{"val":"-1","id":"pi"},"GraveType":{"val":"22","id":"pb"}},"id":"ct"}},"id":"ct"}}
:enddata
:endrule

rule:
plugin=vanillaBlocks
number=29
data:
JSON:{{"val":{"buildPass":{"val":"0","id":"pi"},"blockName":{"val":"minecraft:fence_gate","id":"ss"},"meta":{"val":"0","id":"pi"}},"id":"ct"}}
:enddata
:endrule

rule:
plugin=vanillaBlocks
number=30
data:
JSON:{{"val":{"buildPass":{"val":"2","id":"pi"},"blockName":{"val":"minecraft:torch","id":"ss"},"meta":{"val":"5","id":"pi"}},"id":"ct"}}
:enddata
:endrule

rule:
plugin=vanillaBlocks
number=31
data:
JSON:{{"val":{"buildPass":{"val":"0","id":"pi"},"blockName":{"val":"minecraft:stained_glass","id":"ss"},"meta":{"val":"13","id":"pi"}},"id":"ct"}}
:enddata
:endrule

rule:
plugin=vanillaLogic
number=32
data:
JSON:{{"val":{"buildPass":{"val":"0","id":"pi"},"blockName":{"val":"customnpcs:npcTallLamp","id":"ss"},"meta":{"val":"2","id":"pi"},"teData":{"val":{"BannerColor":{"val":"13","id":"pi"},"BannerRotation":{"val":"2","id":"pi"},"id":{"val":"TileNPCTallLamp","id":"ss"}},"id":"ct"}},"id":"ct"}}
:enddata
:endrule

rule:
plugin=vanillaLogic
number=33
data:
JSON:{{"val":{"buildPass":{"val":"0","id":"pi"},"blockName":{"val":"customnpcs:npcTallLamp","id":"ss"},"meta":{"val":"2","id":"pi"},"teData":{"val":{"BannerColor":{"val":"13","id":"pi"},"BannerRotation":{"val":"3","id":"pi"},"id":{"val":"TileNPCTallLamp","id":"ss"}},"id":"ct"}},"id":"ct"}}
:enddata
:endrule

rule:
plugin=vanillaBlocks
number=34
data:
JSON:{{"val":{"buildPass":{"val":"0","id":"pi"},"blockName":{"val":"minecraft:glass","id":"ss"},"meta":{"val":"0","id":"pi"}},"id":"ct"}}
:enddata
:endrule

rule:
plugin=vanillaBlocks
number=35
data:
JSON:{{"val":{"buildPass":{"val":"0","id":"pi"},"blockName":{"val":"minecraft:bookshelf","id":"ss"},"meta":{"val":"0","id":"pi"}},"id":"ct"}}
:enddata
:endrule

rule:
plugin=vanillaLogic
number=36
data:
JSON:{{"val":{"buildPass":{"val":"0","id":"pi"},"blockName":{"val":"GraveStone:GSMemorial","id":"ss"},"meta":{"val":"3","id":"pi"},"teData":{"val":{"isLocalized":{"val":"0","id":"pb"},"HangedMob":{"val":"0","id":"pb"},"DeathText":{"val":"","id":"ss"},"Enchanted":{"val":"0","id":"pb"},"HangedVillagerProfession":{"val":"0","id":"pi"},"id":{"val":"GSMemorial","id":"ss"},"GraveType":{"val":"98","id":"pb"}},"id":"ct"}},"id":"ct"}}
:enddata
:endrule

rule:
plugin=vanillaBlocks
number=37
data:
JSON:{{"val":{"buildPass":{"val":"0","id":"pi"},"blockName":{"val":"minecraft:birch_stairs","id":"ss"},"meta":{"val":"3","id":"pi"}},"id":"ct"}}
:enddata
:endrule

rule:
plugin=vanillaBlocks
number=38
data:
JSON:{{"val":{"buildPass":{"val":"0","id":"pi"},"blockName":{"val":"minecraft:stone_brick_stairs","id":"ss"},"meta":{"val":"2","id":"pi"}},"id":"ct"}}
:enddata
:endrule

rule:
plugin=vanillaInventory
number=39
data:
JSON:{{"val":{"buildPass":{"val":"0","id":"pi"},"blockName":{"val":"minecraft:chest","id":"ss"},"meta":{"val":"3","id":"pi"},"lootLevel":{"val":"0","id":"pi"},"teData":{"val":{"x":{"val":"546","id":"pi"},"y":{"val":"66","id":"pi"},"z":{"val":"1284","id":"pi"},"id":{"val":"Chest","id":"ss"}},"id":"ct"},"inventoryData":{"val":{"length":{"val":"27","id":"pi"},"inventoryContents":{"val":[],"id":"ls"}},"id":"ct"}},"id":"ct"}}
:enddata
:endrule

rule:
plugin=vanillaInventory
number=40
data:
JSON:{{"val":{"buildPass":{"val":"0","id":"pi"},"blockName":{"val":"minecraft:chest","id":"ss"},"meta":{"val":"3","id":"pi"},"lootLevel":{"val":"0","id":"pi"},"teData":{"val":{"x":{"val":"547","id":"pi"},"y":{"val":"66","id":"pi"},"z":{"val":"1284","id":"pi"},"id":{"val":"Chest","id":"ss"}},"id":"ct"},"inventoryData":{"val":{"length":{"val":"27","id":"pi"},"inventoryContents":{"val":[],"id":"ls"}},"id":"ct"}},"id":"ct"}}
:enddata
:endrule

rule:
plugin=vanillaDoors
number=41
data:
JSON:{{"val":{"buildPass":{"val":"2","id":"pi"},"blockName":{"val":"minecraft:wooden_door","id":"ss"},"meta":{"val":"2","id":"pi"},"sideFlag":{"val":"8","id":"pb"}},"id":"ct"}}
:enddata
:endrule

rule:
plugin=vanillaBlocks
number=42
data:
JSON:{{"val":{"buildPass":{"val":"0","id":"pi"},"blockName":{"val":"minecraft:birch_stairs","id":"ss"},"meta":{"val":"2","id":"pi"}},"id":"ct"}}
:enddata
:endrule

rule:
plugin=vanillaLogic
number=43
data:
JSON:{{"val":{"buildPass":{"val":"0","id":"pi"},"blockName":{"val":"GraveStone:GSMemorial","id":"ss"},"meta":{"val":"3","id":"pi"},"teData":{"val":{"isLocalized":{"val":"0","id":"pb"},"HangedMob":{"val":"0","id":"pb"},"DeathText":{"val":"","id":"ss"},"Enchanted":{"val":"0","id":"pb"},"HangedVillagerProfession":{"val":"0","id":"pi"},"id":{"val":"GSMemorial","id":"ss"},"GraveType":{"val":"98","id":"pb"}},"id":"ct"}},"id":"ct"}}
:enddata
:endrule

rule:
plugin=vanillaDoors
number=44
data:
JSON:{{"val":{"buildPass":{"val":"2","id":"pi"},"blockName":{"val":"minecraft:iron_door","id":"ss"},"meta":{"val":"3","id":"pi"},"sideFlag":{"val":"8","id":"pb"}},"id":"ct"}}
:enddata
:endrule

rule:
plugin=vanillaDoors
number=45
data:
JSON:{{"val":{"buildPass":{"val":"2","id":"pi"},"blockName":{"val":"minecraft:iron_door","id":"ss"},"meta":{"val":"3","id":"pi"},"sideFlag":{"val":"9","id":"pb"}},"id":"ct"}}
:enddata
:endrule

rule:
plugin=vanillaLogic
number=46
data:
JSON:{{"val":{"buildPass":{"val":"0","id":"pi"},"blockName":{"val":"customnpcs:npcTallLamp","id":"ss"},"meta":{"val":"2","id":"pi"},"teData":{"val":{"BannerColor":{"val":"13","id":"pi"},"BannerRotation":{"val":"0","id":"pi"},"id":{"val":"TileNPCTallLamp","id":"ss"}},"id":"ct"}},"id":"ct"}}
:enddata
:endrule

rule:
plugin=vanillaBlocks
number=47
data:
JSON:{{"val":{"buildPass":{"val":"2","id":"pi"},"blockName":{"val":"minecraft:torch","id":"ss"},"meta":{"val":"3","id":"pi"}},"id":"ct"}}
:enddata
:endrule

rule:
plugin=vanillaBlocks
number=48
data:
JSON:{{"val":{"buildPass":{"val":"0","id":"pi"},"blockName":{"val":"minecraft:leaves","id":"ss"},"meta":{"val":"1","id":"pi"}},"id":"ct"}}
:enddata
:endrule

rule:
plugin=vanillaBlocks
number=49
data:
JSON:{{"val":{"buildPass":{"val":"0","id":"pi"},"blockName":{"val":"minecraft:quartz_stairs","id":"ss"},"meta":{"val":"3","id":"pi"}},"id":"ct"}}
:enddata
:endrule

rule:
plugin=vanillaBlocks
number=50
data:
JSON:{{"val":{"buildPass":{"val":"0","id":"pi"},"blockName":{"val":"minecraft:nether_brick_stairs","id":"ss"},"meta":{"val":"3","id":"pi"}},"id":"ct"}}
:enddata
:endrule

rule:
plugin=vanillaLogic
number=51
data:
JSON:{{"val":{"buildPass":{"val":"0","id":"pi"},"blockName":{"val":"GraveStone:GSAltar","id":"ss"},"meta":{"val":"0","id":"pi"},"teData":{"val":{"id":{"val":"GSAltarTE","id":"ss"}},"id":"ct"}},"id":"ct"}}
:enddata
:endrule

rule:
plugin=vanillaLogic
number=52
data:
JSON:{{"val":{"buildPass":{"val":"0","id":"pi"},"blockName":{"val":"GraveStone:GSAltar","id":"ss"},"meta":{"val":"0","id":"pi"},"teData":{"val":{"id":{"val":"GSAltarTE","id":"ss"}},"id":"ct"}},"id":"ct"}}
:enddata
:endrule

rule:
plugin=vanillaBlocks
number=53
data:
JSON:{{"val":{"buildPass":{"val":"0","id":"pi"},"blockName":{"val":"minecraft:leaves","id":"ss"},"meta":{"val":"5","id":"pi"}},"id":"ct"}}
:enddata
:endrule

rule:
plugin=vanillaBlocks
number=54
data:
JSON:{{"val":{"buildPass":{"val":"0","id":"pi"},"blockName":{"val":"minecraft:nether_brick_stairs","id":"ss"},"meta":{"val":"2","id":"pi"}},"id":"ct"}}
:enddata
:endrule

rule:
plugin=vanillaLogic
number=55
data:
JSON:{{"val":{"buildPass":{"val":"0","id":"pi"},"blockName":{"val":"props:blockFake","id":"ss"},"meta":{"val":"0","id":"pi"},"teData":{"val":{"id":{"val":"TileFake","id":"ss"},"master":{"val":["560","65","1296"],"id":"ai"}},"id":"ct"}},"id":"ct"}}
:enddata
:endrule

rule:
plugin=modBlockDefault
number=56
data:
JSON:{{"val":{"blockName":{"val":"GraveStone:GSInvisibleWall","id":"ss"},"meta":{"val":"0","id":"pi"}},"id":"ct"}}
:enddata
:endrule

rule:
plugin=vanillaDoors
number=57
data:
JSON:{{"val":{"buildPass":{"val":"2","id":"pi"},"blockName":{"val":"minecraft:wooden_door","id":"ss"},"meta":{"val":"1","id":"pi"},"sideFlag":{"val":"9","id":"pb"}},"id":"ct"}}
:enddata
:endrule

rule:
plugin=vanillaBlocks
number=58
data:
JSON:{{"val":{"buildPass":{"val":"2","id":"pi"},"blockName":{"val":"minecraft:torch","id":"ss"},"meta":{"val":"2","id":"pi"}},"id":"ct"}}
:enddata
:endrule

rule:
plugin=vanillaBlocks
number=59
data:
JSON:{{"val":{"buildPass":{"val":"0","id":"pi"},"blockName":{"val":"minecraft:stained_glass","id":"ss"},"meta":{"val":"15","id":"pi"}},"id":"ct"}}
:enddata
:endrule

rule:
plugin=vanillaBlocks
number=60
data:
JSON:{{"val":{"buildPass":{"val":"2","id":"pi"},"blockName":{"val":"minecraft:torch","id":"ss"},"meta":{"val":"1","id":"pi"}},"id":"ct"}}
:enddata
:endrule

rule:
plugin=vanillaBlocks
number=61
data:
JSON:{{"val":{"buildPass":{"val":"2","id":"pi"},"blockName":{"val":"minecraft:torch","id":"ss"},"meta":{"val":"4","id":"pi"}},"id":"ct"}}
:enddata
:endrule

rule:
plugin=vanillaLogic
number=62
data:
JSON:{{"val":{"buildPass":{"val":"0","id":"pi"},"blockName":{"val":"customnpcs:npcTallLamp","id":"ss"},"meta":{"val":"9","id":"pi"},"teData":{"val":{},"id":"ct"}},"id":"ct"}}
:enddata
:endrule

rule:
plugin=vanillaLogic
number=63
data:
JSON:{{"val":{"buildPass":{"val":"0","id":"pi"},"blockName":{"val":"customnpcs:npcTallLamp","id":"ss"},"meta":{"val":"9","id":"pi"},"teData":{"val":{},"id":"ct"}},"id":"ct"}}
:enddata
:endrule

rule:
plugin=vanillaBlocks
number=64
data:
JSON:{{"val":{"buildPass":{"val":"2","id":"pi"},"blockName":{"val":"minecraft:carpet","id":"ss"},"meta":{"val":"7","id":"pi"}},"id":"ct"}}
:enddata
:endrule

rule:
plugin=vanillaSign
number=65
data:
JSON:{{"val":{"signContents0":{"val":"","id":"ss"},"signContents2":{"val":"corner","id":"ss"},"buildPass":{"val":"2","id":"pi"},"signContents1":{"val":"Time Out","id":"ss"},"blockName":{"val":"minecraft:wall_sign","id":"ss"},"signContents3":{"val":"","id":"ss"},"meta":{"val":"5","id":"pi"}},"id":"ct"}}
:enddata
:endrule

rule:
plugin=vanillaDoors
number=66
data:
JSON:{{"val":{"buildPass":{"val":"2","id":"pi"},"blockName":{"val":"minecraft:wooden_door","id":"ss"},"meta":{"val":"8","id":"pi"},"sideFlag":{"val":"0","id":"pb"}},"id":"ct"}}
:enddata
:endrule

rule:
plugin=vanillaDoors
number=67
data:
JSON:{{"val":{"buildPass":{"val":"2","id":"pi"},"blockName":{"val":"minecraft:wooden_door","id":"ss"},"meta":{"val":"8","id":"pi"},"sideFlag":{"val":"0","id":"pb"}},"id":"ct"}}
:enddata
:endrule

rule:
plugin=vanillaDoors
number=68
data:
JSON:{{"val":{"buildPass":{"val":"2","id":"pi"},"blockName":{"val":"minecraft:wooden_door","id":"ss"},"meta":{"val":"8","id":"pi"},"sideFlag":{"val":"0","id":"pb"}},"id":"ct"}}
:enddata
:endrule

rule:
plugin=vanillaDoors
number=69
data:
JSON:{{"val":{"buildPass":{"val":"2","id":"pi"},"blockName":{"val":"minecraft:iron_door","id":"ss"},"meta":{"val":"8","id":"pi"},"sideFlag":{"val":"0","id":"pb"}},"id":"ct"}}
:enddata
:endrule

rule:
plugin=vanillaDoors
number=70
data:
JSON:{{"val":{"buildPass":{"val":"2","id":"pi"},"blockName":{"val":"minecraft:iron_door","id":"ss"},"meta":{"val":"9","id":"pi"},"sideFlag":{"val":"0","id":"pb"}},"id":"ct"}}
:enddata
:endrule

rule:
plugin=vanillaSign
number=71
data:
JSON:{{"val":{"signContents0":{"val":"Forgive me","id":"ss"},"signContents2":{"val":"about to sin","id":"ss"},"buildPass":{"val":"2","id":"pi"},"signContents1":{"val":"Lord, for I am","id":"ss"},"blockName":{"val":"minecraft:wall_sign","id":"ss"},"signContents3":{"val":"...and enjoy it","id":"ss"},"meta":{"val":"5","id":"pi"}},"id":"ct"}}
:enddata
:endrule

rule:
plugin=vanillaLogic
number=72
data:
JSON:{{"val":{"buildPass":{"val":"0","id":"pi"},"blockName":{"val":"customnpcs:npcTallLamp","id":"ss"},"meta":{"val":"9","id":"pi"},"teData":{"val":{},"id":"ct"}},"id":"ct"}}
:enddata
:endrule

rule:
plugin=vanillaSign
number=73
data:
JSON:{{"val":{"signContents0":{"val":"Dispense with","id":"ss"},"signContents2":{"val":"soul here.","id":"ss"},"buildPass":{"val":"2","id":"pi"},"signContents1":{"val":"your rotten","id":"ss"},"blockName":{"val":"minecraft:wall_sign","id":"ss"},"signContents3":{"val":"NEPENTHE","id":"ss"},"meta":{"val":"5","id":"pi"}},"id":"ct"}}
:enddata
:endrule

rule:
plugin=vanillaLogic
number=74
data:
JSON:{{"val":{"buildPass":{"val":"0","id":"pi"},"blockName":{"val":"AncientWarfareStructure:advanced_spawner","id":"ss"},"meta":{"val":"0","id":"pi"},"teData":{"val":{"id":{"val":"advanced_spawner_tile","id":"ss"},"spawnerSettings":{"val":{"minDelay":{"val":"0","id":"pi"},"spawnDelay":{"val":"2","id":"pi"},"lightSensitive":{"val":"0","id":"pb"},"spawnGroups":{"val":[{"val":{"settingsList":{"val":[{"val":{"remainingSpawnCount":{"val":"-1","id":"pi"},"forced":{"val":"1","id":"pb"},"maxToSpawn":{"val":"2","id":"pi"},"entityId":{"val":"Thaumcraft.CultistCleric","id":"ss"},"customData":{"val":[],"id":"ls"},"minToSpawn":{"val":"1","id":"pi"}},"id":"ct"}],"id":"ls"},"groupWeight":{"val":"1","id":"pi"}},"id":"ct"}],"id":"ls"},"playerRange":{"val":"16","id":"pi"},"respondToRedstone":{"val":"0","id":"pb"},"inventory":{"val":{"itemList":{"val":[],"id":"ls"}},"id":"ct"},"spawnRange":{"val":"4","id":"pi"},"transparent":{"val":"0","id":"pb"},"maxDelay":{"val":"40","id":"pi"},"xpToDrop":{"val":"0","id":"pi"},"mobRange":{"val":"6","id":"pi"},"debugMode":{"val":"0","id":"pb"},"maxNearbyMonsters":{"val":"4","id":"pi"}},"id":"ct"}},"id":"ct"}},"id":"ct"}}
:enddata
:endrule

rule:
plugin=vanillaBlocks
number=75
data:
JSON:{{"val":{"buildPass":{"val":"0","id":"pi"},"blockName":{"val":"minecraft:nether_brick_fence","id":"ss"},"meta":{"val":"0","id":"pi"}},"id":"ct"}}
:enddata
:endrule

rule:
plugin=vanillaDoors
number=76
data:
JSON:{{"val":{"buildPass":{"val":"2","id":"pi"},"blockName":{"val":"minecraft:wooden_door","id":"ss"},"meta":{"val":"8","id":"pi"},"sideFlag":{"val":"0","id":"pb"}},"id":"ct"}}
:enddata
:endrule

rule:
plugin=vanillaSign
number=77
data:
JSON:{{"val":{"signContents0":{"val":"Confession","id":"ss"},"signContents2":{"val":"Enter to be","id":"ss"},"buildPass":{"val":"2","id":"pi"},"signContents1":{"val":"","id":"ss"},"blockName":{"val":"minecraft:wall_sign","id":"ss"},"signContents3":{"val":"CLEANSED","id":"ss"},"meta":{"val":"3","id":"pi"}},"id":"ct"}}
:enddata
:endrule

rule:
plugin=vanillaLogic
number=78
data:
JSON:{{"val":{"buildPass":{"val":"0","id":"pi"},"blockName":{"val":"props:blockFake","id":"ss"},"meta":{"val":"0","id":"pi"},"teData":{"val":{"id":{"val":"TileFake","id":"ss"},"master":{"val":["560","65","1296"],"id":"ai"}},"id":"ct"}},"id":"ct"}}
:enddata
:endrule

rule:
plugin=vanillaDoors
number=79
data:
JSON:{{"val":{"buildPass":{"val":"2","id":"pi"},"blockName":{"val":"minecraft:wooden_door","id":"ss"},"meta":{"val":"9","id":"pi"},"sideFlag":{"val":"0","id":"pb"}},"id":"ct"}}
:enddata
:endrule

rule:
plugin=vanillaDoors
number=80
data:
JSON:{{"val":{"buildPass":{"val":"2","id":"pi"},"blockName":{"val":"minecraft:wooden_door","id":"ss"},"meta":{"val":"8","id":"pi"},"sideFlag":{"val":"0","id":"pb"}},"id":"ct"}}
:enddata
:endrule

rule:
plugin=vanillaBlocks
number=81
data:
JSON:{{"val":{"buildPass":{"val":"2","id":"pi"},"blockName":{"val":"minecraft:carpet","id":"ss"},"meta":{"val":"13","id":"pi"}},"id":"ct"}}
:enddata
:endrule

rule:
plugin=vanillaLogic
number=82
data:
JSON:{{"val":{"buildPass":{"val":"0","id":"pi"},"blockName":{"val":"props:blockFake","id":"ss"},"meta":{"val":"0","id":"pi"},"teData":{"val":{"id":{"val":"TileFake","id":"ss"},"master":{"val":["560","65","1296"],"id":"ai"}},"id":"ct"}},"id":"ct"}}
:enddata
:endrule

rule:
plugin=vanillaBlocks
number=83
data:
JSON:{{"val":{"buildPass":{"val":"0","id":"pi"},"blockName":{"val":"minecraft:stone_brick_stairs","id":"ss"},"meta":{"val":"6","id":"pi"}},"id":"ct"}}
:enddata
:endrule

rule:
plugin=vanillaBlocks
number=84
data:
JSON:{{"val":{"buildPass":{"val":"0","id":"pi"},"blockName":{"val":"minecraft:stone_brick_stairs","id":"ss"},"meta":{"val":"5","id":"pi"}},"id":"ct"}}
:enddata
:endrule

rule:
plugin=vanillaBlocks
number=85
data:
JSON:{{"val":{"buildPass":{"val":"0","id":"pi"},"blockName":{"val":"minecraft:stone_brick_stairs","id":"ss"},"meta":{"val":"4","id":"pi"}},"id":"ct"}}
:enddata
:endrule

rule:
plugin=vanillaBlocks
number=86
data:
JSON:{{"val":{"buildPass":{"val":"2","id":"pi"},"blockName":{"val":"minecraft:lit_redstone_lamp","id":"ss"},"meta":{"val":"0","id":"pi"}},"id":"ct"}}
:enddata
:endrule

rule:
plugin=vanillaBlocks
number=87
data:
JSON:{{"val":{"buildPass":{"val":"2","id":"pi"},"blockName":{"val":"minecraft:lever","id":"ss"},"meta":{"val":"9","id":"pi"}},"id":"ct"}}
:enddata
:endrule

rule:
plugin=vanillaBlocks
number=88
data:
JSON:{{"val":{"buildPass":{"val":"0","id":"pi"},"blockName":{"val":"minecraft:glass_pane","id":"ss"},"meta":{"val":"0","id":"pi"}},"id":"ct"}}
:enddata
:endrule

rule:
plugin=vanillaBlocks
number=89
data:
JSON:{{"val":{"buildPass":{"val":"2","id":"pi"},"blockName":{"val":"minecraft:lever","id":"ss"},"meta":{"val":"15","id":"pi"}},"id":"ct"}}
:enddata
:endrule

rule:
plugin=vanillaBlocks
number=90
data:
JSON:{{"val":{"buildPass":{"val":"0","id":"pi"},"blockName":{"val":"minecraft:stained_glass","id":"ss"},"meta":{"val":"0","id":"pi"}},"id":"ct"}}
:enddata
:endrule

rule:
plugin=vanillaBlocks
number=91
data:
JSON:{{"val":{"buildPass":{"val":"0","id":"pi"},"blockName":{"val":"minecraft:iron_bars","id":"ss"},"meta":{"val":"0","id":"pi"}},"id":"ct"}}
:enddata
:endrule

rule:
plugin=vanillaBlocks
number=92
data:
JSON:{{"val":{"buildPass":{"val":"0","id":"pi"},"blockName":{"val":"minecraft:stained_glass","id":"ss"},"meta":{"val":"7","id":"pi"}},"id":"ct"}}
:enddata
:endrule

rule:
plugin=vanillaBlocks
number=93
data:
JSON:{{"val":{"buildPass":{"val":"0","id":"pi"},"blockName":{"val":"minecraft:stone_brick_stairs","id":"ss"},"meta":{"val":"7","id":"pi"}},"id":"ct"}}
:enddata
:endrule

rule:
plugin=vanillaBlocks
number=94
data:
JSON:{{"val":{"buildPass":{"val":"2","id":"pi"},"blockName":{"val":"minecraft:lever","id":"ss"},"meta":{"val":"12","id":"pi"}},"id":"ct"}}
:enddata
:endrule

rule:
plugin=vanillaBlocks
number=95
data:
JSON:{{"val":{"buildPass":{"val":"2","id":"pi"},"blockName":{"val":"minecraft:stone_button","id":"ss"},"meta":{"val":"4","id":"pi"}},"id":"ct"}}
:enddata
:endrule

rule:
plugin=vanillaDoors
number=96
data:
JSON:{{"val":{"buildPass":{"val":"2","id":"pi"},"blockName":{"val":"minecraft:iron_door","id":"ss"},"meta":{"val":"8","id":"pi"},"sideFlag":{"val":"0","id":"pb"}},"id":"ct"}}
:enddata
:endrule

rule:
plugin=vanillaBlocks
number=97
data:
JSON:{{"val":{"buildPass":{"val":"0","id":"pi"},"blockName":{"val":"minecraft:birch_stairs","id":"ss"},"meta":{"val":"1","id":"pi"}},"id":"ct"}}
:enddata
:endrule

rule:
plugin=vanillaBlocks
number=98
data:
JSON:{{"val":{"buildPass":{"val":"0","id":"pi"},"blockName":{"val":"minecraft:birch_stairs","id":"ss"},"meta":{"val":"0","id":"pi"}},"id":"ct"}}
:enddata
:endrule

rule:
plugin=vanillaBlocks
number=99
data:
JSON:{{"val":{"buildPass":{"val":"2","id":"pi"},"blockName":{"val":"minecraft:lever","id":"ss"},"meta":{"val":"10","id":"pi"}},"id":"ct"}}
:enddata
:endrule

rule:
plugin=vanillaBlocks
number=100
data:
JSON:{{"val":{"buildPass":{"val":"0","id":"pi"},"blockName":{"val":"minecraft:wooden_slab","id":"ss"},"meta":{"val":"2","id":"pi"}},"id":"ct"}}
:enddata
:endrule

#### ENTITIES ####
entity:
plugin=vanillaLogicEntity
number=0
data:
position=3,2,8
JSON:{{"val":{"xOffset":{"val":"0.012865051","id":"pf"},"equipmentData":{"val":{"length":{"val":"5","id":"pi"},"equipmentContents":{"val":[],"id":"ls"}},"id":"ct"},"rotation":{"val":"90.0","id":"pf"},"mobID":{"val":"SpecialMobs.SpecialCreeper","id":"ss"},"zOffset":{"val":"0.5","id":"pf"},"entityData":{"val":{"ForgeData":{"val":{"MP|Init":{"val":"1","id":"pb"},"ESM_TARGET_COOLDOWN":{"val":"0","id":"pi"},"ESM_MODIFIED":{"val":"1","id":"pb"},"ezModsApp":{"val":"1","id":"pb"},"sAI":{"val":{"Fiddling":{"val":"0","id":"pb"},"AvoidExplosions":{"val":"1","id":"pb"},"DefendVillage":{"val":"0","id":"pb"},"Griefing":{"val":"0","id":"pb"},"uAI":{"val":{},"id":"ct"},"Rider":{"val":"0","id":"pb"}},"id":"ct"},"SMData":{"val":{"SMWebImmune":{"val":"0","id":"pb"},"SMArrowRefireMin":{"val":"0","id":"ps"},"SMUnderPressure":{"val":"0","id":"pb"},"SMWaterDamage":{"val":"0","id":"pb"},"ShotExplode":{"val":"0","id":"pb"},"SMLeash":{"val":"0","id":"pb"},"DryExplode":{"val":"0","id":"pb"},"SMBurningImmune":{"val":"0","id":"pb"},"BurningExplode":{"val":"0","id":"pb"},"SMRegenTick":{"val":"0","id":"pb"},"SMArrowSpread":{"val":"14.0","id":"pf"},"SMFallImmune":{"val":"0","id":"pb"},"SMWaterPushImmune":{"val":"0","id":"pb"},"SMArrowRange":{"val":"0.0","id":"pf"},"SMArrowMoveSpeed":{"val":"0.0","id":"pf"},"SMArmor":{"val":"0","id":"pb"},"SMWaterBreath":{"val":"0","id":"pb"},"SMArrowRefireMax":{"val":"0","id":"ps"},"SMTex":{"val":[{"val":"minecraft:textures/entity/creeper/creeper.png","id":"ss"}],"id":"ls"},"SMScale":{"val":"1.0958942","id":"pf"},"SMArrowDamage":{"val":"2.0","id":"pf"},"SMFireImmune":{"val":"0","id":"pb"},"SMPotionImmune":{"val":[],"id":"ai"},"SMRegen":{"val":"0","id":"pb"}},"id":"ct"},"ORIGINAL_SPAWN_POS":{"val":["547","65","1285"],"id":"ai"},"HungerOverhaulCheck":{"val":"7","id":"pi"}},"id":"ct"},"Attributes":{"val":[{"val":{"Base":{"val":"-2.0","id":"pd"},"Modifiers":{"val":[{"val":{"UUIDMost":{"val":"2189974539282499591","id":"pl"},"UUIDLeast":{"val":"-6477178668949725305","id":"pl"},"Amount":{"val":"1.0","id":"pd"},"Operation":{"val":"0","id":"pi"},"Name":{"val":"normal","id":"ss"}},"id":"ct"}],"id":"ls"},"Name":{"val":"tc.mobmod","id":"ss"}},"id":"ct"},{"val":{"Base":{"val":"22.0","id":"pd"},"Modifiers":{"val":[{"val":{"UUIDMost":{"val":"770719144193377","id":"pl"},"UUIDLeast":{"val":"3260367731102264","id":"pl"},"Amount":{"val":"0.0","id":"pd"},"Operation":{"val":"1","id":"pi"},"Name":{"val":"ESM_TWEAK_1","id":"ss"}},"id":"ct"}],"id":"ls"},"Name":{"val":"generic.maxHealth","id":"ss"}},"id":"ct"},{"val":{"Base":{"val":"0.0","id":"pd"},"Modifiers":{"val":[{"val":{"UUIDMost":{"val":"770719144195787","id":"pl"},"UUIDLeast":{"val":"5915635504567739483","id":"pl"},"Amount":{"val":"0.0","id":"pd"},"Operation":{"val":"1","id":"pi"},"Name":{"val":"ESM_TWEAK_4","id":"ss"}},"id":"ct"}],"id":"ls"},"Name":{"val":"generic.knockbackResistance","id":"ss"}},"id":"ct"},{"val":{"Base":{"val":"0.25","id":"pd"},"Modifiers":{"val":[{"val":{"UUIDMost":{"val":"770719144195185","id":"pl"},"UUIDLeast":{"val":"3426686371136582306","id":"pl"},"Amount":{"val":"0.0","id":"pd"},"Operation":{"val":"1","id":"pi"},"Name":{"val":"ESM_TWEAK_2","id":"ss"}},"id":"ct"}],"id":"ls"},"Name":{"val":"generic.movementSpeed","id":"ss"}},"id":"ct"},{"val":{"Base":{"val":"64.0","id":"pd"},"Modifiers":{"val":[{"val":{"UUIDMost":{"val":"770719144049373","id":"pl"},"UUIDLeast":{"val":"-7550505514777627337","id":"pl"},"Amount":{"val":"0.004459320294921461","id":"pd"},"Operation":{"val":"1","id":"pi"},"Name":{"val":"Random spawn bonus","id":"ss"}},"id":"ct"}],"id":"ls"},"Name":{"val":"generic.followRange","id":"ss"}},"id":"ct"},{"val":{"Base":{"val":"2.2","id":"pd"},"Modifiers":{"val":[{"val":{"UUIDMost":{"val":"770719144195486","id":"pl"},"UUIDLeast":{"val":"5717044308811458637","id":"pl"},"Amount":{"val":"0.0","id":"pd"},"Operation":{"val":"1","id":"pi"},"Name":{"val":"ESM_TWEAK_3","id":"ss"}},"id":"ct"}],"id":"ls"},"Name":{"val":"generic.attackDamage","id":"ss"}},"id":"ct"}],"id":"ls"},"Invulnerable":{"val":"0","id":"pb"},"PortalCooldown":{"val":"0","id":"pi"},"AbsorptionAmount":{"val":"0.0","id":"pf"},"FallDistance":{"val":"0.0","id":"pf"},"DeathTime":{"val":"0","id":"ps"},"DropChances":{"val":[{"val":"0.085","id":"pf"},{"val":"0.085","id":"pf"},{"val":"0.085","id":"pf"},{"val":"0.085","id":"pf"},{"val":"0.085","id":"pf"}],"id":"ls"},"PersistenceRequired":{"val":"0","id":"pb"},"HealF":{"val":"22.0","id":"pf"},"Fuse":{"val":"30","id":"ps"},"Motion":{"val":[{"val":"0.0","id":"pd"},{"val":"-0.0784000015258789","id":"pd"},{"val":"0.0","id":"pd"}],"id":"ls"},"Leashed":{"val":"0","id":"pb"},"Health":{"val":"22","id":"ps"},"Air":{"val":"300","id":"ps"},"OnGround":{"val":"1","id":"pb"},"Dimension":{"val":"0","id":"pi"},"ignited":{"val":"0","id":"pb"},"Rotation":{"val":[{"val":"90.0","id":"pf"},{"val":"0.0","id":"pf"}],"id":"ls"},"CustomName":{"val":"","id":"ss"},"Pos":{"val":[{"val":"547.0128650506645","id":"pd"},{"val":"66.0","id":"pd"},{"val":"1285.5","id":"pd"}],"id":"ls"},"Fire":{"val":"-1","id":"ps"},"CanPickUpLoot":{"val":"0","id":"pb"},"HurtTime":{"val":"0","id":"ps"},"AttackTime":{"val":"0","id":"ps"},"ExplosionRadius":{"val":"3","id":"pb"},"CustomNameVisible":{"val":"0","id":"pb"}},"id":"ct"}},"id":"ct"}}
:enddata
:endentity

entity:
plugin=vanillaLogicEntity
number=1
data:
position=3,2,10
JSON:{{"val":{"xOffset":{"val":"0.43797204","id":"pf"},"equipmentData":{"val":{"length":{"val":"5","id":"pi"},"equipmentContents":{"val":[],"id":"ls"}},"id":"ct"},"rotation":{"val":"16.225372","id":"pf"},"mobID":{"val":"BiomesOPlenty.Phantom","id":"ss"},"zOffset":{"val":"0.40990996","id":"pf"},"entityData":{"val":{"ForgeData":{"val":{"MP|Init":{"val":"1","id":"pb"},"ESM_TARGET_COOLDOWN":{"val":"0","id":"pi"},"ESM_MODIFIED":{"val":"1","id":"pb"},"ezModsApp":{"val":"1","id":"pb"},"sAI":{"val":{"Fiddling":{"val":"0","id":"pb"},"AvoidExplosions":{"val":"1","id":"pb"},"DefendVillage":{"val":"0","id":"pb"},"Griefing":{"val":"0","id":"pb"},"uAI":{"val":{},"id":"ct"},"Rider":{"val":"0","id":"pb"}},"id":"ct"},"ORIGINAL_SPAWN_POS":{"val":["547","65","1287"],"id":"ai"},"smi":{"val":"1","id":"pb"},"HungerOverhaulCheck":{"val":"6","id":"pi"}},"id":"ct"},"Attributes":{"val":[{"val":{"Base":{"val":"-2.0","id":"pd"},"Modifiers":{"val":[{"val":{"UUIDMost":{"val":"2189974539282499591","id":"pl"},"UUIDLeast":{"val":"-6477178668949725305","id":"pl"},"Amount":{"val":"1.0","id":"pd"},"Operation":{"val":"0","id":"pi"},"Name":{"val":"normal","id":"ss"}},"id":"ct"}],"id":"ls"},"Name":{"val":"tc.mobmod","id":"ss"}},"id":"ct"},{"val":{"Base":{"val":"22.0","id":"pd"},"Modifiers":{"val":[{"val":{"UUIDMost":{"val":"771133444819585","id":"pl"},"UUIDLeast":{"val":"8185096131585719818","id":"pl"},"Amount":{"val":"0.0","id":"pd"},"Operation":{"val":"1","id":"pi"},"Name":{"val":"ESM_TWEAK_1","id":"ss"}},"id":"ct"}],"id":"ls"},"Name":{"val":"generic.maxHealth","id":"ss"}},"id":"ct"},{"val":{"Base":{"val":"0.0","id":"pd"},"Modifiers":{"val":[{"val":{"UUIDMost":{"val":"771133444823802","id":"pl"},"UUIDLeast":{"val":"7856446473718212559","id":"pl"},"Amount":{"val":"0.0","id":"pd"},"Operation":{"val":"1","id":"pi"},"Name":{"val":"ESM_TWEAK_4","id":"ss"}},"id":"ct"}],"id":"ls"},"Name":{"val":"generic.knockbackResistance","id":"ss"}},"id":"ct"},{"val":{"Base":{"val":"0.45","id":"pd"},"Modifiers":{"val":[{"val":{"UUIDMost":{"val":"771133444822296","id":"pl"},"UUIDLeast":{"val":"5983594764624017387","id":"pl"},"Amount":{"val":"0.0","id":"pd"},"Operation":{"val":"1","id":"pi"},"Name":{"val":"ESM_TWEAK_2","id":"ss"}},"id":"ct"}],"id":"ls"},"Name":{"val":"generic.movementSpeed","id":"ss"}},"id":"ct"},{"val":{"Base":{"val":"16.0","id":"pd"},"Modifiers":{"val":[{"val":{"UUIDMost":{"val":"771133444647864","id":"pl"},"UUIDLeast":{"val":"800945915055929987","id":"pl"},"Amount":{"val":"0.00783756304629808","id":"pd"},"Operation":{"val":"1","id":"pi"},"Name":{"val":"Random spawn bonus","id":"ss"}},"id":"ct"}],"id":"ls"},"Name":{"val":"generic.followRange","id":"ss"}},"id":"ct"},{"val":{"Base":{"val":"2.2","id":"pd"},"Modifiers":{"val":[{"val":{"UUIDMost":{"val":"771133444823200","id":"pl"},"UUIDLeast":{"val":"1192470763724233010","id":"pl"},"Amount":{"val":"0.0","id":"pd"},"Operation":{"val":"1","id":"pi"},"Name":{"val":"ESM_TWEAK_3","id":"ss"}},"id":"ct"},{"val":{"UUIDMost":{"val":"7245570952092733273","id":"pl"},"UUIDLeast":{"val":"-8449101711440750679","id":"pl"},"Amount":{"val":"1.3","id":"pd"},"Operation":{"val":"2","id":"pi"},"Name":{"val":"potion.damageBoost 0","id":"ss"}},"id":"ct"}],"id":"ls"},"Name":{"val":"generic.attackDamage","id":"ss"}},"id":"ct"}],"id":"ls"},"Invulnerable":{"val":"0","id":"pb"},"PortalCooldown":{"val":"0","id":"pi"},"AbsorptionAmount":{"val":"0.0","id":"pf"},"FallDistance":{"val":"0.0","id":"pf"},"DeathTime":{"val":"0","id":"ps"},"DropChances":{"val":[{"val":"0.085","id":"pf"},{"val":"0.085","id":"pf"},{"val":"0.085","id":"pf"},{"val":"0.085","id":"pf"},{"val":"0.085","id":"pf"}],"id":"ls"},"PersistenceRequired":{"val":"0","id":"pb"},"HealF":{"val":"22.0","id":"pf"},"Motion":{"val":[{"val":"0.0","id":"pd"},{"val":"-0.0784000015258789","id":"pd"},{"val":"0.0","id":"pd"}],"id":"ls"},"Leashed":{"val":"0","id":"pb"},"Health":{"val":"22","id":"ps"},"Air":{"val":"300","id":"ps"},"OnGround":{"val":"1","id":"pb"},"Dimension":{"val":"0","id":"pi"},"Rotation":{"val":[{"val":"376.22537","id":"pf"},{"val":"0.0","id":"pf"}],"id":"ls"},"CustomName":{"val":"","id":"ss"},"Pos":{"val":[{"val":"547.4379720315712","id":"pd"},{"val":"66.0","id":"pd"},{"val":"1287.4099099600153","id":"pd"}],"id":"ls"},"Fire":{"val":"-1","id":"ps"},"CanPickUpLoot":{"val":"0","id":"pb"},"HurtTime":{"val":"0","id":"ps"},"AttackTime":{"val":"0","id":"ps"},"ActiveEffects":{"val":[{"val":{"Ambient":{"val":"0","id":"pb"},"Duration":{"val":"994195","id":"pi"},"Id":{"val":"5","id":"pi"},"Amplifier":{"val":"0","id":"pb"}},"id":"ct"}],"id":"ls"},"CustomNameVisible":{"val":"0","id":"pb"}},"id":"ct"}},"id":"ct"}}
:enddata
:endentity

entity:
plugin=vanillaHangingEntity
number=2
data:
position=18,4,3
JSON:{{"val":{"xOffset":{"val":"0.0","id":"pf"},"rotation":{"val":"180.0","id":"pf"},"mobID":{"val":"Painting","id":"ss"},"zOffset":{"val":"0.0625","id":"pf"},"entityData":{"val":{"Motion":{"val":[{"val":"0.0","id":"pd"},{"val":"0.0","id":"pd"},{"val":"0.0","id":"pd"}],"id":"ls"},"ForgeData":{"val":{"ESM_MODIFIED":{"val":"1","id":"pb"}},"id":"ct"},"Invulnerable":{"val":"0","id":"pb"},"Air":{"val":"300","id":"ps"},"OnGround":{"val":"0","id":"pb"},"Dimension":{"val":"0","id":"pi"},"PortalCooldown":{"val":"0","id":"pi"},"Dir":{"val":"2","id":"pb"},"Rotation":{"val":[{"val":"180.0","id":"pf"},{"val":"0.0","id":"pf"}],"id":"ls"},"Direction":{"val":"0","id":"pb"},"FallDistance":{"val":"0.0","id":"pf"},"Motive":{"val":"Creebet","id":"ss"},"Pos":{"val":[{"val":"562.0","id":"pd"},{"val":"68.5","id":"pd"},{"val":"1280.0625","id":"pd"}],"id":"ls"},"Fire":{"val":"0","id":"ps"},"TileY":{"val":"68","id":"pi"},"TileX":{"val":"561","id":"pi"},"TileZ":{"val":"1279","id":"pi"}},"id":"ct"},"direction":{"val":"0","id":"pi"}},"id":"ct"}}
:enddata
:endentity

