# Ancient Warfare Structure Template File
# Auto-generated structure template file. created on: 2/18/2015 at: 12:53:35
# Lines beginning with # denote comments

header:
version=2.1
name=VikingWeaponForgeLarge
size=15,40,37
offset=6,2,33
:endheader

#### VALIDATION ####
validation:
type=ground
survival=false
worldGenEnabled=true
unique=false
preserveBlocks=false
selectionWeight=0
clusterValue=0
minDuplicateDistance=0
dimensionWhiteList=false
dimensionList=
biomeWhiteList=false
biomeList=taiga
leveling=0
fill=0
border=0
validTargetBlocks=
blockSwap=false
data:
:enddata
:endvalidation

#### LAYERS ####
layer: 0
1,1,1,1,1,1,1,1,1,1,1,1,1,1,1
1,1,1,1,1,1,1,1,1,1,1,1,1,1,1
1,1,1,1,1,1,1,1,1,1,1,1,1,1,1
1,1,1,1,1,1,1,1,1,1,1,1,1,1,1
1,1,1,1,1,1,1,1,1,1,1,1,1,1,1
1,1,1,1,1,1,1,1,1,1,1,1,1,1,1
1,1,1,1,1,1,1,1,1,1,1,1,1,1,1
1,1,1,1,1,1,1,1,1,1,1,1,1,1,1
1,1,1,1,1,1,1,1,1,1,1,1,1,1,1
1,1,1,1,1,1,1,1,1,1,1,1,1,1,1
1,1,1,1,1,1,1,1,1,1,1,1,1,1,1
1,1,1,1,1,1,1,1,1,1,1,1,1,1,1
1,1,1,1,1,1,1,1,1,1,1,1,1,1,1
1,1,1,1,1,1,1,1,1,1,1,1,1,1,1
1,1,1,1,1,1,1,1,1,1,1,1,1,1,1
1,1,1,1,1,1,1,1,1,1,1,1,1,1,1
1,1,1,1,1,1,1,1,1,1,1,1,1,1,1
1,1,1,1,1,1,1,1,1,1,1,1,1,1,1
1,1,1,1,1,1,1,1,1,1,1,1,1,1,1
1,1,1,1,1,1,1,1,1,1,1,1,1,1,1
1,1,1,1,1,1,1,1,1,1,1,1,1,1,1
1,1,1,1,1,1,1,1,1,1,1,1,1,1,1
1,1,1,1,1,1,1,1,1,1,1,1,1,1,1
1,1,1,1,1,1,1,1,1,1,1,1,1,1,1
1,1,1,1,1,1,1,1,1,1,1,1,1,1,1
1,1,1,1,1,1,1,1,1,1,1,1,1,1,1
1,1,1,1,1,1,1,1,1,1,1,1,1,1,1
1,1,1,1,1,1,1,1,1,1,1,1,1,1,1
1,1,1,1,1,1,1,1,1,1,1,1,1,1,1
1,1,1,1,1,1,1,1,1,1,1,1,1,1,1
1,1,1,1,1,1,1,1,1,1,1,1,1,1,1
1,1,1,1,1,1,1,1,1,1,1,1,1,1,1
1,1,1,1,1,1,1,1,1,1,1,1,1,1,1
1,1,1,1,1,1,1,1,1,1,1,1,1,1,1
1,1,1,1,1,1,1,1,1,1,1,1,1,1,1
1,1,1,1,1,1,1,1,1,1,1,1,1,1,1
1,1,1,1,1,1,1,1,1,1,1,1,1,1,1
:endlayer
layer: 1
2,2,2,2,2,2,2,2,2,2,2,2,2,2,2
2,3,3,3,3,3,3,3,3,3,3,3,3,3,2
2,3,3,3,3,3,3,3,3,3,3,3,3,3,2
2,3,3,3,3,3,3,3,3,3,3,3,3,3,2
2,3,3,3,3,3,3,3,3,3,3,3,3,3,2
2,3,3,3,3,3,3,3,3,3,3,3,3,3,2
2,3,3,3,3,3,3,3,3,3,3,3,3,3,2
2,3,3,3,3,3,3,3,3,3,3,3,3,3,2
2,3,3,3,3,3,3,3,3,3,3,3,3,3,2
2,3,3,3,3,3,3,3,3,3,3,3,3,3,2
2,3,3,3,3,3,3,3,3,3,3,3,3,3,2
2,3,3,3,3,3,3,3,3,3,3,3,3,3,2
2,3,3,3,3,3,3,3,3,3,3,3,3,3,2
2,3,3,3,3,3,3,3,3,3,3,3,3,3,2
2,3,3,3,3,3,3,3,3,3,3,3,3,3,2
2,3,3,3,3,3,3,3,3,3,3,3,3,3,2
2,3,3,3,3,3,3,3,3,3,3,3,3,3,2
2,3,3,3,3,3,3,3,3,3,3,3,3,3,2
2,3,3,3,3,3,3,3,3,3,3,3,3,3,2
2,3,3,3,3,3,3,3,3,3,3,3,3,3,2
2,3,3,3,3,3,3,3,3,3,3,3,3,3,2
2,3,3,3,3,3,3,3,3,3,3,3,3,3,2
2,3,3,3,3,3,3,3,3,3,3,3,3,3,2
2,3,3,3,3,3,3,4,3,3,3,3,3,3,2
2,3,3,3,3,3,3,3,3,3,3,3,3,3,2
2,3,3,3,3,3,3,5,3,3,3,3,3,3,2
2,3,3,3,3,3,3,3,3,3,3,3,3,3,2
2,3,3,3,3,3,3,3,3,3,3,3,3,3,2
2,3,3,3,3,3,3,3,3,3,3,3,3,3,2
2,3,3,3,3,3,3,3,3,3,3,3,3,3,2
2,3,3,3,3,3,3,3,3,3,3,3,3,3,2
2,3,3,3,3,3,3,3,3,3,3,3,3,3,2
2,3,3,3,3,3,3,3,3,3,3,3,3,3,2
2,3,3,3,3,3,3,3,3,3,3,3,3,3,2
2,3,3,3,3,3,3,3,3,3,3,3,3,3,2
2,2,2,2,2,2,2,2,2,2,2,2,2,2,2
2,2,2,2,2,2,2,2,2,2,2,2,2,2,2
:endlayer
layer: 2
0,6,6,6,6,6,0,0,7,6,6,8,6,6,7
6,7,6,0,7,6,0,0,0,6,6,0,6,6,7
7,7,0,3,3,3,3,9,3,3,3,3,0,6,7
0,0,6,3,10,10,11,11,11,10,10,3,6,8,0
6,6,6,3,0,0,11,11,11,0,0,3,7,6,8
6,6,0,3,12,0,0,0,0,0,13,3,6,6,6
7,6,6,3,0,0,0,0,0,0,0,3,6,0,6
6,6,7,3,14,0,0,0,0,0,15,3,0,0,7
6,7,0,3,3,3,0,0,0,3,3,3,0,6,0
0,6,7,0,16,3,0,17,0,3,0,0,6,6,7
6,6,6,7,0,3,0,17,0,3,8,7,6,7,0
6,7,0,6,0,3,0,17,0,3,6,6,6,7,6
6,0,8,6,0,3,0,17,0,3,6,6,7,6,6
6,6,0,0,6,3,0,17,0,3,6,7,7,8,6
6,6,0,0,0,3,0,17,0,3,0,7,6,0,0
6,6,0,7,0,3,0,17,0,3,0,6,0,6,6
6,6,0,0,7,3,0,17,0,3,8,6,6,0,6
0,6,0,0,0,3,0,17,0,3,6,6,0,8,0
0,0,3,3,3,3,0,0,0,3,3,3,3,0,8
6,0,3,18,0,0,0,0,0,0,0,19,3,7,0
6,6,3,20,0,0,0,0,0,0,0,21,3,0,8
0,0,3,0,0,0,0,0,0,0,0,0,3,7,7
6,6,3,0,0,0,22,22,22,0,0,0,3,0,6
6,0,3,0,0,0,22,0,22,0,0,0,3,7,7
6,6,3,23,23,0,22,0,22,0,24,24,3,6,7
6,6,3,23,23,0,22,0,22,0,24,24,3,6,0
6,0,3,23,23,0,22,0,22,0,24,24,3,7,7
6,6,3,0,0,0,22,22,22,0,0,0,3,0,6
6,6,3,0,0,0,0,0,0,0,0,0,3,7,6
0,6,3,0,0,0,0,0,0,0,0,0,3,6,0
0,7,3,0,0,0,11,11,11,0,0,0,3,6,6
6,0,3,10,0,0,11,11,11,0,0,10,3,6,6
7,7,3,25,0,0,11,11,11,0,0,25,3,6,6
7,0,3,3,3,3,3,26,3,3,3,3,3,0,6
7,7,0,6,0,0,0,0,0,7,6,27,0,7,0
7,7,8,8,6,0,0,0,0,6,6,6,6,7,6
0,6,7,6,7,6,0,0,7,7,0,7,6,6,6
:endlayer
layer: 3
0,0,0,0,0,0,0,0,0,0,0,0,0,0,0
0,0,0,0,0,0,28,0,28,0,0,0,0,0,0
0,0,0,29,30,30,29,31,29,30,30,29,0,0,0
0,0,0,30,0,0,28,0,28,0,0,30,0,0,0
0,0,0,30,0,0,0,0,0,0,0,30,0,0,0
0,0,0,30,0,0,0,0,0,0,0,30,0,0,0
0,0,0,30,0,0,0,0,0,0,0,30,0,0,0
0,0,0,30,0,0,0,0,0,0,0,30,0,0,0
0,0,0,29,30,29,0,0,0,29,30,29,0,0,0
0,0,0,0,0,32,0,0,0,32,0,0,0,0,0
0,0,0,0,0,30,0,0,0,30,0,0,0,0,0
0,0,0,0,0,30,0,0,0,30,0,0,0,0,0
0,0,0,0,0,30,0,0,0,30,0,0,0,0,0
0,0,0,0,0,30,0,0,0,30,0,0,0,0,0
0,0,0,0,0,30,0,0,0,30,0,0,0,0,0
0,0,0,0,0,30,0,0,0,30,0,0,0,0,0
0,0,0,0,0,30,0,0,0,30,0,0,0,0,0
0,0,0,0,0,32,0,0,0,32,0,0,0,0,0
0,0,29,30,30,29,0,0,0,29,30,30,29,0,0
0,0,30,0,28,0,0,0,0,0,28,0,30,0,0
0,0,30,0,0,0,0,0,0,0,0,0,30,0,0
0,0,30,0,0,0,0,0,0,0,0,0,30,0,0
0,0,30,0,0,0,22,0,22,0,0,0,30,0,0
0,0,30,0,0,0,0,0,0,0,0,0,30,0,0
0,0,30,0,0,0,0,0,0,0,0,0,30,0,0
0,0,30,0,0,0,0,0,0,0,0,0,30,0,0
0,0,30,0,0,0,0,0,0,0,0,0,30,0,0
0,0,30,0,0,0,22,0,22,0,0,0,30,0,0
0,0,30,0,0,0,0,0,0,0,0,0,30,0,0
0,0,30,0,0,0,0,0,0,0,0,0,30,0,0
0,0,30,0,0,0,0,0,0,0,0,0,30,0,0
0,0,30,0,0,0,0,0,0,0,0,0,30,0,0
0,0,30,0,0,0,33,0,33,0,0,0,30,0,0
0,0,29,30,30,30,29,34,29,30,30,30,29,0,0
0,0,0,0,0,0,28,0,28,0,0,0,0,0,0
0,0,0,0,0,0,0,0,0,0,0,0,0,0,0
0,0,0,0,0,0,0,0,0,0,0,0,0,0,0
:endlayer
layer: 4
0,0,0,0,0,0,0,0,0,0,0,0,0,0,0
0,0,0,33,0,0,35,0,35,0,0,33,0,0,0
0,0,36,29,30,30,29,37,29,30,30,29,38,0,0
0,0,0,30,0,0,35,0,35,0,0,30,0,0,0
0,0,0,30,0,0,0,0,0,0,0,30,0,0,0
0,0,0,30,38,0,0,0,0,0,36,30,0,0,0
0,0,0,30,0,0,0,0,0,0,0,30,0,0,0
0,0,0,30,0,28,0,0,0,28,0,30,0,0,0
0,0,36,29,30,29,28,0,28,29,30,29,38,0,0
0,0,0,39,0,32,0,0,0,32,0,39,0,0,0
0,0,0,0,0,30,0,0,0,30,0,0,0,0,0
0,0,0,0,0,30,0,0,0,30,0,0,0,0,0
0,0,0,0,0,32,0,0,0,32,0,0,0,0,0
0,0,0,0,0,32,0,0,0,32,0,0,0,0,0
0,0,0,0,0,32,0,0,0,32,0,0,0,0,0
0,0,0,0,0,30,0,0,0,30,0,0,0,0,0
0,0,0,0,0,30,0,0,0,30,0,0,0,0,0
0,0,33,0,0,32,0,0,0,32,0,0,33,0,0
0,36,29,30,30,29,28,0,28,29,30,30,29,38,0
0,0,30,0,35,0,0,0,0,0,35,0,30,0,0
0,0,30,0,0,0,0,0,0,0,0,0,30,0,0
0,0,30,0,0,0,0,0,0,0,0,0,30,0,0
0,0,30,0,0,0,3,3,3,0,0,0,30,0,0
0,0,30,0,0,0,3,3,3,0,0,0,30,0,0
0,0,30,0,0,0,3,3,3,0,0,0,30,0,0
0,0,30,0,0,0,3,3,3,0,0,0,30,0,0
0,0,30,0,0,0,3,3,3,0,0,0,30,0,0
0,0,30,0,0,0,3,3,3,0,0,0,30,0,0
0,0,30,0,0,0,0,0,0,0,0,0,30,0,0
0,0,30,0,0,0,0,0,0,0,0,0,30,0,0
0,0,30,0,0,0,0,0,0,0,0,0,30,0,0
0,0,30,38,0,0,0,0,0,0,0,36,30,0,0
0,0,30,0,0,0,0,0,0,0,0,0,30,0,0
0,36,29,30,30,30,29,37,29,30,30,30,29,38,0
0,0,39,0,0,0,35,0,35,0,0,0,39,0,0
0,0,0,0,0,0,0,0,0,0,0,0,0,0,0
0,0,0,0,0,0,0,0,0,0,0,0,0,0,0
:endlayer
layer: 5
0,0,0,0,0,0,0,0,0,0,0,0,0,0,0
0,0,40,41,41,41,41,41,41,41,41,41,41,0,0
0,0,40,29,42,42,42,42,42,42,42,29,43,0,0
0,0,40,42,0,0,0,0,0,0,0,42,43,0,0
0,0,40,42,0,0,0,0,0,0,0,42,43,0,0
0,0,40,42,0,0,0,0,0,0,0,42,43,0,0
0,0,40,42,0,0,0,0,0,0,0,42,43,0,0
0,0,40,42,0,35,0,0,0,35,0,42,43,0,0
0,0,40,29,42,29,28,28,28,29,42,29,43,0,0
0,0,44,44,44,42,0,0,0,42,43,44,43,0,0
0,0,0,0,40,42,0,0,0,42,43,0,0,0,0
0,0,0,0,40,42,0,0,0,42,43,0,0,0,0
0,0,0,0,40,42,0,0,0,42,43,0,0,0,0
0,0,0,0,40,42,0,0,0,42,43,0,0,0,0
0,0,0,0,40,42,0,0,0,42,43,0,0,0,0
0,0,0,0,40,42,0,0,0,42,43,0,0,0,0
0,0,0,0,40,42,0,0,0,42,43,0,0,0,0
0,40,41,41,40,42,0,0,0,42,41,41,41,43,0
0,40,29,42,42,29,28,28,28,29,42,42,29,43,0
0,40,42,0,0,0,0,0,0,0,0,0,42,43,0
0,40,42,0,0,0,0,0,0,0,0,0,42,43,0
0,40,42,0,0,0,0,0,0,0,0,0,42,43,0
0,40,42,0,0,0,0,0,0,0,0,0,42,43,0
0,40,42,0,0,0,0,0,0,0,0,0,42,43,0
0,40,42,0,0,0,0,0,0,0,0,0,42,43,0
0,40,42,0,0,0,0,0,0,0,0,0,42,43,0
0,40,42,0,0,0,0,0,0,0,0,0,42,43,0
0,40,42,0,0,0,0,0,0,0,0,0,42,43,0
0,40,42,0,0,0,0,0,0,0,0,0,42,43,0
0,40,42,0,0,0,0,0,0,0,0,0,42,43,0
0,40,42,0,0,0,0,0,0,0,0,0,42,43,0
0,40,42,0,0,0,0,0,0,0,0,0,42,43,0
0,40,42,0,0,0,0,0,0,0,0,0,42,43,0
0,40,29,42,42,42,42,42,42,42,42,42,29,43,0
0,0,0,0,0,0,0,0,0,0,0,0,0,0,0
0,0,0,0,0,0,0,0,0,0,0,0,0,0,0
0,0,0,0,0,0,0,0,0,0,0,0,0,0,0
:endlayer
layer: 6
0,0,0,0,0,0,0,0,0,0,0,0,0,0,0
0,0,0,0,0,0,0,0,0,0,0,0,0,0,0
0,0,0,40,45,32,32,32,32,32,46,43,0,0,0
0,0,0,40,45,0,0,0,0,0,46,43,0,0,0
0,0,0,40,45,0,0,0,0,0,46,43,0,0,0
0,0,0,40,45,0,0,0,0,0,46,43,0,0,0
0,0,0,40,45,0,0,0,0,0,46,43,0,0,0
0,0,0,40,45,0,0,0,0,0,46,43,0,0,0
0,0,0,40,45,40,47,28,47,43,46,43,0,0,0
0,0,0,0,0,40,47,0,47,43,0,0,0,0,0
0,0,0,0,0,40,47,0,47,43,0,0,0,0,0
0,0,0,0,0,40,47,0,47,43,0,0,0,0,0
0,0,0,0,0,40,47,0,47,43,0,0,0,0,0
0,0,0,0,0,40,47,0,47,43,0,0,0,0,0
0,0,0,0,0,40,47,0,47,43,0,0,0,0,0
0,0,0,0,0,40,47,0,47,43,0,0,0,0,0
0,0,0,0,0,40,47,0,47,43,0,0,0,0,0
0,0,40,45,0,40,47,0,47,43,0,46,43,0,0
0,0,40,45,32,40,47,28,47,43,32,46,43,0,0
0,0,40,45,0,0,0,0,0,0,0,46,43,0,0
0,0,40,45,0,0,0,0,0,0,0,46,43,0,0
0,0,40,45,0,0,0,0,0,0,0,46,43,0,0
0,0,40,45,0,0,0,0,0,0,0,46,43,0,0
0,0,40,45,0,0,0,0,0,0,0,46,43,0,0
0,0,40,45,0,0,0,0,0,0,0,46,43,0,0
0,0,40,45,0,0,0,0,0,0,0,46,43,0,0
0,0,40,45,0,0,0,0,0,0,0,46,43,0,0
0,0,40,45,0,0,0,0,0,0,0,46,43,0,0
0,0,40,45,0,0,0,0,0,0,0,46,43,0,0
0,0,40,45,0,0,0,0,0,0,0,46,43,0,0
0,0,40,45,0,0,0,0,0,0,0,46,43,0,0
0,0,40,45,0,0,0,0,0,0,0,46,43,0,0
0,0,40,45,0,0,0,0,0,0,0,46,43,0,0
0,0,40,45,32,32,32,32,32,32,32,46,43,0,0
0,0,0,0,0,0,0,0,0,0,0,0,0,0,0
0,0,0,0,0,0,0,0,0,0,0,0,0,0,0
0,0,0,0,0,0,0,0,0,0,0,0,0,0,0
:endlayer
layer: 7
0,0,0,0,0,0,0,0,0,0,0,0,0,0,0
0,0,0,0,0,0,0,0,0,0,0,0,0,0,0
0,0,0,0,42,32,32,32,32,32,42,0,0,0,0
0,0,0,0,42,0,0,0,0,0,42,0,0,0,0
0,0,0,0,42,0,0,0,0,0,42,0,0,0,0
0,0,0,0,42,0,0,0,0,0,42,0,0,0,0
0,0,0,0,42,0,0,0,0,0,42,0,0,0,0
0,0,0,0,42,0,0,0,0,0,42,0,0,0,0
0,0,0,0,42,32,40,48,43,32,42,0,0,0,0
0,0,0,0,0,0,40,47,43,0,0,0,0,0,0
0,0,0,0,0,0,40,47,43,0,0,0,0,0,0
0,0,0,0,0,0,40,47,43,0,0,0,0,0,0
0,0,0,0,0,0,40,47,43,0,0,0,0,0,0
0,0,0,0,0,0,40,47,43,0,0,0,0,0,0
0,0,0,0,0,0,40,47,43,0,0,0,0,0,0
0,0,0,0,0,0,40,47,43,0,0,0,0,0,0
0,0,0,0,0,0,40,47,43,0,0,0,0,0,0
0,0,0,42,0,0,40,47,43,0,0,42,0,0,0
0,0,0,42,32,32,40,48,43,32,32,42,0,0,0
0,0,0,42,0,0,0,0,0,0,0,42,0,0,0
0,0,0,42,0,0,0,0,0,0,0,42,0,0,0
0,0,0,42,0,0,0,0,0,0,0,42,0,0,0
0,0,0,42,0,0,0,0,0,0,0,42,0,0,0
0,0,0,42,0,0,0,0,0,0,0,42,0,0,0
0,0,0,42,0,0,0,0,0,0,0,42,0,0,0
0,0,0,42,0,0,0,0,0,0,0,42,0,0,0
0,0,0,42,0,0,0,0,0,0,0,42,0,0,0
0,0,0,42,0,0,0,0,0,0,0,42,0,0,0
0,0,0,42,0,0,0,0,0,0,0,42,0,0,0
0,0,0,42,0,0,0,0,0,0,0,42,0,0,0
0,0,0,42,0,0,0,0,0,0,0,42,0,0,0
0,0,0,42,0,0,0,0,0,0,0,42,0,0,0
0,0,0,42,0,0,0,0,0,0,0,42,0,0,0
0,0,0,42,32,32,32,32,32,32,32,42,0,0,0
0,0,0,0,0,0,0,0,0,0,0,0,0,0,0
0,0,0,0,0,0,0,0,0,0,0,0,0,0,0
0,0,0,0,0,0,0,0,0,0,0,0,0,0,0
:endlayer
layer: 8
0,0,0,0,0,0,0,0,0,0,0,0,0,0,0
0,0,0,0,0,0,0,0,0,0,0,0,0,0,0
0,0,0,0,40,45,32,32,32,46,43,0,0,0,0
0,0,0,0,40,45,0,0,0,46,43,0,0,0,0
0,0,0,0,40,45,0,0,0,46,43,0,0,0,0
0,0,0,0,40,45,0,0,0,46,43,0,0,0,0
0,0,0,0,40,45,0,0,0,46,43,0,0,0,0
0,0,0,0,40,45,0,0,0,46,43,0,0,0,0
0,0,0,0,40,45,32,32,32,46,43,0,0,0,0
0,0,0,0,0,0,0,0,0,0,0,0,0,0,0
0,0,0,0,0,0,0,0,0,0,0,0,0,0,0
0,0,0,0,0,0,0,0,0,0,0,0,0,0,0
0,0,0,0,0,0,0,0,0,0,0,0,0,0,0
0,0,0,0,0,0,0,0,0,0,0,0,0,0,0
0,0,0,0,0,0,0,0,0,0,0,0,0,0,0
0,0,0,0,0,0,0,0,0,0,0,0,0,0,0
0,0,0,0,0,0,0,0,0,0,0,0,0,0,0
0,0,0,40,45,0,0,0,0,0,46,43,0,0,0
0,0,0,40,45,32,32,32,32,32,46,43,0,0,0
0,0,0,40,45,0,0,0,0,0,46,43,0,0,0
0,0,0,40,45,0,0,0,0,0,46,43,0,0,0
0,0,0,40,45,0,0,0,0,0,46,43,0,0,0
0,0,0,40,45,0,0,0,0,0,46,43,0,0,0
0,0,0,40,45,0,0,0,0,0,46,43,0,0,0
0,0,0,40,45,0,0,0,0,0,46,43,0,0,0
0,0,0,40,45,0,0,0,0,0,46,43,0,0,0
0,0,0,40,45,0,0,0,0,0,46,43,0,0,0
0,0,0,40,45,0,0,0,0,0,46,43,0,0,0
0,0,0,40,45,0,0,0,0,0,46,43,0,0,0
0,0,0,40,45,0,0,0,0,0,46,43,0,0,0
0,0,0,40,45,0,0,0,0,0,46,43,0,0,0
0,0,0,40,45,0,0,0,0,0,46,43,0,0,0
0,0,0,40,45,0,0,0,0,0,46,43,0,0,0
0,0,0,40,45,32,32,32,32,32,46,43,0,0,0
0,0,0,0,0,0,0,0,0,0,0,0,0,0,0
0,0,0,0,0,0,0,0,0,0,0,0,0,0,0
0,0,0,0,0,0,0,0,0,0,0,0,0,0,0
:endlayer
layer: 9
0,0,0,0,0,0,0,0,0,0,0,0,0,0,0
0,0,0,0,0,0,0,0,0,0,0,0,0,0,0
0,0,0,0,0,40,45,32,46,43,0,0,0,0,0
0,0,0,0,0,40,45,0,46,43,0,0,0,0,0
0,0,0,0,0,40,45,0,46,43,0,0,0,0,0
0,0,0,0,0,40,45,0,46,43,0,0,0,0,0
0,0,0,0,0,40,45,0,46,43,0,0,0,0,0
0,0,0,0,0,40,45,0,46,43,0,0,0,0,0
0,0,0,0,0,40,45,32,46,43,0,0,0,0,0
0,0,0,0,0,0,0,0,0,0,0,0,0,0,0
0,0,0,0,0,0,0,0,0,0,0,0,0,0,0
0,0,0,0,0,0,0,0,0,0,0,0,0,0,0
0,0,0,0,0,0,0,0,0,0,0,0,0,0,0
0,0,0,0,0,0,0,0,0,0,0,0,0,0,0
0,0,0,0,0,0,0,0,0,0,0,0,0,0,0
0,0,0,0,0,0,0,0,0,0,0,0,0,0,0
0,0,0,0,0,0,0,0,0,0,0,0,0,0,0
0,0,0,0,42,0,0,0,0,0,42,0,0,0,0
0,0,0,0,42,32,32,32,32,32,42,0,0,0,0
0,0,0,0,42,0,0,0,0,0,42,0,0,0,0
0,0,0,0,42,0,0,0,0,0,42,0,0,0,0
0,0,0,0,42,0,0,0,0,0,42,0,0,0,0
0,0,0,0,42,0,0,0,0,0,42,0,0,0,0
0,0,0,0,42,0,0,0,0,0,42,0,0,0,0
0,0,0,0,42,0,0,0,0,0,42,0,0,0,0
0,0,0,0,42,0,0,0,0,0,42,0,0,0,0
0,0,0,0,42,0,0,0,0,0,42,0,0,0,0
0,0,0,0,42,0,0,0,0,0,42,0,0,0,0
0,0,0,0,42,0,0,0,0,0,42,0,0,0,0
0,0,0,0,42,0,0,0,0,0,42,0,0,0,0
0,0,0,0,42,0,0,0,0,0,42,0,0,0,0
0,0,0,0,42,0,0,0,0,0,42,0,0,0,0
0,0,0,0,42,0,0,0,0,0,42,0,0,0,0
0,0,0,0,42,32,32,32,32,32,42,0,0,0,0
0,0,0,0,0,0,0,0,0,0,0,0,0,0,0
0,0,0,0,0,0,0,0,0,0,0,0,0,0,0
0,0,0,0,0,0,0,0,0,0,0,0,0,0,0
:endlayer
layer: 10
0,0,0,0,0,0,0,0,0,0,0,0,0,0,0
0,0,0,0,0,0,0,47,0,0,0,0,0,0,0
0,0,0,0,0,0,42,47,42,0,0,0,0,0,0
0,0,0,0,0,0,42,47,42,0,0,0,0,0,0
0,0,0,0,0,0,42,47,42,0,0,0,0,0,0
0,0,0,0,0,0,42,47,42,0,0,0,0,0,0
0,0,0,0,0,0,42,47,42,0,0,0,0,0,0
0,0,0,0,0,0,42,47,42,0,0,0,0,0,0
0,0,0,0,0,0,42,47,42,0,0,0,0,0,0
0,0,0,0,0,0,0,47,0,0,0,0,0,0,0
0,0,0,0,0,0,0,0,0,0,0,0,0,0,0
0,0,0,0,0,0,0,0,0,0,0,0,0,0,0
0,0,0,0,0,0,0,0,0,0,0,0,0,0,0
0,0,0,0,0,0,0,0,0,0,0,0,0,0,0
0,0,0,0,0,0,0,0,0,0,0,0,0,0,0
0,0,0,0,0,0,0,0,0,0,0,0,0,0,0
0,0,0,0,0,0,0,0,0,0,0,0,0,0,0
0,0,0,0,40,45,0,0,0,46,43,0,0,0,0
0,0,0,0,40,45,32,32,32,46,43,0,0,0,0
0,0,0,0,40,45,0,0,0,46,43,0,0,0,0
0,0,0,0,40,45,0,0,0,46,43,0,0,0,0
0,0,0,0,40,45,0,0,0,46,43,0,0,0,0
0,0,0,0,40,45,0,0,0,46,43,0,0,0,0
0,0,0,0,40,45,0,0,0,46,43,0,0,0,0
0,0,0,0,40,45,0,0,0,46,43,0,0,0,0
0,0,0,0,40,45,0,0,0,46,43,0,0,0,0
0,0,0,0,40,45,0,0,0,46,43,0,0,0,0
0,0,0,0,40,45,0,0,0,46,43,0,0,0,0
0,0,0,0,40,45,0,0,0,46,43,0,0,0,0
0,0,0,0,40,45,0,0,0,46,43,0,0,0,0
0,0,0,0,40,45,0,0,0,46,43,0,0,0,0
0,0,0,0,40,45,0,0,0,46,43,0,0,0,0
0,0,0,0,40,45,0,0,0,46,43,0,0,0,0
0,0,0,0,40,45,32,32,32,46,43,0,0,0,0
0,0,0,0,0,0,0,0,0,0,0,0,0,0,0
0,0,0,0,0,0,0,0,0,0,0,0,0,0,0
0,0,0,0,0,0,0,0,0,0,0,0,0,0,0
:endlayer
layer: 11
0,0,0,0,0,0,0,0,0,0,0,0,0,0,0
0,0,0,0,0,0,0,35,0,0,0,0,0,0,0
0,0,0,0,0,0,0,0,0,0,0,0,0,0,0
0,0,0,0,0,0,0,49,0,0,0,0,0,0,0
0,0,0,0,0,0,0,49,0,0,0,0,0,0,0
0,0,0,0,0,0,0,49,0,0,0,0,0,0,0
0,0,0,0,0,0,0,49,0,0,0,0,0,0,0
0,0,0,0,0,0,0,49,0,0,0,0,0,0,0
0,0,0,0,0,0,0,0,0,0,0,0,0,0,0
0,0,0,0,0,0,0,35,0,0,0,0,0,0,0
0,0,0,0,0,0,0,0,0,0,0,0,0,0,0
0,0,0,0,0,0,0,0,0,0,0,0,0,0,0
0,0,0,0,0,0,0,0,0,0,0,0,0,0,0
0,0,0,0,0,0,0,0,0,0,0,0,0,0,0
0,0,0,0,0,0,0,0,0,0,0,0,0,0,0
0,0,0,0,0,0,0,0,0,0,0,0,0,0,0
0,0,0,0,0,0,0,0,0,0,0,0,0,0,0
0,0,0,0,0,42,0,0,0,42,0,0,0,0,0
0,0,0,0,0,42,32,32,32,42,0,0,0,0,0
0,0,0,0,0,42,0,0,0,42,0,0,0,0,0
0,0,0,0,0,42,0,0,0,42,0,0,0,0,0
0,0,0,0,0,42,0,0,0,42,0,0,0,0,0
0,0,0,0,0,42,0,0,0,42,0,0,0,0,0
0,0,0,0,0,42,0,0,0,42,0,0,0,0,0
0,0,0,0,0,42,0,0,0,42,0,0,0,0,0
0,0,0,0,0,42,0,0,0,42,0,0,0,0,0
0,0,0,0,0,42,0,0,0,42,0,0,0,0,0
0,0,0,0,0,42,0,0,0,42,0,0,0,0,0
0,0,0,0,0,42,0,0,0,42,0,0,0,0,0
0,0,0,0,0,42,0,0,0,42,0,0,0,0,0
0,0,0,0,0,42,0,0,0,42,0,0,0,0,0
0,0,0,0,0,42,0,0,0,42,0,0,0,0,0
0,0,0,0,0,42,0,0,0,42,0,0,0,0,0
0,0,0,0,0,42,32,32,32,42,0,0,0,0,0
0,0,0,0,0,0,0,0,0,0,0,0,0,0,0
0,0,0,0,0,0,0,0,0,0,0,0,0,0,0
0,0,0,0,0,0,0,0,0,0,0,0,0,0,0
:endlayer
layer: 12
0,0,0,0,0,0,0,0,0,0,0,0,0,0,0
0,0,0,0,0,0,0,0,0,0,0,0,0,0,0
0,0,0,0,0,0,0,0,0,0,0,0,0,0,0
0,0,0,0,0,0,0,0,0,0,0,0,0,0,0
0,0,0,0,0,0,0,0,0,0,0,0,0,0,0
0,0,0,0,0,0,0,0,0,0,0,0,0,0,0
0,0,0,0,0,0,0,0,0,0,0,0,0,0,0
0,0,0,0,0,0,0,0,0,0,0,0,0,0,0
0,0,0,0,0,0,0,0,0,0,0,0,0,0,0
0,0,0,0,0,0,0,0,0,0,0,0,0,0,0
0,0,0,0,0,0,0,0,0,0,0,0,0,0,0
0,0,0,0,0,0,0,0,0,0,0,0,0,0,0
0,0,0,0,0,0,0,0,0,0,0,0,0,0,0
0,0,0,0,0,0,0,0,0,0,0,0,0,0,0
0,0,0,0,0,0,0,0,0,0,0,0,0,0,0
0,0,0,0,0,0,0,0,0,0,0,0,0,0,0
0,0,0,0,0,0,0,0,0,0,0,0,0,0,0
0,0,0,0,0,40,45,0,46,43,0,0,0,0,0
0,0,0,0,0,40,45,32,46,43,0,0,0,0,0
0,0,0,0,0,40,45,0,46,43,0,0,0,0,0
0,0,0,0,0,40,45,0,46,43,0,0,0,0,0
0,0,0,0,0,40,45,0,46,43,0,0,0,0,0
0,0,0,0,0,40,45,0,46,43,0,0,0,0,0
0,0,0,0,0,40,45,0,46,43,0,0,0,0,0
0,0,0,0,0,40,45,0,46,43,0,0,0,0,0
0,0,0,0,0,40,45,0,46,43,0,0,0,0,0
0,0,0,0,0,40,45,0,46,43,0,0,0,0,0
0,0,0,0,0,40,45,0,46,43,0,0,0,0,0
0,0,0,0,0,40,45,0,46,43,0,0,0,0,0
0,0,0,0,0,40,45,0,46,43,0,0,0,0,0
0,0,0,0,0,40,45,0,46,43,0,0,0,0,0
0,0,0,0,0,40,45,0,46,43,0,0,0,0,0
0,0,0,0,0,40,45,0,46,43,0,0,0,0,0
0,0,0,0,0,40,45,32,46,43,0,0,0,0,0
0,0,0,0,0,0,0,0,0,0,0,0,0,0,0
0,0,0,0,0,0,0,0,0,0,0,0,0,0,0
0,0,0,0,0,0,0,0,0,0,0,0,0,0,0
:endlayer
layer: 13
0,0,0,0,0,0,0,0,0,0,0,0,0,0,0
0,0,0,0,0,0,0,0,0,0,0,0,0,0,0
0,0,0,0,0,0,0,0,0,0,0,0,0,0,0
0,0,0,0,0,0,0,0,0,0,0,0,0,0,0
0,0,0,0,0,0,0,0,0,0,0,0,0,0,0
0,0,0,0,0,0,0,0,0,0,0,0,0,0,0
0,0,0,0,0,0,0,0,0,0,0,0,0,0,0
0,0,0,0,0,0,0,0,0,0,0,0,0,0,0
0,0,0,0,0,0,0,0,0,0,0,0,0,0,0
0,0,0,0,0,0,0,0,0,0,0,0,0,0,0
0,0,0,0,0,0,0,0,0,0,0,0,0,0,0
0,0,0,0,0,0,0,0,0,0,0,0,0,0,0
0,0,0,0,0,0,0,0,0,0,0,0,0,0,0
0,0,0,0,0,0,0,0,0,0,0,0,0,0,0
0,0,0,0,0,0,0,0,0,0,0,0,0,0,0
0,0,0,0,0,0,0,0,0,0,0,0,0,0,0
0,0,0,0,0,0,33,0,33,0,0,0,0,0,0
0,0,0,0,0,0,42,0,42,0,0,0,0,0,0
0,0,0,0,0,0,42,32,42,0,0,0,0,0,0
0,0,0,0,0,0,42,0,42,0,0,0,0,0,0
0,0,0,0,0,0,42,0,42,0,0,0,0,0,0
0,0,0,0,0,0,42,0,42,0,0,0,0,0,0
0,0,0,0,0,0,42,0,42,0,0,0,0,0,0
0,0,0,0,0,0,42,0,42,0,0,0,0,0,0
0,0,0,0,0,0,42,0,42,0,0,0,0,0,0
0,0,0,0,0,0,42,0,42,0,0,0,0,0,0
0,0,0,0,0,0,42,0,42,0,0,0,0,0,0
0,0,0,0,0,0,42,0,42,0,0,0,0,0,0
0,0,0,0,0,0,42,0,42,0,0,0,0,0,0
0,0,0,0,0,0,42,0,42,0,0,0,0,0,0
0,0,0,0,0,0,42,0,42,0,0,0,0,0,0
0,0,0,0,0,0,42,0,42,0,0,0,0,0,0
0,0,0,0,0,0,42,0,42,0,0,0,0,0,0
0,0,0,0,0,0,42,32,42,0,0,0,0,0,0
0,0,0,0,0,0,39,0,39,0,0,0,0,0,0
0,0,0,0,0,0,0,0,0,0,0,0,0,0,0
0,0,0,0,0,0,0,0,0,0,0,0,0,0,0
:endlayer
layer: 14
0,0,0,0,0,0,0,0,0,0,0,0,0,0,0
0,0,0,0,0,0,0,0,0,0,0,0,0,0,0
0,0,0,0,0,0,0,0,0,0,0,0,0,0,0
0,0,0,0,0,0,0,0,0,0,0,0,0,0,0
0,0,0,0,0,0,0,0,0,0,0,0,0,0,0
0,0,0,0,0,0,0,0,0,0,0,0,0,0,0
0,0,0,0,0,0,0,0,0,0,0,0,0,0,0
0,0,0,0,0,0,0,0,0,0,0,0,0,0,0
0,0,0,0,0,0,0,0,0,0,0,0,0,0,0
0,0,0,0,0,0,0,0,0,0,0,0,0,0,0
0,0,0,0,0,0,0,0,0,0,0,0,0,0,0
0,0,0,0,0,0,0,0,0,0,0,0,0,0,0
0,0,0,0,0,0,0,0,0,0,0,0,0,0,0
0,0,0,0,0,0,0,0,0,0,0,0,0,0,0
0,0,0,0,0,0,0,0,0,0,0,0,0,0,0
0,0,0,0,0,0,0,0,0,0,0,0,0,0,0
0,0,0,0,0,0,0,0,0,0,0,0,0,0,0
0,0,0,0,0,0,40,50,43,0,0,0,0,0,0
0,0,0,0,0,0,40,42,43,0,0,0,0,0,0
0,0,0,0,0,0,40,42,43,0,0,0,0,0,0
0,0,0,0,0,0,40,42,43,0,0,0,0,0,0
0,0,0,0,0,0,40,42,43,0,0,0,0,0,0
0,0,0,0,0,0,40,42,43,0,0,0,0,0,0
0,0,0,0,0,0,40,42,43,0,0,0,0,0,0
0,0,0,0,0,0,40,42,43,0,0,0,0,0,0
0,0,0,0,0,0,40,42,43,0,0,0,0,0,0
0,0,0,0,0,0,40,42,43,0,0,0,0,0,0
0,0,0,0,0,0,40,42,43,0,0,0,0,0,0
0,0,0,0,0,0,40,42,43,0,0,0,0,0,0
0,0,0,0,0,0,40,42,43,0,0,0,0,0,0
0,0,0,0,0,0,40,42,43,0,0,0,0,0,0
0,0,0,0,0,0,40,42,43,0,0,0,0,0,0
0,0,0,0,0,0,40,42,43,0,0,0,0,0,0
0,0,0,0,0,0,40,50,43,0,0,0,0,0,0
0,0,0,0,0,0,0,0,0,0,0,0,0,0,0
0,0,0,0,0,0,0,0,0,0,0,0,0,0,0
0,0,0,0,0,0,0,0,0,0,0,0,0,0,0
:endlayer
layer: 15
0,0,0,0,0,0,0,0,0,0,0,0,0,0,0
0,0,0,0,0,0,0,0,0,0,0,0,0,0,0
0,0,0,0,0,0,0,0,0,0,0,0,0,0,0
0,0,0,0,0,0,0,0,0,0,0,0,0,0,0
0,0,0,0,0,0,0,0,0,0,0,0,0,0,0
0,0,0,0,0,0,0,0,0,0,0,0,0,0,0
0,0,0,0,0,0,0,0,0,0,0,0,0,0,0
0,0,0,0,0,0,0,0,0,0,0,0,0,0,0
0,0,0,0,0,0,0,0,0,0,0,0,0,0,0
0,0,0,0,0,0,0,0,0,0,0,0,0,0,0
0,0,0,0,0,0,0,0,0,0,0,0,0,0,0
0,0,0,0,0,0,0,0,0,0,0,0,0,0,0
0,0,0,0,0,0,0,0,0,0,0,0,0,0,0
0,0,0,0,0,0,0,0,0,0,0,0,0,0,0
0,0,0,0,0,0,0,0,0,0,0,0,0,0,0
0,0,0,0,0,0,0,51,0,0,0,0,0,0,0
0,0,0,0,0,0,0,44,0,0,0,0,0,0,0
0,0,0,0,0,0,0,52,0,0,0,0,0,0,0
0,0,0,0,0,0,0,52,0,0,0,0,0,0,0
0,0,0,0,0,0,0,52,0,0,0,0,0,0,0
0,0,0,0,0,0,0,52,0,0,0,0,0,0,0
0,0,0,0,0,0,0,52,0,0,0,0,0,0,0
0,0,0,0,0,0,0,52,0,0,0,0,0,0,0
0,0,0,0,0,0,0,52,0,0,0,0,0,0,0
0,0,0,0,0,0,0,52,0,0,0,0,0,0,0
0,0,0,0,0,0,0,52,0,0,0,0,0,0,0
0,0,0,0,0,0,0,52,0,0,0,0,0,0,0
0,0,0,0,0,0,0,52,0,0,0,0,0,0,0
0,0,0,0,0,0,0,52,0,0,0,0,0,0,0
0,0,0,0,0,0,0,52,0,0,0,0,0,0,0
0,0,0,0,0,0,0,52,0,0,0,0,0,0,0
0,0,0,0,0,0,0,52,0,0,0,0,0,0,0
0,0,0,0,0,0,0,52,0,0,0,0,0,0,0
0,0,0,0,0,0,0,52,0,0,0,0,0,0,0
0,0,0,0,0,0,0,52,0,0,0,0,0,0,0
0,0,0,0,0,0,0,53,0,0,0,0,0,0,0
0,0,0,0,0,0,0,0,0,0,0,0,0,0,0
:endlayer
layer: 16
0,0,0,0,0,0,0,0,0,0,0,0,0,0,0
0,0,0,0,0,0,0,0,0,0,0,0,0,0,0
0,0,0,0,0,0,0,0,0,0,0,0,0,0,0
0,0,0,0,0,0,0,0,0,0,0,0,0,0,0
0,0,0,0,0,0,0,0,0,0,0,0,0,0,0
0,0,0,0,0,0,0,0,0,0,0,0,0,0,0
0,0,0,0,0,0,0,0,0,0,0,0,0,0,0
0,0,0,0,0,0,0,0,0,0,0,0,0,0,0
0,0,0,0,0,0,0,0,0,0,0,0,0,0,0
0,0,0,0,0,0,0,0,0,0,0,0,0,0,0
0,0,0,0,0,0,0,0,0,0,0,0,0,0,0
0,0,0,0,0,0,0,0,0,0,0,0,0,0,0
0,0,0,0,0,0,0,0,0,0,0,0,0,0,0
0,0,0,0,0,0,0,0,0,0,0,0,0,0,0
0,0,0,0,0,0,0,51,0,0,0,0,0,0,0
0,0,0,0,0,0,0,44,0,0,0,0,0,0,0
0,0,0,0,0,0,0,0,0,0,0,0,0,0,0
0,0,0,0,0,0,0,0,0,0,0,0,0,0,0
0,0,0,0,0,0,0,0,0,0,0,0,0,0,0
0,0,0,0,0,0,0,0,0,0,0,0,0,0,0
0,0,0,0,0,0,0,0,0,0,0,0,0,0,0
0,0,0,0,0,0,0,0,0,0,0,0,0,0,0
0,0,0,0,0,0,0,0,0,0,0,0,0,0,0
0,0,0,0,0,0,0,0,0,0,0,0,0,0,0
0,0,0,0,0,0,0,0,0,0,0,0,0,0,0
0,0,0,0,0,0,0,0,0,0,0,0,0,0,0
0,0,0,0,0,0,0,0,0,0,0,0,0,0,0
0,0,0,0,0,0,0,0,0,0,0,0,0,0,0
0,0,0,0,0,0,0,0,0,0,0,0,0,0,0
0,0,0,0,0,0,0,0,0,0,0,0,0,0,0
0,0,0,0,0,0,0,0,0,0,0,0,0,0,0
0,0,0,0,0,0,0,0,0,0,0,0,0,0,0
0,0,0,0,0,0,0,0,0,0,0,0,0,0,0
0,0,0,0,0,0,0,0,0,0,0,0,0,0,0
0,0,0,0,0,0,0,0,0,0,0,0,0,0,0
0,0,0,0,0,0,0,41,0,0,0,0,0,0,0
0,0,0,0,0,0,0,53,0,0,0,0,0,0,0
:endlayer
layer: 17
0,0,0,0,0,0,0,0,0,0,0,0,0,0,0
0,0,0,0,0,0,0,0,0,0,0,0,0,0,0
0,0,0,0,0,0,0,0,0,0,0,0,0,0,0
0,0,0,0,0,0,0,0,0,0,0,0,0,0,0
0,0,0,0,0,0,0,0,0,0,0,0,0,0,0
0,0,0,0,0,0,0,0,0,0,0,0,0,0,0
0,0,0,0,0,0,0,0,0,0,0,0,0,0,0
0,0,0,0,0,0,0,0,0,0,0,0,0,0,0
0,0,0,0,0,0,0,0,0,0,0,0,0,0,0
0,0,0,0,0,0,0,0,0,0,0,0,0,0,0
0,0,0,0,0,0,0,0,0,0,0,0,0,0,0
0,0,0,0,0,0,0,0,0,0,0,0,0,0,0
0,0,0,0,0,0,0,0,0,0,0,0,0,0,0
0,0,0,0,0,0,0,0,0,0,0,0,0,0,0
0,0,0,0,0,0,0,0,0,0,0,0,0,0,0
0,0,0,0,0,0,0,0,0,0,0,0,0,0,0
0,0,0,0,0,0,0,0,0,0,0,0,0,0,0
0,0,0,0,0,0,0,0,0,0,0,0,0,0,0
0,0,0,0,0,0,0,0,0,0,0,0,0,0,0
0,0,0,0,0,0,0,0,0,0,0,0,0,0,0
0,0,0,0,0,0,0,0,0,0,0,0,0,0,0
0,0,0,0,0,0,0,0,0,0,0,0,0,0,0
0,0,0,0,0,0,0,0,0,0,0,0,0,0,0
0,0,0,0,0,0,0,0,0,0,0,0,0,0,0
0,0,0,0,0,0,0,0,0,0,0,0,0,0,0
0,0,0,0,0,0,0,0,0,0,0,0,0,0,0
0,0,0,0,0,0,0,0,0,0,0,0,0,0,0
0,0,0,0,0,0,0,0,0,0,0,0,0,0,0
0,0,0,0,0,0,0,0,0,0,0,0,0,0,0
0,0,0,0,0,0,0,0,0,0,0,0,0,0,0
0,0,0,0,0,0,0,0,0,0,0,0,0,0,0
0,0,0,0,0,0,0,0,0,0,0,0,0,0,0
0,0,0,0,0,0,0,0,0,0,0,0,0,0,0
0,0,0,0,0,0,0,0,0,0,0,0,0,0,0
0,0,0,0,0,0,0,0,0,0,0,0,0,0,0
0,0,0,0,0,0,0,0,0,0,0,0,0,0,0
0,0,0,0,0,0,0,0,0,0,0,0,0,0,0
:endlayer
layer: 18
0,0,0,0,0,0,0,0,0,0,0,0,0,0,0
0,0,0,0,0,0,0,0,0,0,0,0,0,0,0
0,0,0,0,0,0,0,0,0,0,0,0,0,0,0
0,0,0,0,0,0,0,0,0,0,0,0,0,0,0
0,0,0,0,0,0,0,0,0,0,0,0,0,0,0
0,0,0,0,0,0,0,0,0,0,0,0,0,0,0
0,0,0,0,0,0,0,0,0,0,0,0,0,0,0
0,0,0,0,0,0,0,0,0,0,0,0,0,0,0
0,0,0,0,0,0,0,0,0,0,0,0,0,0,0
0,0,0,0,0,0,0,0,0,0,0,0,0,0,0
0,0,0,0,0,0,0,0,0,0,0,0,0,0,0
0,0,0,0,0,0,0,0,0,0,0,0,0,0,0
0,0,0,0,0,0,0,0,0,0,0,0,0,0,0
0,0,0,0,0,0,0,0,0,0,0,0,0,0,0
0,0,0,0,0,0,0,0,0,0,0,0,0,0,0
0,0,0,0,0,0,0,0,0,0,0,0,0,0,0
0,0,0,0,0,0,0,0,0,0,0,0,0,0,0
0,0,0,0,0,0,0,0,0,0,0,0,0,0,0
0,0,0,0,0,0,0,0,0,0,0,0,0,0,0
0,0,0,0,0,0,0,0,0,0,0,0,0,0,0
0,0,0,0,0,0,0,0,0,0,0,0,0,0,0
0,0,0,0,0,0,0,0,0,0,0,0,0,0,0
0,0,0,0,0,0,0,0,0,0,0,0,0,0,0
0,0,0,0,0,0,0,0,0,0,0,0,0,0,0
0,0,0,0,0,0,0,0,0,0,0,0,0,0,0
0,0,0,0,0,0,0,0,0,0,0,0,0,0,0
0,0,0,0,0,0,0,0,0,0,0,0,0,0,0
0,0,0,0,0,0,0,0,0,0,0,0,0,0,0
0,0,0,0,0,0,0,0,0,0,0,0,0,0,0
0,0,0,0,0,0,0,0,0,0,0,0,0,0,0
0,0,0,0,0,0,0,0,0,0,0,0,0,0,0
0,0,0,0,0,0,0,0,0,0,0,0,0,0,0
0,0,0,0,0,0,0,0,0,0,0,0,0,0,0
0,0,0,0,0,0,0,0,0,0,0,0,0,0,0
0,0,0,0,0,0,0,0,0,0,0,0,0,0,0
0,0,0,0,0,0,0,0,0,0,0,0,0,0,0
0,0,0,0,0,0,0,0,0,0,0,0,0,0,0
:endlayer
layer: 19
0,0,0,0,0,0,0,0,0,0,0,0,0,0,0
0,0,0,0,0,0,0,0,0,0,0,0,0,0,0
0,0,0,0,0,0,0,0,0,0,0,0,0,0,0
0,0,0,0,0,0,0,0,0,0,0,0,0,0,0
0,0,0,0,0,0,0,0,0,0,0,0,0,0,0
0,0,0,0,0,0,0,0,0,0,0,0,0,0,0
0,0,0,0,0,0,0,0,0,0,0,0,0,0,0
0,0,0,0,0,0,0,0,0,0,0,0,0,0,0
0,0,0,0,0,0,0,0,0,0,0,0,0,0,0
0,0,0,0,0,0,0,0,0,0,0,0,0,0,0
0,0,0,0,0,0,0,0,0,0,0,0,0,0,0
0,0,0,0,0,0,0,0,0,0,0,0,0,0,0
0,0,0,0,0,0,0,0,0,0,0,0,0,0,0
0,0,0,0,0,0,0,0,0,0,0,0,0,0,0
0,0,0,0,0,0,0,0,0,0,0,0,0,0,0
0,0,0,0,0,0,0,0,0,0,0,0,0,0,0
0,0,0,0,0,0,0,0,0,0,0,0,0,0,0
0,0,0,0,0,0,0,0,0,0,0,0,0,0,0
0,0,0,0,0,0,0,0,0,0,0,0,0,0,0
0,0,0,0,0,0,0,0,0,0,0,0,0,0,0
0,0,0,0,0,0,0,0,0,0,0,0,0,0,0
0,0,0,0,0,0,0,0,0,0,0,0,0,0,0
0,0,0,0,0,0,0,0,0,0,0,0,0,0,0
0,0,0,0,0,0,0,0,0,0,0,0,0,0,0
0,0,0,0,0,0,0,0,0,0,0,0,0,0,0
0,0,0,0,0,0,0,0,0,0,0,0,0,0,0
0,0,0,0,0,0,0,0,0,0,0,0,0,0,0
0,0,0,0,0,0,0,0,0,0,0,0,0,0,0
0,0,0,0,0,0,0,0,0,0,0,0,0,0,0
0,0,0,0,0,0,0,0,0,0,0,0,0,0,0
0,0,0,0,0,0,0,0,0,0,0,0,0,0,0
0,0,0,0,0,0,0,0,0,0,0,0,0,0,0
0,0,0,0,0,0,0,0,0,0,0,0,0,0,0
0,0,0,0,0,0,0,0,0,0,0,0,0,0,0
0,0,0,0,0,0,0,0,0,0,0,0,0,0,0
0,0,0,0,0,0,0,0,0,0,0,0,0,0,0
0,0,0,0,0,0,0,0,0,0,0,0,0,0,0
:endlayer
layer: 20
0,0,0,0,0,0,0,0,0,0,0,0,0,0,0
0,0,0,0,0,0,0,0,0,0,0,0,0,0,0
0,0,0,0,0,0,0,0,0,0,0,0,0,0,0
0,0,0,0,0,0,0,0,0,0,0,0,0,0,0
0,0,0,0,0,0,0,0,0,0,0,0,0,0,0
0,0,0,0,0,0,0,0,0,0,0,0,0,0,0
0,0,0,0,0,0,0,0,0,0,0,0,0,0,0
0,0,0,0,0,0,0,0,0,0,0,0,0,0,0
0,0,0,0,0,0,0,0,0,0,0,0,0,0,0
0,0,0,0,0,0,0,0,0,0,0,0,0,0,0
0,0,0,0,0,0,0,0,0,0,0,0,0,0,0
0,0,0,0,0,0,0,0,0,0,0,0,0,0,0
0,0,0,0,0,0,0,0,0,0,0,0,0,0,0
0,0,0,0,0,0,0,0,0,0,0,0,0,0,0
0,0,0,0,0,0,0,0,0,0,0,0,0,0,0
0,0,0,0,0,0,0,0,0,0,0,0,0,0,0
0,0,0,0,0,0,0,0,0,0,0,0,0,0,0
0,0,0,0,0,0,0,0,0,0,0,0,0,0,0
0,0,0,0,0,0,0,0,0,0,0,0,0,0,0
0,0,0,0,0,0,0,0,0,0,0,0,0,0,0
0,0,0,0,0,0,0,0,0,0,0,0,0,0,0
0,0,0,0,0,0,0,0,0,0,0,0,0,0,0
0,0,0,0,0,0,0,0,0,0,0,0,0,0,0
0,0,0,0,0,0,0,0,0,0,0,0,0,0,0
0,0,0,0,0,0,0,0,0,0,0,0,0,0,0
0,0,0,0,0,0,0,0,0,0,0,0,0,0,0
0,0,0,0,0,0,0,0,0,0,0,0,0,0,0
0,0,0,0,0,0,0,0,0,0,0,0,0,0,0
0,0,0,0,0,0,0,0,0,0,0,0,0,0,0
0,0,0,0,0,0,0,0,0,0,0,0,0,0,0
0,0,0,0,0,0,0,0,0,0,0,0,0,0,0
0,0,0,0,0,0,0,0,0,0,0,0,0,0,0
0,0,0,0,0,0,0,0,0,0,0,0,0,0,0
0,0,0,0,0,0,0,0,0,0,0,0,0,0,0
0,0,0,0,0,0,0,0,0,0,0,0,0,0,0
0,0,0,0,0,0,0,0,0,0,0,0,0,0,0
0,0,0,0,0,0,0,0,0,0,0,0,0,0,0
:endlayer
layer: 21
0,0,0,0,0,0,0,0,0,0,0,0,0,0,0
0,0,0,0,0,0,0,0,0,0,0,0,0,0,0
0,0,0,0,0,0,0,0,0,0,0,0,0,0,0
0,0,0,0,0,0,0,0,0,0,0,0,0,0,0
0,0,0,0,0,0,0,0,0,0,0,0,0,0,0
0,0,0,0,0,0,0,0,0,0,0,0,0,0,0
0,0,0,0,0,0,0,0,0,0,0,0,0,0,0
0,0,0,0,0,0,0,0,0,0,0,0,0,0,0
0,0,0,0,0,0,0,0,0,0,0,0,0,0,0
0,0,0,0,0,0,0,0,0,0,0,0,0,0,0
0,0,0,0,0,0,0,0,0,0,0,0,0,0,0
0,0,0,0,0,0,0,0,0,0,0,0,0,0,0
0,0,0,0,0,0,0,0,0,0,0,0,0,0,0
0,0,0,0,0,0,0,0,0,0,0,0,0,0,0
0,0,0,0,0,0,0,0,0,0,0,0,0,0,0
0,0,0,0,0,0,0,0,0,0,0,0,0,0,0
0,0,0,0,0,0,0,0,0,0,0,0,0,0,0
0,0,0,0,0,0,0,0,0,0,0,0,0,0,0
0,0,0,0,0,0,0,0,0,0,0,0,0,0,0
0,0,0,0,0,0,0,0,0,0,0,0,0,0,0
0,0,0,0,0,0,0,0,0,0,0,0,0,0,0
0,0,0,0,0,0,0,0,0,0,0,0,0,0,0
0,0,0,0,0,0,0,0,0,0,0,0,0,0,0
0,0,0,0,0,0,0,0,0,0,0,0,0,0,0
0,0,0,0,0,0,0,0,0,0,0,0,0,0,0
0,0,0,0,0,0,0,0,0,0,0,0,0,0,0
0,0,0,0,0,0,0,0,0,0,0,0,0,0,0
0,0,0,0,0,0,0,0,0,0,0,0,0,0,0
0,0,0,0,0,0,0,0,0,0,0,0,0,0,0
0,0,0,0,0,0,0,0,0,0,0,0,0,0,0
0,0,0,0,0,0,0,0,0,0,0,0,0,0,0
0,0,0,0,0,0,0,0,0,0,0,0,0,0,0
0,0,0,0,0,0,0,0,0,0,0,0,0,0,0
0,0,0,0,0,0,0,0,0,0,0,0,0,0,0
0,0,0,0,0,0,0,0,0,0,0,0,0,0,0
0,0,0,0,0,0,0,0,0,0,0,0,0,0,0
0,0,0,0,0,0,0,0,0,0,0,0,0,0,0
:endlayer
layer: 22
0,0,0,0,0,0,0,0,0,0,0,0,0,0,0
0,0,0,0,0,0,0,0,0,0,0,0,0,0,0
0,0,0,0,0,0,0,0,0,0,0,0,0,0,0
0,0,0,0,0,0,0,0,0,0,0,0,0,0,0
0,0,0,0,0,0,0,0,0,0,0,0,0,0,0
0,0,0,0,0,0,0,0,0,0,0,0,0,0,0
0,0,0,0,0,0,0,0,0,0,0,0,0,0,0
0,0,0,0,0,0,0,0,0,0,0,0,0,0,0
0,0,0,0,0,0,0,0,0,0,0,0,0,0,0
0,0,0,0,0,0,0,0,0,0,0,0,0,0,0
0,0,0,0,0,0,0,0,0,0,0,0,0,0,0
0,0,0,0,0,0,0,0,0,0,0,0,0,0,0
0,0,0,0,0,0,0,0,0,0,0,0,0,0,0
0,0,0,0,0,0,0,0,0,0,0,0,0,0,0
0,0,0,0,0,0,0,0,0,0,0,0,0,0,0
0,0,0,0,0,0,0,0,0,0,0,0,0,0,0
0,0,0,0,0,0,0,0,0,0,0,0,0,0,0
0,0,0,0,0,0,0,0,0,0,0,0,0,0,0
0,0,0,0,0,0,0,0,0,0,0,0,0,0,0
0,0,0,0,0,0,0,0,0,0,0,0,0,0,0
0,0,0,0,0,0,0,0,0,0,0,0,0,0,0
0,0,0,0,0,0,0,0,0,0,0,0,0,0,0
0,0,0,0,0,0,0,0,0,0,0,0,0,0,0
0,0,0,0,0,0,0,0,0,0,0,0,0,0,0
0,0,0,0,0,0,0,0,0,0,0,0,0,0,0
0,0,0,0,0,0,0,0,0,0,0,0,0,0,0
0,0,0,0,0,0,0,0,0,0,0,0,0,0,0
0,0,0,0,0,0,0,0,0,0,0,0,0,0,0
0,0,0,0,0,0,0,0,0,0,0,0,0,0,0
0,0,0,0,0,0,0,0,0,0,0,0,0,0,0
0,0,0,0,0,0,0,0,0,0,0,0,0,0,0
0,0,0,0,0,0,0,0,0,0,0,0,0,0,0
0,0,0,0,0,0,0,0,0,0,0,0,0,0,0
0,0,0,0,0,0,0,0,0,0,0,0,0,0,0
0,0,0,0,0,0,0,0,0,0,0,0,0,0,0
0,0,0,0,0,0,0,0,0,0,0,0,0,0,0
0,0,0,0,0,0,0,0,0,0,0,0,0,0,0
:endlayer
layer: 23
0,0,0,0,0,0,0,0,0,0,0,0,0,0,0
0,0,0,0,0,0,0,0,0,0,0,0,0,0,0
0,0,0,0,0,0,0,0,0,0,0,0,0,0,0
0,0,0,0,0,0,0,0,0,0,0,0,0,0,0
0,0,0,0,0,0,0,0,0,0,0,0,0,0,0
0,0,0,0,0,0,0,0,0,0,0,0,0,0,0
0,0,0,0,0,0,0,0,0,0,0,0,0,0,0
0,0,0,0,0,0,0,0,0,0,0,0,0,0,0
0,0,0,0,0,0,0,0,0,0,0,0,0,0,0
0,0,0,0,0,0,0,0,0,0,0,0,0,0,0
0,0,0,0,0,0,0,0,0,0,0,0,0,0,0
0,0,0,0,0,0,0,0,0,0,0,0,0,0,0
0,0,0,0,0,0,0,0,0,0,0,0,0,0,0
0,0,0,0,0,0,0,0,0,0,0,0,0,0,0
0,0,0,0,0,0,0,0,0,0,0,0,0,0,0
0,0,0,0,0,0,0,0,0,0,0,0,0,0,0
0,0,0,0,0,0,0,0,0,0,0,0,0,0,0
0,0,0,0,0,0,0,0,0,0,0,0,0,0,0
0,0,0,0,0,0,0,0,0,0,0,0,0,0,0
0,0,0,0,0,0,0,0,0,0,0,0,0,0,0
0,0,0,0,0,0,0,0,0,0,0,0,0,0,0
0,0,0,0,0,0,0,0,0,0,0,0,0,0,0
0,0,0,0,0,0,0,0,0,0,0,0,0,0,0
0,0,0,0,0,0,0,0,0,0,0,0,0,0,0
0,0,0,0,0,0,0,0,0,0,0,0,0,0,0
0,0,0,0,0,0,0,0,0,0,0,0,0,0,0
0,0,0,0,0,0,0,0,0,0,0,0,0,0,0
0,0,0,0,0,0,0,0,0,0,0,0,0,0,0
0,0,0,0,0,0,0,0,0,0,0,0,0,0,0
0,0,0,0,0,0,0,0,0,0,0,0,0,0,0
0,0,0,0,0,0,0,0,0,0,0,0,0,0,0
0,0,0,0,0,0,0,0,0,0,0,0,0,0,0
0,0,0,0,0,0,0,0,0,0,0,0,0,0,0
0,0,0,0,0,0,0,0,0,0,0,0,0,0,0
0,0,0,0,0,0,0,0,0,0,0,0,0,0,0
0,0,0,0,0,0,0,0,0,0,0,0,0,0,0
0,0,0,0,0,0,0,0,0,0,0,0,0,0,0
:endlayer
layer: 24
0,0,0,0,0,0,0,0,0,0,0,0,0,0,0
0,0,0,0,0,0,0,0,0,0,0,0,0,0,0
0,0,0,0,0,0,0,0,0,0,0,0,0,0,0
0,0,0,0,0,0,0,0,0,0,0,0,0,0,0
0,0,0,0,0,0,0,0,0,0,0,0,0,0,0
0,0,0,0,0,0,0,0,0,0,0,0,0,0,0
0,0,0,0,0,0,0,0,0,0,0,0,0,0,0
0,0,0,0,0,0,0,0,0,0,0,0,0,0,0
0,0,0,0,0,0,0,0,0,0,0,0,0,0,0
0,0,0,0,0,0,0,0,0,0,0,0,0,0,0
0,0,0,0,0,0,0,0,0,0,0,0,0,0,0
0,0,0,0,0,0,0,0,0,0,0,0,0,0,0
0,0,0,0,0,0,0,0,0,0,0,0,0,0,0
0,0,0,0,0,0,0,0,0,0,0,0,0,0,0
0,0,0,0,0,0,0,0,0,0,0,0,0,0,0
0,0,0,0,0,0,0,0,0,0,0,0,0,0,0
0,0,0,0,0,0,0,0,0,0,0,0,0,0,0
0,0,0,0,0,0,0,0,0,0,0,0,0,0,0
0,0,0,0,0,0,0,0,0,0,0,0,0,0,0
0,0,0,0,0,0,0,0,0,0,0,0,0,0,0
0,0,0,0,0,0,0,0,0,0,0,0,0,0,0
0,0,0,0,0,0,0,0,0,0,0,0,0,0,0
0,0,0,0,0,0,0,0,0,0,0,0,0,0,0
0,0,0,0,0,0,0,0,0,0,0,0,0,0,0
0,0,0,0,0,0,0,0,0,0,0,0,0,0,0
0,0,0,0,0,0,0,0,0,0,0,0,0,0,0
0,0,0,0,0,0,0,0,0,0,0,0,0,0,0
0,0,0,0,0,0,0,0,0,0,0,0,0,0,0
0,0,0,0,0,0,0,0,0,0,0,0,0,0,0
0,0,0,0,0,0,0,0,0,0,0,0,0,0,0
0,0,0,0,0,0,0,0,0,0,0,0,0,0,0
0,0,0,0,0,0,0,0,0,0,0,0,0,0,0
0,0,0,0,0,0,0,0,0,0,0,0,0,0,0
0,0,0,0,0,0,0,0,0,0,0,0,0,0,0
0,0,0,0,0,0,0,0,0,0,0,0,0,0,0
0,0,0,0,0,0,0,0,0,0,0,0,0,0,0
0,0,0,0,0,0,0,0,0,0,0,0,0,0,0
:endlayer
layer: 25
0,0,0,0,0,0,0,0,0,0,0,0,0,0,0
0,0,0,0,0,0,0,0,0,0,0,0,0,0,0
0,0,0,0,0,0,0,0,0,0,0,0,0,0,0
0,0,0,0,0,0,0,0,0,0,0,0,0,0,0
0,0,0,0,0,0,0,0,0,0,0,0,0,0,0
0,0,0,0,0,0,0,0,0,0,0,0,0,0,0
0,0,0,0,0,0,0,0,0,0,0,0,0,0,0
0,0,0,0,0,0,0,0,0,0,0,0,0,0,0
0,0,0,0,0,0,0,0,0,0,0,0,0,0,0
0,0,0,0,0,0,0,0,0,0,0,0,0,0,0
0,0,0,0,0,0,0,0,0,0,0,0,0,0,0
0,0,0,0,0,0,0,0,0,0,0,0,0,0,0
0,0,0,0,0,0,0,0,0,0,0,0,0,0,0
0,0,0,0,0,0,0,0,0,0,0,0,0,0,0
0,0,0,0,0,0,0,0,0,0,0,0,0,0,0
0,0,0,0,0,0,0,0,0,0,0,0,0,0,0
0,0,0,0,0,0,0,0,0,0,0,0,0,0,0
0,0,0,0,0,0,0,0,0,0,0,0,0,0,0
0,0,0,0,0,0,0,0,0,0,0,0,0,0,0
0,0,0,0,0,0,0,0,0,0,0,0,0,0,0
0,0,0,0,0,0,0,0,0,0,0,0,0,0,0
0,0,0,0,0,0,0,0,0,0,0,0,0,0,0
0,0,0,0,0,0,0,0,0,0,0,0,0,0,0
0,0,0,0,0,0,0,0,0,0,0,0,0,0,0
0,0,0,0,0,0,0,0,0,0,0,0,0,0,0
0,0,0,0,0,0,0,0,0,0,0,0,0,0,0
0,0,0,0,0,0,0,0,0,0,0,0,0,0,0
0,0,0,0,0,0,0,0,0,0,0,0,0,0,0
0,0,0,0,0,0,0,0,0,0,0,0,0,0,0
0,0,0,0,0,0,0,0,0,0,0,0,0,0,0
0,0,0,0,0,0,0,0,0,0,0,0,0,0,0
0,0,0,0,0,0,0,0,0,0,0,0,0,0,0
0,0,0,0,0,0,0,0,0,0,0,0,0,0,0
0,0,0,0,0,0,0,0,0,0,0,0,0,0,0
0,0,0,0,0,0,0,0,0,0,0,0,0,0,0
0,0,0,0,0,0,0,0,0,0,0,0,0,0,0
0,0,0,0,0,0,0,0,0,0,0,0,0,0,0
:endlayer
layer: 26
0,0,0,0,0,0,0,0,0,0,0,0,0,0,0
0,0,0,0,0,0,0,0,0,0,0,0,0,0,0
0,0,0,0,0,0,0,0,0,0,0,0,0,0,0
0,0,0,0,0,0,0,0,0,0,0,0,0,0,0
0,0,0,0,0,0,0,0,0,0,0,0,0,0,0
0,0,0,0,0,0,0,0,0,0,0,0,0,0,0
0,0,0,0,0,0,0,0,0,0,0,0,0,0,0
0,0,0,0,0,0,0,0,0,0,0,0,0,0,0
0,0,0,0,0,0,0,0,0,0,0,0,0,0,0
0,0,0,0,0,0,0,0,0,0,0,0,0,0,0
0,0,0,0,0,0,0,0,0,0,0,0,0,0,0
0,0,0,0,0,0,0,0,0,0,0,0,0,0,0
0,0,0,0,0,0,0,0,0,0,0,0,0,0,0
0,0,0,0,0,0,0,0,0,0,0,0,0,0,0
0,0,0,0,0,0,0,0,0,0,0,0,0,0,0
0,0,0,0,0,0,0,0,0,0,0,0,0,0,0
0,0,0,0,0,0,0,0,0,0,0,0,0,0,0
0,0,0,0,0,0,0,0,0,0,0,0,0,0,0
0,0,0,0,0,0,0,0,0,0,0,0,0,0,0
0,0,0,0,0,0,0,0,0,0,0,0,0,0,0
0,0,0,0,0,0,0,0,0,0,0,0,0,0,0
0,0,0,0,0,0,0,0,0,0,0,0,0,0,0
0,0,0,0,0,0,0,0,0,0,0,0,0,0,0
0,0,0,0,0,0,0,0,0,0,0,0,0,0,0
0,0,0,0,0,0,0,0,0,0,0,0,0,0,0
0,0,0,0,0,0,0,0,0,0,0,0,0,0,0
0,0,0,0,0,0,0,0,0,0,0,0,0,0,0
0,0,0,0,0,0,0,0,0,0,0,0,0,0,0
0,0,0,0,0,0,0,0,0,0,0,0,0,0,0
0,0,0,0,0,0,0,0,0,0,0,0,0,0,0
0,0,0,0,0,0,0,0,0,0,0,0,0,0,0
0,0,0,0,0,0,0,0,0,0,0,0,0,0,0
0,0,0,0,0,0,0,0,0,0,0,0,0,0,0
0,0,0,0,0,0,0,0,0,0,0,0,0,0,0
0,0,0,0,0,0,0,0,0,0,0,0,0,0,0
0,0,0,0,0,0,0,0,0,0,0,0,0,0,0
0,0,0,0,0,0,0,0,0,0,0,0,0,0,0
:endlayer
layer: 27
0,0,0,0,0,0,0,0,0,0,0,0,0,0,0
0,0,0,0,0,0,0,0,0,0,0,0,0,0,0
0,0,0,0,0,0,0,0,0,0,0,0,0,0,0
0,0,0,0,0,0,0,0,0,0,0,0,0,0,0
0,0,0,0,0,0,0,0,0,0,0,0,0,0,0
0,0,0,0,0,0,0,0,0,0,0,0,0,0,0
0,0,0,0,0,0,0,0,0,0,0,0,0,0,0
0,0,0,0,0,0,0,0,0,0,0,0,0,0,0
0,0,0,0,0,0,0,0,0,0,0,0,0,0,0
0,0,0,0,0,0,0,0,0,0,0,0,0,0,0
0,0,0,0,0,0,0,0,0,0,0,0,0,0,0
0,0,0,0,0,0,0,0,0,0,0,0,0,0,0
0,0,0,0,0,0,0,0,0,0,0,0,0,0,0
0,0,0,0,0,0,0,0,0,0,0,0,0,0,0
0,0,0,0,0,0,0,0,0,0,0,0,0,0,0
0,0,0,0,0,0,0,0,0,0,0,0,0,0,0
0,0,0,0,0,0,0,0,0,0,0,0,0,0,0
0,0,0,0,0,0,0,0,0,0,0,0,0,0,0
0,0,0,0,0,0,0,0,0,0,0,0,0,0,0
0,0,0,0,0,0,0,0,0,0,0,0,0,0,0
0,0,0,0,0,0,0,0,0,0,0,0,0,0,0
0,0,0,0,0,0,0,0,0,0,0,0,0,0,0
0,0,0,0,0,0,0,0,0,0,0,0,0,0,0
0,0,0,0,0,0,0,0,0,0,0,0,0,0,0
0,0,0,0,0,0,0,0,0,0,0,0,0,0,0
0,0,0,0,0,0,0,0,0,0,0,0,0,0,0
0,0,0,0,0,0,0,0,0,0,0,0,0,0,0
0,0,0,0,0,0,0,0,0,0,0,0,0,0,0
0,0,0,0,0,0,0,0,0,0,0,0,0,0,0
0,0,0,0,0,0,0,0,0,0,0,0,0,0,0
0,0,0,0,0,0,0,0,0,0,0,0,0,0,0
0,0,0,0,0,0,0,0,0,0,0,0,0,0,0
0,0,0,0,0,0,0,0,0,0,0,0,0,0,0
0,0,0,0,0,0,0,0,0,0,0,0,0,0,0
0,0,0,0,0,0,0,0,0,0,0,0,0,0,0
0,0,0,0,0,0,0,0,0,0,0,0,0,0,0
0,0,0,0,0,0,0,0,0,0,0,0,0,0,0
:endlayer
layer: 28
0,0,0,0,0,0,0,0,0,0,0,0,0,0,0
0,0,0,0,0,0,0,0,0,0,0,0,0,0,0
0,0,0,0,0,0,0,0,0,0,0,0,0,0,0
0,0,0,0,0,0,0,0,0,0,0,0,0,0,0
0,0,0,0,0,0,0,0,0,0,0,0,0,0,0
0,0,0,0,0,0,0,0,0,0,0,0,0,0,0
0,0,0,0,0,0,0,0,0,0,0,0,0,0,0
0,0,0,0,0,0,0,0,0,0,0,0,0,0,0
0,0,0,0,0,0,0,0,0,0,0,0,0,0,0
0,0,0,0,0,0,0,0,0,0,0,0,0,0,0
0,0,0,0,0,0,0,0,0,0,0,0,0,0,0
0,0,0,0,0,0,0,0,0,0,0,0,0,0,0
0,0,0,0,0,0,0,0,0,0,0,0,0,0,0
0,0,0,0,0,0,0,0,0,0,0,0,0,0,0
0,0,0,0,0,0,0,0,0,0,0,0,0,0,0
0,0,0,0,0,0,0,0,0,0,0,0,0,0,0
0,0,0,0,0,0,0,0,0,0,0,0,0,0,0
0,0,0,0,0,0,0,0,0,0,0,0,0,0,0
0,0,0,0,0,0,0,0,0,0,0,0,0,0,0
0,0,0,0,0,0,0,0,0,0,0,0,0,0,0
0,0,0,0,0,0,0,0,0,0,0,0,0,0,0
0,0,0,0,0,0,0,0,0,0,0,0,0,0,0
0,0,0,0,0,0,0,0,0,0,0,0,0,0,0
0,0,0,0,0,0,0,0,0,0,0,0,0,0,0
0,0,0,0,0,0,0,0,0,0,0,0,0,0,0
0,0,0,0,0,0,0,0,0,0,0,0,0,0,0
0,0,0,0,0,0,0,0,0,0,0,0,0,0,0
0,0,0,0,0,0,0,0,0,0,0,0,0,0,0
0,0,0,0,0,0,0,0,0,0,0,0,0,0,0
0,0,0,0,0,0,0,0,0,0,0,0,0,0,0
0,0,0,0,0,0,0,0,0,0,0,0,0,0,0
0,0,0,0,0,0,0,0,0,0,0,0,0,0,0
0,0,0,0,0,0,0,0,0,0,0,0,0,0,0
0,0,0,0,0,0,0,0,0,0,0,0,0,0,0
0,0,0,0,0,0,0,0,0,0,0,0,0,0,0
0,0,0,0,0,0,0,0,0,0,0,0,0,0,0
0,0,0,0,0,0,0,0,0,0,0,0,0,0,0
:endlayer
layer: 29
0,0,0,0,0,0,0,0,0,0,0,0,0,0,0
0,0,0,0,0,0,0,0,0,0,0,0,0,0,0
0,0,0,0,0,0,0,0,0,0,0,0,0,0,0
0,0,0,0,0,0,0,0,0,0,0,0,0,0,0
0,0,0,0,0,0,0,0,0,0,0,0,0,0,0
0,0,0,0,0,0,0,0,0,0,0,0,0,0,0
0,0,0,0,0,0,0,0,0,0,0,0,0,0,0
0,0,0,0,0,0,0,0,0,0,0,0,0,0,0
0,0,0,0,0,0,0,0,0,0,0,0,0,0,0
0,0,0,0,0,0,0,0,0,0,0,0,0,0,0
0,0,0,0,0,0,0,0,0,0,0,0,0,0,0
0,0,0,0,0,0,0,0,0,0,0,0,0,0,0
0,0,0,0,0,0,0,0,0,0,0,0,0,0,0
0,0,0,0,0,0,0,0,0,0,0,0,0,0,0
0,0,0,0,0,0,0,0,0,0,0,0,0,0,0
0,0,0,0,0,0,0,0,0,0,0,0,0,0,0
0,0,0,0,0,0,0,0,0,0,0,0,0,0,0
0,0,0,0,0,0,0,0,0,0,0,0,0,0,0
0,0,0,0,0,0,0,0,0,0,0,0,0,0,0
0,0,0,0,0,0,0,0,0,0,0,0,0,0,0
0,0,0,0,0,0,0,0,0,0,0,0,0,0,0
0,0,0,0,0,0,0,0,0,0,0,0,0,0,0
0,0,0,0,0,0,0,0,0,0,0,0,0,0,0
0,0,0,0,0,0,0,0,0,0,0,0,0,0,0
0,0,0,0,0,0,0,0,0,0,0,0,0,0,0
0,0,0,0,0,0,0,0,0,0,0,0,0,0,0
0,0,0,0,0,0,0,0,0,0,0,0,0,0,0
0,0,0,0,0,0,0,0,0,0,0,0,0,0,0
0,0,0,0,0,0,0,0,0,0,0,0,0,0,0
0,0,0,0,0,0,0,0,0,0,0,0,0,0,0
0,0,0,0,0,0,0,0,0,0,0,0,0,0,0
0,0,0,0,0,0,0,0,0,0,0,0,0,0,0
0,0,0,0,0,0,0,0,0,0,0,0,0,0,0
0,0,0,0,0,0,0,0,0,0,0,0,0,0,0
0,0,0,0,0,0,0,0,0,0,0,0,0,0,0
0,0,0,0,0,0,0,0,0,0,0,0,0,0,0
0,0,0,0,0,0,0,0,0,0,0,0,0,0,0
:endlayer
layer: 30
0,0,0,0,0,0,0,0,0,0,0,0,0,0,0
0,0,0,0,0,0,0,0,0,0,0,0,0,0,0
0,0,0,0,0,0,0,0,0,0,0,0,0,0,0
0,0,0,0,0,0,0,0,0,0,0,0,0,0,0
0,0,0,0,0,0,0,0,0,0,0,0,0,0,0
0,0,0,0,0,0,0,0,0,0,0,0,0,0,0
0,0,0,0,0,0,0,0,0,0,0,0,0,0,0
0,0,0,0,0,0,0,0,0,0,0,0,0,0,0
0,0,0,0,0,0,0,0,0,0,0,0,0,0,0
0,0,0,0,0,0,0,0,0,0,0,0,0,0,0
0,0,0,0,0,0,0,0,0,0,0,0,0,0,0
0,0,0,0,0,0,0,0,0,0,0,0,0,0,0
0,0,0,0,0,0,0,0,0,0,0,0,0,0,0
0,0,0,0,0,0,0,0,0,0,0,0,0,0,0
0,0,0,0,0,0,0,0,0,0,0,0,0,0,0
0,0,0,0,0,0,0,0,0,0,0,0,0,0,0
0,0,0,0,0,0,0,0,0,0,0,0,0,0,0
0,0,0,0,0,0,0,0,0,0,0,0,0,0,0
0,0,0,0,0,0,0,0,0,0,0,0,0,0,0
0,0,0,0,0,0,0,0,0,0,0,0,0,0,0
0,0,0,0,0,0,0,0,0,0,0,0,0,0,0
0,0,0,0,0,0,0,0,0,0,0,0,0,0,0
0,0,0,0,0,0,0,0,0,0,0,0,0,0,0
0,0,0,0,0,0,0,0,0,0,0,0,0,0,0
0,0,0,0,0,0,0,0,0,0,0,0,0,0,0
0,0,0,0,0,0,0,0,0,0,0,0,0,0,0
0,0,0,0,0,0,0,0,0,0,0,0,0,0,0
0,0,0,0,0,0,0,0,0,0,0,0,0,0,0
0,0,0,0,0,0,0,0,0,0,0,0,0,0,0
0,0,0,0,0,0,0,0,0,0,0,0,0,0,0
0,0,0,0,0,0,0,0,0,0,0,0,0,0,0
0,0,0,0,0,0,0,0,0,0,0,0,0,0,0
0,0,0,0,0,0,0,0,0,0,0,0,0,0,0
0,0,0,0,0,0,0,0,0,0,0,0,0,0,0
0,0,0,0,0,0,0,0,0,0,0,0,0,0,0
0,0,0,0,0,0,0,0,0,0,0,0,0,0,0
0,0,0,0,0,0,0,0,0,0,0,0,0,0,0
:endlayer
layer: 31
0,0,0,0,0,0,0,0,0,0,0,0,0,0,0
0,0,0,0,0,0,0,0,0,0,0,0,0,0,0
0,0,0,0,0,0,0,0,0,0,0,0,0,0,0
0,0,0,0,0,0,0,0,0,0,0,0,0,0,0
0,0,0,0,0,0,0,0,0,0,0,0,0,0,0
0,0,0,0,0,0,0,0,0,0,0,0,0,0,0
0,0,0,0,0,0,0,0,0,0,0,0,0,0,0
0,0,0,0,0,0,0,0,0,0,0,0,0,0,0
0,0,0,0,0,0,0,0,0,0,0,0,0,0,0
0,0,0,0,0,0,0,0,0,0,0,0,0,0,0
0,0,0,0,0,0,0,0,0,0,0,0,0,0,0
0,0,0,0,0,0,0,0,0,0,0,0,0,0,0
0,0,0,0,0,0,0,0,0,0,0,0,0,0,0
0,0,0,0,0,0,0,0,0,0,0,0,0,0,0
0,0,0,0,0,0,0,0,0,0,0,0,0,0,0
0,0,0,0,0,0,0,0,0,0,0,0,0,0,0
0,0,0,0,0,0,0,0,0,0,0,0,0,0,0
0,0,0,0,0,0,0,0,0,0,0,0,0,0,0
0,0,0,0,0,0,0,0,0,0,0,0,0,0,0
0,0,0,0,0,0,0,0,0,0,0,0,0,0,0
0,0,0,0,0,0,0,0,0,0,0,0,0,0,0
0,0,0,0,0,0,0,0,0,0,0,0,0,0,0
0,0,0,0,0,0,0,0,0,0,0,0,0,0,0
0,0,0,0,0,0,0,0,0,0,0,0,0,0,0
0,0,0,0,0,0,0,0,0,0,0,0,0,0,0
0,0,0,0,0,0,0,0,0,0,0,0,0,0,0
0,0,0,0,0,0,0,0,0,0,0,0,0,0,0
0,0,0,0,0,0,0,0,0,0,0,0,0,0,0
0,0,0,0,0,0,0,0,0,0,0,0,0,0,0
0,0,0,0,0,0,0,0,0,0,0,0,0,0,0
0,0,0,0,0,0,0,0,0,0,0,0,0,0,0
0,0,0,0,0,0,0,0,0,0,0,0,0,0,0
0,0,0,0,0,0,0,0,0,0,0,0,0,0,0
0,0,0,0,0,0,0,0,0,0,0,0,0,0,0
0,0,0,0,0,0,0,0,0,0,0,0,0,0,0
0,0,0,0,0,0,0,0,0,0,0,0,0,0,0
0,0,0,0,0,0,0,0,0,0,0,0,0,0,0
:endlayer
layer: 32
0,0,0,0,0,0,0,0,0,0,0,0,0,0,0
0,0,0,0,0,0,0,0,0,0,0,0,0,0,0
0,0,0,0,0,0,0,0,0,0,0,0,0,0,0
0,0,0,0,0,0,0,0,0,0,0,0,0,0,0
0,0,0,0,0,0,0,0,0,0,0,0,0,0,0
0,0,0,0,0,0,0,0,0,0,0,0,0,0,0
0,0,0,0,0,0,0,0,0,0,0,0,0,0,0
0,0,0,0,0,0,0,0,0,0,0,0,0,0,0
0,0,0,0,0,0,0,0,0,0,0,0,0,0,0
0,0,0,0,0,0,0,0,0,0,0,0,0,0,0
0,0,0,0,0,0,0,0,0,0,0,0,0,0,0
0,0,0,0,0,0,0,0,0,0,0,0,0,0,0
0,0,0,0,0,0,0,0,0,0,0,0,0,0,0
0,0,0,0,0,0,0,0,0,0,0,0,0,0,0
0,0,0,0,0,0,0,0,0,0,0,0,0,0,0
0,0,0,0,0,0,0,0,0,0,0,0,0,0,0
0,0,0,0,0,0,0,0,0,0,0,0,0,0,0
0,0,0,0,0,0,0,0,0,0,0,0,0,0,0
0,0,0,0,0,0,0,0,0,0,0,0,0,0,0
0,0,0,0,0,0,0,0,0,0,0,0,0,0,0
0,0,0,0,0,0,0,0,0,0,0,0,0,0,0
0,0,0,0,0,0,0,0,0,0,0,0,0,0,0
0,0,0,0,0,0,0,0,0,0,0,0,0,0,0
0,0,0,0,0,0,0,0,0,0,0,0,0,0,0
0,0,0,0,0,0,0,0,0,0,0,0,0,0,0
0,0,0,0,0,0,0,0,0,0,0,0,0,0,0
0,0,0,0,0,0,0,0,0,0,0,0,0,0,0
0,0,0,0,0,0,0,0,0,0,0,0,0,0,0
0,0,0,0,0,0,0,0,0,0,0,0,0,0,0
0,0,0,0,0,0,0,0,0,0,0,0,0,0,0
0,0,0,0,0,0,0,0,0,0,0,0,0,0,0
0,0,0,0,0,0,0,0,0,0,0,0,0,0,0
0,0,0,0,0,0,0,0,0,0,0,0,0,0,0
0,0,0,0,0,0,0,0,0,0,0,0,0,0,0
0,0,0,0,0,0,0,0,0,0,0,0,0,0,0
0,0,0,0,0,0,0,0,0,0,0,0,0,0,0
0,0,0,0,0,0,0,0,0,0,0,0,0,0,0
:endlayer
layer: 33
0,0,0,0,0,0,0,0,0,0,0,0,0,0,0
0,0,0,0,0,0,0,0,0,0,0,0,0,0,0
0,0,0,0,0,0,0,0,0,0,0,0,0,0,0
0,0,0,0,0,0,0,0,0,0,0,0,0,0,0
0,0,0,0,0,0,0,0,0,0,0,0,0,0,0
0,0,0,0,0,0,0,0,0,0,0,0,0,0,0
0,0,0,0,0,0,0,0,0,0,0,0,0,0,0
0,0,0,0,0,0,0,0,0,0,0,0,0,0,0
0,0,0,0,0,0,0,0,0,0,0,0,0,0,0
0,0,0,0,0,0,0,0,0,0,0,0,0,0,0
0,0,0,0,0,0,0,0,0,0,0,0,0,0,0
0,0,0,0,0,0,0,0,0,0,0,0,0,0,0
0,0,0,0,0,0,0,0,0,0,0,0,0,0,0
0,0,0,0,0,0,0,0,0,0,0,0,0,0,0
0,0,0,0,0,0,0,0,0,0,0,0,0,0,0
0,0,0,0,0,0,0,0,0,0,0,0,0,0,0
0,0,0,0,0,0,0,0,0,0,0,0,0,0,0
0,0,0,0,0,0,0,0,0,0,0,0,0,0,0
0,0,0,0,0,0,0,0,0,0,0,0,0,0,0
0,0,0,0,0,0,0,0,0,0,0,0,0,0,0
0,0,0,0,0,0,0,0,0,0,0,0,0,0,0
0,0,0,0,0,0,0,0,0,0,0,0,0,0,0
0,0,0,0,0,0,0,0,0,0,0,0,0,0,0
0,0,0,0,0,0,0,0,0,0,0,0,0,0,0
0,0,0,0,0,0,0,0,0,0,0,0,0,0,0
0,0,0,0,0,0,0,0,0,0,0,0,0,0,0
0,0,0,0,0,0,0,0,0,0,0,0,0,0,0
0,0,0,0,0,0,0,0,0,0,0,0,0,0,0
0,0,0,0,0,0,0,0,0,0,0,0,0,0,0
0,0,0,0,0,0,0,0,0,0,0,0,0,0,0
0,0,0,0,0,0,0,0,0,0,0,0,0,0,0
0,0,0,0,0,0,0,0,0,0,0,0,0,0,0
0,0,0,0,0,0,0,0,0,0,0,0,0,0,0
0,0,0,0,0,0,0,0,0,0,0,0,0,0,0
0,0,0,0,0,0,0,0,0,0,0,0,0,0,0
0,0,0,0,0,0,0,0,0,0,0,0,0,0,0
0,0,0,0,0,0,0,0,0,0,0,0,0,0,0
:endlayer
layer: 34
0,0,0,0,0,0,0,0,0,0,0,0,0,0,0
0,0,0,0,0,0,0,0,0,0,0,0,0,0,0
0,0,0,0,0,0,0,0,0,0,0,0,0,0,0
0,0,0,0,0,0,0,0,0,0,0,0,0,0,0
0,0,0,0,0,0,0,0,0,0,0,0,0,0,0
0,0,0,0,0,0,0,0,0,0,0,0,0,0,0
0,0,0,0,0,0,0,0,0,0,0,0,0,0,0
0,0,0,0,0,0,0,0,0,0,0,0,0,0,0
0,0,0,0,0,0,0,0,0,0,0,0,0,0,0
0,0,0,0,0,0,0,0,0,0,0,0,0,0,0
0,0,0,0,0,0,0,0,0,0,0,0,0,0,0
0,0,0,0,0,0,0,0,0,0,0,0,0,0,0
0,0,0,0,0,0,0,0,0,0,0,0,0,0,0
0,0,0,0,0,0,0,0,0,0,0,0,0,0,0
0,0,0,0,0,0,0,0,0,0,0,0,0,0,0
0,0,0,0,0,0,0,0,0,0,0,0,0,0,0
0,0,0,0,0,0,0,0,0,0,0,0,0,0,0
0,0,0,0,0,0,0,0,0,0,0,0,0,0,0
0,0,0,0,0,0,0,0,0,0,0,0,0,0,0
0,0,0,0,0,0,0,0,0,0,0,0,0,0,0
0,0,0,0,0,0,0,0,0,0,0,0,0,0,0
0,0,0,0,0,0,0,0,0,0,0,0,0,0,0
0,0,0,0,0,0,0,0,0,0,0,0,0,0,0
0,0,0,0,0,0,0,0,0,0,0,0,0,0,0
0,0,0,0,0,0,0,0,0,0,0,0,0,0,0
0,0,0,0,0,0,0,0,0,0,0,0,0,0,0
0,0,0,0,0,0,0,0,0,0,0,0,0,0,0
0,0,0,0,0,0,0,0,0,0,0,0,0,0,0
0,0,0,0,0,0,0,0,0,0,0,0,0,0,0
0,0,0,0,0,0,0,0,0,0,0,0,0,0,0
0,0,0,0,0,0,0,0,0,0,0,0,0,0,0
0,0,0,0,0,0,0,0,0,0,0,0,0,0,0
0,0,0,0,0,0,0,0,0,0,0,0,0,0,0
0,0,0,0,0,0,0,0,0,0,0,0,0,0,0
0,0,0,0,0,0,0,0,0,0,0,0,0,0,0
0,0,0,0,0,0,0,0,0,0,0,0,0,0,0
0,0,0,0,0,0,0,0,0,0,0,0,0,0,0
:endlayer
layer: 35
0,0,0,0,0,0,0,0,0,0,0,0,0,0,0
0,0,0,0,0,0,0,0,0,0,0,0,0,0,0
0,0,0,0,0,0,0,0,0,0,0,0,0,0,0
0,0,0,0,0,0,0,0,0,0,0,0,0,0,0
0,0,0,0,0,0,0,0,0,0,0,0,0,0,0
0,0,0,0,0,0,0,0,0,0,0,0,0,0,0
0,0,0,0,0,0,0,0,0,0,0,0,0,0,0
0,0,0,0,0,0,0,0,0,0,0,0,0,0,0
0,0,0,0,0,0,0,0,0,0,0,0,0,0,0
0,0,0,0,0,0,0,0,0,0,0,0,0,0,0
0,0,0,0,0,0,0,0,0,0,0,0,0,0,0
0,0,0,0,0,0,0,0,0,0,0,0,0,0,0
0,0,0,0,0,0,0,0,0,0,0,0,0,0,0
0,0,0,0,0,0,0,0,0,0,0,0,0,0,0
0,0,0,0,0,0,0,0,0,0,0,0,0,0,0
0,0,0,0,0,0,0,0,0,0,0,0,0,0,0
0,0,0,0,0,0,0,0,0,0,0,0,0,0,0
0,0,0,0,0,0,0,0,0,0,0,0,0,0,0
0,0,0,0,0,0,0,0,0,0,0,0,0,0,0
0,0,0,0,0,0,0,0,0,0,0,0,0,0,0
0,0,0,0,0,0,0,0,0,0,0,0,0,0,0
0,0,0,0,0,0,0,0,0,0,0,0,0,0,0
0,0,0,0,0,0,0,0,0,0,0,0,0,0,0
0,0,0,0,0,0,0,0,0,0,0,0,0,0,0
0,0,0,0,0,0,0,0,0,0,0,0,0,0,0
0,0,0,0,0,0,0,0,0,0,0,0,0,0,0
0,0,0,0,0,0,0,0,0,0,0,0,0,0,0
0,0,0,0,0,0,0,0,0,0,0,0,0,0,0
0,0,0,0,0,0,0,0,0,0,0,0,0,0,0
0,0,0,0,0,0,0,0,0,0,0,0,0,0,0
0,0,0,0,0,0,0,0,0,0,0,0,0,0,0
0,0,0,0,0,0,0,0,0,0,0,0,0,0,0
0,0,0,0,0,0,0,0,0,0,0,0,0,0,0
0,0,0,0,0,0,0,0,0,0,0,0,0,0,0
0,0,0,0,0,0,0,0,0,0,0,0,0,0,0
0,0,0,0,0,0,0,0,0,0,0,0,0,0,0
0,0,0,0,0,0,0,0,0,0,0,0,0,0,0
:endlayer
layer: 36
0,0,0,0,0,0,0,0,0,0,0,0,0,0,0
0,0,0,0,0,0,0,0,0,0,0,0,0,0,0
0,0,0,0,0,0,0,0,0,0,0,0,0,0,0
0,0,0,0,0,0,0,0,0,0,0,0,0,0,0
0,0,0,0,0,0,0,0,0,0,0,0,0,0,0
0,0,0,0,0,0,0,0,0,0,0,0,0,0,0
0,0,0,0,0,0,0,0,0,0,0,0,0,0,0
0,0,0,0,0,0,0,0,0,0,0,0,0,0,0
0,0,0,0,0,0,0,0,0,0,0,0,0,0,0
0,0,0,0,0,0,0,0,0,0,0,0,0,0,0
0,0,0,0,0,0,0,0,0,0,0,0,0,0,0
0,0,0,0,0,0,0,0,0,0,0,0,0,0,0
0,0,0,0,0,0,0,0,0,0,0,0,0,0,0
0,0,0,0,0,0,0,0,0,0,0,0,0,0,0
0,0,0,0,0,0,0,0,0,0,0,0,0,0,0
0,0,0,0,0,0,0,0,0,0,0,0,0,0,0
0,0,0,0,0,0,0,0,0,0,0,0,0,0,0
0,0,0,0,0,0,0,0,0,0,0,0,0,0,0
0,0,0,0,0,0,0,0,0,0,0,0,0,0,0
0,0,0,0,0,0,0,0,0,0,0,0,0,0,0
0,0,0,0,0,0,0,0,0,0,0,0,0,0,0
0,0,0,0,0,0,0,0,0,0,0,0,0,0,0
0,0,0,0,0,0,0,0,0,0,0,0,0,0,0
0,0,0,0,0,0,0,0,0,0,0,0,0,0,0
0,0,0,0,0,0,0,0,0,0,0,0,0,0,0
0,0,0,0,0,0,0,0,0,0,0,0,0,0,0
0,0,0,0,0,0,0,0,0,0,0,0,0,0,0
0,0,0,0,0,0,0,0,0,0,0,0,0,0,0
0,0,0,0,0,0,0,0,0,0,0,0,0,0,0
0,0,0,0,0,0,0,0,0,0,0,0,0,0,0
0,0,0,0,0,0,0,0,0,0,0,0,0,0,0
0,0,0,0,0,0,0,0,0,0,0,0,0,0,0
0,0,0,0,0,0,0,0,0,0,0,0,0,0,0
0,0,0,0,0,0,0,0,0,0,0,0,0,0,0
0,0,0,0,0,0,0,0,0,0,0,0,0,0,0
0,0,0,0,0,0,0,0,0,0,0,0,0,0,0
0,0,0,0,0,0,0,0,0,0,0,0,0,0,0
:endlayer
layer: 37
0,0,0,0,0,0,0,0,0,0,0,0,0,0,0
0,0,0,0,0,0,0,0,0,0,0,0,0,0,0
0,0,0,0,0,0,0,0,0,0,0,0,0,0,0
0,0,0,0,0,0,0,0,0,0,0,0,0,0,0
0,0,0,0,0,0,0,0,0,0,0,0,0,0,0
0,0,0,0,0,0,0,0,0,0,0,0,0,0,0
0,0,0,0,0,0,0,0,0,0,0,0,0,0,0
0,0,0,0,0,0,0,0,0,0,0,0,0,0,0
0,0,0,0,0,0,0,0,0,0,0,0,0,0,0
0,0,0,0,0,0,0,0,0,0,0,0,0,0,0
0,0,0,0,0,0,0,0,0,0,0,0,0,0,0
0,0,0,0,0,0,0,0,0,0,0,0,0,0,0
0,0,0,0,0,0,0,0,0,0,0,0,0,0,0
0,0,0,0,0,0,0,0,0,0,0,0,0,0,0
0,0,0,0,0,0,0,0,0,0,0,0,0,0,0
0,0,0,0,0,0,0,0,0,0,0,0,0,0,0
0,0,0,0,0,0,0,0,0,0,0,0,0,0,0
0,0,0,0,0,0,0,0,0,0,0,0,0,0,0
0,0,0,0,0,0,0,0,0,0,0,0,0,0,0
0,0,0,0,0,0,0,0,0,0,0,0,0,0,0
0,0,0,0,0,0,0,0,0,0,0,0,0,0,0
0,0,0,0,0,0,0,0,0,0,0,0,0,0,0
0,0,0,0,0,0,0,0,0,0,0,0,0,0,0
0,0,0,0,0,0,0,0,0,0,0,0,0,0,0
0,0,0,0,0,0,0,0,0,0,0,0,0,0,0
0,0,0,0,0,0,0,0,0,0,0,0,0,0,0
0,0,0,0,0,0,0,0,0,0,0,0,0,0,0
0,0,0,0,0,0,0,0,0,0,0,0,0,0,0
0,0,0,0,0,0,0,0,0,0,0,0,0,0,0
0,0,0,0,0,0,0,0,0,0,0,0,0,0,0
0,0,0,0,0,0,0,0,0,0,0,0,0,0,0
0,0,0,0,0,0,0,0,0,0,0,0,0,0,0
0,0,0,0,0,0,0,0,0,0,0,0,0,0,0
0,0,0,0,0,0,0,0,0,0,0,0,0,0,0
0,0,0,0,0,0,0,0,0,0,0,0,0,0,0
0,0,0,0,0,0,0,0,0,0,0,0,0,0,0
0,0,0,0,0,0,0,0,0,0,0,0,0,0,0
:endlayer
layer: 38
0,0,0,0,0,0,0,0,0,0,0,0,0,0,0
0,0,0,0,0,0,0,0,0,0,0,0,0,0,0
0,0,0,0,0,0,0,0,0,0,0,0,0,0,0
0,0,0,0,0,0,0,0,0,0,0,0,0,0,0
0,0,0,0,0,0,0,0,0,0,0,0,0,0,0
0,0,0,0,0,0,0,0,0,0,0,0,0,0,0
0,0,0,0,0,0,0,0,0,0,0,0,0,0,0
0,0,0,0,0,0,0,0,0,0,0,0,0,0,0
0,0,0,0,0,0,0,0,0,0,0,0,0,0,0
0,0,0,0,0,0,0,0,0,0,0,0,0,0,0
0,0,0,0,0,0,0,0,0,0,0,0,0,0,0
0,0,0,0,0,0,0,0,0,0,0,0,0,0,0
0,0,0,0,0,0,0,0,0,0,0,0,0,0,0
0,0,0,0,0,0,0,0,0,0,0,0,0,0,0
0,0,0,0,0,0,0,0,0,0,0,0,0,0,0
0,0,0,0,0,0,0,0,0,0,0,0,0,0,0
0,0,0,0,0,0,0,0,0,0,0,0,0,0,0
0,0,0,0,0,0,0,0,0,0,0,0,0,0,0
0,0,0,0,0,0,0,0,0,0,0,0,0,0,0
0,0,0,0,0,0,0,0,0,0,0,0,0,0,0
0,0,0,0,0,0,0,0,0,0,0,0,0,0,0
0,0,0,0,0,0,0,0,0,0,0,0,0,0,0
0,0,0,0,0,0,0,0,0,0,0,0,0,0,0
0,0,0,0,0,0,0,0,0,0,0,0,0,0,0
0,0,0,0,0,0,0,0,0,0,0,0,0,0,0
0,0,0,0,0,0,0,0,0,0,0,0,0,0,0
0,0,0,0,0,0,0,0,0,0,0,0,0,0,0
0,0,0,0,0,0,0,0,0,0,0,0,0,0,0
0,0,0,0,0,0,0,0,0,0,0,0,0,0,0
0,0,0,0,0,0,0,0,0,0,0,0,0,0,0
0,0,0,0,0,0,0,0,0,0,0,0,0,0,0
0,0,0,0,0,0,0,0,0,0,0,0,0,0,0
0,0,0,0,0,0,0,0,0,0,0,0,0,0,0
0,0,0,0,0,0,0,0,0,0,0,0,0,0,0
0,0,0,0,0,0,0,0,0,0,0,0,0,0,0
0,0,0,0,0,0,0,0,0,0,0,0,0,0,0
0,0,0,0,0,0,0,0,0,0,0,0,0,0,0
:endlayer
layer: 39
0,0,0,0,0,0,0,0,0,0,0,0,0,0,0
0,0,0,0,0,0,0,0,0,0,0,0,0,0,0
0,0,0,0,0,0,0,0,0,0,0,0,0,0,0
0,0,0,0,0,0,0,0,0,0,0,0,0,0,0
0,0,0,0,0,0,0,0,0,0,0,0,0,0,0
0,0,0,0,0,0,0,0,0,0,0,0,0,0,0
0,0,0,0,0,0,0,0,0,0,0,0,0,0,0
0,0,0,0,0,0,0,0,0,0,0,0,0,0,0
0,0,0,0,0,0,0,0,0,0,0,0,0,0,0
0,0,0,0,0,0,0,0,0,0,0,0,0,0,0
0,0,0,0,0,0,0,0,0,0,0,0,0,0,0
0,0,0,0,0,0,0,0,0,0,0,0,0,0,0
0,0,0,0,0,0,0,0,0,0,0,0,0,0,0
0,0,0,0,0,0,0,0,0,0,0,0,0,0,0
0,0,0,0,0,0,0,0,0,0,0,0,0,0,0
0,0,0,0,0,0,0,0,0,0,0,0,0,0,0
0,0,0,0,0,0,0,0,0,0,0,0,0,0,0
0,0,0,0,0,0,0,0,0,0,0,0,0,0,0
0,0,0,0,0,0,0,0,0,0,0,0,0,0,0
0,0,0,0,0,0,0,0,0,0,0,0,0,0,0
0,0,0,0,0,0,0,0,0,0,0,0,0,0,0
0,0,0,0,0,0,0,0,0,0,0,0,0,0,0
0,0,0,0,0,0,0,0,0,0,0,0,0,0,0
0,0,0,0,0,0,0,0,0,0,0,0,0,0,0
0,0,0,0,0,0,0,0,0,0,0,0,0,0,0
0,0,0,0,0,0,0,0,0,0,0,0,0,0,0
0,0,0,0,0,0,0,0,0,0,0,0,0,0,0
0,0,0,0,0,0,0,0,0,0,0,0,0,0,0
0,0,0,0,0,0,0,0,0,0,0,0,0,0,0
0,0,0,0,0,0,0,0,0,0,0,0,0,0,0
0,0,0,0,0,0,0,0,0,0,0,0,0,0,0
0,0,0,0,0,0,0,0,0,0,0,0,0,0,0
0,0,0,0,0,0,0,0,0,0,0,0,0,0,0
0,0,0,0,0,0,0,0,0,0,0,0,0,0,0
0,0,0,0,0,0,0,0,0,0,0,0,0,0,0
0,0,0,0,0,0,0,0,0,0,0,0,0,0,0
0,0,0,0,0,0,0,0,0,0,0,0,0,0,0
:endlayer

#### RULES ####
rule:
plugin=vanillaBlocks
number=1
data:
JSON:{{"val":{"blockName":{"val":"minecraft:dirt","id":"ss"},"meta":{"val":"0","id":"pi"},"buildPass":{"val":"0","id":"pi"}},"id":"ct"}}
:enddata
:endrule

rule:
plugin=vanillaBlocks
number=2
data:
JSON:{{"val":{"blockName":{"val":"minecraft:grass","id":"ss"},"meta":{"val":"0","id":"pi"},"buildPass":{"val":"0","id":"pi"}},"id":"ct"}}
:enddata
:endrule

rule:
plugin=vanillaBlocks
number=3
data:
JSON:{{"val":{"blockName":{"val":"minecraft:cobblestone","id":"ss"},"meta":{"val":"0","id":"pi"},"buildPass":{"val":"0","id":"pi"}},"id":"ct"}}
:enddata
:endrule

rule:
plugin=vanillaBlocks
number=4
data:
JSON:{{"val":{"blockName":{"val":"minecraft:water","id":"ss"},"meta":{"val":"0","id":"pi"},"buildPass":{"val":"0","id":"pi"}},"id":"ct"}}
:enddata
:endrule

rule:
plugin=vanillaBlocks
number=5
data:
JSON:{{"val":{"blockName":{"val":"minecraft:lava","id":"ss"},"meta":{"val":"0","id":"pi"},"buildPass":{"val":"0","id":"pi"}},"id":"ct"}}
:enddata
:endrule

rule:
plugin=vanillaBlocks
number=6
data:
JSON:{{"val":{"blockName":{"val":"minecraft:snow_layer","id":"ss"},"meta":{"val":"0","id":"pi"},"buildPass":{"val":"2","id":"pi"}},"id":"ct"}}
:enddata
:endrule

rule:
plugin=vanillaBlocks
number=7
data:
JSON:{{"val":{"blockName":{"val":"minecraft:snow_layer","id":"ss"},"meta":{"val":"1","id":"pi"},"buildPass":{"val":"2","id":"pi"}},"id":"ct"}}
:enddata
:endrule

rule:
plugin=vanillaBlocks
number=8
data:
JSON:{{"val":{"blockName":{"val":"minecraft:snow_layer","id":"ss"},"meta":{"val":"2","id":"pi"},"buildPass":{"val":"2","id":"pi"}},"id":"ct"}}
:enddata
:endrule

rule:
plugin=vanillaDoors
number=9
data:
JSON:{{"val":{"sideFlag":{"val":"8","id":"pb"},"blockName":{"val":"minecraft:wooden_door","id":"ss"},"meta":{"val":"1","id":"pi"},"buildPass":{"val":"2","id":"pi"}},"id":"ct"}}
:enddata
:endrule

rule:
plugin=vanillaBlocks
number=10
data:
JSON:{{"val":{"blockName":{"val":"minecraft:crafting_table","id":"ss"},"meta":{"val":"0","id":"pi"},"buildPass":{"val":"0","id":"pi"}},"id":"ct"}}
:enddata
:endrule

rule:
plugin=vanillaBlocks
number=11
data:
JSON:{{"val":{"blockName":{"val":"minecraft:carpet","id":"ss"},"meta":{"val":"12","id":"pi"},"buildPass":{"val":"2","id":"pi"}},"id":"ct"}}
:enddata
:endrule

rule:
plugin=vanillaBlocks
number=12
data:
JSON:{{"val":{"blockName":{"val":"minecraft:anvil","id":"ss"},"meta":{"val":"0","id":"pi"},"buildPass":{"val":"0","id":"pi"}},"id":"ct"}}
:enddata
:endrule

rule:
plugin=vanillaBlocks
number=13
data:
JSON:{{"val":{"blockName":{"val":"minecraft:anvil","id":"ss"},"meta":{"val":"2","id":"pi"},"buildPass":{"val":"0","id":"pi"}},"id":"ct"}}
:enddata
:endrule

rule:
plugin=awTownHall
number=14
data:
JSON:{{"val":{"teData":{"val":{"id":{"val":"Furnace","id":"ss"},"Items":{"val":[{"val":{"id":{"val":"263","id":"ps"},"Damage":{"val":"1","id":"ps"},"Count":{"val":"32","id":"pb"},"Slot":{"val":"1","id":"pb"}},"id":"ct"}],"id":"ls"},"BurnTime":{"val":"0","id":"ps"},"z":{"val":"1575","id":"pi"},"y":{"val":"91","id":"pi"},"CookTime":{"val":"0","id":"ps"},"x":{"val":"1500","id":"pi"}},"id":"ct"},"blockName":{"val":"minecraft:lit_furnace","id":"ss"},"meta":{"val":"2","id":"pi"},"buildPass":{"val":"0","id":"pi"}},"id":"ct"}}
:enddata
:endrule

rule:
plugin=awTownHall
number=15
data:
JSON:{{"val":{"teData":{"val":{"id":{"val":"Furnace","id":"ss"},"Items":{"val":[{"val":{"id":{"val":"263","id":"ps"},"Damage":{"val":"1","id":"ps"},"Count":{"val":"32","id":"pb"},"Slot":{"val":"1","id":"pb"}},"id":"ct"}],"id":"ls"},"BurnTime":{"val":"0","id":"ps"},"z":{"val":"1575","id":"pi"},"y":{"val":"91","id":"pi"},"CookTime":{"val":"0","id":"ps"},"x":{"val":"1506","id":"pi"}},"id":"ct"},"blockName":{"val":"minecraft:lit_furnace","id":"ss"},"meta":{"val":"2","id":"pi"},"buildPass":{"val":"0","id":"pi"}},"id":"ct"}}
:enddata
:endrule

rule:
plugin=vanillaBlocks
number=16
data:
JSON:{{"val":{"blockName":{"val":"minecraft:snow_layer","id":"ss"},"meta":{"val":"4","id":"pi"},"buildPass":{"val":"2","id":"pi"}},"id":"ct"}}
:enddata
:endrule

rule:
plugin=vanillaBlocks
number=17
data:
JSON:{{"val":{"blockName":{"val":"minecraft:carpet","id":"ss"},"meta":{"val":"7","id":"pi"},"buildPass":{"val":"2","id":"pi"}},"id":"ct"}}
:enddata
:endrule

rule:
plugin=vanillaInventory
number=18
data:
JSON:{{"val":{"lootLevel":{"val":"0","id":"pi"},"inventoryData":{"val":{"length":{"val":"27","id":"pi"},"inventoryContents":{"val":[{"val":{"item":{"val":"minecraft:chainmail_chestplate","id":"ss"},"damage":{"val":"0","id":"pi"},"quantity":{"val":"1","id":"pi"},"slot":{"val":"0","id":"pi"}},"id":"ct"},{"val":{"item":{"val":"minecraft:chainmail_chestplate","id":"ss"},"damage":{"val":"0","id":"pi"},"quantity":{"val":"1","id":"pi"},"slot":{"val":"1","id":"pi"}},"id":"ct"},{"val":{"item":{"val":"minecraft:chainmail_chestplate","id":"ss"},"damage":{"val":"0","id":"pi"},"quantity":{"val":"1","id":"pi"},"slot":{"val":"2","id":"pi"}},"id":"ct"},{"val":{"item":{"val":"minecraft:chainmail_helmet","id":"ss"},"damage":{"val":"0","id":"pi"},"quantity":{"val":"1","id":"pi"},"slot":{"val":"3","id":"pi"}},"id":"ct"},{"val":{"item":{"val":"minecraft:chainmail_helmet","id":"ss"},"damage":{"val":"0","id":"pi"},"quantity":{"val":"1","id":"pi"},"slot":{"val":"4","id":"pi"}},"id":"ct"},{"val":{"item":{"val":"minecraft:chainmail_helmet","id":"ss"},"damage":{"val":"0","id":"pi"},"quantity":{"val":"1","id":"pi"},"slot":{"val":"5","id":"pi"}},"id":"ct"},{"val":{"item":{"val":"minecraft:chainmail_boots","id":"ss"},"damage":{"val":"0","id":"pi"},"quantity":{"val":"1","id":"pi"},"slot":{"val":"6","id":"pi"}},"id":"ct"},{"val":{"item":{"val":"minecraft:chainmail_boots","id":"ss"},"damage":{"val":"0","id":"pi"},"quantity":{"val":"1","id":"pi"},"slot":{"val":"7","id":"pi"}},"id":"ct"},{"val":{"item":{"val":"minecraft:chainmail_boots","id":"ss"},"damage":{"val":"0","id":"pi"},"quantity":{"val":"1","id":"pi"},"slot":{"val":"8","id":"pi"}},"id":"ct"},{"val":{"item":{"val":"minecraft:chainmail_leggings","id":"ss"},"damage":{"val":"0","id":"pi"},"quantity":{"val":"1","id":"pi"},"slot":{"val":"9","id":"pi"}},"id":"ct"},{"val":{"item":{"val":"minecraft:chainmail_leggings","id":"ss"},"damage":{"val":"0","id":"pi"},"quantity":{"val":"1","id":"pi"},"slot":{"val":"10","id":"pi"}},"id":"ct"},{"val":{"item":{"val":"minecraft:chainmail_leggings","id":"ss"},"damage":{"val":"0","id":"pi"},"quantity":{"val":"1","id":"pi"},"slot":{"val":"11","id":"pi"}},"id":"ct"},{"val":{"item":{"val":"minecraft:iron_axe","id":"ss"},"damage":{"val":"0","id":"pi"},"quantity":{"val":"1","id":"pi"},"slot":{"val":"18","id":"pi"}},"id":"ct"},{"val":{"item":{"val":"minecraft:iron_axe","id":"ss"},"damage":{"val":"0","id":"pi"},"quantity":{"val":"1","id":"pi"},"slot":{"val":"25","id":"pi"}},"id":"ct"}],"id":"ls"}},"id":"ct"},"teData":{"val":{"id":{"val":"Chest","id":"ss"},"z":{"val":"1587","id":"pi"},"y":{"val":"91","id":"pi"},"x":{"val":"1499","id":"pi"}},"id":"ct"},"blockName":{"val":"minecraft:chest","id":"ss"},"meta":{"val":"5","id":"pi"},"buildPass":{"val":"0","id":"pi"}},"id":"ct"}}
:enddata
:endrule

rule:
plugin=vanillaInventory
number=19
data:
JSON:{{"val":{"lootLevel":{"val":"0","id":"pi"},"inventoryData":{"val":{"length":{"val":"27","id":"pi"},"inventoryContents":{"val":[{"val":{"item":{"val":"minecraft:iron_ingot","id":"ss"},"damage":{"val":"0","id":"pi"},"quantity":{"val":"1","id":"pi"},"slot":{"val":"3","id":"pi"}},"id":"ct"},{"val":{"item":{"val":"minecraft:iron_ingot","id":"ss"},"damage":{"val":"0","id":"pi"},"quantity":{"val":"1","id":"pi"},"slot":{"val":"10","id":"pi"}},"id":"ct"},{"val":{"item":{"val":"minecraft:iron_ingot","id":"ss"},"damage":{"val":"0","id":"pi"},"quantity":{"val":"1","id":"pi"},"slot":{"val":"11","id":"pi"}},"id":"ct"},{"val":{"item":{"val":"minecraft:iron_ingot","id":"ss"},"damage":{"val":"0","id":"pi"},"quantity":{"val":"2","id":"pi"},"slot":{"val":"12","id":"pi"}},"id":"ct"},{"val":{"item":{"val":"minecraft:iron_ingot","id":"ss"},"damage":{"val":"0","id":"pi"},"quantity":{"val":"1","id":"pi"},"slot":{"val":"13","id":"pi"}},"id":"ct"},{"val":{"item":{"val":"minecraft:iron_ingot","id":"ss"},"damage":{"val":"0","id":"pi"},"quantity":{"val":"1","id":"pi"},"slot":{"val":"15","id":"pi"}},"id":"ct"},{"val":{"item":{"val":"minecraft:iron_ingot","id":"ss"},"damage":{"val":"0","id":"pi"},"quantity":{"val":"1","id":"pi"},"slot":{"val":"16","id":"pi"}},"id":"ct"},{"val":{"item":{"val":"minecraft:iron_ingot","id":"ss"},"damage":{"val":"0","id":"pi"},"quantity":{"val":"1","id":"pi"},"slot":{"val":"19","id":"pi"}},"id":"ct"},{"val":{"item":{"val":"minecraft:iron_ingot","id":"ss"},"damage":{"val":"0","id":"pi"},"quantity":{"val":"1","id":"pi"},"slot":{"val":"20","id":"pi"}},"id":"ct"},{"val":{"item":{"val":"minecraft:iron_ingot","id":"ss"},"damage":{"val":"0","id":"pi"},"quantity":{"val":"1","id":"pi"},"slot":{"val":"21","id":"pi"}},"id":"ct"},{"val":{"item":{"val":"minecraft:iron_ingot","id":"ss"},"damage":{"val":"0","id":"pi"},"quantity":{"val":"1","id":"pi"},"slot":{"val":"22","id":"pi"}},"id":"ct"},{"val":{"item":{"val":"minecraft:iron_ingot","id":"ss"},"damage":{"val":"0","id":"pi"},"quantity":{"val":"1","id":"pi"},"slot":{"val":"23","id":"pi"}},"id":"ct"}],"id":"ls"}},"id":"ct"},"teData":{"val":{"id":{"val":"Chest","id":"ss"},"z":{"val":"1587","id":"pi"},"y":{"val":"91","id":"pi"},"x":{"val":"1507","id":"pi"}},"id":"ct"},"blockName":{"val":"minecraft:chest","id":"ss"},"meta":{"val":"4","id":"pi"},"buildPass":{"val":"0","id":"pi"}},"id":"ct"}}
:enddata
:endrule

rule:
plugin=vanillaInventory
number=20
data:
JSON:{{"val":{"lootLevel":{"val":"0","id":"pi"},"inventoryData":{"val":{"length":{"val":"27","id":"pi"},"inventoryContents":{"val":[{"val":{"item":{"val":"minecraft:iron_sword","id":"ss"},"damage":{"val":"0","id":"pi"},"quantity":{"val":"1","id":"pi"},"slot":{"val":"2","id":"pi"}},"id":"ct"},{"val":{"item":{"val":"minecraft:iron_sword","id":"ss"},"damage":{"val":"0","id":"pi"},"quantity":{"val":"1","id":"pi"},"slot":{"val":"5","id":"pi"}},"id":"ct"},{"val":{"item":{"val":"minecraft:iron_axe","id":"ss"},"damage":{"val":"0","id":"pi"},"quantity":{"val":"1","id":"pi"},"slot":{"val":"13","id":"pi"}},"id":"ct"},{"val":{"item":{"val":"minecraft:iron_sword","id":"ss"},"damage":{"val":"0","id":"pi"},"quantity":{"val":"1","id":"pi"},"slot":{"val":"26","id":"pi"}},"id":"ct"}],"id":"ls"}},"id":"ct"},"teData":{"val":{"id":{"val":"Chest","id":"ss"},"z":{"val":"1588","id":"pi"},"y":{"val":"91","id":"pi"},"x":{"val":"1499","id":"pi"}},"id":"ct"},"blockName":{"val":"minecraft:chest","id":"ss"},"meta":{"val":"5","id":"pi"},"buildPass":{"val":"0","id":"pi"}},"id":"ct"}}
:enddata
:endrule

rule:
plugin=vanillaInventory
number=21
data:
JSON:{{"val":{"lootLevel":{"val":"0","id":"pi"},"inventoryData":{"val":{"length":{"val":"27","id":"pi"},"inventoryContents":{"val":[{"val":{"item":{"val":"minecraft:iron_ingot","id":"ss"},"damage":{"val":"0","id":"pi"},"quantity":{"val":"1","id":"pi"},"slot":{"val":"1","id":"pi"}},"id":"ct"},{"val":{"item":{"val":"minecraft:iron_ingot","id":"ss"},"damage":{"val":"0","id":"pi"},"quantity":{"val":"1","id":"pi"},"slot":{"val":"3","id":"pi"}},"id":"ct"},{"val":{"item":{"val":"minecraft:iron_ingot","id":"ss"},"damage":{"val":"0","id":"pi"},"quantity":{"val":"1","id":"pi"},"slot":{"val":"4","id":"pi"}},"id":"ct"},{"val":{"item":{"val":"minecraft:iron_ingot","id":"ss"},"damage":{"val":"0","id":"pi"},"quantity":{"val":"1","id":"pi"},"slot":{"val":"6","id":"pi"}},"id":"ct"},{"val":{"item":{"val":"minecraft:iron_ingot","id":"ss"},"damage":{"val":"0","id":"pi"},"quantity":{"val":"1","id":"pi"},"slot":{"val":"7","id":"pi"}},"id":"ct"},{"val":{"item":{"val":"minecraft:iron_ingot","id":"ss"},"damage":{"val":"0","id":"pi"},"quantity":{"val":"1","id":"pi"},"slot":{"val":"10","id":"pi"}},"id":"ct"},{"val":{"item":{"val":"minecraft:iron_ingot","id":"ss"},"damage":{"val":"0","id":"pi"},"quantity":{"val":"2","id":"pi"},"slot":{"val":"12","id":"pi"}},"id":"ct"},{"val":{"item":{"val":"minecraft:iron_ingot","id":"ss"},"damage":{"val":"0","id":"pi"},"quantity":{"val":"1","id":"pi"},"slot":{"val":"13","id":"pi"}},"id":"ct"},{"val":{"item":{"val":"minecraft:iron_ingot","id":"ss"},"damage":{"val":"0","id":"pi"},"quantity":{"val":"1","id":"pi"},"slot":{"val":"14","id":"pi"}},"id":"ct"},{"val":{"item":{"val":"minecraft:iron_ingot","id":"ss"},"damage":{"val":"0","id":"pi"},"quantity":{"val":"1","id":"pi"},"slot":{"val":"15","id":"pi"}},"id":"ct"},{"val":{"item":{"val":"minecraft:iron_ingot","id":"ss"},"damage":{"val":"0","id":"pi"},"quantity":{"val":"1","id":"pi"},"slot":{"val":"16","id":"pi"}},"id":"ct"},{"val":{"item":{"val":"minecraft:iron_ingot","id":"ss"},"damage":{"val":"0","id":"pi"},"quantity":{"val":"1","id":"pi"},"slot":{"val":"17","id":"pi"}},"id":"ct"},{"val":{"item":{"val":"minecraft:iron_ingot","id":"ss"},"damage":{"val":"0","id":"pi"},"quantity":{"val":"2","id":"pi"},"slot":{"val":"18","id":"pi"}},"id":"ct"},{"val":{"item":{"val":"minecraft:iron_ingot","id":"ss"},"damage":{"val":"0","id":"pi"},"quantity":{"val":"1","id":"pi"},"slot":{"val":"21","id":"pi"}},"id":"ct"},{"val":{"item":{"val":"minecraft:iron_ingot","id":"ss"},"damage":{"val":"0","id":"pi"},"quantity":{"val":"2","id":"pi"},"slot":{"val":"25","id":"pi"}},"id":"ct"}],"id":"ls"}},"id":"ct"},"teData":{"val":{"id":{"val":"Chest","id":"ss"},"z":{"val":"1588","id":"pi"},"y":{"val":"91","id":"pi"},"x":{"val":"1507","id":"pi"}},"id":"ct"},"blockName":{"val":"minecraft:chest","id":"ss"},"meta":{"val":"4","id":"pi"},"buildPass":{"val":"0","id":"pi"}},"id":"ct"}}
:enddata
:endrule

rule:
plugin=vanillaBlocks
number=22
data:
JSON:{{"val":{"blockName":{"val":"minecraft:cobblestone_wall","id":"ss"},"meta":{"val":"0","id":"pi"},"buildPass":{"val":"0","id":"pi"}},"id":"ct"}}
:enddata
:endrule

rule:
plugin=vanillaBlocks
number=23
data:
JSON:{{"val":{"blockName":{"val":"minecraft:carpet","id":"ss"},"meta":{"val":"0","id":"pi"},"buildPass":{"val":"2","id":"pi"}},"id":"ct"}}
:enddata
:endrule

rule:
plugin=vanillaBlocks
number=24
data:
JSON:{{"val":{"blockName":{"val":"minecraft:carpet","id":"ss"},"meta":{"val":"8","id":"pi"},"buildPass":{"val":"2","id":"pi"}},"id":"ct"}}
:enddata
:endrule

rule:
plugin=vanillaBlocks
number=25
data:
JSON:{{"val":{"blockName":{"val":"minecraft:anvil","id":"ss"},"meta":{"val":"3","id":"pi"},"buildPass":{"val":"0","id":"pi"}},"id":"ct"}}
:enddata
:endrule

rule:
plugin=vanillaDoors
number=26
data:
JSON:{{"val":{"sideFlag":{"val":"8","id":"pb"},"blockName":{"val":"minecraft:wooden_door","id":"ss"},"meta":{"val":"3","id":"pi"},"buildPass":{"val":"2","id":"pi"}},"id":"ct"}}
:enddata
:endrule

rule:
plugin=vanillaBlocks
number=27
data:
JSON:{{"val":{"blockName":{"val":"minecraft:snow_layer","id":"ss"},"meta":{"val":"3","id":"pi"},"buildPass":{"val":"2","id":"pi"}},"id":"ct"}}
:enddata
:endrule

rule:
plugin=vanillaBlocks
number=28
data:
JSON:{{"val":{"blockName":{"val":"minecraft:nether_brick_fence","id":"ss"},"meta":{"val":"0","id":"pi"},"buildPass":{"val":"0","id":"pi"}},"id":"ct"}}
:enddata
:endrule

rule:
plugin=vanillaBlocks
number=29
data:
JSON:{{"val":{"blockName":{"val":"minecraft:log","id":"ss"},"meta":{"val":"1","id":"pi"},"buildPass":{"val":"0","id":"pi"}},"id":"ct"}}
:enddata
:endrule

rule:
plugin=vanillaBlocks
number=30
data:
JSON:{{"val":{"blockName":{"val":"minecraft:planks","id":"ss"},"meta":{"val":"0","id":"pi"},"buildPass":{"val":"0","id":"pi"}},"id":"ct"}}
:enddata
:endrule

rule:
plugin=vanillaDoors
number=31
data:
JSON:{{"val":{"sideFlag":{"val":"0","id":"pb"},"blockName":{"val":"minecraft:wooden_door","id":"ss"},"meta":{"val":"8","id":"pi"},"buildPass":{"val":"2","id":"pi"}},"id":"ct"}}
:enddata
:endrule

rule:
plugin=vanillaBlocks
number=32
data:
JSON:{{"val":{"blockName":{"val":"minecraft:fence","id":"ss"},"meta":{"val":"0","id":"pi"},"buildPass":{"val":"0","id":"pi"}},"id":"ct"}}
:enddata
:endrule

rule:
plugin=vanillaBlocks
number=33
data:
JSON:{{"val":{"blockName":{"val":"minecraft:torch","id":"ss"},"meta":{"val":"4","id":"pi"},"buildPass":{"val":"2","id":"pi"}},"id":"ct"}}
:enddata
:endrule

rule:
plugin=vanillaDoors
number=34
data:
JSON:{{"val":{"sideFlag":{"val":"0","id":"pb"},"blockName":{"val":"minecraft:wooden_door","id":"ss"},"meta":{"val":"8","id":"pi"},"buildPass":{"val":"2","id":"pi"}},"id":"ct"}}
:enddata
:endrule

rule:
plugin=vanillaBlocks
number=35
data:
JSON:{{"val":{"blockName":{"val":"minecraft:torch","id":"ss"},"meta":{"val":"5","id":"pi"},"buildPass":{"val":"2","id":"pi"}},"id":"ct"}}
:enddata
:endrule

rule:
plugin=vanillaBlocks
number=36
data:
JSON:{{"val":{"blockName":{"val":"minecraft:torch","id":"ss"},"meta":{"val":"2","id":"pi"},"buildPass":{"val":"2","id":"pi"}},"id":"ct"}}
:enddata
:endrule

rule:
plugin=vanillaBlocks
number=37
data:
JSON:{{"val":{"blockName":{"val":"minecraft:log","id":"ss"},"meta":{"val":"5","id":"pi"},"buildPass":{"val":"0","id":"pi"}},"id":"ct"}}
:enddata
:endrule

rule:
plugin=vanillaBlocks
number=38
data:
JSON:{{"val":{"blockName":{"val":"minecraft:torch","id":"ss"},"meta":{"val":"1","id":"pi"},"buildPass":{"val":"2","id":"pi"}},"id":"ct"}}
:enddata
:endrule

rule:
plugin=vanillaBlocks
number=39
data:
JSON:{{"val":{"blockName":{"val":"minecraft:torch","id":"ss"},"meta":{"val":"3","id":"pi"},"buildPass":{"val":"2","id":"pi"}},"id":"ct"}}
:enddata
:endrule

rule:
plugin=vanillaBlocks
number=40
data:
JSON:{{"val":{"blockName":{"val":"minecraft:dark_oak_stairs","id":"ss"},"meta":{"val":"0","id":"pi"},"buildPass":{"val":"0","id":"pi"}},"id":"ct"}}
:enddata
:endrule

rule:
plugin=vanillaBlocks
number=41
data:
JSON:{{"val":{"blockName":{"val":"minecraft:dark_oak_stairs","id":"ss"},"meta":{"val":"2","id":"pi"},"buildPass":{"val":"0","id":"pi"}},"id":"ct"}}
:enddata
:endrule

rule:
plugin=vanillaBlocks
number=42
data:
JSON:{{"val":{"blockName":{"val":"minecraft:planks","id":"ss"},"meta":{"val":"1","id":"pi"},"buildPass":{"val":"0","id":"pi"}},"id":"ct"}}
:enddata
:endrule

rule:
plugin=vanillaBlocks
number=43
data:
JSON:{{"val":{"blockName":{"val":"minecraft:dark_oak_stairs","id":"ss"},"meta":{"val":"1","id":"pi"},"buildPass":{"val":"0","id":"pi"}},"id":"ct"}}
:enddata
:endrule

rule:
plugin=vanillaBlocks
number=44
data:
JSON:{{"val":{"blockName":{"val":"minecraft:dark_oak_stairs","id":"ss"},"meta":{"val":"3","id":"pi"},"buildPass":{"val":"0","id":"pi"}},"id":"ct"}}
:enddata
:endrule

rule:
plugin=vanillaBlocks
number=45
data:
JSON:{{"val":{"blockName":{"val":"minecraft:dark_oak_stairs","id":"ss"},"meta":{"val":"5","id":"pi"},"buildPass":{"val":"0","id":"pi"}},"id":"ct"}}
:enddata
:endrule

rule:
plugin=vanillaBlocks
number=46
data:
JSON:{{"val":{"blockName":{"val":"minecraft:dark_oak_stairs","id":"ss"},"meta":{"val":"4","id":"pi"},"buildPass":{"val":"0","id":"pi"}},"id":"ct"}}
:enddata
:endrule

rule:
plugin=vanillaBlocks
number=47
data:
JSON:{{"val":{"blockName":{"val":"minecraft:wooden_slab","id":"ss"},"meta":{"val":"9","id":"pi"},"buildPass":{"val":"0","id":"pi"}},"id":"ct"}}
:enddata
:endrule

rule:
plugin=vanillaBlocks
number=48
data:
JSON:{{"val":{"blockName":{"val":"minecraft:double_wooden_slab","id":"ss"},"meta":{"val":"5","id":"pi"},"buildPass":{"val":"0","id":"pi"}},"id":"ct"}}
:enddata
:endrule

rule:
plugin=vanillaBlocks
number=49
data:
JSON:{{"val":{"blockName":{"val":"minecraft:wooden_slab","id":"ss"},"meta":{"val":"1","id":"pi"},"buildPass":{"val":"0","id":"pi"}},"id":"ct"}}
:enddata
:endrule

rule:
plugin=vanillaBlocks
number=50
data:
JSON:{{"val":{"blockName":{"val":"minecraft:planks","id":"ss"},"meta":{"val":"5","id":"pi"},"buildPass":{"val":"0","id":"pi"}},"id":"ct"}}
:enddata
:endrule

rule:
plugin=vanillaBlocks
number=51
data:
JSON:{{"val":{"blockName":{"val":"minecraft:dark_oak_stairs","id":"ss"},"meta":{"val":"6","id":"pi"},"buildPass":{"val":"0","id":"pi"}},"id":"ct"}}
:enddata
:endrule

rule:
plugin=vanillaBlocks
number=52
data:
JSON:{{"val":{"blockName":{"val":"minecraft:wooden_slab","id":"ss"},"meta":{"val":"5","id":"pi"},"buildPass":{"val":"0","id":"pi"}},"id":"ct"}}
:enddata
:endrule

rule:
plugin=vanillaBlocks
number=53
data:
JSON:{{"val":{"blockName":{"val":"minecraft:dark_oak_stairs","id":"ss"},"meta":{"val":"7","id":"pi"},"buildPass":{"val":"0","id":"pi"}},"id":"ct"}}
:enddata
:endrule

#### ENTITIES ####
entity:
plugin=AWNpc
number=0
data:
position=6,2,7
JSON:{{"val":{"entityData":{"val":{"DropChances":{"val":[{"val":"1.0","id":"pf"},{"val":"1.0","id":"pf"},{"val":"1.0","id":"pf"},{"val":"1.0","id":"pf"},{"val":"1.0","id":"pf"}],"id":"ls"},"Attributes":{"val":[{"val":{"Name":{"val":"generic.maxHealth","id":"ss"},"Base":{"val":"20.0","id":"pd"}},"id":"ct"},{"val":{"Name":{"val":"generic.knockbackResistance","id":"ss"},"Base":{"val":"0.0","id":"pd"}},"id":"ct"},{"val":{"Name":{"val":"generic.movementSpeed","id":"ss"},"Base":{"val":"0.325","id":"pd"}},"id":"ct"},{"val":{"Name":{"val":"generic.followRange","id":"ss"},"Base":{"val":"60.0","id":"pd"}},"id":"ct"},{"val":{"Name":{"val":"generic.attackDamage","id":"ss"},"Base":{"val":"2.0","id":"pd"}},"id":"ct"}],"id":"ls"},"Motion":{"val":[{"val":"0.0","id":"pd"},{"val":"-0.0784000015258789","id":"pd"},{"val":"0.0","id":"pd"}],"id":"ls"},"CustomName":{"val":"","id":"ss"},"Health":{"val":"20","id":"ps"},"HealF":{"val":"20.0","id":"pf"},"CustomNameVisible":{"val":"0","id":"pb"},"AttackTime":{"val":"0","id":"ps"},"Fire":{"val":"-1","id":"ps"},"attackDamageOverride":{"val":"-1","id":"pi"},"Invulnerable":{"val":"0","id":"pb"},"DeathTime":{"val":"0","id":"ps"},"ForgeData":{"val":{"WITCInitialWidth":{"val":"0.6","id":"pf"},"WITCInitialHeight":{"val":"1.8","id":"pf"}},"id":"ct"},"AbsorptionAmount":{"val":"0.0","id":"pf"},"OnGround":{"val":"1","id":"pb"},"HurtTime":{"val":"0","id":"ps"},"Dimension":{"val":"0","id":"pi"},"Air":{"val":"300","id":"ps"},"customTex":{"val":"","id":"ss"},"armorValueOverride":{"val":"-1","id":"pi"},"Pos":{"val":[{"val":"1502.3878416100088","id":"pd"},{"val":"91.0","id":"pd"},{"val":"1575.813272173073","id":"pd"}],"id":"ls"},"CanPickUpLoot":{"val":"0","id":"pb"},"PortalCooldown":{"val":"0","id":"pi"},"PersistenceRequired":{"val":"1","id":"pb"},"shieldStack":{"val":{"item":{"val":"AncientWarfareNpc:iron_shield","id":"ss"},"damage":{"val":"0","id":"pi"},"quantity":{"val":"1","id":"pi"}},"id":"ct"},"Leashed":{"val":"0","id":"pb"},"owner":{"val":"OldMiniCollector","id":"ss"},"FallDistance":{"val":"0.0","id":"pf"},"Rotation":{"val":[{"val":"-248.37616","id":"pf"},{"val":"0.0","id":"pf"}],"id":"ls"},"levelingStats":{"val":{"level":{"val":"0","id":"pi"},"xp":{"val":"0","id":"pi"},"entryList":{"val":[],"id":"ls"}},"id":"ct"}},"id":"ct"},"xOffset":{"val":"0.3878416","id":"pf"},"mobID":{"val":"AncientWarfareNpc.viking.soldier","id":"ss"},"zOffset":{"val":"0.8132722","id":"pf"},"rotation":{"val":"-248.37616","id":"pf"},"equipmentData":{"val":{"equipmentContents":{"val":[{"val":{"item":{"val":"minecraft:iron_sword","id":"ss"},"damage":{"val":"0","id":"pi"},"quantity":{"val":"1","id":"pi"},"slot":{"val":"0","id":"pi"}},"id":"ct"}],"id":"ls"},"length":{"val":"5","id":"pi"}},"id":"ct"}},"id":"ct"}}
:enddata
:endentity

entity:
plugin=AWNpc
number=1
data:
position=4,2,25
JSON:{{"val":{"entityData":{"val":{"DropChances":{"val":[{"val":"1.0","id":"pf"},{"val":"1.0","id":"pf"},{"val":"1.0","id":"pf"},{"val":"1.0","id":"pf"},{"val":"1.0","id":"pf"}],"id":"ls"},"Attributes":{"val":[{"val":{"Name":{"val":"generic.maxHealth","id":"ss"},"Base":{"val":"20.0","id":"pd"}},"id":"ct"},{"val":{"Name":{"val":"generic.knockbackResistance","id":"ss"},"Base":{"val":"0.0","id":"pd"}},"id":"ct"},{"val":{"Name":{"val":"generic.movementSpeed","id":"ss"},"Base":{"val":"0.325","id":"pd"}},"id":"ct"},{"val":{"Name":{"val":"generic.followRange","id":"ss"},"Base":{"val":"60.0","id":"pd"}},"id":"ct"},{"val":{"Name":{"val":"generic.attackDamage","id":"ss"},"Base":{"val":"2.0","id":"pd"}},"id":"ct"}],"id":"ls"},"Motion":{"val":[{"val":"0.0","id":"pd"},{"val":"-0.0784000015258789","id":"pd"},{"val":"0.0","id":"pd"}],"id":"ls"},"CustomName":{"val":"","id":"ss"},"Health":{"val":"20","id":"ps"},"HealF":{"val":"20.0","id":"pf"},"CustomNameVisible":{"val":"0","id":"pb"},"AttackTime":{"val":"0","id":"ps"},"Fire":{"val":"-1","id":"ps"},"attackDamageOverride":{"val":"-1","id":"pi"},"Invulnerable":{"val":"0","id":"pb"},"DeathTime":{"val":"0","id":"ps"},"ForgeData":{"val":{"WITCInitialWidth":{"val":"0.6","id":"pf"},"WITCInitialHeight":{"val":"1.8","id":"pf"}},"id":"ct"},"AbsorptionAmount":{"val":"0.0","id":"pf"},"OnGround":{"val":"1","id":"pb"},"HurtTime":{"val":"0","id":"ps"},"Dimension":{"val":"0","id":"pi"},"Air":{"val":"300","id":"ps"},"customTex":{"val":"","id":"ss"},"armorValueOverride":{"val":"-1","id":"pi"},"Pos":{"val":[{"val":"1500.686652657765","id":"pd"},{"val":"91.0","id":"pd"},{"val":"1593.4307953160105","id":"pd"}],"id":"ls"},"CanPickUpLoot":{"val":"0","id":"pb"},"PortalCooldown":{"val":"0","id":"pi"},"PersistenceRequired":{"val":"1","id":"pb"},"shieldStack":{"val":{"item":{"val":"AncientWarfareNpc:iron_shield","id":"ss"},"damage":{"val":"0","id":"pi"},"quantity":{"val":"1","id":"pi"}},"id":"ct"},"Leashed":{"val":"0","id":"pb"},"owner":{"val":"OldMiniCollector","id":"ss"},"FallDistance":{"val":"0.0","id":"pf"},"Rotation":{"val":[{"val":"4.7479525","id":"pf"},{"val":"0.0","id":"pf"}],"id":"ls"},"levelingStats":{"val":{"level":{"val":"0","id":"pi"},"xp":{"val":"0","id":"pi"},"entryList":{"val":[],"id":"ls"}},"id":"ct"}},"id":"ct"},"xOffset":{"val":"0.68665266","id":"pf"},"mobID":{"val":"AncientWarfareNpc.viking.soldier","id":"ss"},"zOffset":{"val":"0.4307953","id":"pf"},"rotation":{"val":"4.7479525","id":"pf"},"equipmentData":{"val":{"equipmentContents":{"val":[{"val":{"item":{"val":"minecraft:iron_sword","id":"ss"},"damage":{"val":"0","id":"pi"},"quantity":{"val":"1","id":"pi"},"slot":{"val":"0","id":"pi"}},"id":"ct"}],"id":"ls"},"length":{"val":"5","id":"pi"}},"id":"ct"}},"id":"ct"}}
:enddata
:endentity

entity:
plugin=AWNpc
number=2
data:
position=5,2,28
JSON:{{"val":{"entityData":{"val":{"DropChances":{"val":[{"val":"1.0","id":"pf"},{"val":"1.0","id":"pf"},{"val":"1.0","id":"pf"},{"val":"1.0","id":"pf"},{"val":"1.0","id":"pf"}],"id":"ls"},"Attributes":{"val":[{"val":{"Name":{"val":"generic.maxHealth","id":"ss"},"Base":{"val":"20.0","id":"pd"}},"id":"ct"},{"val":{"Name":{"val":"generic.knockbackResistance","id":"ss"},"Base":{"val":"0.0","id":"pd"}},"id":"ct"},{"val":{"Name":{"val":"generic.movementSpeed","id":"ss"},"Base":{"val":"0.325","id":"pd"}},"id":"ct"},{"val":{"Name":{"val":"generic.followRange","id":"ss"},"Base":{"val":"60.0","id":"pd"}},"id":"ct"},{"val":{"Name":{"val":"generic.attackDamage","id":"ss"},"Base":{"val":"2.0","id":"pd"}},"id":"ct"}],"id":"ls"},"Motion":{"val":[{"val":"0.0","id":"pd"},{"val":"-0.0784000015258789","id":"pd"},{"val":"0.0","id":"pd"}],"id":"ls"},"CustomName":{"val":"","id":"ss"},"Health":{"val":"20","id":"ps"},"HealF":{"val":"20.0","id":"pf"},"CustomNameVisible":{"val":"0","id":"pb"},"ordersStack":{"val":{"item":{"val":"minecraft:arrow","id":"ss"},"damage":{"val":"0","id":"pi"},"quantity":{"val":"1","id":"pi"}},"id":"ct"},"AttackTime":{"val":"0","id":"ps"},"upkeepStack":{"val":{"item":{"val":"minecraft:arrow","id":"ss"},"damage":{"val":"0","id":"pi"},"quantity":{"val":"1","id":"pi"}},"id":"ct"},"Fire":{"val":"-1","id":"ps"},"attackDamageOverride":{"val":"-1","id":"pi"},"Invulnerable":{"val":"0","id":"pb"},"DeathTime":{"val":"0","id":"ps"},"ForgeData":{"val":{"WITCInitialWidth":{"val":"0.6","id":"pf"},"WITCInitialHeight":{"val":"1.8","id":"pf"}},"id":"ct"},"AbsorptionAmount":{"val":"0.0","id":"pf"},"OnGround":{"val":"1","id":"pb"},"HurtTime":{"val":"0","id":"ps"},"Dimension":{"val":"0","id":"pi"},"Air":{"val":"300","id":"ps"},"customTex":{"val":"","id":"ss"},"armorValueOverride":{"val":"-1","id":"pi"},"Pos":{"val":[{"val":"1501.5","id":"pd"},{"val":"91.0","id":"pd"},{"val":"1596.5","id":"pd"}],"id":"ls"},"CanPickUpLoot":{"val":"0","id":"pb"},"PortalCooldown":{"val":"0","id":"pi"},"PersistenceRequired":{"val":"1","id":"pb"},"Leashed":{"val":"0","id":"pb"},"owner":{"val":"OldMiniCollector","id":"ss"},"FallDistance":{"val":"0.0","id":"pf"},"Rotation":{"val":[{"val":"5.149628","id":"pf"},{"val":"0.0","id":"pf"}],"id":"ls"},"levelingStats":{"val":{"level":{"val":"0","id":"pi"},"xp":{"val":"0","id":"pi"},"entryList":{"val":[],"id":"ls"}},"id":"ct"}},"id":"ct"},"xOffset":{"val":"0.5","id":"pf"},"mobID":{"val":"AncientWarfareNpc.viking.archer","id":"ss"},"zOffset":{"val":"0.5","id":"pf"},"rotation":{"val":"5.149628","id":"pf"},"equipmentData":{"val":{"equipmentContents":{"val":[{"val":{"item":{"val":"minecraft:bow","id":"ss"},"damage":{"val":"0","id":"pi"},"quantity":{"val":"1","id":"pi"},"slot":{"val":"0","id":"pi"}},"id":"ct"}],"id":"ls"},"length":{"val":"5","id":"pi"}},"id":"ct"}},"id":"ct"}}
:enddata
:endentity

entity:
plugin=AWNpc
number=3
data:
position=9,2,6
JSON:{{"val":{"entityData":{"val":{"DropChances":{"val":[{"val":"1.0","id":"pf"},{"val":"1.0","id":"pf"},{"val":"1.0","id":"pf"},{"val":"1.0","id":"pf"},{"val":"1.0","id":"pf"}],"id":"ls"},"Attributes":{"val":[{"val":{"Name":{"val":"generic.maxHealth","id":"ss"},"Base":{"val":"20.0","id":"pd"}},"id":"ct"},{"val":{"Name":{"val":"generic.knockbackResistance","id":"ss"},"Base":{"val":"0.0","id":"pd"}},"id":"ct"},{"val":{"Name":{"val":"generic.movementSpeed","id":"ss"},"Base":{"val":"0.325","id":"pd"}},"id":"ct"},{"val":{"Name":{"val":"generic.followRange","id":"ss"},"Base":{"val":"60.0","id":"pd"}},"id":"ct"},{"val":{"Name":{"val":"generic.attackDamage","id":"ss"},"Base":{"val":"2.0","id":"pd"}},"id":"ct"}],"id":"ls"},"Motion":{"val":[{"val":"0.0","id":"pd"},{"val":"-0.0784000015258789","id":"pd"},{"val":"0.0","id":"pd"}],"id":"ls"},"CustomName":{"val":"","id":"ss"},"Health":{"val":"20","id":"ps"},"HealF":{"val":"20.0","id":"pf"},"CustomNameVisible":{"val":"0","id":"pb"},"AttackTime":{"val":"0","id":"ps"},"Fire":{"val":"-1","id":"ps"},"attackDamageOverride":{"val":"-1","id":"pi"},"Invulnerable":{"val":"0","id":"pb"},"DeathTime":{"val":"0","id":"ps"},"ForgeData":{"val":{"WITCInitialWidth":{"val":"0.6","id":"pf"},"WITCInitialHeight":{"val":"1.8","id":"pf"}},"id":"ct"},"AbsorptionAmount":{"val":"0.0","id":"pf"},"OnGround":{"val":"1","id":"pb"},"HurtTime":{"val":"0","id":"ps"},"Dimension":{"val":"0","id":"pi"},"Air":{"val":"300","id":"ps"},"customTex":{"val":"","id":"ss"},"armorValueOverride":{"val":"-1","id":"pi"},"Pos":{"val":[{"val":"1505.3788439997966","id":"pd"},{"val":"91.0","id":"pd"},{"val":"1574.3366820120095","id":"pd"}],"id":"ls"},"CanPickUpLoot":{"val":"0","id":"pb"},"PortalCooldown":{"val":"0","id":"pi"},"PersistenceRequired":{"val":"1","id":"pb"},"shieldStack":{"val":{"item":{"val":"AncientWarfareNpc:iron_shield","id":"ss"},"damage":{"val":"0","id":"pi"},"quantity":{"val":"1","id":"pi"}},"id":"ct"},"Leashed":{"val":"0","id":"pb"},"owner":{"val":"OldMiniCollector","id":"ss"},"FallDistance":{"val":"0.0","id":"pf"},"Rotation":{"val":[{"val":"5.190513","id":"pf"},{"val":"0.0","id":"pf"}],"id":"ls"},"levelingStats":{"val":{"level":{"val":"0","id":"pi"},"xp":{"val":"0","id":"pi"},"entryList":{"val":[],"id":"ls"}},"id":"ct"}},"id":"ct"},"xOffset":{"val":"0.378844","id":"pf"},"mobID":{"val":"AncientWarfareNpc.viking.soldier","id":"ss"},"zOffset":{"val":"0.33668202","id":"pf"},"rotation":{"val":"5.190513","id":"pf"},"equipmentData":{"val":{"equipmentContents":{"val":[{"val":{"item":{"val":"minecraft:iron_sword","id":"ss"},"damage":{"val":"0","id":"pi"},"quantity":{"val":"1","id":"pi"},"slot":{"val":"0","id":"pi"}},"id":"ct"}],"id":"ls"},"length":{"val":"5","id":"pi"}},"id":"ct"}},"id":"ct"}}
:enddata
:endentity

entity:
plugin=AWNpc
number=4
data:
position=14,2,1
JSON:{{"val":{"entityData":{"val":{"DropChances":{"val":[{"val":"1.0","id":"pf"},{"val":"1.0","id":"pf"},{"val":"1.0","id":"pf"},{"val":"1.0","id":"pf"},{"val":"1.0","id":"pf"}],"id":"ls"},"Attributes":{"val":[{"val":{"Name":{"val":"generic.maxHealth","id":"ss"},"Base":{"val":"20.0","id":"pd"}},"id":"ct"},{"val":{"Name":{"val":"generic.knockbackResistance","id":"ss"},"Base":{"val":"0.0","id":"pd"}},"id":"ct"},{"val":{"Name":{"val":"generic.movementSpeed","id":"ss"},"Base":{"val":"0.325","id":"pd"}},"id":"ct"},{"val":{"Name":{"val":"generic.followRange","id":"ss"},"Base":{"val":"60.0","id":"pd"}},"id":"ct"},{"val":{"Name":{"val":"generic.attackDamage","id":"ss"},"Base":{"val":"2.0","id":"pd"}},"id":"ct"}],"id":"ls"},"Motion":{"val":[{"val":"-0.08013546531435374","id":"pd"},{"val":"-0.0784000015258789","id":"pd"},{"val":"0.07152146535749845","id":"pd"}],"id":"ls"},"CustomName":{"val":"","id":"ss"},"Health":{"val":"20","id":"ps"},"HealF":{"val":"20.0","id":"pf"},"CustomNameVisible":{"val":"0","id":"pb"},"AttackTime":{"val":"0","id":"ps"},"Fire":{"val":"-1","id":"ps"},"attackDamageOverride":{"val":"-1","id":"pi"},"Invulnerable":{"val":"0","id":"pb"},"DeathTime":{"val":"0","id":"ps"},"ForgeData":{"val":{"WITCInitialWidth":{"val":"0.6","id":"pf"},"WITCInitialHeight":{"val":"1.8","id":"pf"}},"id":"ct"},"AbsorptionAmount":{"val":"0.0","id":"pf"},"OnGround":{"val":"1","id":"pb"},"HurtTime":{"val":"0","id":"ps"},"Dimension":{"val":"0","id":"pi"},"Air":{"val":"300","id":"ps"},"customTex":{"val":"","id":"ss"},"armorValueOverride":{"val":"-1","id":"pi"},"Pos":{"val":[{"val":"1510.4728866795645","id":"pd"},{"val":"91.125","id":"pd"},{"val":"1569.7875266798085","id":"pd"}],"id":"ls"},"CanPickUpLoot":{"val":"0","id":"pb"},"PortalCooldown":{"val":"0","id":"pi"},"PersistenceRequired":{"val":"1","id":"pb"},"Leashed":{"val":"0","id":"pb"},"owner":{"val":"OldMiniCollector","id":"ss"},"FallDistance":{"val":"0.0","id":"pf"},"Rotation":{"val":[{"val":"7631.4946","id":"pf"},{"val":"0.0","id":"pf"}],"id":"ls"},"levelingStats":{"val":{"level":{"val":"0","id":"pi"},"xp":{"val":"0","id":"pi"},"entryList":{"val":[],"id":"ls"}},"id":"ct"}},"id":"ct"},"xOffset":{"val":"0.47288668","id":"pf"},"mobID":{"val":"AncientWarfareNpc.viking.priest","id":"ss"},"zOffset":{"val":"0.78752667","id":"pf"},"rotation":{"val":"71.49463","id":"pf"},"equipmentData":{"val":{"equipmentContents":{"val":[{"val":{"item":{"val":"minecraft:book","id":"ss"},"damage":{"val":"0","id":"pi"},"quantity":{"val":"1","id":"pi"},"slot":{"val":"0","id":"pi"}},"id":"ct"}],"id":"ls"},"length":{"val":"5","id":"pi"}},"id":"ct"}},"id":"ct"}}
:enddata
:endentity

entity:
plugin=AWNpc
number=5
data:
position=9,2,29
JSON:{{"val":{"entityData":{"val":{"DropChances":{"val":[{"val":"1.0","id":"pf"},{"val":"1.0","id":"pf"},{"val":"1.0","id":"pf"},{"val":"1.0","id":"pf"},{"val":"1.0","id":"pf"}],"id":"ls"},"Attributes":{"val":[{"val":{"Name":{"val":"generic.maxHealth","id":"ss"},"Base":{"val":"20.0","id":"pd"}},"id":"ct"},{"val":{"Name":{"val":"generic.knockbackResistance","id":"ss"},"Base":{"val":"0.0","id":"pd"}},"id":"ct"},{"val":{"Name":{"val":"generic.movementSpeed","id":"ss"},"Base":{"val":"0.325","id":"pd"}},"id":"ct"},{"val":{"Name":{"val":"generic.followRange","id":"ss"},"Base":{"val":"60.0","id":"pd"}},"id":"ct"},{"val":{"Name":{"val":"generic.attackDamage","id":"ss"},"Base":{"val":"2.0","id":"pd"}},"id":"ct"}],"id":"ls"},"Motion":{"val":[{"val":"0.0","id":"pd"},{"val":"-0.0784000015258789","id":"pd"},{"val":"0.0","id":"pd"}],"id":"ls"},"CustomName":{"val":"","id":"ss"},"Health":{"val":"20","id":"ps"},"HealF":{"val":"20.0","id":"pf"},"CustomNameVisible":{"val":"0","id":"pb"},"AttackTime":{"val":"0","id":"ps"},"Fire":{"val":"-1","id":"ps"},"attackDamageOverride":{"val":"-1","id":"pi"},"Invulnerable":{"val":"0","id":"pb"},"DeathTime":{"val":"0","id":"ps"},"ForgeData":{"val":{"WITCInitialWidth":{"val":"0.6","id":"pf"},"WITCInitialHeight":{"val":"1.8","id":"pf"}},"id":"ct"},"AbsorptionAmount":{"val":"0.0","id":"pf"},"OnGround":{"val":"1","id":"pb"},"HurtTime":{"val":"0","id":"ps"},"Dimension":{"val":"0","id":"pi"},"Air":{"val":"300","id":"ps"},"customTex":{"val":"","id":"ss"},"armorValueOverride":{"val":"-1","id":"pi"},"Pos":{"val":[{"val":"1505.710248231837","id":"pd"},{"val":"91.0","id":"pd"},{"val":"1597.5621237744485","id":"pd"}],"id":"ls"},"CanPickUpLoot":{"val":"0","id":"pb"},"PortalCooldown":{"val":"0","id":"pi"},"PersistenceRequired":{"val":"1","id":"pb"},"shieldStack":{"val":{"item":{"val":"AncientWarfareNpc:iron_shield","id":"ss"},"damage":{"val":"0","id":"pi"},"quantity":{"val":"1","id":"pi"}},"id":"ct"},"Leashed":{"val":"0","id":"pb"},"owner":{"val":"OldMiniCollector","id":"ss"},"FallDistance":{"val":"0.0","id":"pf"},"Rotation":{"val":[{"val":"36.895775","id":"pf"},{"val":"0.0","id":"pf"}],"id":"ls"},"levelingStats":{"val":{"level":{"val":"0","id":"pi"},"xp":{"val":"0","id":"pi"},"entryList":{"val":[],"id":"ls"}},"id":"ct"}},"id":"ct"},"xOffset":{"val":"0.71024823","id":"pf"},"mobID":{"val":"AncientWarfareNpc.viking.soldier","id":"ss"},"zOffset":{"val":"0.5621238","id":"pf"},"rotation":{"val":"36.895775","id":"pf"},"equipmentData":{"val":{"equipmentContents":{"val":[{"val":{"item":{"val":"minecraft:iron_sword","id":"ss"},"damage":{"val":"0","id":"pi"},"quantity":{"val":"1","id":"pi"},"slot":{"val":"0","id":"pi"}},"id":"ct"}],"id":"ls"},"length":{"val":"5","id":"pi"}},"id":"ct"}},"id":"ct"}}
:enddata
:endentity

