# Ancient Warfare Structure Template File
# Auto-generated structure template file. created on: 2/18/2015 at: 13:22:24
# Lines beginning with # denote comments

header:
version=2.1
name=VikingJarlsHall
size=28,46,21
offset=12,6,18
:endheader

#### VALIDATION ####
validation:
type=ground
survival=false
worldGenEnabled=true
unique=false
preserveBlocks=false
selectionWeight=0
clusterValue=0
minDuplicateDistance=0
dimensionWhiteList=false
dimensionList=
biomeWhiteList=false
biomeList=taiga
leveling=0
fill=0
border=0
validTargetBlocks=
blockSwap=false
data:
:enddata
:endvalidation

#### LAYERS ####
layer: 0
1,1,1,1,1,1,1,1,1,1,1,1,1,1,1,1,1,1,1,1,1,1,1,1,1,1,1,1
1,1,1,1,1,1,1,1,1,1,1,1,1,1,1,1,1,1,1,1,1,1,1,1,1,1,1,1
1,1,1,1,1,1,1,1,1,1,1,1,1,1,1,1,1,1,1,1,1,1,1,1,1,1,1,1
1,1,1,1,1,1,1,1,1,1,1,1,1,1,1,1,1,1,1,1,1,1,1,1,1,1,1,1
1,1,1,1,1,1,1,1,1,1,1,1,1,1,1,1,1,1,1,1,1,1,1,1,1,1,1,1
1,1,1,1,1,1,1,1,1,1,1,1,1,1,1,1,1,1,1,1,1,1,1,1,1,1,1,1
1,1,1,1,1,1,1,1,1,1,1,1,1,1,1,1,1,1,1,1,1,1,1,1,1,1,1,1
1,1,1,1,1,1,1,1,1,1,1,1,1,1,1,1,1,1,1,1,1,1,1,1,1,1,1,1
1,1,1,1,1,1,1,1,1,1,1,1,1,1,1,1,1,1,1,1,1,1,1,1,1,1,1,1
1,1,1,1,1,1,1,1,1,1,1,1,1,1,1,1,1,1,1,1,1,1,1,1,1,1,1,1
1,1,1,1,1,1,1,1,1,1,1,1,1,1,1,1,1,1,1,1,1,1,1,1,1,1,1,1
1,1,1,1,1,1,1,1,1,1,1,1,1,1,1,1,1,1,1,1,1,1,1,1,1,1,1,1
1,1,1,1,1,1,1,1,1,1,1,1,1,1,1,1,1,1,1,1,1,1,1,1,1,1,1,1
1,1,1,1,1,1,1,1,1,1,1,1,1,1,1,1,1,1,1,1,1,1,1,1,1,1,1,1
1,1,1,1,1,1,1,1,1,1,1,1,1,1,1,1,1,1,1,1,1,1,1,1,1,1,1,1
1,1,1,1,1,1,1,1,1,1,1,1,1,1,1,1,1,1,1,1,1,1,1,1,1,1,1,1
1,1,1,1,1,1,1,1,1,1,1,1,1,1,1,1,1,1,1,1,1,1,1,1,1,1,1,1
1,1,1,1,1,1,1,1,1,1,1,1,1,1,1,1,1,1,1,1,1,1,1,1,1,1,1,1
1,1,1,1,1,1,1,1,1,1,1,1,1,1,1,1,1,1,1,1,1,1,1,1,1,1,1,1
1,1,1,1,1,1,1,1,1,1,1,1,1,1,1,1,1,1,1,1,1,1,1,1,1,1,1,1
1,1,1,1,1,1,1,1,1,1,1,1,1,1,1,1,1,1,1,1,1,1,1,1,1,1,1,1
:endlayer
layer: 1
1,1,1,1,1,1,1,1,1,1,1,1,1,1,1,1,1,1,1,1,1,1,1,1,1,1,1,1
1,1,1,1,1,1,1,1,1,1,1,1,1,1,1,1,1,1,1,1,1,1,1,1,1,1,1,1
1,1,1,1,1,1,1,1,1,1,1,1,1,1,1,1,1,1,1,1,1,1,1,1,1,1,1,1
1,1,1,1,1,1,1,1,1,1,1,1,1,1,1,1,1,1,1,1,1,1,1,1,1,1,1,1
1,1,1,1,1,1,1,1,1,1,1,1,1,1,1,1,1,1,1,1,1,1,1,1,1,1,1,1
1,1,1,1,1,1,1,1,1,1,1,1,1,1,1,1,1,1,1,1,1,1,1,1,1,1,1,1
1,1,1,1,1,1,1,1,1,1,1,1,1,1,1,1,1,1,1,1,1,1,1,1,1,1,1,1
1,1,1,1,1,1,1,1,1,1,1,1,1,1,1,1,1,1,1,1,1,1,1,1,1,1,1,1
1,1,1,1,1,1,1,1,1,1,1,1,1,1,1,1,1,1,1,1,1,1,1,1,1,1,1,1
1,1,1,1,1,1,1,1,1,1,1,1,1,1,1,1,1,1,1,1,1,1,1,1,1,1,1,1
1,1,1,1,1,1,1,1,1,1,1,1,1,1,1,1,1,1,1,1,1,1,1,1,1,1,1,1
1,1,1,1,1,1,1,1,1,1,1,1,1,1,1,1,1,1,1,1,1,1,1,1,1,1,1,1
1,1,1,1,1,1,1,1,1,1,1,1,1,1,1,1,1,1,1,1,1,1,1,1,1,1,1,1
1,1,1,1,1,1,1,1,1,1,1,1,1,1,1,1,1,1,1,1,1,1,1,1,1,1,1,1
1,1,1,1,1,1,1,1,1,1,1,1,1,1,1,1,1,1,1,1,1,1,1,1,1,1,1,1
1,1,1,1,1,1,1,1,1,1,1,1,1,1,1,1,1,1,1,1,1,1,1,1,1,1,1,1
1,1,1,1,1,1,1,1,1,1,1,1,1,1,1,1,1,1,1,1,1,1,1,1,1,1,1,1
1,1,1,1,1,1,1,1,1,1,1,1,1,1,1,1,1,1,1,1,1,1,1,1,1,1,1,1
1,1,1,1,1,1,1,1,1,1,1,1,1,1,1,1,1,1,1,1,1,1,1,1,1,1,1,1
1,1,1,1,1,1,1,1,1,1,1,1,1,1,1,1,1,1,1,1,1,1,1,1,1,1,1,1
1,1,1,1,1,1,1,1,1,1,1,1,1,1,1,1,1,1,1,1,1,1,1,1,1,1,1,1
:endlayer
layer: 2
1,1,1,1,1,1,1,1,1,1,1,1,1,1,1,1,1,1,1,1,1,1,1,1,1,1,1,1
1,1,1,1,1,1,1,1,1,1,1,1,1,1,1,1,1,1,1,1,1,1,1,1,1,1,1,1
1,1,1,1,1,1,1,1,1,1,1,1,1,1,1,1,1,1,1,1,1,1,1,1,1,1,1,1
1,1,1,1,1,1,1,1,1,1,1,1,1,1,1,1,1,1,1,1,1,1,1,1,1,1,1,1
1,1,1,1,1,1,1,1,1,1,1,1,1,1,1,1,1,1,1,1,1,1,1,1,1,1,1,1
1,1,1,1,1,1,1,1,1,1,1,1,1,1,1,1,1,1,1,1,1,1,1,1,1,1,1,1
1,1,1,1,1,1,1,1,1,1,1,1,1,1,1,1,1,1,1,1,1,1,1,1,1,1,1,1
1,1,1,1,1,1,1,1,1,1,1,1,1,1,1,1,1,1,1,1,1,1,1,1,1,1,1,1
1,1,1,1,1,1,1,1,1,1,1,1,1,1,1,1,1,1,1,1,1,1,1,1,1,1,1,1
1,1,1,1,1,1,1,1,1,1,1,1,1,1,1,1,1,1,1,1,1,1,1,1,1,1,1,1
1,1,1,1,1,1,1,1,1,1,1,1,1,1,1,1,1,1,1,1,1,1,1,1,1,1,1,1
1,1,1,1,1,1,1,1,1,1,1,1,1,1,1,1,1,1,1,1,1,1,1,1,1,1,1,1
1,1,1,1,1,1,1,1,1,1,1,1,1,1,1,1,1,1,1,1,1,1,1,1,1,1,1,1
1,1,1,1,1,1,1,1,1,1,1,1,1,1,1,1,1,1,1,1,1,1,1,1,1,1,1,1
1,1,1,1,1,1,1,1,1,1,1,1,1,1,1,1,1,1,1,1,1,1,1,1,1,1,1,1
1,1,1,1,1,1,1,1,1,1,1,1,1,1,1,1,1,1,1,1,1,1,1,1,1,1,1,1
1,1,1,1,1,1,1,1,1,1,1,1,1,1,1,1,1,1,1,1,1,1,1,1,1,1,1,1
1,1,1,1,1,1,1,1,1,1,1,1,1,1,1,1,1,1,1,1,1,1,1,1,1,1,1,1
1,1,1,1,1,1,1,1,1,1,1,1,1,1,1,1,1,1,1,1,1,1,1,1,1,1,1,1
1,1,1,1,1,1,1,1,1,1,1,1,1,1,1,1,1,1,1,1,1,1,1,1,1,1,1,1
1,1,1,1,1,1,1,1,1,1,1,1,1,1,1,1,1,1,1,1,1,1,1,1,1,1,1,1
:endlayer
layer: 3
1,1,1,1,1,1,1,1,1,1,1,1,1,1,1,1,1,1,1,1,1,1,1,1,1,1,1,1
1,1,1,1,1,1,1,1,1,1,1,1,1,1,1,1,1,1,1,1,1,1,1,1,1,1,1,1
1,1,1,1,1,1,1,1,1,1,1,1,1,1,1,1,1,1,1,1,1,1,1,1,1,1,1,1
1,1,1,1,1,1,1,1,1,1,1,1,1,1,1,1,1,1,1,1,1,1,1,1,1,1,1,1
1,1,1,1,1,1,1,1,1,1,1,1,1,1,1,1,1,1,1,1,1,1,1,1,1,1,1,1
1,1,1,1,1,1,1,1,1,1,1,1,1,1,1,1,1,1,1,1,1,1,1,1,1,1,1,1
1,1,1,1,1,1,1,1,1,1,1,1,1,1,1,1,1,1,1,1,1,1,1,1,1,1,1,1
1,1,1,1,1,1,1,1,1,1,1,1,1,1,1,1,1,1,1,1,1,1,1,1,1,1,1,1
1,1,1,1,1,1,1,1,1,1,1,1,1,1,1,1,1,1,1,1,1,1,1,1,1,1,1,1
1,1,1,1,1,1,1,1,1,1,1,1,1,1,1,1,1,1,1,1,1,1,1,1,1,1,1,1
1,1,1,1,1,1,1,1,1,1,1,1,1,1,1,1,1,1,1,1,1,1,1,1,1,1,1,1
1,1,1,1,1,1,1,1,1,1,1,1,1,1,1,1,1,1,1,1,1,1,1,1,1,1,1,1
1,1,1,1,1,1,1,1,1,1,1,1,1,1,1,1,1,1,1,1,1,1,1,1,1,1,1,1
1,1,1,1,1,1,1,1,1,1,1,1,1,1,1,1,1,1,1,1,1,1,1,1,1,1,1,1
1,1,1,1,1,1,1,1,1,1,1,1,1,1,1,1,1,1,1,1,1,1,1,1,1,1,1,1
1,1,1,1,1,1,1,1,1,1,1,1,1,1,1,1,1,1,1,1,1,1,1,1,1,1,1,1
1,1,1,1,1,1,1,1,1,1,1,1,1,1,1,1,1,1,1,1,1,1,1,1,1,1,1,1
1,1,1,1,1,1,1,1,1,1,1,1,1,1,1,1,1,1,1,1,1,1,1,1,1,1,1,1
1,1,1,1,1,1,1,1,1,1,1,1,1,1,1,1,1,1,1,1,1,1,1,1,1,1,1,1
1,1,1,1,1,1,1,1,1,1,1,1,1,1,1,1,1,1,1,1,1,1,1,1,1,1,1,1
1,1,1,1,1,1,1,1,1,1,1,1,1,1,1,1,1,1,1,1,1,1,1,1,1,1,1,1
:endlayer
layer: 4
1,1,1,1,1,1,1,1,1,1,1,1,1,1,1,1,1,1,1,1,1,1,1,1,1,1,1,1
1,1,1,1,1,1,1,1,1,1,1,1,1,1,1,1,1,1,1,1,1,1,1,1,1,1,1,1
1,1,1,1,1,1,1,1,1,1,1,1,1,1,1,1,1,1,1,1,1,1,1,1,1,1,1,1
1,1,1,1,1,1,1,1,1,1,1,1,1,1,1,1,1,1,1,1,1,1,1,1,1,1,1,1
1,1,1,1,1,1,1,1,1,1,1,1,1,1,1,1,1,1,1,1,1,1,1,1,1,1,1,1
1,1,1,1,1,1,1,1,1,1,1,1,1,1,1,1,1,1,1,1,1,1,1,1,1,1,1,1
1,1,1,1,1,1,1,1,1,1,1,1,1,1,1,1,1,1,1,1,1,1,1,1,1,1,1,1
1,1,1,1,1,1,1,1,1,1,1,1,1,1,1,1,1,1,1,1,1,1,1,1,1,1,1,1
1,1,1,1,1,1,1,1,1,1,1,1,1,1,1,1,1,1,1,1,1,1,1,1,1,1,1,1
1,1,1,1,1,1,1,1,1,1,1,1,1,1,1,1,1,1,1,1,1,1,1,1,1,1,1,1
1,1,1,1,1,1,1,1,1,1,1,1,1,1,1,1,1,1,1,1,1,1,1,1,1,1,1,1
1,1,1,1,1,1,1,1,1,1,1,1,1,1,1,1,1,1,1,1,1,1,1,1,1,1,1,1
1,1,1,1,1,1,1,1,1,1,1,1,1,1,1,1,1,1,1,1,1,1,1,1,1,1,1,1
1,1,1,1,1,1,1,1,1,1,1,1,1,1,1,1,1,1,1,1,1,1,1,1,1,1,1,1
1,1,1,1,1,1,1,1,1,1,1,1,1,1,1,1,1,1,1,1,1,1,1,1,1,1,1,1
1,1,1,1,1,1,1,1,1,1,1,1,1,1,1,1,1,1,1,1,1,1,1,1,1,1,1,1
1,1,1,1,1,1,1,1,1,1,1,1,1,1,1,1,1,1,1,1,1,1,1,1,1,1,1,1
1,1,1,1,1,1,1,1,1,1,1,1,1,1,1,1,1,1,1,1,1,1,1,1,1,1,1,1
1,1,1,1,1,1,1,1,1,1,1,1,1,1,1,1,1,1,1,1,1,1,1,1,1,1,1,1
1,1,1,1,1,1,1,1,1,1,1,1,1,1,1,1,1,1,1,1,1,1,1,1,1,1,1,1
1,1,1,1,1,1,1,1,1,1,1,1,1,1,1,1,1,1,1,1,1,1,1,1,1,1,1,1
:endlayer
layer: 5
2,2,2,2,2,2,2,2,2,2,2,2,2,2,2,2,2,2,2,2,2,2,2,2,2,2,2,2
2,2,2,2,2,2,2,2,2,2,2,2,2,2,2,2,2,2,2,2,2,2,2,2,2,2,2,2
2,2,2,2,2,2,2,2,2,2,2,2,2,2,2,2,2,2,2,2,2,2,2,2,2,2,2,2
2,2,2,2,1,1,1,1,1,1,1,1,1,1,1,1,1,1,1,1,1,1,1,1,2,2,2,2
2,2,2,2,1,1,3,3,3,3,3,4,4,3,3,4,4,3,3,3,3,3,1,1,2,2,2,2
2,2,2,2,1,3,3,3,3,1,3,4,1,3,3,1,4,3,1,3,3,3,3,1,2,2,2,2
2,2,2,2,1,3,3,3,3,3,3,4,4,3,3,4,4,3,3,3,3,3,3,1,2,2,2,2
2,2,2,1,1,4,4,4,1,3,3,3,4,4,4,4,3,3,3,1,4,4,4,1,1,2,2,2
2,2,1,1,1,4,1,4,4,4,4,4,3,3,3,3,4,4,4,4,4,1,4,1,1,1,2,2
2,2,3,3,3,3,3,3,3,3,3,4,3,5,5,3,4,3,3,3,3,3,3,3,3,3,2,2
2,2,3,3,3,3,3,3,3,3,3,4,3,5,5,3,4,3,3,3,3,3,3,3,3,3,2,2
2,2,1,1,1,4,1,4,4,4,4,4,3,3,3,3,4,4,4,4,4,1,4,1,1,1,2,2
2,2,2,1,1,4,4,4,3,3,3,3,4,4,4,4,3,3,3,1,4,4,4,1,1,2,2,2
2,2,2,2,1,3,3,3,3,3,3,4,4,3,3,4,4,3,3,3,3,3,3,1,2,2,2,2
2,2,2,2,1,3,3,3,3,1,3,4,4,3,3,4,4,3,1,3,3,3,3,1,2,2,2,2
2,2,2,2,1,1,3,3,3,3,3,4,4,3,3,4,4,3,3,3,3,3,1,1,2,2,2,2
2,2,2,2,1,1,1,1,1,1,1,1,1,3,3,1,1,1,1,1,1,1,1,1,2,2,2,2
2,2,2,2,2,2,2,2,2,2,2,1,1,3,3,1,1,2,2,2,2,2,2,2,2,2,2,2
2,2,2,2,2,2,2,2,2,2,2,2,1,3,3,1,2,2,2,2,2,2,2,2,2,2,2,2
2,2,2,2,2,2,2,2,2,2,2,2,2,2,2,2,2,2,2,2,2,2,2,2,2,2,2,2
2,2,2,2,2,2,2,2,2,2,2,2,2,2,2,2,2,2,2,2,2,2,2,2,2,2,2,2
:endlayer
layer: 6
6,6,6,6,6,6,6,6,6,6,6,6,6,6,6,6,6,6,6,6,6,6,6,6,6,6,6,6
6,6,6,6,0,6,6,6,6,6,6,6,6,6,6,6,6,6,6,6,6,6,6,0,6,6,6,6
6,6,6,0,0,0,6,6,6,6,6,6,6,6,6,6,6,6,6,6,6,9,0,0,0,6,6,6
6,6,0,0,8,3,3,3,8,3,3,3,8,3,3,8,3,3,3,8,3,3,3,8,0,0,6,6
6,6,6,0,3,8,0,0,0,0,0,0,0,0,0,0,0,0,0,0,0,0,8,3,0,6,6,6
6,6,6,6,3,0,0,0,0,8,0,0,8,0,0,8,0,0,8,0,0,0,0,3,6,6,6,6
6,6,6,9,3,0,0,0,0,14,14,0,0,0,0,0,0,13,13,0,0,0,0,3,6,6,6,6
6,0,7,8,8,0,0,0,8,0,0,0,0,0,0,0,0,0,0,8,0,0,0,8,8,7,0,6
0,0,8,3,8,0,8,0,0,0,0,0,4,15,15,4,0,0,0,0,0,8,0,8,3,8,0,0
6,0,0,20,0,0,0,0,0,0,0,0,15,17,17,15,0,0,0,0,0,0,0,0,19,0,0,6
6,0,0,18,0,0,0,0,0,0,0,0,15,17,17,15,0,0,0,0,0,0,0,0,16,0,0,6
0,0,8,3,8,0,8,0,0,0,0,0,4,15,15,4,0,0,0,0,0,8,0,8,3,8,0,0
6,0,7,8,8,0,0,0,8,0,0,0,0,0,0,0,0,0,0,8,0,0,0,8,8,7,0,6
6,6,6,9,3,0,0,0,0,14,14,0,0,0,0,0,0,13,13,0,0,0,0,3,9,6,6,6
6,6,6,6,3,0,0,0,0,8,0,0,8,0,0,8,0,0,8,0,0,0,0,3,6,6,6,6
6,6,6,12,3,8,0,0,0,0,0,0,0,0,0,0,0,0,0,0,0,0,8,3,0,6,6,6
6,6,6,6,8,3,3,3,8,3,3,3,8,0,0,8,3,3,3,8,3,3,3,8,0,0,6,6
6,6,6,9,6,9,6,0,6,6,9,8,3,11,10,3,8,6,9,6,6,6,0,0,0,9,6,6
6,6,6,6,6,6,6,6,9,6,6,7,8,0,0,8,7,6,6,6,6,6,6,0,6,6,6,6
6,6,6,6,6,6,6,6,6,6,6,0,0,0,0,0,0,6,6,6,6,6,6,6,6,6,6,6
6,6,6,6,6,6,6,6,6,6,6,6,0,6,6,0,6,6,6,6,6,6,6,6,6,6,6,6
:endlayer
layer: 7
0,0,0,0,0,0,0,0,0,0,0,0,0,0,0,0,0,0,0,0,0,0,0,0,0,0,0,0
0,0,0,0,0,0,0,0,0,0,0,0,0,0,0,0,0,0,0,0,0,0,0,0,0,0,0,0
0,0,0,0,34,0,0,0,0,0,0,0,0,0,0,0,0,0,0,0,0,0,0,34,0,0,0,0
0,0,0,28,8,8,8,8,8,8,8,8,8,8,8,8,8,8,8,8,8,8,8,8,24,0,0,0
0,0,0,0,8,8,0,0,0,0,0,0,0,0,0,0,0,0,0,0,0,0,8,8,0,0,0,0
0,0,0,0,8,0,0,0,0,8,0,0,8,0,0,8,0,0,8,0,0,0,0,8,0,0,0,0
0,0,0,0,8,0,0,0,0,14,0,0,0,0,0,0,0,0,13,0,0,0,0,8,0,0,0,0
0,0,33,8,8,0,0,0,8,0,0,0,0,0,0,0,0,0,0,8,0,0,0,8,8,33,0,0
0,28,8,3,8,0,8,0,0,0,0,0,26,27,27,26,0,0,0,0,0,8,0,8,3,8,24,0
0,0,0,32,0,0,0,0,0,0,0,0,27,0,0,27,0,0,0,0,0,0,0,0,31,0,0,0
0,0,0,30,0,0,0,0,0,0,0,0,27,0,0,27,0,0,0,0,0,0,0,0,29,0,0,0
0,28,8,3,8,0,8,0,0,0,0,0,26,27,27,26,0,0,0,0,0,8,0,8,3,8,24,0
0,0,25,8,8,0,0,0,8,0,0,0,0,0,0,0,0,0,0,8,0,0,0,8,8,25,0,0
0,0,0,0,8,0,0,0,0,14,0,0,0,0,0,0,0,0,13,0,0,0,0,8,0,0,0,0
0,0,0,0,8,0,0,0,0,8,0,0,8,0,0,8,0,0,8,0,0,0,0,8,0,0,0,0
0,0,0,0,8,8,0,0,0,0,0,0,0,0,0,0,0,0,0,0,0,0,8,8,0,0,0,0
0,0,0,0,8,8,8,8,8,8,8,8,8,0,0,8,8,8,8,8,8,8,8,8,24,0,0,0
0,0,0,0,0,0,0,0,0,0,0,8,3,23,22,3,8,0,0,0,0,0,0,21,0,0,0,0
0,0,0,0,0,0,0,0,0,0,0,13,8,0,0,8,14,0,0,0,0,0,0,0,0,0,0,0
0,0,0,0,0,0,0,0,0,0,0,0,21,0,0,21,0,0,0,0,0,0,0,0,0,0,0,0
0,0,0,0,0,0,0,0,0,0,0,0,0,0,0,0,0,0,0,0,0,0,0,0,0,0,0,0
:endlayer
layer: 8
0,0,0,0,0,0,0,0,0,0,0,0,0,0,0,0,0,0,0,0,0,0,0,0,0,0,0,0
0,0,0,0,0,0,0,0,0,0,0,0,0,0,0,0,0,0,0,0,0,0,0,0,0,0,0,0
0,0,0,35,33,33,33,33,33,33,33,33,33,33,33,33,33,33,33,33,33,33,33,33,35,0,0,0
0,0,0,13,3,3,3,3,3,3,3,3,3,3,3,3,3,3,3,3,3,3,3,3,14,0,0,0
0,0,0,13,3,8,3,3,3,0,0,0,0,0,0,0,0,0,0,3,3,3,8,3,14,0,0,0
0,0,0,13,3,3,3,3,3,8,0,0,8,0,0,8,0,0,8,3,3,3,3,3,14,0,0,0
0,0,0,13,3,3,3,3,14,0,0,0,0,0,0,0,0,0,0,13,3,3,3,3,14,0,0,0
0,0,0,13,3,3,3,3,8,0,0,0,0,0,0,0,0,0,0,8,3,3,3,3,14,0,0,0
0,0,33,3,3,0,8,0,0,0,0,0,26,0,0,26,0,0,0,0,0,8,0,3,3,33,0,0
0,0,3,3,3,0,0,0,0,0,0,0,0,0,0,0,0,0,0,0,0,0,0,3,3,3,0,0
0,0,3,3,3,0,0,0,0,0,0,0,0,0,0,0,0,0,0,0,0,0,0,3,3,3,0,0
0,0,25,3,3,0,8,0,0,0,0,0,26,0,0,26,0,0,0,0,0,8,0,3,3,25,0,0
0,0,0,13,3,3,3,3,8,0,0,0,0,0,0,0,0,0,0,8,3,3,3,3,14,0,0,0
0,0,0,13,3,3,3,3,14,0,0,0,0,0,0,0,0,0,0,13,3,3,3,3,14,0,0,0
0,0,0,13,3,3,3,3,3,8,0,0,8,0,0,8,0,0,8,3,3,3,3,3,14,0,0,0
0,0,0,13,3,8,3,3,3,0,0,0,0,0,0,0,0,0,0,3,3,3,8,3,14,0,0,0
0,0,0,13,3,3,3,3,3,3,3,3,8,0,0,8,3,3,3,3,3,3,3,3,14,0,0,0
0,0,0,35,25,25,25,25,25,25,25,25,3,3,3,3,25,25,25,25,25,25,25,25,35,0,0,0
0,0,0,0,0,0,0,0,0,0,0,0,13,3,3,14,0,0,0,0,0,0,0,0,0,0,0,0
0,0,0,0,0,0,0,0,0,0,0,0,0,0,0,0,0,0,0,0,0,0,0,0,0,0,0,0
0,0,0,0,0,0,0,0,0,0,0,0,0,0,0,0,0,0,0,0,0,0,0,0,0,0,0,0
:endlayer
layer: 9
0,0,0,0,0,0,0,0,0,0,0,0,0,0,0,0,0,0,0,0,0,0,0,0,0,0,0,0
0,0,0,0,0,0,0,0,0,0,0,0,0,0,0,0,0,0,0,0,0,0,0,0,0,0,0,0
0,0,0,0,0,0,0,0,0,0,0,0,0,0,0,0,0,0,0,0,0,0,0,0,0,0,0,0
0,0,0,0,35,33,33,33,33,33,33,33,33,33,33,33,33,33,33,33,33,33,33,35,0,0,0,0
0,0,0,0,13,3,3,3,3,3,3,3,3,3,3,3,3,3,3,3,3,3,3,14,0,0,0,0
0,0,0,0,13,3,0,0,0,8,0,28,8,24,0,8,0,0,8,0,0,0,3,14,0,0,0,0
0,0,0,0,13,3,0,0,0,0,0,0,21,0,0,0,0,0,0,0,0,0,3,14,0,0,0,0
0,0,0,0,13,3,0,35,8,0,0,0,0,0,0,0,0,0,0,8,35,0,3,14,0,0,0,0
0,0,0,6,13,3,8,3,24,0,0,0,26,0,0,26,0,0,0,28,3,8,3,14,6,0,0,0
0,0,33,33,3,3,3,3,3,0,0,0,0,0,0,0,0,0,0,3,3,3,3,3,33,33,0,0
0,0,25,25,3,3,3,3,3,0,0,0,0,0,0,0,0,0,0,3,3,3,3,3,25,25,0,0
0,0,0,6,13,3,8,3,24,0,0,0,26,0,0,26,0,0,0,28,3,8,3,14,6,0,0,0
0,0,0,0,13,3,0,35,8,0,0,0,0,0,0,0,0,0,0,8,35,0,3,14,0,0,0,0
0,0,0,0,13,3,0,0,0,0,0,0,34,0,0,34,0,0,0,0,0,0,3,14,0,0,0,0
0,0,0,0,13,3,0,0,0,8,0,0,8,24,28,8,0,0,8,0,0,0,3,14,0,0,0,0
0,0,0,0,13,3,3,3,3,3,3,3,3,3,3,3,3,3,3,3,3,3,3,14,0,0,0,0
0,0,0,0,35,25,25,25,25,25,25,25,25,3,3,25,25,25,25,25,25,25,25,35,0,0,0,0
0,0,0,0,0,0,0,0,0,0,0,0,6,13,14,6,0,0,0,0,0,0,0,0,0,0,0,0
0,0,0,0,0,0,0,0,0,0,0,0,0,13,14,0,0,0,0,0,0,0,0,0,0,0,0,0
0,0,0,0,0,0,0,0,0,0,0,0,0,0,0,0,0,0,0,0,0,0,0,0,0,0,0,0
0,0,0,0,0,0,0,0,0,0,0,0,0,0,0,0,0,0,0,0,0,0,0,0,0,0,0,0
:endlayer
layer: 10
0,0,0,0,0,0,0,0,0,0,0,0,0,0,0,0,0,0,0,0,0,0,0,0,0,0,0,0
0,0,0,0,0,0,0,0,0,0,0,0,0,0,0,0,0,0,0,0,0,0,0,0,0,0,0,0
0,0,0,0,0,0,0,0,0,0,0,0,0,0,0,0,0,0,0,0,0,0,0,0,0,0,0,0
0,0,0,0,0,0,0,0,0,0,0,0,0,0,0,0,0,0,0,0,0,0,0,0,0,0,0,0
0,0,0,0,0,7,8,7,3,7,3,3,7,3,3,7,3,3,7,3,7,8,7,0,0,0,0,0
0,0,0,0,0,8,24,0,0,8,0,0,8,0,0,8,0,0,8,0,0,28,8,0,0,0,0,0
0,0,0,0,0,7,0,0,0,0,0,0,0,0,0,0,0,0,0,0,0,0,7,0,0,0,0,0
0,0,0,0,0,3,0,0,8,0,0,0,0,0,0,0,0,0,0,8,0,0,3,0,0,0,0,0
0,0,0,0,0,7,8,0,0,0,0,0,4,0,0,4,0,0,0,0,0,8,7,0,0,0,0,0
0,0,25,0,6,3,0,0,13,3,0,0,0,0,0,0,0,0,3,14,0,0,3,6,0,25,0,0
0,0,33,0,6,3,0,0,13,3,0,0,0,0,0,0,0,0,3,14,0,0,3,6,0,33,0,0
0,0,0,0,0,7,8,0,0,0,0,0,4,0,0,4,0,0,0,0,0,8,7,0,0,0,0,0
0,0,0,0,0,3,0,0,8,0,0,0,0,0,0,0,0,0,0,8,0,0,3,0,0,0,0,0
0,0,0,0,0,7,0,0,0,0,0,0,0,0,0,0,0,0,0,0,0,0,7,0,0,0,0,0
0,0,0,0,0,8,24,0,0,8,0,0,8,0,0,8,0,0,8,0,0,28,8,0,0,0,0,0
0,0,0,0,0,7,8,7,3,7,3,3,7,3,3,7,3,3,7,3,7,8,7,0,0,0,0,0
0,0,0,0,0,0,0,0,0,0,0,0,0,6,6,0,0,0,0,0,0,0,0,0,0,0,0,0
0,0,0,0,0,0,0,0,0,0,0,0,0,0,0,0,0,0,0,0,0,0,0,0,0,0,0,0
0,0,0,0,0,0,0,0,0,0,0,0,0,14,13,0,0,0,0,0,0,0,0,0,0,0,0,0
0,0,0,0,0,0,0,0,0,0,0,0,0,0,0,0,0,0,0,0,0,0,0,0,0,0,0,0
0,0,0,0,0,0,0,0,0,0,0,0,0,0,0,0,0,0,0,0,0,0,0,0,0,0,0,0
:endlayer
layer: 11
0,0,0,0,0,0,0,0,0,0,0,0,0,0,0,0,0,0,0,0,0,0,0,0,0,0,0,0
0,0,0,0,0,0,0,0,0,0,0,0,0,0,0,0,0,0,0,0,0,0,0,0,0,0,0,0
0,0,0,0,0,0,0,0,0,0,0,0,0,0,0,0,0,0,0,0,0,0,0,0,0,0,0,0
0,0,0,0,0,0,0,0,0,0,0,0,0,0,0,0,0,0,0,0,0,0,0,0,0,0,0,0
0,0,0,0,0,35,33,33,33,33,33,33,33,33,33,33,33,33,33,33,33,33,35,0,0,0,0,0
0,0,0,0,0,13,3,3,3,8,3,3,8,3,3,8,3,3,8,3,3,3,14,0,0,0,0,0
0,0,0,0,0,13,3,0,0,0,0,0,0,0,0,0,0,0,0,0,0,3,14,0,0,0,0,0
0,0,0,0,0,33,3,0,8,0,0,0,0,0,0,0,0,0,0,8,0,3,33,0,0,0,0,0
0,0,0,0,0,3,8,0,0,0,0,0,4,4,4,4,0,0,0,0,0,8,3,0,0,0,0,0
0,0,0,0,0,7,0,0,0,13,3,0,4,4,4,4,0,3,14,0,0,0,7,0,0,0,0,0
0,0,0,0,0,7,0,0,0,13,3,0,4,4,4,4,0,3,14,0,0,0,7,0,0,0,0,0
0,0,0,0,0,3,8,0,0,0,0,0,4,4,4,4,0,0,0,0,0,8,3,0,0,0,0,0
0,0,0,0,0,25,3,0,8,0,0,0,0,0,0,0,0,0,0,8,0,3,25,0,0,0,0,0
0,0,0,0,0,13,3,0,0,0,0,0,0,0,0,0,0,0,0,0,0,3,14,0,0,0,0,0
0,0,0,0,0,13,3,3,3,8,3,3,8,3,3,8,3,3,8,3,3,3,14,0,0,0,0,0
0,0,0,0,0,35,25,25,25,25,25,25,25,25,25,25,25,25,25,25,25,25,35,0,0,0,0,0
0,0,0,0,0,0,0,0,0,0,0,0,0,0,0,0,0,0,0,0,0,0,0,0,0,0,0,0
0,0,0,0,0,0,0,0,0,0,0,0,0,0,0,0,0,0,0,0,0,0,0,0,0,0,0,0
0,0,0,0,0,0,0,0,0,0,0,0,0,0,0,0,0,0,0,0,0,0,0,0,0,0,0,0
0,0,0,0,0,0,0,0,0,0,0,0,0,0,0,0,0,0,0,0,0,0,0,0,0,0,0,0
0,0,0,0,0,0,0,0,0,0,0,0,0,0,0,0,0,0,0,0,0,0,0,0,0,0,0,0
:endlayer
layer: 12
0,0,0,0,0,0,0,0,0,0,0,0,0,0,0,0,0,0,0,0,0,0,0,0,0,0,0,0
0,0,0,0,0,0,0,0,0,0,0,0,0,0,0,0,0,0,0,0,0,0,0,0,0,0,0,0
0,0,0,0,0,0,0,0,0,0,0,0,0,0,0,0,0,0,0,0,0,0,0,0,0,0,0,0
0,0,0,0,0,0,0,0,0,0,0,0,0,0,0,0,0,0,0,0,0,0,0,0,0,0,0,0
0,0,0,0,0,0,0,0,0,0,0,0,0,0,0,0,0,0,0,0,0,0,0,0,0,0,0,0
0,0,0,0,0,0,35,33,33,33,33,33,33,33,33,33,33,33,33,33,33,35,0,0,0,0,0,0
0,0,0,0,0,0,13,3,3,3,3,3,3,3,3,3,3,3,3,3,3,14,0,0,0,0,0,0
0,0,0,0,0,0,13,3,8,3,3,3,3,3,3,3,3,3,3,8,3,14,0,0,0,0,0,0
0,0,0,0,0,33,3,0,0,3,3,3,3,3,3,3,3,3,3,0,3,3,33,0,0,0,0,0
0,0,0,0,0,3,0,0,0,0,13,3,3,3,3,3,3,14,0,0,0,0,3,0,0,0,0,0
0,0,0,0,0,3,0,0,0,0,13,3,3,3,3,3,3,14,0,0,0,0,3,0,0,0,0,0
0,0,0,0,0,25,3,0,0,3,3,3,3,3,3,3,3,3,3,0,3,3,25,0,0,0,0,0
0,0,0,0,0,0,13,3,8,3,3,3,3,3,3,3,3,3,3,8,3,14,0,0,0,0,0,0
0,0,0,0,0,0,13,3,3,3,3,3,3,3,3,3,3,3,3,3,3,14,0,0,0,0,0,0
0,0,0,0,0,0,35,25,25,25,25,25,25,25,25,25,25,25,25,25,25,35,0,0,0,0,0,0
0,0,0,0,0,0,0,0,0,0,0,0,0,0,0,0,0,0,0,0,0,0,0,0,0,0,0,0
0,0,0,0,0,0,0,0,0,0,0,0,0,0,0,0,0,0,0,0,0,0,0,0,0,0,0,0
0,0,0,0,0,0,0,0,0,0,0,0,0,0,0,0,0,0,0,0,0,0,0,0,0,0,0,0
0,0,0,0,0,0,0,0,0,0,0,0,0,0,0,0,0,0,0,0,0,0,0,0,0,0,0,0
0,0,0,0,0,0,0,0,0,0,0,0,0,0,0,0,0,0,0,0,0,0,0,0,0,0,0,0
0,0,0,0,0,0,0,0,0,0,0,0,0,0,0,0,0,0,0,0,0,0,0,0,0,0,0,0
:endlayer
layer: 13
0,0,0,0,0,0,0,0,0,0,0,0,0,0,0,0,0,0,0,0,0,0,0,0,0,0,0,0
0,0,0,0,0,0,0,0,0,0,0,0,0,0,0,0,0,0,0,0,0,0,0,0,0,0,0,0
0,0,0,0,0,0,0,0,0,0,0,0,0,0,0,0,0,0,0,0,0,0,0,0,0,0,0,0
0,0,0,0,0,0,0,0,0,0,0,0,0,0,0,0,0,0,0,0,0,0,0,0,0,0,0,0
0,0,0,0,0,0,0,0,0,0,0,0,0,0,0,0,0,0,0,0,0,0,0,0,0,0,0,0
0,0,0,0,0,0,0,0,0,0,0,0,0,0,0,0,0,0,0,0,0,0,0,0,0,0,0,0
0,0,0,0,0,0,0,35,33,33,33,33,33,33,33,33,33,33,33,33,35,0,0,0,0,0,0,0
0,0,0,0,0,0,0,13,8,3,3,3,3,3,3,3,3,3,3,8,14,0,0,0,0,0,0,0
0,0,0,0,0,0,6,13,3,0,0,0,39,38,38,37,0,0,0,3,14,6,0,0,0,0,0,0
0,0,0,0,0,33,33,3,0,0,0,0,0,36,36,0,0,0,0,0,3,33,33,0,0,0,0,0
0,0,0,0,0,25,25,3,0,0,0,0,0,0,0,0,0,0,0,0,3,25,25,0,0,0,0,0
0,0,0,0,0,0,6,13,3,0,0,0,0,0,0,0,0,0,0,3,14,6,0,0,0,0,0,0
0,0,0,0,0,0,0,13,8,3,3,3,3,3,3,3,3,3,3,8,14,0,0,0,0,0,0,0
0,0,0,0,0,0,0,35,25,25,25,25,25,25,25,25,25,25,25,25,35,0,0,0,0,0,0,0
0,0,0,0,0,0,0,0,0,0,0,0,0,0,0,0,0,0,0,0,0,0,0,0,0,0,0,0
0,0,0,0,0,0,0,0,0,0,0,0,0,0,0,0,0,0,0,0,0,0,0,0,0,0,0,0
0,0,0,0,0,0,0,0,0,0,0,0,0,0,0,0,0,0,0,0,0,0,0,0,0,0,0,0
0,0,0,0,0,0,0,0,0,0,0,0,0,0,0,0,0,0,0,0,0,0,0,0,0,0,0,0
0,0,0,0,0,0,0,0,0,0,0,0,0,0,0,0,0,0,0,0,0,0,0,0,0,0,0,0
0,0,0,0,0,0,0,0,0,0,0,0,0,0,0,0,0,0,0,0,0,0,0,0,0,0,0,0
0,0,0,0,0,0,0,0,0,0,0,0,0,0,0,0,0,0,0,0,0,0,0,0,0,0,0,0
:endlayer
layer: 14
0,0,0,0,0,0,0,0,0,0,0,0,0,0,0,0,0,0,0,0,0,0,0,0,0,0,0,0
0,0,0,0,0,0,0,0,0,0,0,0,0,0,0,0,0,0,0,0,0,0,0,0,0,0,0,0
0,0,0,0,0,0,0,0,0,0,0,0,0,0,0,0,0,0,0,0,0,0,0,0,0,0,0,0
0,0,0,0,0,0,0,0,0,0,0,0,0,0,0,0,0,0,0,0,0,0,0,0,0,0,0,0
0,0,0,0,0,0,0,0,0,0,0,0,0,0,0,0,0,0,0,0,0,0,0,0,0,0,0,0
0,0,0,0,0,0,0,0,0,0,0,0,0,0,0,0,0,0,0,0,0,0,0,0,0,0,0,0
0,0,0,0,0,0,0,0,34,0,34,0,34,0,0,34,0,34,0,34,0,0,0,0,0,0,0,0
0,0,0,0,0,0,0,28,8,7,3,7,3,7,7,3,7,3,7,8,24,0,0,0,0,0,0,0
0,0,0,0,0,0,0,0,3,0,0,0,0,0,0,0,0,0,0,3,0,0,0,0,0,0,0,0
0,0,0,0,0,25,0,0,3,0,0,0,0,0,0,0,0,0,0,3,0,0,25,0,0,0,0,0
0,0,0,0,0,33,0,0,3,0,0,0,0,0,0,0,0,0,0,3,0,0,33,0,0,0,0,0
0,0,0,0,0,0,0,0,3,0,0,0,0,0,0,0,0,0,0,3,0,0,0,0,0,0,0,0
0,0,0,0,0,0,0,28,8,7,3,7,3,7,7,3,7,3,7,8,24,0,0,0,0,0,0,0
0,0,0,0,0,0,0,0,21,0,21,0,21,0,0,21,0,21,0,21,0,0,0,0,0,0,0,0
0,0,0,0,0,0,0,0,0,0,0,0,0,0,0,0,0,0,0,0,0,0,0,0,0,0,0,0
0,0,0,0,0,0,0,0,0,0,0,0,0,0,0,0,0,0,0,0,0,0,0,0,0,0,0,0
0,0,0,0,0,0,0,0,0,0,0,0,0,0,0,0,0,0,0,0,0,0,0,0,0,0,0,0
0,0,0,0,0,0,0,0,0,0,0,0,0,0,0,0,0,0,0,0,0,0,0,0,0,0,0,0
0,0,0,0,0,0,0,0,0,0,0,0,0,0,0,0,0,0,0,0,0,0,0,0,0,0,0,0
0,0,0,0,0,0,0,0,0,0,0,0,0,0,0,0,0,0,0,0,0,0,0,0,0,0,0,0
0,0,0,0,0,0,0,0,0,0,0,0,0,0,0,0,0,0,0,0,0,0,0,0,0,0,0,0
:endlayer
layer: 15
0,0,0,0,0,0,0,0,0,0,0,0,0,0,0,0,0,0,0,0,0,0,0,0,0,0,0,0
0,0,0,0,0,0,0,0,0,0,0,0,0,0,0,0,0,0,0,0,0,0,0,0,0,0,0,0
0,0,0,0,0,0,0,0,0,0,0,0,0,0,0,0,0,0,0,0,0,0,0,0,0,0,0,0
0,0,0,0,0,0,0,0,0,0,0,0,0,0,0,0,0,0,0,0,0,0,0,0,0,0,0,0
0,0,0,0,0,0,0,0,0,0,0,0,0,0,0,0,0,0,0,0,0,0,0,0,0,0,0,0
0,0,0,0,0,0,0,0,0,0,0,0,0,0,0,0,0,0,0,0,0,0,0,0,0,0,0,0
0,0,0,0,0,0,0,33,33,33,33,33,33,33,33,33,33,33,33,33,33,0,0,0,0,0,0,0
0,0,0,0,0,0,0,0,8,3,3,3,3,3,3,3,3,3,3,8,0,0,0,0,0,0,0,0
0,0,0,0,0,0,0,0,7,0,0,21,0,0,0,0,21,0,0,7,0,0,0,0,0,0,0,0
0,0,0,0,0,0,0,0,3,24,0,0,0,0,0,0,0,0,28,3,0,0,0,0,0,0,0,0
0,0,0,0,0,0,0,0,3,24,0,0,0,0,0,0,0,0,28,3,0,0,0,0,0,0,0,0
0,0,0,0,0,0,0,0,7,0,0,34,0,0,0,0,34,0,0,7,0,0,0,0,0,0,0,0
0,0,0,0,0,0,0,0,8,3,3,3,3,3,3,3,3,3,3,8,0,0,0,0,0,0,0,0
0,0,0,0,0,0,0,25,25,25,25,25,25,25,25,25,25,25,25,25,25,0,0,0,0,0,0,0
0,0,0,0,0,0,0,0,0,0,0,0,0,0,0,0,0,0,0,0,0,0,0,0,0,0,0,0
0,0,0,0,0,0,0,0,0,0,0,0,0,0,0,0,0,0,0,0,0,0,0,0,0,0,0,0
0,0,0,0,0,0,0,0,0,0,0,0,0,0,0,0,0,0,0,0,0,0,0,0,0,0,0,0
0,0,0,0,0,0,0,0,0,0,0,0,0,0,0,0,0,0,0,0,0,0,0,0,0,0,0,0
0,0,0,0,0,0,0,0,0,0,0,0,0,0,0,0,0,0,0,0,0,0,0,0,0,0,0,0
0,0,0,0,0,0,0,0,0,0,0,0,0,0,0,0,0,0,0,0,0,0,0,0,0,0,0,0
0,0,0,0,0,0,0,0,0,0,0,0,0,0,0,0,0,0,0,0,0,0,0,0,0,0,0,0
:endlayer
layer: 16
0,0,0,0,0,0,0,0,0,0,0,0,0,0,0,0,0,0,0,0,0,0,0,0,0,0,0,0
0,0,0,0,0,0,0,0,0,0,0,0,0,0,0,0,0,0,0,0,0,0,0,0,0,0,0,0
0,0,0,0,0,0,0,0,0,0,0,0,0,0,0,0,0,0,0,0,0,0,0,0,0,0,0,0
0,0,0,0,0,0,0,0,0,0,0,0,0,0,0,0,0,0,0,0,0,0,0,0,0,0,0,0
0,0,0,0,0,0,0,0,0,0,0,0,0,0,0,0,0,0,0,0,0,0,0,0,0,0,0,0
0,0,0,0,0,0,0,0,0,0,0,0,0,0,0,0,0,0,0,0,0,0,0,0,0,0,0,0
0,0,0,0,0,0,0,0,0,0,0,0,0,0,0,0,0,0,0,0,0,0,0,0,0,0,0,0
0,0,0,0,0,0,0,33,33,33,33,33,33,33,33,33,33,33,33,33,33,0,0,0,0,0,0,0
0,0,0,0,0,0,0,0,8,3,3,3,3,3,3,3,3,3,3,8,0,0,0,0,0,0,0,0
0,0,0,0,0,0,0,0,8,0,0,0,0,0,0,0,0,0,0,8,0,0,0,0,0,0,0,0
0,0,0,0,0,0,0,0,8,0,0,0,0,0,0,0,0,0,0,8,0,0,0,0,0,0,0,0
0,0,0,0,0,0,0,0,8,3,3,3,3,3,3,3,3,3,3,8,0,0,0,0,0,0,0,0
0,0,0,0,0,0,0,25,25,25,25,25,25,25,25,25,25,25,25,25,25,0,0,0,0,0,0,0
0,0,0,0,0,0,0,0,0,0,0,0,0,0,0,0,0,0,0,0,0,0,0,0,0,0,0,0
0,0,0,0,0,0,0,0,0,0,0,0,0,0,0,0,0,0,0,0,0,0,0,0,0,0,0,0
0,0,0,0,0,0,0,0,0,0,0,0,0,0,0,0,0,0,0,0,0,0,0,0,0,0,0,0
0,0,0,0,0,0,0,0,0,0,0,0,0,0,0,0,0,0,0,0,0,0,0,0,0,0,0,0
0,0,0,0,0,0,0,0,0,0,0,0,0,0,0,0,0,0,0,0,0,0,0,0,0,0,0,0
0,0,0,0,0,0,0,0,0,0,0,0,0,0,0,0,0,0,0,0,0,0,0,0,0,0,0,0
0,0,0,0,0,0,0,0,0,0,0,0,0,0,0,0,0,0,0,0,0,0,0,0,0,0,0,0
0,0,0,0,0,0,0,0,0,0,0,0,0,0,0,0,0,0,0,0,0,0,0,0,0,0,0,0
:endlayer
layer: 17
0,0,0,0,0,0,0,0,0,0,0,0,0,0,0,0,0,0,0,0,0,0,0,0,0,0,0,0
0,0,0,0,0,0,0,0,0,0,0,0,0,0,0,0,0,0,0,0,0,0,0,0,0,0,0,0
0,0,0,0,0,0,0,0,0,0,0,0,0,0,0,0,0,0,0,0,0,0,0,0,0,0,0,0
0,0,0,0,0,0,0,0,0,0,0,0,0,0,0,0,0,0,0,0,0,0,0,0,0,0,0,0
0,0,0,0,0,0,0,0,0,0,0,0,0,0,0,0,0,0,0,0,0,0,0,0,0,0,0,0
0,0,0,0,0,0,0,0,0,0,0,0,0,0,0,0,0,0,0,0,0,0,0,0,0,0,0,0
0,0,0,0,0,0,0,0,0,0,0,0,0,0,0,0,0,0,0,0,0,0,0,0,0,0,0,0
0,0,0,0,0,0,0,0,0,0,0,0,0,0,0,0,0,0,0,0,0,0,0,0,0,0,0,0
0,0,0,0,0,0,0,33,33,33,33,33,33,33,33,33,33,33,33,33,33,0,0,0,0,0,0,0
0,0,0,0,0,0,0,0,3,3,3,3,3,3,3,3,3,3,3,3,0,0,0,0,0,0,0,0
0,0,0,0,0,0,0,0,3,3,3,3,3,3,3,3,3,3,3,3,0,0,0,0,0,0,0,0
0,0,0,0,0,0,0,25,25,25,25,25,25,25,25,25,25,25,25,25,25,0,0,0,0,0,0,0
0,0,0,0,0,0,0,0,0,0,0,0,0,0,0,0,0,0,0,0,0,0,0,0,0,0,0,0
0,0,0,0,0,0,0,0,0,0,0,0,0,0,0,0,0,0,0,0,0,0,0,0,0,0,0,0
0,0,0,0,0,0,0,0,0,0,0,0,0,0,0,0,0,0,0,0,0,0,0,0,0,0,0,0
0,0,0,0,0,0,0,0,0,0,0,0,0,0,0,0,0,0,0,0,0,0,0,0,0,0,0,0
0,0,0,0,0,0,0,0,0,0,0,0,0,0,0,0,0,0,0,0,0,0,0,0,0,0,0,0
0,0,0,0,0,0,0,0,0,0,0,0,0,0,0,0,0,0,0,0,0,0,0,0,0,0,0,0
0,0,0,0,0,0,0,0,0,0,0,0,0,0,0,0,0,0,0,0,0,0,0,0,0,0,0,0
0,0,0,0,0,0,0,0,0,0,0,0,0,0,0,0,0,0,0,0,0,0,0,0,0,0,0,0
0,0,0,0,0,0,0,0,0,0,0,0,0,0,0,0,0,0,0,0,0,0,0,0,0,0,0,0
:endlayer
layer: 18
0,0,0,0,0,0,0,0,0,0,0,0,0,0,0,0,0,0,0,0,0,0,0,0,0,0,0,0
0,0,0,0,0,0,0,0,0,0,0,0,0,0,0,0,0,0,0,0,0,0,0,0,0,0,0,0
0,0,0,0,0,0,0,0,0,0,0,0,0,0,0,0,0,0,0,0,0,0,0,0,0,0,0,0
0,0,0,0,0,0,0,0,0,0,0,0,0,0,0,0,0,0,0,0,0,0,0,0,0,0,0,0
0,0,0,0,0,0,0,0,0,0,0,0,0,0,0,0,0,0,0,0,0,0,0,0,0,0,0,0
0,0,0,0,0,0,0,0,0,0,0,0,0,0,0,0,0,0,0,0,0,0,0,0,0,0,0,0
0,0,0,0,0,0,0,0,0,0,0,0,0,0,0,0,0,0,0,0,0,0,0,0,0,0,0,0
0,0,0,0,0,0,0,0,0,0,0,0,0,0,0,0,0,0,0,0,0,0,0,0,0,0,0,0
0,0,0,0,0,0,0,0,0,0,0,0,0,0,0,0,0,0,0,0,0,0,0,0,0,0,0,0
0,0,0,0,0,0,0,33,33,33,33,33,33,33,33,33,33,33,33,33,33,0,0,0,0,0,0,0
0,0,0,0,0,0,0,25,25,25,25,25,25,25,25,25,25,25,25,25,25,0,0,0,0,0,0,0
0,0,0,0,0,0,0,0,0,0,0,0,0,0,0,0,0,0,0,0,0,0,0,0,0,0,0,0
0,0,0,0,0,0,0,0,0,0,0,0,0,0,0,0,0,0,0,0,0,0,0,0,0,0,0,0
0,0,0,0,0,0,0,0,0,0,0,0,0,0,0,0,0,0,0,0,0,0,0,0,0,0,0,0
0,0,0,0,0,0,0,0,0,0,0,0,0,0,0,0,0,0,0,0,0,0,0,0,0,0,0,0
0,0,0,0,0,0,0,0,0,0,0,0,0,0,0,0,0,0,0,0,0,0,0,0,0,0,0,0
0,0,0,0,0,0,0,0,0,0,0,0,0,0,0,0,0,0,0,0,0,0,0,0,0,0,0,0
0,0,0,0,0,0,0,0,0,0,0,0,0,0,0,0,0,0,0,0,0,0,0,0,0,0,0,0
0,0,0,0,0,0,0,0,0,0,0,0,0,0,0,0,0,0,0,0,0,0,0,0,0,0,0,0
0,0,0,0,0,0,0,0,0,0,0,0,0,0,0,0,0,0,0,0,0,0,0,0,0,0,0,0
0,0,0,0,0,0,0,0,0,0,0,0,0,0,0,0,0,0,0,0,0,0,0,0,0,0,0,0
:endlayer
layer: 19
0,0,0,0,0,0,0,0,0,0,0,0,0,0,0,0,0,0,0,0,0,0,0,0,0,0,0,0
0,0,0,0,0,0,0,0,0,0,0,0,0,0,0,0,0,0,0,0,0,0,0,0,0,0,0,0
0,0,0,0,0,0,0,0,0,0,0,0,0,0,0,0,0,0,0,0,0,0,0,0,0,0,0,0
0,0,0,0,0,0,0,0,0,0,0,0,0,0,0,0,0,0,0,0,0,0,0,0,0,0,0,0
0,0,0,0,0,0,0,0,0,0,0,0,0,0,0,0,0,0,0,0,0,0,0,0,0,0,0,0
0,0,0,0,0,0,0,0,0,0,0,0,0,0,0,0,0,0,0,0,0,0,0,0,0,0,0,0
0,0,0,0,0,0,0,0,0,0,0,0,0,0,0,0,0,0,0,0,0,0,0,0,0,0,0,0
0,0,0,0,0,0,0,0,0,0,0,0,0,0,0,0,0,0,0,0,0,0,0,0,0,0,0,0
0,0,0,0,0,0,0,34,0,0,0,0,0,0,0,0,0,0,0,0,34,0,0,0,0,0,0,0
0,0,0,0,0,0,0,25,0,0,0,0,0,0,0,0,0,0,0,0,25,0,0,0,0,0,0,0
0,0,0,0,0,0,0,33,0,0,0,0,0,0,0,0,0,0,0,0,33,0,0,0,0,0,0,0
0,0,0,0,0,0,0,21,0,0,0,0,0,0,0,0,0,0,0,0,21,0,0,0,0,0,0,0
0,0,0,0,0,0,0,0,0,0,0,0,0,0,0,0,0,0,0,0,0,0,0,0,0,0,0,0
0,0,0,0,0,0,0,0,0,0,0,0,0,0,0,0,0,0,0,0,0,0,0,0,0,0,0,0
0,0,0,0,0,0,0,0,0,0,0,0,0,0,0,0,0,0,0,0,0,0,0,0,0,0,0,0
0,0,0,0,0,0,0,0,0,0,0,0,0,0,0,0,0,0,0,0,0,0,0,0,0,0,0,0
0,0,0,0,0,0,0,0,0,0,0,0,0,0,0,0,0,0,0,0,0,0,0,0,0,0,0,0
0,0,0,0,0,0,0,0,0,0,0,0,0,0,0,0,0,0,0,0,0,0,0,0,0,0,0,0
0,0,0,0,0,0,0,0,0,0,0,0,0,0,0,0,0,0,0,0,0,0,0,0,0,0,0,0
0,0,0,0,0,0,0,0,0,0,0,0,0,0,0,0,0,0,0,0,0,0,0,0,0,0,0,0
0,0,0,0,0,0,0,0,0,0,0,0,0,0,0,0,0,0,0,0,0,0,0,0,0,0,0,0
:endlayer
layer: 20
0,0,0,0,0,0,0,0,0,0,0,0,0,0,0,0,0,0,0,0,0,0,0,0,0,0,0,0
0,0,0,0,0,0,0,0,0,0,0,0,0,0,0,0,0,0,0,0,0,0,0,0,0,0,0,0
0,0,0,0,0,0,0,0,0,0,0,0,0,0,0,0,0,0,0,0,0,0,0,0,0,0,0,0
0,0,0,0,0,0,0,0,0,0,0,0,0,0,0,0,0,0,0,0,0,0,0,0,0,0,0,0
0,0,0,0,0,0,0,0,0,0,0,0,0,0,0,0,0,0,0,0,0,0,0,0,0,0,0,0
0,0,0,0,0,0,0,0,0,0,0,0,0,0,0,0,0,0,0,0,0,0,0,0,0,0,0,0
0,0,0,0,0,0,0,0,0,0,0,0,0,0,0,0,0,0,0,0,0,0,0,0,0,0,0,0
0,0,0,0,0,0,0,0,0,0,0,0,0,0,0,0,0,0,0,0,0,0,0,0,0,0,0,0
0,0,0,0,0,0,0,0,0,0,0,0,0,0,0,0,0,0,0,0,0,0,0,0,0,0,0,0
0,0,0,0,0,0,0,0,0,0,0,0,0,0,0,0,0,0,0,0,0,0,0,0,0,0,0,0
0,0,0,0,0,0,0,0,0,0,0,0,0,0,0,0,0,0,0,0,0,0,0,0,0,0,0,0
0,0,0,0,0,0,0,0,0,0,0,0,0,0,0,0,0,0,0,0,0,0,0,0,0,0,0,0
0,0,0,0,0,0,0,0,0,0,0,0,0,0,0,0,0,0,0,0,0,0,0,0,0,0,0,0
0,0,0,0,0,0,0,0,0,0,0,0,0,0,0,0,0,0,0,0,0,0,0,0,0,0,0,0
0,0,0,0,0,0,0,0,0,0,0,0,0,0,0,0,0,0,0,0,0,0,0,0,0,0,0,0
0,0,0,0,0,0,0,0,0,0,0,0,0,0,0,0,0,0,0,0,0,0,0,0,0,0,0,0
0,0,0,0,0,0,0,0,0,0,0,0,0,0,0,0,0,0,0,0,0,0,0,0,0,0,0,0
0,0,0,0,0,0,0,0,0,0,0,0,0,0,0,0,0,0,0,0,0,0,0,0,0,0,0,0
0,0,0,0,0,0,0,0,0,0,0,0,0,0,0,0,0,0,0,0,0,0,0,0,0,0,0,0
0,0,0,0,0,0,0,0,0,0,0,0,0,0,0,0,0,0,0,0,0,0,0,0,0,0,0,0
0,0,0,0,0,0,0,0,0,0,0,0,0,0,0,0,0,0,0,0,0,0,0,0,0,0,0,0
:endlayer
layer: 21
0,0,0,0,0,0,0,0,0,0,0,0,0,0,0,0,0,0,0,0,0,0,0,0,0,0,0,0
0,0,0,0,0,0,0,0,0,0,0,0,0,0,0,0,0,0,0,0,0,0,0,0,0,0,0,0
0,0,0,0,0,0,0,0,0,0,0,0,0,0,0,0,0,0,0,0,0,0,0,0,0,0,0,0
0,0,0,0,0,0,0,0,0,0,0,0,0,0,0,0,0,0,0,0,0,0,0,0,0,0,0,0
0,0,0,0,0,0,0,0,0,0,0,0,0,0,0,0,0,0,0,0,0,0,0,0,0,0,0,0
0,0,0,0,0,0,0,0,0,0,0,0,0,0,0,0,0,0,0,0,0,0,0,0,0,0,0,0
0,0,0,0,0,0,0,0,0,0,0,0,0,0,0,0,0,0,0,0,0,0,0,0,0,0,0,0
0,0,0,0,0,0,0,0,0,0,0,0,0,0,0,0,0,0,0,0,0,0,0,0,0,0,0,0
0,0,0,0,0,0,0,0,0,0,0,0,0,0,0,0,0,0,0,0,0,0,0,0,0,0,0,0
0,0,0,0,0,0,0,0,0,0,0,0,0,0,0,0,0,0,0,0,0,0,0,0,0,0,0,0
0,0,0,0,0,0,0,0,0,0,0,0,0,0,0,0,0,0,0,0,0,0,0,0,0,0,0,0
0,0,0,0,0,0,0,0,0,0,0,0,0,0,0,0,0,0,0,0,0,0,0,0,0,0,0,0
0,0,0,0,0,0,0,0,0,0,0,0,0,0,0,0,0,0,0,0,0,0,0,0,0,0,0,0
0,0,0,0,0,0,0,0,0,0,0,0,0,0,0,0,0,0,0,0,0,0,0,0,0,0,0,0
0,0,0,0,0,0,0,0,0,0,0,0,0,0,0,0,0,0,0,0,0,0,0,0,0,0,0,0
0,0,0,0,0,0,0,0,0,0,0,0,0,0,0,0,0,0,0,0,0,0,0,0,0,0,0,0
0,0,0,0,0,0,0,0,0,0,0,0,0,0,0,0,0,0,0,0,0,0,0,0,0,0,0,0
0,0,0,0,0,0,0,0,0,0,0,0,0,0,0,0,0,0,0,0,0,0,0,0,0,0,0,0
0,0,0,0,0,0,0,0,0,0,0,0,0,0,0,0,0,0,0,0,0,0,0,0,0,0,0,0
0,0,0,0,0,0,0,0,0,0,0,0,0,0,0,0,0,0,0,0,0,0,0,0,0,0,0,0
0,0,0,0,0,0,0,0,0,0,0,0,0,0,0,0,0,0,0,0,0,0,0,0,0,0,0,0
:endlayer
layer: 22
0,0,0,0,0,0,0,0,0,0,0,0,0,0,0,0,0,0,0,0,0,0,0,0,0,0,0,0
0,0,0,0,0,0,0,0,0,0,0,0,0,0,0,0,0,0,0,0,0,0,0,0,0,0,0,0
0,0,0,0,0,0,0,0,0,0,0,0,0,0,0,0,0,0,0,0,0,0,0,0,0,0,0,0
0,0,0,0,0,0,0,0,0,0,0,0,0,0,0,0,0,0,0,0,0,0,0,0,0,0,0,0
0,0,0,0,0,0,0,0,0,0,0,0,0,0,0,0,0,0,0,0,0,0,0,0,0,0,0,0
0,0,0,0,0,0,0,0,0,0,0,0,0,0,0,0,0,0,0,0,0,0,0,0,0,0,0,0
0,0,0,0,0,0,0,0,0,0,0,0,0,0,0,0,0,0,0,0,0,0,0,0,0,0,0,0
0,0,0,0,0,0,0,0,0,0,0,0,0,0,0,0,0,0,0,0,0,0,0,0,0,0,0,0
0,0,0,0,0,0,0,0,0,0,0,0,0,0,0,0,0,0,0,0,0,0,0,0,0,0,0,0
0,0,0,0,0,0,0,0,0,0,0,0,0,0,0,0,0,0,0,0,0,0,0,0,0,0,0,0
0,0,0,0,0,0,0,0,0,0,0,0,0,0,0,0,0,0,0,0,0,0,0,0,0,0,0,0
0,0,0,0,0,0,0,0,0,0,0,0,0,0,0,0,0,0,0,0,0,0,0,0,0,0,0,0
0,0,0,0,0,0,0,0,0,0,0,0,0,0,0,0,0,0,0,0,0,0,0,0,0,0,0,0
0,0,0,0,0,0,0,0,0,0,0,0,0,0,0,0,0,0,0,0,0,0,0,0,0,0,0,0
0,0,0,0,0,0,0,0,0,0,0,0,0,0,0,0,0,0,0,0,0,0,0,0,0,0,0,0
0,0,0,0,0,0,0,0,0,0,0,0,0,0,0,0,0,0,0,0,0,0,0,0,0,0,0,0
0,0,0,0,0,0,0,0,0,0,0,0,0,0,0,0,0,0,0,0,0,0,0,0,0,0,0,0
0,0,0,0,0,0,0,0,0,0,0,0,0,0,0,0,0,0,0,0,0,0,0,0,0,0,0,0
0,0,0,0,0,0,0,0,0,0,0,0,0,0,0,0,0,0,0,0,0,0,0,0,0,0,0,0
0,0,0,0,0,0,0,0,0,0,0,0,0,0,0,0,0,0,0,0,0,0,0,0,0,0,0,0
0,0,0,0,0,0,0,0,0,0,0,0,0,0,0,0,0,0,0,0,0,0,0,0,0,0,0,0
:endlayer
layer: 23
0,0,0,0,0,0,0,0,0,0,0,0,0,0,0,0,0,0,0,0,0,0,0,0,0,0,0,0
0,0,0,0,0,0,0,0,0,0,0,0,0,0,0,0,0,0,0,0,0,0,0,0,0,0,0,0
0,0,0,0,0,0,0,0,0,0,0,0,0,0,0,0,0,0,0,0,0,0,0,0,0,0,0,0
0,0,0,0,0,0,0,0,0,0,0,0,0,0,0,0,0,0,0,0,0,0,0,0,0,0,0,0
0,0,0,0,0,0,0,0,0,0,0,0,0,0,0,0,0,0,0,0,0,0,0,0,0,0,0,0
0,0,0,0,0,0,0,0,0,0,0,0,0,0,0,0,0,0,0,0,0,0,0,0,0,0,0,0
0,0,0,0,0,0,0,0,0,0,0,0,0,0,0,0,0,0,0,0,0,0,0,0,0,0,0,0
0,0,0,0,0,0,0,0,0,0,0,0,0,0,0,0,0,0,0,0,0,0,0,0,0,0,0,0
0,0,0,0,0,0,0,0,0,0,0,0,0,0,0,0,0,0,0,0,0,0,0,0,0,0,0,0
0,0,0,0,0,0,0,0,0,0,0,0,0,0,0,0,0,0,0,0,0,0,0,0,0,0,0,0
0,0,0,0,0,0,0,0,0,0,0,0,0,0,0,0,0,0,0,0,0,0,0,0,0,0,0,0
0,0,0,0,0,0,0,0,0,0,0,0,0,0,0,0,0,0,0,0,0,0,0,0,0,0,0,0
0,0,0,0,0,0,0,0,0,0,0,0,0,0,0,0,0,0,0,0,0,0,0,0,0,0,0,0
0,0,0,0,0,0,0,0,0,0,0,0,0,0,0,0,0,0,0,0,0,0,0,0,0,0,0,0
0,0,0,0,0,0,0,0,0,0,0,0,0,0,0,0,0,0,0,0,0,0,0,0,0,0,0,0
0,0,0,0,0,0,0,0,0,0,0,0,0,0,0,0,0,0,0,0,0,0,0,0,0,0,0,0
0,0,0,0,0,0,0,0,0,0,0,0,0,0,0,0,0,0,0,0,0,0,0,0,0,0,0,0
0,0,0,0,0,0,0,0,0,0,0,0,0,0,0,0,0,0,0,0,0,0,0,0,0,0,0,0
0,0,0,0,0,0,0,0,0,0,0,0,0,0,0,0,0,0,0,0,0,0,0,0,0,0,0,0
0,0,0,0,0,0,0,0,0,0,0,0,0,0,0,0,0,0,0,0,0,0,0,0,0,0,0,0
0,0,0,0,0,0,0,0,0,0,0,0,0,0,0,0,0,0,0,0,0,0,0,0,0,0,0,0
:endlayer
layer: 24
0,0,0,0,0,0,0,0,0,0,0,0,0,0,0,0,0,0,0,0,0,0,0,0,0,0,0,0
0,0,0,0,0,0,0,0,0,0,0,0,0,0,0,0,0,0,0,0,0,0,0,0,0,0,0,0
0,0,0,0,0,0,0,0,0,0,0,0,0,0,0,0,0,0,0,0,0,0,0,0,0,0,0,0
0,0,0,0,0,0,0,0,0,0,0,0,0,0,0,0,0,0,0,0,0,0,0,0,0,0,0,0
0,0,0,0,0,0,0,0,0,0,0,0,0,0,0,0,0,0,0,0,0,0,0,0,0,0,0,0
0,0,0,0,0,0,0,0,0,0,0,0,0,0,0,0,0,0,0,0,0,0,0,0,0,0,0,0
0,0,0,0,0,0,0,0,0,0,0,0,0,0,0,0,0,0,0,0,0,0,0,0,0,0,0,0
0,0,0,0,0,0,0,0,0,0,0,0,0,0,0,0,0,0,0,0,0,0,0,0,0,0,0,0
0,0,0,0,0,0,0,0,0,0,0,0,0,0,0,0,0,0,0,0,0,0,0,0,0,0,0,0
0,0,0,0,0,0,0,0,0,0,0,0,0,0,0,0,0,0,0,0,0,0,0,0,0,0,0,0
0,0,0,0,0,0,0,0,0,0,0,0,0,0,0,0,0,0,0,0,0,0,0,0,0,0,0,0
0,0,0,0,0,0,0,0,0,0,0,0,0,0,0,0,0,0,0,0,0,0,0,0,0,0,0,0
0,0,0,0,0,0,0,0,0,0,0,0,0,0,0,0,0,0,0,0,0,0,0,0,0,0,0,0
0,0,0,0,0,0,0,0,0,0,0,0,0,0,0,0,0,0,0,0,0,0,0,0,0,0,0,0
0,0,0,0,0,0,0,0,0,0,0,0,0,0,0,0,0,0,0,0,0,0,0,0,0,0,0,0
0,0,0,0,0,0,0,0,0,0,0,0,0,0,0,0,0,0,0,0,0,0,0,0,0,0,0,0
0,0,0,0,0,0,0,0,0,0,0,0,0,0,0,0,0,0,0,0,0,0,0,0,0,0,0,0
0,0,0,0,0,0,0,0,0,0,0,0,0,0,0,0,0,0,0,0,0,0,0,0,0,0,0,0
0,0,0,0,0,0,0,0,0,0,0,0,0,0,0,0,0,0,0,0,0,0,0,0,0,0,0,0
0,0,0,0,0,0,0,0,0,0,0,0,0,0,0,0,0,0,0,0,0,0,0,0,0,0,0,0
0,0,0,0,0,0,0,0,0,0,0,0,0,0,0,0,0,0,0,0,0,0,0,0,0,0,0,0
:endlayer
layer: 25
0,0,0,0,0,0,0,0,0,0,0,0,0,0,0,0,0,0,0,0,0,0,0,0,0,0,0,0
0,0,0,0,0,0,0,0,0,0,0,0,0,0,0,0,0,0,0,0,0,0,0,0,0,0,0,0
0,0,0,0,0,0,0,0,0,0,0,0,0,0,0,0,0,0,0,0,0,0,0,0,0,0,0,0
0,0,0,0,0,0,0,0,0,0,0,0,0,0,0,0,0,0,0,0,0,0,0,0,0,0,0,0
0,0,0,0,0,0,0,0,0,0,0,0,0,0,0,0,0,0,0,0,0,0,0,0,0,0,0,0
0,0,0,0,0,0,0,0,0,0,0,0,0,0,0,0,0,0,0,0,0,0,0,0,0,0,0,0
0,0,0,0,0,0,0,0,0,0,0,0,0,0,0,0,0,0,0,0,0,0,0,0,0,0,0,0
0,0,0,0,0,0,0,0,0,0,0,0,0,0,0,0,0,0,0,0,0,0,0,0,0,0,0,0
0,0,0,0,0,0,0,0,0,0,0,0,0,0,0,0,0,0,0,0,0,0,0,0,0,0,0,0
0,0,0,0,0,0,0,0,0,0,0,0,0,0,0,0,0,0,0,0,0,0,0,0,0,0,0,0
0,0,0,0,0,0,0,0,0,0,0,0,0,0,0,0,0,0,0,0,0,0,0,0,0,0,0,0
0,0,0,0,0,0,0,0,0,0,0,0,0,0,0,0,0,0,0,0,0,0,0,0,0,0,0,0
0,0,0,0,0,0,0,0,0,0,0,0,0,0,0,0,0,0,0,0,0,0,0,0,0,0,0,0
0,0,0,0,0,0,0,0,0,0,0,0,0,0,0,0,0,0,0,0,0,0,0,0,0,0,0,0
0,0,0,0,0,0,0,0,0,0,0,0,0,0,0,0,0,0,0,0,0,0,0,0,0,0,0,0
0,0,0,0,0,0,0,0,0,0,0,0,0,0,0,0,0,0,0,0,0,0,0,0,0,0,0,0
0,0,0,0,0,0,0,0,0,0,0,0,0,0,0,0,0,0,0,0,0,0,0,0,0,0,0,0
0,0,0,0,0,0,0,0,0,0,0,0,0,0,0,0,0,0,0,0,0,0,0,0,0,0,0,0
0,0,0,0,0,0,0,0,0,0,0,0,0,0,0,0,0,0,0,0,0,0,0,0,0,0,0,0
0,0,0,0,0,0,0,0,0,0,0,0,0,0,0,0,0,0,0,0,0,0,0,0,0,0,0,0
0,0,0,0,0,0,0,0,0,0,0,0,0,0,0,0,0,0,0,0,0,0,0,0,0,0,0,0
:endlayer
layer: 26
0,0,0,0,0,0,0,0,0,0,0,0,0,0,0,0,0,0,0,0,0,0,0,0,0,0,0,0
0,0,0,0,0,0,0,0,0,0,0,0,0,0,0,0,0,0,0,0,0,0,0,0,0,0,0,0
0,0,0,0,0,0,0,0,0,0,0,0,0,0,0,0,0,0,0,0,0,0,0,0,0,0,0,0
0,0,0,0,0,0,0,0,0,0,0,0,0,0,0,0,0,0,0,0,0,0,0,0,0,0,0,0
0,0,0,0,0,0,0,0,0,0,0,0,0,0,0,0,0,0,0,0,0,0,0,0,0,0,0,0
0,0,0,0,0,0,0,0,0,0,0,0,0,0,0,0,0,0,0,0,0,0,0,0,0,0,0,0
0,0,0,0,0,0,0,0,0,0,0,0,0,0,0,0,0,0,0,0,0,0,0,0,0,0,0,0
0,0,0,0,0,0,0,0,0,0,0,0,0,0,0,0,0,0,0,0,0,0,0,0,0,0,0,0
0,0,0,0,0,0,0,0,0,0,0,0,0,0,0,0,0,0,0,0,0,0,0,0,0,0,0,0
0,0,0,0,0,0,0,0,0,0,0,0,0,0,0,0,0,0,0,0,0,0,0,0,0,0,0,0
0,0,0,0,0,0,0,0,0,0,0,0,0,0,0,0,0,0,0,0,0,0,0,0,0,0,0,0
0,0,0,0,0,0,0,0,0,0,0,0,0,0,0,0,0,0,0,0,0,0,0,0,0,0,0,0
0,0,0,0,0,0,0,0,0,0,0,0,0,0,0,0,0,0,0,0,0,0,0,0,0,0,0,0
0,0,0,0,0,0,0,0,0,0,0,0,0,0,0,0,0,0,0,0,0,0,0,0,0,0,0,0
0,0,0,0,0,0,0,0,0,0,0,0,0,0,0,0,0,0,0,0,0,0,0,0,0,0,0,0
0,0,0,0,0,0,0,0,0,0,0,0,0,0,0,0,0,0,0,0,0,0,0,0,0,0,0,0
0,0,0,0,0,0,0,0,0,0,0,0,0,0,0,0,0,0,0,0,0,0,0,0,0,0,0,0
0,0,0,0,0,0,0,0,0,0,0,0,0,0,0,0,0,0,0,0,0,0,0,0,0,0,0,0
0,0,0,0,0,0,0,0,0,0,0,0,0,0,0,0,0,0,0,0,0,0,0,0,0,0,0,0
0,0,0,0,0,0,0,0,0,0,0,0,0,0,0,0,0,0,0,0,0,0,0,0,0,0,0,0
0,0,0,0,0,0,0,0,0,0,0,0,0,0,0,0,0,0,0,0,0,0,0,0,0,0,0,0
:endlayer
layer: 27
0,0,0,0,0,0,0,0,0,0,0,0,0,0,0,0,0,0,0,0,0,0,0,0,0,0,0,0
0,0,0,0,0,0,0,0,0,0,0,0,0,0,0,0,0,0,0,0,0,0,0,0,0,0,0,0
0,0,0,0,0,0,0,0,0,0,0,0,0,0,0,0,0,0,0,0,0,0,0,0,0,0,0,0
0,0,0,0,0,0,0,0,0,0,0,0,0,0,0,0,0,0,0,0,0,0,0,0,0,0,0,0
0,0,0,0,0,0,0,0,0,0,0,0,0,0,0,0,0,0,0,0,0,0,0,0,0,0,0,0
0,0,0,0,0,0,0,0,0,0,0,0,0,0,0,0,0,0,0,0,0,0,0,0,0,0,0,0
0,0,0,0,0,0,0,0,0,0,0,0,0,0,0,0,0,0,0,0,0,0,0,0,0,0,0,0
0,0,0,0,0,0,0,0,0,0,0,0,0,0,0,0,0,0,0,0,0,0,0,0,0,0,0,0
0,0,0,0,0,0,0,0,0,0,0,0,0,0,0,0,0,0,0,0,0,0,0,0,0,0,0,0
0,0,0,0,0,0,0,0,0,0,0,0,0,0,0,0,0,0,0,0,0,0,0,0,0,0,0,0
0,0,0,0,0,0,0,0,0,0,0,0,0,0,0,0,0,0,0,0,0,0,0,0,0,0,0,0
0,0,0,0,0,0,0,0,0,0,0,0,0,0,0,0,0,0,0,0,0,0,0,0,0,0,0,0
0,0,0,0,0,0,0,0,0,0,0,0,0,0,0,0,0,0,0,0,0,0,0,0,0,0,0,0
0,0,0,0,0,0,0,0,0,0,0,0,0,0,0,0,0,0,0,0,0,0,0,0,0,0,0,0
0,0,0,0,0,0,0,0,0,0,0,0,0,0,0,0,0,0,0,0,0,0,0,0,0,0,0,0
0,0,0,0,0,0,0,0,0,0,0,0,0,0,0,0,0,0,0,0,0,0,0,0,0,0,0,0
0,0,0,0,0,0,0,0,0,0,0,0,0,0,0,0,0,0,0,0,0,0,0,0,0,0,0,0
0,0,0,0,0,0,0,0,0,0,0,0,0,0,0,0,0,0,0,0,0,0,0,0,0,0,0,0
0,0,0,0,0,0,0,0,0,0,0,0,0,0,0,0,0,0,0,0,0,0,0,0,0,0,0,0
0,0,0,0,0,0,0,0,0,0,0,0,0,0,0,0,0,0,0,0,0,0,0,0,0,0,0,0
0,0,0,0,0,0,0,0,0,0,0,0,0,0,0,0,0,0,0,0,0,0,0,0,0,0,0,0
:endlayer
layer: 28
0,0,0,0,0,0,0,0,0,0,0,0,0,0,0,0,0,0,0,0,0,0,0,0,0,0,0,0
0,0,0,0,0,0,0,0,0,0,0,0,0,0,0,0,0,0,0,0,0,0,0,0,0,0,0,0
0,0,0,0,0,0,0,0,0,0,0,0,0,0,0,0,0,0,0,0,0,0,0,0,0,0,0,0
0,0,0,0,0,0,0,0,0,0,0,0,0,0,0,0,0,0,0,0,0,0,0,0,0,0,0,0
0,0,0,0,0,0,0,0,0,0,0,0,0,0,0,0,0,0,0,0,0,0,0,0,0,0,0,0
0,0,0,0,0,0,0,0,0,0,0,0,0,0,0,0,0,0,0,0,0,0,0,0,0,0,0,0
0,0,0,0,0,0,0,0,0,0,0,0,0,0,0,0,0,0,0,0,0,0,0,0,0,0,0,0
0,0,0,0,0,0,0,0,0,0,0,0,0,0,0,0,0,0,0,0,0,0,0,0,0,0,0,0
0,0,0,0,0,0,0,0,0,0,0,0,0,0,0,0,0,0,0,0,0,0,0,0,0,0,0,0
0,0,0,0,0,0,0,0,0,0,0,0,0,0,0,0,0,0,0,0,0,0,0,0,0,0,0,0
0,0,0,0,0,0,0,0,0,0,0,0,0,0,0,0,0,0,0,0,0,0,0,0,0,0,0,0
0,0,0,0,0,0,0,0,0,0,0,0,0,0,0,0,0,0,0,0,0,0,0,0,0,0,0,0
0,0,0,0,0,0,0,0,0,0,0,0,0,0,0,0,0,0,0,0,0,0,0,0,0,0,0,0
0,0,0,0,0,0,0,0,0,0,0,0,0,0,0,0,0,0,0,0,0,0,0,0,0,0,0,0
0,0,0,0,0,0,0,0,0,0,0,0,0,0,0,0,0,0,0,0,0,0,0,0,0,0,0,0
0,0,0,0,0,0,0,0,0,0,0,0,0,0,0,0,0,0,0,0,0,0,0,0,0,0,0,0
0,0,0,0,0,0,0,0,0,0,0,0,0,0,0,0,0,0,0,0,0,0,0,0,0,0,0,0
0,0,0,0,0,0,0,0,0,0,0,0,0,0,0,0,0,0,0,0,0,0,0,0,0,0,0,0
0,0,0,0,0,0,0,0,0,0,0,0,0,0,0,0,0,0,0,0,0,0,0,0,0,0,0,0
0,0,0,0,0,0,0,0,0,0,0,0,0,0,0,0,0,0,0,0,0,0,0,0,0,0,0,0
0,0,0,0,0,0,0,0,0,0,0,0,0,0,0,0,0,0,0,0,0,0,0,0,0,0,0,0
:endlayer
layer: 29
0,0,0,0,0,0,0,0,0,0,0,0,0,0,0,0,0,0,0,0,0,0,0,0,0,0,0,0
0,0,0,0,0,0,0,0,0,0,0,0,0,0,0,0,0,0,0,0,0,0,0,0,0,0,0,0
0,0,0,0,0,0,0,0,0,0,0,0,0,0,0,0,0,0,0,0,0,0,0,0,0,0,0,0
0,0,0,0,0,0,0,0,0,0,0,0,0,0,0,0,0,0,0,0,0,0,0,0,0,0,0,0
0,0,0,0,0,0,0,0,0,0,0,0,0,0,0,0,0,0,0,0,0,0,0,0,0,0,0,0
0,0,0,0,0,0,0,0,0,0,0,0,0,0,0,0,0,0,0,0,0,0,0,0,0,0,0,0
0,0,0,0,0,0,0,0,0,0,0,0,0,0,0,0,0,0,0,0,0,0,0,0,0,0,0,0
0,0,0,0,0,0,0,0,0,0,0,0,0,0,0,0,0,0,0,0,0,0,0,0,0,0,0,0
0,0,0,0,0,0,0,0,0,0,0,0,0,0,0,0,0,0,0,0,0,0,0,0,0,0,0,0
0,0,0,0,0,0,0,0,0,0,0,0,0,0,0,0,0,0,0,0,0,0,0,0,0,0,0,0
0,0,0,0,0,0,0,0,0,0,0,0,0,0,0,0,0,0,0,0,0,0,0,0,0,0,0,0
0,0,0,0,0,0,0,0,0,0,0,0,0,0,0,0,0,0,0,0,0,0,0,0,0,0,0,0
0,0,0,0,0,0,0,0,0,0,0,0,0,0,0,0,0,0,0,0,0,0,0,0,0,0,0,0
0,0,0,0,0,0,0,0,0,0,0,0,0,0,0,0,0,0,0,0,0,0,0,0,0,0,0,0
0,0,0,0,0,0,0,0,0,0,0,0,0,0,0,0,0,0,0,0,0,0,0,0,0,0,0,0
0,0,0,0,0,0,0,0,0,0,0,0,0,0,0,0,0,0,0,0,0,0,0,0,0,0,0,0
0,0,0,0,0,0,0,0,0,0,0,0,0,0,0,0,0,0,0,0,0,0,0,0,0,0,0,0
0,0,0,0,0,0,0,0,0,0,0,0,0,0,0,0,0,0,0,0,0,0,0,0,0,0,0,0
0,0,0,0,0,0,0,0,0,0,0,0,0,0,0,0,0,0,0,0,0,0,0,0,0,0,0,0
0,0,0,0,0,0,0,0,0,0,0,0,0,0,0,0,0,0,0,0,0,0,0,0,0,0,0,0
0,0,0,0,0,0,0,0,0,0,0,0,0,0,0,0,0,0,0,0,0,0,0,0,0,0,0,0
:endlayer
layer: 30
0,0,0,0,0,0,0,0,0,0,0,0,0,0,0,0,0,0,0,0,0,0,0,0,0,0,0,0
0,0,0,0,0,0,0,0,0,0,0,0,0,0,0,0,0,0,0,0,0,0,0,0,0,0,0,0
0,0,0,0,0,0,0,0,0,0,0,0,0,0,0,0,0,0,0,0,0,0,0,0,0,0,0,0
0,0,0,0,0,0,0,0,0,0,0,0,0,0,0,0,0,0,0,0,0,0,0,0,0,0,0,0
0,0,0,0,0,0,0,0,0,0,0,0,0,0,0,0,0,0,0,0,0,0,0,0,0,0,0,0
0,0,0,0,0,0,0,0,0,0,0,0,0,0,0,0,0,0,0,0,0,0,0,0,0,0,0,0
0,0,0,0,0,0,0,0,0,0,0,0,0,0,0,0,0,0,0,0,0,0,0,0,0,0,0,0
0,0,0,0,0,0,0,0,0,0,0,0,0,0,0,0,0,0,0,0,0,0,0,0,0,0,0,0
0,0,0,0,0,0,0,0,0,0,0,0,0,0,0,0,0,0,0,0,0,0,0,0,0,0,0,0
0,0,0,0,0,0,0,0,0,0,0,0,0,0,0,0,0,0,0,0,0,0,0,0,0,0,0,0
0,0,0,0,0,0,0,0,0,0,0,0,0,0,0,0,0,0,0,0,0,0,0,0,0,0,0,0
0,0,0,0,0,0,0,0,0,0,0,0,0,0,0,0,0,0,0,0,0,0,0,0,0,0,0,0
0,0,0,0,0,0,0,0,0,0,0,0,0,0,0,0,0,0,0,0,0,0,0,0,0,0,0,0
0,0,0,0,0,0,0,0,0,0,0,0,0,0,0,0,0,0,0,0,0,0,0,0,0,0,0,0
0,0,0,0,0,0,0,0,0,0,0,0,0,0,0,0,0,0,0,0,0,0,0,0,0,0,0,0
0,0,0,0,0,0,0,0,0,0,0,0,0,0,0,0,0,0,0,0,0,0,0,0,0,0,0,0
0,0,0,0,0,0,0,0,0,0,0,0,0,0,0,0,0,0,0,0,0,0,0,0,0,0,0,0
0,0,0,0,0,0,0,0,0,0,0,0,0,0,0,0,0,0,0,0,0,0,0,0,0,0,0,0
0,0,0,0,0,0,0,0,0,0,0,0,0,0,0,0,0,0,0,0,0,0,0,0,0,0,0,0
0,0,0,0,0,0,0,0,0,0,0,0,0,0,0,0,0,0,0,0,0,0,0,0,0,0,0,0
0,0,0,0,0,0,0,0,0,0,0,0,0,0,0,0,0,0,0,0,0,0,0,0,0,0,0,0
:endlayer
layer: 31
0,0,0,0,0,0,0,0,0,0,0,0,0,0,0,0,0,0,0,0,0,0,0,0,0,0,0,0
0,0,0,0,0,0,0,0,0,0,0,0,0,0,0,0,0,0,0,0,0,0,0,0,0,0,0,0
0,0,0,0,0,0,0,0,0,0,0,0,0,0,0,0,0,0,0,0,0,0,0,0,0,0,0,0
0,0,0,0,0,0,0,0,0,0,0,0,0,0,0,0,0,0,0,0,0,0,0,0,0,0,0,0
0,0,0,0,0,0,0,0,0,0,0,0,0,0,0,0,0,0,0,0,0,0,0,0,0,0,0,0
0,0,0,0,0,0,0,0,0,0,0,0,0,0,0,0,0,0,0,0,0,0,0,0,0,0,0,0
0,0,0,0,0,0,0,0,0,0,0,0,0,0,0,0,0,0,0,0,0,0,0,0,0,0,0,0
0,0,0,0,0,0,0,0,0,0,0,0,0,0,0,0,0,0,0,0,0,0,0,0,0,0,0,0
0,0,0,0,0,0,0,0,0,0,0,0,0,0,0,0,0,0,0,0,0,0,0,0,0,0,0,0
0,0,0,0,0,0,0,0,0,0,0,0,0,0,0,0,0,0,0,0,0,0,0,0,0,0,0,0
0,0,0,0,0,0,0,0,0,0,0,0,0,0,0,0,0,0,0,0,0,0,0,0,0,0,0,0
0,0,0,0,0,0,0,0,0,0,0,0,0,0,0,0,0,0,0,0,0,0,0,0,0,0,0,0
0,0,0,0,0,0,0,0,0,0,0,0,0,0,0,0,0,0,0,0,0,0,0,0,0,0,0,0
0,0,0,0,0,0,0,0,0,0,0,0,0,0,0,0,0,0,0,0,0,0,0,0,0,0,0,0
0,0,0,0,0,0,0,0,0,0,0,0,0,0,0,0,0,0,0,0,0,0,0,0,0,0,0,0
0,0,0,0,0,0,0,0,0,0,0,0,0,0,0,0,0,0,0,0,0,0,0,0,0,0,0,0
0,0,0,0,0,0,0,0,0,0,0,0,0,0,0,0,0,0,0,0,0,0,0,0,0,0,0,0
0,0,0,0,0,0,0,0,0,0,0,0,0,0,0,0,0,0,0,0,0,0,0,0,0,0,0,0
0,0,0,0,0,0,0,0,0,0,0,0,0,0,0,0,0,0,0,0,0,0,0,0,0,0,0,0
0,0,0,0,0,0,0,0,0,0,0,0,0,0,0,0,0,0,0,0,0,0,0,0,0,0,0,0
0,0,0,0,0,0,0,0,0,0,0,0,0,0,0,0,0,0,0,0,0,0,0,0,0,0,0,0
:endlayer
layer: 32
0,0,0,0,0,0,0,0,0,0,0,0,0,0,0,0,0,0,0,0,0,0,0,0,0,0,0,0
0,0,0,0,0,0,0,0,0,0,0,0,0,0,0,0,0,0,0,0,0,0,0,0,0,0,0,0
0,0,0,0,0,0,0,0,0,0,0,0,0,0,0,0,0,0,0,0,0,0,0,0,0,0,0,0
0,0,0,0,0,0,0,0,0,0,0,0,0,0,0,0,0,0,0,0,0,0,0,0,0,0,0,0
0,0,0,0,0,0,0,0,0,0,0,0,0,0,0,0,0,0,0,0,0,0,0,0,0,0,0,0
0,0,0,0,0,0,0,0,0,0,0,0,0,0,0,0,0,0,0,0,0,0,0,0,0,0,0,0
0,0,0,0,0,0,0,0,0,0,0,0,0,0,0,0,0,0,0,0,0,0,0,0,0,0,0,0
0,0,0,0,0,0,0,0,0,0,0,0,0,0,0,0,0,0,0,0,0,0,0,0,0,0,0,0
0,0,0,0,0,0,0,0,0,0,0,0,0,0,0,0,0,0,0,0,0,0,0,0,0,0,0,0
0,0,0,0,0,0,0,0,0,0,0,0,0,0,0,0,0,0,0,0,0,0,0,0,0,0,0,0
0,0,0,0,0,0,0,0,0,0,0,0,0,0,0,0,0,0,0,0,0,0,0,0,0,0,0,0
0,0,0,0,0,0,0,0,0,0,0,0,0,0,0,0,0,0,0,0,0,0,0,0,0,0,0,0
0,0,0,0,0,0,0,0,0,0,0,0,0,0,0,0,0,0,0,0,0,0,0,0,0,0,0,0
0,0,0,0,0,0,0,0,0,0,0,0,0,0,0,0,0,0,0,0,0,0,0,0,0,0,0,0
0,0,0,0,0,0,0,0,0,0,0,0,0,0,0,0,0,0,0,0,0,0,0,0,0,0,0,0
0,0,0,0,0,0,0,0,0,0,0,0,0,0,0,0,0,0,0,0,0,0,0,0,0,0,0,0
0,0,0,0,0,0,0,0,0,0,0,0,0,0,0,0,0,0,0,0,0,0,0,0,0,0,0,0
0,0,0,0,0,0,0,0,0,0,0,0,0,0,0,0,0,0,0,0,0,0,0,0,0,0,0,0
0,0,0,0,0,0,0,0,0,0,0,0,0,0,0,0,0,0,0,0,0,0,0,0,0,0,0,0
0,0,0,0,0,0,0,0,0,0,0,0,0,0,0,0,0,0,0,0,0,0,0,0,0,0,0,0
0,0,0,0,0,0,0,0,0,0,0,0,0,0,0,0,0,0,0,0,0,0,0,0,0,0,0,0
:endlayer
layer: 33
0,0,0,0,0,0,0,0,0,0,0,0,0,0,0,0,0,0,0,0,0,0,0,0,0,0,0,0
0,0,0,0,0,0,0,0,0,0,0,0,0,0,0,0,0,0,0,0,0,0,0,0,0,0,0,0
0,0,0,0,0,0,0,0,0,0,0,0,0,0,0,0,0,0,0,0,0,0,0,0,0,0,0,0
0,0,0,0,0,0,0,0,0,0,0,0,0,0,0,0,0,0,0,0,0,0,0,0,0,0,0,0
0,0,0,0,0,0,0,0,0,0,0,0,0,0,0,0,0,0,0,0,0,0,0,0,0,0,0,0
0,0,0,0,0,0,0,0,0,0,0,0,0,0,0,0,0,0,0,0,0,0,0,0,0,0,0,0
0,0,0,0,0,0,0,0,0,0,0,0,0,0,0,0,0,0,0,0,0,0,0,0,0,0,0,0
0,0,0,0,0,0,0,0,0,0,0,0,0,0,0,0,0,0,0,0,0,0,0,0,0,0,0,0
0,0,0,0,0,0,0,0,0,0,0,0,0,0,0,0,0,0,0,0,0,0,0,0,0,0,0,0
0,0,0,0,0,0,0,0,0,0,0,0,0,0,0,0,0,0,0,0,0,0,0,0,0,0,0,0
0,0,0,0,0,0,0,0,0,0,0,0,0,0,0,0,0,0,0,0,0,0,0,0,0,0,0,0
0,0,0,0,0,0,0,0,0,0,0,0,0,0,0,0,0,0,0,0,0,0,0,0,0,0,0,0
0,0,0,0,0,0,0,0,0,0,0,0,0,0,0,0,0,0,0,0,0,0,0,0,0,0,0,0
0,0,0,0,0,0,0,0,0,0,0,0,0,0,0,0,0,0,0,0,0,0,0,0,0,0,0,0
0,0,0,0,0,0,0,0,0,0,0,0,0,0,0,0,0,0,0,0,0,0,0,0,0,0,0,0
0,0,0,0,0,0,0,0,0,0,0,0,0,0,0,0,0,0,0,0,0,0,0,0,0,0,0,0
0,0,0,0,0,0,0,0,0,0,0,0,0,0,0,0,0,0,0,0,0,0,0,0,0,0,0,0
0,0,0,0,0,0,0,0,0,0,0,0,0,0,0,0,0,0,0,0,0,0,0,0,0,0,0,0
0,0,0,0,0,0,0,0,0,0,0,0,0,0,0,0,0,0,0,0,0,0,0,0,0,0,0,0
0,0,0,0,0,0,0,0,0,0,0,0,0,0,0,0,0,0,0,0,0,0,0,0,0,0,0,0
0,0,0,0,0,0,0,0,0,0,0,0,0,0,0,0,0,0,0,0,0,0,0,0,0,0,0,0
:endlayer
layer: 34
0,0,0,0,0,0,0,0,0,0,0,0,0,0,0,0,0,0,0,0,0,0,0,0,0,0,0,0
0,0,0,0,0,0,0,0,0,0,0,0,0,0,0,0,0,0,0,0,0,0,0,0,0,0,0,0
0,0,0,0,0,0,0,0,0,0,0,0,0,0,0,0,0,0,0,0,0,0,0,0,0,0,0,0
0,0,0,0,0,0,0,0,0,0,0,0,0,0,0,0,0,0,0,0,0,0,0,0,0,0,0,0
0,0,0,0,0,0,0,0,0,0,0,0,0,0,0,0,0,0,0,0,0,0,0,0,0,0,0,0
0,0,0,0,0,0,0,0,0,0,0,0,0,0,0,0,0,0,0,0,0,0,0,0,0,0,0,0
0,0,0,0,0,0,0,0,0,0,0,0,0,0,0,0,0,0,0,0,0,0,0,0,0,0,0,0
0,0,0,0,0,0,0,0,0,0,0,0,0,0,0,0,0,0,0,0,0,0,0,0,0,0,0,0
0,0,0,0,0,0,0,0,0,0,0,0,0,0,0,0,0,0,0,0,0,0,0,0,0,0,0,0
0,0,0,0,0,0,0,0,0,0,0,0,0,0,0,0,0,0,0,0,0,0,0,0,0,0,0,0
0,0,0,0,0,0,0,0,0,0,0,0,0,0,0,0,0,0,0,0,0,0,0,0,0,0,0,0
0,0,0,0,0,0,0,0,0,0,0,0,0,0,0,0,0,0,0,0,0,0,0,0,0,0,0,0
0,0,0,0,0,0,0,0,0,0,0,0,0,0,0,0,0,0,0,0,0,0,0,0,0,0,0,0
0,0,0,0,0,0,0,0,0,0,0,0,0,0,0,0,0,0,0,0,0,0,0,0,0,0,0,0
0,0,0,0,0,0,0,0,0,0,0,0,0,0,0,0,0,0,0,0,0,0,0,0,0,0,0,0
0,0,0,0,0,0,0,0,0,0,0,0,0,0,0,0,0,0,0,0,0,0,0,0,0,0,0,0
0,0,0,0,0,0,0,0,0,0,0,0,0,0,0,0,0,0,0,0,0,0,0,0,0,0,0,0
0,0,0,0,0,0,0,0,0,0,0,0,0,0,0,0,0,0,0,0,0,0,0,0,0,0,0,0
0,0,0,0,0,0,0,0,0,0,0,0,0,0,0,0,0,0,0,0,0,0,0,0,0,0,0,0
0,0,0,0,0,0,0,0,0,0,0,0,0,0,0,0,0,0,0,0,0,0,0,0,0,0,0,0
0,0,0,0,0,0,0,0,0,0,0,0,0,0,0,0,0,0,0,0,0,0,0,0,0,0,0,0
:endlayer
layer: 35
0,0,0,0,0,0,0,0,0,0,0,0,0,0,0,0,0,0,0,0,0,0,0,0,0,0,0,0
0,0,0,0,0,0,0,0,0,0,0,0,0,0,0,0,0,0,0,0,0,0,0,0,0,0,0,0
0,0,0,0,0,0,0,0,0,0,0,0,0,0,0,0,0,0,0,0,0,0,0,0,0,0,0,0
0,0,0,0,0,0,0,0,0,0,0,0,0,0,0,0,0,0,0,0,0,0,0,0,0,0,0,0
0,0,0,0,0,0,0,0,0,0,0,0,0,0,0,0,0,0,0,0,0,0,0,0,0,0,0,0
0,0,0,0,0,0,0,0,0,0,0,0,0,0,0,0,0,0,0,0,0,0,0,0,0,0,0,0
0,0,0,0,0,0,0,0,0,0,0,0,0,0,0,0,0,0,0,0,0,0,0,0,0,0,0,0
0,0,0,0,0,0,0,0,0,0,0,0,0,0,0,0,0,0,0,0,0,0,0,0,0,0,0,0
0,0,0,0,0,0,0,0,0,0,0,0,0,0,0,0,0,0,0,0,0,0,0,0,0,0,0,0
0,0,0,0,0,0,0,0,0,0,0,0,0,0,0,0,0,0,0,0,0,0,0,0,0,0,0,0
0,0,0,0,0,0,0,0,0,0,0,0,0,0,0,0,0,0,0,0,0,0,0,0,0,0,0,0
0,0,0,0,0,0,0,0,0,0,0,0,0,0,0,0,0,0,0,0,0,0,0,0,0,0,0,0
0,0,0,0,0,0,0,0,0,0,0,0,0,0,0,0,0,0,0,0,0,0,0,0,0,0,0,0
0,0,0,0,0,0,0,0,0,0,0,0,0,0,0,0,0,0,0,0,0,0,0,0,0,0,0,0
0,0,0,0,0,0,0,0,0,0,0,0,0,0,0,0,0,0,0,0,0,0,0,0,0,0,0,0
0,0,0,0,0,0,0,0,0,0,0,0,0,0,0,0,0,0,0,0,0,0,0,0,0,0,0,0
0,0,0,0,0,0,0,0,0,0,0,0,0,0,0,0,0,0,0,0,0,0,0,0,0,0,0,0
0,0,0,0,0,0,0,0,0,0,0,0,0,0,0,0,0,0,0,0,0,0,0,0,0,0,0,0
0,0,0,0,0,0,0,0,0,0,0,0,0,0,0,0,0,0,0,0,0,0,0,0,0,0,0,0
0,0,0,0,0,0,0,0,0,0,0,0,0,0,0,0,0,0,0,0,0,0,0,0,0,0,0,0
0,0,0,0,0,0,0,0,0,0,0,0,0,0,0,0,0,0,0,0,0,0,0,0,0,0,0,0
:endlayer
layer: 36
0,0,0,0,0,0,0,0,0,0,0,0,0,0,0,0,0,0,0,0,0,0,0,0,0,0,0,0
0,0,0,0,0,0,0,0,0,0,0,0,0,0,0,0,0,0,0,0,0,0,0,0,0,0,0,0
0,0,0,0,0,0,0,0,0,0,0,0,0,0,0,0,0,0,0,0,0,0,0,0,0,0,0,0
0,0,0,0,0,0,0,0,0,0,0,0,0,0,0,0,0,0,0,0,0,0,0,0,0,0,0,0
0,0,0,0,0,0,0,0,0,0,0,0,0,0,0,0,0,0,0,0,0,0,0,0,0,0,0,0
0,0,0,0,0,0,0,0,0,0,0,0,0,0,0,0,0,0,0,0,0,0,0,0,0,0,0,0
0,0,0,0,0,0,0,0,0,0,0,0,0,0,0,0,0,0,0,0,0,0,0,0,0,0,0,0
0,0,0,0,0,0,0,0,0,0,0,0,0,0,0,0,0,0,0,0,0,0,0,0,0,0,0,0
0,0,0,0,0,0,0,0,0,0,0,0,0,0,0,0,0,0,0,0,0,0,0,0,0,0,0,0
0,0,0,0,0,0,0,0,0,0,0,0,0,0,0,0,0,0,0,0,0,0,0,0,0,0,0,0
0,0,0,0,0,0,0,0,0,0,0,0,0,0,0,0,0,0,0,0,0,0,0,0,0,0,0,0
0,0,0,0,0,0,0,0,0,0,0,0,0,0,0,0,0,0,0,0,0,0,0,0,0,0,0,0
0,0,0,0,0,0,0,0,0,0,0,0,0,0,0,0,0,0,0,0,0,0,0,0,0,0,0,0
0,0,0,0,0,0,0,0,0,0,0,0,0,0,0,0,0,0,0,0,0,0,0,0,0,0,0,0
0,0,0,0,0,0,0,0,0,0,0,0,0,0,0,0,0,0,0,0,0,0,0,0,0,0,0,0
0,0,0,0,0,0,0,0,0,0,0,0,0,0,0,0,0,0,0,0,0,0,0,0,0,0,0,0
0,0,0,0,0,0,0,0,0,0,0,0,0,0,0,0,0,0,0,0,0,0,0,0,0,0,0,0
0,0,0,0,0,0,0,0,0,0,0,0,0,0,0,0,0,0,0,0,0,0,0,0,0,0,0,0
0,0,0,0,0,0,0,0,0,0,0,0,0,0,0,0,0,0,0,0,0,0,0,0,0,0,0,0
0,0,0,0,0,0,0,0,0,0,0,0,0,0,0,0,0,0,0,0,0,0,0,0,0,0,0,0
0,0,0,0,0,0,0,0,0,0,0,0,0,0,0,0,0,0,0,0,0,0,0,0,0,0,0,0
:endlayer
layer: 37
0,0,0,0,0,0,0,0,0,0,0,0,0,0,0,0,0,0,0,0,0,0,0,0,0,0,0,0
0,0,0,0,0,0,0,0,0,0,0,0,0,0,0,0,0,0,0,0,0,0,0,0,0,0,0,0
0,0,0,0,0,0,0,0,0,0,0,0,0,0,0,0,0,0,0,0,0,0,0,0,0,0,0,0
0,0,0,0,0,0,0,0,0,0,0,0,0,0,0,0,0,0,0,0,0,0,0,0,0,0,0,0
0,0,0,0,0,0,0,0,0,0,0,0,0,0,0,0,0,0,0,0,0,0,0,0,0,0,0,0
0,0,0,0,0,0,0,0,0,0,0,0,0,0,0,0,0,0,0,0,0,0,0,0,0,0,0,0
0,0,0,0,0,0,0,0,0,0,0,0,0,0,0,0,0,0,0,0,0,0,0,0,0,0,0,0
0,0,0,0,0,0,0,0,0,0,0,0,0,0,0,0,0,0,0,0,0,0,0,0,0,0,0,0
0,0,0,0,0,0,0,0,0,0,0,0,0,0,0,0,0,0,0,0,0,0,0,0,0,0,0,0
0,0,0,0,0,0,0,0,0,0,0,0,0,0,0,0,0,0,0,0,0,0,0,0,0,0,0,0
0,0,0,0,0,0,0,0,0,0,0,0,0,0,0,0,0,0,0,0,0,0,0,0,0,0,0,0
0,0,0,0,0,0,0,0,0,0,0,0,0,0,0,0,0,0,0,0,0,0,0,0,0,0,0,0
0,0,0,0,0,0,0,0,0,0,0,0,0,0,0,0,0,0,0,0,0,0,0,0,0,0,0,0
0,0,0,0,0,0,0,0,0,0,0,0,0,0,0,0,0,0,0,0,0,0,0,0,0,0,0,0
0,0,0,0,0,0,0,0,0,0,0,0,0,0,0,0,0,0,0,0,0,0,0,0,0,0,0,0
0,0,0,0,0,0,0,0,0,0,0,0,0,0,0,0,0,0,0,0,0,0,0,0,0,0,0,0
0,0,0,0,0,0,0,0,0,0,0,0,0,0,0,0,0,0,0,0,0,0,0,0,0,0,0,0
0,0,0,0,0,0,0,0,0,0,0,0,0,0,0,0,0,0,0,0,0,0,0,0,0,0,0,0
0,0,0,0,0,0,0,0,0,0,0,0,0,0,0,0,0,0,0,0,0,0,0,0,0,0,0,0
0,0,0,0,0,0,0,0,0,0,0,0,0,0,0,0,0,0,0,0,0,0,0,0,0,0,0,0
0,0,0,0,0,0,0,0,0,0,0,0,0,0,0,0,0,0,0,0,0,0,0,0,0,0,0,0
:endlayer
layer: 38
0,0,0,0,0,0,0,0,0,0,0,0,0,0,0,0,0,0,0,0,0,0,0,0,0,0,0,0
0,0,0,0,0,0,0,0,0,0,0,0,0,0,0,0,0,0,0,0,0,0,0,0,0,0,0,0
0,0,0,0,0,0,0,0,0,0,0,0,0,0,0,0,0,0,0,0,0,0,0,0,0,0,0,0
0,0,0,0,0,0,0,0,0,0,0,0,0,0,0,0,0,0,0,0,0,0,0,0,0,0,0,0
0,0,0,0,0,0,0,0,0,0,0,0,0,0,0,0,0,0,0,0,0,0,0,0,0,0,0,0
0,0,0,0,0,0,0,0,0,0,0,0,0,0,0,0,0,0,0,0,0,0,0,0,0,0,0,0
0,0,0,0,0,0,0,0,0,0,0,0,0,0,0,0,0,0,0,0,0,0,0,0,0,0,0,0
0,0,0,0,0,0,0,0,0,0,0,0,0,0,0,0,0,0,0,0,0,0,0,0,0,0,0,0
0,0,0,0,0,0,0,0,0,0,0,0,0,0,0,0,0,0,0,0,0,0,0,0,0,0,0,0
0,0,0,0,0,0,0,0,0,0,0,0,0,0,0,0,0,0,0,0,0,0,0,0,0,0,0,0
0,0,0,0,0,0,0,0,0,0,0,0,0,0,0,0,0,0,0,0,0,0,0,0,0,0,0,0
0,0,0,0,0,0,0,0,0,0,0,0,0,0,0,0,0,0,0,0,0,0,0,0,0,0,0,0
0,0,0,0,0,0,0,0,0,0,0,0,0,0,0,0,0,0,0,0,0,0,0,0,0,0,0,0
0,0,0,0,0,0,0,0,0,0,0,0,0,0,0,0,0,0,0,0,0,0,0,0,0,0,0,0
0,0,0,0,0,0,0,0,0,0,0,0,0,0,0,0,0,0,0,0,0,0,0,0,0,0,0,0
0,0,0,0,0,0,0,0,0,0,0,0,0,0,0,0,0,0,0,0,0,0,0,0,0,0,0,0
0,0,0,0,0,0,0,0,0,0,0,0,0,0,0,0,0,0,0,0,0,0,0,0,0,0,0,0
0,0,0,0,0,0,0,0,0,0,0,0,0,0,0,0,0,0,0,0,0,0,0,0,0,0,0,0
0,0,0,0,0,0,0,0,0,0,0,0,0,0,0,0,0,0,0,0,0,0,0,0,0,0,0,0
0,0,0,0,0,0,0,0,0,0,0,0,0,0,0,0,0,0,0,0,0,0,0,0,0,0,0,0
0,0,0,0,0,0,0,0,0,0,0,0,0,0,0,0,0,0,0,0,0,0,0,0,0,0,0,0
:endlayer
layer: 39
0,0,0,0,0,0,0,0,0,0,0,0,0,0,0,0,0,0,0,0,0,0,0,0,0,0,0,0
0,0,0,0,0,0,0,0,0,0,0,0,0,0,0,0,0,0,0,0,0,0,0,0,0,0,0,0
0,0,0,0,0,0,0,0,0,0,0,0,0,0,0,0,0,0,0,0,0,0,0,0,0,0,0,0
0,0,0,0,0,0,0,0,0,0,0,0,0,0,0,0,0,0,0,0,0,0,0,0,0,0,0,0
0,0,0,0,0,0,0,0,0,0,0,0,0,0,0,0,0,0,0,0,0,0,0,0,0,0,0,0
0,0,0,0,0,0,0,0,0,0,0,0,0,0,0,0,0,0,0,0,0,0,0,0,0,0,0,0
0,0,0,0,0,0,0,0,0,0,0,0,0,0,0,0,0,0,0,0,0,0,0,0,0,0,0,0
0,0,0,0,0,0,0,0,0,0,0,0,0,0,0,0,0,0,0,0,0,0,0,0,0,0,0,0
0,0,0,0,0,0,0,0,0,0,0,0,0,0,0,0,0,0,0,0,0,0,0,0,0,0,0,0
0,0,0,0,0,0,0,0,0,0,0,0,0,0,0,0,0,0,0,0,0,0,0,0,0,0,0,0
0,0,0,0,0,0,0,0,0,0,0,0,0,0,0,0,0,0,0,0,0,0,0,0,0,0,0,0
0,0,0,0,0,0,0,0,0,0,0,0,0,0,0,0,0,0,0,0,0,0,0,0,0,0,0,0
0,0,0,0,0,0,0,0,0,0,0,0,0,0,0,0,0,0,0,0,0,0,0,0,0,0,0,0
0,0,0,0,0,0,0,0,0,0,0,0,0,0,0,0,0,0,0,0,0,0,0,0,0,0,0,0
0,0,0,0,0,0,0,0,0,0,0,0,0,0,0,0,0,0,0,0,0,0,0,0,0,0,0,0
0,0,0,0,0,0,0,0,0,0,0,0,0,0,0,0,0,0,0,0,0,0,0,0,0,0,0,0
0,0,0,0,0,0,0,0,0,0,0,0,0,0,0,0,0,0,0,0,0,0,0,0,0,0,0,0
0,0,0,0,0,0,0,0,0,0,0,0,0,0,0,0,0,0,0,0,0,0,0,0,0,0,0,0
0,0,0,0,0,0,0,0,0,0,0,0,0,0,0,0,0,0,0,0,0,0,0,0,0,0,0,0
0,0,0,0,0,0,0,0,0,0,0,0,0,0,0,0,0,0,0,0,0,0,0,0,0,0,0,0
0,0,0,0,0,0,0,0,0,0,0,0,0,0,0,0,0,0,0,0,0,0,0,0,0,0,0,0
:endlayer
layer: 40
0,0,0,0,0,0,0,0,0,0,0,0,0,0,0,0,0,0,0,0,0,0,0,0,0,0,0,0
0,0,0,0,0,0,0,0,0,0,0,0,0,0,0,0,0,0,0,0,0,0,0,0,0,0,0,0
0,0,0,0,0,0,0,0,0,0,0,0,0,0,0,0,0,0,0,0,0,0,0,0,0,0,0,0
0,0,0,0,0,0,0,0,0,0,0,0,0,0,0,0,0,0,0,0,0,0,0,0,0,0,0,0
0,0,0,0,0,0,0,0,0,0,0,0,0,0,0,0,0,0,0,0,0,0,0,0,0,0,0,0
0,0,0,0,0,0,0,0,0,0,0,0,0,0,0,0,0,0,0,0,0,0,0,0,0,0,0,0
0,0,0,0,0,0,0,0,0,0,0,0,0,0,0,0,0,0,0,0,0,0,0,0,0,0,0,0
0,0,0,0,0,0,0,0,0,0,0,0,0,0,0,0,0,0,0,0,0,0,0,0,0,0,0,0
0,0,0,0,0,0,0,0,0,0,0,0,0,0,0,0,0,0,0,0,0,0,0,0,0,0,0,0
0,0,0,0,0,0,0,0,0,0,0,0,0,0,0,0,0,0,0,0,0,0,0,0,0,0,0,0
0,0,0,0,0,0,0,0,0,0,0,0,0,0,0,0,0,0,0,0,0,0,0,0,0,0,0,0
0,0,0,0,0,0,0,0,0,0,0,0,0,0,0,0,0,0,0,0,0,0,0,0,0,0,0,0
0,0,0,0,0,0,0,0,0,0,0,0,0,0,0,0,0,0,0,0,0,0,0,0,0,0,0,0
0,0,0,0,0,0,0,0,0,0,0,0,0,0,0,0,0,0,0,0,0,0,0,0,0,0,0,0
0,0,0,0,0,0,0,0,0,0,0,0,0,0,0,0,0,0,0,0,0,0,0,0,0,0,0,0
0,0,0,0,0,0,0,0,0,0,0,0,0,0,0,0,0,0,0,0,0,0,0,0,0,0,0,0
0,0,0,0,0,0,0,0,0,0,0,0,0,0,0,0,0,0,0,0,0,0,0,0,0,0,0,0
0,0,0,0,0,0,0,0,0,0,0,0,0,0,0,0,0,0,0,0,0,0,0,0,0,0,0,0
0,0,0,0,0,0,0,0,0,0,0,0,0,0,0,0,0,0,0,0,0,0,0,0,0,0,0,0
0,0,0,0,0,0,0,0,0,0,0,0,0,0,0,0,0,0,0,0,0,0,0,0,0,0,0,0
0,0,0,0,0,0,0,0,0,0,0,0,0,0,0,0,0,0,0,0,0,0,0,0,0,0,0,0
:endlayer
layer: 41
0,0,0,0,0,0,0,0,0,0,0,0,0,0,0,0,0,0,0,0,0,0,0,0,0,0,0,0
0,0,0,0,0,0,0,0,0,0,0,0,0,0,0,0,0,0,0,0,0,0,0,0,0,0,0,0
0,0,0,0,0,0,0,0,0,0,0,0,0,0,0,0,0,0,0,0,0,0,0,0,0,0,0,0
0,0,0,0,0,0,0,0,0,0,0,0,0,0,0,0,0,0,0,0,0,0,0,0,0,0,0,0
0,0,0,0,0,0,0,0,0,0,0,0,0,0,0,0,0,0,0,0,0,0,0,0,0,0,0,0
0,0,0,0,0,0,0,0,0,0,0,0,0,0,0,0,0,0,0,0,0,0,0,0,0,0,0,0
0,0,0,0,0,0,0,0,0,0,0,0,0,0,0,0,0,0,0,0,0,0,0,0,0,0,0,0
0,0,0,0,0,0,0,0,0,0,0,0,0,0,0,0,0,0,0,0,0,0,0,0,0,0,0,0
0,0,0,0,0,0,0,0,0,0,0,0,0,0,0,0,0,0,0,0,0,0,0,0,0,0,0,0
0,0,0,0,0,0,0,0,0,0,0,0,0,0,0,0,0,0,0,0,0,0,0,0,0,0,0,0
0,0,0,0,0,0,0,0,0,0,0,0,0,0,0,0,0,0,0,0,0,0,0,0,0,0,0,0
0,0,0,0,0,0,0,0,0,0,0,0,0,0,0,0,0,0,0,0,0,0,0,0,0,0,0,0
0,0,0,0,0,0,0,0,0,0,0,0,0,0,0,0,0,0,0,0,0,0,0,0,0,0,0,0
0,0,0,0,0,0,0,0,0,0,0,0,0,0,0,0,0,0,0,0,0,0,0,0,0,0,0,0
0,0,0,0,0,0,0,0,0,0,0,0,0,0,0,0,0,0,0,0,0,0,0,0,0,0,0,0
0,0,0,0,0,0,0,0,0,0,0,0,0,0,0,0,0,0,0,0,0,0,0,0,0,0,0,0
0,0,0,0,0,0,0,0,0,0,0,0,0,0,0,0,0,0,0,0,0,0,0,0,0,0,0,0
0,0,0,0,0,0,0,0,0,0,0,0,0,0,0,0,0,0,0,0,0,0,0,0,0,0,0,0
0,0,0,0,0,0,0,0,0,0,0,0,0,0,0,0,0,0,0,0,0,0,0,0,0,0,0,0
0,0,0,0,0,0,0,0,0,0,0,0,0,0,0,0,0,0,0,0,0,0,0,0,0,0,0,0
0,0,0,0,0,0,0,0,0,0,0,0,0,0,0,0,0,0,0,0,0,0,0,0,0,0,0,0
:endlayer
layer: 42
0,0,0,0,0,0,0,0,0,0,0,0,0,0,0,0,0,0,0,0,0,0,0,0,0,0,0,0
0,0,0,0,0,0,0,0,0,0,0,0,0,0,0,0,0,0,0,0,0,0,0,0,0,0,0,0
0,0,0,0,0,0,0,0,0,0,0,0,0,0,0,0,0,0,0,0,0,0,0,0,0,0,0,0
0,0,0,0,0,0,0,0,0,0,0,0,0,0,0,0,0,0,0,0,0,0,0,0,0,0,0,0
0,0,0,0,0,0,0,0,0,0,0,0,0,0,0,0,0,0,0,0,0,0,0,0,0,0,0,0
0,0,0,0,0,0,0,0,0,0,0,0,0,0,0,0,0,0,0,0,0,0,0,0,0,0,0,0
0,0,0,0,0,0,0,0,0,0,0,0,0,0,0,0,0,0,0,0,0,0,0,0,0,0,0,0
0,0,0,0,0,0,0,0,0,0,0,0,0,0,0,0,0,0,0,0,0,0,0,0,0,0,0,0
0,0,0,0,0,0,0,0,0,0,0,0,0,0,0,0,0,0,0,0,0,0,0,0,0,0,0,0
0,0,0,0,0,0,0,0,0,0,0,0,0,0,0,0,0,0,0,0,0,0,0,0,0,0,0,0
0,0,0,0,0,0,0,0,0,0,0,0,0,0,0,0,0,0,0,0,0,0,0,0,0,0,0,0
0,0,0,0,0,0,0,0,0,0,0,0,0,0,0,0,0,0,0,0,0,0,0,0,0,0,0,0
0,0,0,0,0,0,0,0,0,0,0,0,0,0,0,0,0,0,0,0,0,0,0,0,0,0,0,0
0,0,0,0,0,0,0,0,0,0,0,0,0,0,0,0,0,0,0,0,0,0,0,0,0,0,0,0
0,0,0,0,0,0,0,0,0,0,0,0,0,0,0,0,0,0,0,0,0,0,0,0,0,0,0,0
0,0,0,0,0,0,0,0,0,0,0,0,0,0,0,0,0,0,0,0,0,0,0,0,0,0,0,0
0,0,0,0,0,0,0,0,0,0,0,0,0,0,0,0,0,0,0,0,0,0,0,0,0,0,0,0
0,0,0,0,0,0,0,0,0,0,0,0,0,0,0,0,0,0,0,0,0,0,0,0,0,0,0,0
0,0,0,0,0,0,0,0,0,0,0,0,0,0,0,0,0,0,0,0,0,0,0,0,0,0,0,0
0,0,0,0,0,0,0,0,0,0,0,0,0,0,0,0,0,0,0,0,0,0,0,0,0,0,0,0
0,0,0,0,0,0,0,0,0,0,0,0,0,0,0,0,0,0,0,0,0,0,0,0,0,0,0,0
:endlayer
layer: 43
0,0,0,0,0,0,0,0,0,0,0,0,0,0,0,0,0,0,0,0,0,0,0,0,0,0,0,0
0,0,0,0,0,0,0,0,0,0,0,0,0,0,0,0,0,0,0,0,0,0,0,0,0,0,0,0
0,0,0,0,0,0,0,0,0,0,0,0,0,0,0,0,0,0,0,0,0,0,0,0,0,0,0,0
0,0,0,0,0,0,0,0,0,0,0,0,0,0,0,0,0,0,0,0,0,0,0,0,0,0,0,0
0,0,0,0,0,0,0,0,0,0,0,0,0,0,0,0,0,0,0,0,0,0,0,0,0,0,0,0
0,0,0,0,0,0,0,0,0,0,0,0,0,0,0,0,0,0,0,0,0,0,0,0,0,0,0,0
0,0,0,0,0,0,0,0,0,0,0,0,0,0,0,0,0,0,0,0,0,0,0,0,0,0,0,0
0,0,0,0,0,0,0,0,0,0,0,0,0,0,0,0,0,0,0,0,0,0,0,0,0,0,0,0
0,0,0,0,0,0,0,0,0,0,0,0,0,0,0,0,0,0,0,0,0,0,0,0,0,0,0,0
0,0,0,0,0,0,0,0,0,0,0,0,0,0,0,0,0,0,0,0,0,0,0,0,0,0,0,0
0,0,0,0,0,0,0,0,0,0,0,0,0,0,0,0,0,0,0,0,0,0,0,0,0,0,0,0
0,0,0,0,0,0,0,0,0,0,0,0,0,0,0,0,0,0,0,0,0,0,0,0,0,0,0,0
0,0,0,0,0,0,0,0,0,0,0,0,0,0,0,0,0,0,0,0,0,0,0,0,0,0,0,0
0,0,0,0,0,0,0,0,0,0,0,0,0,0,0,0,0,0,0,0,0,0,0,0,0,0,0,0
0,0,0,0,0,0,0,0,0,0,0,0,0,0,0,0,0,0,0,0,0,0,0,0,0,0,0,0
0,0,0,0,0,0,0,0,0,0,0,0,0,0,0,0,0,0,0,0,0,0,0,0,0,0,0,0
0,0,0,0,0,0,0,0,0,0,0,0,0,0,0,0,0,0,0,0,0,0,0,0,0,0,0,0
0,0,0,0,0,0,0,0,0,0,0,0,0,0,0,0,0,0,0,0,0,0,0,0,0,0,0,0
0,0,0,0,0,0,0,0,0,0,0,0,0,0,0,0,0,0,0,0,0,0,0,0,0,0,0,0
0,0,0,0,0,0,0,0,0,0,0,0,0,0,0,0,0,0,0,0,0,0,0,0,0,0,0,0
0,0,0,0,0,0,0,0,0,0,0,0,0,0,0,0,0,0,0,0,0,0,0,0,0,0,0,0
:endlayer
layer: 44
0,0,0,0,0,0,0,0,0,0,0,0,0,0,0,0,0,0,0,0,0,0,0,0,0,0,0,0
0,0,0,0,0,0,0,0,0,0,0,0,0,0,0,0,0,0,0,0,0,0,0,0,0,0,0,0
0,0,0,0,0,0,0,0,0,0,0,0,0,0,0,0,0,0,0,0,0,0,0,0,0,0,0,0
0,0,0,0,0,0,0,0,0,0,0,0,0,0,0,0,0,0,0,0,0,0,0,0,0,0,0,0
0,0,0,0,0,0,0,0,0,0,0,0,0,0,0,0,0,0,0,0,0,0,0,0,0,0,0,0
0,0,0,0,0,0,0,0,0,0,0,0,0,0,0,0,0,0,0,0,0,0,0,0,0,0,0,0
0,0,0,0,0,0,0,0,0,0,0,0,0,0,0,0,0,0,0,0,0,0,0,0,0,0,0,0
0,0,0,0,0,0,0,0,0,0,0,0,0,0,0,0,0,0,0,0,0,0,0,0,0,0,0,0
0,0,0,0,0,0,0,0,0,0,0,0,0,0,0,0,0,0,0,0,0,0,0,0,0,0,0,0
0,0,0,0,0,0,0,0,0,0,0,0,0,0,0,0,0,0,0,0,0,0,0,0,0,0,0,0
0,0,0,0,0,0,0,0,0,0,0,0,0,0,0,0,0,0,0,0,0,0,0,0,0,0,0,0
0,0,0,0,0,0,0,0,0,0,0,0,0,0,0,0,0,0,0,0,0,0,0,0,0,0,0,0
0,0,0,0,0,0,0,0,0,0,0,0,0,0,0,0,0,0,0,0,0,0,0,0,0,0,0,0
0,0,0,0,0,0,0,0,0,0,0,0,0,0,0,0,0,0,0,0,0,0,0,0,0,0,0,0
0,0,0,0,0,0,0,0,0,0,0,0,0,0,0,0,0,0,0,0,0,0,0,0,0,0,0,0
0,0,0,0,0,0,0,0,0,0,0,0,0,0,0,0,0,0,0,0,0,0,0,0,0,0,0,0
0,0,0,0,0,0,0,0,0,0,0,0,0,0,0,0,0,0,0,0,0,0,0,0,0,0,0,0
0,0,0,0,0,0,0,0,0,0,0,0,0,0,0,0,0,0,0,0,0,0,0,0,0,0,0,0
0,0,0,0,0,0,0,0,0,0,0,0,0,0,0,0,0,0,0,0,0,0,0,0,0,0,0,0
0,0,0,0,0,0,0,0,0,0,0,0,0,0,0,0,0,0,0,0,0,0,0,0,0,0,0,0
0,0,0,0,0,0,0,0,0,0,0,0,0,0,0,0,0,0,0,0,0,0,0,0,0,0,0,0
:endlayer
layer: 45
0,0,0,0,0,0,0,0,0,0,0,0,0,0,0,0,0,0,0,0,0,0,0,0,0,0,0,0
0,0,0,0,0,0,0,0,0,0,0,0,0,0,0,0,0,0,0,0,0,0,0,0,0,0,0,0
0,0,0,0,0,0,0,0,0,0,0,0,0,0,0,0,0,0,0,0,0,0,0,0,0,0,0,0
0,0,0,0,0,0,0,0,0,0,0,0,0,0,0,0,0,0,0,0,0,0,0,0,0,0,0,0
0,0,0,0,0,0,0,0,0,0,0,0,0,0,0,0,0,0,0,0,0,0,0,0,0,0,0,0
0,0,0,0,0,0,0,0,0,0,0,0,0,0,0,0,0,0,0,0,0,0,0,0,0,0,0,0
0,0,0,0,0,0,0,0,0,0,0,0,0,0,0,0,0,0,0,0,0,0,0,0,0,0,0,0
0,0,0,0,0,0,0,0,0,0,0,0,0,0,0,0,0,0,0,0,0,0,0,0,0,0,0,0
0,0,0,0,0,0,0,0,0,0,0,0,0,0,0,0,0,0,0,0,0,0,0,0,0,0,0,0
0,0,0,0,0,0,0,0,0,0,0,0,0,0,0,0,0,0,0,0,0,0,0,0,0,0,0,0
0,0,0,0,0,0,0,0,0,0,0,0,0,0,0,0,0,0,0,0,0,0,0,0,0,0,0,0
0,0,0,0,0,0,0,0,0,0,0,0,0,0,0,0,0,0,0,0,0,0,0,0,0,0,0,0
0,0,0,0,0,0,0,0,0,0,0,0,0,0,0,0,0,0,0,0,0,0,0,0,0,0,0,0
0,0,0,0,0,0,0,0,0,0,0,0,0,0,0,0,0,0,0,0,0,0,0,0,0,0,0,0
0,0,0,0,0,0,0,0,0,0,0,0,0,0,0,0,0,0,0,0,0,0,0,0,0,0,0,0
0,0,0,0,0,0,0,0,0,0,0,0,0,0,0,0,0,0,0,0,0,0,0,0,0,0,0,0
0,0,0,0,0,0,0,0,0,0,0,0,0,0,0,0,0,0,0,0,0,0,0,0,0,0,0,0
0,0,0,0,0,0,0,0,0,0,0,0,0,0,0,0,0,0,0,0,0,0,0,0,0,0,0,0
0,0,0,0,0,0,0,0,0,0,0,0,0,0,0,0,0,0,0,0,0,0,0,0,0,0,0,0
0,0,0,0,0,0,0,0,0,0,0,0,0,0,0,0,0,0,0,0,0,0,0,0,0,0,0,0
0,0,0,0,0,0,0,0,0,0,0,0,0,0,0,0,0,0,0,0,0,0,0,0,0,0,0,0
:endlayer

#### RULES ####
rule:
plugin=vanillaBlocks
number=1
data:
JSON:{{"val":{"blockName":{"val":"minecraft:dirt","id":"ss"},"meta":{"val":"0","id":"pi"},"buildPass":{"val":"0","id":"pi"}},"id":"ct"}}
:enddata
:endrule

rule:
plugin=vanillaBlocks
number=2
data:
JSON:{{"val":{"blockName":{"val":"minecraft:grass","id":"ss"},"meta":{"val":"0","id":"pi"},"buildPass":{"val":"0","id":"pi"}},"id":"ct"}}
:enddata
:endrule

rule:
plugin=vanillaBlocks
number=3
data:
JSON:{{"val":{"blockName":{"val":"minecraft:planks","id":"ss"},"meta":{"val":"5","id":"pi"},"buildPass":{"val":"0","id":"pi"}},"id":"ct"}}
:enddata
:endrule

rule:
plugin=vanillaBlocks
number=4
data:
JSON:{{"val":{"blockName":{"val":"minecraft:cobblestone","id":"ss"},"meta":{"val":"0","id":"pi"},"buildPass":{"val":"0","id":"pi"}},"id":"ct"}}
:enddata
:endrule

rule:
plugin=vanillaBlocks
number=5
data:
JSON:{{"val":{"blockName":{"val":"minecraft:netherrack","id":"ss"},"meta":{"val":"0","id":"pi"},"buildPass":{"val":"0","id":"pi"}},"id":"ct"}}
:enddata
:endrule

rule:
plugin=vanillaBlocks
number=6
data:
JSON:{{"val":{"blockName":{"val":"minecraft:snow_layer","id":"ss"},"meta":{"val":"0","id":"pi"},"buildPass":{"val":"2","id":"pi"}},"id":"ct"}}
:enddata
:endrule

rule:
plugin=vanillaBlocks
number=7
data:
JSON:{{"val":{"blockName":{"val":"minecraft:fence","id":"ss"},"meta":{"val":"0","id":"pi"},"buildPass":{"val":"0","id":"pi"}},"id":"ct"}}
:enddata
:endrule

rule:
plugin=vanillaBlocks
number=8
data:
JSON:{{"val":{"blockName":{"val":"minecraft:log","id":"ss"},"meta":{"val":"0","id":"pi"},"buildPass":{"val":"0","id":"pi"}},"id":"ct"}}
:enddata
:endrule

rule:
plugin=vanillaBlocks
number=9
data:
JSON:{{"val":{"blockName":{"val":"minecraft:snow_layer","id":"ss"},"meta":{"val":"1","id":"pi"},"buildPass":{"val":"2","id":"pi"}},"id":"ct"}}
:enddata
:endrule

rule:
plugin=vanillaDoors
number=10
data:
JSON:{{"val":{"sideFlag":{"val":"9","id":"pb"},"blockName":{"val":"minecraft:wooden_door","id":"ss"},"meta":{"val":"3","id":"pi"},"buildPass":{"val":"2","id":"pi"}},"id":"ct"}}
:enddata
:endrule

rule:
plugin=vanillaDoors
number=11
data:
JSON:{{"val":{"sideFlag":{"val":"8","id":"pb"},"blockName":{"val":"minecraft:wooden_door","id":"ss"},"meta":{"val":"3","id":"pi"},"buildPass":{"val":"2","id":"pi"}},"id":"ct"}}
:enddata
:endrule

rule:
plugin=vanillaBlocks
number=12
data:
JSON:{{"val":{"blockName":{"val":"minecraft:snow_layer","id":"ss"},"meta":{"val":"2","id":"pi"},"buildPass":{"val":"2","id":"pi"}},"id":"ct"}}
:enddata
:endrule

rule:
plugin=vanillaBlocks
number=13
data:
JSON:{{"val":{"blockName":{"val":"minecraft:dark_oak_stairs","id":"ss"},"meta":{"val":"0","id":"pi"},"buildPass":{"val":"0","id":"pi"}},"id":"ct"}}
:enddata
:endrule

rule:
plugin=vanillaBlocks
number=14
data:
JSON:{{"val":{"blockName":{"val":"minecraft:dark_oak_stairs","id":"ss"},"meta":{"val":"1","id":"pi"},"buildPass":{"val":"0","id":"pi"}},"id":"ct"}}
:enddata
:endrule

rule:
plugin=vanillaBlocks
number=15
data:
JSON:{{"val":{"blockName":{"val":"minecraft:stone_slab","id":"ss"},"meta":{"val":"3","id":"pi"},"buildPass":{"val":"0","id":"pi"}},"id":"ct"}}
:enddata
:endrule

rule:
plugin=vanillaDoors
number=16
data:
JSON:{{"val":{"sideFlag":{"val":"8","id":"pb"},"blockName":{"val":"minecraft:wooden_door","id":"ss"},"meta":{"val":"2","id":"pi"},"buildPass":{"val":"2","id":"pi"}},"id":"ct"}}
:enddata
:endrule

rule:
plugin=vanillaBlocks
number=17
data:
JSON:{{"val":{"blockName":{"val":"minecraft:fire","id":"ss"},"meta":{"val":"15","id":"pi"},"buildPass":{"val":"0","id":"pi"}},"id":"ct"}}
:enddata
:endrule

rule:
plugin=vanillaDoors
number=18
data:
JSON:{{"val":{"sideFlag":{"val":"9","id":"pb"},"blockName":{"val":"minecraft:wooden_door","id":"ss"},"meta":{"val":"0","id":"pi"},"buildPass":{"val":"2","id":"pi"}},"id":"ct"}}
:enddata
:endrule

rule:
plugin=vanillaDoors
number=19
data:
JSON:{{"val":{"sideFlag":{"val":"9","id":"pb"},"blockName":{"val":"minecraft:wooden_door","id":"ss"},"meta":{"val":"2","id":"pi"},"buildPass":{"val":"2","id":"pi"}},"id":"ct"}}
:enddata
:endrule

rule:
plugin=vanillaDoors
number=20
data:
JSON:{{"val":{"sideFlag":{"val":"8","id":"pb"},"blockName":{"val":"minecraft:wooden_door","id":"ss"},"meta":{"val":"0","id":"pi"},"buildPass":{"val":"2","id":"pi"}},"id":"ct"}}
:enddata
:endrule

rule:
plugin=vanillaBlocks
number=21
data:
JSON:{{"val":{"blockName":{"val":"minecraft:torch","id":"ss"},"meta":{"val":"3","id":"pi"},"buildPass":{"val":"2","id":"pi"}},"id":"ct"}}
:enddata
:endrule

rule:
plugin=vanillaDoors
number=22
data:
JSON:{{"val":{"sideFlag":{"val":"0","id":"pb"},"blockName":{"val":"minecraft:wooden_door","id":"ss"},"meta":{"val":"9","id":"pi"},"buildPass":{"val":"2","id":"pi"}},"id":"ct"}}
:enddata
:endrule

rule:
plugin=vanillaDoors
number=23
data:
JSON:{{"val":{"sideFlag":{"val":"0","id":"pb"},"blockName":{"val":"minecraft:wooden_door","id":"ss"},"meta":{"val":"8","id":"pi"},"buildPass":{"val":"2","id":"pi"}},"id":"ct"}}
:enddata
:endrule

rule:
plugin=vanillaBlocks
number=24
data:
JSON:{{"val":{"blockName":{"val":"minecraft:torch","id":"ss"},"meta":{"val":"1","id":"pi"},"buildPass":{"val":"2","id":"pi"}},"id":"ct"}}
:enddata
:endrule

rule:
plugin=vanillaBlocks
number=25
data:
JSON:{{"val":{"blockName":{"val":"minecraft:dark_oak_stairs","id":"ss"},"meta":{"val":"3","id":"pi"},"buildPass":{"val":"0","id":"pi"}},"id":"ct"}}
:enddata
:endrule

rule:
plugin=vanillaBlocks
number=26
data:
JSON:{{"val":{"blockName":{"val":"minecraft:cobblestone_wall","id":"ss"},"meta":{"val":"0","id":"pi"},"buildPass":{"val":"0","id":"pi"}},"id":"ct"}}
:enddata
:endrule

rule:
plugin=vanillaBlocks
number=27
data:
JSON:{{"val":{"blockName":{"val":"minecraft:iron_bars","id":"ss"},"meta":{"val":"0","id":"pi"},"buildPass":{"val":"0","id":"pi"}},"id":"ct"}}
:enddata
:endrule

rule:
plugin=vanillaBlocks
number=28
data:
JSON:{{"val":{"blockName":{"val":"minecraft:torch","id":"ss"},"meta":{"val":"2","id":"pi"},"buildPass":{"val":"2","id":"pi"}},"id":"ct"}}
:enddata
:endrule

rule:
plugin=vanillaDoors
number=29
data:
JSON:{{"val":{"sideFlag":{"val":"0","id":"pb"},"blockName":{"val":"minecraft:wooden_door","id":"ss"},"meta":{"val":"8","id":"pi"},"buildPass":{"val":"2","id":"pi"}},"id":"ct"}}
:enddata
:endrule

rule:
plugin=vanillaDoors
number=30
data:
JSON:{{"val":{"sideFlag":{"val":"0","id":"pb"},"blockName":{"val":"minecraft:wooden_door","id":"ss"},"meta":{"val":"9","id":"pi"},"buildPass":{"val":"2","id":"pi"}},"id":"ct"}}
:enddata
:endrule

rule:
plugin=vanillaDoors
number=31
data:
JSON:{{"val":{"sideFlag":{"val":"0","id":"pb"},"blockName":{"val":"minecraft:wooden_door","id":"ss"},"meta":{"val":"9","id":"pi"},"buildPass":{"val":"2","id":"pi"}},"id":"ct"}}
:enddata
:endrule

rule:
plugin=vanillaDoors
number=32
data:
JSON:{{"val":{"sideFlag":{"val":"0","id":"pb"},"blockName":{"val":"minecraft:wooden_door","id":"ss"},"meta":{"val":"8","id":"pi"},"buildPass":{"val":"2","id":"pi"}},"id":"ct"}}
:enddata
:endrule

rule:
plugin=vanillaBlocks
number=33
data:
JSON:{{"val":{"blockName":{"val":"minecraft:dark_oak_stairs","id":"ss"},"meta":{"val":"2","id":"pi"},"buildPass":{"val":"0","id":"pi"}},"id":"ct"}}
:enddata
:endrule

rule:
plugin=vanillaBlocks
number=34
data:
JSON:{{"val":{"blockName":{"val":"minecraft:torch","id":"ss"},"meta":{"val":"4","id":"pi"},"buildPass":{"val":"2","id":"pi"}},"id":"ct"}}
:enddata
:endrule

rule:
plugin=vanillaBlocks
number=35
data:
JSON:{{"val":{"blockName":{"val":"minecraft:stone_slab","id":"ss"},"meta":{"val":"2","id":"pi"},"buildPass":{"val":"0","id":"pi"}},"id":"ct"}}
:enddata
:endrule

rule:
plugin=vanillaBlocks
number=36
data:
JSON:{{"val":{"blockName":{"val":"minecraft:bed","id":"ss"},"meta":{"val":"2","id":"pi"},"buildPass":{"val":"2","id":"pi"}},"id":"ct"}}
:enddata
:endrule

rule:
plugin=vanillaInventory
number=37
data:
JSON:{{"val":{"lootLevel":{"val":"0","id":"pi"},"inventoryData":{"val":{"length":{"val":"27","id":"pi"},"inventoryContents":{"val":[{"val":{"item":{"val":"minecraft:diamond","id":"ss"},"damage":{"val":"0","id":"pi"},"quantity":{"val":"1","id":"pi"},"slot":{"val":"9","id":"pi"}},"id":"ct"},{"val":{"item":{"val":"minecraft:diamond_sword","id":"ss"},"damage":{"val":"0","id":"pi"},"quantity":{"val":"1","id":"pi"},"slot":{"val":"14","id":"pi"}},"id":"ct"}],"id":"ls"}},"id":"ct"},"teData":{"val":{"id":{"val":"Chest","id":"ss"},"z":{"val":"1903","id":"pi"},"y":{"val":"110","id":"pi"},"x":{"val":"1427","id":"pi"}},"id":"ct"},"blockName":{"val":"minecraft:chest","id":"ss"},"meta":{"val":"3","id":"pi"},"buildPass":{"val":"0","id":"pi"}},"id":"ct"}}
:enddata
:endrule

rule:
plugin=vanillaBlocks
number=38
data:
JSON:{{"val":{"blockName":{"val":"minecraft:bed","id":"ss"},"meta":{"val":"10","id":"pi"},"buildPass":{"val":"2","id":"pi"}},"id":"ct"}}
:enddata
:endrule

rule:
plugin=vanillaInventory
number=39
data:
JSON:{{"val":{"lootLevel":{"val":"0","id":"pi"},"inventoryData":{"val":{"length":{"val":"27","id":"pi"},"inventoryContents":{"val":[{"val":{"item":{"val":"minecraft:iron_ingot","id":"ss"},"damage":{"val":"0","id":"pi"},"quantity":{"val":"1","id":"pi"},"slot":{"val":"0","id":"pi"}},"id":"ct"},{"val":{"item":{"val":"minecraft:emerald","id":"ss"},"damage":{"val":"0","id":"pi"},"quantity":{"val":"1","id":"pi"},"slot":{"val":"1","id":"pi"}},"id":"ct"},{"val":{"item":{"val":"minecraft:iron_ingot","id":"ss"},"damage":{"val":"0","id":"pi"},"quantity":{"val":"3","id":"pi"},"slot":{"val":"2","id":"pi"}},"id":"ct"},{"val":{"item":{"val":"minecraft:iron_ingot","id":"ss"},"damage":{"val":"0","id":"pi"},"quantity":{"val":"1","id":"pi"},"slot":{"val":"3","id":"pi"}},"id":"ct"},{"val":{"item":{"val":"minecraft:gold_ingot","id":"ss"},"damage":{"val":"0","id":"pi"},"quantity":{"val":"1","id":"pi"},"slot":{"val":"4","id":"pi"}},"id":"ct"},{"val":{"item":{"val":"minecraft:iron_ingot","id":"ss"},"damage":{"val":"0","id":"pi"},"quantity":{"val":"1","id":"pi"},"slot":{"val":"5","id":"pi"}},"id":"ct"},{"val":{"item":{"val":"minecraft:redstone","id":"ss"},"damage":{"val":"0","id":"pi"},"quantity":{"val":"3","id":"pi"},"slot":{"val":"6","id":"pi"}},"id":"ct"},{"val":{"item":{"val":"minecraft:redstone","id":"ss"},"damage":{"val":"0","id":"pi"},"quantity":{"val":"2","id":"pi"},"slot":{"val":"7","id":"pi"}},"id":"ct"},{"val":{"item":{"val":"minecraft:redstone","id":"ss"},"damage":{"val":"0","id":"pi"},"quantity":{"val":"2","id":"pi"},"slot":{"val":"8","id":"pi"}},"id":"ct"},{"val":{"item":{"val":"minecraft:iron_ingot","id":"ss"},"damage":{"val":"0","id":"pi"},"quantity":{"val":"2","id":"pi"},"slot":{"val":"9","id":"pi"}},"id":"ct"},{"val":{"item":{"val":"minecraft:iron_ingot","id":"ss"},"damage":{"val":"0","id":"pi"},"quantity":{"val":"2","id":"pi"},"slot":{"val":"10","id":"pi"}},"id":"ct"},{"val":{"item":{"val":"minecraft:iron_ingot","id":"ss"},"damage":{"val":"0","id":"pi"},"quantity":{"val":"1","id":"pi"},"slot":{"val":"11","id":"pi"}},"id":"ct"},{"val":{"item":{"val":"minecraft:gold_ingot","id":"ss"},"damage":{"val":"0","id":"pi"},"quantity":{"val":"1","id":"pi"},"slot":{"val":"12","id":"pi"}},"id":"ct"},{"val":{"item":{"val":"minecraft:iron_ingot","id":"ss"},"damage":{"val":"0","id":"pi"},"quantity":{"val":"1","id":"pi"},"slot":{"val":"13","id":"pi"}},"id":"ct"},{"val":{"item":{"val":"minecraft:gold_ingot","id":"ss"},"damage":{"val":"0","id":"pi"},"quantity":{"val":"1","id":"pi"},"slot":{"val":"14","id":"pi"}},"id":"ct"},{"val":{"item":{"val":"minecraft:iron_ingot","id":"ss"},"damage":{"val":"0","id":"pi"},"quantity":{"val":"1","id":"pi"},"slot":{"val":"15","id":"pi"}},"id":"ct"},{"val":{"item":{"val":"minecraft:redstone","id":"ss"},"damage":{"val":"0","id":"pi"},"quantity":{"val":"3","id":"pi"},"slot":{"val":"16","id":"pi"}},"id":"ct"},{"val":{"item":{"val":"minecraft:redstone","id":"ss"},"damage":{"val":"0","id":"pi"},"quantity":{"val":"2","id":"pi"},"slot":{"val":"17","id":"pi"}},"id":"ct"},{"val":{"item":{"val":"minecraft:emerald","id":"ss"},"damage":{"val":"0","id":"pi"},"quantity":{"val":"1","id":"pi"},"slot":{"val":"18","id":"pi"}},"id":"ct"},{"val":{"item":{"val":"minecraft:iron_ingot","id":"ss"},"damage":{"val":"0","id":"pi"},"quantity":{"val":"1","id":"pi"},"slot":{"val":"19","id":"pi"}},"id":"ct"},{"val":{"item":{"val":"minecraft:iron_ingot","id":"ss"},"damage":{"val":"0","id":"pi"},"quantity":{"val":"1","id":"pi"},"slot":{"val":"20","id":"pi"}},"id":"ct"},{"val":{"item":{"val":"minecraft:emerald","id":"ss"},"damage":{"val":"0","id":"pi"},"quantity":{"val":"1","id":"pi"},"slot":{"val":"21","id":"pi"}},"id":"ct"},{"val":{"item":{"val":"minecraft:iron_ingot","id":"ss"},"damage":{"val":"0","id":"pi"},"quantity":{"val":"1","id":"pi"},"slot":{"val":"22","id":"pi"}},"id":"ct"},{"val":{"item":{"val":"minecraft:gold_ingot","id":"ss"},"damage":{"val":"0","id":"pi"},"quantity":{"val":"1","id":"pi"},"slot":{"val":"23","id":"pi"}},"id":"ct"},{"val":{"item":{"val":"minecraft:gold_ingot","id":"ss"},"damage":{"val":"0","id":"pi"},"quantity":{"val":"1","id":"pi"},"slot":{"val":"24","id":"pi"}},"id":"ct"},{"val":{"item":{"val":"minecraft:redstone","id":"ss"},"damage":{"val":"0","id":"pi"},"quantity":{"val":"3","id":"pi"},"slot":{"val":"25","id":"pi"}},"id":"ct"},{"val":{"item":{"val":"minecraft:redstone","id":"ss"},"damage":{"val":"0","id":"pi"},"quantity":{"val":"2","id":"pi"},"slot":{"val":"26","id":"pi"}},"id":"ct"}],"id":"ls"}},"id":"ct"},"teData":{"val":{"id":{"val":"Chest","id":"ss"},"z":{"val":"1903","id":"pi"},"y":{"val":"110","id":"pi"},"x":{"val":"1430","id":"pi"}},"id":"ct"},"blockName":{"val":"minecraft:chest","id":"ss"},"meta":{"val":"3","id":"pi"},"buildPass":{"val":"0","id":"pi"}},"id":"ct"}}
:enddata
:endrule

#### ENTITIES ####
entity:
plugin=AWNpc
number=0
data:
position=21,6,14
JSON:{{"val":{"entityData":{"val":{"DropChances":{"val":[{"val":"1.0","id":"pf"},{"val":"1.0","id":"pf"},{"val":"1.0","id":"pf"},{"val":"1.0","id":"pf"},{"val":"1.0","id":"pf"}],"id":"ls"},"Attributes":{"val":[{"val":{"Name":{"val":"generic.maxHealth","id":"ss"},"Base":{"val":"20.0","id":"pd"}},"id":"ct"},{"val":{"Name":{"val":"generic.knockbackResistance","id":"ss"},"Base":{"val":"0.0","id":"pd"}},"id":"ct"},{"val":{"Name":{"val":"generic.movementSpeed","id":"ss"},"Base":{"val":"0.325","id":"pd"}},"id":"ct"},{"val":{"Name":{"val":"generic.followRange","id":"ss"},"Base":{"val":"60.0","id":"pd"}},"id":"ct"},{"val":{"Name":{"val":"generic.attackDamage","id":"ss"},"Base":{"val":"2.0","id":"pd"}},"id":"ct"}],"id":"ls"},"Motion":{"val":[{"val":"0.0","id":"pd"},{"val":"-0.0784000015258789","id":"pd"},{"val":"0.0","id":"pd"}],"id":"ls"},"CustomName":{"val":"","id":"ss"},"Health":{"val":"20","id":"ps"},"HealF":{"val":"20.0","id":"pf"},"CustomNameVisible":{"val":"0","id":"pb"},"AttackTime":{"val":"0","id":"ps"},"Fire":{"val":"-1","id":"ps"},"attackDamageOverride":{"val":"-1","id":"pi"},"Invulnerable":{"val":"0","id":"pb"},"DeathTime":{"val":"0","id":"ps"},"ForgeData":{"val":{"WITCInitialWidth":{"val":"0.6","id":"pf"},"WITCInitialHeight":{"val":"1.8","id":"pf"}},"id":"ct"},"AbsorptionAmount":{"val":"0.0","id":"pf"},"OnGround":{"val":"1","id":"pb"},"HurtTime":{"val":"0","id":"ps"},"Dimension":{"val":"0","id":"pi"},"Air":{"val":"300","id":"ps"},"customTex":{"val":"","id":"ss"},"armorValueOverride":{"val":"-1","id":"pi"},"Pos":{"val":[{"val":"1421.5","id":"pd"},{"val":"103.0","id":"pd"},{"val":"1897.5","id":"pd"}],"id":"ls"},"CanPickUpLoot":{"val":"0","id":"pb"},"PortalCooldown":{"val":"0","id":"pi"},"PersistenceRequired":{"val":"1","id":"pb"},"shieldStack":{"val":{"item":{"val":"AncientWarfareNpc:iron_shield","id":"ss"},"damage":{"val":"0","id":"pi"},"quantity":{"val":"1","id":"pi"}},"id":"ct"},"Leashed":{"val":"0","id":"pb"},"owner":{"val":"OldMiniCollector","id":"ss"},"FallDistance":{"val":"0.0","id":"pf"},"Rotation":{"val":[{"val":"1.9870765","id":"pf"},{"val":"0.0","id":"pf"}],"id":"ls"},"levelingStats":{"val":{"level":{"val":"0","id":"pi"},"xp":{"val":"0","id":"pi"},"entryList":{"val":[],"id":"ls"}},"id":"ct"}},"id":"ct"},"xOffset":{"val":"0.5","id":"pf"},"mobID":{"val":"AncientWarfareNpc.viking.soldier","id":"ss"},"zOffset":{"val":"0.5","id":"pf"},"rotation":{"val":"181.98708","id":"pf"},"equipmentData":{"val":{"equipmentContents":{"val":[{"val":{"item":{"val":"minecraft:iron_sword","id":"ss"},"damage":{"val":"0","id":"pi"},"quantity":{"val":"1","id":"pi"},"slot":{"val":"0","id":"pi"}},"id":"ct"}],"id":"ls"},"length":{"val":"5","id":"pi"}},"id":"ct"}},"id":"ct"}}
:enddata
:endentity

entity:
plugin=AWNpc
number=1
data:
position=22,6,5
JSON:{{"val":{"entityData":{"val":{"DropChances":{"val":[{"val":"1.0","id":"pf"},{"val":"1.0","id":"pf"},{"val":"1.0","id":"pf"},{"val":"1.0","id":"pf"},{"val":"1.0","id":"pf"}],"id":"ls"},"Attributes":{"val":[{"val":{"Name":{"val":"generic.maxHealth","id":"ss"},"Base":{"val":"20.0","id":"pd"}},"id":"ct"},{"val":{"Name":{"val":"generic.knockbackResistance","id":"ss"},"Base":{"val":"0.0","id":"pd"}},"id":"ct"},{"val":{"Name":{"val":"generic.movementSpeed","id":"ss"},"Base":{"val":"0.325","id":"pd"}},"id":"ct"},{"val":{"Name":{"val":"generic.followRange","id":"ss"},"Base":{"val":"60.0","id":"pd"}},"id":"ct"},{"val":{"Name":{"val":"generic.attackDamage","id":"ss"},"Base":{"val":"2.0","id":"pd"}},"id":"ct"}],"id":"ls"},"Motion":{"val":[{"val":"0.0","id":"pd"},{"val":"-0.0784000015258789","id":"pd"},{"val":"0.0","id":"pd"}],"id":"ls"},"CustomName":{"val":"","id":"ss"},"Health":{"val":"20","id":"ps"},"HealF":{"val":"20.0","id":"pf"},"CustomNameVisible":{"val":"0","id":"pb"},"AttackTime":{"val":"0","id":"ps"},"Fire":{"val":"-1","id":"ps"},"attackDamageOverride":{"val":"-1","id":"pi"},"Invulnerable":{"val":"0","id":"pb"},"DeathTime":{"val":"0","id":"ps"},"ForgeData":{"val":{"WITCInitialWidth":{"val":"0.6","id":"pf"},"WITCInitialHeight":{"val":"1.8","id":"pf"}},"id":"ct"},"AbsorptionAmount":{"val":"0.0","id":"pf"},"OnGround":{"val":"1","id":"pb"},"HurtTime":{"val":"0","id":"ps"},"Dimension":{"val":"0","id":"pi"},"Air":{"val":"300","id":"ps"},"customTex":{"val":"","id":"ss"},"armorValueOverride":{"val":"-1","id":"pi"},"Pos":{"val":[{"val":"1420.5","id":"pd"},{"val":"103.0","id":"pd"},{"val":"1906.5","id":"pd"}],"id":"ls"},"CanPickUpLoot":{"val":"0","id":"pb"},"PortalCooldown":{"val":"0","id":"pi"},"PersistenceRequired":{"val":"1","id":"pb"},"shieldStack":{"val":{"item":{"val":"AncientWarfareNpc:iron_shield","id":"ss"},"damage":{"val":"0","id":"pi"},"quantity":{"val":"1","id":"pi"}},"id":"ct"},"Leashed":{"val":"0","id":"pb"},"owner":{"val":"OldMiniCollector","id":"ss"},"FallDistance":{"val":"0.0","id":"pf"},"Rotation":{"val":[{"val":"2.9467287","id":"pf"},{"val":"0.0","id":"pf"}],"id":"ls"},"levelingStats":{"val":{"level":{"val":"0","id":"pi"},"xp":{"val":"0","id":"pi"},"entryList":{"val":[],"id":"ls"}},"id":"ct"}},"id":"ct"},"xOffset":{"val":"0.5","id":"pf"},"mobID":{"val":"AncientWarfareNpc.viking.soldier","id":"ss"},"zOffset":{"val":"0.5","id":"pf"},"rotation":{"val":"182.94673","id":"pf"},"equipmentData":{"val":{"equipmentContents":{"val":[{"val":{"item":{"val":"minecraft:iron_sword","id":"ss"},"damage":{"val":"0","id":"pi"},"quantity":{"val":"1","id":"pi"},"slot":{"val":"0","id":"pi"}},"id":"ct"}],"id":"ls"},"length":{"val":"5","id":"pi"}},"id":"ct"}},"id":"ct"}}
:enddata
:endentity

entity:
plugin=AWNpc
number=2
data:
position=14,13,10
JSON:{{"val":{"entityData":{"val":{"DropChances":{"val":[{"val":"1.0","id":"pf"},{"val":"1.0","id":"pf"},{"val":"1.0","id":"pf"},{"val":"1.0","id":"pf"},{"val":"1.0","id":"pf"}],"id":"ls"},"Attributes":{"val":[{"val":{"Name":{"val":"generic.maxHealth","id":"ss"},"Base":{"val":"40.0","id":"pd"}},"id":"ct"},{"val":{"Name":{"val":"generic.knockbackResistance","id":"ss"},"Base":{"val":"0.0","id":"pd"}},"id":"ct"},{"val":{"Name":{"val":"generic.movementSpeed","id":"ss"},"Base":{"val":"0.325","id":"pd"}},"id":"ct"},{"val":{"Name":{"val":"generic.followRange","id":"ss"},"Base":{"val":"60.0","id":"pd"}},"id":"ct"},{"val":{"Name":{"val":"generic.attackDamage","id":"ss"},"Base":{"val":"2.0","id":"pd"}},"id":"ct"}],"id":"ls"},"Motion":{"val":[{"val":"0.0","id":"pd"},{"val":"-0.0784000015258789","id":"pd"},{"val":"0.0","id":"pd"}],"id":"ls"},"CustomName":{"val":"","id":"ss"},"Health":{"val":"40","id":"ps"},"HealF":{"val":"40.0","id":"pf"},"CustomNameVisible":{"val":"0","id":"pb"},"AttackTime":{"val":"0","id":"ps"},"Fire":{"val":"-1","id":"ps"},"attackDamageOverride":{"val":"-1","id":"pi"},"Invulnerable":{"val":"0","id":"pb"},"DeathTime":{"val":"0","id":"ps"},"ForgeData":{"val":{"WITCInitialWidth":{"val":"0.6","id":"pf"},"WITCInitialHeight":{"val":"1.8","id":"pf"}},"id":"ct"},"AbsorptionAmount":{"val":"0.0","id":"pf"},"OnGround":{"val":"1","id":"pb"},"HurtTime":{"val":"0","id":"ps"},"Dimension":{"val":"0","id":"pi"},"Air":{"val":"300","id":"ps"},"customTex":{"val":"","id":"ss"},"armorValueOverride":{"val":"-1","id":"pi"},"Pos":{"val":[{"val":"1428.5497607624645","id":"pd"},{"val":"110.0","id":"pd"},{"val":"1901.1250370594796","id":"pd"}],"id":"ls"},"CanPickUpLoot":{"val":"0","id":"pb"},"PortalCooldown":{"val":"0","id":"pi"},"PersistenceRequired":{"val":"1","id":"pb"},"shieldStack":{"val":{"item":{"val":"AncientWarfareNpc:iron_shield","id":"ss"},"damage":{"val":"0","id":"pi"},"quantity":{"val":"1","id":"pi"}},"id":"ct"},"Leashed":{"val":"0","id":"pb"},"owner":{"val":"OldMiniCollector","id":"ss"},"FallDistance":{"val":"0.0","id":"pf"},"Rotation":{"val":[{"val":"3.9648924","id":"pf"},{"val":"0.0","id":"pf"}],"id":"ls"},"levelingStats":{"val":{"level":{"val":"0","id":"pi"},"xp":{"val":"0","id":"pi"},"entryList":{"val":[],"id":"ls"}},"id":"ct"}},"id":"ct"},"xOffset":{"val":"0.45023924","id":"pf"},"mobID":{"val":"AncientWarfareNpc.viking.leader","id":"ss"},"zOffset":{"val":"0.8749629","id":"pf"},"rotation":{"val":"183.96489","id":"pf"},"equipmentData":{"val":{"equipmentContents":{"val":[{"val":{"item":{"val":"minecraft:diamond_axe","id":"ss"},"damage":{"val":"0","id":"pi"},"quantity":{"val":"1","id":"pi"},"slot":{"val":"0","id":"pi"}},"id":"ct"}],"id":"ls"},"length":{"val":"5","id":"pi"}},"id":"ct"}},"id":"ct"}}
:enddata
:endentity

entity:
plugin=AWNpc
number=3
data:
position=17,6,12
JSON:{{"val":{"entityData":{"val":{"DropChances":{"val":[{"val":"1.0","id":"pf"},{"val":"1.0","id":"pf"},{"val":"1.0","id":"pf"},{"val":"1.0","id":"pf"},{"val":"1.0","id":"pf"}],"id":"ls"},"Attributes":{"val":[{"val":{"Name":{"val":"generic.maxHealth","id":"ss"},"Base":{"val":"20.0","id":"pd"}},"id":"ct"},{"val":{"Name":{"val":"generic.knockbackResistance","id":"ss"},"Base":{"val":"0.0","id":"pd"}},"id":"ct"},{"val":{"Name":{"val":"generic.movementSpeed","id":"ss"},"Base":{"val":"0.325","id":"pd"}},"id":"ct"},{"val":{"Name":{"val":"generic.followRange","id":"ss"},"Base":{"val":"60.0","id":"pd"}},"id":"ct"},{"val":{"Name":{"val":"generic.attackDamage","id":"ss"},"Base":{"val":"2.0","id":"pd"}},"id":"ct"}],"id":"ls"},"Motion":{"val":[{"val":"0.0","id":"pd"},{"val":"-0.0784000015258789","id":"pd"},{"val":"0.0","id":"pd"}],"id":"ls"},"CustomName":{"val":"","id":"ss"},"Health":{"val":"20","id":"ps"},"HealF":{"val":"20.0","id":"pf"},"CustomNameVisible":{"val":"0","id":"pb"},"AttackTime":{"val":"0","id":"ps"},"Fire":{"val":"-1","id":"ps"},"attackDamageOverride":{"val":"-1","id":"pi"},"Invulnerable":{"val":"0","id":"pb"},"DeathTime":{"val":"0","id":"ps"},"ForgeData":{"val":{"WITCInitialWidth":{"val":"0.6","id":"pf"},"WITCInitialHeight":{"val":"1.8","id":"pf"}},"id":"ct"},"AbsorptionAmount":{"val":"0.0","id":"pf"},"OnGround":{"val":"1","id":"pb"},"HurtTime":{"val":"0","id":"ps"},"Dimension":{"val":"0","id":"pi"},"Air":{"val":"300","id":"ps"},"customTex":{"val":"","id":"ss"},"armorValueOverride":{"val":"-1","id":"pi"},"Pos":{"val":[{"val":"1425.4116075270508","id":"pd"},{"val":"103.0","id":"pd"},{"val":"1899.4188448738194","id":"pd"}],"id":"ls"},"CanPickUpLoot":{"val":"0","id":"pb"},"PortalCooldown":{"val":"0","id":"pi"},"PersistenceRequired":{"val":"1","id":"pb"},"shieldStack":{"val":{"item":{"val":"AncientWarfareNpc:iron_shield","id":"ss"},"damage":{"val":"0","id":"pi"},"quantity":{"val":"1","id":"pi"}},"id":"ct"},"Leashed":{"val":"0","id":"pb"},"owner":{"val":"OldMiniCollector","id":"ss"},"FallDistance":{"val":"0.0","id":"pf"},"Rotation":{"val":[{"val":"4.436282","id":"pf"},{"val":"0.0","id":"pf"}],"id":"ls"},"levelingStats":{"val":{"level":{"val":"0","id":"pi"},"xp":{"val":"0","id":"pi"},"entryList":{"val":[],"id":"ls"}},"id":"ct"}},"id":"ct"},"xOffset":{"val":"0.5883925","id":"pf"},"mobID":{"val":"AncientWarfareNpc.viking.soldier","id":"ss"},"zOffset":{"val":"0.5811551","id":"pf"},"rotation":{"val":"184.43628","id":"pf"},"equipmentData":{"val":{"equipmentContents":{"val":[{"val":{"item":{"val":"minecraft:iron_sword","id":"ss"},"damage":{"val":"0","id":"pi"},"quantity":{"val":"1","id":"pi"},"slot":{"val":"0","id":"pi"}},"id":"ct"}],"id":"ls"},"length":{"val":"5","id":"pi"}},"id":"ct"}},"id":"ct"}}
:enddata
:endentity

entity:
plugin=AWNpc
number=4
data:
position=6,6,14
JSON:{{"val":{"entityData":{"val":{"DropChances":{"val":[{"val":"1.0","id":"pf"},{"val":"1.0","id":"pf"},{"val":"1.0","id":"pf"},{"val":"1.0","id":"pf"},{"val":"1.0","id":"pf"}],"id":"ls"},"Attributes":{"val":[{"val":{"Name":{"val":"generic.maxHealth","id":"ss"},"Base":{"val":"20.0","id":"pd"}},"id":"ct"},{"val":{"Name":{"val":"generic.knockbackResistance","id":"ss"},"Base":{"val":"0.0","id":"pd"}},"id":"ct"},{"val":{"Name":{"val":"generic.movementSpeed","id":"ss"},"Base":{"val":"0.325","id":"pd"}},"id":"ct"},{"val":{"Name":{"val":"generic.followRange","id":"ss"},"Base":{"val":"60.0","id":"pd"}},"id":"ct"},{"val":{"Name":{"val":"generic.attackDamage","id":"ss"},"Base":{"val":"2.0","id":"pd"}},"id":"ct"}],"id":"ls"},"Motion":{"val":[{"val":"0.0","id":"pd"},{"val":"-0.0784000015258789","id":"pd"},{"val":"0.0","id":"pd"}],"id":"ls"},"CustomName":{"val":"","id":"ss"},"Health":{"val":"20","id":"ps"},"HealF":{"val":"20.0","id":"pf"},"CustomNameVisible":{"val":"0","id":"pb"},"AttackTime":{"val":"0","id":"ps"},"Fire":{"val":"-1","id":"ps"},"attackDamageOverride":{"val":"-1","id":"pi"},"Invulnerable":{"val":"0","id":"pb"},"DeathTime":{"val":"0","id":"ps"},"ForgeData":{"val":{"WITCInitialWidth":{"val":"0.6","id":"pf"},"WITCInitialHeight":{"val":"1.8","id":"pf"}},"id":"ct"},"AbsorptionAmount":{"val":"0.0","id":"pf"},"OnGround":{"val":"1","id":"pb"},"HurtTime":{"val":"0","id":"ps"},"Dimension":{"val":"0","id":"pi"},"Air":{"val":"300","id":"ps"},"customTex":{"val":"","id":"ss"},"armorValueOverride":{"val":"-1","id":"pi"},"Pos":{"val":[{"val":"1436.5","id":"pd"},{"val":"103.0","id":"pd"},{"val":"1897.5","id":"pd"}],"id":"ls"},"CanPickUpLoot":{"val":"0","id":"pb"},"PortalCooldown":{"val":"0","id":"pi"},"PersistenceRequired":{"val":"1","id":"pb"},"shieldStack":{"val":{"item":{"val":"AncientWarfareNpc:iron_shield","id":"ss"},"damage":{"val":"0","id":"pi"},"quantity":{"val":"1","id":"pi"}},"id":"ct"},"Leashed":{"val":"0","id":"pb"},"owner":{"val":"OldMiniCollector","id":"ss"},"FallDistance":{"val":"0.0","id":"pf"},"Rotation":{"val":[{"val":"0.7624464","id":"pf"},{"val":"0.0","id":"pf"}],"id":"ls"},"levelingStats":{"val":{"level":{"val":"0","id":"pi"},"xp":{"val":"0","id":"pi"},"entryList":{"val":[],"id":"ls"}},"id":"ct"}},"id":"ct"},"xOffset":{"val":"0.5","id":"pf"},"mobID":{"val":"AncientWarfareNpc.viking.soldier","id":"ss"},"zOffset":{"val":"0.5","id":"pf"},"rotation":{"val":"180.76245","id":"pf"},"equipmentData":{"val":{"equipmentContents":{"val":[{"val":{"item":{"val":"minecraft:iron_sword","id":"ss"},"damage":{"val":"0","id":"pi"},"quantity":{"val":"1","id":"pi"},"slot":{"val":"0","id":"pi"}},"id":"ct"}],"id":"ls"},"length":{"val":"5","id":"pi"}},"id":"ct"}},"id":"ct"}}
:enddata
:endentity

entity:
plugin=AWNpc
number=5
data:
position=14,6,7
JSON:{{"val":{"entityData":{"val":{"DropChances":{"val":[{"val":"1.0","id":"pf"},{"val":"1.0","id":"pf"},{"val":"1.0","id":"pf"},{"val":"1.0","id":"pf"},{"val":"1.0","id":"pf"}],"id":"ls"},"Attributes":{"val":[{"val":{"Name":{"val":"generic.maxHealth","id":"ss"},"Base":{"val":"20.0","id":"pd"}},"id":"ct"},{"val":{"Name":{"val":"generic.knockbackResistance","id":"ss"},"Base":{"val":"0.0","id":"pd"}},"id":"ct"},{"val":{"Name":{"val":"generic.movementSpeed","id":"ss"},"Base":{"val":"0.325","id":"pd"}},"id":"ct"},{"val":{"Name":{"val":"generic.followRange","id":"ss"},"Base":{"val":"60.0","id":"pd"}},"id":"ct"},{"val":{"Name":{"val":"generic.attackDamage","id":"ss"},"Base":{"val":"2.0","id":"pd"}},"id":"ct"}],"id":"ls"},"Motion":{"val":[{"val":"0.0","id":"pd"},{"val":"-0.0784000015258789","id":"pd"},{"val":"0.0","id":"pd"}],"id":"ls"},"CustomName":{"val":"","id":"ss"},"Health":{"val":"20","id":"ps"},"HealF":{"val":"20.0","id":"pf"},"CustomNameVisible":{"val":"0","id":"pb"},"AttackTime":{"val":"0","id":"ps"},"Fire":{"val":"-1","id":"ps"},"attackDamageOverride":{"val":"-1","id":"pi"},"Invulnerable":{"val":"0","id":"pb"},"DeathTime":{"val":"0","id":"ps"},"ForgeData":{"val":{"WITCInitialWidth":{"val":"0.6","id":"pf"},"WITCInitialHeight":{"val":"1.8","id":"pf"}},"id":"ct"},"AbsorptionAmount":{"val":"0.0","id":"pf"},"OnGround":{"val":"1","id":"pb"},"HurtTime":{"val":"0","id":"ps"},"Dimension":{"val":"0","id":"pi"},"Air":{"val":"300","id":"ps"},"customTex":{"val":"","id":"ss"},"armorValueOverride":{"val":"-1","id":"pi"},"Pos":{"val":[{"val":"1428.55712973021","id":"pd"},{"val":"103.0","id":"pd"},{"val":"1904.42388760549","id":"pd"}],"id":"ls"},"CanPickUpLoot":{"val":"0","id":"pb"},"PortalCooldown":{"val":"0","id":"pi"},"PersistenceRequired":{"val":"1","id":"pb"},"Leashed":{"val":"0","id":"pb"},"owner":{"val":"OldMiniCollector","id":"ss"},"FallDistance":{"val":"0.0","id":"pf"},"Rotation":{"val":[{"val":"63.49391","id":"pf"},{"val":"0.0","id":"pf"}],"id":"ls"},"levelingStats":{"val":{"level":{"val":"0","id":"pi"},"xp":{"val":"0","id":"pi"},"entryList":{"val":[],"id":"ls"}},"id":"ct"}},"id":"ct"},"xOffset":{"val":"0.44287026","id":"pf"},"mobID":{"val":"AncientWarfareNpc.viking.priest","id":"ss"},"zOffset":{"val":"0.5761124","id":"pf"},"rotation":{"val":"243.49391","id":"pf"},"equipmentData":{"val":{"equipmentContents":{"val":[{"val":{"item":{"val":"minecraft:book","id":"ss"},"damage":{"val":"0","id":"pi"},"quantity":{"val":"1","id":"pi"},"slot":{"val":"0","id":"pi"}},"id":"ct"}],"id":"ls"},"length":{"val":"5","id":"pi"}},"id":"ct"}},"id":"ct"}}
:enddata
:endentity

entity:
plugin=AWNpc
number=6
data:
position=6,6,4
JSON:{{"val":{"entityData":{"val":{"DropChances":{"val":[{"val":"1.0","id":"pf"},{"val":"1.0","id":"pf"},{"val":"1.0","id":"pf"},{"val":"1.0","id":"pf"},{"val":"1.0","id":"pf"}],"id":"ls"},"Attributes":{"val":[{"val":{"Name":{"val":"generic.maxHealth","id":"ss"},"Base":{"val":"20.0","id":"pd"}},"id":"ct"},{"val":{"Name":{"val":"generic.knockbackResistance","id":"ss"},"Base":{"val":"0.0","id":"pd"}},"id":"ct"},{"val":{"Name":{"val":"generic.movementSpeed","id":"ss"},"Base":{"val":"0.325","id":"pd"}},"id":"ct"},{"val":{"Name":{"val":"generic.followRange","id":"ss"},"Base":{"val":"60.0","id":"pd"}},"id":"ct"},{"val":{"Name":{"val":"generic.attackDamage","id":"ss"},"Base":{"val":"2.0","id":"pd"}},"id":"ct"}],"id":"ls"},"Motion":{"val":[{"val":"0.0","id":"pd"},{"val":"-0.0784000015258789","id":"pd"},{"val":"0.0","id":"pd"}],"id":"ls"},"CustomName":{"val":"","id":"ss"},"Health":{"val":"20","id":"ps"},"HealF":{"val":"20.0","id":"pf"},"CustomNameVisible":{"val":"0","id":"pb"},"AttackTime":{"val":"0","id":"ps"},"Fire":{"val":"-1","id":"ps"},"attackDamageOverride":{"val":"-1","id":"pi"},"Invulnerable":{"val":"0","id":"pb"},"DeathTime":{"val":"0","id":"ps"},"ForgeData":{"val":{"WITCInitialWidth":{"val":"0.6","id":"pf"},"WITCInitialHeight":{"val":"1.8","id":"pf"}},"id":"ct"},"AbsorptionAmount":{"val":"0.0","id":"pf"},"OnGround":{"val":"1","id":"pb"},"HurtTime":{"val":"0","id":"ps"},"Dimension":{"val":"0","id":"pi"},"Air":{"val":"300","id":"ps"},"customTex":{"val":"","id":"ss"},"armorValueOverride":{"val":"-1","id":"pi"},"Pos":{"val":[{"val":"1436.5","id":"pd"},{"val":"103.0","id":"pd"},{"val":"1907.5","id":"pd"}],"id":"ls"},"CanPickUpLoot":{"val":"0","id":"pb"},"PortalCooldown":{"val":"0","id":"pi"},"PersistenceRequired":{"val":"1","id":"pb"},"shieldStack":{"val":{"item":{"val":"AncientWarfareNpc:iron_shield","id":"ss"},"damage":{"val":"0","id":"pi"},"quantity":{"val":"1","id":"pi"}},"id":"ct"},"Leashed":{"val":"0","id":"pb"},"owner":{"val":"OldMiniCollector","id":"ss"},"FallDistance":{"val":"0.0","id":"pf"},"Rotation":{"val":[{"val":"0.46978047","id":"pf"},{"val":"0.0","id":"pf"}],"id":"ls"},"levelingStats":{"val":{"level":{"val":"0","id":"pi"},"xp":{"val":"0","id":"pi"},"entryList":{"val":[],"id":"ls"}},"id":"ct"}},"id":"ct"},"xOffset":{"val":"0.5","id":"pf"},"mobID":{"val":"AncientWarfareNpc.viking.soldier","id":"ss"},"zOffset":{"val":"0.5","id":"pf"},"rotation":{"val":"180.46979","id":"pf"},"equipmentData":{"val":{"equipmentContents":{"val":[{"val":{"item":{"val":"minecraft:iron_sword","id":"ss"},"damage":{"val":"0","id":"pi"},"quantity":{"val":"1","id":"pi"},"slot":{"val":"0","id":"pi"}},"id":"ct"}],"id":"ls"},"length":{"val":"5","id":"pi"}},"id":"ct"}},"id":"ct"}}
:enddata
:endentity

