# Ancient Warfare Structure Template File
# Auto-generated structure template file. created on: 3/22/2015 at: 6:7:19
# Lines beginning with # denote comments

header:
version=2.1
name=CannibalTree1
size=7,44,7
offset=2,3,6
:endheader

#### VALIDATION ####
validation:
type=ground
survival=false
worldGenEnabled=true
unique=false
preserveBlocks=false
selectionWeight=0
clusterValue=0
minDuplicateDistance=0
dimensionWhiteList=false
dimensionList=
biomeWhiteList=false
biomeList=
leveling=0
fill=0
border=0
validTargetBlocks=
blockSwap=false
data:
:enddata
:endvalidation

#### LAYERS ####
layer: 0
2,2,2,2,2,1,1
2,2,2,2,2,1,1
2,2,2,2,2,1,1
2,2,2,2,2,1,1
2,2,2,2,2,2,1
2,2,2,2,2,1,1
2,2,2,2,2,1,1
:endlayer
layer: 1
2,2,2,2,2,2,2
2,2,2,2,2,2,2
2,2,2,2,2,2,2
2,2,2,2,2,2,2
2,2,2,2,2,2,2
2,2,2,2,2,2,2
2,2,2,2,2,2,2
:endlayer
layer: 2
3,3,3,3,3,3,3
3,3,3,3,3,3,3
3,3,3,3,3,3,3
3,3,3,2,3,3,3
3,3,3,3,3,3,3
3,3,3,3,3,3,3
3,3,3,3,3,3,3
:endlayer
layer: 3
0,0,10,4,4,10,0
0,4,0,4,0,0,0
9,4,0,8,0,0,6
0,0,8,7,6,0,0
4,4,4,5,4,4,0
4,0,4,4,4,0,0
0,4,4,0,0,0,0
:endlayer
layer: 4
0,0,10,10,0,10,0
0,0,0,0,0,0,0
9,0,0,10,0,0,6
9,0,9,7,6,0,6
0,0,0,5,0,0,0
0,0,0,0,0,0,0
0,0,0,0,0,0,0
:endlayer
layer: 5
0,0,10,10,0,10,0
0,0,0,0,0,10,0
9,0,0,10,0,0,6
9,0,9,7,6,0,6
0,0,0,5,0,0,0
0,0,0,0,0,0,0
0,0,0,0,0,0,0
:endlayer
layer: 6
0,0,10,10,0,10,0
0,0,0,0,0,10,0
9,0,0,10,0,0,6
9,0,0,7,6,0,6
9,0,0,5,0,0,0
0,0,0,0,0,0,0
0,0,0,0,0,0,0
:endlayer
layer: 7
0,0,10,10,0,10,0
0,0,0,0,0,10,0
9,0,0,10,0,0,6
9,0,9,7,0,0,6
9,0,0,5,0,0,0
0,0,0,0,0,0,0
0,0,0,0,0,0,0
:endlayer
layer: 8
0,0,10,10,0,10,0
0,0,0,0,0,10,0
9,0,0,10,0,0,6
9,0,0,7,0,0,6
9,0,0,5,0,0,0
0,0,0,0,0,0,0
0,0,0,0,0,0,0
:endlayer
layer: 9
0,0,10,10,0,10,0
0,0,0,0,0,10,0
9,0,0,10,0,0,6
9,0,0,7,0,0,6
9,0,0,0,0,0,0
0,0,0,0,0,0,0
0,0,0,0,0,0,0
:endlayer
layer: 10
0,0,10,10,0,10,0
0,0,0,0,0,10,0
9,0,0,10,0,0,6
9,0,0,7,0,0,6
9,0,0,0,0,0,0
0,0,0,0,0,0,0
0,0,0,0,0,0,0
:endlayer
layer: 11
0,0,10,10,0,10,0
0,11,11,11,11,10,0
9,11,11,11,11,11,6
9,11,11,7,11,11,6
9,11,11,11,11,11,0
0,0,0,0,0,0,0
0,0,0,0,0,0,0
:endlayer
layer: 12
0,0,0,10,0,10,0
0,9,11,11,11,11,0
9,11,11,11,11,11,0
0,11,11,7,11,11,0
9,11,11,11,11,11,0
0,0,0,0,0,0,0
0,0,0,0,0,0,0
:endlayer
layer: 13
0,0,0,0,0,0,0
0,0,10,10,0,0,0
0,0,11,11,6,0,0
0,0,11,7,11,6,0
0,0,11,11,11,0,0
0,0,0,0,0,0,0
0,0,0,0,0,0,0
:endlayer
layer: 14
0,0,0,0,0,0,0
0,0,0,0,0,0,0
0,0,0,11,10,0,0
0,0,11,11,11,6,0
0,0,0,11,0,0,0
0,0,0,0,0,0,0
0,0,0,0,0,0,0
:endlayer
layer: 15
0,0,0,0,0,0,0
0,0,0,0,0,0,0
0,0,0,0,0,0,0
0,0,0,0,0,0,0
0,0,0,0,0,0,0
0,0,0,0,0,0,0
0,0,0,0,0,0,0
:endlayer
layer: 16
0,0,0,0,0,0,0
0,0,0,0,0,0,0
0,0,0,0,0,0,0
0,0,0,0,0,0,0
0,0,0,0,0,0,0
0,0,0,0,0,0,0
0,0,0,0,0,0,0
:endlayer
layer: 17
0,0,0,0,0,0,0
0,0,0,0,0,0,0
0,0,0,0,0,0,0
0,0,0,0,0,0,0
0,0,0,0,0,0,0
0,0,0,0,0,0,0
0,0,0,0,0,0,0
:endlayer
layer: 18
0,0,0,0,0,0,0
0,0,0,0,0,0,0
0,0,0,0,0,0,0
0,0,0,0,0,0,0
0,0,0,0,0,0,0
0,0,0,0,0,0,0
0,0,0,0,0,0,0
:endlayer
layer: 19
0,0,0,0,0,0,0
0,0,0,0,0,0,0
0,0,0,0,0,0,0
0,0,0,0,0,0,0
0,0,0,0,0,0,0
0,0,0,0,0,0,0
0,0,0,0,0,0,0
:endlayer
layer: 20
0,0,0,0,0,0,0
0,0,0,0,0,0,0
0,0,0,0,0,0,0
0,0,0,0,0,0,0
0,0,0,0,0,0,0
0,0,0,0,0,0,0
0,0,0,0,0,0,0
:endlayer
layer: 21
0,0,0,0,0,0,0
0,0,0,0,0,0,0
0,0,0,0,0,0,0
0,0,0,0,0,0,0
0,0,0,0,0,0,0
0,0,0,0,0,0,0
0,0,0,0,0,0,0
:endlayer
layer: 22
0,0,0,0,0,0,0
0,0,0,0,0,0,0
0,0,0,0,0,0,0
0,0,0,0,0,0,0
0,0,0,0,0,0,0
0,0,0,0,0,0,0
0,0,0,0,0,0,0
:endlayer
layer: 23
0,0,0,0,0,0,0
0,0,0,0,0,0,0
0,0,0,0,0,0,0
0,0,0,0,0,0,0
0,0,0,0,0,0,0
0,0,0,0,0,0,0
0,0,0,0,0,0,0
:endlayer
layer: 24
0,0,0,0,0,0,0
0,0,0,0,0,0,0
0,0,0,0,0,0,0
0,0,0,0,0,0,0
0,0,0,0,0,0,0
0,0,0,0,0,0,0
0,0,0,0,0,0,0
:endlayer
layer: 25
0,0,0,0,0,0,0
0,0,0,0,0,0,0
0,0,0,0,0,0,0
0,0,0,0,0,0,0
0,0,0,0,0,0,0
0,0,0,0,0,0,0
0,0,0,0,0,0,0
:endlayer
layer: 26
0,0,0,0,0,0,0
0,0,0,0,0,0,0
0,0,0,0,0,0,0
0,0,0,0,0,0,0
0,0,0,0,0,0,0
0,0,0,0,0,0,0
0,0,0,0,0,0,0
:endlayer
layer: 27
0,0,0,0,0,0,0
0,0,0,0,0,0,0
0,0,0,0,0,0,0
0,0,0,0,0,0,0
0,0,0,0,0,0,0
0,0,0,0,0,0,0
0,0,0,0,0,0,0
:endlayer
layer: 28
0,0,0,0,0,0,0
0,0,0,0,0,0,0
0,0,0,0,0,0,0
0,0,0,0,0,0,0
0,0,0,0,0,0,0
0,0,0,0,0,0,0
0,0,0,0,0,0,0
:endlayer
layer: 29
0,0,0,0,0,0,0
0,0,0,0,0,0,0
0,0,0,0,0,0,0
0,0,0,0,0,0,0
0,0,0,0,0,0,0
0,0,0,0,0,0,0
0,0,0,0,0,0,0
:endlayer
layer: 30
0,0,0,0,0,0,0
0,0,0,0,0,0,0
0,0,0,0,0,0,0
0,0,0,0,0,0,0
0,0,0,0,0,0,0
0,0,0,0,0,0,0
0,0,0,0,0,0,0
:endlayer
layer: 31
0,0,0,0,0,0,0
0,0,0,0,0,0,0
0,0,0,0,0,0,0
0,0,0,0,0,0,0
0,0,0,0,0,0,0
0,0,0,0,0,0,0
0,0,0,0,0,0,0
:endlayer
layer: 32
0,0,0,0,0,0,0
0,0,0,0,0,0,0
0,0,0,0,0,0,0
0,0,0,0,0,0,0
0,0,0,0,0,0,0
0,0,0,0,0,0,0
0,0,0,0,0,0,0
:endlayer
layer: 33
0,0,0,0,0,0,0
0,0,0,0,0,0,0
0,0,0,0,0,0,0
0,0,0,0,0,0,0
0,0,0,0,0,0,0
0,0,0,0,0,0,0
0,0,0,0,0,0,0
:endlayer
layer: 34
0,0,0,0,0,0,0
0,0,0,0,0,0,0
0,0,0,0,0,0,0
0,0,0,0,0,0,0
0,0,0,0,0,0,0
0,0,0,0,0,0,0
0,0,0,0,0,0,0
:endlayer
layer: 35
0,0,0,0,0,0,0
0,0,0,0,0,0,0
0,0,0,0,0,0,0
0,0,0,0,0,0,0
0,0,0,0,0,0,0
0,0,0,0,0,0,0
0,0,0,0,0,0,0
:endlayer
layer: 36
0,0,0,0,0,0,0
0,0,0,0,0,0,0
0,0,0,0,0,0,0
0,0,0,0,0,0,0
0,0,0,0,0,0,0
0,0,0,0,0,0,0
0,0,0,0,0,0,0
:endlayer
layer: 37
0,0,0,0,0,0,0
0,0,0,0,0,0,0
0,0,0,0,0,0,0
0,0,0,0,0,0,0
0,0,0,0,0,0,0
0,0,0,0,0,0,0
0,0,0,0,0,0,0
:endlayer
layer: 38
0,0,0,0,0,0,0
0,0,0,0,0,0,0
0,0,0,0,0,0,0
0,0,0,0,0,0,0
0,0,0,0,0,0,0
0,0,0,0,0,0,0
0,0,0,0,0,0,0
:endlayer
layer: 39
0,0,0,0,0,0,0
0,0,0,0,0,0,0
0,0,0,0,0,0,0
0,0,0,0,0,0,0
0,0,0,0,0,0,0
0,0,0,0,0,0,0
0,0,0,0,0,0,0
:endlayer
layer: 40
0,0,0,0,0,0,0
0,0,0,0,0,0,0
0,0,0,0,0,0,0
0,0,0,0,0,0,0
0,0,0,0,0,0,0
0,0,0,0,0,0,0
0,0,0,0,0,0,0
:endlayer
layer: 41
0,0,0,0,0,0,0
0,0,0,0,0,0,0
0,0,0,0,0,0,0
0,0,0,0,0,0,0
0,0,0,0,0,0,0
0,0,0,0,0,0,0
0,0,0,0,0,0,0
:endlayer
layer: 42
0,0,0,0,0,0,0
0,0,0,0,0,0,0
0,0,0,0,0,0,0
0,0,0,0,0,0,0
0,0,0,0,0,0,0
0,0,0,0,0,0,0
0,0,0,0,0,0,0
:endlayer
layer: 43
0,0,0,0,0,0,0
0,0,0,0,0,0,0
0,0,0,0,0,0,0
0,0,0,0,0,0,0
0,0,0,0,0,0,0
0,0,0,0,0,0,0
0,0,0,0,0,0,0
:endlayer

#### RULES ####
rule:
plugin=vanillaBlocks
number=1
data:
JSON:{{"val":{"blockName":{"val":"minecraft:stone","id":"ss"},"meta":{"val":"0","id":"pi"},"buildPass":{"val":"0","id":"pi"}},"id":"ct"}}
:enddata
:endrule

rule:
plugin=vanillaBlocks
number=2
data:
JSON:{{"val":{"blockName":{"val":"minecraft:dirt","id":"ss"},"meta":{"val":"0","id":"pi"},"buildPass":{"val":"0","id":"pi"}},"id":"ct"}}
:enddata
:endrule

rule:
plugin=vanillaBlocks
number=3
data:
JSON:{{"val":{"blockName":{"val":"minecraft:grass","id":"ss"},"meta":{"val":"0","id":"pi"},"buildPass":{"val":"0","id":"pi"}},"id":"ct"}}
:enddata
:endrule

rule:
plugin=vanillaBlocks
number=4
data:
JSON:{{"val":{"blockName":{"val":"minecraft:tallgrass","id":"ss"},"meta":{"val":"1","id":"pi"},"buildPass":{"val":"2","id":"pi"}},"id":"ct"}}
:enddata
:endrule

rule:
plugin=vanillaBlocks
number=5
data:
JSON:{{"val":{"blockName":{"val":"minecraft:vine","id":"ss"},"meta":{"val":"4","id":"pi"},"buildPass":{"val":"2","id":"pi"}},"id":"ct"}}
:enddata
:endrule

rule:
plugin=vanillaBlocks
number=6
data:
JSON:{{"val":{"blockName":{"val":"minecraft:vine","id":"ss"},"meta":{"val":"2","id":"pi"},"buildPass":{"val":"2","id":"pi"}},"id":"ct"}}
:enddata
:endrule

rule:
plugin=vanillaBlocks
number=7
data:
JSON:{{"val":{"blockName":{"val":"minecraft:log","id":"ss"},"meta":{"val":"3","id":"pi"},"buildPass":{"val":"0","id":"pi"}},"id":"ct"}}
:enddata
:endrule

rule:
plugin=vanillaBlocks
number=8
data:
JSON:{{"val":{"blockName":{"val":"minecraft:tallgrass","id":"ss"},"meta":{"val":"2","id":"pi"},"buildPass":{"val":"2","id":"pi"}},"id":"ct"}}
:enddata
:endrule

rule:
plugin=vanillaBlocks
number=9
data:
JSON:{{"val":{"blockName":{"val":"minecraft:vine","id":"ss"},"meta":{"val":"8","id":"pi"},"buildPass":{"val":"2","id":"pi"}},"id":"ct"}}
:enddata
:endrule

rule:
plugin=vanillaBlocks
number=10
data:
JSON:{{"val":{"blockName":{"val":"minecraft:vine","id":"ss"},"meta":{"val":"1","id":"pi"},"buildPass":{"val":"2","id":"pi"}},"id":"ct"}}
:enddata
:endrule

rule:
plugin=vanillaBlocks
number=11
data:
JSON:{{"val":{"blockName":{"val":"minecraft:leaves","id":"ss"},"meta":{"val":"3","id":"pi"},"buildPass":{"val":"0","id":"pi"}},"id":"ct"}}
:enddata
:endrule

#### ENTITIES ####
