# Ancient Warfare Structure Template File
# Auto-generated structure template file. created on: 2/18/2015 at: 13:37:18
# Lines beginning with # denote comments

header:
version=2.1
name=Viking Barracks
size=21,42,19
offset=8,3,17
:endheader

#### VALIDATION ####
validation:
type=ground
survival=false
worldGenEnabled=true
unique=false
preserveBlocks=false
selectionWeight=0
clusterValue=100
minDuplicateDistance=0
dimensionWhiteList=false
dimensionList=
biomeWhiteList=false
biomeList=taiga
leveling=0
fill=0
border=0
validTargetBlocks=
blockSwap=false
data:
:enddata
:endvalidation

#### LAYERS ####
layer: 0
1,1,1,1,1,1,1,1,1,1,1,1,1,1,1,1,1,1,1,1,1
1,1,1,1,1,1,1,1,1,1,1,1,1,1,1,1,1,1,1,1,1
1,1,1,1,1,1,1,1,1,1,1,1,1,1,1,1,1,1,1,1,1
1,1,1,1,1,1,1,1,1,1,1,1,1,1,1,1,1,1,1,1,1
1,1,1,1,1,1,1,1,1,1,1,1,1,1,1,1,1,1,1,1,1
1,1,1,1,1,1,1,1,1,1,1,1,1,1,1,1,1,1,1,1,1
1,1,1,1,1,1,1,1,1,1,1,1,1,1,1,1,1,1,1,1,1
1,1,1,1,1,1,1,1,1,1,1,1,1,1,1,1,1,1,1,1,1
1,1,1,1,1,1,1,1,1,1,1,1,1,1,1,1,1,1,1,1,1
1,1,1,1,1,1,1,1,1,1,1,1,1,1,1,1,1,1,1,1,1
1,1,1,1,1,1,1,1,1,1,1,1,1,1,1,1,1,1,1,1,1
1,1,1,1,1,1,1,1,1,1,1,1,1,1,1,1,1,1,1,1,1
1,1,1,1,1,1,1,1,1,1,1,1,1,1,1,1,1,1,1,1,1
1,1,1,1,1,1,1,1,1,1,1,1,1,1,1,1,1,1,1,1,1
1,1,1,1,1,1,1,1,1,1,1,1,1,1,1,1,1,1,1,1,1
1,1,1,1,1,1,1,1,1,1,1,1,1,1,1,1,1,1,1,1,1
1,1,1,1,1,1,1,1,1,1,1,1,1,1,1,1,1,1,1,1,1
1,1,1,1,1,1,1,1,1,1,1,1,1,1,1,1,1,1,1,1,1
1,1,1,1,1,1,1,1,1,1,1,1,1,1,1,1,1,1,1,1,1
:endlayer
layer: 1
1,1,1,1,1,1,1,1,1,1,1,1,1,1,1,1,1,1,1,1,1
1,1,1,1,1,1,1,1,1,1,1,1,1,1,1,1,1,1,1,1,1
1,1,1,1,1,1,1,1,1,1,1,1,1,1,1,1,1,1,1,1,1
1,1,1,1,1,1,1,1,1,1,1,1,1,1,1,1,1,1,1,1,1
1,1,1,1,1,1,1,1,1,1,1,1,1,1,1,1,1,1,1,1,1
1,1,1,1,1,1,1,1,1,1,1,1,1,1,1,1,1,1,1,1,1
1,1,1,1,1,1,1,1,1,1,1,1,1,1,1,1,1,1,1,1,1
1,1,1,1,1,1,1,1,1,1,1,1,1,1,1,1,1,1,1,1,1
1,1,1,1,1,1,1,1,1,1,1,1,1,1,1,1,1,1,1,1,1
1,1,1,1,1,1,1,1,1,1,1,1,1,1,1,1,1,1,1,1,1
1,1,1,1,1,1,1,1,1,1,1,1,1,1,1,1,1,1,1,1,1
1,1,1,1,1,1,1,1,1,1,1,1,1,1,1,1,1,1,1,1,1
1,1,1,1,1,1,1,1,1,1,1,1,1,1,1,1,1,1,1,1,1
1,1,1,1,1,1,1,1,1,1,1,1,1,1,1,1,1,1,1,1,1
1,1,1,1,1,1,1,1,1,1,1,1,1,1,1,1,1,1,1,1,1
1,1,1,1,1,1,1,1,1,1,1,1,1,1,1,1,1,1,1,1,1
1,1,1,1,1,1,1,1,1,1,1,1,1,1,1,1,1,1,1,1,1
1,1,1,1,1,1,1,1,1,1,1,1,1,1,1,1,1,1,1,1,1
1,1,1,1,1,1,1,1,1,1,1,1,1,1,1,1,1,1,1,1,1
:endlayer
layer: 2
2,2,2,2,2,2,2,2,2,2,2,2,2,2,2,2,2,2,2,2,2
2,1,1,1,1,1,1,1,1,1,1,1,1,1,1,1,1,1,1,1,2
2,1,1,1,1,1,1,1,1,1,1,1,1,1,1,1,1,1,1,1,2
2,1,1,1,1,1,1,1,1,1,1,1,1,1,1,1,1,1,1,1,2
2,1,1,1,1,1,1,1,1,1,1,1,1,1,1,1,1,1,1,1,2
2,1,1,1,1,1,1,1,1,1,1,1,1,1,1,1,1,1,1,1,2
2,1,1,1,1,1,1,1,1,1,1,1,1,1,1,1,1,1,1,1,2
2,1,1,1,1,1,1,1,1,1,1,1,1,1,1,1,1,1,1,1,2
2,1,1,1,1,1,1,1,1,1,1,1,1,1,1,1,1,1,1,1,2
2,1,1,1,1,1,1,1,1,1,1,1,1,1,1,1,1,1,1,1,2
2,1,1,1,1,1,1,1,1,1,1,1,1,1,1,1,1,1,1,1,2
2,1,1,1,1,1,1,1,1,1,1,1,1,1,1,1,1,1,1,1,2
2,1,1,1,1,1,1,1,1,1,1,1,1,1,1,1,1,1,1,1,2
2,1,1,1,1,1,1,1,1,1,1,1,1,1,1,1,1,1,1,1,2
2,1,1,1,1,1,1,1,1,1,1,1,1,1,1,1,1,1,1,1,2
2,1,1,1,1,1,1,1,1,1,1,1,1,1,1,1,1,1,1,1,2
2,1,1,1,1,1,1,1,1,1,1,1,1,1,1,1,1,1,1,1,2
2,1,1,2,2,2,2,2,1,1,1,1,1,1,1,1,1,1,1,1,2
2,2,2,2,2,2,2,2,2,2,2,2,2,2,2,2,2,2,2,2,2
:endlayer
layer: 3
4,4,4,3,0,4,3,4,4,4,4,4,3,3,0,11,4,4,4,3,3
4,5,5,5,5,5,5,5,5,5,5,5,5,5,5,5,5,5,5,5,4
4,5,6,5,5,5,5,5,6,7,7,7,7,7,7,7,7,7,6,5,4
3,5,5,5,5,5,5,5,5,5,5,5,5,5,5,5,5,5,7,5,3
3,5,5,5,5,5,5,5,5,5,5,5,5,5,5,5,5,5,7,5,0
4,5,5,5,5,5,5,5,5,5,5,5,5,5,5,5,5,5,7,5,3
3,5,5,5,5,5,5,5,5,5,5,5,5,5,5,5,5,5,7,5,4
4,5,5,5,5,5,5,5,5,5,5,5,5,5,5,5,5,5,7,5,4
4,5,6,5,5,5,5,5,6,7,7,7,7,7,7,7,7,7,6,5,4
3,5,7,10,10,10,10,10,10,10,10,10,10,10,10,10,10,10,10,5,3
4,5,7,10,10,10,10,10,10,10,10,10,10,10,10,10,10,10,10,5,4
4,5,7,10,10,10,10,10,10,10,10,10,10,10,10,10,10,10,10,5,4
4,5,7,10,10,10,10,10,10,10,10,10,10,10,10,10,10,10,10,5,3
0,5,7,10,10,10,10,10,10,10,10,10,10,10,10,10,10,10,10,5,4
4,5,7,10,10,10,10,10,10,10,10,10,10,10,10,10,10,10,10,5,4
3,5,7,10,10,10,10,10,10,10,10,10,10,10,10,10,10,10,10,5,4
3,5,6,9,9,9,9,9,6,10,10,10,10,10,10,10,10,10,10,5,3
4,5,5,8,8,8,8,8,5,5,5,5,5,5,5,5,5,5,5,5,3
3,4,3,4,3,4,3,3,0,3,4,4,3,4,3,4,4,4,3,4,0
:endlayer
layer: 4
0,0,0,0,0,0,0,0,0,0,0,0,0,0,0,0,0,0,0,0,0
0,3,0,3,4,4,0,4,4,4,4,4,0,4,4,3,4,4,4,4,0
0,4,12,7,7,7,7,7,12,7,7,7,7,7,7,7,7,7,12,4,0
0,4,7,19,0,0,0,0,0,13,0,13,0,13,0,13,0,0,7,4,0
0,4,7,18,0,0,0,0,0,0,0,0,0,0,0,0,0,0,7,4,0
0,4,7,17,0,0,0,0,6,6,6,6,6,6,6,6,6,0,7,3,0
0,3,7,16,0,0,0,0,0,0,0,0,0,0,0,0,0,0,7,4,0
0,4,7,0,0,0,0,0,0,23,0,23,0,23,0,23,0,0,7,3,0
0,4,12,7,20,21,7,7,12,7,7,7,7,7,7,7,7,7,12,0,0
0,4,13,0,0,0,0,3,0,11,4,4,4,4,4,0,0,4,12,3,0
0,3,14,15,0,0,0,0,4,3,0,4,4,4,0,4,3,22,12,4,0
0,0,13,0,0,0,0,0,4,4,3,4,4,4,0,4,4,4,12,4,0
0,4,14,0,0,0,0,4,3,11,4,4,0,4,0,4,11,22,12,4,0
0,4,13,0,0,0,0,4,4,4,4,0,3,4,3,0,4,4,12,3,0
0,4,14,0,0,0,0,3,4,4,3,4,4,4,3,0,4,22,12,4,0
0,4,13,4,0,0,4,4,12,0,4,4,4,4,4,4,4,3,12,11,0
0,4,12,4,4,0,4,4,12,22,22,22,22,22,22,22,22,22,12,4,0
0,3,4,0,0,0,0,0,3,0,4,4,0,4,4,4,4,4,4,3,0
0,0,0,0,0,0,0,0,0,0,0,0,0,0,0,0,0,0,0,0,0
:endlayer
layer: 5
0,0,0,0,0,0,0,0,0,0,0,0,0,0,0,0,0,0,0,0,0
0,0,0,0,0,0,0,0,0,0,0,0,0,0,0,0,0,0,0,0,0
0,0,12,7,7,7,7,7,12,7,22,7,22,7,22,7,22,7,12,0,0
0,0,7,0,0,0,0,0,0,0,0,0,0,0,0,0,0,0,7,0,0
0,0,7,0,0,0,0,0,0,0,0,0,0,0,0,0,0,0,7,0,0
0,0,7,8,0,0,0,0,26,26,26,26,26,26,26,0,26,0,7,0,0
0,0,7,0,0,0,0,0,0,0,0,0,0,0,0,0,0,0,7,0,0
0,0,7,0,0,0,0,0,0,0,0,0,0,0,0,0,0,0,7,0,0
0,0,12,7,24,25,7,7,12,7,22,7,22,7,22,7,22,7,12,0,0
0,0,14,0,0,0,0,0,0,0,0,0,0,0,0,0,0,0,12,0,0
0,0,13,0,0,0,0,0,0,0,0,0,0,0,0,0,0,27,12,0,0
0,0,14,15,0,0,0,0,0,0,0,0,0,0,0,0,0,0,12,0,0
0,0,13,0,0,0,0,0,0,0,0,0,0,0,0,0,0,27,12,0,0
0,0,14,0,0,0,0,0,0,0,0,0,0,0,0,0,0,0,12,0,0
0,0,13,0,0,0,0,0,0,0,0,0,0,0,0,0,0,27,12,0,0
0,0,14,0,0,0,0,0,12,0,0,0,0,0,0,0,0,0,12,0,0
0,0,12,0,0,0,0,0,12,0,0,0,0,0,0,0,0,0,12,0,0
0,0,0,0,0,0,0,0,0,0,0,0,0,0,0,0,0,0,0,0,0
0,0,0,0,0,0,0,0,0,0,0,0,0,0,0,0,0,0,0,0,0
:endlayer
layer: 6
0,0,0,0,0,0,0,0,0,0,0,0,0,0,0,0,0,0,0,0,0
0,0,0,0,0,0,0,0,0,0,0,0,0,0,0,0,0,0,0,0,0
0,0,12,7,22,7,22,7,12,7,22,7,22,7,22,7,22,7,12,0,0
0,0,7,0,0,28,0,28,0,28,0,28,0,28,0,28,0,0,7,0,0
0,0,22,0,0,0,0,0,0,0,0,0,0,0,0,0,0,0,22,0,0
0,0,7,0,0,0,0,0,0,0,0,0,0,0,0,0,0,0,7,0,0
0,0,22,0,0,0,0,0,0,0,0,0,0,0,0,0,0,0,22,0,0
0,0,7,0,0,0,0,29,0,29,0,29,0,29,0,29,0,0,7,0,0
0,0,12,7,7,7,7,7,12,7,22,7,22,7,22,7,22,7,12,0,0
0,0,13,0,0,0,0,0,0,0,0,0,0,0,0,0,0,0,30,0,0
0,0,14,0,0,0,0,0,0,0,0,0,0,0,0,0,0,4,30,0,0
0,0,13,0,0,0,0,0,0,0,0,0,0,0,0,0,0,0,30,0,0
0,0,14,15,0,0,0,0,0,0,0,0,0,0,0,0,0,4,30,0,0
0,0,13,0,0,0,0,0,0,0,0,0,0,0,0,0,0,0,30,0,0
0,0,14,0,0,0,0,0,0,0,0,0,0,0,0,0,0,4,30,0,0
0,0,13,0,0,0,0,0,12,0,0,0,0,0,0,0,0,0,30,0,0
0,0,12,0,0,0,0,0,12,0,0,0,0,0,0,0,0,0,30,0,0
0,0,0,0,0,0,0,0,0,0,0,0,0,0,0,0,0,0,0,0,0
0,0,0,0,0,0,0,0,0,0,0,0,0,0,0,0,0,0,0,0,0
:endlayer
layer: 7
0,0,0,0,0,0,0,0,0,0,0,0,0,0,0,0,0,0,0,0,0
0,0,0,0,0,0,0,0,0,0,0,0,0,0,0,0,0,0,0,0,0
0,0,12,7,7,7,7,7,12,7,7,7,7,7,7,7,7,7,12,0,0
0,0,7,0,0,0,0,0,0,0,0,0,0,0,0,0,0,0,7,0,0
0,0,7,0,0,0,0,0,0,0,0,0,0,0,0,0,0,0,7,0,0
0,0,7,0,0,0,0,0,0,0,0,0,0,0,0,0,0,0,7,0,0
0,0,7,0,0,0,0,0,0,0,0,0,0,0,0,0,0,0,7,0,0
0,0,7,0,0,0,0,0,0,0,0,0,0,0,0,0,0,0,7,0,0
0,0,12,7,7,7,7,7,12,7,7,7,7,7,7,7,7,7,12,0,0
0,0,14,0,0,0,0,0,0,0,0,0,0,0,0,0,0,0,0,0,0
0,0,13,0,0,0,0,0,0,0,0,0,0,0,0,0,0,0,0,0,0
0,0,14,0,0,0,0,0,0,0,0,0,0,0,0,0,0,0,0,0,0
0,0,13,0,0,0,0,0,0,0,0,0,0,0,0,0,0,0,0,0,0
0,0,14,15,0,0,0,0,0,0,0,0,0,0,0,0,0,0,0,0,0
0,0,13,0,0,0,0,0,0,0,0,0,0,0,0,0,0,0,0,0,0
0,0,14,0,0,0,0,0,12,0,0,0,0,0,0,0,0,0,0,0,0
0,0,12,31,0,0,0,32,12,31,0,0,0,0,0,0,0,0,0,0,0
0,0,28,0,0,0,0,0,28,0,0,0,0,0,0,0,0,0,0,0,0
0,0,0,0,0,0,0,0,0,0,0,0,0,0,0,0,0,0,0,0,0
:endlayer
layer: 8
0,0,0,0,0,0,0,0,0,0,0,0,0,0,0,0,0,0,0,0,0
0,0,0,0,0,0,0,0,15,15,15,15,15,15,15,15,15,15,15,15,0
0,0,12,36,36,36,36,36,12,6,6,6,6,6,6,6,6,6,12,39,0
0,0,35,7,7,7,7,7,7,7,7,7,7,7,7,7,7,7,35,39,0
0,0,35,7,7,7,7,7,7,7,7,7,7,7,7,7,7,7,35,39,0
0,0,35,7,7,7,7,7,7,7,7,7,7,7,7,7,7,7,35,39,0
0,0,35,7,7,7,7,7,7,7,7,7,7,7,7,7,7,7,35,39,0
0,0,35,7,7,7,7,7,7,7,7,7,7,7,7,7,7,7,35,39,0
0,0,12,7,7,7,7,7,12,6,6,6,6,6,6,6,6,6,12,39,0
0,0,35,7,7,7,7,7,35,38,38,38,38,38,38,38,38,38,38,38,0
0,0,35,7,7,7,7,7,35,0,0,0,0,0,0,0,0,0,0,0,0
0,0,35,0,7,7,7,7,35,0,0,0,0,0,0,0,0,0,0,0,0
0,0,35,0,7,7,7,7,35,0,0,0,0,0,0,0,0,0,0,0,0
0,0,35,0,7,7,7,7,35,0,0,0,0,0,0,0,0,0,0,0,0
0,0,35,15,7,7,7,7,35,0,0,0,0,0,0,0,0,0,0,0,0
0,0,35,7,7,7,7,7,35,0,0,0,0,0,0,0,0,0,0,0,0
0,33,12,36,36,36,36,36,12,37,0,0,0,0,0,0,0,0,0,0,0
0,0,34,0,0,0,0,0,34,0,0,0,0,0,0,0,0,0,0,0,0
0,0,0,0,0,0,0,0,0,0,0,0,0,0,0,0,0,0,0,0,0
:endlayer
layer: 9
0,0,0,0,0,0,0,0,0,0,0,0,0,0,0,0,0,0,0,0,0
0,0,0,0,0,0,0,0,0,0,0,0,0,0,0,0,0,0,0,0,0
0,0,12,7,7,7,7,7,12,15,15,15,15,15,15,15,15,15,15,15,0
0,0,7,0,43,13,44,0,7,22,22,22,22,22,22,22,22,22,35,0,0
0,0,7,0,0,0,0,0,7,0,47,13,13,48,0,0,51,52,7,0,0
0,0,7,0,6,6,6,0,46,0,0,0,0,0,0,0,0,0,7,0,0
0,0,7,40,0,0,0,0,7,0,0,0,0,0,0,49,50,50,7,0,0
0,0,7,1,42,0,0,0,7,22,22,22,22,22,22,22,22,22,35,0,0
0,0,12,7,7,7,20,7,12,38,38,38,38,38,38,38,38,38,38,38,0
0,0,22,0,41,0,4,4,22,0,0,0,0,0,0,0,0,0,0,0,0
0,0,22,4,4,0,4,0,22,0,0,0,0,0,0,0,0,0,0,0,0
0,0,22,0,4,4,4,0,22,0,0,0,0,0,0,0,0,0,0,0,0
0,0,22,0,0,4,0,4,22,0,0,0,0,0,0,0,0,0,0,0,0
0,0,22,0,0,3,4,0,22,0,0,0,0,0,0,0,0,0,0,0,0
0,0,22,0,3,4,0,4,22,0,0,0,0,0,0,0,0,0,0,0,0
0,0,22,0,0,4,3,0,45,0,0,0,0,0,0,0,0,0,0,0,0
0,0,12,22,22,22,22,22,12,0,0,0,0,0,0,0,0,0,0,0,0
0,0,0,0,0,0,0,0,0,0,0,0,0,0,0,0,0,0,0,0,0
0,0,0,0,0,0,0,0,0,0,0,0,0,0,0,0,0,0,0,0,0
:endlayer
layer: 10
0,0,0,0,0,0,0,0,0,0,0,0,0,0,0,0,0,0,0,0,0
0,0,0,0,0,0,0,0,0,0,0,0,0,0,0,0,0,0,0,0,0
0,0,12,7,22,7,22,7,12,0,0,0,0,0,0,0,0,0,0,0,0
0,0,7,0,0,0,0,0,7,15,15,15,15,15,15,15,15,15,15,15,0
0,0,22,0,0,0,0,0,7,31,0,0,0,0,0,0,0,0,35,0,0
0,0,7,0,26,26,26,0,55,0,0,0,0,0,0,0,0,0,7,0,0
0,0,22,0,0,0,0,0,7,31,0,0,0,0,0,0,0,0,35,0,0
0,0,7,53,0,0,0,0,7,38,38,38,38,38,38,38,38,38,38,38,0
0,0,12,7,7,7,54,7,12,0,0,0,0,0,0,0,0,0,0,0,0
0,0,0,0,41,0,0,0,0,0,0,0,0,0,0,0,0,0,0,0,0
0,0,0,0,0,0,0,0,0,0,0,0,0,0,0,0,0,0,0,0,0
0,0,0,0,0,0,0,0,0,0,0,0,0,0,0,0,0,0,0,0,0
0,0,0,0,0,0,0,0,0,0,0,0,0,0,0,0,0,0,0,0,0
0,0,0,0,0,0,0,0,0,0,0,0,0,0,0,0,0,0,0,0,0
0,0,0,0,0,0,0,0,0,0,0,0,0,0,0,0,0,0,0,0,0
0,0,0,0,0,0,0,0,0,0,0,0,0,0,0,0,0,0,0,0,0
0,0,12,0,0,0,0,0,12,0,0,0,0,0,0,0,0,0,0,0,0
0,0,0,0,0,0,0,0,0,0,0,0,0,0,0,0,0,0,0,0,0
0,0,0,0,0,0,0,0,0,0,0,0,0,0,0,0,0,0,0,0,0
:endlayer
layer: 11
0,0,0,0,0,0,0,0,0,0,0,0,0,0,0,0,0,0,0,0,0
0,0,0,0,0,0,0,0,0,0,0,0,0,0,0,0,0,0,0,0,0
0,0,12,7,22,7,22,7,12,0,0,0,0,0,0,0,0,0,0,0,0
0,0,7,0,0,28,0,0,7,0,0,0,0,0,0,0,0,0,0,0,0
0,0,22,0,0,0,0,0,7,15,15,15,15,15,15,15,15,15,15,15,0
0,0,7,31,0,0,0,0,7,0,0,0,0,0,0,0,0,0,6,60,0
0,0,22,0,0,0,0,0,7,38,38,38,38,38,38,38,38,38,38,38,0
0,0,7,0,0,0,0,0,7,0,0,0,0,0,0,0,0,0,0,0,0
0,0,12,7,7,7,7,7,12,0,0,0,0,0,0,0,0,0,0,0,0
0,0,0,0,41,0,0,0,0,0,0,0,0,0,0,0,0,0,0,0,0
0,0,0,0,0,0,0,0,0,0,0,0,0,0,0,0,0,0,0,0,0
0,0,0,0,0,0,0,0,0,0,0,0,0,0,0,0,0,0,0,0,0
0,0,0,0,0,0,0,0,0,0,0,0,0,0,0,0,0,0,0,0,0
0,0,0,0,0,0,0,0,0,0,0,0,0,0,0,0,0,0,0,0,0
0,0,0,0,0,0,0,0,0,0,0,0,0,0,0,0,0,0,0,0,0
0,0,58,0,0,0,0,0,58,0,0,0,0,0,0,0,0,0,0,0,0
0,56,12,59,0,0,0,56,12,59,0,0,0,0,0,0,0,0,0,0,0
0,0,57,0,0,0,0,0,57,0,0,0,0,0,0,0,0,0,0,0,0
0,0,0,0,0,0,0,0,0,0,0,0,0,0,0,0,0,0,0,0,0
:endlayer
layer: 12
0,0,0,0,0,0,0,0,0,0,0,0,0,0,0,0,0,0,0,0,0
0,0,0,0,0,0,0,0,0,0,0,0,0,0,0,0,0,0,0,0,0
0,0,12,7,7,7,7,7,12,0,0,0,0,0,0,0,0,0,0,0,0
0,0,7,0,0,0,0,0,7,0,0,0,0,0,0,0,0,0,0,0,0
0,0,7,0,0,0,0,0,7,0,0,0,0,0,0,0,0,0,0,0,0
0,0,7,0,0,0,0,0,7,39,39,39,39,39,39,39,39,39,39,60,0
0,0,7,0,0,0,0,0,7,0,0,0,0,0,0,0,0,0,0,0,0
0,0,7,0,0,0,0,0,7,0,0,0,0,0,0,0,0,0,0,0,0
0,0,12,7,7,7,7,7,12,0,0,0,0,0,0,0,0,0,0,0,0
0,0,0,0,41,0,0,0,0,0,0,0,0,0,0,0,0,0,0,0,0
0,0,0,0,0,0,0,0,0,0,0,0,0,0,0,0,0,0,0,0,0
0,0,0,0,0,0,0,0,0,0,0,0,0,0,0,0,0,0,0,0,0
0,0,0,0,0,0,0,0,0,0,0,0,0,0,0,0,0,0,0,0,0
0,0,0,0,0,0,0,0,0,0,0,0,0,0,0,0,0,0,0,0,0
0,0,0,0,0,0,0,0,0,0,0,0,0,0,0,0,0,0,0,0,0
0,0,0,0,0,0,0,0,0,0,0,0,0,0,0,0,0,0,0,0,0
0,0,39,0,0,0,0,0,39,0,0,0,0,0,0,0,0,0,0,0,0
0,0,0,0,0,0,0,0,0,0,0,0,0,0,0,0,0,0,0,0,0
0,0,0,0,0,0,0,0,0,0,0,0,0,0,0,0,0,0,0,0,0
:endlayer
layer: 13
0,0,0,0,0,0,0,0,0,0,0,0,0,0,0,0,0,0,0,0,0
0,0,61,0,0,0,0,0,61,0,0,0,0,0,0,0,0,0,0,0,0
0,33,12,36,36,36,36,36,12,37,0,0,0,0,0,0,0,0,0,0,0
0,0,35,7,7,7,7,7,35,0,0,0,0,0,0,0,0,0,0,0,0
0,0,35,7,7,7,7,7,35,0,0,0,0,0,0,0,0,0,0,58,0
0,0,35,7,7,7,7,7,35,0,0,0,0,0,0,0,0,0,0,62,0
0,0,35,7,7,7,7,7,35,0,0,0,0,0,0,0,0,0,0,57,0
0,0,35,7,7,7,7,7,35,0,0,0,0,0,0,0,0,0,0,0,0
0,33,12,36,36,36,36,36,12,37,0,0,0,0,0,0,0,0,0,0,0
0,0,34,0,41,0,0,0,34,0,0,0,0,0,0,0,0,0,0,0,0
0,0,0,0,0,0,0,0,0,0,0,0,0,0,0,0,0,0,0,0,0
0,0,0,0,0,0,0,0,0,0,0,0,0,0,0,0,0,0,0,0,0
0,0,0,0,0,0,0,0,0,0,0,0,0,0,0,0,0,0,0,0,0
0,0,0,0,0,0,0,0,0,0,0,0,0,0,0,0,0,0,0,0,0
0,0,0,0,0,0,0,0,0,0,0,0,0,0,0,0,0,0,0,0,0
0,0,0,0,0,0,0,0,0,0,0,0,0,0,0,0,0,0,0,0,0
0,0,0,0,0,0,0,0,0,0,0,0,0,0,0,0,0,0,0,0,0
0,0,0,0,0,0,0,0,0,0,0,0,0,0,0,0,0,0,0,0,0
0,0,0,0,0,0,0,0,0,0,0,0,0,0,0,0,0,0,0,0,0
:endlayer
layer: 14
0,0,0,0,0,0,0,0,0,0,0,0,0,0,0,0,0,0,0,0,0
0,0,0,0,0,0,0,0,0,0,0,0,0,0,0,0,0,0,0,0,0
0,0,12,22,22,22,22,22,12,0,0,0,0,0,0,0,0,0,0,0,0
0,0,22,0,3,4,0,4,22,0,0,0,0,0,0,0,0,0,0,58,0
0,0,22,4,0,4,0,0,22,0,0,0,0,0,0,0,0,0,0,38,0
0,0,22,0,0,3,4,4,22,0,0,0,0,0,0,0,0,0,0,0,0
0,0,22,4,0,0,4,0,22,0,0,0,0,0,0,0,0,0,0,15,0
0,0,22,0,4,4,0,3,22,0,0,0,0,0,0,0,0,0,0,57,0
0,0,12,22,63,22,22,22,12,0,0,0,0,0,0,0,0,0,0,0,0
0,0,0,0,0,0,0,0,0,0,0,0,0,0,0,0,0,0,0,0,0
0,0,0,0,0,0,0,0,0,0,0,0,0,0,0,0,0,0,0,0,0
0,0,0,0,0,0,0,0,0,0,0,0,0,0,0,0,0,0,0,0,0
0,0,0,0,0,0,0,0,0,0,0,0,0,0,0,0,0,0,0,0,0
0,0,0,0,0,0,0,0,0,0,0,0,0,0,0,0,0,0,0,0,0
0,0,0,0,0,0,0,0,0,0,0,0,0,0,0,0,0,0,0,0,0
0,0,0,0,0,0,0,0,0,0,0,0,0,0,0,0,0,0,0,0,0
0,0,0,0,0,0,0,0,0,0,0,0,0,0,0,0,0,0,0,0,0
0,0,0,0,0,0,0,0,0,0,0,0,0,0,0,0,0,0,0,0,0
0,0,0,0,0,0,0,0,0,0,0,0,0,0,0,0,0,0,0,0,0
:endlayer
layer: 15
0,0,0,0,0,0,0,0,0,0,0,0,0,0,0,0,0,0,0,0,0
0,0,58,0,0,0,0,0,58,0,0,0,0,0,0,0,0,0,0,0,0
0,56,12,59,0,0,0,56,12,59,0,0,0,0,0,0,0,0,0,0,0
0,0,57,0,0,0,0,0,57,0,0,0,0,0,0,0,0,0,0,0,0
0,0,0,0,0,0,0,0,0,0,0,0,0,0,0,0,0,0,0,0,0
0,0,0,0,0,0,0,0,0,0,0,0,0,0,0,0,0,0,0,0,0
0,0,0,0,0,0,0,0,0,0,0,0,0,0,0,0,0,0,0,0,0
0,0,58,0,0,0,0,0,58,0,0,0,0,0,0,0,0,0,0,0,0
0,56,12,59,0,0,0,56,12,59,0,0,0,0,0,0,0,0,0,0,0
0,0,57,0,0,0,0,0,57,0,0,0,0,0,0,0,0,0,0,0,0
0,0,0,0,0,0,0,0,0,0,0,0,0,0,0,0,0,0,0,0,0
0,0,0,0,0,0,0,0,0,0,0,0,0,0,0,0,0,0,0,0,0
0,0,0,0,0,0,0,0,0,0,0,0,0,0,0,0,0,0,0,0,0
0,0,0,0,0,0,0,0,0,0,0,0,0,0,0,0,0,0,0,0,0
0,0,0,0,0,0,0,0,0,0,0,0,0,0,0,0,0,0,0,0,0
0,0,0,0,0,0,0,0,0,0,0,0,0,0,0,0,0,0,0,0,0
0,0,0,0,0,0,0,0,0,0,0,0,0,0,0,0,0,0,0,0,0
0,0,0,0,0,0,0,0,0,0,0,0,0,0,0,0,0,0,0,0,0
0,0,0,0,0,0,0,0,0,0,0,0,0,0,0,0,0,0,0,0,0
:endlayer
layer: 16
0,0,0,0,0,0,0,0,0,0,0,0,0,0,0,0,0,0,0,0,0
0,0,0,0,0,0,0,0,0,0,0,0,0,0,0,0,0,0,0,0,0
0,0,39,0,0,0,0,0,39,0,0,0,0,0,0,0,0,0,0,0,0
0,0,0,0,0,0,0,0,0,0,0,0,0,0,0,0,0,0,0,0,0
0,0,0,0,0,0,0,0,0,0,0,0,0,0,0,0,0,0,0,0,0
0,0,0,0,0,0,0,0,0,0,0,0,0,0,0,0,0,0,0,0,0
0,0,0,0,0,0,0,0,0,0,0,0,0,0,0,0,0,0,0,0,0
0,0,0,0,0,0,0,0,0,0,0,0,0,0,0,0,0,0,0,0,0
0,0,39,0,0,0,0,0,39,0,0,0,0,0,0,0,0,0,0,0,0
0,0,0,0,0,0,0,0,0,0,0,0,0,0,0,0,0,0,0,0,0
0,0,0,0,0,0,0,0,0,0,0,0,0,0,0,0,0,0,0,0,0
0,0,0,0,0,0,0,0,0,0,0,0,0,0,0,0,0,0,0,0,0
0,0,0,0,0,0,0,0,0,0,0,0,0,0,0,0,0,0,0,0,0
0,0,0,0,0,0,0,0,0,0,0,0,0,0,0,0,0,0,0,0,0
0,0,0,0,0,0,0,0,0,0,0,0,0,0,0,0,0,0,0,0,0
0,0,0,0,0,0,0,0,0,0,0,0,0,0,0,0,0,0,0,0,0
0,0,0,0,0,0,0,0,0,0,0,0,0,0,0,0,0,0,0,0,0
0,0,0,0,0,0,0,0,0,0,0,0,0,0,0,0,0,0,0,0,0
0,0,0,0,0,0,0,0,0,0,0,0,0,0,0,0,0,0,0,0,0
:endlayer
layer: 17
0,0,0,0,0,0,0,0,0,0,0,0,0,0,0,0,0,0,0,0,0
0,0,0,0,0,0,0,0,0,0,0,0,0,0,0,0,0,0,0,0,0
0,0,0,0,0,0,0,0,0,0,0,0,0,0,0,0,0,0,0,0,0
0,0,0,0,0,0,0,0,0,0,0,0,0,0,0,0,0,0,0,0,0
0,0,0,0,0,0,0,0,0,0,0,0,0,0,0,0,0,0,0,0,0
0,0,0,0,0,0,0,0,0,0,0,0,0,0,0,0,0,0,0,0,0
0,0,0,0,0,0,0,0,0,0,0,0,0,0,0,0,0,0,0,0,0
0,0,0,0,0,0,0,0,0,0,0,0,0,0,0,0,0,0,0,0,0
0,0,0,0,0,0,0,0,0,0,0,0,0,0,0,0,0,0,0,0,0
0,0,0,0,0,0,0,0,0,0,0,0,0,0,0,0,0,0,0,0,0
0,0,0,0,0,0,0,0,0,0,0,0,0,0,0,0,0,0,0,0,0
0,0,0,0,0,0,0,0,0,0,0,0,0,0,0,0,0,0,0,0,0
0,0,0,0,0,0,0,0,0,0,0,0,0,0,0,0,0,0,0,0,0
0,0,0,0,0,0,0,0,0,0,0,0,0,0,0,0,0,0,0,0,0
0,0,0,0,0,0,0,0,0,0,0,0,0,0,0,0,0,0,0,0,0
0,0,0,0,0,0,0,0,0,0,0,0,0,0,0,0,0,0,0,0,0
0,0,0,0,0,0,0,0,0,0,0,0,0,0,0,0,0,0,0,0,0
0,0,0,0,0,0,0,0,0,0,0,0,0,0,0,0,0,0,0,0,0
0,0,0,0,0,0,0,0,0,0,0,0,0,0,0,0,0,0,0,0,0
:endlayer
layer: 18
0,0,0,0,0,0,0,0,0,0,0,0,0,0,0,0,0,0,0,0,0
0,0,0,0,0,0,0,0,0,0,0,0,0,0,0,0,0,0,0,0,0
0,0,0,0,0,0,0,0,0,0,0,0,0,0,0,0,0,0,0,0,0
0,0,0,0,0,0,0,0,0,0,0,0,0,0,0,0,0,0,0,0,0
0,0,0,0,0,0,0,0,0,0,0,0,0,0,0,0,0,0,0,0,0
0,0,0,0,0,0,0,0,0,0,0,0,0,0,0,0,0,0,0,0,0
0,0,0,0,0,0,0,0,0,0,0,0,0,0,0,0,0,0,0,0,0
0,0,0,0,0,0,0,0,0,0,0,0,0,0,0,0,0,0,0,0,0
0,0,0,0,0,0,0,0,0,0,0,0,0,0,0,0,0,0,0,0,0
0,0,0,0,0,0,0,0,0,0,0,0,0,0,0,0,0,0,0,0,0
0,0,0,0,0,0,0,0,0,0,0,0,0,0,0,0,0,0,0,0,0
0,0,0,0,0,0,0,0,0,0,0,0,0,0,0,0,0,0,0,0,0
0,0,0,0,0,0,0,0,0,0,0,0,0,0,0,0,0,0,0,0,0
0,0,0,0,0,0,0,0,0,0,0,0,0,0,0,0,0,0,0,0,0
0,0,0,0,0,0,0,0,0,0,0,0,0,0,0,0,0,0,0,0,0
0,0,0,0,0,0,0,0,0,0,0,0,0,0,0,0,0,0,0,0,0
0,0,0,0,0,0,0,0,0,0,0,0,0,0,0,0,0,0,0,0,0
0,0,0,0,0,0,0,0,0,0,0,0,0,0,0,0,0,0,0,0,0
0,0,0,0,0,0,0,0,0,0,0,0,0,0,0,0,0,0,0,0,0
:endlayer
layer: 19
0,0,0,0,0,0,0,0,0,0,0,0,0,0,0,0,0,0,0,0,0
0,0,0,0,0,0,0,0,0,0,0,0,0,0,0,0,0,0,0,0,0
0,0,0,0,0,0,0,0,0,0,0,0,0,0,0,0,0,0,0,0,0
0,0,0,0,0,0,0,0,0,0,0,0,0,0,0,0,0,0,0,0,0
0,0,0,0,0,0,0,0,0,0,0,0,0,0,0,0,0,0,0,0,0
0,0,0,0,0,0,0,0,0,0,0,0,0,0,0,0,0,0,0,0,0
0,0,0,0,0,0,0,0,0,0,0,0,0,0,0,0,0,0,0,0,0
0,0,0,0,0,0,0,0,0,0,0,0,0,0,0,0,0,0,0,0,0
0,0,0,0,0,0,0,0,0,0,0,0,0,0,0,0,0,0,0,0,0
0,0,0,0,0,0,0,0,0,0,0,0,0,0,0,0,0,0,0,0,0
0,0,0,0,0,0,0,0,0,0,0,0,0,0,0,0,0,0,0,0,0
0,0,0,0,0,0,0,0,0,0,0,0,0,0,0,0,0,0,0,0,0
0,0,0,0,0,0,0,0,0,0,0,0,0,0,0,0,0,0,0,0,0
0,0,0,0,0,0,0,0,0,0,0,0,0,0,0,0,0,0,0,0,0
0,0,0,0,0,0,0,0,0,0,0,0,0,0,0,0,0,0,0,0,0
0,0,0,0,0,0,0,0,0,0,0,0,0,0,0,0,0,0,0,0,0
0,0,0,0,0,0,0,0,0,0,0,0,0,0,0,0,0,0,0,0,0
0,0,0,0,0,0,0,0,0,0,0,0,0,0,0,0,0,0,0,0,0
0,0,0,0,0,0,0,0,0,0,0,0,0,0,0,0,0,0,0,0,0
:endlayer
layer: 20
0,0,0,0,0,0,0,0,0,0,0,0,0,0,0,0,0,0,0,0,0
0,0,0,0,0,0,0,0,0,0,0,0,0,0,0,0,0,0,0,0,0
0,0,0,0,0,0,0,0,0,0,0,0,0,0,0,0,0,0,0,0,0
0,0,0,0,0,0,0,0,0,0,0,0,0,0,0,0,0,0,0,0,0
0,0,0,0,0,0,0,0,0,0,0,0,0,0,0,0,0,0,0,0,0
0,0,0,0,0,0,0,0,0,0,0,0,0,0,0,0,0,0,0,0,0
0,0,0,0,0,0,0,0,0,0,0,0,0,0,0,0,0,0,0,0,0
0,0,0,0,0,0,0,0,0,0,0,0,0,0,0,0,0,0,0,0,0
0,0,0,0,0,0,0,0,0,0,0,0,0,0,0,0,0,0,0,0,0
0,0,0,0,0,0,0,0,0,0,0,0,0,0,0,0,0,0,0,0,0
0,0,0,0,0,0,0,0,0,0,0,0,0,0,0,0,0,0,0,0,0
0,0,0,0,0,0,0,0,0,0,0,0,0,0,0,0,0,0,0,0,0
0,0,0,0,0,0,0,0,0,0,0,0,0,0,0,0,0,0,0,0,0
0,0,0,0,0,0,0,0,0,0,0,0,0,0,0,0,0,0,0,0,0
0,0,0,0,0,0,0,0,0,0,0,0,0,0,0,0,0,0,0,0,0
0,0,0,0,0,0,0,0,0,0,0,0,0,0,0,0,0,0,0,0,0
0,0,0,0,0,0,0,0,0,0,0,0,0,0,0,0,0,0,0,0,0
0,0,0,0,0,0,0,0,0,0,0,0,0,0,0,0,0,0,0,0,0
0,0,0,0,0,0,0,0,0,0,0,0,0,0,0,0,0,0,0,0,0
:endlayer
layer: 21
0,0,0,0,0,0,0,0,0,0,0,0,0,0,0,0,0,0,0,0,0
0,0,0,0,0,0,0,0,0,0,0,0,0,0,0,0,0,0,0,0,0
0,0,0,0,0,0,0,0,0,0,0,0,0,0,0,0,0,0,0,0,0
0,0,0,0,0,0,0,0,0,0,0,0,0,0,0,0,0,0,0,0,0
0,0,0,0,0,0,0,0,0,0,0,0,0,0,0,0,0,0,0,0,0
0,0,0,0,0,0,0,0,0,0,0,0,0,0,0,0,0,0,0,0,0
0,0,0,0,0,0,0,0,0,0,0,0,0,0,0,0,0,0,0,0,0
0,0,0,0,0,0,0,0,0,0,0,0,0,0,0,0,0,0,0,0,0
0,0,0,0,0,0,0,0,0,0,0,0,0,0,0,0,0,0,0,0,0
0,0,0,0,0,0,0,0,0,0,0,0,0,0,0,0,0,0,0,0,0
0,0,0,0,0,0,0,0,0,0,0,0,0,0,0,0,0,0,0,0,0
0,0,0,0,0,0,0,0,0,0,0,0,0,0,0,0,0,0,0,0,0
0,0,0,0,0,0,0,0,0,0,0,0,0,0,0,0,0,0,0,0,0
0,0,0,0,0,0,0,0,0,0,0,0,0,0,0,0,0,0,0,0,0
0,0,0,0,0,0,0,0,0,0,0,0,0,0,0,0,0,0,0,0,0
0,0,0,0,0,0,0,0,0,0,0,0,0,0,0,0,0,0,0,0,0
0,0,0,0,0,0,0,0,0,0,0,0,0,0,0,0,0,0,0,0,0
0,0,0,0,0,0,0,0,0,0,0,0,0,0,0,0,0,0,0,0,0
0,0,0,0,0,0,0,0,0,0,0,0,0,0,0,0,0,0,0,0,0
:endlayer
layer: 22
0,0,0,0,0,0,0,0,0,0,0,0,0,0,0,0,0,0,0,0,0
0,0,0,0,0,0,0,0,0,0,0,0,0,0,0,0,0,0,0,0,0
0,0,0,0,0,0,0,0,0,0,0,0,0,0,0,0,0,0,0,0,0
0,0,0,0,0,0,0,0,0,0,0,0,0,0,0,0,0,0,0,0,0
0,0,0,0,0,0,0,0,0,0,0,0,0,0,0,0,0,0,0,0,0
0,0,0,0,0,0,0,0,0,0,0,0,0,0,0,0,0,0,0,0,0
0,0,0,0,0,0,0,0,0,0,0,0,0,0,0,0,0,0,0,0,0
0,0,0,0,0,0,0,0,0,0,0,0,0,0,0,0,0,0,0,0,0
0,0,0,0,0,0,0,0,0,0,0,0,0,0,0,0,0,0,0,0,0
0,0,0,0,0,0,0,0,0,0,0,0,0,0,0,0,0,0,0,0,0
0,0,0,0,0,0,0,0,0,0,0,0,0,0,0,0,0,0,0,0,0
0,0,0,0,0,0,0,0,0,0,0,0,0,0,0,0,0,0,0,0,0
0,0,0,0,0,0,0,0,0,0,0,0,0,0,0,0,0,0,0,0,0
0,0,0,0,0,0,0,0,0,0,0,0,0,0,0,0,0,0,0,0,0
0,0,0,0,0,0,0,0,0,0,0,0,0,0,0,0,0,0,0,0,0
0,0,0,0,0,0,0,0,0,0,0,0,0,0,0,0,0,0,0,0,0
0,0,0,0,0,0,0,0,0,0,0,0,0,0,0,0,0,0,0,0,0
0,0,0,0,0,0,0,0,0,0,0,0,0,0,0,0,0,0,0,0,0
0,0,0,0,0,0,0,0,0,0,0,0,0,0,0,0,0,0,0,0,0
:endlayer
layer: 23
0,0,0,0,0,0,0,0,0,0,0,0,0,0,0,0,0,0,0,0,0
0,0,0,0,0,0,0,0,0,0,0,0,0,0,0,0,0,0,0,0,0
0,0,0,0,0,0,0,0,0,0,0,0,0,0,0,0,0,0,0,0,0
0,0,0,0,0,0,0,0,0,0,0,0,0,0,0,0,0,0,0,0,0
0,0,0,0,0,0,0,0,0,0,0,0,0,0,0,0,0,0,0,0,0
0,0,0,0,0,0,0,0,0,0,0,0,0,0,0,0,0,0,0,0,0
0,0,0,0,0,0,0,0,0,0,0,0,0,0,0,0,0,0,0,0,0
0,0,0,0,0,0,0,0,0,0,0,0,0,0,0,0,0,0,0,0,0
0,0,0,0,0,0,0,0,0,0,0,0,0,0,0,0,0,0,0,0,0
0,0,0,0,0,0,0,0,0,0,0,0,0,0,0,0,0,0,0,0,0
0,0,0,0,0,0,0,0,0,0,0,0,0,0,0,0,0,0,0,0,0
0,0,0,0,0,0,0,0,0,0,0,0,0,0,0,0,0,0,0,0,0
0,0,0,0,0,0,0,0,0,0,0,0,0,0,0,0,0,0,0,0,0
0,0,0,0,0,0,0,0,0,0,0,0,0,0,0,0,0,0,0,0,0
0,0,0,0,0,0,0,0,0,0,0,0,0,0,0,0,0,0,0,0,0
0,0,0,0,0,0,0,0,0,0,0,0,0,0,0,0,0,0,0,0,0
0,0,0,0,0,0,0,0,0,0,0,0,0,0,0,0,0,0,0,0,0
0,0,0,0,0,0,0,0,0,0,0,0,0,0,0,0,0,0,0,0,0
0,0,0,0,0,0,0,0,0,0,0,0,0,0,0,0,0,0,0,0,0
:endlayer
layer: 24
0,0,0,0,0,0,0,0,0,0,0,0,0,0,0,0,0,0,0,0,0
0,0,0,0,0,0,0,0,0,0,0,0,0,0,0,0,0,0,0,0,0
0,0,0,0,0,0,0,0,0,0,0,0,0,0,0,0,0,0,0,0,0
0,0,0,0,0,0,0,0,0,0,0,0,0,0,0,0,0,0,0,0,0
0,0,0,0,0,0,0,0,0,0,0,0,0,0,0,0,0,0,0,0,0
0,0,0,0,0,0,0,0,0,0,0,0,0,0,0,0,0,0,0,0,0
0,0,0,0,0,0,0,0,0,0,0,0,0,0,0,0,0,0,0,0,0
0,0,0,0,0,0,0,0,0,0,0,0,0,0,0,0,0,0,0,0,0
0,0,0,0,0,0,0,0,0,0,0,0,0,0,0,0,0,0,0,0,0
0,0,0,0,0,0,0,0,0,0,0,0,0,0,0,0,0,0,0,0,0
0,0,0,0,0,0,0,0,0,0,0,0,0,0,0,0,0,0,0,0,0
0,0,0,0,0,0,0,0,0,0,0,0,0,0,0,0,0,0,0,0,0
0,0,0,0,0,0,0,0,0,0,0,0,0,0,0,0,0,0,0,0,0
0,0,0,0,0,0,0,0,0,0,0,0,0,0,0,0,0,0,0,0,0
0,0,0,0,0,0,0,0,0,0,0,0,0,0,0,0,0,0,0,0,0
0,0,0,0,0,0,0,0,0,0,0,0,0,0,0,0,0,0,0,0,0
0,0,0,0,0,0,0,0,0,0,0,0,0,0,0,0,0,0,0,0,0
0,0,0,0,0,0,0,0,0,0,0,0,0,0,0,0,0,0,0,0,0
0,0,0,0,0,0,0,0,0,0,0,0,0,0,0,0,0,0,0,0,0
:endlayer
layer: 25
0,0,0,0,0,0,0,0,0,0,0,0,0,0,0,0,0,0,0,0,0
0,0,0,0,0,0,0,0,0,0,0,0,0,0,0,0,0,0,0,0,0
0,0,0,0,0,0,0,0,0,0,0,0,0,0,0,0,0,0,0,0,0
0,0,0,0,0,0,0,0,0,0,0,0,0,0,0,0,0,0,0,0,0
0,0,0,0,0,0,0,0,0,0,0,0,0,0,0,0,0,0,0,0,0
0,0,0,0,0,0,0,0,0,0,0,0,0,0,0,0,0,0,0,0,0
0,0,0,0,0,0,0,0,0,0,0,0,0,0,0,0,0,0,0,0,0
0,0,0,0,0,0,0,0,0,0,0,0,0,0,0,0,0,0,0,0,0
0,0,0,0,0,0,0,0,0,0,0,0,0,0,0,0,0,0,0,0,0
0,0,0,0,0,0,0,0,0,0,0,0,0,0,0,0,0,0,0,0,0
0,0,0,0,0,0,0,0,0,0,0,0,0,0,0,0,0,0,0,0,0
0,0,0,0,0,0,0,0,0,0,0,0,0,0,0,0,0,0,0,0,0
0,0,0,0,0,0,0,0,0,0,0,0,0,0,0,0,0,0,0,0,0
0,0,0,0,0,0,0,0,0,0,0,0,0,0,0,0,0,0,0,0,0
0,0,0,0,0,0,0,0,0,0,0,0,0,0,0,0,0,0,0,0,0
0,0,0,0,0,0,0,0,0,0,0,0,0,0,0,0,0,0,0,0,0
0,0,0,0,0,0,0,0,0,0,0,0,0,0,0,0,0,0,0,0,0
0,0,0,0,0,0,0,0,0,0,0,0,0,0,0,0,0,0,0,0,0
0,0,0,0,0,0,0,0,0,0,0,0,0,0,0,0,0,0,0,0,0
:endlayer
layer: 26
0,0,0,0,0,0,0,0,0,0,0,0,0,0,0,0,0,0,0,0,0
0,0,0,0,0,0,0,0,0,0,0,0,0,0,0,0,0,0,0,0,0
0,0,0,0,0,0,0,0,0,0,0,0,0,0,0,0,0,0,0,0,0
0,0,0,0,0,0,0,0,0,0,0,0,0,0,0,0,0,0,0,0,0
0,0,0,0,0,0,0,0,0,0,0,0,0,0,0,0,0,0,0,0,0
0,0,0,0,0,0,0,0,0,0,0,0,0,0,0,0,0,0,0,0,0
0,0,0,0,0,0,0,0,0,0,0,0,0,0,0,0,0,0,0,0,0
0,0,0,0,0,0,0,0,0,0,0,0,0,0,0,0,0,0,0,0,0
0,0,0,0,0,0,0,0,0,0,0,0,0,0,0,0,0,0,0,0,0
0,0,0,0,0,0,0,0,0,0,0,0,0,0,0,0,0,0,0,0,0
0,0,0,0,0,0,0,0,0,0,0,0,0,0,0,0,0,0,0,0,0
0,0,0,0,0,0,0,0,0,0,0,0,0,0,0,0,0,0,0,0,0
0,0,0,0,0,0,0,0,0,0,0,0,0,0,0,0,0,0,0,0,0
0,0,0,0,0,0,0,0,0,0,0,0,0,0,0,0,0,0,0,0,0
0,0,0,0,0,0,0,0,0,0,0,0,0,0,0,0,0,0,0,0,0
0,0,0,0,0,0,0,0,0,0,0,0,0,0,0,0,0,0,0,0,0
0,0,0,0,0,0,0,0,0,0,0,0,0,0,0,0,0,0,0,0,0
0,0,0,0,0,0,0,0,0,0,0,0,0,0,0,0,0,0,0,0,0
0,0,0,0,0,0,0,0,0,0,0,0,0,0,0,0,0,0,0,0,0
:endlayer
layer: 27
0,0,0,0,0,0,0,0,0,0,0,0,0,0,0,0,0,0,0,0,0
0,0,0,0,0,0,0,0,0,0,0,0,0,0,0,0,0,0,0,0,0
0,0,0,0,0,0,0,0,0,0,0,0,0,0,0,0,0,0,0,0,0
0,0,0,0,0,0,0,0,0,0,0,0,0,0,0,0,0,0,0,0,0
0,0,0,0,0,0,0,0,0,0,0,0,0,0,0,0,0,0,0,0,0
0,0,0,0,0,0,0,0,0,0,0,0,0,0,0,0,0,0,0,0,0
0,0,0,0,0,0,0,0,0,0,0,0,0,0,0,0,0,0,0,0,0
0,0,0,0,0,0,0,0,0,0,0,0,0,0,0,0,0,0,0,0,0
0,0,0,0,0,0,0,0,0,0,0,0,0,0,0,0,0,0,0,0,0
0,0,0,0,0,0,0,0,0,0,0,0,0,0,0,0,0,0,0,0,0
0,0,0,0,0,0,0,0,0,0,0,0,0,0,0,0,0,0,0,0,0
0,0,0,0,0,0,0,0,0,0,0,0,0,0,0,0,0,0,0,0,0
0,0,0,0,0,0,0,0,0,0,0,0,0,0,0,0,0,0,0,0,0
0,0,0,0,0,0,0,0,0,0,0,0,0,0,0,0,0,0,0,0,0
0,0,0,0,0,0,0,0,0,0,0,0,0,0,0,0,0,0,0,0,0
0,0,0,0,0,0,0,0,0,0,0,0,0,0,0,0,0,0,0,0,0
0,0,0,0,0,0,0,0,0,0,0,0,0,0,0,0,0,0,0,0,0
0,0,0,0,0,0,0,0,0,0,0,0,0,0,0,0,0,0,0,0,0
0,0,0,0,0,0,0,0,0,0,0,0,0,0,0,0,0,0,0,0,0
:endlayer
layer: 28
0,0,0,0,0,0,0,0,0,0,0,0,0,0,0,0,0,0,0,0,0
0,0,0,0,0,0,0,0,0,0,0,0,0,0,0,0,0,0,0,0,0
0,0,0,0,0,0,0,0,0,0,0,0,0,0,0,0,0,0,0,0,0
0,0,0,0,0,0,0,0,0,0,0,0,0,0,0,0,0,0,0,0,0
0,0,0,0,0,0,0,0,0,0,0,0,0,0,0,0,0,0,0,0,0
0,0,0,0,0,0,0,0,0,0,0,0,0,0,0,0,0,0,0,0,0
0,0,0,0,0,0,0,0,0,0,0,0,0,0,0,0,0,0,0,0,0
0,0,0,0,0,0,0,0,0,0,0,0,0,0,0,0,0,0,0,0,0
0,0,0,0,0,0,0,0,0,0,0,0,0,0,0,0,0,0,0,0,0
0,0,0,0,0,0,0,0,0,0,0,0,0,0,0,0,0,0,0,0,0
0,0,0,0,0,0,0,0,0,0,0,0,0,0,0,0,0,0,0,0,0
0,0,0,0,0,0,0,0,0,0,0,0,0,0,0,0,0,0,0,0,0
0,0,0,0,0,0,0,0,0,0,0,0,0,0,0,0,0,0,0,0,0
0,0,0,0,0,0,0,0,0,0,0,0,0,0,0,0,0,0,0,0,0
0,0,0,0,0,0,0,0,0,0,0,0,0,0,0,0,0,0,0,0,0
0,0,0,0,0,0,0,0,0,0,0,0,0,0,0,0,0,0,0,0,0
0,0,0,0,0,0,0,0,0,0,0,0,0,0,0,0,0,0,0,0,0
0,0,0,0,0,0,0,0,0,0,0,0,0,0,0,0,0,0,0,0,0
0,0,0,0,0,0,0,0,0,0,0,0,0,0,0,0,0,0,0,0,0
:endlayer
layer: 29
0,0,0,0,0,0,0,0,0,0,0,0,0,0,0,0,0,0,0,0,0
0,0,0,0,0,0,0,0,0,0,0,0,0,0,0,0,0,0,0,0,0
0,0,0,0,0,0,0,0,0,0,0,0,0,0,0,0,0,0,0,0,0
0,0,0,0,0,0,0,0,0,0,0,0,0,0,0,0,0,0,0,0,0
0,0,0,0,0,0,0,0,0,0,0,0,0,0,0,0,0,0,0,0,0
0,0,0,0,0,0,0,0,0,0,0,0,0,0,0,0,0,0,0,0,0
0,0,0,0,0,0,0,0,0,0,0,0,0,0,0,0,0,0,0,0,0
0,0,0,0,0,0,0,0,0,0,0,0,0,0,0,0,0,0,0,0,0
0,0,0,0,0,0,0,0,0,0,0,0,0,0,0,0,0,0,0,0,0
0,0,0,0,0,0,0,0,0,0,0,0,0,0,0,0,0,0,0,0,0
0,0,0,0,0,0,0,0,0,0,0,0,0,0,0,0,0,0,0,0,0
0,0,0,0,0,0,0,0,0,0,0,0,0,0,0,0,0,0,0,0,0
0,0,0,0,0,0,0,0,0,0,0,0,0,0,0,0,0,0,0,0,0
0,0,0,0,0,0,0,0,0,0,0,0,0,0,0,0,0,0,0,0,0
0,0,0,0,0,0,0,0,0,0,0,0,0,0,0,0,0,0,0,0,0
0,0,0,0,0,0,0,0,0,0,0,0,0,0,0,0,0,0,0,0,0
0,0,0,0,0,0,0,0,0,0,0,0,0,0,0,0,0,0,0,0,0
0,0,0,0,0,0,0,0,0,0,0,0,0,0,0,0,0,0,0,0,0
0,0,0,0,0,0,0,0,0,0,0,0,0,0,0,0,0,0,0,0,0
:endlayer
layer: 30
0,0,0,0,0,0,0,0,0,0,0,0,0,0,0,0,0,0,0,0,0
0,0,0,0,0,0,0,0,0,0,0,0,0,0,0,0,0,0,0,0,0
0,0,0,0,0,0,0,0,0,0,0,0,0,0,0,0,0,0,0,0,0
0,0,0,0,0,0,0,0,0,0,0,0,0,0,0,0,0,0,0,0,0
0,0,0,0,0,0,0,0,0,0,0,0,0,0,0,0,0,0,0,0,0
0,0,0,0,0,0,0,0,0,0,0,0,0,0,0,0,0,0,0,0,0
0,0,0,0,0,0,0,0,0,0,0,0,0,0,0,0,0,0,0,0,0
0,0,0,0,0,0,0,0,0,0,0,0,0,0,0,0,0,0,0,0,0
0,0,0,0,0,0,0,0,0,0,0,0,0,0,0,0,0,0,0,0,0
0,0,0,0,0,0,0,0,0,0,0,0,0,0,0,0,0,0,0,0,0
0,0,0,0,0,0,0,0,0,0,0,0,0,0,0,0,0,0,0,0,0
0,0,0,0,0,0,0,0,0,0,0,0,0,0,0,0,0,0,0,0,0
0,0,0,0,0,0,0,0,0,0,0,0,0,0,0,0,0,0,0,0,0
0,0,0,0,0,0,0,0,0,0,0,0,0,0,0,0,0,0,0,0,0
0,0,0,0,0,0,0,0,0,0,0,0,0,0,0,0,0,0,0,0,0
0,0,0,0,0,0,0,0,0,0,0,0,0,0,0,0,0,0,0,0,0
0,0,0,0,0,0,0,0,0,0,0,0,0,0,0,0,0,0,0,0,0
0,0,0,0,0,0,0,0,0,0,0,0,0,0,0,0,0,0,0,0,0
0,0,0,0,0,0,0,0,0,0,0,0,0,0,0,0,0,0,0,0,0
:endlayer
layer: 31
0,0,0,0,0,0,0,0,0,0,0,0,0,0,0,0,0,0,0,0,0
0,0,0,0,0,0,0,0,0,0,0,0,0,0,0,0,0,0,0,0,0
0,0,0,0,0,0,0,0,0,0,0,0,0,0,0,0,0,0,0,0,0
0,0,0,0,0,0,0,0,0,0,0,0,0,0,0,0,0,0,0,0,0
0,0,0,0,0,0,0,0,0,0,0,0,0,0,0,0,0,0,0,0,0
0,0,0,0,0,0,0,0,0,0,0,0,0,0,0,0,0,0,0,0,0
0,0,0,0,0,0,0,0,0,0,0,0,0,0,0,0,0,0,0,0,0
0,0,0,0,0,0,0,0,0,0,0,0,0,0,0,0,0,0,0,0,0
0,0,0,0,0,0,0,0,0,0,0,0,0,0,0,0,0,0,0,0,0
0,0,0,0,0,0,0,0,0,0,0,0,0,0,0,0,0,0,0,0,0
0,0,0,0,0,0,0,0,0,0,0,0,0,0,0,0,0,0,0,0,0
0,0,0,0,0,0,0,0,0,0,0,0,0,0,0,0,0,0,0,0,0
0,0,0,0,0,0,0,0,0,0,0,0,0,0,0,0,0,0,0,0,0
0,0,0,0,0,0,0,0,0,0,0,0,0,0,0,0,0,0,0,0,0
0,0,0,0,0,0,0,0,0,0,0,0,0,0,0,0,0,0,0,0,0
0,0,0,0,0,0,0,0,0,0,0,0,0,0,0,0,0,0,0,0,0
0,0,0,0,0,0,0,0,0,0,0,0,0,0,0,0,0,0,0,0,0
0,0,0,0,0,0,0,0,0,0,0,0,0,0,0,0,0,0,0,0,0
0,0,0,0,0,0,0,0,0,0,0,0,0,0,0,0,0,0,0,0,0
:endlayer
layer: 32
0,0,0,0,0,0,0,0,0,0,0,0,0,0,0,0,0,0,0,0,0
0,0,0,0,0,0,0,0,0,0,0,0,0,0,0,0,0,0,0,0,0
0,0,0,0,0,0,0,0,0,0,0,0,0,0,0,0,0,0,0,0,0
0,0,0,0,0,0,0,0,0,0,0,0,0,0,0,0,0,0,0,0,0
0,0,0,0,0,0,0,0,0,0,0,0,0,0,0,0,0,0,0,0,0
0,0,0,0,0,0,0,0,0,0,0,0,0,0,0,0,0,0,0,0,0
0,0,0,0,0,0,0,0,0,0,0,0,0,0,0,0,0,0,0,0,0
0,0,0,0,0,0,0,0,0,0,0,0,0,0,0,0,0,0,0,0,0
0,0,0,0,0,0,0,0,0,0,0,0,0,0,0,0,0,0,0,0,0
0,0,0,0,0,0,0,0,0,0,0,0,0,0,0,0,0,0,0,0,0
0,0,0,0,0,0,0,0,0,0,0,0,0,0,0,0,0,0,0,0,0
0,0,0,0,0,0,0,0,0,0,0,0,0,0,0,0,0,0,0,0,0
0,0,0,0,0,0,0,0,0,0,0,0,0,0,0,0,0,0,0,0,0
0,0,0,0,0,0,0,0,0,0,0,0,0,0,0,0,0,0,0,0,0
0,0,0,0,0,0,0,0,0,0,0,0,0,0,0,0,0,0,0,0,0
0,0,0,0,0,0,0,0,0,0,0,0,0,0,0,0,0,0,0,0,0
0,0,0,0,0,0,0,0,0,0,0,0,0,0,0,0,0,0,0,0,0
0,0,0,0,0,0,0,0,0,0,0,0,0,0,0,0,0,0,0,0,0
0,0,0,0,0,0,0,0,0,0,0,0,0,0,0,0,0,0,0,0,0
:endlayer
layer: 33
0,0,0,0,0,0,0,0,0,0,0,0,0,0,0,0,0,0,0,0,0
0,0,0,0,0,0,0,0,0,0,0,0,0,0,0,0,0,0,0,0,0
0,0,0,0,0,0,0,0,0,0,0,0,0,0,0,0,0,0,0,0,0
0,0,0,0,0,0,0,0,0,0,0,0,0,0,0,0,0,0,0,0,0
0,0,0,0,0,0,0,0,0,0,0,0,0,0,0,0,0,0,0,0,0
0,0,0,0,0,0,0,0,0,0,0,0,0,0,0,0,0,0,0,0,0
0,0,0,0,0,0,0,0,0,0,0,0,0,0,0,0,0,0,0,0,0
0,0,0,0,0,0,0,0,0,0,0,0,0,0,0,0,0,0,0,0,0
0,0,0,0,0,0,0,0,0,0,0,0,0,0,0,0,0,0,0,0,0
0,0,0,0,0,0,0,0,0,0,0,0,0,0,0,0,0,0,0,0,0
0,0,0,0,0,0,0,0,0,0,0,0,0,0,0,0,0,0,0,0,0
0,0,0,0,0,0,0,0,0,0,0,0,0,0,0,0,0,0,0,0,0
0,0,0,0,0,0,0,0,0,0,0,0,0,0,0,0,0,0,0,0,0
0,0,0,0,0,0,0,0,0,0,0,0,0,0,0,0,0,0,0,0,0
0,0,0,0,0,0,0,0,0,0,0,0,0,0,0,0,0,0,0,0,0
0,0,0,0,0,0,0,0,0,0,0,0,0,0,0,0,0,0,0,0,0
0,0,0,0,0,0,0,0,0,0,0,0,0,0,0,0,0,0,0,0,0
0,0,0,0,0,0,0,0,0,0,0,0,0,0,0,0,0,0,0,0,0
0,0,0,0,0,0,0,0,0,0,0,0,0,0,0,0,0,0,0,0,0
:endlayer
layer: 34
0,0,0,0,0,0,0,0,0,0,0,0,0,0,0,0,0,0,0,0,0
0,0,0,0,0,0,0,0,0,0,0,0,0,0,0,0,0,0,0,0,0
0,0,0,0,0,0,0,0,0,0,0,0,0,0,0,0,0,0,0,0,0
0,0,0,0,0,0,0,0,0,0,0,0,0,0,0,0,0,0,0,0,0
0,0,0,0,0,0,0,0,0,0,0,0,0,0,0,0,0,0,0,0,0
0,0,0,0,0,0,0,0,0,0,0,0,0,0,0,0,0,0,0,0,0
0,0,0,0,0,0,0,0,0,0,0,0,0,0,0,0,0,0,0,0,0
0,0,0,0,0,0,0,0,0,0,0,0,0,0,0,0,0,0,0,0,0
0,0,0,0,0,0,0,0,0,0,0,0,0,0,0,0,0,0,0,0,0
0,0,0,0,0,0,0,0,0,0,0,0,0,0,0,0,0,0,0,0,0
0,0,0,0,0,0,0,0,0,0,0,0,0,0,0,0,0,0,0,0,0
0,0,0,0,0,0,0,0,0,0,0,0,0,0,0,0,0,0,0,0,0
0,0,0,0,0,0,0,0,0,0,0,0,0,0,0,0,0,0,0,0,0
0,0,0,0,0,0,0,0,0,0,0,0,0,0,0,0,0,0,0,0,0
0,0,0,0,0,0,0,0,0,0,0,0,0,0,0,0,0,0,0,0,0
0,0,0,0,0,0,0,0,0,0,0,0,0,0,0,0,0,0,0,0,0
0,0,0,0,0,0,0,0,0,0,0,0,0,0,0,0,0,0,0,0,0
0,0,0,0,0,0,0,0,0,0,0,0,0,0,0,0,0,0,0,0,0
0,0,0,0,0,0,0,0,0,0,0,0,0,0,0,0,0,0,0,0,0
:endlayer
layer: 35
0,0,0,0,0,0,0,0,0,0,0,0,0,0,0,0,0,0,0,0,0
0,0,0,0,0,0,0,0,0,0,0,0,0,0,0,0,0,0,0,0,0
0,0,0,0,0,0,0,0,0,0,0,0,0,0,0,0,0,0,0,0,0
0,0,0,0,0,0,0,0,0,0,0,0,0,0,0,0,0,0,0,0,0
0,0,0,0,0,0,0,0,0,0,0,0,0,0,0,0,0,0,0,0,0
0,0,0,0,0,0,0,0,0,0,0,0,0,0,0,0,0,0,0,0,0
0,0,0,0,0,0,0,0,0,0,0,0,0,0,0,0,0,0,0,0,0
0,0,0,0,0,0,0,0,0,0,0,0,0,0,0,0,0,0,0,0,0
0,0,0,0,0,0,0,0,0,0,0,0,0,0,0,0,0,0,0,0,0
0,0,0,0,0,0,0,0,0,0,0,0,0,0,0,0,0,0,0,0,0
0,0,0,0,0,0,0,0,0,0,0,0,0,0,0,0,0,0,0,0,0
0,0,0,0,0,0,0,0,0,0,0,0,0,0,0,0,0,0,0,0,0
0,0,0,0,0,0,0,0,0,0,0,0,0,0,0,0,0,0,0,0,0
0,0,0,0,0,0,0,0,0,0,0,0,0,0,0,0,0,0,0,0,0
0,0,0,0,0,0,0,0,0,0,0,0,0,0,0,0,0,0,0,0,0
0,0,0,0,0,0,0,0,0,0,0,0,0,0,0,0,0,0,0,0,0
0,0,0,0,0,0,0,0,0,0,0,0,0,0,0,0,0,0,0,0,0
0,0,0,0,0,0,0,0,0,0,0,0,0,0,0,0,0,0,0,0,0
0,0,0,0,0,0,0,0,0,0,0,0,0,0,0,0,0,0,0,0,0
:endlayer
layer: 36
0,0,0,0,0,0,0,0,0,0,0,0,0,0,0,0,0,0,0,0,0
0,0,0,0,0,0,0,0,0,0,0,0,0,0,0,0,0,0,0,0,0
0,0,0,0,0,0,0,0,0,0,0,0,0,0,0,0,0,0,0,0,0
0,0,0,0,0,0,0,0,0,0,0,0,0,0,0,0,0,0,0,0,0
0,0,0,0,0,0,0,0,0,0,0,0,0,0,0,0,0,0,0,0,0
0,0,0,0,0,0,0,0,0,0,0,0,0,0,0,0,0,0,0,0,0
0,0,0,0,0,0,0,0,0,0,0,0,0,0,0,0,0,0,0,0,0
0,0,0,0,0,0,0,0,0,0,0,0,0,0,0,0,0,0,0,0,0
0,0,0,0,0,0,0,0,0,0,0,0,0,0,0,0,0,0,0,0,0
0,0,0,0,0,0,0,0,0,0,0,0,0,0,0,0,0,0,0,0,0
0,0,0,0,0,0,0,0,0,0,0,0,0,0,0,0,0,0,0,0,0
0,0,0,0,0,0,0,0,0,0,0,0,0,0,0,0,0,0,0,0,0
0,0,0,0,0,0,0,0,0,0,0,0,0,0,0,0,0,0,0,0,0
0,0,0,0,0,0,0,0,0,0,0,0,0,0,0,0,0,0,0,0,0
0,0,0,0,0,0,0,0,0,0,0,0,0,0,0,0,0,0,0,0,0
0,0,0,0,0,0,0,0,0,0,0,0,0,0,0,0,0,0,0,0,0
0,0,0,0,0,0,0,0,0,0,0,0,0,0,0,0,0,0,0,0,0
0,0,0,0,0,0,0,0,0,0,0,0,0,0,0,0,0,0,0,0,0
0,0,0,0,0,0,0,0,0,0,0,0,0,0,0,0,0,0,0,0,0
:endlayer
layer: 37
0,0,0,0,0,0,0,0,0,0,0,0,0,0,0,0,0,0,0,0,0
0,0,0,0,0,0,0,0,0,0,0,0,0,0,0,0,0,0,0,0,0
0,0,0,0,0,0,0,0,0,0,0,0,0,0,0,0,0,0,0,0,0
0,0,0,0,0,0,0,0,0,0,0,0,0,0,0,0,0,0,0,0,0
0,0,0,0,0,0,0,0,0,0,0,0,0,0,0,0,0,0,0,0,0
0,0,0,0,0,0,0,0,0,0,0,0,0,0,0,0,0,0,0,0,0
0,0,0,0,0,0,0,0,0,0,0,0,0,0,0,0,0,0,0,0,0
0,0,0,0,0,0,0,0,0,0,0,0,0,0,0,0,0,0,0,0,0
0,0,0,0,0,0,0,0,0,0,0,0,0,0,0,0,0,0,0,0,0
0,0,0,0,0,0,0,0,0,0,0,0,0,0,0,0,0,0,0,0,0
0,0,0,0,0,0,0,0,0,0,0,0,0,0,0,0,0,0,0,0,0
0,0,0,0,0,0,0,0,0,0,0,0,0,0,0,0,0,0,0,0,0
0,0,0,0,0,0,0,0,0,0,0,0,0,0,0,0,0,0,0,0,0
0,0,0,0,0,0,0,0,0,0,0,0,0,0,0,0,0,0,0,0,0
0,0,0,0,0,0,0,0,0,0,0,0,0,0,0,0,0,0,0,0,0
0,0,0,0,0,0,0,0,0,0,0,0,0,0,0,0,0,0,0,0,0
0,0,0,0,0,0,0,0,0,0,0,0,0,0,0,0,0,0,0,0,0
0,0,0,0,0,0,0,0,0,0,0,0,0,0,0,0,0,0,0,0,0
0,0,0,0,0,0,0,0,0,0,0,0,0,0,0,0,0,0,0,0,0
:endlayer
layer: 38
0,0,0,0,0,0,0,0,0,0,0,0,0,0,0,0,0,0,0,0,0
0,0,0,0,0,0,0,0,0,0,0,0,0,0,0,0,0,0,0,0,0
0,0,0,0,0,0,0,0,0,0,0,0,0,0,0,0,0,0,0,0,0
0,0,0,0,0,0,0,0,0,0,0,0,0,0,0,0,0,0,0,0,0
0,0,0,0,0,0,0,0,0,0,0,0,0,0,0,0,0,0,0,0,0
0,0,0,0,0,0,0,0,0,0,0,0,0,0,0,0,0,0,0,0,0
0,0,0,0,0,0,0,0,0,0,0,0,0,0,0,0,0,0,0,0,0
0,0,0,0,0,0,0,0,0,0,0,0,0,0,0,0,0,0,0,0,0
0,0,0,0,0,0,0,0,0,0,0,0,0,0,0,0,0,0,0,0,0
0,0,0,0,0,0,0,0,0,0,0,0,0,0,0,0,0,0,0,0,0
0,0,0,0,0,0,0,0,0,0,0,0,0,0,0,0,0,0,0,0,0
0,0,0,0,0,0,0,0,0,0,0,0,0,0,0,0,0,0,0,0,0
0,0,0,0,0,0,0,0,0,0,0,0,0,0,0,0,0,0,0,0,0
0,0,0,0,0,0,0,0,0,0,0,0,0,0,0,0,0,0,0,0,0
0,0,0,0,0,0,0,0,0,0,0,0,0,0,0,0,0,0,0,0,0
0,0,0,0,0,0,0,0,0,0,0,0,0,0,0,0,0,0,0,0,0
0,0,0,0,0,0,0,0,0,0,0,0,0,0,0,0,0,0,0,0,0
0,0,0,0,0,0,0,0,0,0,0,0,0,0,0,0,0,0,0,0,0
0,0,0,0,0,0,0,0,0,0,0,0,0,0,0,0,0,0,0,0,0
:endlayer
layer: 39
0,0,0,0,0,0,0,0,0,0,0,0,0,0,0,0,0,0,0,0,0
0,0,0,0,0,0,0,0,0,0,0,0,0,0,0,0,0,0,0,0,0
0,0,0,0,0,0,0,0,0,0,0,0,0,0,0,0,0,0,0,0,0
0,0,0,0,0,0,0,0,0,0,0,0,0,0,0,0,0,0,0,0,0
0,0,0,0,0,0,0,0,0,0,0,0,0,0,0,0,0,0,0,0,0
0,0,0,0,0,0,0,0,0,0,0,0,0,0,0,0,0,0,0,0,0
0,0,0,0,0,0,0,0,0,0,0,0,0,0,0,0,0,0,0,0,0
0,0,0,0,0,0,0,0,0,0,0,0,0,0,0,0,0,0,0,0,0
0,0,0,0,0,0,0,0,0,0,0,0,0,0,0,0,0,0,0,0,0
0,0,0,0,0,0,0,0,0,0,0,0,0,0,0,0,0,0,0,0,0
0,0,0,0,0,0,0,0,0,0,0,0,0,0,0,0,0,0,0,0,0
0,0,0,0,0,0,0,0,0,0,0,0,0,0,0,0,0,0,0,0,0
0,0,0,0,0,0,0,0,0,0,0,0,0,0,0,0,0,0,0,0,0
0,0,0,0,0,0,0,0,0,0,0,0,0,0,0,0,0,0,0,0,0
0,0,0,0,0,0,0,0,0,0,0,0,0,0,0,0,0,0,0,0,0
0,0,0,0,0,0,0,0,0,0,0,0,0,0,0,0,0,0,0,0,0
0,0,0,0,0,0,0,0,0,0,0,0,0,0,0,0,0,0,0,0,0
0,0,0,0,0,0,0,0,0,0,0,0,0,0,0,0,0,0,0,0,0
0,0,0,0,0,0,0,0,0,0,0,0,0,0,0,0,0,0,0,0,0
:endlayer
layer: 40
0,0,0,0,0,0,0,0,0,0,0,0,0,0,0,0,0,0,0,0,0
0,0,0,0,0,0,0,0,0,0,0,0,0,0,0,0,0,0,0,0,0
0,0,0,0,0,0,0,0,0,0,0,0,0,0,0,0,0,0,0,0,0
0,0,0,0,0,0,0,0,0,0,0,0,0,0,0,0,0,0,0,0,0
0,0,0,0,0,0,0,0,0,0,0,0,0,0,0,0,0,0,0,0,0
0,0,0,0,0,0,0,0,0,0,0,0,0,0,0,0,0,0,0,0,0
0,0,0,0,0,0,0,0,0,0,0,0,0,0,0,0,0,0,0,0,0
0,0,0,0,0,0,0,0,0,0,0,0,0,0,0,0,0,0,0,0,0
0,0,0,0,0,0,0,0,0,0,0,0,0,0,0,0,0,0,0,0,0
0,0,0,0,0,0,0,0,0,0,0,0,0,0,0,0,0,0,0,0,0
0,0,0,0,0,0,0,0,0,0,0,0,0,0,0,0,0,0,0,0,0
0,0,0,0,0,0,0,0,0,0,0,0,0,0,0,0,0,0,0,0,0
0,0,0,0,0,0,0,0,0,0,0,0,0,0,0,0,0,0,0,0,0
0,0,0,0,0,0,0,0,0,0,0,0,0,0,0,0,0,0,0,0,0
0,0,0,0,0,0,0,0,0,0,0,0,0,0,0,0,0,0,0,0,0
0,0,0,0,0,0,0,0,0,0,0,0,0,0,0,0,0,0,0,0,0
0,0,0,0,0,0,0,0,0,0,0,0,0,0,0,0,0,0,0,0,0
0,0,0,0,0,0,0,0,0,0,0,0,0,0,0,0,0,0,0,0,0
0,0,0,0,0,0,0,0,0,0,0,0,0,0,0,0,0,0,0,0,0
:endlayer
layer: 41
0,0,0,0,0,0,0,0,0,0,0,0,0,0,0,0,0,0,0,0,0
0,0,0,0,0,0,0,0,0,0,0,0,0,0,0,0,0,0,0,0,0
0,0,0,0,0,0,0,0,0,0,0,0,0,0,0,0,0,0,0,0,0
0,0,0,0,0,0,0,0,0,0,0,0,0,0,0,0,0,0,0,0,0
0,0,0,0,0,0,0,0,0,0,0,0,0,0,0,0,0,0,0,0,0
0,0,0,0,0,0,0,0,0,0,0,0,0,0,0,0,0,0,0,0,0
0,0,0,0,0,0,0,0,0,0,0,0,0,0,0,0,0,0,0,0,0
0,0,0,0,0,0,0,0,0,0,0,0,0,0,0,0,0,0,0,0,0
0,0,0,0,0,0,0,0,0,0,0,0,0,0,0,0,0,0,0,0,0
0,0,0,0,0,0,0,0,0,0,0,0,0,0,0,0,0,0,0,0,0
0,0,0,0,0,0,0,0,0,0,0,0,0,0,0,0,0,0,0,0,0
0,0,0,0,0,0,0,0,0,0,0,0,0,0,0,0,0,0,0,0,0
0,0,0,0,0,0,0,0,0,0,0,0,0,0,0,0,0,0,0,0,0
0,0,0,0,0,0,0,0,0,0,0,0,0,0,0,0,0,0,0,0,0
0,0,0,0,0,0,0,0,0,0,0,0,0,0,0,0,0,0,0,0,0
0,0,0,0,0,0,0,0,0,0,0,0,0,0,0,0,0,0,0,0,0
0,0,0,0,0,0,0,0,0,0,0,0,0,0,0,0,0,0,0,0,0
0,0,0,0,0,0,0,0,0,0,0,0,0,0,0,0,0,0,0,0,0
0,0,0,0,0,0,0,0,0,0,0,0,0,0,0,0,0,0,0,0,0
:endlayer

#### RULES ####
rule:
plugin=vanillaBlocks
number=1
data:
JSON:{{"val":{"blockName":{"val":"minecraft:dirt","id":"ss"},"meta":{"val":"0","id":"pi"},"buildPass":{"val":"0","id":"pi"}},"id":"ct"}}
:enddata
:endrule

rule:
plugin=vanillaBlocks
number=2
data:
JSON:{{"val":{"blockName":{"val":"minecraft:grass","id":"ss"},"meta":{"val":"0","id":"pi"},"buildPass":{"val":"0","id":"pi"}},"id":"ct"}}
:enddata
:endrule

rule:
plugin=vanillaBlocks
number=3
data:
JSON:{{"val":{"blockName":{"val":"minecraft:snow_layer","id":"ss"},"meta":{"val":"1","id":"pi"},"buildPass":{"val":"2","id":"pi"}},"id":"ct"}}
:enddata
:endrule

rule:
plugin=vanillaBlocks
number=4
data:
JSON:{{"val":{"blockName":{"val":"minecraft:snow_layer","id":"ss"},"meta":{"val":"0","id":"pi"},"buildPass":{"val":"2","id":"pi"}},"id":"ct"}}
:enddata
:endrule

rule:
plugin=vanillaBlocks
number=5
data:
JSON:{{"val":{"blockName":{"val":"minecraft:cobblestone","id":"ss"},"meta":{"val":"0","id":"pi"},"buildPass":{"val":"0","id":"pi"}},"id":"ct"}}
:enddata
:endrule

rule:
plugin=vanillaBlocks
number=6
data:
JSON:{{"val":{"blockName":{"val":"minecraft:log","id":"ss"},"meta":{"val":"0","id":"pi"},"buildPass":{"val":"0","id":"pi"}},"id":"ct"}}
:enddata
:endrule

rule:
plugin=vanillaBlocks
number=7
data:
JSON:{{"val":{"blockName":{"val":"minecraft:planks","id":"ss"},"meta":{"val":"0","id":"pi"},"buildPass":{"val":"0","id":"pi"}},"id":"ct"}}
:enddata
:endrule

rule:
plugin=vanillaBlocks
number=8
data:
JSON:{{"val":{"blockName":{"val":"minecraft:stone_slab","id":"ss"},"meta":{"val":"3","id":"pi"},"buildPass":{"val":"0","id":"pi"}},"id":"ct"}}
:enddata
:endrule

rule:
plugin=vanillaBlocks
number=9
data:
JSON:{{"val":{"blockName":{"val":"minecraft:double_stone_slab","id":"ss"},"meta":{"val":"3","id":"pi"},"buildPass":{"val":"0","id":"pi"}},"id":"ct"}}
:enddata
:endrule

rule:
plugin=vanillaBlocks
number=10
data:
JSON:{{"val":{"blockName":{"val":"minecraft:gravel","id":"ss"},"meta":{"val":"0","id":"pi"},"buildPass":{"val":"0","id":"pi"}},"id":"ct"}}
:enddata
:endrule

rule:
plugin=vanillaBlocks
number=11
data:
JSON:{{"val":{"blockName":{"val":"minecraft:snow_layer","id":"ss"},"meta":{"val":"2","id":"pi"},"buildPass":{"val":"2","id":"pi"}},"id":"ct"}}
:enddata
:endrule

rule:
plugin=vanillaBlocks
number=12
data:
JSON:{{"val":{"blockName":{"val":"minecraft:log","id":"ss"},"meta":{"val":"1","id":"pi"},"buildPass":{"val":"0","id":"pi"}},"id":"ct"}}
:enddata
:endrule

rule:
plugin=vanillaBlocks
number=13
data:
JSON:{{"val":{"blockName":{"val":"minecraft:oak_stairs","id":"ss"},"meta":{"val":"3","id":"pi"},"buildPass":{"val":"0","id":"pi"}},"id":"ct"}}
:enddata
:endrule

rule:
plugin=vanillaBlocks
number=14
data:
JSON:{{"val":{"blockName":{"val":"minecraft:oak_stairs","id":"ss"},"meta":{"val":"6","id":"pi"},"buildPass":{"val":"0","id":"pi"}},"id":"ct"}}
:enddata
:endrule

rule:
plugin=vanillaBlocks
number=15
data:
JSON:{{"val":{"blockName":{"val":"minecraft:dark_oak_stairs","id":"ss"},"meta":{"val":"2","id":"pi"},"buildPass":{"val":"0","id":"pi"}},"id":"ct"}}
:enddata
:endrule

rule:
plugin=vanillaBlocks
number=16
data:
JSON:{{"val":{"blockName":{"val":"minecraft:stone_stairs","id":"ss"},"meta":{"val":"3","id":"pi"},"buildPass":{"val":"0","id":"pi"}},"id":"ct"}}
:enddata
:endrule

rule:
plugin=awTownHall
number=17
data:
JSON:{{"val":{"teData":{"val":{"id":{"val":"Furnace","id":"ss"},"Items":{"val":[],"id":"ls"},"BurnTime":{"val":"0","id":"ps"},"z":{"val":"1869","id":"pi"},"y":{"val":"90","id":"pi"},"CookTime":{"val":"0","id":"ps"},"x":{"val":"1331","id":"pi"}},"id":"ct"},"blockName":{"val":"minecraft:furnace","id":"ss"},"meta":{"val":"5","id":"pi"},"buildPass":{"val":"0","id":"pi"}},"id":"ct"}}
:enddata
:endrule

rule:
plugin=vanillaBlocks
number=18
data:
JSON:{{"val":{"blockName":{"val":"minecraft:stone_stairs","id":"ss"},"meta":{"val":"2","id":"pi"},"buildPass":{"val":"0","id":"pi"}},"id":"ct"}}
:enddata
:endrule

rule:
plugin=vanillaBlocks
number=19
data:
JSON:{{"val":{"blockName":{"val":"minecraft:cauldron","id":"ss"},"meta":{"val":"3","id":"pi"},"buildPass":{"val":"0","id":"pi"}},"id":"ct"}}
:enddata
:endrule

rule:
plugin=vanillaDoors
number=20
data:
JSON:{{"val":{"sideFlag":{"val":"8","id":"pb"},"blockName":{"val":"minecraft:wooden_door","id":"ss"},"meta":{"val":"3","id":"pi"},"buildPass":{"val":"2","id":"pi"}},"id":"ct"}}
:enddata
:endrule

rule:
plugin=vanillaDoors
number=21
data:
JSON:{{"val":{"sideFlag":{"val":"9","id":"pb"},"blockName":{"val":"minecraft:wooden_door","id":"ss"},"meta":{"val":"3","id":"pi"},"buildPass":{"val":"2","id":"pi"}},"id":"ct"}}
:enddata
:endrule

rule:
plugin=vanillaBlocks
number=22
data:
JSON:{{"val":{"blockName":{"val":"minecraft:fence","id":"ss"},"meta":{"val":"0","id":"pi"},"buildPass":{"val":"0","id":"pi"}},"id":"ct"}}
:enddata
:endrule

rule:
plugin=vanillaBlocks
number=23
data:
JSON:{{"val":{"blockName":{"val":"minecraft:oak_stairs","id":"ss"},"meta":{"val":"2","id":"pi"},"buildPass":{"val":"0","id":"pi"}},"id":"ct"}}
:enddata
:endrule

rule:
plugin=vanillaDoors
number=24
data:
JSON:{{"val":{"sideFlag":{"val":"0","id":"pb"},"blockName":{"val":"minecraft:wooden_door","id":"ss"},"meta":{"val":"8","id":"pi"},"buildPass":{"val":"2","id":"pi"}},"id":"ct"}}
:enddata
:endrule

rule:
plugin=vanillaDoors
number=25
data:
JSON:{{"val":{"sideFlag":{"val":"0","id":"pb"},"blockName":{"val":"minecraft:wooden_door","id":"ss"},"meta":{"val":"9","id":"pi"},"buildPass":{"val":"2","id":"pi"}},"id":"ct"}}
:enddata
:endrule

rule:
plugin=vanillaBlocks
number=26
data:
JSON:{{"val":{"blockName":{"val":"minecraft:stone_pressure_plate","id":"ss"},"meta":{"val":"0","id":"pi"},"buildPass":{"val":"2","id":"pi"}},"id":"ct"}}
:enddata
:endrule

rule:
plugin=vanillaBlocks
number=27
data:
JSON:{{"val":{"blockName":{"val":"minecraft:wool","id":"ss"},"meta":{"val":"14","id":"pi"},"buildPass":{"val":"0","id":"pi"}},"id":"ct"}}
:enddata
:endrule

rule:
plugin=vanillaBlocks
number=28
data:
JSON:{{"val":{"blockName":{"val":"minecraft:torch","id":"ss"},"meta":{"val":"3","id":"pi"},"buildPass":{"val":"2","id":"pi"}},"id":"ct"}}
:enddata
:endrule

rule:
plugin=vanillaBlocks
number=29
data:
JSON:{{"val":{"blockName":{"val":"minecraft:torch","id":"ss"},"meta":{"val":"4","id":"pi"},"buildPass":{"val":"2","id":"pi"}},"id":"ct"}}
:enddata
:endrule

rule:
plugin=vanillaBlocks
number=30
data:
JSON:{{"val":{"blockName":{"val":"minecraft:stone_slab","id":"ss"},"meta":{"val":"2","id":"pi"},"buildPass":{"val":"0","id":"pi"}},"id":"ct"}}
:enddata
:endrule

rule:
plugin=vanillaBlocks
number=31
data:
JSON:{{"val":{"blockName":{"val":"minecraft:torch","id":"ss"},"meta":{"val":"1","id":"pi"},"buildPass":{"val":"2","id":"pi"}},"id":"ct"}}
:enddata
:endrule

rule:
plugin=vanillaBlocks
number=32
data:
JSON:{{"val":{"blockName":{"val":"minecraft:torch","id":"ss"},"meta":{"val":"2","id":"pi"},"buildPass":{"val":"2","id":"pi"}},"id":"ct"}}
:enddata
:endrule

rule:
plugin=vanillaBlocks
number=33
data:
JSON:{{"val":{"blockName":{"val":"minecraft:stone_button","id":"ss"},"meta":{"val":"2","id":"pi"},"buildPass":{"val":"2","id":"pi"}},"id":"ct"}}
:enddata
:endrule

rule:
plugin=vanillaBlocks
number=34
data:
JSON:{{"val":{"blockName":{"val":"minecraft:stone_button","id":"ss"},"meta":{"val":"3","id":"pi"},"buildPass":{"val":"2","id":"pi"}},"id":"ct"}}
:enddata
:endrule

rule:
plugin=vanillaBlocks
number=35
data:
JSON:{{"val":{"blockName":{"val":"minecraft:log","id":"ss"},"meta":{"val":"9","id":"pi"},"buildPass":{"val":"0","id":"pi"}},"id":"ct"}}
:enddata
:endrule

rule:
plugin=vanillaBlocks
number=36
data:
JSON:{{"val":{"blockName":{"val":"minecraft:log","id":"ss"},"meta":{"val":"5","id":"pi"},"buildPass":{"val":"0","id":"pi"}},"id":"ct"}}
:enddata
:endrule

rule:
plugin=vanillaBlocks
number=37
data:
JSON:{{"val":{"blockName":{"val":"minecraft:stone_button","id":"ss"},"meta":{"val":"1","id":"pi"},"buildPass":{"val":"2","id":"pi"}},"id":"ct"}}
:enddata
:endrule

rule:
plugin=vanillaBlocks
number=38
data:
JSON:{{"val":{"blockName":{"val":"minecraft:dark_oak_stairs","id":"ss"},"meta":{"val":"3","id":"pi"},"buildPass":{"val":"0","id":"pi"}},"id":"ct"}}
:enddata
:endrule

rule:
plugin=vanillaBlocks
number=39
data:
JSON:{{"val":{"blockName":{"val":"minecraft:wooden_slab","id":"ss"},"meta":{"val":"5","id":"pi"},"buildPass":{"val":"0","id":"pi"}},"id":"ct"}}
:enddata
:endrule

rule:
plugin=vanillaBlocks
number=40
data:
JSON:{{"val":{"blockName":{"val":"minecraft:trapdoor","id":"ss"},"meta":{"val":"4","id":"pi"},"buildPass":{"val":"2","id":"pi"}},"id":"ct"}}
:enddata
:endrule

rule:
plugin=vanillaBlocks
number=41
data:
JSON:{{"val":{"blockName":{"val":"minecraft:ladder","id":"ss"},"meta":{"val":"3","id":"pi"},"buildPass":{"val":"2","id":"pi"}},"id":"ct"}}
:enddata
:endrule

rule:
plugin=vanillaBlocks
number=42
data:
JSON:{{"val":{"blockName":{"val":"minecraft:trapdoor","id":"ss"},"meta":{"val":"7","id":"pi"},"buildPass":{"val":"2","id":"pi"}},"id":"ct"}}
:enddata
:endrule

rule:
plugin=vanillaSign
number=43
data:
JSON:{{"val":{"blockName":{"val":"minecraft:wall_sign","id":"ss"},"signContents1":{"val":"","id":"ss"},"signContents2":{"val":"","id":"ss"},"signContents0":{"val":"","id":"ss"},"meta":{"val":"4","id":"pi"},"signContents3":{"val":"","id":"ss"},"buildPass":{"val":"2","id":"pi"}},"id":"ct"}}
:enddata
:endrule

rule:
plugin=vanillaSign
number=44
data:
JSON:{{"val":{"blockName":{"val":"minecraft:wall_sign","id":"ss"},"signContents1":{"val":"","id":"ss"},"signContents2":{"val":"","id":"ss"},"signContents0":{"val":"","id":"ss"},"meta":{"val":"5","id":"pi"},"signContents3":{"val":"","id":"ss"},"buildPass":{"val":"2","id":"pi"}},"id":"ct"}}
:enddata
:endrule

rule:
plugin=vanillaBlocks
number=45
data:
JSON:{{"val":{"blockName":{"val":"minecraft:fence_gate","id":"ss"},"meta":{"val":"1","id":"pi"},"buildPass":{"val":"0","id":"pi"}},"id":"ct"}}
:enddata
:endrule

rule:
plugin=vanillaDoors
number=46
data:
JSON:{{"val":{"sideFlag":{"val":"8","id":"pb"},"blockName":{"val":"minecraft:wooden_door","id":"ss"},"meta":{"val":"0","id":"pi"},"buildPass":{"val":"2","id":"pi"}},"id":"ct"}}
:enddata
:endrule

rule:
plugin=vanillaSign
number=47
data:
JSON:{{"val":{"blockName":{"val":"minecraft:wall_sign","id":"ss"},"signContents1":{"val":"","id":"ss"},"signContents2":{"val":"","id":"ss"},"signContents0":{"val":"","id":"ss"},"meta":{"val":"4","id":"pi"},"signContents3":{"val":"","id":"ss"},"buildPass":{"val":"2","id":"pi"}},"id":"ct"}}
:enddata
:endrule

rule:
plugin=vanillaSign
number=48
data:
JSON:{{"val":{"blockName":{"val":"minecraft:wall_sign","id":"ss"},"signContents1":{"val":"","id":"ss"},"signContents2":{"val":"","id":"ss"},"signContents0":{"val":"","id":"ss"},"meta":{"val":"5","id":"pi"},"signContents3":{"val":"","id":"ss"},"buildPass":{"val":"2","id":"pi"}},"id":"ct"}}
:enddata
:endrule

rule:
plugin=vanillaBlocks
number=49
data:
JSON:{{"val":{"blockName":{"val":"minecraft:crafting_table","id":"ss"},"meta":{"val":"0","id":"pi"},"buildPass":{"val":"0","id":"pi"}},"id":"ct"}}
:enddata
:endrule

rule:
plugin=vanillaBlocks
number=50
data:
JSON:{{"val":{"blockName":{"val":"minecraft:bookshelf","id":"ss"},"meta":{"val":"0","id":"pi"},"buildPass":{"val":"0","id":"pi"}},"id":"ct"}}
:enddata
:endrule

rule:
plugin=vanillaBlocks
number=51
data:
JSON:{{"val":{"blockName":{"val":"minecraft:bed","id":"ss"},"meta":{"val":"3","id":"pi"},"buildPass":{"val":"2","id":"pi"}},"id":"ct"}}
:enddata
:endrule

rule:
plugin=vanillaBlocks
number=52
data:
JSON:{{"val":{"blockName":{"val":"minecraft:bed","id":"ss"},"meta":{"val":"11","id":"pi"},"buildPass":{"val":"2","id":"pi"}},"id":"ct"}}
:enddata
:endrule

rule:
plugin=vanillaBlocks
number=53
data:
JSON:{{"val":{"blockName":{"val":"minecraft:red_flower","id":"ss"},"meta":{"val":"0","id":"pi"},"buildPass":{"val":"2","id":"pi"}},"id":"ct"}}
:enddata
:endrule

rule:
plugin=vanillaDoors
number=54
data:
JSON:{{"val":{"sideFlag":{"val":"0","id":"pb"},"blockName":{"val":"minecraft:wooden_door","id":"ss"},"meta":{"val":"8","id":"pi"},"buildPass":{"val":"2","id":"pi"}},"id":"ct"}}
:enddata
:endrule

rule:
plugin=vanillaDoors
number=55
data:
JSON:{{"val":{"sideFlag":{"val":"0","id":"pb"},"blockName":{"val":"minecraft:wooden_door","id":"ss"},"meta":{"val":"8","id":"pi"},"buildPass":{"val":"2","id":"pi"}},"id":"ct"}}
:enddata
:endrule

rule:
plugin=vanillaBlocks
number=56
data:
JSON:{{"val":{"blockName":{"val":"minecraft:dark_oak_stairs","id":"ss"},"meta":{"val":"4","id":"pi"},"buildPass":{"val":"0","id":"pi"}},"id":"ct"}}
:enddata
:endrule

rule:
plugin=vanillaBlocks
number=57
data:
JSON:{{"val":{"blockName":{"val":"minecraft:dark_oak_stairs","id":"ss"},"meta":{"val":"7","id":"pi"},"buildPass":{"val":"0","id":"pi"}},"id":"ct"}}
:enddata
:endrule

rule:
plugin=vanillaBlocks
number=58
data:
JSON:{{"val":{"blockName":{"val":"minecraft:dark_oak_stairs","id":"ss"},"meta":{"val":"6","id":"pi"},"buildPass":{"val":"0","id":"pi"}},"id":"ct"}}
:enddata
:endrule

rule:
plugin=vanillaBlocks
number=59
data:
JSON:{{"val":{"blockName":{"val":"minecraft:dark_oak_stairs","id":"ss"},"meta":{"val":"5","id":"pi"},"buildPass":{"val":"0","id":"pi"}},"id":"ct"}}
:enddata
:endrule

rule:
plugin=vanillaBlocks
number=60
data:
JSON:{{"val":{"blockName":{"val":"minecraft:planks","id":"ss"},"meta":{"val":"5","id":"pi"},"buildPass":{"val":"0","id":"pi"}},"id":"ct"}}
:enddata
:endrule

rule:
plugin=vanillaBlocks
number=61
data:
JSON:{{"val":{"blockName":{"val":"minecraft:stone_button","id":"ss"},"meta":{"val":"4","id":"pi"},"buildPass":{"val":"2","id":"pi"}},"id":"ct"}}
:enddata
:endrule

rule:
plugin=vanillaBlocks
number=62
data:
JSON:{{"val":{"blockName":{"val":"minecraft:dark_oak_stairs","id":"ss"},"meta":{"val":"0","id":"pi"},"buildPass":{"val":"0","id":"pi"}},"id":"ct"}}
:enddata
:endrule

rule:
plugin=vanillaBlocks
number=63
data:
JSON:{{"val":{"blockName":{"val":"minecraft:fence_gate","id":"ss"},"meta":{"val":"0","id":"pi"},"buildPass":{"val":"0","id":"pi"}},"id":"ct"}}
:enddata
:endrule

#### ENTITIES ####
entity:
plugin=AWNpc
number=0
data:
position=5,9,14
JSON:{{"val":{"entityData":{"val":{"DropChances":{"val":[{"val":"1.0","id":"pf"},{"val":"1.0","id":"pf"},{"val":"1.0","id":"pf"},{"val":"1.0","id":"pf"},{"val":"1.0","id":"pf"}],"id":"ls"},"Attributes":{"val":[{"val":{"Name":{"val":"generic.maxHealth","id":"ss"},"Base":{"val":"20.0","id":"pd"}},"id":"ct"},{"val":{"Name":{"val":"generic.knockbackResistance","id":"ss"},"Base":{"val":"0.0","id":"pd"}},"id":"ct"},{"val":{"Name":{"val":"generic.movementSpeed","id":"ss"},"Base":{"val":"0.325","id":"pd"}},"id":"ct"},{"val":{"Name":{"val":"generic.followRange","id":"ss"},"Base":{"val":"60.0","id":"pd"}},"id":"ct"},{"val":{"Name":{"val":"generic.attackDamage","id":"ss"},"Base":{"val":"2.0","id":"pd"}},"id":"ct"}],"id":"ls"},"Motion":{"val":[{"val":"0.0","id":"pd"},{"val":"-0.0784000015258789","id":"pd"},{"val":"0.0","id":"pd"}],"id":"ls"},"CustomName":{"val":"","id":"ss"},"Health":{"val":"20","id":"ps"},"HealF":{"val":"20.0","id":"pf"},"CustomNameVisible":{"val":"0","id":"pb"},"ordersStack":{"val":{"item":{"val":"minecraft:arrow","id":"ss"},"damage":{"val":"0","id":"pi"},"quantity":{"val":"1","id":"pi"}},"id":"ct"},"AttackTime":{"val":"0","id":"ps"},"upkeepStack":{"val":{"item":{"val":"minecraft:arrow","id":"ss"},"damage":{"val":"0","id":"pi"},"quantity":{"val":"1","id":"pi"}},"id":"ct"},"Fire":{"val":"-1","id":"ps"},"attackDamageOverride":{"val":"-1","id":"pi"},"Invulnerable":{"val":"0","id":"pb"},"DeathTime":{"val":"0","id":"ps"},"ForgeData":{"val":{"WITCInitialWidth":{"val":"0.6","id":"pf"},"WITCInitialHeight":{"val":"1.8","id":"pf"}},"id":"ct"},"AbsorptionAmount":{"val":"0.0","id":"pf"},"OnGround":{"val":"1","id":"pb"},"HurtTime":{"val":"0","id":"ps"},"Dimension":{"val":"0","id":"pi"},"Air":{"val":"300","id":"ps"},"customTex":{"val":"","id":"ss"},"armorValueOverride":{"val":"-1","id":"pi"},"Pos":{"val":[{"val":"1322.5","id":"pd"},{"val":"95.0","id":"pd"},{"val":"1871.5","id":"pd"}],"id":"ls"},"CanPickUpLoot":{"val":"0","id":"pb"},"PortalCooldown":{"val":"0","id":"pi"},"PersistenceRequired":{"val":"1","id":"pb"},"Leashed":{"val":"0","id":"pb"},"owner":{"val":"OldMiniCollector","id":"ss"},"FallDistance":{"val":"0.0","id":"pf"},"Rotation":{"val":[{"val":"1.2528841","id":"pf"},{"val":"0.0","id":"pf"}],"id":"ls"},"levelingStats":{"val":{"level":{"val":"0","id":"pi"},"xp":{"val":"0","id":"pi"},"entryList":{"val":[],"id":"ls"}},"id":"ct"}},"id":"ct"},"xOffset":{"val":"0.5","id":"pf"},"mobID":{"val":"AncientWarfareNpc.viking.archer","id":"ss"},"zOffset":{"val":"0.5","id":"pf"},"rotation":{"val":"271.2529","id":"pf"},"equipmentData":{"val":{"equipmentContents":{"val":[{"val":{"item":{"val":"minecraft:bow","id":"ss"},"damage":{"val":"0","id":"pi"},"quantity":{"val":"1","id":"pi"},"slot":{"val":"0","id":"pi"}},"id":"ct"}],"id":"ls"},"length":{"val":"5","id":"pi"}},"id":"ct"}},"id":"ct"}}
:enddata
:endentity

entity:
plugin=AWNpc
number=1
data:
position=14,4,11
JSON:{{"val":{"entityData":{"val":{"DropChances":{"val":[{"val":"1.0","id":"pf"},{"val":"1.0","id":"pf"},{"val":"1.0","id":"pf"},{"val":"1.0","id":"pf"},{"val":"1.0","id":"pf"}],"id":"ls"},"Attributes":{"val":[{"val":{"Name":{"val":"generic.maxHealth","id":"ss"},"Base":{"val":"20.0","id":"pd"}},"id":"ct"},{"val":{"Name":{"val":"generic.knockbackResistance","id":"ss"},"Base":{"val":"0.0","id":"pd"}},"id":"ct"},{"val":{"Name":{"val":"generic.movementSpeed","id":"ss"},"Base":{"val":"0.325","id":"pd"}},"id":"ct"},{"val":{"Name":{"val":"generic.followRange","id":"ss"},"Base":{"val":"60.0","id":"pd"}},"id":"ct"},{"val":{"Name":{"val":"generic.attackDamage","id":"ss"},"Base":{"val":"2.0","id":"pd"}},"id":"ct"}],"id":"ls"},"Motion":{"val":[{"val":"0.0","id":"pd"},{"val":"-0.0784000015258789","id":"pd"},{"val":"0.0","id":"pd"}],"id":"ls"},"CustomName":{"val":"","id":"ss"},"Health":{"val":"20","id":"ps"},"HealF":{"val":"20.0","id":"pf"},"CustomNameVisible":{"val":"0","id":"pb"},"ordersStack":{"val":{"item":{"val":"minecraft:arrow","id":"ss"},"damage":{"val":"0","id":"pi"},"quantity":{"val":"1","id":"pi"}},"id":"ct"},"AttackTime":{"val":"0","id":"ps"},"upkeepStack":{"val":{"item":{"val":"minecraft:arrow","id":"ss"},"damage":{"val":"0","id":"pi"},"quantity":{"val":"1","id":"pi"}},"id":"ct"},"Fire":{"val":"-1","id":"ps"},"attackDamageOverride":{"val":"-1","id":"pi"},"Invulnerable":{"val":"0","id":"pb"},"DeathTime":{"val":"0","id":"ps"},"ForgeData":{"val":{"WITCInitialWidth":{"val":"0.6","id":"pf"},"WITCInitialHeight":{"val":"1.8","id":"pf"}},"id":"ct"},"AbsorptionAmount":{"val":"0.0","id":"pf"},"OnGround":{"val":"1","id":"pb"},"HurtTime":{"val":"0","id":"ps"},"Dimension":{"val":"0","id":"pi"},"Air":{"val":"300","id":"ps"},"customTex":{"val":"","id":"ss"},"armorValueOverride":{"val":"-1","id":"pi"},"Pos":{"val":[{"val":"1325.7886434109928","id":"pd"},{"val":"90.0","id":"pd"},{"val":"1880.6488220251565","id":"pd"}],"id":"ls"},"CanPickUpLoot":{"val":"0","id":"pb"},"PortalCooldown":{"val":"0","id":"pi"},"PersistenceRequired":{"val":"1","id":"pb"},"Leashed":{"val":"0","id":"pb"},"owner":{"val":"OldMiniCollector","id":"ss"},"FallDistance":{"val":"0.0","id":"pf"},"Rotation":{"val":[{"val":"1.349502","id":"pf"},{"val":"0.0","id":"pf"}],"id":"ls"},"levelingStats":{"val":{"level":{"val":"0","id":"pi"},"xp":{"val":"0","id":"pi"},"entryList":{"val":[],"id":"ls"}},"id":"ct"}},"id":"ct"},"xOffset":{"val":"0.648822","id":"pf"},"mobID":{"val":"AncientWarfareNpc.viking.archer","id":"ss"},"zOffset":{"val":"0.21135658","id":"pf"},"rotation":{"val":"271.3495","id":"pf"},"equipmentData":{"val":{"equipmentContents":{"val":[{"val":{"item":{"val":"minecraft:bow","id":"ss"},"damage":{"val":"0","id":"pi"},"quantity":{"val":"1","id":"pi"},"slot":{"val":"0","id":"pi"}},"id":"ct"}],"id":"ls"},"length":{"val":"5","id":"pi"}},"id":"ct"}},"id":"ct"}}
:enddata
:endentity

entity:
plugin=AWNpc
number=2
data:
position=12,4,11
JSON:{{"val":{"entityData":{"val":{"DropChances":{"val":[{"val":"1.0","id":"pf"},{"val":"1.0","id":"pf"},{"val":"1.0","id":"pf"},{"val":"1.0","id":"pf"},{"val":"1.0","id":"pf"}],"id":"ls"},"Attributes":{"val":[{"val":{"Name":{"val":"generic.maxHealth","id":"ss"},"Base":{"val":"20.0","id":"pd"}},"id":"ct"},{"val":{"Name":{"val":"generic.knockbackResistance","id":"ss"},"Base":{"val":"0.0","id":"pd"}},"id":"ct"},{"val":{"Name":{"val":"generic.movementSpeed","id":"ss"},"Base":{"val":"0.325","id":"pd"}},"id":"ct"},{"val":{"Name":{"val":"generic.followRange","id":"ss"},"Base":{"val":"60.0","id":"pd"}},"id":"ct"},{"val":{"Name":{"val":"generic.attackDamage","id":"ss"},"Base":{"val":"2.0","id":"pd"}},"id":"ct"}],"id":"ls"},"Motion":{"val":[{"val":"0.0","id":"pd"},{"val":"-0.0784000015258789","id":"pd"},{"val":"0.0","id":"pd"}],"id":"ls"},"CustomName":{"val":"","id":"ss"},"Health":{"val":"20","id":"ps"},"HealF":{"val":"20.0","id":"pf"},"CustomNameVisible":{"val":"0","id":"pb"},"ordersStack":{"val":{"item":{"val":"minecraft:arrow","id":"ss"},"damage":{"val":"0","id":"pi"},"quantity":{"val":"1","id":"pi"}},"id":"ct"},"AttackTime":{"val":"0","id":"ps"},"upkeepStack":{"val":{"item":{"val":"minecraft:arrow","id":"ss"},"damage":{"val":"0","id":"pi"},"quantity":{"val":"1","id":"pi"}},"id":"ct"},"Fire":{"val":"-1","id":"ps"},"attackDamageOverride":{"val":"-1","id":"pi"},"Invulnerable":{"val":"0","id":"pb"},"DeathTime":{"val":"0","id":"ps"},"ForgeData":{"val":{"WITCInitialWidth":{"val":"0.6","id":"pf"},"WITCInitialHeight":{"val":"1.8","id":"pf"}},"id":"ct"},"AbsorptionAmount":{"val":"0.0","id":"pf"},"OnGround":{"val":"1","id":"pb"},"HurtTime":{"val":"0","id":"ps"},"Dimension":{"val":"0","id":"pi"},"Air":{"val":"300","id":"ps"},"customTex":{"val":"","id":"ss"},"armorValueOverride":{"val":"-1","id":"pi"},"Pos":{"val":[{"val":"1325.5751294592608","id":"pd"},{"val":"90.0","id":"pd"},{"val":"1878.04033585624","id":"pd"}],"id":"ls"},"CanPickUpLoot":{"val":"0","id":"pb"},"PortalCooldown":{"val":"0","id":"pi"},"PersistenceRequired":{"val":"1","id":"pb"},"Leashed":{"val":"0","id":"pb"},"owner":{"val":"OldMiniCollector","id":"ss"},"FallDistance":{"val":"0.0","id":"pf"},"Rotation":{"val":[{"val":"5.3905997","id":"pf"},{"val":"0.0","id":"pf"}],"id":"ls"},"levelingStats":{"val":{"level":{"val":"0","id":"pi"},"xp":{"val":"0","id":"pi"},"entryList":{"val":[],"id":"ls"}},"id":"ct"}},"id":"ct"},"xOffset":{"val":"0.040335834","id":"pf"},"mobID":{"val":"AncientWarfareNpc.viking.archer","id":"ss"},"zOffset":{"val":"0.42487055","id":"pf"},"rotation":{"val":"275.3906","id":"pf"},"equipmentData":{"val":{"equipmentContents":{"val":[{"val":{"item":{"val":"minecraft:bow","id":"ss"},"damage":{"val":"0","id":"pi"},"quantity":{"val":"1","id":"pi"},"slot":{"val":"0","id":"pi"}},"id":"ct"}],"id":"ls"},"length":{"val":"5","id":"pi"}},"id":"ct"}},"id":"ct"}}
:enddata
:endentity

entity:
plugin=AWNpc
number=3
data:
position=14,4,13
JSON:{{"val":{"entityData":{"val":{"DropChances":{"val":[{"val":"1.0","id":"pf"},{"val":"1.0","id":"pf"},{"val":"1.0","id":"pf"},{"val":"1.0","id":"pf"},{"val":"1.0","id":"pf"}],"id":"ls"},"Attributes":{"val":[{"val":{"Name":{"val":"generic.maxHealth","id":"ss"},"Base":{"val":"20.0","id":"pd"}},"id":"ct"},{"val":{"Name":{"val":"generic.knockbackResistance","id":"ss"},"Base":{"val":"0.0","id":"pd"}},"id":"ct"},{"val":{"Name":{"val":"generic.movementSpeed","id":"ss"},"Base":{"val":"0.325","id":"pd"}},"id":"ct"},{"val":{"Name":{"val":"generic.followRange","id":"ss"},"Base":{"val":"60.0","id":"pd"}},"id":"ct"},{"val":{"Name":{"val":"generic.attackDamage","id":"ss"},"Base":{"val":"2.0","id":"pd"}},"id":"ct"}],"id":"ls"},"Motion":{"val":[{"val":"0.0","id":"pd"},{"val":"-0.0784000015258789","id":"pd"},{"val":"0.0","id":"pd"}],"id":"ls"},"CustomName":{"val":"","id":"ss"},"Health":{"val":"20","id":"ps"},"HealF":{"val":"20.0","id":"pf"},"CustomNameVisible":{"val":"0","id":"pb"},"ordersStack":{"val":{"item":{"val":"minecraft:arrow","id":"ss"},"damage":{"val":"0","id":"pi"},"quantity":{"val":"1","id":"pi"}},"id":"ct"},"AttackTime":{"val":"0","id":"ps"},"upkeepStack":{"val":{"item":{"val":"minecraft:arrow","id":"ss"},"damage":{"val":"0","id":"pi"},"quantity":{"val":"1","id":"pi"}},"id":"ct"},"Fire":{"val":"-1","id":"ps"},"attackDamageOverride":{"val":"-1","id":"pi"},"Invulnerable":{"val":"0","id":"pb"},"DeathTime":{"val":"0","id":"ps"},"ForgeData":{"val":{"WITCInitialWidth":{"val":"0.6","id":"pf"},"WITCInitialHeight":{"val":"1.8","id":"pf"}},"id":"ct"},"AbsorptionAmount":{"val":"0.0","id":"pf"},"OnGround":{"val":"1","id":"pb"},"HurtTime":{"val":"0","id":"ps"},"Dimension":{"val":"0","id":"pi"},"Air":{"val":"300","id":"ps"},"customTex":{"val":"","id":"ss"},"armorValueOverride":{"val":"-1","id":"pi"},"Pos":{"val":[{"val":"1323.674249326925","id":"pd"},{"val":"90.125","id":"pd"},{"val":"1880.053262291736","id":"pd"}],"id":"ls"},"CanPickUpLoot":{"val":"0","id":"pb"},"PortalCooldown":{"val":"0","id":"pi"},"PersistenceRequired":{"val":"1","id":"pb"},"Leashed":{"val":"0","id":"pb"},"owner":{"val":"OldMiniCollector","id":"ss"},"FallDistance":{"val":"0.0","id":"pf"},"Rotation":{"val":[{"val":"5.598785","id":"pf"},{"val":"0.0","id":"pf"}],"id":"ls"},"levelingStats":{"val":{"level":{"val":"0","id":"pi"},"xp":{"val":"0","id":"pi"},"entryList":{"val":[],"id":"ls"}},"id":"ct"}},"id":"ct"},"xOffset":{"val":"0.053262293","id":"pf"},"mobID":{"val":"AncientWarfareNpc.viking.archer","id":"ss"},"zOffset":{"val":"0.32575065","id":"pf"},"rotation":{"val":"275.5988","id":"pf"},"equipmentData":{"val":{"equipmentContents":{"val":[{"val":{"item":{"val":"minecraft:bow","id":"ss"},"damage":{"val":"0","id":"pi"},"quantity":{"val":"1","id":"pi"},"slot":{"val":"0","id":"pi"}},"id":"ct"}],"id":"ls"},"length":{"val":"5","id":"pi"}},"id":"ct"}},"id":"ct"}}
:enddata
:endentity

entity:
plugin=AWNpc
number=4
data:
position=10,4,12
JSON:{{"val":{"entityData":{"val":{"DropChances":{"val":[{"val":"1.0","id":"pf"},{"val":"1.0","id":"pf"},{"val":"1.0","id":"pf"},{"val":"1.0","id":"pf"},{"val":"1.0","id":"pf"}],"id":"ls"},"Attributes":{"val":[{"val":{"Name":{"val":"generic.maxHealth","id":"ss"},"Base":{"val":"20.0","id":"pd"}},"id":"ct"},{"val":{"Name":{"val":"generic.knockbackResistance","id":"ss"},"Base":{"val":"0.0","id":"pd"}},"id":"ct"},{"val":{"Name":{"val":"generic.movementSpeed","id":"ss"},"Base":{"val":"0.325","id":"pd"}},"id":"ct"},{"val":{"Name":{"val":"generic.followRange","id":"ss"},"Base":{"val":"60.0","id":"pd"}},"id":"ct"},{"val":{"Name":{"val":"generic.attackDamage","id":"ss"},"Base":{"val":"2.0","id":"pd"}},"id":"ct"}],"id":"ls"},"Motion":{"val":[{"val":"0.0","id":"pd"},{"val":"-0.0784000015258789","id":"pd"},{"val":"0.0","id":"pd"}],"id":"ls"},"CustomName":{"val":"","id":"ss"},"Health":{"val":"20","id":"ps"},"HealF":{"val":"20.0","id":"pf"},"CustomNameVisible":{"val":"0","id":"pb"},"ordersStack":{"val":{"item":{"val":"minecraft:arrow","id":"ss"},"damage":{"val":"0","id":"pi"},"quantity":{"val":"1","id":"pi"}},"id":"ct"},"AttackTime":{"val":"0","id":"ps"},"upkeepStack":{"val":{"item":{"val":"minecraft:arrow","id":"ss"},"damage":{"val":"0","id":"pi"},"quantity":{"val":"1","id":"pi"}},"id":"ct"},"Fire":{"val":"-1","id":"ps"},"attackDamageOverride":{"val":"-1","id":"pi"},"Invulnerable":{"val":"0","id":"pb"},"DeathTime":{"val":"0","id":"ps"},"ForgeData":{"val":{"WITCInitialWidth":{"val":"0.6","id":"pf"},"WITCInitialHeight":{"val":"1.8","id":"pf"}},"id":"ct"},"AbsorptionAmount":{"val":"0.0","id":"pf"},"OnGround":{"val":"1","id":"pb"},"HurtTime":{"val":"0","id":"ps"},"Dimension":{"val":"0","id":"pi"},"Air":{"val":"300","id":"ps"},"customTex":{"val":"","id":"ss"},"armorValueOverride":{"val":"-1","id":"pi"},"Pos":{"val":[{"val":"1324.5","id":"pd"},{"val":"90.0","id":"pd"},{"val":"1876.5","id":"pd"}],"id":"ls"},"CanPickUpLoot":{"val":"0","id":"pb"},"PortalCooldown":{"val":"0","id":"pi"},"PersistenceRequired":{"val":"1","id":"pb"},"Leashed":{"val":"0","id":"pb"},"owner":{"val":"OldMiniCollector","id":"ss"},"FallDistance":{"val":"0.0","id":"pf"},"Rotation":{"val":[{"val":"0.029526297","id":"pf"},{"val":"0.0","id":"pf"}],"id":"ls"},"levelingStats":{"val":{"level":{"val":"0","id":"pi"},"xp":{"val":"0","id":"pi"},"entryList":{"val":[],"id":"ls"}},"id":"ct"}},"id":"ct"},"xOffset":{"val":"0.5","id":"pf"},"mobID":{"val":"AncientWarfareNpc.viking.archer","id":"ss"},"zOffset":{"val":"0.5","id":"pf"},"rotation":{"val":"270.02954","id":"pf"},"equipmentData":{"val":{"equipmentContents":{"val":[{"val":{"item":{"val":"minecraft:bow","id":"ss"},"damage":{"val":"0","id":"pi"},"quantity":{"val":"1","id":"pi"},"slot":{"val":"0","id":"pi"}},"id":"ct"}],"id":"ls"},"length":{"val":"5","id":"pi"}},"id":"ct"}},"id":"ct"}}
:enddata
:endentity

entity:
plugin=AWNpc
number=5
data:
position=4,14,6
JSON:{{"val":{"entityData":{"val":{"DropChances":{"val":[{"val":"1.0","id":"pf"},{"val":"1.0","id":"pf"},{"val":"1.0","id":"pf"},{"val":"1.0","id":"pf"},{"val":"1.0","id":"pf"}],"id":"ls"},"Attributes":{"val":[{"val":{"Name":{"val":"generic.maxHealth","id":"ss"},"Base":{"val":"20.0","id":"pd"}},"id":"ct"},{"val":{"Name":{"val":"generic.knockbackResistance","id":"ss"},"Base":{"val":"0.0","id":"pd"}},"id":"ct"},{"val":{"Name":{"val":"generic.movementSpeed","id":"ss"},"Base":{"val":"0.325","id":"pd"}},"id":"ct"},{"val":{"Name":{"val":"generic.followRange","id":"ss"},"Base":{"val":"60.0","id":"pd"}},"id":"ct"},{"val":{"Name":{"val":"generic.attackDamage","id":"ss"},"Base":{"val":"2.0","id":"pd"}},"id":"ct"}],"id":"ls"},"Motion":{"val":[{"val":"0.0","id":"pd"},{"val":"-0.0784000015258789","id":"pd"},{"val":"0.0","id":"pd"}],"id":"ls"},"CustomName":{"val":"","id":"ss"},"Health":{"val":"20","id":"ps"},"HealF":{"val":"20.0","id":"pf"},"CustomNameVisible":{"val":"0","id":"pb"},"ordersStack":{"val":{"item":{"val":"minecraft:arrow","id":"ss"},"damage":{"val":"0","id":"pi"},"quantity":{"val":"1","id":"pi"}},"id":"ct"},"AttackTime":{"val":"0","id":"ps"},"upkeepStack":{"val":{"item":{"val":"minecraft:arrow","id":"ss"},"damage":{"val":"0","id":"pi"},"quantity":{"val":"1","id":"pi"}},"id":"ct"},"Fire":{"val":"-1","id":"ps"},"attackDamageOverride":{"val":"-1","id":"pi"},"Invulnerable":{"val":"0","id":"pb"},"DeathTime":{"val":"0","id":"ps"},"ForgeData":{"val":{"WITCInitialWidth":{"val":"0.6","id":"pf"},"WITCInitialHeight":{"val":"1.8","id":"pf"}},"id":"ct"},"AbsorptionAmount":{"val":"0.0","id":"pf"},"OnGround":{"val":"1","id":"pb"},"HurtTime":{"val":"0","id":"ps"},"Dimension":{"val":"0","id":"pi"},"Air":{"val":"300","id":"ps"},"customTex":{"val":"","id":"ss"},"armorValueOverride":{"val":"-1","id":"pi"},"Pos":{"val":[{"val":"1330.6756858763963","id":"pd"},{"val":"100.0","id":"pd"},{"val":"1870.315417820858","id":"pd"}],"id":"ls"},"CanPickUpLoot":{"val":"0","id":"pb"},"PortalCooldown":{"val":"0","id":"pi"},"PersistenceRequired":{"val":"1","id":"pb"},"Leashed":{"val":"0","id":"pb"},"owner":{"val":"OldMiniCollector","id":"ss"},"FallDistance":{"val":"0.0","id":"pf"},"Rotation":{"val":[{"val":"4.8879504","id":"pf"},{"val":"0.0","id":"pf"}],"id":"ls"},"levelingStats":{"val":{"level":{"val":"0","id":"pi"},"xp":{"val":"0","id":"pi"},"entryList":{"val":[],"id":"ls"}},"id":"ct"}},"id":"ct"},"xOffset":{"val":"0.31541783","id":"pf"},"mobID":{"val":"AncientWarfareNpc.viking.archer","id":"ss"},"zOffset":{"val":"0.32431412","id":"pf"},"rotation":{"val":"274.88794","id":"pf"},"equipmentData":{"val":{"equipmentContents":{"val":[{"val":{"item":{"val":"minecraft:bow","id":"ss"},"damage":{"val":"0","id":"pi"},"quantity":{"val":"1","id":"pi"},"slot":{"val":"0","id":"pi"}},"id":"ct"}],"id":"ls"},"length":{"val":"5","id":"pi"}},"id":"ct"}},"id":"ct"}}
:enddata
:endentity

entity:
plugin=AWNpc
number=6
data:
position=5,14,4
JSON:{{"val":{"entityData":{"val":{"DropChances":{"val":[{"val":"1.0","id":"pf"},{"val":"1.0","id":"pf"},{"val":"1.0","id":"pf"},{"val":"1.0","id":"pf"},{"val":"1.0","id":"pf"}],"id":"ls"},"Attributes":{"val":[{"val":{"Name":{"val":"generic.maxHealth","id":"ss"},"Base":{"val":"20.0","id":"pd"}},"id":"ct"},{"val":{"Name":{"val":"generic.knockbackResistance","id":"ss"},"Base":{"val":"0.0","id":"pd"}},"id":"ct"},{"val":{"Name":{"val":"generic.movementSpeed","id":"ss"},"Base":{"val":"0.325","id":"pd"}},"id":"ct"},{"val":{"Name":{"val":"generic.followRange","id":"ss"},"Base":{"val":"60.0","id":"pd"}},"id":"ct"},{"val":{"Name":{"val":"generic.attackDamage","id":"ss"},"Base":{"val":"2.0","id":"pd"}},"id":"ct"}],"id":"ls"},"Motion":{"val":[{"val":"0.0","id":"pd"},{"val":"-0.0784000015258789","id":"pd"},{"val":"0.0","id":"pd"}],"id":"ls"},"CustomName":{"val":"","id":"ss"},"Health":{"val":"20","id":"ps"},"HealF":{"val":"20.0","id":"pf"},"CustomNameVisible":{"val":"0","id":"pb"},"ordersStack":{"val":{"item":{"val":"minecraft:arrow","id":"ss"},"damage":{"val":"0","id":"pi"},"quantity":{"val":"1","id":"pi"}},"id":"ct"},"AttackTime":{"val":"0","id":"ps"},"upkeepStack":{"val":{"item":{"val":"minecraft:arrow","id":"ss"},"damage":{"val":"0","id":"pi"},"quantity":{"val":"1","id":"pi"}},"id":"ct"},"Fire":{"val":"-1","id":"ps"},"attackDamageOverride":{"val":"-1","id":"pi"},"Invulnerable":{"val":"0","id":"pb"},"DeathTime":{"val":"0","id":"ps"},"ForgeData":{"val":{"WITCInitialWidth":{"val":"0.6","id":"pf"},"WITCInitialHeight":{"val":"1.8","id":"pf"}},"id":"ct"},"AbsorptionAmount":{"val":"0.0","id":"pf"},"OnGround":{"val":"1","id":"pb"},"HurtTime":{"val":"0","id":"ps"},"Dimension":{"val":"0","id":"pi"},"Air":{"val":"300","id":"ps"},"customTex":{"val":"","id":"ss"},"armorValueOverride":{"val":"-1","id":"pi"},"Pos":{"val":[{"val":"1332.5","id":"pd"},{"val":"100.0","id":"pd"},{"val":"1871.5","id":"pd"}],"id":"ls"},"CanPickUpLoot":{"val":"0","id":"pb"},"PortalCooldown":{"val":"0","id":"pi"},"PersistenceRequired":{"val":"1","id":"pb"},"Leashed":{"val":"0","id":"pb"},"owner":{"val":"OldMiniCollector","id":"ss"},"FallDistance":{"val":"0.0","id":"pf"},"Rotation":{"val":[{"val":"1.6865351","id":"pf"},{"val":"0.0","id":"pf"}],"id":"ls"},"levelingStats":{"val":{"level":{"val":"0","id":"pi"},"xp":{"val":"0","id":"pi"},"entryList":{"val":[],"id":"ls"}},"id":"ct"}},"id":"ct"},"xOffset":{"val":"0.5","id":"pf"},"mobID":{"val":"AncientWarfareNpc.viking.archer","id":"ss"},"zOffset":{"val":"0.5","id":"pf"},"rotation":{"val":"271.68652","id":"pf"},"equipmentData":{"val":{"equipmentContents":{"val":[{"val":{"item":{"val":"minecraft:bow","id":"ss"},"damage":{"val":"0","id":"pi"},"quantity":{"val":"1","id":"pi"},"slot":{"val":"0","id":"pi"}},"id":"ct"}],"id":"ls"},"length":{"val":"5","id":"pi"}},"id":"ct"}},"id":"ct"}}
:enddata
:endentity

entity:
plugin=AWNpc
number=7
data:
position=6,14,6
JSON:{{"val":{"entityData":{"val":{"DropChances":{"val":[{"val":"1.0","id":"pf"},{"val":"1.0","id":"pf"},{"val":"1.0","id":"pf"},{"val":"1.0","id":"pf"},{"val":"1.0","id":"pf"}],"id":"ls"},"Attributes":{"val":[{"val":{"Name":{"val":"generic.maxHealth","id":"ss"},"Base":{"val":"20.0","id":"pd"}},"id":"ct"},{"val":{"Name":{"val":"generic.knockbackResistance","id":"ss"},"Base":{"val":"0.0","id":"pd"}},"id":"ct"},{"val":{"Name":{"val":"generic.movementSpeed","id":"ss"},"Base":{"val":"0.325","id":"pd"}},"id":"ct"},{"val":{"Name":{"val":"generic.followRange","id":"ss"},"Base":{"val":"60.0","id":"pd"}},"id":"ct"},{"val":{"Name":{"val":"generic.attackDamage","id":"ss"},"Base":{"val":"2.0","id":"pd"}},"id":"ct"}],"id":"ls"},"Motion":{"val":[{"val":"0.0","id":"pd"},{"val":"-0.0784000015258789","id":"pd"},{"val":"0.0","id":"pd"}],"id":"ls"},"CustomName":{"val":"","id":"ss"},"Health":{"val":"20","id":"ps"},"HealF":{"val":"20.0","id":"pf"},"CustomNameVisible":{"val":"0","id":"pb"},"ordersStack":{"val":{"item":{"val":"minecraft:arrow","id":"ss"},"damage":{"val":"0","id":"pi"},"quantity":{"val":"1","id":"pi"}},"id":"ct"},"AttackTime":{"val":"0","id":"ps"},"upkeepStack":{"val":{"item":{"val":"minecraft:arrow","id":"ss"},"damage":{"val":"0","id":"pi"},"quantity":{"val":"1","id":"pi"}},"id":"ct"},"Fire":{"val":"-1","id":"ps"},"attackDamageOverride":{"val":"-1","id":"pi"},"Invulnerable":{"val":"0","id":"pb"},"DeathTime":{"val":"0","id":"ps"},"ForgeData":{"val":{"WITCInitialWidth":{"val":"0.6","id":"pf"},"WITCInitialHeight":{"val":"1.8","id":"pf"}},"id":"ct"},"AbsorptionAmount":{"val":"0.0","id":"pf"},"OnGround":{"val":"1","id":"pb"},"HurtTime":{"val":"0","id":"ps"},"Dimension":{"val":"0","id":"pi"},"Air":{"val":"300","id":"ps"},"customTex":{"val":"","id":"ss"},"armorValueOverride":{"val":"-1","id":"pi"},"Pos":{"val":[{"val":"1330.5","id":"pd"},{"val":"100.0","id":"pd"},{"val":"1872.5","id":"pd"}],"id":"ls"},"CanPickUpLoot":{"val":"0","id":"pb"},"PortalCooldown":{"val":"0","id":"pi"},"PersistenceRequired":{"val":"1","id":"pb"},"Leashed":{"val":"0","id":"pb"},"owner":{"val":"OldMiniCollector","id":"ss"},"FallDistance":{"val":"0.0","id":"pf"},"Rotation":{"val":[{"val":"3.6358814","id":"pf"},{"val":"0.0","id":"pf"}],"id":"ls"},"levelingStats":{"val":{"level":{"val":"0","id":"pi"},"xp":{"val":"0","id":"pi"},"entryList":{"val":[],"id":"ls"}},"id":"ct"}},"id":"ct"},"xOffset":{"val":"0.5","id":"pf"},"mobID":{"val":"AncientWarfareNpc.viking.archer","id":"ss"},"zOffset":{"val":"0.5","id":"pf"},"rotation":{"val":"273.6359","id":"pf"},"equipmentData":{"val":{"equipmentContents":{"val":[{"val":{"item":{"val":"minecraft:bow","id":"ss"},"damage":{"val":"0","id":"pi"},"quantity":{"val":"1","id":"pi"},"slot":{"val":"0","id":"pi"}},"id":"ct"}],"id":"ls"},"length":{"val":"5","id":"pi"}},"id":"ct"}},"id":"ct"}}
:enddata
:endentity

entity:
plugin=AWNpc
number=8
data:
position=6,14,5
JSON:{{"val":{"entityData":{"val":{"DropChances":{"val":[{"val":"1.0","id":"pf"},{"val":"1.0","id":"pf"},{"val":"1.0","id":"pf"},{"val":"1.0","id":"pf"},{"val":"1.0","id":"pf"}],"id":"ls"},"Attributes":{"val":[{"val":{"Name":{"val":"generic.maxHealth","id":"ss"},"Base":{"val":"40.0","id":"pd"}},"id":"ct"},{"val":{"Name":{"val":"generic.knockbackResistance","id":"ss"},"Base":{"val":"0.0","id":"pd"}},"id":"ct"},{"val":{"Name":{"val":"generic.movementSpeed","id":"ss"},"Base":{"val":"0.325","id":"pd"}},"id":"ct"},{"val":{"Name":{"val":"generic.followRange","id":"ss"},"Base":{"val":"60.0","id":"pd"}},"id":"ct"},{"val":{"Name":{"val":"generic.attackDamage","id":"ss"},"Base":{"val":"2.0","id":"pd"}},"id":"ct"}],"id":"ls"},"Motion":{"val":[{"val":"0.0","id":"pd"},{"val":"-0.0784000015258789","id":"pd"},{"val":"0.0","id":"pd"}],"id":"ls"},"CustomName":{"val":"","id":"ss"},"Health":{"val":"40","id":"ps"},"HealF":{"val":"40.0","id":"pf"},"CustomNameVisible":{"val":"0","id":"pb"},"AttackTime":{"val":"0","id":"ps"},"Fire":{"val":"-1","id":"ps"},"attackDamageOverride":{"val":"-1","id":"pi"},"Invulnerable":{"val":"0","id":"pb"},"DeathTime":{"val":"0","id":"ps"},"ForgeData":{"val":{"WITCInitialWidth":{"val":"0.6","id":"pf"},"WITCInitialHeight":{"val":"1.8","id":"pf"}},"id":"ct"},"AbsorptionAmount":{"val":"0.0","id":"pf"},"OnGround":{"val":"1","id":"pb"},"HurtTime":{"val":"0","id":"ps"},"Dimension":{"val":"0","id":"pi"},"Air":{"val":"300","id":"ps"},"customTex":{"val":"","id":"ss"},"armorValueOverride":{"val":"-1","id":"pi"},"Pos":{"val":[{"val":"1331.5","id":"pd"},{"val":"100.0","id":"pd"},{"val":"1872.5","id":"pd"}],"id":"ls"},"CanPickUpLoot":{"val":"0","id":"pb"},"PortalCooldown":{"val":"0","id":"pi"},"PersistenceRequired":{"val":"1","id":"pb"},"shieldStack":{"val":{"item":{"val":"AncientWarfareNpc:iron_shield","id":"ss"},"damage":{"val":"0","id":"pi"},"quantity":{"val":"1","id":"pi"}},"id":"ct"},"Leashed":{"val":"0","id":"pb"},"owner":{"val":"OldMiniCollector","id":"ss"},"FallDistance":{"val":"0.0","id":"pf"},"Rotation":{"val":[{"val":"1.4174101","id":"pf"},{"val":"0.0","id":"pf"}],"id":"ls"},"levelingStats":{"val":{"level":{"val":"0","id":"pi"},"xp":{"val":"0","id":"pi"},"entryList":{"val":[],"id":"ls"}},"id":"ct"}},"id":"ct"},"xOffset":{"val":"0.5","id":"pf"},"mobID":{"val":"AncientWarfareNpc.viking.leader","id":"ss"},"zOffset":{"val":"0.5","id":"pf"},"rotation":{"val":"271.41742","id":"pf"},"equipmentData":{"val":{"equipmentContents":{"val":[{"val":{"item":{"val":"minecraft:diamond_axe","id":"ss"},"damage":{"val":"0","id":"pi"},"quantity":{"val":"1","id":"pi"},"slot":{"val":"0","id":"pi"}},"id":"ct"}],"id":"ls"},"length":{"val":"5","id":"pi"}},"id":"ct"}},"id":"ct"}}
:enddata
:endentity

