# Ancient Warfare Structure Template File
# Auto-generated structure template file. created on: 2/18/2015 at: 13:35:5
# Lines beginning with # denote comments

header:
version=2.1
name=Viking Beacon Tower
size=16,71,14
offset=8,7,12
:endheader

#### VALIDATION ####
validation:
type=ground
survival=false
worldGenEnabled=true
unique=false
preserveBlocks=false
selectionWeight=0
clusterValue=0
minDuplicateDistance=0
dimensionWhiteList=false
dimensionList=
biomeWhiteList=false
biomeList=taiga
leveling=0
fill=0
border=0
validTargetBlocks=
blockSwap=false
data:
:enddata
:endvalidation

#### LAYERS ####
layer: 0
1,1,1,1,1,1,1,1,1,1,1,1,1,1,1,1
1,1,1,1,1,1,1,1,1,1,1,1,1,1,1,1
1,1,1,1,1,1,1,1,1,1,1,1,1,1,1,1
1,1,1,1,1,1,1,1,1,1,1,1,1,1,1,1
1,1,1,1,1,1,1,1,1,1,1,1,1,1,1,1
1,1,1,1,1,1,1,1,1,1,1,1,1,1,1,1
1,1,1,1,1,1,1,1,1,1,1,1,1,1,1,1
1,1,1,1,1,1,1,1,1,1,1,1,1,1,1,1
1,1,1,1,1,1,1,1,1,1,1,1,1,1,1,1
1,1,1,1,1,1,1,1,1,1,1,1,1,1,1,1
1,1,1,1,1,1,1,1,1,1,1,1,1,1,1,1
1,1,1,1,1,1,1,1,1,1,1,1,1,1,1,1
1,1,1,1,1,1,1,1,1,1,1,1,1,1,1,1
1,1,1,1,1,1,1,1,1,1,1,1,1,1,1,1
:endlayer
layer: 1
1,1,1,1,1,1,1,1,1,1,1,1,1,1,1,1
1,1,1,1,1,1,1,1,1,1,1,1,1,1,1,1
1,1,1,1,1,1,1,1,1,1,1,1,1,1,1,1
1,1,1,1,1,1,1,1,1,1,1,1,1,1,1,1
1,1,1,1,1,1,1,1,1,1,1,1,1,1,1,1
1,1,1,1,1,1,1,1,1,1,1,1,1,1,1,1
1,1,1,1,1,1,1,1,1,1,1,1,1,1,1,1
1,1,1,1,1,1,1,1,1,1,1,1,1,1,1,1
1,1,1,1,1,1,1,1,1,1,1,1,1,1,1,1
1,1,1,1,1,1,1,1,1,1,1,1,1,1,1,1
1,1,1,1,1,1,1,1,1,1,1,1,1,1,1,1
1,1,1,1,1,1,1,1,1,1,1,1,1,1,1,1
1,1,1,1,1,1,1,1,1,1,1,1,1,1,1,1
1,1,1,1,1,1,1,1,1,1,1,1,1,1,1,1
:endlayer
layer: 2
1,1,1,1,1,1,1,1,1,1,1,1,1,1,1,1
1,1,1,1,1,1,1,1,1,1,1,1,1,1,1,1
1,1,1,1,1,1,1,1,1,1,1,1,1,1,1,1
1,1,1,1,1,1,1,1,1,1,1,1,1,1,1,1
1,1,1,1,1,1,1,1,1,1,1,1,1,1,1,1
1,1,1,1,1,1,1,1,1,1,1,1,1,1,1,1
1,1,1,1,1,1,1,1,1,1,1,1,1,1,1,1
1,1,1,1,1,1,1,1,1,1,1,1,1,1,1,1
1,1,1,1,1,1,1,1,1,1,1,1,1,1,1,1
1,1,1,1,1,1,1,1,1,1,1,1,1,1,1,1
1,1,1,1,1,1,1,1,1,1,1,1,1,1,1,1
1,1,1,1,1,1,1,1,1,1,1,1,1,1,1,1
1,1,1,1,1,1,1,1,1,1,1,1,1,1,1,1
1,1,1,1,1,1,1,1,1,1,1,1,1,1,1,1
:endlayer
layer: 3
1,1,1,1,1,1,1,1,1,1,1,1,1,1,1,1
1,1,1,1,1,1,1,1,1,1,1,1,1,1,1,1
1,1,1,1,1,1,1,1,1,1,1,1,1,1,1,1
1,1,1,1,1,1,1,1,1,1,1,1,1,1,1,1
1,1,1,1,1,1,1,1,1,1,1,1,1,1,1,1
1,1,1,1,1,1,1,1,1,1,1,1,1,1,1,1
1,1,1,1,1,1,1,1,1,1,1,1,1,1,1,1
1,1,1,1,1,1,1,1,1,1,1,1,1,1,1,1
1,1,1,1,1,1,1,1,1,1,1,1,1,1,1,1
1,1,1,1,1,1,1,1,1,1,1,1,1,1,1,1
1,1,1,1,1,1,1,1,1,1,1,1,1,1,1,1
1,1,1,1,1,1,1,1,1,1,1,1,1,1,1,1
1,1,1,1,1,1,1,1,1,1,1,1,1,1,1,1
1,1,1,1,1,1,1,1,1,1,1,1,1,1,1,1
:endlayer
layer: 4
1,1,1,1,1,1,1,1,1,1,1,1,1,1,1,1
1,1,1,1,1,1,1,1,1,1,1,1,1,1,1,1
1,1,1,1,1,1,1,1,1,1,1,1,1,1,1,1
1,1,1,1,1,1,1,1,1,1,1,1,1,1,1,1
1,1,1,1,1,1,1,1,1,1,1,1,1,1,1,1
1,1,1,1,1,1,1,1,1,1,1,1,1,1,1,1
1,1,1,1,1,1,1,1,1,1,1,1,1,1,1,1
1,1,1,1,1,1,1,1,1,1,1,1,1,1,1,1
1,1,1,1,1,1,1,1,1,1,1,1,1,1,1,1
1,1,1,1,1,1,1,1,1,1,1,1,1,1,1,1
1,1,1,1,1,1,1,1,1,1,1,1,1,1,1,1
1,1,1,1,1,1,1,1,1,1,1,1,1,1,1,1
1,1,1,1,1,1,1,1,1,1,1,1,1,1,1,1
1,1,1,1,1,1,1,1,1,1,1,1,1,1,1,1
:endlayer
layer: 5
1,1,1,1,1,1,1,1,1,1,1,1,1,1,1,1
1,1,1,1,1,1,1,1,1,1,1,1,1,1,1,1
1,1,1,1,1,1,1,1,1,1,1,1,1,1,1,1
1,1,1,1,1,1,1,1,1,1,1,1,1,1,1,1
1,1,1,1,1,1,1,1,1,1,1,1,1,1,1,1
1,1,1,1,1,1,1,1,1,1,1,1,1,1,1,1
1,1,1,1,1,1,1,1,1,1,1,1,1,1,1,1
1,1,1,1,1,1,1,1,1,1,1,1,1,1,1,1
1,1,1,1,1,1,1,1,1,1,1,1,1,1,1,1
1,1,1,1,1,1,1,1,1,1,1,1,1,1,1,1
1,1,1,1,1,1,1,1,1,1,1,1,1,1,1,1
1,1,1,1,1,1,1,1,1,1,1,1,1,1,1,1
1,1,1,1,1,1,1,1,1,1,1,1,1,1,1,1
1,1,1,1,1,1,1,1,1,1,1,1,1,1,1,1
:endlayer
layer: 6
2,2,2,2,2,2,2,1,2,2,2,2,2,2,2,2
2,2,2,1,2,1,1,1,1,1,2,1,2,2,2,2
2,2,2,1,1,1,1,1,1,1,1,1,1,2,2,2
2,2,1,1,1,1,1,2,1,2,1,1,1,2,2,2
2,2,1,1,1,1,2,2,2,2,2,1,1,1,2,2
2,1,1,1,1,2,2,2,2,2,2,2,1,1,1,2
2,1,1,1,2,2,2,2,2,2,2,1,1,1,1,2
2,2,1,1,1,2,2,2,2,2,2,2,1,1,1,2
2,2,1,1,1,1,1,1,2,2,2,1,1,1,1,2
2,1,1,1,1,1,1,2,2,2,1,1,1,1,1,2
2,2,1,1,1,1,1,2,2,2,1,1,1,1,2,2
2,2,2,2,1,1,1,1,1,1,1,1,1,1,1,2
2,2,2,2,2,1,1,1,1,1,1,1,1,1,2,2
2,2,2,2,2,2,2,2,2,2,2,2,2,2,2,2
:endlayer
layer: 7
4,4,4,4,4,3,3,2,3,4,3,4,4,4,4,3
3,3,4,2,3,2,2,2,2,2,4,2,4,4,4,3
3,3,4,2,2,2,2,2,6,2,2,2,2,3,4,4
3,3,2,2,5,5,6,0,6,0,6,2,2,3,3,3
3,3,2,2,5,6,0,0,0,0,0,6,2,2,3,3
3,2,2,5,5,0,0,0,0,0,0,0,2,2,2,3
3,2,5,5,0,0,0,0,0,0,0,6,6,2,2,3
3,3,5,5,5,0,0,0,0,0,0,0,7,2,2,3
3,3,2,5,5,6,6,6,0,0,0,6,5,5,2,4
3,2,2,2,5,6,6,0,0,0,6,5,7,5,2,4
3,4,2,2,5,6,6,0,0,0,6,6,5,2,4,3
3,4,4,3,2,2,2,2,2,2,2,2,2,2,2,3
3,4,4,3,4,2,2,2,2,2,2,2,2,2,3,3
0,4,4,3,4,3,3,0,3,3,3,3,3,3,3,3
:endlayer
layer: 8
0,0,0,0,0,0,0,4,0,0,0,0,0,0,0,0
0,0,0,4,0,4,4,4,4,4,0,4,0,0,0,0
0,0,0,4,4,4,3,4,13,4,4,4,4,0,0,0
0,0,4,8,3,0,6,10,5,10,6,4,16,0,0,0
0,0,4,4,3,6,5,5,5,5,6,6,4,4,0,0
0,4,4,3,0,10,5,5,5,5,5,10,4,4,4,0
0,8,3,3,9,5,5,5,5,5,5,6,0,4,4,0
0,0,3,3,0,10,5,12,12,12,5,10,0,4,4,0
0,0,4,3,3,6,6,6,12,12,6,6,0,0,4,0
0,4,4,4,3,0,5,10,6,10,6,0,0,0,4,0
0,0,4,4,3,3,3,5,7,14,11,0,15,4,0,0
0,0,0,0,3,3,3,11,11,11,11,4,4,4,16,0
0,0,0,0,0,3,3,4,4,4,3,4,0,4,0,0
0,0,0,0,0,0,0,0,0,0,0,0,0,0,0,0
:endlayer
layer: 9
0,0,0,0,0,0,0,0,0,0,0,0,0,0,0,0
0,0,0,0,0,0,0,0,0,0,0,0,0,0,0,0
0,0,0,0,0,0,0,0,0,0,0,0,0,0,0,0
0,0,0,0,0,0,6,10,6,10,6,0,0,0,0,0
0,0,0,0,0,6,6,5,5,23,6,6,0,0,0,0
0,0,0,0,0,10,5,12,5,23,23,10,0,0,0,0
0,0,0,0,0,6,19,20,10,22,22,6,0,0,0,0
0,0,0,0,0,10,18,0,0,0,0,10,0,0,0,0
0,0,0,0,0,6,17,0,0,0,6,6,0,0,0,0
0,0,0,0,0,0,6,10,21,10,6,0,0,0,0,0
0,0,0,0,0,0,0,0,0,0,0,0,24,0,0,0
0,0,0,0,0,0,0,0,0,0,0,0,0,0,0,0
0,0,0,0,0,0,0,0,0,0,0,0,0,0,0,0
0,0,0,0,0,0,0,0,0,0,0,0,0,0,0,0
:endlayer
layer: 10
0,0,0,0,0,0,0,0,0,0,0,0,0,0,0,0
0,0,0,0,0,0,0,0,0,0,0,0,0,0,0,0
0,0,0,0,0,0,0,0,0,0,0,0,0,0,0,0
0,0,0,0,0,0,13,10,6,10,13,0,0,0,0,0
0,0,0,0,0,25,6,23,22,0,6,29,0,0,0,0
0,0,0,0,0,10,12,12,22,0,0,10,0,0,0,0
0,0,0,0,0,6,0,0,10,0,0,6,0,0,0,0
0,0,0,0,0,10,27,0,0,0,0,10,0,0,0,0
0,0,0,0,0,25,0,0,0,0,6,29,0,0,0,0
0,0,0,0,0,0,26,10,28,10,26,0,0,0,0,0
0,0,0,0,0,0,0,0,0,0,0,0,0,0,0,0
0,0,0,0,0,0,0,0,0,0,0,0,0,0,0,0
0,0,0,0,0,0,0,0,0,0,0,0,0,0,0,0
0,0,0,0,0,0,0,0,0,0,0,0,0,0,0,0
:endlayer
layer: 11
0,0,0,0,0,0,0,0,0,0,0,0,0,0,0,0
0,0,0,0,0,0,0,0,0,0,0,0,0,0,0,0
0,0,0,0,0,0,0,0,0,0,0,0,0,0,0,0
0,0,0,0,0,0,0,10,6,10,0,0,0,0,0,0
0,0,0,0,0,0,6,0,0,0,6,0,0,0,0,0
0,0,0,0,0,10,0,0,0,0,0,10,0,0,0,0
0,0,0,0,0,6,22,22,10,0,0,6,0,0,0,0
0,0,0,0,0,10,23,23,0,0,0,10,0,0,0,0
0,0,0,0,0,0,6,23,0,0,6,0,0,0,0,0
0,0,0,0,0,0,0,10,30,10,0,0,0,0,0,0
0,0,0,0,0,0,0,0,0,0,0,0,0,0,0,0
0,0,0,0,0,0,0,0,0,0,0,0,0,0,0,0
0,0,0,0,0,0,0,0,0,0,0,0,0,0,0,0
0,0,0,0,0,0,0,0,0,0,0,0,0,0,0,0
:endlayer
layer: 12
0,0,0,0,0,0,0,0,0,0,0,0,0,0,0,0
0,0,0,0,0,0,0,0,0,0,0,0,0,0,0,0
0,0,0,0,0,0,0,0,0,0,0,0,0,0,0,0
0,0,0,0,0,0,0,10,31,10,0,0,0,0,0,0
0,0,0,0,0,0,10,0,0,0,10,0,0,0,0,0
0,0,0,0,0,10,0,0,0,0,0,10,0,0,0,0
0,0,0,0,0,31,0,0,10,0,32,31,0,0,0,0
0,0,0,0,0,10,0,0,22,23,23,10,0,0,0,0
0,0,0,0,0,0,10,0,22,23,10,0,0,0,0,0
0,0,0,0,0,0,0,10,31,10,0,0,0,0,0,0
0,0,0,0,0,0,0,0,0,0,0,0,0,0,0,0
0,0,0,0,0,0,0,0,0,0,0,0,0,0,0,0
0,0,0,0,0,0,0,0,0,0,0,0,0,0,0,0
0,0,0,0,0,0,0,0,0,0,0,0,0,0,0,0
:endlayer
layer: 13
0,0,0,0,0,0,0,0,0,0,0,0,0,0,0,0
0,0,0,0,0,0,0,0,0,0,0,0,0,0,0,0
0,0,0,0,0,0,0,0,0,0,0,0,0,0,0,0
0,0,0,0,0,0,0,10,6,10,0,0,0,0,0,0
0,0,0,0,0,0,6,0,34,23,6,0,0,0,0,0
0,0,0,0,0,10,0,0,0,23,23,10,0,0,0,0
0,0,0,0,0,33,0,0,10,22,22,6,0,0,0,0
0,0,0,0,0,10,0,0,0,0,0,10,0,0,0,0
0,0,0,0,0,0,6,0,0,0,6,0,0,0,0,0
0,0,0,0,0,0,0,10,6,10,0,0,0,0,0,0
0,0,0,0,0,0,0,0,0,0,0,0,0,0,0,0
0,0,0,0,0,0,0,0,0,0,0,0,0,0,0,0
0,0,0,0,0,0,0,0,0,0,0,0,0,0,0,0
0,0,0,0,0,0,0,0,0,0,0,0,0,0,0,0
:endlayer
layer: 14
0,0,0,0,0,0,0,0,0,0,0,0,0,0,0,0
0,0,0,0,0,0,0,0,0,0,0,0,0,0,0,0
0,0,0,0,0,0,0,0,0,0,0,0,0,0,0,0
0,0,0,0,0,0,0,10,6,10,0,0,0,0,0,0
0,0,0,0,0,0,6,23,22,0,6,0,0,0,0,0
0,0,0,0,0,10,23,23,22,0,0,10,0,0,0,0
0,0,0,0,0,33,0,0,10,0,0,33,0,0,0,0
0,0,0,0,0,10,0,0,0,0,0,10,0,0,0,0
0,0,0,0,0,0,6,0,0,0,6,0,0,0,0,0
0,0,0,0,0,0,0,10,33,10,0,0,0,0,0,0
0,0,0,0,0,0,0,0,0,0,0,0,0,0,0,0
0,0,0,0,0,0,0,0,0,0,0,0,0,0,0,0
0,0,0,0,0,0,0,0,0,0,0,0,0,0,0,0
0,0,0,0,0,0,0,0,0,0,0,0,0,0,0,0
:endlayer
layer: 15
0,0,0,0,0,0,0,0,0,0,0,0,0,0,0,0
0,0,0,0,0,0,0,0,0,0,0,0,0,0,0,0
0,0,0,0,0,0,0,0,0,0,0,0,0,0,0,0
0,0,0,0,0,0,0,10,33,10,0,0,0,0,0,0
0,0,0,0,0,0,6,0,0,0,6,0,0,0,0,0
0,0,0,0,0,10,0,0,0,0,0,10,0,0,0,0
0,0,0,0,0,6,22,22,10,0,0,33,0,0,0,0
0,0,0,0,0,10,23,23,0,0,0,10,0,0,0,0
0,0,0,0,0,0,6,23,0,0,6,0,0,0,0,0
0,0,0,0,0,0,0,10,33,10,0,0,0,0,0,0
0,0,0,0,0,0,0,0,0,0,0,0,0,0,0,0
0,0,0,0,0,0,0,0,0,0,0,0,0,0,0,0
0,0,0,0,0,0,0,0,0,0,0,0,0,0,0,0
0,0,0,0,0,0,0,0,0,0,0,0,0,0,0,0
:endlayer
layer: 16
0,0,0,0,0,0,0,0,0,0,0,0,0,0,0,0
0,0,0,0,0,0,0,0,0,0,0,0,0,0,0,0
0,0,0,0,0,0,0,0,0,0,0,0,0,0,0,0
0,0,0,0,0,0,0,10,33,10,0,0,0,0,0,0
0,0,0,0,0,0,6,0,0,0,6,0,0,0,0,0
0,0,0,0,0,10,0,0,0,0,0,10,0,0,0,0
0,0,0,0,0,6,0,0,10,0,32,6,0,0,0,0
0,0,0,0,0,10,0,0,22,23,23,10,0,0,0,0
0,0,0,0,0,0,6,0,22,23,6,0,0,0,0,0
0,0,0,0,0,0,0,10,6,10,0,0,0,0,0,0
0,0,0,0,0,0,0,0,0,0,0,0,0,0,0,0
0,0,0,0,0,0,0,0,0,0,0,0,0,0,0,0
0,0,0,0,0,0,0,0,0,0,0,0,0,0,0,0
0,0,0,0,0,0,0,0,0,0,0,0,0,0,0,0
:endlayer
layer: 17
0,0,0,0,0,0,0,0,0,0,0,0,0,0,0,0
0,0,0,0,0,0,0,0,0,0,0,0,0,0,0,0
0,0,0,0,0,0,0,0,0,0,0,0,0,0,0,0
0,0,0,0,0,0,37,10,31,10,37,0,0,0,0,0
0,0,0,0,0,35,6,0,0,23,5,38,0,0,0,0
0,0,0,0,0,10,0,0,0,23,23,10,0,0,0,0
0,0,0,0,0,31,0,0,10,22,22,31,0,0,0,0
0,0,0,0,0,10,0,0,0,0,0,10,0,0,0,0
0,0,0,0,0,35,10,0,0,0,6,38,0,0,0,0
0,0,0,0,0,0,36,10,31,10,36,0,0,0,0,0
0,0,0,0,0,0,0,0,0,0,0,0,0,0,0,0
0,0,0,0,0,0,0,0,0,0,0,0,0,0,0,0
0,0,0,0,0,0,0,0,0,0,0,0,0,0,0,0
0,0,0,0,0,0,0,0,0,0,0,0,0,0,0,0
:endlayer
layer: 18
0,0,0,0,0,0,0,0,0,0,0,0,0,0,0,0
0,0,0,0,0,0,0,0,0,0,0,0,0,0,0,0
0,0,0,0,0,0,0,0,37,0,0,0,0,0,0,0
0,0,0,0,0,35,6,6,6,6,6,38,0,0,0,0
0,0,0,0,0,6,0,23,22,0,6,6,0,0,0,0
0,0,0,0,0,6,0,23,22,0,0,6,0,0,0,0
0,0,0,0,35,6,27,0,10,0,0,6,38,0,0,0
0,0,0,0,0,6,0,0,0,0,0,6,0,0,0,0
0,0,0,0,0,6,5,0,0,0,6,6,0,0,0,0
0,0,0,0,0,35,6,6,6,6,6,38,0,0,0,0
0,0,0,0,0,0,0,0,36,0,0,0,0,0,0,0
0,0,0,0,0,0,0,0,0,0,0,0,0,0,0,0
0,0,0,0,0,0,0,0,0,0,0,0,0,0,0,0
0,0,0,0,0,0,0,0,0,0,0,0,0,0,0,0
:endlayer
layer: 19
0,0,0,0,0,0,0,0,0,0,0,0,0,0,0,0
0,0,0,0,0,0,0,0,0,0,0,0,0,0,0,0
0,0,0,0,0,0,0,37,6,37,0,0,0,0,0,0
0,0,0,0,0,39,6,6,6,6,6,39,0,0,0,0
0,0,0,0,0,6,22,0,0,0,6,6,0,0,0,0
0,0,0,0,35,6,22,0,0,0,0,6,38,0,0,0
0,0,0,0,6,6,6,6,6,0,0,6,6,0,0,0
0,0,0,0,35,6,6,6,6,0,0,6,38,0,0,0
0,0,0,0,0,6,6,6,6,0,6,6,0,0,0,0
0,0,0,0,0,39,6,6,6,6,6,39,0,0,0,0
0,0,0,0,0,0,0,36,6,36,0,0,0,0,0,0
0,0,0,0,0,0,0,0,0,0,0,0,0,0,0,0
0,0,0,0,0,0,0,0,0,0,0,0,0,0,0,0
0,0,0,0,0,0,0,0,0,0,0,0,0,0,0,0
:endlayer
layer: 20
0,0,0,0,0,0,0,0,0,0,0,0,0,0,0,0
0,0,0,0,0,0,0,0,0,0,0,0,0,0,0,0
0,0,0,0,0,0,0,39,0,39,0,0,0,0,0,0
0,0,0,0,0,39,0,0,0,0,0,39,0,0,0,0
0,0,0,0,0,0,0,0,0,0,0,0,0,0,0,0
0,0,0,0,39,0,0,0,0,0,0,0,39,0,0,0
0,0,0,0,0,0,0,0,6,0,0,0,0,0,0,0
0,0,0,0,39,0,0,0,0,0,0,0,39,0,0,0
0,0,0,0,0,0,0,0,0,0,0,0,0,0,0,0
0,0,0,0,0,39,0,0,0,0,0,39,0,0,0,0
0,0,0,0,0,0,0,39,0,39,0,0,0,0,0,0
0,0,0,0,0,0,0,0,0,0,0,0,0,0,0,0
0,0,0,0,0,0,0,0,0,0,0,0,0,0,0,0
0,0,0,0,0,0,0,0,0,0,0,0,0,0,0,0
:endlayer
layer: 21
0,0,0,0,0,0,0,0,0,0,0,0,0,0,0,0
0,0,0,0,0,0,0,0,0,0,0,0,0,0,0,0
0,0,0,0,0,0,0,24,0,24,0,0,0,0,0,0
0,0,0,0,0,24,0,0,0,0,0,24,0,0,0,0
0,0,0,0,0,0,0,0,0,0,0,0,0,0,0,0
0,0,0,0,24,0,0,0,0,0,0,0,24,0,0,0
0,0,0,0,0,0,0,0,6,0,0,0,0,0,0,0
0,0,0,0,24,0,0,0,0,0,0,0,24,0,0,0
0,0,0,0,0,0,0,0,0,0,0,0,0,0,0,0
0,0,0,0,0,24,0,0,0,0,0,24,0,0,0,0
0,0,0,0,0,0,0,24,0,24,0,0,0,0,0,0
0,0,0,0,0,0,0,0,0,0,0,0,0,0,0,0
0,0,0,0,0,0,0,0,0,0,0,0,0,0,0,0
0,0,0,0,0,0,0,0,0,0,0,0,0,0,0,0
:endlayer
layer: 22
0,0,0,0,0,0,0,0,0,0,0,0,0,0,0,0
0,0,0,0,0,0,0,0,0,0,0,0,0,0,0,0
0,0,0,0,0,0,0,0,0,0,0,0,0,0,0,0
0,0,0,0,0,0,0,0,0,0,0,0,0,0,0,0
0,0,0,0,0,0,0,0,0,0,0,0,0,0,0,0
0,0,0,0,0,0,0,0,40,0,0,0,0,0,0,0
0,0,0,0,0,0,0,32,6,27,0,0,0,0,0,0
0,0,0,0,0,0,0,0,34,0,0,0,0,0,0,0
0,0,0,0,0,0,0,0,0,0,0,0,0,0,0,0
0,0,0,0,0,0,0,0,0,0,0,0,0,0,0,0
0,0,0,0,0,0,0,0,0,0,0,0,0,0,0,0
0,0,0,0,0,0,0,0,0,0,0,0,0,0,0,0
0,0,0,0,0,0,0,0,0,0,0,0,0,0,0,0
0,0,0,0,0,0,0,0,0,0,0,0,0,0,0,0
:endlayer
layer: 23
0,0,0,0,0,0,0,0,0,0,0,0,0,0,0,0
0,0,0,0,0,0,0,0,0,0,0,0,0,0,0,0
0,0,0,0,0,0,0,0,0,0,0,0,0,0,0,0
0,0,0,0,0,0,0,0,0,0,0,0,0,0,0,0
0,0,0,0,0,0,0,0,0,0,0,0,0,0,0,0
0,0,0,0,0,0,0,37,37,37,0,0,0,0,0,0
0,0,0,0,0,0,0,35,6,38,0,0,0,0,0,0
0,0,0,0,0,0,0,35,36,36,0,0,0,0,0,0
0,0,0,0,0,0,0,0,0,0,0,0,0,0,0,0
0,0,0,0,0,0,0,0,0,0,0,0,0,0,0,0
0,0,0,0,0,0,0,0,0,0,0,0,0,0,0,0
0,0,0,0,0,0,0,0,0,0,0,0,0,0,0,0
0,0,0,0,0,0,0,0,0,0,0,0,0,0,0,0
0,0,0,0,0,0,0,0,0,0,0,0,0,0,0,0
:endlayer
layer: 24
0,0,0,0,0,0,0,0,0,0,0,0,0,0,0,0
0,0,0,0,0,0,0,0,0,0,0,0,0,0,0,0
0,0,0,0,0,0,0,0,0,0,0,0,0,0,0,0
0,0,0,0,0,0,0,0,0,0,0,0,0,0,0,0
0,0,0,0,0,0,0,37,37,37,0,0,0,0,0,0
0,0,0,0,0,0,35,41,41,41,38,0,0,0,0,0
0,0,0,0,0,0,35,41,6,41,38,0,0,0,0,0
0,0,0,0,0,0,35,41,41,41,38,0,0,0,0,0
0,0,0,0,0,0,0,36,36,36,0,0,0,0,0,0
0,0,0,0,0,0,0,0,0,0,0,0,0,0,0,0
0,0,0,0,0,0,0,0,0,0,0,0,0,0,0,0
0,0,0,0,0,0,0,0,0,0,0,0,0,0,0,0
0,0,0,0,0,0,0,0,0,0,0,0,0,0,0,0
0,0,0,0,0,0,0,0,0,0,0,0,0,0,0,0
:endlayer
layer: 25
0,0,0,0,0,0,0,0,0,0,0,0,0,0,0,0
0,0,0,0,0,0,0,0,0,0,0,0,0,0,0,0
0,0,0,0,0,0,0,0,0,0,0,0,0,0,0,0
0,0,0,0,0,0,0,0,0,0,0,0,0,0,0,0
0,0,0,0,0,0,0,0,0,0,0,0,0,0,0,0
0,0,0,0,0,0,0,42,42,42,0,0,0,0,0,0
0,0,0,0,0,0,0,42,41,42,0,0,0,0,0,0
0,0,0,0,0,0,0,42,42,42,0,0,0,0,0,0
0,0,0,0,0,0,0,0,0,0,0,0,0,0,0,0
0,0,0,0,0,0,0,0,0,0,0,0,0,0,0,0
0,0,0,0,0,0,0,0,0,0,0,0,0,0,0,0
0,0,0,0,0,0,0,0,0,0,0,0,0,0,0,0
0,0,0,0,0,0,0,0,0,0,0,0,0,0,0,0
0,0,0,0,0,0,0,0,0,0,0,0,0,0,0,0
:endlayer
layer: 26
0,0,0,0,0,0,0,0,0,0,0,0,0,0,0,0
0,0,0,0,0,0,0,0,0,0,0,0,0,0,0,0
0,0,0,0,0,0,0,0,0,0,0,0,0,0,0,0
0,0,0,0,0,0,0,0,0,0,0,0,0,0,0,0
0,0,0,0,0,0,0,0,0,0,0,0,0,0,0,0
0,0,0,0,0,0,0,0,0,0,0,0,0,0,0,0
0,0,0,0,0,0,0,0,42,0,0,0,0,0,0,0
0,0,0,0,0,0,0,0,0,0,0,0,0,0,0,0
0,0,0,0,0,0,0,0,0,0,0,0,0,0,0,0
0,0,0,0,0,0,0,0,0,0,0,0,0,0,0,0
0,0,0,0,0,0,0,0,0,0,0,0,0,0,0,0
0,0,0,0,0,0,0,0,0,0,0,0,0,0,0,0
0,0,0,0,0,0,0,0,0,0,0,0,0,0,0,0
0,0,0,0,0,0,0,0,0,0,0,0,0,0,0,0
:endlayer
layer: 27
0,0,0,0,0,0,0,0,0,0,0,0,0,0,0,0
0,0,0,0,0,0,0,0,0,0,0,0,0,0,0,0
0,0,0,0,0,0,0,0,0,0,0,0,0,0,0,0
0,0,0,0,0,0,0,0,0,0,0,0,0,0,0,0
0,0,0,0,0,0,0,0,0,0,0,0,0,0,0,0
0,0,0,0,0,0,0,0,0,0,0,0,0,0,0,0
0,0,0,0,0,0,0,0,0,0,0,0,0,0,0,0
0,0,0,0,0,0,0,0,0,0,0,0,0,0,0,0
0,0,0,0,0,0,0,0,0,0,0,0,0,0,0,0
0,0,0,0,0,0,0,0,0,0,0,0,0,0,0,0
0,0,0,0,0,0,0,0,0,0,0,0,0,0,0,0
0,0,0,0,0,0,0,0,0,0,0,0,0,0,0,0
0,0,0,0,0,0,0,0,0,0,0,0,0,0,0,0
0,0,0,0,0,0,0,0,0,0,0,0,0,0,0,0
:endlayer
layer: 28
0,0,0,0,0,0,0,0,0,0,0,0,0,0,0,0
0,0,0,0,0,0,0,0,0,0,0,0,0,0,0,0
0,0,0,0,0,0,0,0,0,0,0,0,0,0,0,0
0,0,0,0,0,0,0,0,0,0,0,0,0,0,0,0
0,0,0,0,0,0,0,0,0,0,0,0,0,0,0,0
0,0,0,0,0,0,0,0,0,0,0,0,0,0,0,0
0,0,0,0,0,0,0,0,0,0,0,0,0,0,0,0
0,0,0,0,0,0,0,0,0,0,0,0,0,0,0,0
0,0,0,0,0,0,0,0,0,0,0,0,0,0,0,0
0,0,0,0,0,0,0,0,0,0,0,0,0,0,0,0
0,0,0,0,0,0,0,0,0,0,0,0,0,0,0,0
0,0,0,0,0,0,0,0,0,0,0,0,0,0,0,0
0,0,0,0,0,0,0,0,0,0,0,0,0,0,0,0
0,0,0,0,0,0,0,0,0,0,0,0,0,0,0,0
:endlayer
layer: 29
0,0,0,0,0,0,0,0,0,0,0,0,0,0,0,0
0,0,0,0,0,0,0,0,0,0,0,0,0,0,0,0
0,0,0,0,0,0,0,0,0,0,0,0,0,0,0,0
0,0,0,0,0,0,0,0,0,0,0,0,0,0,0,0
0,0,0,0,0,0,0,0,0,0,0,0,0,0,0,0
0,0,0,0,0,0,0,0,0,0,0,0,0,0,0,0
0,0,0,0,0,0,0,0,0,0,0,0,0,0,0,0
0,0,0,0,0,0,0,0,0,0,0,0,0,0,0,0
0,0,0,0,0,0,0,0,0,0,0,0,0,0,0,0
0,0,0,0,0,0,0,0,0,0,0,0,0,0,0,0
0,0,0,0,0,0,0,0,0,0,0,0,0,0,0,0
0,0,0,0,0,0,0,0,0,0,0,0,0,0,0,0
0,0,0,0,0,0,0,0,0,0,0,0,0,0,0,0
0,0,0,0,0,0,0,0,0,0,0,0,0,0,0,0
:endlayer
layer: 30
0,0,0,0,0,0,0,0,0,0,0,0,0,0,0,0
0,0,0,0,0,0,0,0,0,0,0,0,0,0,0,0
0,0,0,0,0,0,0,0,0,0,0,0,0,0,0,0
0,0,0,0,0,0,0,0,0,0,0,0,0,0,0,0
0,0,0,0,0,0,0,0,0,0,0,0,0,0,0,0
0,0,0,0,0,0,0,0,0,0,0,0,0,0,0,0
0,0,0,0,0,0,0,0,0,0,0,0,0,0,0,0
0,0,0,0,0,0,0,0,0,0,0,0,0,0,0,0
0,0,0,0,0,0,0,0,0,0,0,0,0,0,0,0
0,0,0,0,0,0,0,0,0,0,0,0,0,0,0,0
0,0,0,0,0,0,0,0,0,0,0,0,0,0,0,0
0,0,0,0,0,0,0,0,0,0,0,0,0,0,0,0
0,0,0,0,0,0,0,0,0,0,0,0,0,0,0,0
0,0,0,0,0,0,0,0,0,0,0,0,0,0,0,0
:endlayer
layer: 31
0,0,0,0,0,0,0,0,0,0,0,0,0,0,0,0
0,0,0,0,0,0,0,0,0,0,0,0,0,0,0,0
0,0,0,0,0,0,0,0,0,0,0,0,0,0,0,0
0,0,0,0,0,0,0,0,0,0,0,0,0,0,0,0
0,0,0,0,0,0,0,0,0,0,0,0,0,0,0,0
0,0,0,0,0,0,0,0,0,0,0,0,0,0,0,0
0,0,0,0,0,0,0,0,0,0,0,0,0,0,0,0
0,0,0,0,0,0,0,0,0,0,0,0,0,0,0,0
0,0,0,0,0,0,0,0,0,0,0,0,0,0,0,0
0,0,0,0,0,0,0,0,0,0,0,0,0,0,0,0
0,0,0,0,0,0,0,0,0,0,0,0,0,0,0,0
0,0,0,0,0,0,0,0,0,0,0,0,0,0,0,0
0,0,0,0,0,0,0,0,0,0,0,0,0,0,0,0
0,0,0,0,0,0,0,0,0,0,0,0,0,0,0,0
:endlayer
layer: 32
0,0,0,0,0,0,0,0,0,0,0,0,0,0,0,0
0,0,0,0,0,0,0,0,0,0,0,0,0,0,0,0
0,0,0,0,0,0,0,0,0,0,0,0,0,0,0,0
0,0,0,0,0,0,0,0,0,0,0,0,0,0,0,0
0,0,0,0,0,0,0,0,0,0,0,0,0,0,0,0
0,0,0,0,0,0,0,0,0,0,0,0,0,0,0,0
0,0,0,0,0,0,0,0,0,0,0,0,0,0,0,0
0,0,0,0,0,0,0,0,0,0,0,0,0,0,0,0
0,0,0,0,0,0,0,0,0,0,0,0,0,0,0,0
0,0,0,0,0,0,0,0,0,0,0,0,0,0,0,0
0,0,0,0,0,0,0,0,0,0,0,0,0,0,0,0
0,0,0,0,0,0,0,0,0,0,0,0,0,0,0,0
0,0,0,0,0,0,0,0,0,0,0,0,0,0,0,0
0,0,0,0,0,0,0,0,0,0,0,0,0,0,0,0
:endlayer
layer: 33
0,0,0,0,0,0,0,0,0,0,0,0,0,0,0,0
0,0,0,0,0,0,0,0,0,0,0,0,0,0,0,0
0,0,0,0,0,0,0,0,0,0,0,0,0,0,0,0
0,0,0,0,0,0,0,0,0,0,0,0,0,0,0,0
0,0,0,0,0,0,0,0,0,0,0,0,0,0,0,0
0,0,0,0,0,0,0,0,0,0,0,0,0,0,0,0
0,0,0,0,0,0,0,0,0,0,0,0,0,0,0,0
0,0,0,0,0,0,0,0,0,0,0,0,0,0,0,0
0,0,0,0,0,0,0,0,0,0,0,0,0,0,0,0
0,0,0,0,0,0,0,0,0,0,0,0,0,0,0,0
0,0,0,0,0,0,0,0,0,0,0,0,0,0,0,0
0,0,0,0,0,0,0,0,0,0,0,0,0,0,0,0
0,0,0,0,0,0,0,0,0,0,0,0,0,0,0,0
0,0,0,0,0,0,0,0,0,0,0,0,0,0,0,0
:endlayer
layer: 34
0,0,0,0,0,0,0,0,0,0,0,0,0,0,0,0
0,0,0,0,0,0,0,0,0,0,0,0,0,0,0,0
0,0,0,0,0,0,0,0,0,0,0,0,0,0,0,0
0,0,0,0,0,0,0,0,0,0,0,0,0,0,0,0
0,0,0,0,0,0,0,0,0,0,0,0,0,0,0,0
0,0,0,0,0,0,0,0,0,0,0,0,0,0,0,0
0,0,0,0,0,0,0,0,0,0,0,0,0,0,0,0
0,0,0,0,0,0,0,0,0,0,0,0,0,0,0,0
0,0,0,0,0,0,0,0,0,0,0,0,0,0,0,0
0,0,0,0,0,0,0,0,0,0,0,0,0,0,0,0
0,0,0,0,0,0,0,0,0,0,0,0,0,0,0,0
0,0,0,0,0,0,0,0,0,0,0,0,0,0,0,0
0,0,0,0,0,0,0,0,0,0,0,0,0,0,0,0
0,0,0,0,0,0,0,0,0,0,0,0,0,0,0,0
:endlayer
layer: 35
0,0,0,0,0,0,0,0,0,0,0,0,0,0,0,0
0,0,0,0,0,0,0,0,0,0,0,0,0,0,0,0
0,0,0,0,0,0,0,0,0,0,0,0,0,0,0,0
0,0,0,0,0,0,0,0,0,0,0,0,0,0,0,0
0,0,0,0,0,0,0,0,0,0,0,0,0,0,0,0
0,0,0,0,0,0,0,0,0,0,0,0,0,0,0,0
0,0,0,0,0,0,0,0,0,0,0,0,0,0,0,0
0,0,0,0,0,0,0,0,0,0,0,0,0,0,0,0
0,0,0,0,0,0,0,0,0,0,0,0,0,0,0,0
0,0,0,0,0,0,0,0,0,0,0,0,0,0,0,0
0,0,0,0,0,0,0,0,0,0,0,0,0,0,0,0
0,0,0,0,0,0,0,0,0,0,0,0,0,0,0,0
0,0,0,0,0,0,0,0,0,0,0,0,0,0,0,0
0,0,0,0,0,0,0,0,0,0,0,0,0,0,0,0
:endlayer
layer: 36
0,0,0,0,0,0,0,0,0,0,0,0,0,0,0,0
0,0,0,0,0,0,0,0,0,0,0,0,0,0,0,0
0,0,0,0,0,0,0,0,0,0,0,0,0,0,0,0
0,0,0,0,0,0,0,0,0,0,0,0,0,0,0,0
0,0,0,0,0,0,0,0,0,0,0,0,0,0,0,0
0,0,0,0,0,0,0,0,0,0,0,0,0,0,0,0
0,0,0,0,0,0,0,0,0,0,0,0,0,0,0,0
0,0,0,0,0,0,0,0,0,0,0,0,0,0,0,0
0,0,0,0,0,0,0,0,0,0,0,0,0,0,0,0
0,0,0,0,0,0,0,0,0,0,0,0,0,0,0,0
0,0,0,0,0,0,0,0,0,0,0,0,0,0,0,0
0,0,0,0,0,0,0,0,0,0,0,0,0,0,0,0
0,0,0,0,0,0,0,0,0,0,0,0,0,0,0,0
0,0,0,0,0,0,0,0,0,0,0,0,0,0,0,0
:endlayer
layer: 37
0,0,0,0,0,0,0,0,0,0,0,0,0,0,0,0
0,0,0,0,0,0,0,0,0,0,0,0,0,0,0,0
0,0,0,0,0,0,0,0,0,0,0,0,0,0,0,0
0,0,0,0,0,0,0,0,0,0,0,0,0,0,0,0
0,0,0,0,0,0,0,0,0,0,0,0,0,0,0,0
0,0,0,0,0,0,0,0,0,0,0,0,0,0,0,0
0,0,0,0,0,0,0,0,0,0,0,0,0,0,0,0
0,0,0,0,0,0,0,0,0,0,0,0,0,0,0,0
0,0,0,0,0,0,0,0,0,0,0,0,0,0,0,0
0,0,0,0,0,0,0,0,0,0,0,0,0,0,0,0
0,0,0,0,0,0,0,0,0,0,0,0,0,0,0,0
0,0,0,0,0,0,0,0,0,0,0,0,0,0,0,0
0,0,0,0,0,0,0,0,0,0,0,0,0,0,0,0
0,0,0,0,0,0,0,0,0,0,0,0,0,0,0,0
:endlayer
layer: 38
0,0,0,0,0,0,0,0,0,0,0,0,0,0,0,0
0,0,0,0,0,0,0,0,0,0,0,0,0,0,0,0
0,0,0,0,0,0,0,0,0,0,0,0,0,0,0,0
0,0,0,0,0,0,0,0,0,0,0,0,0,0,0,0
0,0,0,0,0,0,0,0,0,0,0,0,0,0,0,0
0,0,0,0,0,0,0,0,0,0,0,0,0,0,0,0
0,0,0,0,0,0,0,0,0,0,0,0,0,0,0,0
0,0,0,0,0,0,0,0,0,0,0,0,0,0,0,0
0,0,0,0,0,0,0,0,0,0,0,0,0,0,0,0
0,0,0,0,0,0,0,0,0,0,0,0,0,0,0,0
0,0,0,0,0,0,0,0,0,0,0,0,0,0,0,0
0,0,0,0,0,0,0,0,0,0,0,0,0,0,0,0
0,0,0,0,0,0,0,0,0,0,0,0,0,0,0,0
0,0,0,0,0,0,0,0,0,0,0,0,0,0,0,0
:endlayer
layer: 39
0,0,0,0,0,0,0,0,0,0,0,0,0,0,0,0
0,0,0,0,0,0,0,0,0,0,0,0,0,0,0,0
0,0,0,0,0,0,0,0,0,0,0,0,0,0,0,0
0,0,0,0,0,0,0,0,0,0,0,0,0,0,0,0
0,0,0,0,0,0,0,0,0,0,0,0,0,0,0,0
0,0,0,0,0,0,0,0,0,0,0,0,0,0,0,0
0,0,0,0,0,0,0,0,0,0,0,0,0,0,0,0
0,0,0,0,0,0,0,0,0,0,0,0,0,0,0,0
0,0,0,0,0,0,0,0,0,0,0,0,0,0,0,0
0,0,0,0,0,0,0,0,0,0,0,0,0,0,0,0
0,0,0,0,0,0,0,0,0,0,0,0,0,0,0,0
0,0,0,0,0,0,0,0,0,0,0,0,0,0,0,0
0,0,0,0,0,0,0,0,0,0,0,0,0,0,0,0
0,0,0,0,0,0,0,0,0,0,0,0,0,0,0,0
:endlayer
layer: 40
0,0,0,0,0,0,0,0,0,0,0,0,0,0,0,0
0,0,0,0,0,0,0,0,0,0,0,0,0,0,0,0
0,0,0,0,0,0,0,0,0,0,0,0,0,0,0,0
0,0,0,0,0,0,0,0,0,0,0,0,0,0,0,0
0,0,0,0,0,0,0,0,0,0,0,0,0,0,0,0
0,0,0,0,0,0,0,0,0,0,0,0,0,0,0,0
0,0,0,0,0,0,0,0,0,0,0,0,0,0,0,0
0,0,0,0,0,0,0,0,0,0,0,0,0,0,0,0
0,0,0,0,0,0,0,0,0,0,0,0,0,0,0,0
0,0,0,0,0,0,0,0,0,0,0,0,0,0,0,0
0,0,0,0,0,0,0,0,0,0,0,0,0,0,0,0
0,0,0,0,0,0,0,0,0,0,0,0,0,0,0,0
0,0,0,0,0,0,0,0,0,0,0,0,0,0,0,0
0,0,0,0,0,0,0,0,0,0,0,0,0,0,0,0
:endlayer
layer: 41
0,0,0,0,0,0,0,0,0,0,0,0,0,0,0,0
0,0,0,0,0,0,0,0,0,0,0,0,0,0,0,0
0,0,0,0,0,0,0,0,0,0,0,0,0,0,0,0
0,0,0,0,0,0,0,0,0,0,0,0,0,0,0,0
0,0,0,0,0,0,0,0,0,0,0,0,0,0,0,0
0,0,0,0,0,0,0,0,0,0,0,0,0,0,0,0
0,0,0,0,0,0,0,0,0,0,0,0,0,0,0,0
0,0,0,0,0,0,0,0,0,0,0,0,0,0,0,0
0,0,0,0,0,0,0,0,0,0,0,0,0,0,0,0
0,0,0,0,0,0,0,0,0,0,0,0,0,0,0,0
0,0,0,0,0,0,0,0,0,0,0,0,0,0,0,0
0,0,0,0,0,0,0,0,0,0,0,0,0,0,0,0
0,0,0,0,0,0,0,0,0,0,0,0,0,0,0,0
0,0,0,0,0,0,0,0,0,0,0,0,0,0,0,0
:endlayer
layer: 42
0,0,0,0,0,0,0,0,0,0,0,0,0,0,0,0
0,0,0,0,0,0,0,0,0,0,0,0,0,0,0,0
0,0,0,0,0,0,0,0,0,0,0,0,0,0,0,0
0,0,0,0,0,0,0,0,0,0,0,0,0,0,0,0
0,0,0,0,0,0,0,0,0,0,0,0,0,0,0,0
0,0,0,0,0,0,0,0,0,0,0,0,0,0,0,0
0,0,0,0,0,0,0,0,0,0,0,0,0,0,0,0
0,0,0,0,0,0,0,0,0,0,0,0,0,0,0,0
0,0,0,0,0,0,0,0,0,0,0,0,0,0,0,0
0,0,0,0,0,0,0,0,0,0,0,0,0,0,0,0
0,0,0,0,0,0,0,0,0,0,0,0,0,0,0,0
0,0,0,0,0,0,0,0,0,0,0,0,0,0,0,0
0,0,0,0,0,0,0,0,0,0,0,0,0,0,0,0
0,0,0,0,0,0,0,0,0,0,0,0,0,0,0,0
:endlayer
layer: 43
0,0,0,0,0,0,0,0,0,0,0,0,0,0,0,0
0,0,0,0,0,0,0,0,0,0,0,0,0,0,0,0
0,0,0,0,0,0,0,0,0,0,0,0,0,0,0,0
0,0,0,0,0,0,0,0,0,0,0,0,0,0,0,0
0,0,0,0,0,0,0,0,0,0,0,0,0,0,0,0
0,0,0,0,0,0,0,0,0,0,0,0,0,0,0,0
0,0,0,0,0,0,0,0,0,0,0,0,0,0,0,0
0,0,0,0,0,0,0,0,0,0,0,0,0,0,0,0
0,0,0,0,0,0,0,0,0,0,0,0,0,0,0,0
0,0,0,0,0,0,0,0,0,0,0,0,0,0,0,0
0,0,0,0,0,0,0,0,0,0,0,0,0,0,0,0
0,0,0,0,0,0,0,0,0,0,0,0,0,0,0,0
0,0,0,0,0,0,0,0,0,0,0,0,0,0,0,0
0,0,0,0,0,0,0,0,0,0,0,0,0,0,0,0
:endlayer
layer: 44
0,0,0,0,0,0,0,0,0,0,0,0,0,0,0,0
0,0,0,0,0,0,0,0,0,0,0,0,0,0,0,0
0,0,0,0,0,0,0,0,0,0,0,0,0,0,0,0
0,0,0,0,0,0,0,0,0,0,0,0,0,0,0,0
0,0,0,0,0,0,0,0,0,0,0,0,0,0,0,0
0,0,0,0,0,0,0,0,0,0,0,0,0,0,0,0
0,0,0,0,0,0,0,0,0,0,0,0,0,0,0,0
0,0,0,0,0,0,0,0,0,0,0,0,0,0,0,0
0,0,0,0,0,0,0,0,0,0,0,0,0,0,0,0
0,0,0,0,0,0,0,0,0,0,0,0,0,0,0,0
0,0,0,0,0,0,0,0,0,0,0,0,0,0,0,0
0,0,0,0,0,0,0,0,0,0,0,0,0,0,0,0
0,0,0,0,0,0,0,0,0,0,0,0,0,0,0,0
0,0,0,0,0,0,0,0,0,0,0,0,0,0,0,0
:endlayer
layer: 45
0,0,0,0,0,0,0,0,0,0,0,0,0,0,0,0
0,0,0,0,0,0,0,0,0,0,0,0,0,0,0,0
0,0,0,0,0,0,0,0,0,0,0,0,0,0,0,0
0,0,0,0,0,0,0,0,0,0,0,0,0,0,0,0
0,0,0,0,0,0,0,0,0,0,0,0,0,0,0,0
0,0,0,0,0,0,0,0,0,0,0,0,0,0,0,0
0,0,0,0,0,0,0,0,0,0,0,0,0,0,0,0
0,0,0,0,0,0,0,0,0,0,0,0,0,0,0,0
0,0,0,0,0,0,0,0,0,0,0,0,0,0,0,0
0,0,0,0,0,0,0,0,0,0,0,0,0,0,0,0
0,0,0,0,0,0,0,0,0,0,0,0,0,0,0,0
0,0,0,0,0,0,0,0,0,0,0,0,0,0,0,0
0,0,0,0,0,0,0,0,0,0,0,0,0,0,0,0
0,0,0,0,0,0,0,0,0,0,0,0,0,0,0,0
:endlayer
layer: 46
0,0,0,0,0,0,0,0,0,0,0,0,0,0,0,0
0,0,0,0,0,0,0,0,0,0,0,0,0,0,0,0
0,0,0,0,0,0,0,0,0,0,0,0,0,0,0,0
0,0,0,0,0,0,0,0,0,0,0,0,0,0,0,0
0,0,0,0,0,0,0,0,0,0,0,0,0,0,0,0
0,0,0,0,0,0,0,0,0,0,0,0,0,0,0,0
0,0,0,0,0,0,0,0,0,0,0,0,0,0,0,0
0,0,0,0,0,0,0,0,0,0,0,0,0,0,0,0
0,0,0,0,0,0,0,0,0,0,0,0,0,0,0,0
0,0,0,0,0,0,0,0,0,0,0,0,0,0,0,0
0,0,0,0,0,0,0,0,0,0,0,0,0,0,0,0
0,0,0,0,0,0,0,0,0,0,0,0,0,0,0,0
0,0,0,0,0,0,0,0,0,0,0,0,0,0,0,0
0,0,0,0,0,0,0,0,0,0,0,0,0,0,0,0
:endlayer
layer: 47
0,0,0,0,0,0,0,0,0,0,0,0,0,0,0,0
0,0,0,0,0,0,0,0,0,0,0,0,0,0,0,0
0,0,0,0,0,0,0,0,0,0,0,0,0,0,0,0
0,0,0,0,0,0,0,0,0,0,0,0,0,0,0,0
0,0,0,0,0,0,0,0,0,0,0,0,0,0,0,0
0,0,0,0,0,0,0,0,0,0,0,0,0,0,0,0
0,0,0,0,0,0,0,0,0,0,0,0,0,0,0,0
0,0,0,0,0,0,0,0,0,0,0,0,0,0,0,0
0,0,0,0,0,0,0,0,0,0,0,0,0,0,0,0
0,0,0,0,0,0,0,0,0,0,0,0,0,0,0,0
0,0,0,0,0,0,0,0,0,0,0,0,0,0,0,0
0,0,0,0,0,0,0,0,0,0,0,0,0,0,0,0
0,0,0,0,0,0,0,0,0,0,0,0,0,0,0,0
0,0,0,0,0,0,0,0,0,0,0,0,0,0,0,0
:endlayer
layer: 48
0,0,0,0,0,0,0,0,0,0,0,0,0,0,0,0
0,0,0,0,0,0,0,0,0,0,0,0,0,0,0,0
0,0,0,0,0,0,0,0,0,0,0,0,0,0,0,0
0,0,0,0,0,0,0,0,0,0,0,0,0,0,0,0
0,0,0,0,0,0,0,0,0,0,0,0,0,0,0,0
0,0,0,0,0,0,0,0,0,0,0,0,0,0,0,0
0,0,0,0,0,0,0,0,0,0,0,0,0,0,0,0
0,0,0,0,0,0,0,0,0,0,0,0,0,0,0,0
0,0,0,0,0,0,0,0,0,0,0,0,0,0,0,0
0,0,0,0,0,0,0,0,0,0,0,0,0,0,0,0
0,0,0,0,0,0,0,0,0,0,0,0,0,0,0,0
0,0,0,0,0,0,0,0,0,0,0,0,0,0,0,0
0,0,0,0,0,0,0,0,0,0,0,0,0,0,0,0
0,0,0,0,0,0,0,0,0,0,0,0,0,0,0,0
:endlayer
layer: 49
0,0,0,0,0,0,0,0,0,0,0,0,0,0,0,0
0,0,0,0,0,0,0,0,0,0,0,0,0,0,0,0
0,0,0,0,0,0,0,0,0,0,0,0,0,0,0,0
0,0,0,0,0,0,0,0,0,0,0,0,0,0,0,0
0,0,0,0,0,0,0,0,0,0,0,0,0,0,0,0
0,0,0,0,0,0,0,0,0,0,0,0,0,0,0,0
0,0,0,0,0,0,0,0,0,0,0,0,0,0,0,0
0,0,0,0,0,0,0,0,0,0,0,0,0,0,0,0
0,0,0,0,0,0,0,0,0,0,0,0,0,0,0,0
0,0,0,0,0,0,0,0,0,0,0,0,0,0,0,0
0,0,0,0,0,0,0,0,0,0,0,0,0,0,0,0
0,0,0,0,0,0,0,0,0,0,0,0,0,0,0,0
0,0,0,0,0,0,0,0,0,0,0,0,0,0,0,0
0,0,0,0,0,0,0,0,0,0,0,0,0,0,0,0
:endlayer
layer: 50
0,0,0,0,0,0,0,0,0,0,0,0,0,0,0,0
0,0,0,0,0,0,0,0,0,0,0,0,0,0,0,0
0,0,0,0,0,0,0,0,0,0,0,0,0,0,0,0
0,0,0,0,0,0,0,0,0,0,0,0,0,0,0,0
0,0,0,0,0,0,0,0,0,0,0,0,0,0,0,0
0,0,0,0,0,0,0,0,0,0,0,0,0,0,0,0
0,0,0,0,0,0,0,0,0,0,0,0,0,0,0,0
0,0,0,0,0,0,0,0,0,0,0,0,0,0,0,0
0,0,0,0,0,0,0,0,0,0,0,0,0,0,0,0
0,0,0,0,0,0,0,0,0,0,0,0,0,0,0,0
0,0,0,0,0,0,0,0,0,0,0,0,0,0,0,0
0,0,0,0,0,0,0,0,0,0,0,0,0,0,0,0
0,0,0,0,0,0,0,0,0,0,0,0,0,0,0,0
0,0,0,0,0,0,0,0,0,0,0,0,0,0,0,0
:endlayer
layer: 51
0,0,0,0,0,0,0,0,0,0,0,0,0,0,0,0
0,0,0,0,0,0,0,0,0,0,0,0,0,0,0,0
0,0,0,0,0,0,0,0,0,0,0,0,0,0,0,0
0,0,0,0,0,0,0,0,0,0,0,0,0,0,0,0
0,0,0,0,0,0,0,0,0,0,0,0,0,0,0,0
0,0,0,0,0,0,0,0,0,0,0,0,0,0,0,0
0,0,0,0,0,0,0,0,0,0,0,0,0,0,0,0
0,0,0,0,0,0,0,0,0,0,0,0,0,0,0,0
0,0,0,0,0,0,0,0,0,0,0,0,0,0,0,0
0,0,0,0,0,0,0,0,0,0,0,0,0,0,0,0
0,0,0,0,0,0,0,0,0,0,0,0,0,0,0,0
0,0,0,0,0,0,0,0,0,0,0,0,0,0,0,0
0,0,0,0,0,0,0,0,0,0,0,0,0,0,0,0
0,0,0,0,0,0,0,0,0,0,0,0,0,0,0,0
:endlayer
layer: 52
0,0,0,0,0,0,0,0,0,0,0,0,0,0,0,0
0,0,0,0,0,0,0,0,0,0,0,0,0,0,0,0
0,0,0,0,0,0,0,0,0,0,0,0,0,0,0,0
0,0,0,0,0,0,0,0,0,0,0,0,0,0,0,0
0,0,0,0,0,0,0,0,0,0,0,0,0,0,0,0
0,0,0,0,0,0,0,0,0,0,0,0,0,0,0,0
0,0,0,0,0,0,0,0,0,0,0,0,0,0,0,0
0,0,0,0,0,0,0,0,0,0,0,0,0,0,0,0
0,0,0,0,0,0,0,0,0,0,0,0,0,0,0,0
0,0,0,0,0,0,0,0,0,0,0,0,0,0,0,0
0,0,0,0,0,0,0,0,0,0,0,0,0,0,0,0
0,0,0,0,0,0,0,0,0,0,0,0,0,0,0,0
0,0,0,0,0,0,0,0,0,0,0,0,0,0,0,0
0,0,0,0,0,0,0,0,0,0,0,0,0,0,0,0
:endlayer
layer: 53
0,0,0,0,0,0,0,0,0,0,0,0,0,0,0,0
0,0,0,0,0,0,0,0,0,0,0,0,0,0,0,0
0,0,0,0,0,0,0,0,0,0,0,0,0,0,0,0
0,0,0,0,0,0,0,0,0,0,0,0,0,0,0,0
0,0,0,0,0,0,0,0,0,0,0,0,0,0,0,0
0,0,0,0,0,0,0,0,0,0,0,0,0,0,0,0
0,0,0,0,0,0,0,0,0,0,0,0,0,0,0,0
0,0,0,0,0,0,0,0,0,0,0,0,0,0,0,0
0,0,0,0,0,0,0,0,0,0,0,0,0,0,0,0
0,0,0,0,0,0,0,0,0,0,0,0,0,0,0,0
0,0,0,0,0,0,0,0,0,0,0,0,0,0,0,0
0,0,0,0,0,0,0,0,0,0,0,0,0,0,0,0
0,0,0,0,0,0,0,0,0,0,0,0,0,0,0,0
0,0,0,0,0,0,0,0,0,0,0,0,0,0,0,0
:endlayer
layer: 54
0,0,0,0,0,0,0,0,0,0,0,0,0,0,0,0
0,0,0,0,0,0,0,0,0,0,0,0,0,0,0,0
0,0,0,0,0,0,0,0,0,0,0,0,0,0,0,0
0,0,0,0,0,0,0,0,0,0,0,0,0,0,0,0
0,0,0,0,0,0,0,0,0,0,0,0,0,0,0,0
0,0,0,0,0,0,0,0,0,0,0,0,0,0,0,0
0,0,0,0,0,0,0,0,0,0,0,0,0,0,0,0
0,0,0,0,0,0,0,0,0,0,0,0,0,0,0,0
0,0,0,0,0,0,0,0,0,0,0,0,0,0,0,0
0,0,0,0,0,0,0,0,0,0,0,0,0,0,0,0
0,0,0,0,0,0,0,0,0,0,0,0,0,0,0,0
0,0,0,0,0,0,0,0,0,0,0,0,0,0,0,0
0,0,0,0,0,0,0,0,0,0,0,0,0,0,0,0
0,0,0,0,0,0,0,0,0,0,0,0,0,0,0,0
:endlayer
layer: 55
0,0,0,0,0,0,0,0,0,0,0,0,0,0,0,0
0,0,0,0,0,0,0,0,0,0,0,0,0,0,0,0
0,0,0,0,0,0,0,0,0,0,0,0,0,0,0,0
0,0,0,0,0,0,0,0,0,0,0,0,0,0,0,0
0,0,0,0,0,0,0,0,0,0,0,0,0,0,0,0
0,0,0,0,0,0,0,0,0,0,0,0,0,0,0,0
0,0,0,0,0,0,0,0,0,0,0,0,0,0,0,0
0,0,0,0,0,0,0,0,0,0,0,0,0,0,0,0
0,0,0,0,0,0,0,0,0,0,0,0,0,0,0,0
0,0,0,0,0,0,0,0,0,0,0,0,0,0,0,0
0,0,0,0,0,0,0,0,0,0,0,0,0,0,0,0
0,0,0,0,0,0,0,0,0,0,0,0,0,0,0,0
0,0,0,0,0,0,0,0,0,0,0,0,0,0,0,0
0,0,0,0,0,0,0,0,0,0,0,0,0,0,0,0
:endlayer
layer: 56
0,0,0,0,0,0,0,0,0,0,0,0,0,0,0,0
0,0,0,0,0,0,0,0,0,0,0,0,0,0,0,0
0,0,0,0,0,0,0,0,0,0,0,0,0,0,0,0
0,0,0,0,0,0,0,0,0,0,0,0,0,0,0,0
0,0,0,0,0,0,0,0,0,0,0,0,0,0,0,0
0,0,0,0,0,0,0,0,0,0,0,0,0,0,0,0
0,0,0,0,0,0,0,0,0,0,0,0,0,0,0,0
0,0,0,0,0,0,0,0,0,0,0,0,0,0,0,0
0,0,0,0,0,0,0,0,0,0,0,0,0,0,0,0
0,0,0,0,0,0,0,0,0,0,0,0,0,0,0,0
0,0,0,0,0,0,0,0,0,0,0,0,0,0,0,0
0,0,0,0,0,0,0,0,0,0,0,0,0,0,0,0
0,0,0,0,0,0,0,0,0,0,0,0,0,0,0,0
0,0,0,0,0,0,0,0,0,0,0,0,0,0,0,0
:endlayer
layer: 57
0,0,0,0,0,0,0,0,0,0,0,0,0,0,0,0
0,0,0,0,0,0,0,0,0,0,0,0,0,0,0,0
0,0,0,0,0,0,0,0,0,0,0,0,0,0,0,0
0,0,0,0,0,0,0,0,0,0,0,0,0,0,0,0
0,0,0,0,0,0,0,0,0,0,0,0,0,0,0,0
0,0,0,0,0,0,0,0,0,0,0,0,0,0,0,0
0,0,0,0,0,0,0,0,0,0,0,0,0,0,0,0
0,0,0,0,0,0,0,0,0,0,0,0,0,0,0,0
0,0,0,0,0,0,0,0,0,0,0,0,0,0,0,0
0,0,0,0,0,0,0,0,0,0,0,0,0,0,0,0
0,0,0,0,0,0,0,0,0,0,0,0,0,0,0,0
0,0,0,0,0,0,0,0,0,0,0,0,0,0,0,0
0,0,0,0,0,0,0,0,0,0,0,0,0,0,0,0
0,0,0,0,0,0,0,0,0,0,0,0,0,0,0,0
:endlayer
layer: 58
0,0,0,0,0,0,0,0,0,0,0,0,0,0,0,0
0,0,0,0,0,0,0,0,0,0,0,0,0,0,0,0
0,0,0,0,0,0,0,0,0,0,0,0,0,0,0,0
0,0,0,0,0,0,0,0,0,0,0,0,0,0,0,0
0,0,0,0,0,0,0,0,0,0,0,0,0,0,0,0
0,0,0,0,0,0,0,0,0,0,0,0,0,0,0,0
0,0,0,0,0,0,0,0,0,0,0,0,0,0,0,0
0,0,0,0,0,0,0,0,0,0,0,0,0,0,0,0
0,0,0,0,0,0,0,0,0,0,0,0,0,0,0,0
0,0,0,0,0,0,0,0,0,0,0,0,0,0,0,0
0,0,0,0,0,0,0,0,0,0,0,0,0,0,0,0
0,0,0,0,0,0,0,0,0,0,0,0,0,0,0,0
0,0,0,0,0,0,0,0,0,0,0,0,0,0,0,0
0,0,0,0,0,0,0,0,0,0,0,0,0,0,0,0
:endlayer
layer: 59
0,0,0,0,0,0,0,0,0,0,0,0,0,0,0,0
0,0,0,0,0,0,0,0,0,0,0,0,0,0,0,0
0,0,0,0,0,0,0,0,0,0,0,0,0,0,0,0
0,0,0,0,0,0,0,0,0,0,0,0,0,0,0,0
0,0,0,0,0,0,0,0,0,0,0,0,0,0,0,0
0,0,0,0,0,0,0,0,0,0,0,0,0,0,0,0
0,0,0,0,0,0,0,0,0,0,0,0,0,0,0,0
0,0,0,0,0,0,0,0,0,0,0,0,0,0,0,0
0,0,0,0,0,0,0,0,0,0,0,0,0,0,0,0
0,0,0,0,0,0,0,0,0,0,0,0,0,0,0,0
0,0,0,0,0,0,0,0,0,0,0,0,0,0,0,0
0,0,0,0,0,0,0,0,0,0,0,0,0,0,0,0
0,0,0,0,0,0,0,0,0,0,0,0,0,0,0,0
0,0,0,0,0,0,0,0,0,0,0,0,0,0,0,0
:endlayer
layer: 60
0,0,0,0,0,0,0,0,0,0,0,0,0,0,0,0
0,0,0,0,0,0,0,0,0,0,0,0,0,0,0,0
0,0,0,0,0,0,0,0,0,0,0,0,0,0,0,0
0,0,0,0,0,0,0,0,0,0,0,0,0,0,0,0
0,0,0,0,0,0,0,0,0,0,0,0,0,0,0,0
0,0,0,0,0,0,0,0,0,0,0,0,0,0,0,0
0,0,0,0,0,0,0,0,0,0,0,0,0,0,0,0
0,0,0,0,0,0,0,0,0,0,0,0,0,0,0,0
0,0,0,0,0,0,0,0,0,0,0,0,0,0,0,0
0,0,0,0,0,0,0,0,0,0,0,0,0,0,0,0
0,0,0,0,0,0,0,0,0,0,0,0,0,0,0,0
0,0,0,0,0,0,0,0,0,0,0,0,0,0,0,0
0,0,0,0,0,0,0,0,0,0,0,0,0,0,0,0
0,0,0,0,0,0,0,0,0,0,0,0,0,0,0,0
:endlayer
layer: 61
0,0,0,0,0,0,0,0,0,0,0,0,0,0,0,0
0,0,0,0,0,0,0,0,0,0,0,0,0,0,0,0
0,0,0,0,0,0,0,0,0,0,0,0,0,0,0,0
0,0,0,0,0,0,0,0,0,0,0,0,0,0,0,0
0,0,0,0,0,0,0,0,0,0,0,0,0,0,0,0
0,0,0,0,0,0,0,0,0,0,0,0,0,0,0,0
0,0,0,0,0,0,0,0,0,0,0,0,0,0,0,0
0,0,0,0,0,0,0,0,0,0,0,0,0,0,0,0
0,0,0,0,0,0,0,0,0,0,0,0,0,0,0,0
0,0,0,0,0,0,0,0,0,0,0,0,0,0,0,0
0,0,0,0,0,0,0,0,0,0,0,0,0,0,0,0
0,0,0,0,0,0,0,0,0,0,0,0,0,0,0,0
0,0,0,0,0,0,0,0,0,0,0,0,0,0,0,0
0,0,0,0,0,0,0,0,0,0,0,0,0,0,0,0
:endlayer
layer: 62
0,0,0,0,0,0,0,0,0,0,0,0,0,0,0,0
0,0,0,0,0,0,0,0,0,0,0,0,0,0,0,0
0,0,0,0,0,0,0,0,0,0,0,0,0,0,0,0
0,0,0,0,0,0,0,0,0,0,0,0,0,0,0,0
0,0,0,0,0,0,0,0,0,0,0,0,0,0,0,0
0,0,0,0,0,0,0,0,0,0,0,0,0,0,0,0
0,0,0,0,0,0,0,0,0,0,0,0,0,0,0,0
0,0,0,0,0,0,0,0,0,0,0,0,0,0,0,0
0,0,0,0,0,0,0,0,0,0,0,0,0,0,0,0
0,0,0,0,0,0,0,0,0,0,0,0,0,0,0,0
0,0,0,0,0,0,0,0,0,0,0,0,0,0,0,0
0,0,0,0,0,0,0,0,0,0,0,0,0,0,0,0
0,0,0,0,0,0,0,0,0,0,0,0,0,0,0,0
0,0,0,0,0,0,0,0,0,0,0,0,0,0,0,0
:endlayer
layer: 63
0,0,0,0,0,0,0,0,0,0,0,0,0,0,0,0
0,0,0,0,0,0,0,0,0,0,0,0,0,0,0,0
0,0,0,0,0,0,0,0,0,0,0,0,0,0,0,0
0,0,0,0,0,0,0,0,0,0,0,0,0,0,0,0
0,0,0,0,0,0,0,0,0,0,0,0,0,0,0,0
0,0,0,0,0,0,0,0,0,0,0,0,0,0,0,0
0,0,0,0,0,0,0,0,0,0,0,0,0,0,0,0
0,0,0,0,0,0,0,0,0,0,0,0,0,0,0,0
0,0,0,0,0,0,0,0,0,0,0,0,0,0,0,0
0,0,0,0,0,0,0,0,0,0,0,0,0,0,0,0
0,0,0,0,0,0,0,0,0,0,0,0,0,0,0,0
0,0,0,0,0,0,0,0,0,0,0,0,0,0,0,0
0,0,0,0,0,0,0,0,0,0,0,0,0,0,0,0
0,0,0,0,0,0,0,0,0,0,0,0,0,0,0,0
:endlayer
layer: 64
0,0,0,0,0,0,0,0,0,0,0,0,0,0,0,0
0,0,0,0,0,0,0,0,0,0,0,0,0,0,0,0
0,0,0,0,0,0,0,0,0,0,0,0,0,0,0,0
0,0,0,0,0,0,0,0,0,0,0,0,0,0,0,0
0,0,0,0,0,0,0,0,0,0,0,0,0,0,0,0
0,0,0,0,0,0,0,0,0,0,0,0,0,0,0,0
0,0,0,0,0,0,0,0,0,0,0,0,0,0,0,0
0,0,0,0,0,0,0,0,0,0,0,0,0,0,0,0
0,0,0,0,0,0,0,0,0,0,0,0,0,0,0,0
0,0,0,0,0,0,0,0,0,0,0,0,0,0,0,0
0,0,0,0,0,0,0,0,0,0,0,0,0,0,0,0
0,0,0,0,0,0,0,0,0,0,0,0,0,0,0,0
0,0,0,0,0,0,0,0,0,0,0,0,0,0,0,0
0,0,0,0,0,0,0,0,0,0,0,0,0,0,0,0
:endlayer
layer: 65
0,0,0,0,0,0,0,0,0,0,0,0,0,0,0,0
0,0,0,0,0,0,0,0,0,0,0,0,0,0,0,0
0,0,0,0,0,0,0,0,0,0,0,0,0,0,0,0
0,0,0,0,0,0,0,0,0,0,0,0,0,0,0,0
0,0,0,0,0,0,0,0,0,0,0,0,0,0,0,0
0,0,0,0,0,0,0,0,0,0,0,0,0,0,0,0
0,0,0,0,0,0,0,0,0,0,0,0,0,0,0,0
0,0,0,0,0,0,0,0,0,0,0,0,0,0,0,0
0,0,0,0,0,0,0,0,0,0,0,0,0,0,0,0
0,0,0,0,0,0,0,0,0,0,0,0,0,0,0,0
0,0,0,0,0,0,0,0,0,0,0,0,0,0,0,0
0,0,0,0,0,0,0,0,0,0,0,0,0,0,0,0
0,0,0,0,0,0,0,0,0,0,0,0,0,0,0,0
0,0,0,0,0,0,0,0,0,0,0,0,0,0,0,0
:endlayer
layer: 66
0,0,0,0,0,0,0,0,0,0,0,0,0,0,0,0
0,0,0,0,0,0,0,0,0,0,0,0,0,0,0,0
0,0,0,0,0,0,0,0,0,0,0,0,0,0,0,0
0,0,0,0,0,0,0,0,0,0,0,0,0,0,0,0
0,0,0,0,0,0,0,0,0,0,0,0,0,0,0,0
0,0,0,0,0,0,0,0,0,0,0,0,0,0,0,0
0,0,0,0,0,0,0,0,0,0,0,0,0,0,0,0
0,0,0,0,0,0,0,0,0,0,0,0,0,0,0,0
0,0,0,0,0,0,0,0,0,0,0,0,0,0,0,0
0,0,0,0,0,0,0,0,0,0,0,0,0,0,0,0
0,0,0,0,0,0,0,0,0,0,0,0,0,0,0,0
0,0,0,0,0,0,0,0,0,0,0,0,0,0,0,0
0,0,0,0,0,0,0,0,0,0,0,0,0,0,0,0
0,0,0,0,0,0,0,0,0,0,0,0,0,0,0,0
:endlayer
layer: 67
0,0,0,0,0,0,0,0,0,0,0,0,0,0,0,0
0,0,0,0,0,0,0,0,0,0,0,0,0,0,0,0
0,0,0,0,0,0,0,0,0,0,0,0,0,0,0,0
0,0,0,0,0,0,0,0,0,0,0,0,0,0,0,0
0,0,0,0,0,0,0,0,0,0,0,0,0,0,0,0
0,0,0,0,0,0,0,0,0,0,0,0,0,0,0,0
0,0,0,0,0,0,0,0,0,0,0,0,0,0,0,0
0,0,0,0,0,0,0,0,0,0,0,0,0,0,0,0
0,0,0,0,0,0,0,0,0,0,0,0,0,0,0,0
0,0,0,0,0,0,0,0,0,0,0,0,0,0,0,0
0,0,0,0,0,0,0,0,0,0,0,0,0,0,0,0
0,0,0,0,0,0,0,0,0,0,0,0,0,0,0,0
0,0,0,0,0,0,0,0,0,0,0,0,0,0,0,0
0,0,0,0,0,0,0,0,0,0,0,0,0,0,0,0
:endlayer
layer: 68
0,0,0,0,0,0,0,0,0,0,0,0,0,0,0,0
0,0,0,0,0,0,0,0,0,0,0,0,0,0,0,0
0,0,0,0,0,0,0,0,0,0,0,0,0,0,0,0
0,0,0,0,0,0,0,0,0,0,0,0,0,0,0,0
0,0,0,0,0,0,0,0,0,0,0,0,0,0,0,0
0,0,0,0,0,0,0,0,0,0,0,0,0,0,0,0
0,0,0,0,0,0,0,0,0,0,0,0,0,0,0,0
0,0,0,0,0,0,0,0,0,0,0,0,0,0,0,0
0,0,0,0,0,0,0,0,0,0,0,0,0,0,0,0
0,0,0,0,0,0,0,0,0,0,0,0,0,0,0,0
0,0,0,0,0,0,0,0,0,0,0,0,0,0,0,0
0,0,0,0,0,0,0,0,0,0,0,0,0,0,0,0
0,0,0,0,0,0,0,0,0,0,0,0,0,0,0,0
0,0,0,0,0,0,0,0,0,0,0,0,0,0,0,0
:endlayer
layer: 69
0,0,0,0,0,0,0,0,0,0,0,0,0,0,0,0
0,0,0,0,0,0,0,0,0,0,0,0,0,0,0,0
0,0,0,0,0,0,0,0,0,0,0,0,0,0,0,0
0,0,0,0,0,0,0,0,0,0,0,0,0,0,0,0
0,0,0,0,0,0,0,0,0,0,0,0,0,0,0,0
0,0,0,0,0,0,0,0,0,0,0,0,0,0,0,0
0,0,0,0,0,0,0,0,0,0,0,0,0,0,0,0
0,0,0,0,0,0,0,0,0,0,0,0,0,0,0,0
0,0,0,0,0,0,0,0,0,0,0,0,0,0,0,0
0,0,0,0,0,0,0,0,0,0,0,0,0,0,0,0
0,0,0,0,0,0,0,0,0,0,0,0,0,0,0,0
0,0,0,0,0,0,0,0,0,0,0,0,0,0,0,0
0,0,0,0,0,0,0,0,0,0,0,0,0,0,0,0
0,0,0,0,0,0,0,0,0,0,0,0,0,0,0,0
:endlayer
layer: 70
0,0,0,0,0,0,0,0,0,0,0,0,0,0,0,0
0,0,0,0,0,0,0,0,0,0,0,0,0,0,0,0
0,0,0,0,0,0,0,0,0,0,0,0,0,0,0,0
0,0,0,0,0,0,0,0,0,0,0,0,0,0,0,0
0,0,0,0,0,0,0,0,0,0,0,0,0,0,0,0
0,0,0,0,0,0,0,0,0,0,0,0,0,0,0,0
0,0,0,0,0,0,0,0,0,0,0,0,0,0,0,0
0,0,0,0,0,0,0,0,0,0,0,0,0,0,0,0
0,0,0,0,0,0,0,0,0,0,0,0,0,0,0,0
0,0,0,0,0,0,0,0,0,0,0,0,0,0,0,0
0,0,0,0,0,0,0,0,0,0,0,0,0,0,0,0
0,0,0,0,0,0,0,0,0,0,0,0,0,0,0,0
0,0,0,0,0,0,0,0,0,0,0,0,0,0,0,0
0,0,0,0,0,0,0,0,0,0,0,0,0,0,0,0
:endlayer

#### RULES ####
rule:
plugin=vanillaBlocks
number=1
data:
JSON:{{"val":{"blockName":{"val":"minecraft:dirt","id":"ss"},"meta":{"val":"0","id":"pi"},"buildPass":{"val":"0","id":"pi"}},"id":"ct"}}
:enddata
:endrule

rule:
plugin=vanillaBlocks
number=2
data:
JSON:{{"val":{"blockName":{"val":"minecraft:grass","id":"ss"},"meta":{"val":"0","id":"pi"},"buildPass":{"val":"0","id":"pi"}},"id":"ct"}}
:enddata
:endrule

rule:
plugin=vanillaBlocks
number=3
data:
JSON:{{"val":{"blockName":{"val":"minecraft:snow_layer","id":"ss"},"meta":{"val":"0","id":"pi"},"buildPass":{"val":"2","id":"pi"}},"id":"ct"}}
:enddata
:endrule

rule:
plugin=vanillaBlocks
number=4
data:
JSON:{{"val":{"blockName":{"val":"minecraft:tallgrass","id":"ss"},"meta":{"val":"1","id":"pi"},"buildPass":{"val":"2","id":"pi"}},"id":"ct"}}
:enddata
:endrule

rule:
plugin=vanillaBlocks
number=5
data:
JSON:{{"val":{"blockName":{"val":"minecraft:cobblestone","id":"ss"},"meta":{"val":"0","id":"pi"},"buildPass":{"val":"0","id":"pi"}},"id":"ct"}}
:enddata
:endrule

rule:
plugin=vanillaBlocks
number=6
data:
JSON:{{"val":{"blockName":{"val":"minecraft:stonebrick","id":"ss"},"meta":{"val":"0","id":"pi"},"buildPass":{"val":"0","id":"pi"}},"id":"ct"}}
:enddata
:endrule

rule:
plugin=vanillaBlocks
number=7
data:
JSON:{{"val":{"blockName":{"val":"minecraft:mossy_cobblestone","id":"ss"},"meta":{"val":"0","id":"pi"},"buildPass":{"val":"0","id":"pi"}},"id":"ct"}}
:enddata
:endrule

rule:
plugin=vanillaBlocks
number=8
data:
JSON:{{"val":{"blockName":{"val":"minecraft:red_flower","id":"ss"},"meta":{"val":"0","id":"pi"},"buildPass":{"val":"2","id":"pi"}},"id":"ct"}}
:enddata
:endrule

rule:
plugin=vanillaBlocks
number=9
data:
JSON:{{"val":{"blockName":{"val":"minecraft:stone_stairs","id":"ss"},"meta":{"val":"0","id":"pi"},"buildPass":{"val":"0","id":"pi"}},"id":"ct"}}
:enddata
:endrule

rule:
plugin=vanillaBlocks
number=10
data:
JSON:{{"val":{"blockName":{"val":"minecraft:log","id":"ss"},"meta":{"val":"1","id":"pi"},"buildPass":{"val":"0","id":"pi"}},"id":"ct"}}
:enddata
:endrule

rule:
plugin=vanillaBlocks
number=11
data:
JSON:{{"val":{"blockName":{"val":"minecraft:stone_slab","id":"ss"},"meta":{"val":"3","id":"pi"},"buildPass":{"val":"0","id":"pi"}},"id":"ct"}}
:enddata
:endrule

rule:
plugin=vanillaBlocks
number=12
data:
JSON:{{"val":{"blockName":{"val":"minecraft:double_stone_slab","id":"ss"},"meta":{"val":"5","id":"pi"},"buildPass":{"val":"0","id":"pi"}},"id":"ct"}}
:enddata
:endrule

rule:
plugin=vanillaBlocks
number=13
data:
JSON:{{"val":{"blockName":{"val":"minecraft:stone_brick_stairs","id":"ss"},"meta":{"val":"2","id":"pi"},"buildPass":{"val":"0","id":"pi"}},"id":"ct"}}
:enddata
:endrule

rule:
plugin=vanillaBlocks
number=14
data:
JSON:{{"val":{"blockName":{"val":"minecraft:double_stone_slab","id":"ss"},"meta":{"val":"3","id":"pi"},"buildPass":{"val":"0","id":"pi"}},"id":"ct"}}
:enddata
:endrule

rule:
plugin=vanillaBlocks
number=15
data:
JSON:{{"val":{"blockName":{"val":"minecraft:fence","id":"ss"},"meta":{"val":"0","id":"pi"},"buildPass":{"val":"0","id":"pi"}},"id":"ct"}}
:enddata
:endrule

rule:
plugin=vanillaBlocks
number=16
data:
JSON:{{"val":{"blockName":{"val":"minecraft:yellow_flower","id":"ss"},"meta":{"val":"0","id":"pi"},"buildPass":{"val":"2","id":"pi"}},"id":"ct"}}
:enddata
:endrule

rule:
plugin=vanillaInventory
number=17
data:
JSON:{{"val":{"lootLevel":{"val":"0","id":"pi"},"inventoryData":{"val":{"length":{"val":"27","id":"pi"},"inventoryContents":{"val":[],"id":"ls"}},"id":"ct"},"teData":{"val":{"id":{"val":"Chest","id":"ss"},"z":{"val":"1889","id":"pi"},"y":{"val":"106","id":"pi"},"x":{"val":"1392","id":"pi"}},"id":"ct"},"blockName":{"val":"minecraft:chest","id":"ss"},"meta":{"val":"3","id":"pi"},"buildPass":{"val":"0","id":"pi"}},"id":"ct"}}
:enddata
:endrule

rule:
plugin=vanillaBlocks
number=18
data:
JSON:{{"val":{"blockName":{"val":"minecraft:crafting_table","id":"ss"},"meta":{"val":"0","id":"pi"},"buildPass":{"val":"0","id":"pi"}},"id":"ct"}}
:enddata
:endrule

rule:
plugin=vanillaInventory
number=19
data:
JSON:{{"val":{"lootLevel":{"val":"0","id":"pi"},"inventoryData":{"val":{"length":{"val":"27","id":"pi"},"inventoryContents":{"val":[],"id":"ls"}},"id":"ct"},"teData":{"val":{"id":{"val":"Chest","id":"ss"},"z":{"val":"1889","id":"pi"},"y":{"val":"106","id":"pi"},"x":{"val":"1394","id":"pi"}},"id":"ct"},"blockName":{"val":"minecraft:chest","id":"ss"},"meta":{"val":"3","id":"pi"},"buildPass":{"val":"0","id":"pi"}},"id":"ct"}}
:enddata
:endrule

rule:
plugin=vanillaInventory
number=20
data:
JSON:{{"val":{"lootLevel":{"val":"0","id":"pi"},"inventoryData":{"val":{"length":{"val":"27","id":"pi"},"inventoryContents":{"val":[],"id":"ls"}},"id":"ct"},"teData":{"val":{"id":{"val":"Chest","id":"ss"},"z":{"val":"1890","id":"pi"},"y":{"val":"106","id":"pi"},"x":{"val":"1394","id":"pi"}},"id":"ct"},"blockName":{"val":"minecraft:chest","id":"ss"},"meta":{"val":"3","id":"pi"},"buildPass":{"val":"0","id":"pi"}},"id":"ct"}}
:enddata
:endrule

rule:
plugin=vanillaDoors
number=21
data:
JSON:{{"val":{"sideFlag":{"val":"8","id":"pb"},"blockName":{"val":"minecraft:iron_door","id":"ss"},"meta":{"val":"3","id":"pi"},"buildPass":{"val":"2","id":"pi"}},"id":"ct"}}
:enddata
:endrule

rule:
plugin=vanillaBlocks
number=22
data:
JSON:{{"val":{"blockName":{"val":"minecraft:stone_slab","id":"ss"},"meta":{"val":"5","id":"pi"},"buildPass":{"val":"0","id":"pi"}},"id":"ct"}}
:enddata
:endrule

rule:
plugin=vanillaBlocks
number=23
data:
JSON:{{"val":{"blockName":{"val":"minecraft:stone_slab","id":"ss"},"meta":{"val":"13","id":"pi"},"buildPass":{"val":"0","id":"pi"}},"id":"ct"}}
:enddata
:endrule

rule:
plugin=vanillaBlocks
number=24
data:
JSON:{{"val":{"blockName":{"val":"minecraft:torch","id":"ss"},"meta":{"val":"5","id":"pi"},"buildPass":{"val":"2","id":"pi"}},"id":"ct"}}
:enddata
:endrule

rule:
plugin=vanillaBlocks
number=25
data:
JSON:{{"val":{"blockName":{"val":"minecraft:stone_brick_stairs","id":"ss"},"meta":{"val":"0","id":"pi"},"buildPass":{"val":"0","id":"pi"}},"id":"ct"}}
:enddata
:endrule

rule:
plugin=vanillaBlocks
number=26
data:
JSON:{{"val":{"blockName":{"val":"minecraft:stone_brick_stairs","id":"ss"},"meta":{"val":"3","id":"pi"},"buildPass":{"val":"0","id":"pi"}},"id":"ct"}}
:enddata
:endrule

rule:
plugin=vanillaBlocks
number=27
data:
JSON:{{"val":{"blockName":{"val":"minecraft:torch","id":"ss"},"meta":{"val":"1","id":"pi"},"buildPass":{"val":"2","id":"pi"}},"id":"ct"}}
:enddata
:endrule

rule:
plugin=vanillaDoors
number=28
data:
JSON:{{"val":{"sideFlag":{"val":"0","id":"pb"},"blockName":{"val":"minecraft:iron_door","id":"ss"},"meta":{"val":"8","id":"pi"},"buildPass":{"val":"2","id":"pi"}},"id":"ct"}}
:enddata
:endrule

rule:
plugin=vanillaBlocks
number=29
data:
JSON:{{"val":{"blockName":{"val":"minecraft:stone_brick_stairs","id":"ss"},"meta":{"val":"1","id":"pi"},"buildPass":{"val":"0","id":"pi"}},"id":"ct"}}
:enddata
:endrule

rule:
plugin=vanillaBlocks
number=30
data:
JSON:{{"val":{"blockName":{"val":"minecraft:lever","id":"ss"},"meta":{"val":"7","id":"pi"},"buildPass":{"val":"2","id":"pi"}},"id":"ct"}}
:enddata
:endrule

rule:
plugin=vanillaBlocks
number=31
data:
JSON:{{"val":{"blockName":{"val":"minecraft:planks","id":"ss"},"meta":{"val":"5","id":"pi"},"buildPass":{"val":"0","id":"pi"}},"id":"ct"}}
:enddata
:endrule

rule:
plugin=vanillaBlocks
number=32
data:
JSON:{{"val":{"blockName":{"val":"minecraft:torch","id":"ss"},"meta":{"val":"2","id":"pi"},"buildPass":{"val":"2","id":"pi"}},"id":"ct"}}
:enddata
:endrule

rule:
plugin=vanillaBlocks
number=33
data:
JSON:{{"val":{"blockName":{"val":"minecraft:iron_bars","id":"ss"},"meta":{"val":"0","id":"pi"},"buildPass":{"val":"0","id":"pi"}},"id":"ct"}}
:enddata
:endrule

rule:
plugin=vanillaBlocks
number=34
data:
JSON:{{"val":{"blockName":{"val":"minecraft:torch","id":"ss"},"meta":{"val":"3","id":"pi"},"buildPass":{"val":"2","id":"pi"}},"id":"ct"}}
:enddata
:endrule

rule:
plugin=vanillaBlocks
number=35
data:
JSON:{{"val":{"blockName":{"val":"minecraft:stone_brick_stairs","id":"ss"},"meta":{"val":"4","id":"pi"},"buildPass":{"val":"0","id":"pi"}},"id":"ct"}}
:enddata
:endrule

rule:
plugin=vanillaBlocks
number=36
data:
JSON:{{"val":{"blockName":{"val":"minecraft:stone_brick_stairs","id":"ss"},"meta":{"val":"7","id":"pi"},"buildPass":{"val":"0","id":"pi"}},"id":"ct"}}
:enddata
:endrule

rule:
plugin=vanillaBlocks
number=37
data:
JSON:{{"val":{"blockName":{"val":"minecraft:stone_brick_stairs","id":"ss"},"meta":{"val":"6","id":"pi"},"buildPass":{"val":"0","id":"pi"}},"id":"ct"}}
:enddata
:endrule

rule:
plugin=vanillaBlocks
number=38
data:
JSON:{{"val":{"blockName":{"val":"minecraft:stone_brick_stairs","id":"ss"},"meta":{"val":"5","id":"pi"},"buildPass":{"val":"0","id":"pi"}},"id":"ct"}}
:enddata
:endrule

rule:
plugin=vanillaBlocks
number=39
data:
JSON:{{"val":{"blockName":{"val":"minecraft:stonebrick","id":"ss"},"meta":{"val":"3","id":"pi"},"buildPass":{"val":"0","id":"pi"}},"id":"ct"}}
:enddata
:endrule

rule:
plugin=vanillaBlocks
number=40
data:
JSON:{{"val":{"blockName":{"val":"minecraft:torch","id":"ss"},"meta":{"val":"4","id":"pi"},"buildPass":{"val":"2","id":"pi"}},"id":"ct"}}
:enddata
:endrule

rule:
plugin=vanillaBlocks
number=41
data:
JSON:{{"val":{"blockName":{"val":"minecraft:netherrack","id":"ss"},"meta":{"val":"0","id":"pi"},"buildPass":{"val":"0","id":"pi"}},"id":"ct"}}
:enddata
:endrule

rule:
plugin=vanillaBlocks
number=42
data:
JSON:{{"val":{"blockName":{"val":"minecraft:fire","id":"ss"},"meta":{"val":"15","id":"pi"},"buildPass":{"val":"0","id":"pi"}},"id":"ct"}}
:enddata
:endrule

#### ENTITIES ####
entity:
plugin=AWNpc
number=0
data:
position=9,7,13
JSON:{{"val":{"entityData":{"val":{"DropChances":{"val":[{"val":"1.0","id":"pf"},{"val":"1.0","id":"pf"},{"val":"1.0","id":"pf"},{"val":"1.0","id":"pf"},{"val":"1.0","id":"pf"}],"id":"ls"},"Attributes":{"val":[{"val":{"Name":{"val":"generic.maxHealth","id":"ss"},"Base":{"val":"20.0","id":"pd"}},"id":"ct"},{"val":{"Name":{"val":"generic.knockbackResistance","id":"ss"},"Base":{"val":"0.0","id":"pd"}},"id":"ct"},{"val":{"Name":{"val":"generic.movementSpeed","id":"ss"},"Base":{"val":"0.325","id":"pd"}},"id":"ct"},{"val":{"Name":{"val":"generic.followRange","id":"ss"},"Base":{"val":"60.0","id":"pd"}},"id":"ct"},{"val":{"Name":{"val":"generic.attackDamage","id":"ss"},"Base":{"val":"2.0","id":"pd"}},"id":"ct"}],"id":"ls"},"Motion":{"val":[{"val":"0.0","id":"pd"},{"val":"-0.0784000015258789","id":"pd"},{"val":"0.0","id":"pd"}],"id":"ls"},"CustomName":{"val":"","id":"ss"},"Health":{"val":"20","id":"ps"},"HealF":{"val":"20.0","id":"pf"},"CustomNameVisible":{"val":"0","id":"pb"},"AttackTime":{"val":"0","id":"ps"},"Fire":{"val":"-1","id":"ps"},"attackDamageOverride":{"val":"-1","id":"pi"},"Invulnerable":{"val":"0","id":"pb"},"DeathTime":{"val":"0","id":"ps"},"ForgeData":{"val":{"WITCInitialWidth":{"val":"0.6","id":"pf"},"WITCInitialHeight":{"val":"1.8","id":"pf"}},"id":"ct"},"AbsorptionAmount":{"val":"0.0","id":"pf"},"OnGround":{"val":"1","id":"pb"},"HurtTime":{"val":"0","id":"ps"},"Dimension":{"val":"0","id":"pi"},"Air":{"val":"300","id":"ps"},"customTex":{"val":"","id":"ss"},"armorValueOverride":{"val":"-1","id":"pi"},"Pos":{"val":[{"val":"1387.400517456609","id":"pd"},{"val":"104.0","id":"pd"},{"val":"1892.5","id":"pd"}],"id":"ls"},"CanPickUpLoot":{"val":"0","id":"pb"},"PortalCooldown":{"val":"0","id":"pi"},"PersistenceRequired":{"val":"1","id":"pb"},"shieldStack":{"val":{"item":{"val":"AncientWarfareNpc:iron_shield","id":"ss"},"damage":{"val":"0","id":"pi"},"quantity":{"val":"1","id":"pi"}},"id":"ct"},"Leashed":{"val":"0","id":"pb"},"owner":{"val":"OldMiniCollector","id":"ss"},"FallDistance":{"val":"0.0","id":"pf"},"Rotation":{"val":[{"val":"6.1057925","id":"pf"},{"val":"0.0","id":"pf"}],"id":"ls"},"levelingStats":{"val":{"level":{"val":"0","id":"pi"},"xp":{"val":"0","id":"pi"},"entryList":{"val":[],"id":"ls"}},"id":"ct"}},"id":"ct"},"xOffset":{"val":"0.5","id":"pf"},"mobID":{"val":"AncientWarfareNpc.viking.soldier","id":"ss"},"zOffset":{"val":"0.59948254","id":"pf"},"rotation":{"val":"276.1058","id":"pf"},"equipmentData":{"val":{"equipmentContents":{"val":[{"val":{"item":{"val":"minecraft:iron_sword","id":"ss"},"damage":{"val":"0","id":"pi"},"quantity":{"val":"1","id":"pi"},"slot":{"val":"0","id":"pi"}},"id":"ct"}],"id":"ls"},"length":{"val":"5","id":"pi"}},"id":"ct"}},"id":"ct"}}
:enddata
:endentity

entity:
plugin=AWNpc
number=1
data:
position=8,8,11
JSON:{{"val":{"entityData":{"val":{"DropChances":{"val":[{"val":"1.0","id":"pf"},{"val":"1.0","id":"pf"},{"val":"1.0","id":"pf"},{"val":"1.0","id":"pf"},{"val":"1.0","id":"pf"}],"id":"ls"},"Attributes":{"val":[{"val":{"Name":{"val":"generic.maxHealth","id":"ss"},"Base":{"val":"20.0","id":"pd"}},"id":"ct"},{"val":{"Name":{"val":"generic.knockbackResistance","id":"ss"},"Base":{"val":"0.0","id":"pd"}},"id":"ct"},{"val":{"Name":{"val":"generic.movementSpeed","id":"ss"},"Base":{"val":"0.325","id":"pd"}},"id":"ct"},{"val":{"Name":{"val":"generic.followRange","id":"ss"},"Base":{"val":"60.0","id":"pd"}},"id":"ct"},{"val":{"Name":{"val":"generic.attackDamage","id":"ss"},"Base":{"val":"2.0","id":"pd"}},"id":"ct"}],"id":"ls"},"Motion":{"val":[{"val":"0.0","id":"pd"},{"val":"-0.0784000015258789","id":"pd"},{"val":"0.0","id":"pd"}],"id":"ls"},"CustomName":{"val":"","id":"ss"},"Health":{"val":"20","id":"ps"},"HealF":{"val":"20.0","id":"pf"},"CustomNameVisible":{"val":"0","id":"pb"},"AttackTime":{"val":"0","id":"ps"},"Fire":{"val":"-1","id":"ps"},"attackDamageOverride":{"val":"-1","id":"pi"},"Invulnerable":{"val":"0","id":"pb"},"DeathTime":{"val":"0","id":"ps"},"ForgeData":{"val":{"WITCInitialWidth":{"val":"0.6","id":"pf"},"WITCInitialHeight":{"val":"1.8","id":"pf"}},"id":"ct"},"AbsorptionAmount":{"val":"0.0","id":"pf"},"OnGround":{"val":"1","id":"pb"},"HurtTime":{"val":"0","id":"ps"},"Dimension":{"val":"0","id":"pi"},"Air":{"val":"300","id":"ps"},"customTex":{"val":"","id":"ss"},"armorValueOverride":{"val":"-1","id":"pi"},"Pos":{"val":[{"val":"1389.5","id":"pd"},{"val":"105.5","id":"pd"},{"val":"1891.5","id":"pd"}],"id":"ls"},"CanPickUpLoot":{"val":"0","id":"pb"},"PortalCooldown":{"val":"0","id":"pi"},"PersistenceRequired":{"val":"1","id":"pb"},"shieldStack":{"val":{"item":{"val":"AncientWarfareNpc:iron_shield","id":"ss"},"damage":{"val":"0","id":"pi"},"quantity":{"val":"1","id":"pi"}},"id":"ct"},"Leashed":{"val":"0","id":"pb"},"owner":{"val":"OldMiniCollector","id":"ss"},"FallDistance":{"val":"0.0","id":"pf"},"Rotation":{"val":[{"val":"3.76701","id":"pf"},{"val":"0.0","id":"pf"}],"id":"ls"},"levelingStats":{"val":{"level":{"val":"0","id":"pi"},"xp":{"val":"0","id":"pi"},"entryList":{"val":[],"id":"ls"}},"id":"ct"}},"id":"ct"},"xOffset":{"val":"0.5","id":"pf"},"mobID":{"val":"AncientWarfareNpc.viking.soldier","id":"ss"},"zOffset":{"val":"0.5","id":"pf"},"rotation":{"val":"273.767","id":"pf"},"equipmentData":{"val":{"equipmentContents":{"val":[{"val":{"item":{"val":"minecraft:iron_sword","id":"ss"},"damage":{"val":"0","id":"pi"},"quantity":{"val":"1","id":"pi"},"slot":{"val":"0","id":"pi"}},"id":"ct"}],"id":"ls"},"length":{"val":"5","id":"pi"}},"id":"ct"}},"id":"ct"}}
:enddata
:endentity

entity:
plugin=AWNpc
number=2
data:
position=4,8,4
JSON:{{"val":{"entityData":{"val":{"DropChances":{"val":[{"val":"1.0","id":"pf"},{"val":"1.0","id":"pf"},{"val":"1.0","id":"pf"},{"val":"1.0","id":"pf"},{"val":"1.0","id":"pf"}],"id":"ls"},"Attributes":{"val":[{"val":{"Name":{"val":"generic.maxHealth","id":"ss"},"Base":{"val":"20.0","id":"pd"}},"id":"ct"},{"val":{"Name":{"val":"generic.knockbackResistance","id":"ss"},"Base":{"val":"0.0","id":"pd"}},"id":"ct"},{"val":{"Name":{"val":"generic.movementSpeed","id":"ss"},"Base":{"val":"0.325","id":"pd"}},"id":"ct"},{"val":{"Name":{"val":"generic.followRange","id":"ss"},"Base":{"val":"60.0","id":"pd"}},"id":"ct"},{"val":{"Name":{"val":"generic.attackDamage","id":"ss"},"Base":{"val":"2.0","id":"pd"}},"id":"ct"}],"id":"ls"},"Motion":{"val":[{"val":"0.0","id":"pd"},{"val":"-0.0784000015258789","id":"pd"},{"val":"0.0","id":"pd"}],"id":"ls"},"CustomName":{"val":"","id":"ss"},"Health":{"val":"20","id":"ps"},"HealF":{"val":"20.0","id":"pf"},"CustomNameVisible":{"val":"0","id":"pb"},"AttackTime":{"val":"0","id":"ps"},"Fire":{"val":"-1","id":"ps"},"attackDamageOverride":{"val":"-1","id":"pi"},"Invulnerable":{"val":"0","id":"pb"},"DeathTime":{"val":"0","id":"ps"},"ForgeData":{"val":{"WITCInitialWidth":{"val":"0.6","id":"pf"},"WITCInitialHeight":{"val":"1.8","id":"pf"}},"id":"ct"},"AbsorptionAmount":{"val":"0.0","id":"pf"},"OnGround":{"val":"1","id":"pb"},"HurtTime":{"val":"0","id":"ps"},"Dimension":{"val":"0","id":"pi"},"Air":{"val":"300","id":"ps"},"customTex":{"val":"","id":"ss"},"armorValueOverride":{"val":"-1","id":"pi"},"Pos":{"val":[{"val":"1396.5","id":"pd"},{"val":"105.0","id":"pd"},{"val":"1887.5","id":"pd"}],"id":"ls"},"CanPickUpLoot":{"val":"0","id":"pb"},"PortalCooldown":{"val":"0","id":"pi"},"PersistenceRequired":{"val":"1","id":"pb"},"shieldStack":{"val":{"item":{"val":"AncientWarfareNpc:iron_shield","id":"ss"},"damage":{"val":"0","id":"pi"},"quantity":{"val":"1","id":"pi"}},"id":"ct"},"Leashed":{"val":"0","id":"pb"},"owner":{"val":"OldMiniCollector","id":"ss"},"FallDistance":{"val":"0.0","id":"pf"},"Rotation":{"val":[{"val":"3.5867448","id":"pf"},{"val":"0.0","id":"pf"}],"id":"ls"},"levelingStats":{"val":{"level":{"val":"0","id":"pi"},"xp":{"val":"0","id":"pi"},"entryList":{"val":[],"id":"ls"}},"id":"ct"}},"id":"ct"},"xOffset":{"val":"0.5","id":"pf"},"mobID":{"val":"AncientWarfareNpc.viking.soldier","id":"ss"},"zOffset":{"val":"0.5","id":"pf"},"rotation":{"val":"273.58673","id":"pf"},"equipmentData":{"val":{"equipmentContents":{"val":[{"val":{"item":{"val":"minecraft:iron_sword","id":"ss"},"damage":{"val":"0","id":"pi"},"quantity":{"val":"1","id":"pi"},"slot":{"val":"0","id":"pi"}},"id":"ct"}],"id":"ls"},"length":{"val":"5","id":"pi"}},"id":"ct"}},"id":"ct"}}
:enddata
:endentity

entity:
plugin=AWNpc
number=3
data:
position=4,8,7
JSON:{{"val":{"entityData":{"val":{"DropChances":{"val":[{"val":"1.0","id":"pf"},{"val":"1.0","id":"pf"},{"val":"1.0","id":"pf"},{"val":"1.0","id":"pf"},{"val":"1.0","id":"pf"}],"id":"ls"},"Attributes":{"val":[{"val":{"Name":{"val":"generic.maxHealth","id":"ss"},"Base":{"val":"20.0","id":"pd"}},"id":"ct"},{"val":{"Name":{"val":"generic.knockbackResistance","id":"ss"},"Base":{"val":"0.0","id":"pd"}},"id":"ct"},{"val":{"Name":{"val":"generic.movementSpeed","id":"ss"},"Base":{"val":"0.325","id":"pd"}},"id":"ct"},{"val":{"Name":{"val":"generic.followRange","id":"ss"},"Base":{"val":"60.0","id":"pd"}},"id":"ct"},{"val":{"Name":{"val":"generic.attackDamage","id":"ss"},"Base":{"val":"2.0","id":"pd"}},"id":"ct"}],"id":"ls"},"Motion":{"val":[{"val":"0.0","id":"pd"},{"val":"-0.0784000015258789","id":"pd"},{"val":"0.0","id":"pd"}],"id":"ls"},"CustomName":{"val":"","id":"ss"},"Health":{"val":"20","id":"ps"},"HealF":{"val":"20.0","id":"pf"},"CustomNameVisible":{"val":"0","id":"pb"},"AttackTime":{"val":"0","id":"ps"},"Fire":{"val":"-1","id":"ps"},"attackDamageOverride":{"val":"-1","id":"pi"},"Invulnerable":{"val":"0","id":"pb"},"DeathTime":{"val":"0","id":"ps"},"ForgeData":{"val":{"WITCInitialWidth":{"val":"0.6","id":"pf"},"WITCInitialHeight":{"val":"1.8","id":"pf"}},"id":"ct"},"AbsorptionAmount":{"val":"0.0","id":"pf"},"OnGround":{"val":"1","id":"pb"},"HurtTime":{"val":"0","id":"ps"},"Dimension":{"val":"0","id":"pi"},"Air":{"val":"300","id":"ps"},"customTex":{"val":"","id":"ss"},"armorValueOverride":{"val":"-1","id":"pi"},"Pos":{"val":[{"val":"1393.5","id":"pd"},{"val":"105.0","id":"pd"},{"val":"1887.5","id":"pd"}],"id":"ls"},"CanPickUpLoot":{"val":"0","id":"pb"},"PortalCooldown":{"val":"0","id":"pi"},"PersistenceRequired":{"val":"1","id":"pb"},"shieldStack":{"val":{"item":{"val":"AncientWarfareNpc:iron_shield","id":"ss"},"damage":{"val":"0","id":"pi"},"quantity":{"val":"1","id":"pi"}},"id":"ct"},"Leashed":{"val":"0","id":"pb"},"owner":{"val":"OldMiniCollector","id":"ss"},"FallDistance":{"val":"0.0","id":"pf"},"Rotation":{"val":[{"val":"5.3319182","id":"pf"},{"val":"0.0","id":"pf"}],"id":"ls"},"levelingStats":{"val":{"level":{"val":"0","id":"pi"},"xp":{"val":"0","id":"pi"},"entryList":{"val":[],"id":"ls"}},"id":"ct"}},"id":"ct"},"xOffset":{"val":"0.5","id":"pf"},"mobID":{"val":"AncientWarfareNpc.viking.soldier","id":"ss"},"zOffset":{"val":"0.5","id":"pf"},"rotation":{"val":"275.3319","id":"pf"},"equipmentData":{"val":{"equipmentContents":{"val":[{"val":{"item":{"val":"minecraft:iron_sword","id":"ss"},"damage":{"val":"0","id":"pi"},"quantity":{"val":"1","id":"pi"},"slot":{"val":"0","id":"pi"}},"id":"ct"}],"id":"ls"},"length":{"val":"5","id":"pi"}},"id":"ct"}},"id":"ct"}}
:enddata
:endentity

entity:
plugin=AWNpc
number=4
data:
position=11,20,8
JSON:{{"val":{"entityData":{"val":{"DropChances":{"val":[{"val":"1.0","id":"pf"},{"val":"1.0","id":"pf"},{"val":"1.0","id":"pf"},{"val":"1.0","id":"pf"},{"val":"1.0","id":"pf"}],"id":"ls"},"Attributes":{"val":[{"val":{"Name":{"val":"generic.maxHealth","id":"ss"},"Base":{"val":"20.0","id":"pd"}},"id":"ct"},{"val":{"Name":{"val":"generic.knockbackResistance","id":"ss"},"Base":{"val":"0.0","id":"pd"}},"id":"ct"},{"val":{"Name":{"val":"generic.movementSpeed","id":"ss"},"Base":{"val":"0.325","id":"pd"}},"id":"ct"},{"val":{"Name":{"val":"generic.followRange","id":"ss"},"Base":{"val":"60.0","id":"pd"}},"id":"ct"},{"val":{"Name":{"val":"generic.attackDamage","id":"ss"},"Base":{"val":"2.0","id":"pd"}},"id":"ct"}],"id":"ls"},"Motion":{"val":[{"val":"0.0","id":"pd"},{"val":"-0.0784000015258789","id":"pd"},{"val":"0.0","id":"pd"}],"id":"ls"},"CustomName":{"val":"","id":"ss"},"Health":{"val":"20","id":"ps"},"HealF":{"val":"20.0","id":"pf"},"CustomNameVisible":{"val":"0","id":"pb"},"ordersStack":{"val":{"item":{"val":"minecraft:arrow","id":"ss"},"damage":{"val":"0","id":"pi"},"quantity":{"val":"1","id":"pi"}},"id":"ct"},"AttackTime":{"val":"0","id":"ps"},"upkeepStack":{"val":{"item":{"val":"minecraft:arrow","id":"ss"},"damage":{"val":"0","id":"pi"},"quantity":{"val":"1","id":"pi"}},"id":"ct"},"Fire":{"val":"-1","id":"ps"},"attackDamageOverride":{"val":"-1","id":"pi"},"Invulnerable":{"val":"0","id":"pb"},"DeathTime":{"val":"0","id":"ps"},"ForgeData":{"val":{"WITCInitialWidth":{"val":"0.6","id":"pf"},"WITCInitialHeight":{"val":"1.8","id":"pf"}},"id":"ct"},"AbsorptionAmount":{"val":"0.0","id":"pf"},"OnGround":{"val":"1","id":"pb"},"HurtTime":{"val":"0","id":"ps"},"Dimension":{"val":"0","id":"pi"},"Air":{"val":"300","id":"ps"},"customTex":{"val":"","id":"ss"},"armorValueOverride":{"val":"-1","id":"pi"},"Pos":{"val":[{"val":"1392.5","id":"pd"},{"val":"117.0","id":"pd"},{"val":"1894.5","id":"pd"}],"id":"ls"},"CanPickUpLoot":{"val":"0","id":"pb"},"PortalCooldown":{"val":"0","id":"pi"},"PersistenceRequired":{"val":"1","id":"pb"},"Leashed":{"val":"0","id":"pb"},"owner":{"val":"OldMiniCollector","id":"ss"},"FallDistance":{"val":"0.0","id":"pf"},"Rotation":{"val":[{"val":"4.8513927","id":"pf"},{"val":"0.0","id":"pf"}],"id":"ls"},"levelingStats":{"val":{"level":{"val":"0","id":"pi"},"xp":{"val":"0","id":"pi"},"entryList":{"val":[],"id":"ls"}},"id":"ct"}},"id":"ct"},"xOffset":{"val":"0.5","id":"pf"},"mobID":{"val":"AncientWarfareNpc.viking.archer","id":"ss"},"zOffset":{"val":"0.5","id":"pf"},"rotation":{"val":"274.85138","id":"pf"},"equipmentData":{"val":{"equipmentContents":{"val":[{"val":{"item":{"val":"minecraft:bow","id":"ss"},"damage":{"val":"0","id":"pi"},"quantity":{"val":"1","id":"pi"},"slot":{"val":"0","id":"pi"}},"id":"ct"}],"id":"ls"},"length":{"val":"5","id":"pi"}},"id":"ct"}},"id":"ct"}}
:enddata
:endentity

entity:
plugin=AWNpc
number=5
data:
position=10,20,3
JSON:{{"val":{"entityData":{"val":{"DropChances":{"val":[{"val":"1.0","id":"pf"},{"val":"1.0","id":"pf"},{"val":"1.0","id":"pf"},{"val":"1.0","id":"pf"},{"val":"1.0","id":"pf"}],"id":"ls"},"Attributes":{"val":[{"val":{"Name":{"val":"generic.maxHealth","id":"ss"},"Base":{"val":"20.0","id":"pd"}},"id":"ct"},{"val":{"Name":{"val":"generic.knockbackResistance","id":"ss"},"Base":{"val":"0.0","id":"pd"}},"id":"ct"},{"val":{"Name":{"val":"generic.movementSpeed","id":"ss"},"Base":{"val":"0.325","id":"pd"}},"id":"ct"},{"val":{"Name":{"val":"generic.followRange","id":"ss"},"Base":{"val":"60.0","id":"pd"}},"id":"ct"},{"val":{"Name":{"val":"generic.attackDamage","id":"ss"},"Base":{"val":"2.0","id":"pd"}},"id":"ct"}],"id":"ls"},"Motion":{"val":[{"val":"0.0","id":"pd"},{"val":"-0.0784000015258789","id":"pd"},{"val":"0.0","id":"pd"}],"id":"ls"},"CustomName":{"val":"","id":"ss"},"Health":{"val":"20","id":"ps"},"HealF":{"val":"20.0","id":"pf"},"CustomNameVisible":{"val":"0","id":"pb"},"ordersStack":{"val":{"item":{"val":"minecraft:arrow","id":"ss"},"damage":{"val":"0","id":"pi"},"quantity":{"val":"1","id":"pi"}},"id":"ct"},"AttackTime":{"val":"0","id":"ps"},"upkeepStack":{"val":{"item":{"val":"minecraft:arrow","id":"ss"},"damage":{"val":"0","id":"pi"},"quantity":{"val":"1","id":"pi"}},"id":"ct"},"Fire":{"val":"-1","id":"ps"},"attackDamageOverride":{"val":"-1","id":"pi"},"Invulnerable":{"val":"0","id":"pb"},"DeathTime":{"val":"0","id":"ps"},"ForgeData":{"val":{"WITCInitialWidth":{"val":"0.6","id":"pf"},"WITCInitialHeight":{"val":"1.8","id":"pf"}},"id":"ct"},"AbsorptionAmount":{"val":"0.0","id":"pf"},"OnGround":{"val":"1","id":"pb"},"HurtTime":{"val":"0","id":"ps"},"Dimension":{"val":"0","id":"pi"},"Air":{"val":"300","id":"ps"},"customTex":{"val":"","id":"ss"},"armorValueOverride":{"val":"-1","id":"pi"},"Pos":{"val":[{"val":"1397.5","id":"pd"},{"val":"117.0","id":"pd"},{"val":"1893.5","id":"pd"}],"id":"ls"},"CanPickUpLoot":{"val":"0","id":"pb"},"PortalCooldown":{"val":"0","id":"pi"},"PersistenceRequired":{"val":"1","id":"pb"},"Leashed":{"val":"0","id":"pb"},"owner":{"val":"OldMiniCollector","id":"ss"},"FallDistance":{"val":"0.0","id":"pf"},"Rotation":{"val":[{"val":"1.1923895","id":"pf"},{"val":"0.0","id":"pf"}],"id":"ls"},"levelingStats":{"val":{"level":{"val":"0","id":"pi"},"xp":{"val":"0","id":"pi"},"entryList":{"val":[],"id":"ls"}},"id":"ct"}},"id":"ct"},"xOffset":{"val":"0.5","id":"pf"},"mobID":{"val":"AncientWarfareNpc.viking.archer","id":"ss"},"zOffset":{"val":"0.5","id":"pf"},"rotation":{"val":"271.19238","id":"pf"},"equipmentData":{"val":{"equipmentContents":{"val":[{"val":{"item":{"val":"minecraft:bow","id":"ss"},"damage":{"val":"0","id":"pi"},"quantity":{"val":"1","id":"pi"},"slot":{"val":"0","id":"pi"}},"id":"ct"}],"id":"ls"},"length":{"val":"5","id":"pi"}},"id":"ct"}},"id":"ct"}}
:enddata
:endentity

entity:
plugin=AWNpc
number=6
data:
position=6,20,6
JSON:{{"val":{"entityData":{"val":{"DropChances":{"val":[{"val":"1.0","id":"pf"},{"val":"1.0","id":"pf"},{"val":"1.0","id":"pf"},{"val":"1.0","id":"pf"},{"val":"1.0","id":"pf"}],"id":"ls"},"Attributes":{"val":[{"val":{"Name":{"val":"generic.maxHealth","id":"ss"},"Base":{"val":"20.0","id":"pd"}},"id":"ct"},{"val":{"Name":{"val":"generic.knockbackResistance","id":"ss"},"Base":{"val":"0.0","id":"pd"}},"id":"ct"},{"val":{"Name":{"val":"generic.movementSpeed","id":"ss"},"Base":{"val":"0.325","id":"pd"}},"id":"ct"},{"val":{"Name":{"val":"generic.followRange","id":"ss"},"Base":{"val":"60.0","id":"pd"}},"id":"ct"},{"val":{"Name":{"val":"generic.attackDamage","id":"ss"},"Base":{"val":"2.0","id":"pd"}},"id":"ct"}],"id":"ls"},"Motion":{"val":[{"val":"0.0","id":"pd"},{"val":"-0.0784000015258789","id":"pd"},{"val":"0.0","id":"pd"}],"id":"ls"},"CustomName":{"val":"","id":"ss"},"Health":{"val":"20","id":"ps"},"HealF":{"val":"20.0","id":"pf"},"CustomNameVisible":{"val":"0","id":"pb"},"ordersStack":{"val":{"item":{"val":"minecraft:arrow","id":"ss"},"damage":{"val":"0","id":"pi"},"quantity":{"val":"1","id":"pi"}},"id":"ct"},"AttackTime":{"val":"0","id":"ps"},"upkeepStack":{"val":{"item":{"val":"minecraft:arrow","id":"ss"},"damage":{"val":"0","id":"pi"},"quantity":{"val":"1","id":"pi"}},"id":"ct"},"Fire":{"val":"-1","id":"ps"},"attackDamageOverride":{"val":"-1","id":"pi"},"Invulnerable":{"val":"0","id":"pb"},"DeathTime":{"val":"0","id":"ps"},"ForgeData":{"val":{"WITCInitialWidth":{"val":"0.6","id":"pf"},"WITCInitialHeight":{"val":"1.8","id":"pf"}},"id":"ct"},"AbsorptionAmount":{"val":"0.0","id":"pf"},"OnGround":{"val":"1","id":"pb"},"HurtTime":{"val":"0","id":"ps"},"Dimension":{"val":"0","id":"pi"},"Air":{"val":"300","id":"ps"},"customTex":{"val":"","id":"ss"},"armorValueOverride":{"val":"-1","id":"pi"},"Pos":{"val":[{"val":"1394.5","id":"pd"},{"val":"117.0","id":"pd"},{"val":"1889.5","id":"pd"}],"id":"ls"},"CanPickUpLoot":{"val":"0","id":"pb"},"PortalCooldown":{"val":"0","id":"pi"},"PersistenceRequired":{"val":"1","id":"pb"},"Leashed":{"val":"0","id":"pb"},"owner":{"val":"OldMiniCollector","id":"ss"},"FallDistance":{"val":"0.0","id":"pf"},"Rotation":{"val":[{"val":"1.2142614","id":"pf"},{"val":"0.0","id":"pf"}],"id":"ls"},"levelingStats":{"val":{"level":{"val":"0","id":"pi"},"xp":{"val":"0","id":"pi"},"entryList":{"val":[],"id":"ls"}},"id":"ct"}},"id":"ct"},"xOffset":{"val":"0.5","id":"pf"},"mobID":{"val":"AncientWarfareNpc.viking.archer","id":"ss"},"zOffset":{"val":"0.5","id":"pf"},"rotation":{"val":"271.21426","id":"pf"},"equipmentData":{"val":{"equipmentContents":{"val":[{"val":{"item":{"val":"minecraft:bow","id":"ss"},"damage":{"val":"0","id":"pi"},"quantity":{"val":"1","id":"pi"},"slot":{"val":"0","id":"pi"}},"id":"ct"}],"id":"ls"},"length":{"val":"5","id":"pi"}},"id":"ct"}},"id":"ct"}}
:enddata
:endentity

entity:
plugin=AWNpc
number=7
data:
position=7,16,7
JSON:{{"val":{"entityData":{"val":{"DropChances":{"val":[{"val":"1.0","id":"pf"},{"val":"1.0","id":"pf"},{"val":"1.0","id":"pf"},{"val":"1.0","id":"pf"},{"val":"1.0","id":"pf"}],"id":"ls"},"Attributes":{"val":[{"val":{"Name":{"val":"generic.maxHealth","id":"ss"},"Base":{"val":"40.0","id":"pd"}},"id":"ct"},{"val":{"Name":{"val":"generic.knockbackResistance","id":"ss"},"Base":{"val":"0.0","id":"pd"}},"id":"ct"},{"val":{"Name":{"val":"generic.movementSpeed","id":"ss"},"Base":{"val":"0.325","id":"pd"}},"id":"ct"},{"val":{"Name":{"val":"generic.followRange","id":"ss"},"Base":{"val":"60.0","id":"pd"}},"id":"ct"},{"val":{"Name":{"val":"generic.attackDamage","id":"ss"},"Base":{"val":"2.0","id":"pd"}},"id":"ct"}],"id":"ls"},"Motion":{"val":[{"val":"0.0","id":"pd"},{"val":"-0.0784000015258789","id":"pd"},{"val":"0.0","id":"pd"}],"id":"ls"},"CustomName":{"val":"","id":"ss"},"Health":{"val":"40","id":"ps"},"HealF":{"val":"40.0","id":"pf"},"CustomNameVisible":{"val":"0","id":"pb"},"AttackTime":{"val":"0","id":"ps"},"Fire":{"val":"-1","id":"ps"},"attackDamageOverride":{"val":"-1","id":"pi"},"Invulnerable":{"val":"0","id":"pb"},"DeathTime":{"val":"0","id":"ps"},"ForgeData":{"val":{"WITCInitialWidth":{"val":"0.6","id":"pf"},"WITCInitialHeight":{"val":"1.8","id":"pf"}},"id":"ct"},"AbsorptionAmount":{"val":"0.0","id":"pf"},"OnGround":{"val":"1","id":"pb"},"HurtTime":{"val":"0","id":"ps"},"Dimension":{"val":"0","id":"pi"},"Air":{"val":"300","id":"ps"},"customTex":{"val":"","id":"ss"},"armorValueOverride":{"val":"-1","id":"pi"},"Pos":{"val":[{"val":"1393.5","id":"pd"},{"val":"113.0","id":"pd"},{"val":"1890.5","id":"pd"}],"id":"ls"},"CanPickUpLoot":{"val":"0","id":"pb"},"PortalCooldown":{"val":"0","id":"pi"},"PersistenceRequired":{"val":"1","id":"pb"},"shieldStack":{"val":{"item":{"val":"AncientWarfareNpc:iron_shield","id":"ss"},"damage":{"val":"0","id":"pi"},"quantity":{"val":"1","id":"pi"}},"id":"ct"},"Leashed":{"val":"0","id":"pb"},"owner":{"val":"OldMiniCollector","id":"ss"},"FallDistance":{"val":"0.0","id":"pf"},"Rotation":{"val":[{"val":"0.9222367","id":"pf"},{"val":"0.0","id":"pf"}],"id":"ls"},"levelingStats":{"val":{"level":{"val":"0","id":"pi"},"xp":{"val":"0","id":"pi"},"entryList":{"val":[],"id":"ls"}},"id":"ct"}},"id":"ct"},"xOffset":{"val":"0.5","id":"pf"},"mobID":{"val":"AncientWarfareNpc.viking.leader","id":"ss"},"zOffset":{"val":"0.5","id":"pf"},"rotation":{"val":"270.92224","id":"pf"},"equipmentData":{"val":{"equipmentContents":{"val":[{"val":{"item":{"val":"minecraft:diamond_axe","id":"ss"},"damage":{"val":"0","id":"pi"},"quantity":{"val":"1","id":"pi"},"slot":{"val":"0","id":"pi"}},"id":"ct"}],"id":"ls"},"length":{"val":"5","id":"pi"}},"id":"ct"}},"id":"ct"}}
:enddata
:endentity

entity:
plugin=AWNpc
number=8
data:
position=9,17,6
JSON:{{"val":{"entityData":{"val":{"DropChances":{"val":[{"val":"1.0","id":"pf"},{"val":"1.0","id":"pf"},{"val":"1.0","id":"pf"},{"val":"1.0","id":"pf"},{"val":"1.0","id":"pf"}],"id":"ls"},"Attributes":{"val":[{"val":{"Name":{"val":"generic.maxHealth","id":"ss"},"Base":{"val":"20.0","id":"pd"}},"id":"ct"},{"val":{"Name":{"val":"generic.knockbackResistance","id":"ss"},"Base":{"val":"0.0","id":"pd"}},"id":"ct"},{"val":{"Name":{"val":"generic.movementSpeed","id":"ss"},"Base":{"val":"0.325","id":"pd"}},"id":"ct"},{"val":{"Name":{"val":"generic.followRange","id":"ss"},"Base":{"val":"60.0","id":"pd"}},"id":"ct"},{"val":{"Name":{"val":"generic.attackDamage","id":"ss"},"Base":{"val":"2.0","id":"pd"}},"id":"ct"}],"id":"ls"},"Motion":{"val":[{"val":"0.0","id":"pd"},{"val":"-0.0784000015258789","id":"pd"},{"val":"0.0","id":"pd"}],"id":"ls"},"CustomName":{"val":"","id":"ss"},"Health":{"val":"20","id":"ps"},"HealF":{"val":"20.0","id":"pf"},"CustomNameVisible":{"val":"0","id":"pb"},"AttackTime":{"val":"0","id":"ps"},"Fire":{"val":"-1","id":"ps"},"attackDamageOverride":{"val":"-1","id":"pi"},"Invulnerable":{"val":"0","id":"pb"},"DeathTime":{"val":"0","id":"ps"},"ForgeData":{"val":{"WITCInitialWidth":{"val":"0.6","id":"pf"},"WITCInitialHeight":{"val":"1.8","id":"pf"}},"id":"ct"},"AbsorptionAmount":{"val":"0.0","id":"pf"},"OnGround":{"val":"1","id":"pb"},"HurtTime":{"val":"0","id":"ps"},"Dimension":{"val":"0","id":"pi"},"Air":{"val":"300","id":"ps"},"customTex":{"val":"","id":"ss"},"armorValueOverride":{"val":"-1","id":"pi"},"Pos":{"val":[{"val":"1394.589556883143","id":"pd"},{"val":"114.5","id":"pd"},{"val":"1892.695733982646","id":"pd"}],"id":"ls"},"CanPickUpLoot":{"val":"0","id":"pb"},"PortalCooldown":{"val":"0","id":"pi"},"PersistenceRequired":{"val":"1","id":"pb"},"Leashed":{"val":"0","id":"pb"},"owner":{"val":"OldMiniCollector","id":"ss"},"FallDistance":{"val":"0.0","id":"pf"},"Rotation":{"val":[{"val":"-25.541656","id":"pf"},{"val":"0.0","id":"pf"}],"id":"ls"},"levelingStats":{"val":{"level":{"val":"0","id":"pi"},"xp":{"val":"0","id":"pi"},"entryList":{"val":[],"id":"ls"}},"id":"ct"}},"id":"ct"},"xOffset":{"val":"0.69573396","id":"pf"},"mobID":{"val":"AncientWarfareNpc.viking.priest","id":"ss"},"zOffset":{"val":"0.41044313","id":"pf"},"rotation":{"val":"244.45834","id":"pf"},"equipmentData":{"val":{"equipmentContents":{"val":[{"val":{"item":{"val":"minecraft:book","id":"ss"},"damage":{"val":"0","id":"pi"},"quantity":{"val":"1","id":"pi"},"slot":{"val":"0","id":"pi"}},"id":"ct"}],"id":"ls"},"length":{"val":"5","id":"pi"}},"id":"ct"}},"id":"ct"}}
:enddata
:endentity

